{
  "xsize": 16,
  "zsize": 16,
  "palette": {
    "palette": [
      {
        "char": " ",
        "block": "minecraft:air"
      },
      {
        "char": "r",
        "block": "minecraft:air"
      },
      {
        "char": "o",
        "block": "minecraft:air"
      },
      {
        "char": "m",
        "block": "minecraft:air"
      },
      {
        "char": "q",
        "block": "minecraft:air"
      },
      {
        "char": "p",
        "block": "minecraft:air"
      },
      {
        "char": "e",
        "block": "minecraft:air"
      },
      {
        "char": "ͽ",
        "block": "minecraft:air"
      },
      {
        "char": "v",
        "block": "minecraft:air"
      },
      {
        "char": ";",
        "block": "minecraft:air"
      },
      {
        "char": "A",
        "block": "minecraft:air"
      },
      {
        "char": "k",
        "block": "minecraft:air"
      },
      {
        "char": "Α",
        "block": "minecraft:air"
      },
      {
        "char": "f",
        "block": "minecraft:air"
      },
      {
        "char": "j",
        "block": "minecraft:air"
      },
      {
        "char": "Ω",
        "block": "minecraft:air"
      },
      {
        "char": "d",
        "block": "minecraft:air"
      },
      {
        "char": "Ϳ",
        "block": "minecraft:air"
      },
      {
        "char": "н",
        "block": "minecraft:air"
      },
      {
        "char": "γ",
        "block": "minecraft:air"
      },
      {
        "char": "a",
        "block": "minecraft:air"
      },
      {
        "char": "s",
        "block": "minecraft:grass"
      },
      {
        "char": "g",
        "block": "minecraft:air"
      },
      {
        "char": "ΰ",
        "block": "minecraft:air"
      },
      {
        "char": "е",
        "block": "minecraft:air"
      },
      {
        "char": "Ή",
        "block": "minecraft:air"
      },
      {
        "char": "Ѱ",
        "block": "minecraft:air"
      },
      {
        "char": "z",
        "block": "minecraft:air"
      },
      {
        "char": "Ҽ",
        "block": "minecraft:air"
      },
      {
        "char": "Ќ",
        "block": "minecraft:air",
        "tag": {
          "z": 623,
          "x": 195,
          "is_waxed": "0b",
          "ForgeCaps": {
            "supplementaries:antique_ink": {
              "ink": "0b"
            }
          },
          "id": "minecraft:sign",
          "y": 136,
          "front_text": {
            "color": "black",
            "has_glowing_text": "0b",
            "messages": [
              "{\"text\":\"344\"}",
              "{\"text\":\"\"}",
              "{\"text\":\"\"}",
              "{\"text\":\"\"}"
            ]
          },
          "back_text": {
            "color": "black",
            "has_glowing_text": "0b",
            "messages": [
              "{\"text\":\"\"}",
              "{\"text\":\"\"}",
              "{\"text\":\"\"}",
              "{\"text\":\"\"}"
            ]
          }
        }
      },
      {
        "char": "Ѯ",
        "block": "minecraft:air"
      }
    ]
  },
  "slices": [
    [
      "romqoommomrrpopo",
      "pmpprpomqrrpmqro",
      "oropmmmoqpprpoqo",
      "pqqrrommqpmmmmor",
      "moqorpmmpmprpmpo",
      "poqppmpmrpqroomm",
      "pqmqmpopoooqpqmq",
      "pmmooqoppromqoqo",
      "qqpqqrqqormpqomr",
      "qqqppmrrqorqmrqo",
      "oorqrqmrmprrqpmq",
      "mmmeͽvvvvͽ;ͽͽ;v;",
      "oppAvͽvkvkͽv;Α;v",
      "mpmAfffffvvvffff",
      "prmj     jΑjΩ   ",
      "qrmjd dddjΑjdddͿ"
    ],
    [
      "                ",
      "                ",
      "                ",
      "                ",
      "                ",
      "                ",
      "                ",
      "                ",
      "                ",
      "                ",
      "                ",
      "   A  Ϳ     н γa",
      "   A   s    eͿ  ",
      "   gΰΰΰΰеΉΉΉѰΰΰΰ",
      "   z     jjj    ",
      "   zd dddjjjdddd"
    ],
    [
      "                ",
      "                ",
      "                ",
      "                ",
      "                ",
      "                ",
      "                ",
      "                ",
      "                ",
      "                ",
      "                ",
      "   Ҽ           Ϳ",
      "   A            ",
      "   A            ",
      "   g     ΉΉΉ    ",
      "   zd dddjjjdddd"
    ],
    [
      "                ",
      "                ",
      "                ",
      "                ",
      "                ",
      "                ",
      "                ",
      "                ",
      "                ",
      "                ",
      "                ",
      "                ",
      "   A            ",
      "   A            ",
      "   A            ",
      "   Ad ddd   dddd"
    ],
    [
      "                ",
      "                ",
      "                ",
      "                ",
      "                ",
      "                ",
      "                ",
      "                ",
      "                ",
      "                ",
      "                ",
      "                ",
      "                ",
      "   A            ",
      "   z            ",
      "   zd ddd  Ќdddd"
    ],
    [
      "                ",
      "                ",
      "                ",
      "                ",
      "                ",
      "                ",
      "                ",
      "                ",
      "                ",
      "                ",
      "                ",
      "                ",
      "                ",
      "   Ѯ            ",
      "                ",
      "   Ad ddd   dddd"
    ]
  ]
}