{
  "xsize": 16,
  "zsize": 16,
  "palette": {
    "palette": [
      {
        "char": " ",
        "block": "minecraft:air"
      },
      {
        "char": "b",
        "block": "minecraft:basalt[axis=x]"
      },
      {
        "char": "e",
        "block": "minecraft:cyan_terracotta"
      },
      {
        "char": "c",
        "block": "minecraft:deepslate[axis=y]"
      },
      {
        "char": "d",
        "block": "minecraft:cobbled_deepslate"
      },
      {
        "char": "g",
        "block": "minecraft:redstone_lamp[lit=false]"
      },
      {
        "char": "a",
        "block": "minecraft:blackstone"
      },
      {
        "char": "p",
        "block": "minecraft:gray_carpet"
      },
      {
        "char": "f",
        "block": "minecraft:light_gray_concrete"
      },
      {
        "char": "w",
        "block": "minecraft:quartz_stairs[facing=south,half=bottom,shape=straight,waterlogged=false]"
      },
      {
        "char": "ϓ",
        "block": "minecraft:quartz_stairs[facing=north,half=top,shape=straight,waterlogged=false]"
      },
      {
        "char": "x",
        "block": "minecraft:quartz_stairs[facing=north,half=bottom,shape=straight,waterlogged=false]"
      },
      {
        "char": "ҕ",
        "block": "minecraft:chest[facing=south,type=right,waterlogged=false]",
        "loot": "bigbuildingsloot",
        "tag": {
          "z": 942,
          "x": -502,
          "ForgeData": {
            "LockFlag": "1b"
          },
          "ForgeCaps": {},
          "id": "minecraft:chest",
          "y": 112,
          "Items": []
        }
      },
      {
        "char": "Ѷ",
        "block": "minecraft:chest[facing=south,type=left,waterlogged=false]",
        "loot": "bigbuildingsloot",
        "tag": {
          "z": 940,
          "x": -437,
          "ForgeData": {
            "LockFlag": "1b"
          },
          "ForgeCaps": {},
          "id": "minecraft:chest",
          "y": 115,
          "Items": []
        }
      },
      {
        "char": "t",
        "block": "minecraft:green_carpet"
      }
    ]
  },
  "slices": [
    [
      "                ",
      "                ",
      "                ",
      "                ",
      "                ",
      "                ",
      "                ",
      "                ",
      "                ",
      "                ",
      "                ",
      "             bee",
      "      ecedcccdgg",
      "ddecbddeddaeecab",
      "ccabbaadbcceedcb",
      "bbebcbadbeebdcbd"
    ],
    [
      "                ",
      "                ",
      "                ",
      "                ",
      "                ",
      "                ",
      "                ",
      "                ",
      "                ",
      "                ",
      "                ",
      "             bed",
      "      cedccdba  ",
      "ebbecapppppppfgw",
      "ϓϓϓϓϓϓpppppppp  ",
      "pppppppppppppp  "
    ],
    [
      "                ",
      "                ",
      "                ",
      "                ",
      "                ",
      "                ",
      "                ",
      "                ",
      "                ",
      "                ",
      "            cbbe",
      "     acdaebebfg ",
      "eaeddagxxxxxgf  ",
      "geddad       fg ",
      "                ",
      "                "
    ],
    [
      "                ",
      "                ",
      "                ",
      "                ",
      "                ",
      "                ",
      "                ",
      "                ",
      "                ",
      "                ",
      "            deae",
      "     aaeecaecfg ",
      "ceaabegϓϓϓϓϓgf  ",
      "gacaaa       fg ",
      "             f  ",
      "             f  "
    ],
    [
      "                ",
      "                ",
      "                ",
      "                ",
      "                ",
      "                ",
      "                ",
      "                ",
      "                ",
      "           bbcea",
      "    cedcabbdbdea",
      "bcaedacebeadbddc",
      "cdbdccdcccbaeeba",
      "eaabaaecbcdcbbda",
      "bebdbbabdeeaccad",
      "adcceebebbcddedb"
    ],
    [
      "                ",
      "                ",
      "                ",
      "                ",
      "                ",
      "                ",
      "                ",
      "                ",
      "                ",
      "           cbaee",
      "    cebaadb     ",
      "dabeb           ",
      "            gfff",
      "            fҕѶҕ",
      "            tttt",
      "            tttt"
    ]
  ]
}