{
  "xsize": 16,
  "zsize": 16,
  "palette": {
    "palette": [
      {
        "char": " ",
        "block": "minecraft:air"
      },
      {
        "char": "d",
        "block": "minecraft:cobbled_deepslate"
      },
      {
        "char": "c",
        "block": "minecraft:deepslate[axis=y]"
      },
      {
        "char": "a",
        "block": "minecraft:blackstone"
      },
      {
        "char": "e",
        "block": "minecraft:cyan_terracotta"
      },
      {
        "char": "b",
        "block": "minecraft:basalt[axis=x]"
      },
      {
        "char": "g",
        "block": "minecraft:redstone_lamp[lit=false]"
      },
      {
        "char": "f",
        "block": "minecraft:light_gray_concrete"
      },
      {
        "char": "C",
        "block": "minecraft:quartz_stairs[facing=east,half=bottom,shape=straight,waterlogged=false]"
      },
      {
        "char": "n",
        "block": "minecraft:black_concrete"
      },
      {
        "char": "坛",
        "block": "minecraft:redstone_wall_torch[facing=west,lit=true]"
      },
      {
        "char": "x",
        "block": "minecraft:quartz_stairs[facing=north,half=bottom,shape=straight,waterlogged=false]"
      },
      {
        "char": "矮",
        "block": "minecraft:spruce_trapdoor[facing=east,half=top,open=false,powered=false,waterlogged=false]"
      }
    ]
  },
  "slices": [
    [
      "dcdacaaacacacdce",
      "bcceadedacdadecb",
      "cabbebeedaacbcgg",
      "cdeeabccedabdcab",
      "bdeadbdcbdebeccc",
      "dadbbcbccdbbcbbb",
      "bbaeeadccddaeaca",
      "eacbcbcacbbbcccc",
      "beedbdebbabccade",
      "dbccdceeeedcbcdd",
      "daaabbbaaacbecba",
      "bdcceddeaddcdbaa",
      "edadeaaaaddecaad",
      "bcegggeacgggbdcg",
      "dbbacedabacbceeb",
      "adeabeababbacded"
    ],
    [
      "             f  ",
      "              ff",
      "                ",
      "Cffff n         ",
      "                ",
      "                ",
      "                ",
      "                ",
      "                ",
      "                ",
      "                ",
      "                ",
      "                ",
      "                ",
      "                ",
      "                "
    ],
    [
      "             f  ",
      "              ff",
      "                ",
      " Cfff n         ",
      "                ",
      "                ",
      "                ",
      "                ",
      "                ",
      "                ",
      "                ",
      "                ",
      "                ",
      "                ",
      "                ",
      "                "
    ],
    [
      "             f  ",
      "              ff",
      "                ",
      "  Cff n         ",
      "                ",
      "                ",
      "                ",
      "                ",
      "                ",
      "                ",
      "                ",
      "                ",
      "                ",
      "                ",
      "                ",
      "                "
    ],
    [
      "fffffff      f  ",
      "ffffff        ff",
      "ffffff          ",
      "   Cf n         ",
      "                ",
      "                ",
      "                ",
      "                ",
      "                ",
      "                ",
      "                ",
      "                ",
      "                ",
      "                ",
      "                ",
      "                "
    ],
    [
      "abca 坛af     f  ",
      "cbcebcf       ff",
      "bacxagf         ",
      "矮   ffn         ",
      "ffff            ",
      "                ",
      "                ",
      "                ",
      "                ",
      "                ",
      "                ",
      "                ",
      "                ",
      "                ",
      "                ",
      "                "
    ]
  ]
}