{
  "xsize": 16,
  "zsize": 16,
  "palette": {
    "palette": [
      {
        "char": " ",
        "block": "minecraft:air"
      },
      {
        "char": "a",
        "block": "minecraft:blackstone"
      },
      {
        "char": "c",
        "block": "minecraft:deepslate[axis=y]"
      },
      {
        "char": "卷",
        "block": "minecraft:snow[layers=1]"
      },
      {
        "char": "b",
        "block": "minecraft:basalt[axis=x]"
      },
      {
        "char": "呀",
        "block": "minecraft:barrel[facing=south,open=false]",
        "tag": {
          "z": 940,
          "x": -414,
          "ForgeData": {
            "LockFlag": "1b"
          },
          "ForgeCaps": {},
          "id": "minecraft:barrel",
          "y": 112,
          "Items": []
        }
      },
      {
        "char": "d",
        "block": "minecraft:cobbled_deepslate"
      },
      {
        "char": "e",
        "block": "minecraft:cyan_terracotta"
      },
      {
        "char": "g",
        "block": "minecraft:redstone_lamp[lit=false]"
      },
      {
        "char": "f",
        "block": "minecraft:light_gray_concrete"
      },
      {
        "char": "k",
        "block": "minecraft:bookshelf"
      },
      {
        "char": "x",
        "block": "minecraft:quartz_stairs[facing=north,half=bottom,shape=straight,waterlogged=false]"
      },
      {
        "char": "r",
        "block": "minecraft:red_carpet"
      },
      {
        "char": "j",
        "block": "minecraft:black_carpet"
      },
      {
        "char": "癢",
        "block": "minecraft:air"
      },
      {
        "char": "Ӯ",
        "block": "minecraft:birch_wall_sign[facing=north,waterlogged=false]",
        "tag": {
          "z": 955,
          "x": -442,
          "is_waxed": "0b",
          "ForgeCaps": {
            "supplementaries:antique_ink": {
              "ink": "0b"
            }
          },
          "id": "minecraft:sign",
          "y": 108,
          "front_text": {
            "color": "black",
            "has_glowing_text": "0b",
            "messages": [
              "{\"extra\":[{\"text\":\"Exodus Squadron\"}],\"text\":\"\"}",
              "{\"extra\":[{\"text\":\"Quarters\"}],\"text\":\"\"}",
              "{\"text\":\"\"}",
              "{\"text\":\"\"}"
            ]
          },
          "back_text": {
            "color": "black",
            "has_glowing_text": "0b",
            "messages": [
              "{\"text\":\"\"}",
              "{\"text\":\"\"}",
              "{\"text\":\"\"}",
              "{\"text\":\"\"}"
            ]
          }
        }
      },
      {
        "char": "未",
        "block": "minecraft:air",
        "tag": {
          "z": 948,
          "x": -513,
          "ForgeCaps": {},
          "id": "refurbished_furniture:ceiling_light",
          "y": 117,
          "NodePos": "-141012362379147L",
          "Connections": [
            "L"
          ]
        }
      },
      {
        "char": "父",
        "block": "minecraft:air",
        "tag": {
          "z": 953,
          "x": -457,
          "ForgeCaps": {},
          "id": "refurbished_furniture:ceiling_light",
          "y": 117,
          "NodePos": "-125619199569803L",
          "Connections": [
            "L"
          ]
        }
      }
    ]
  },
  "slices": [
    [
      "                ",
      "                ",
      "                ",
      "                ",
      "                ",
      "                ",
      "                ",
      "                ",
      "                ",
      "                ",
      "                ",
      "                ",
      "a               ",
      "caa             ",
      "卷abcbc          ",
      " 呀呀呀呀bdabddae   "
    ],
    [
      "                ",
      "                ",
      "                ",
      "                ",
      "                ",
      "                ",
      "                ",
      "                ",
      "                ",
      "                ",
      "                ",
      "ec              ",
      " dbc            ",
      "  gbcad         ",
      " 呀呀呀呀gdecdcea   ",
      "           gedbe"
    ],
    [
      "                ",
      "                ",
      "                ",
      "                ",
      "                ",
      "                ",
      "                ",
      "                ",
      "                ",
      "a               ",
      "bde             ",
      "cabbc           ",
      "dcddaaec        ",
      "bacbddedadbdcb  ",
      "bbaddcaeebacdede",
      "dbebebaeaaccdcbc"
    ],
    [
      "                ",
      "                ",
      "                ",
      "                ",
      "                ",
      "                ",
      "                ",
      "                ",
      "ab              ",
      " cdd            ",
      "   adb          ",
      "     dadb       ",
      "        daabbbe ",
      "f       fkkkkkbd",
      "xff       rjrjrj",
      " xxff     jrjrj癢"
    ],
    [
      "                ",
      "                ",
      "                ",
      "                ",
      "                ",
      "                ",
      "                ",
      "                ",
      "eb              ",
      " bee            ",
      "   eee          ",
      "     edbb       ",
      "        addbcca ",
      "f       fkkkkkda",
      " ff             ",
      "   ffӮ          "
    ],
    [
      "                ",
      "                ",
      "                ",
      "                ",
      "                ",
      "                ",
      "b               ",
      "ccd             ",
      " geeb           ",
      "   gcbb         ",
      "     gacbe      ",
      "         abcccbe",
      "               c",
      "f       fkkkkkad",
      "未ff     f父     未",
      " 未未ff   f       "
    ]
  ]
}