{
  "xsize": 16,
  "zsize": 16,
  "palette": {
    "palette": [
      {
        "char": " ",
        "block": "minecraft:air"
      },
      {
        "char": "a",
        "block": "minecraft:blackstone"
      },
      {
        "char": "d",
        "block": "minecraft:cobbled_deepslate"
      },
      {
        "char": "b",
        "block": "minecraft:basalt[axis=x]"
      },
      {
        "char": "e",
        "block": "minecraft:cyan_terracotta"
      },
      {
        "char": "c",
        "block": "minecraft:deepslate[axis=y]"
      },
      {
        "char": "烧",
        "block": "minecraft:ladder[facing=south,waterlogged=false]"
      },
      {
        "char": "g",
        "block": "minecraft:redstone_lamp[lit=false]"
      },
      {
        "char": "恶",
        "block": "minecraft:lever[face=wall,facing=south,powered=false]"
      },
      {
        "char": "璞",
        "block": "minecraft:redstone_wall_torch[facing=south,lit=true]"
      },
      {
        "char": "f",
        "block": "minecraft:light_gray_concrete"
      },
      {
        "char": "腥",
        "block": "minecraft:iron_trapdoor[facing=south,half=bottom,open=true,powered=true,waterlogged=false]"
      },
      {
        "char": "w",
        "block": "minecraft:quartz_stairs[facing=south,half=bottom,shape=straight,waterlogged=false]"
      },
      {
        "char": "卷",
        "block": "minecraft:ladder[facing=west,waterlogged=false]"
      },
      {
        "char": "z",
        "block": "minecraft:quartz_stairs[facing=west,half=bottom,shape=straight,waterlogged=false]"
      },
      {
        "char": "首",
        "block": "minecraft:sticky_piston[extended=false,facing=north]"
      },
      {
        "char": "x",
        "block": "minecraft:quartz_stairs[facing=north,half=bottom,shape=straight,waterlogged=false]"
      },
      {
        "char": "颖",
        "block": "minecraft:lever[face=wall,facing=north,powered=false]"
      },
      {
        "char": "伐",
        "block": "minecraft:redstone_wall_torch[facing=north,lit=true]"
      }
    ]
  },
  "slices": [
    [
      "                ",
      "                ",
      "                ",
      "                ",
      "                ",
      "                ",
      "                ",
      "                ",
      "                ",
      "                ",
      "                ",
      "                ",
      "addd            ",
      "adbabeecbbceccbd",
      "aadd            ",
      "                "
    ],
    [
      "                ",
      "                ",
      "                ",
      "                ",
      "                ",
      "                ",
      "                ",
      "                ",
      "                ",
      "                ",
      "                ",
      "                ",
      "ddccd           ",
      "     accdeeebccc",
      "bedac           ",
      "                "
    ],
    [
      "                ",
      "                ",
      "                ",
      "                ",
      "                ",
      "                ",
      "                ",
      "                ",
      "                ",
      "                ",
      "                ",
      "ceedce          ",
      "   烧 caccea     ",
      "     cdbaaaddcdb",
      "     aeaebd     ",
      "bacbda          "
    ],
    [
      "                ",
      "                ",
      "                ",
      "                ",
      "                ",
      "                ",
      "                ",
      "                ",
      "                ",
      "                ",
      "                ",
      "eeadecd         ",
      "   烧 daddddd    ",
      "     a      ebbb",
      "     bccdabb    ",
      "ccdebda         "
    ],
    [
      "                ",
      "                ",
      "                ",
      "                ",
      "                ",
      "                ",
      "                ",
      "                ",
      "                ",
      "                ",
      "babacdbe        ",
      "bbdeabeebeeeab  ",
      "ead烧ebaeeabebb  ",
      "edagggcadeeebdba",
      "beeddaebbadaea  ",
      "ddcdacecbedaee  "
    ],
    [
      "                ",
      "                ",
      "                ",
      "                ",
      "                ",
      "                ",
      "                ",
      "                ",
      "                ",
      "                ",
      "ccdddeda        ",
      "eccb恶璞恶 edcecec ",
      "cfb腥 w        ed",
      "     卷e       z ",
      "c首e  x        dc",
      "bcba颖 伐 acddedd "
    ]
  ]
}