{
  "xsize": 16,
  "zsize": 16,
  "palette": {
    "palette": [
      {
        "char": " ",
        "block": "minecraft:air"
      },
      {
        "char": "h",
        "block": "minecraft:red_terracotta"
      },
      {
        "char": "陷",
        "block": "minecraft:observer[facing=up,powered=false]"
      },
      {
        "char": "g",
        "block": "minecraft:redstone_lamp[lit=false]"
      },
      {
        "char": "o",
        "block": "minecraft:black_stained_glass"
      },
      {
        "char": "E",
        "block": "minecraft:iron_block"
      },
      {
        "char": "O",
        "block": "minecraft:observer[facing=east,powered=false]"
      },
      {
        "char": "手",
        "block": "minecraft:observer[facing=down,powered=false]"
      },
      {
        "char": "驴",
        "block": "minecraft:redstone_wire[east=side,north=up,power=0,south=none,west=up]"
      },
      {
        "char": "咸",
        "block": "minecraft:redstone_wire[east=side,north=up,power=0,south=side,west=side]"
      },
      {
        "char": "掰",
        "block": "minecraft:redstone_wire[east=side,north=none,power=0,south=side,west=side]"
      },
      {
        "char": "黏",
        "block": "minecraft:redstone_wire[east=none,north=none,power=0,south=side,west=side]"
      },
      {
        "char": "黎",
        "block": "minecraft:redstone_wire[east=none,north=side,power=0,south=side,west=none]"
      },
      {
        "char": "瘦",
        "block": "minecraft:repeater[delay=1,facing=north,locked=false,powered=false]"
      },
      {
        "char": "婉",
        "block": "minecraft:piston[extended=false,facing=south]"
      },
      {
        "char": "凄",
        "block": "minecraft:piston[extended=false,facing=down]"
      },
      {
        "char": "雕",
        "block": "minecraft:repeater[delay=1,facing=south,locked=false,powered=false]"
      },
      {
        "char": "e",
        "block": "minecraft:cyan_terracotta"
      },
      {
        "char": "b",
        "block": "minecraft:basalt[axis=x]"
      },
      {
        "char": "c",
        "block": "minecraft:deepslate[axis=y]"
      },
      {
        "char": "d",
        "block": "minecraft:cobbled_deepslate"
      },
      {
        "char": "a",
        "block": "minecraft:blackstone"
      },
      {
        "char": "蟑",
        "block": "minecraft:redstone_wire[east=side,north=none,power=0,south=side,west=none]"
      },
      {
        "char": "趴",
        "block": "minecraft:redstone_wire[east=side,north=side,power=0,south=up,west=none]"
      },
      {
        "char": "拢",
        "block": "minecraft:redstone_wire[east=side,north=side,power=0,south=side,west=side]"
      },
      {
        "char": "获",
        "block": "minecraft:redstone_wire[east=none,north=up,power=0,south=side,west=none]"
      },
      {
        "char": "G",
        "block": "minecraft:green_stained_glass"
      },
      {
        "char": "M",
        "block": "minecraft:quartz_pillar[axis=y]"
      },
      {
        "char": "堪",
        "block": "minecraft:lava[level=0]"
      },
      {
        "char": "俊",
        "block": "minecraft:observer[facing=north,powered=false]"
      },
      {
        "char": "毙",
        "block": "minecraft:lava[level=2]"
      },
      {
        "char": "锵",
        "block": "minecraft:lava[level=6]"
      },
      {
        "char": "黯",
        "block": "minecraft:lava[level=4]"
      }
    ]
  },
  "slices": [
    [
      "                ",
      "                ",
      "                ",
      "                ",
      "                ",
      "                ",
      "                ",
      "                ",
      "                ",
      "hhhhhhhh hhhhhhh",
      "   hh陷hhhhhhhhg ",
      "     hgggggggo  ",
      "h            o  ",
      "EEEEEEEEEEEEEo  ",
      "h OO手        o  ",
      "      gggggggo  "
    ],
    [
      "                ",
      "                ",
      "                ",
      "                ",
      "                ",
      "                ",
      "                ",
      "                ",
      "                ",
      "hhhhhhhhhhhhhhhh",
      "   hh陷驴咸掰掰掰黏hhg ",
      "    hh 黎瘦黎瘦黎ho  ",
      "     婉婉婉婉婉婉婉 o  ",
      "h            o  ",
      "  手  凄凄凄凄凄凄凄 o  ",
      "    h 黎雕黎雕黎雕ho  "
    ],
    [
      "                ",
      "                ",
      "                ",
      "                ",
      "               e",
      "           ebbec",
      "       cdcedccce",
      "   adebbaebebabc",
      " ededdccceeeedeb",
      "ab  蟑掰掰黏   bdedd",
      "hhhh趴拢      hhhh",
      "    h黎      ho  ",
      "    hhhhhhhhho  ",
      "    hggggggggo  ",
      "  手 hhhhhhhhho  ",
      "    获       ho  "
    ],
    [
      "                ",
      "                ",
      "                ",
      "              ad",
      "          adebeG",
      "      badcbagGGG",
      "  beabb    cGGGE",
      "dac        MGGEM",
      "a          aGGGE",
      "           bgGGE",
      "           ebG堪E",
      "hhhh黎hhhhhhhhhhE",
      "    雕 E     ho E",
      "    黎 EEEEEEEEEE",
      "  手 黎       ho E",
      "hh俊h        hhhE"
    ],
    [
      "                ",
      "                ",
      "             beb",
      "         ebeeaeM",
      "     bbcad  aGGG",
      " bbddd     bgG G",
      "bc         dG GE",
      "           M GEM",
      "           aG GE",
      "           bgG堪G",
      "           ecG堪堪",
      "          拢 d b毙",
      "hhhh hhhhhhhhhh堪",
      "          h h锵黯毙",
      "h  h hhhhhhhhhh堪",
      "             ae堪"
    ],
    [
      "                ",
      "                ",
      "             bac",
      "         cdddacM",
      "     caade  dGGG",
      " dbebb     dgG G",
      "cb         dG GE",
      "           M GEM",
      "           eG GE",
      "           bgG毙G",
      "           daG堪堪",
      "            d aM",
      "                ",
      "hhhhhhhhhhhhhhhh",
      "                ",
      "             bbM"
    ]
  ]
}