{
  "xsize": 16,
  "zsize": 16,
  "palette": {
    "palette": [
      {
        "char": " ",
        "block": "minecraft:air"
      },
      {
        "char": "b",
        "block": "minecraft:basalt[axis=x]"
      },
      {
        "char": "c",
        "block": "minecraft:deepslate[axis=y]"
      },
      {
        "char": "a",
        "block": "minecraft:blackstone"
      },
      {
        "char": "e",
        "block": "minecraft:cyan_terracotta"
      },
      {
        "char": "d",
        "block": "minecraft:cobbled_deepslate"
      },
      {
        "char": "g",
        "block": "minecraft:redstone_lamp[lit=false]"
      },
      {
        "char": "f",
        "block": "minecraft:light_gray_concrete"
      },
      {
        "char": "q",
        "block": "minecraft:gold_block"
      },
      {
        "char": "奉",
        "block": "minecraft:lever[face=wall,facing=east,powered=true]"
      }
    ]
  },
  "slices": [
    [
      "bbcabedaecebbebd",
      "deeecdebdcabacca",
      "geaeadebdbadecec",
      "cecebedebadcaegg",
      "ceadabeabcaaadba",
      "aedcbdeebcdadadc",
      "aaccdbdabbbcebec",
      "eacacdaebbaaaabe",
      "bbcdeadbeaecbceb",
      "aeccecddcaebebda",
      "ecbddadeccddbacc",
      "ddcdbacedebdaacc",
      "ccbeabdbdbbcadab",
      "ggbadgggbaaggged",
      "cecdcbdcddcddaad",
      "eadabdcedccdbbcc"
    ],
    [
      " f          ffff",
      "f            fff",
      "              ff",
      "                ",
      "                ",
      "                ",
      "                ",
      "                ",
      "                ",
      "                ",
      "                ",
      "                ",
      "                ",
      "                ",
      "                ",
      "                "
    ],
    [
      " f          f qq",
      "f            f  ",
      "              ff",
      "                ",
      "                ",
      "                ",
      "                ",
      "                ",
      "                ",
      "                ",
      "                ",
      "                ",
      "                ",
      "                ",
      "                ",
      "                "
    ],
    [
      " f          f奉qq",
      "f            f  ",
      "              ff",
      "                ",
      "                ",
      "                ",
      "                ",
      "                ",
      "                ",
      "                ",
      "                ",
      "                ",
      "                ",
      "                ",
      "                ",
      "                "
    ],
    [
      " f          f qq",
      "f            f  ",
      "              ff",
      "                ",
      "                ",
      "                ",
      "                ",
      "                ",
      "                ",
      "                ",
      "                ",
      "                ",
      "                ",
      "                ",
      "                ",
      "                "
    ],
    [
      " f          f qq",
      "f            f  ",
      "              ff",
      "                ",
      "                ",
      "                ",
      "                ",
      "                ",
      "                ",
      "                ",
      "                ",
      "                ",
      "                ",
      "                ",
      "                ",
      "                "
    ]
  ]
}