{
  "xsize": 16,
  "zsize": 16,
  "palette": {
    "palette": [
      {
        "char": " ",
        "block": "minecraft:air"
      },
      {
        "char": "a",
        "block": "minecraft:blackstone"
      },
      {
        "char": "d",
        "block": "minecraft:cobbled_deepslate"
      },
      {
        "char": "e",
        "block": "minecraft:cyan_terracotta"
      },
      {
        "char": "g",
        "block": "minecraft:redstone_lamp[lit=false]"
      },
      {
        "char": "b",
        "block": "minecraft:basalt[axis=x]"
      },
      {
        "char": "c",
        "block": "minecraft:deepslate[axis=y]"
      },
      {
        "char": "C",
        "block": "minecraft:quartz_stairs[facing=east,half=bottom,shape=straight,waterlogged=false]"
      },
      {
        "char": "助",
        "block": "minecraft:ladder[facing=east,waterlogged=false]"
      },
      {
        "char": "P",
        "block": "minecraft:dark_oak_trapdoor[facing=north,half=bottom,open=true,powered=false,waterlogged=false]"
      },
      {
        "char": "ϒ",
        "block": "minecraft:dark_oak_trapdoor[facing=east,half=bottom,open=true,powered=false,waterlogged=false]"
      },
      {
        "char": "璋",
        "block": "minecraft:air",
        "tag": {
          "z": 990,
          "x": -475,
          "ForgeCaps": {},
          "id": "refurbished_furniture:ceiling_light",
          "y": 139,
          "NodePos": "-130567001743221L",
          "Connections": [
            "L"
          ]
        }
      },
      {
        "char": "磊",
        "block": "minecraft:air",
        "tag": {
          "z": 986,
          "x": -477,
          "ForgeCaps": {},
          "id": "refurbished_furniture:ceiling_light",
          "y": 139,
          "NodePos": "-131116757573493L",
          "Connections": [
            "L"
          ]
        }
      },
      {
        "char": "憧",
        "block": "minecraft:light_blue_wall_banner[facing=west]",
        "tag": {
          "z": 987,
          "Patterns": [
            {
              "Color": 11,
              "Pattern": "gra"
            },
            {
              "Color": 0,
              "Pattern": "cbo"
            },
            {
              "Color": 0,
              "Pattern": "cr"
            },
            {
              "Color": 0,
              "Pattern": "mc"
            },
            {
              "Color": 11,
              "Pattern": "flo"
            },
            {
              "Color": 0,
              "Pattern": "tt"
            }
          ],
          "x": -480,
          "ForgeCaps": {},
          "id": "minecraft:banner",
          "y": 139
        }
      },
      {
        "char": "o",
        "block": "minecraft:black_stained_glass"
      },
      {
        "char": "奉",
        "block": "minecraft:lever[face=wall,facing=east,powered=true]"
      },
      {
        "char": "穴",
        "block": "minecraft:air"
      }
    ]
  },
  "slices": [
    [
      "                ",
      "                ",
      "                ",
      "                ",
      "                ",
      "                ",
      "                ",
      "                ",
      "                ",
      "               a",
      "             deg",
      "     aedebcddg  ",
      "    e           ",
      "   e  Cd        ",
      "   e  c         ",
      "   e            "
    ],
    [
      "                ",
      "                ",
      "                ",
      "                ",
      "                ",
      "                ",
      "                ",
      "                ",
      "                ",
      "                ",
      "                ",
      "              ee",
      "     bcccaedeacb",
      "    c  Ccaaaccac",
      "    b ceeeddcbab",
      "    c   cccdebea"
    ],
    [
      "                ",
      "                ",
      "                ",
      "                ",
      "                ",
      "                ",
      "                ",
      "                ",
      "                ",
      "               a",
      "             ebb",
      "     acceecdbc  ",
      "    c           ",
      "   a       b助   ",
      "   c  PP        ",
      "   c    ϒ       "
    ],
    [
      "                ",
      "                ",
      "                ",
      "                ",
      "                ",
      "                ",
      "                ",
      "               b",
      "              ba",
      "             ad ",
      "     babdedecd  ",
      "    d           ",
      "   bb璋          ",
      "  b 磊      d助   ",
      " 憧c             ",
      "  a             "
    ],
    [
      "                ",
      "                ",
      "                ",
      "                ",
      "                ",
      "                ",
      "                ",
      "                ",
      "                ",
      "               b",
      "            becd",
      "     bdedcebaade",
      "    cbbbbbeecebc",
      "   dbecbceec助bbd",
      "   ccbcbaccdcdbb",
      "   dbdebececebec"
    ],
    [
      "                ",
      "                ",
      "                ",
      "                ",
      "                ",
      "                ",
      "                ",
      "                ",
      "               o",
      "           oooo ",
      "     ooooooo    ",
      "    o        acd",
      "    o       a奉  ",
      "   oo      a穴   ",
      "   o        e   ",
      "   o         a  "
    ]
  ]
}