{
  "xsize": 16,
  "zsize": 16,
  "palette": {
    "palette": [
      {
        "char": " ",
        "block": "minecraft:air"
      },
      {
        "char": "d",
        "block": "minecraft:cobbled_deepslate"
      },
      {
        "char": "e",
        "block": "minecraft:cyan_terracotta"
      },
      {
        "char": "g",
        "block": "minecraft:redstone_lamp[lit=false]"
      },
      {
        "char": "b",
        "block": "minecraft:basalt[axis=x]"
      },
      {
        "char": "a",
        "block": "minecraft:blackstone"
      },
      {
        "char": "c",
        "block": "minecraft:deepslate[axis=y]"
      },
      {
        "char": "w",
        "block": "minecraft:quartz_stairs[facing=south,half=bottom,shape=straight,waterlogged=false]"
      },
      {
        "char": "n",
        "block": "minecraft:black_concrete"
      },
      {
        "char": "职",
        "block": "minecraft:black_stained_glass_pane[east=false,north=true,south=true,waterlogged=false,west=false]"
      },
      {
        "char": "缚",
        "block": "minecraft:black_stained_glass_pane[east=false,north=true,south=false,waterlogged=false,west=false]"
      }
    ]
  },
  "slices": [
    [
      "ddeege   bgacddb",
      "daccgc   dgaeacd",
      "cccbga   bgccaec",
      "bdcegb   cgedccd",
      "eaadgd   egdbeae",
      "aedceb   eeaabbe",
      "bcabeawwwcebeaeb",
      "bcaebabcbcdacc  ",
      "ebaadeacaadb    ",
      "aaaaebdaea      ",
      "bacccadb        ",
      "ccacae          ",
      "abec            ",
      "eb              ",
      "d               ",
      "n               "
    ],
    [
      "     职   职      ",
      "     职   职      ",
      "     职   职      ",
      "     职   职      ",
      "     职   职      ",
      "     缚   缚      ",
      "                ",
      "              ad",
      "            ceb ",
      "          edd   ",
      "        aed     ",
      "      ddc       ",
      "    ebe         ",
      "  aba           ",
      "ncc             ",
      "a               "
    ],
    [
      "                ",
      "                ",
      "                ",
      "                ",
      "                ",
      "                ",
      "                ",
      "                ",
      "               c",
      "             aed",
      "           adc  ",
      "         cde    ",
      "       ccc      ",
      "     aad        ",
      "n  cab          ",
      "eacb            "
    ],
    [
      "                ",
      "                ",
      "                ",
      "                ",
      "                ",
      "                ",
      "                ",
      "                ",
      "                ",
      "                ",
      "              eb",
      "            bea ",
      "          aee   ",
      "        dbc     ",
      "n     cbc       ",
      "d   cdd         "
    ],
    [
      "                ",
      "                ",
      "                ",
      "                ",
      "                ",
      "                ",
      "                ",
      "                ",
      "                ",
      "                ",
      "                ",
      "              gb",
      "            gbad",
      "          gdcc  ",
      "n       gedb    ",
      "b     gcdc      "
    ],
    [
      "                ",
      "                ",
      "                ",
      "                ",
      "                ",
      "                ",
      "                ",
      "                ",
      "                ",
      "                ",
      "                ",
      "                ",
      "              ad",
      "            cc  ",
      "n         de    ",
      "b       ee      "
    ]
  ]
}