{
  "xsize": 16,
  "zsize": 16,
  "palette": {
    "palette": [
      {
        "char": " ",
        "block": "minecraft:air"
      },
      {
        "char": "e",
        "block": "minecraft:cyan_terracotta"
      },
      {
        "char": "d",
        "block": "minecraft:cobbled_deepslate"
      },
      {
        "char": "b",
        "block": "minecraft:basalt[axis=x]"
      },
      {
        "char": "c",
        "block": "minecraft:deepslate[axis=y]"
      },
      {
        "char": "a",
        "block": "minecraft:blackstone"
      },
      {
        "char": "蝎",
        "block": "minecraft:light_gray_bed[facing=east,occupied=false,part=head]",
        "tag": {
          "z": 951,
          "x": -369,
          "ForgeCaps": {},
          "id": "minecraft:bed",
          "y": 107
        }
      },
      {
        "char": "枪",
        "block": "minecraft:light_gray_bed[facing=east,occupied=false,part=foot]",
        "tag": {
          "z": 957,
          "x": -364,
          "ForgeCaps": {},
          "id": "minecraft:bed",
          "y": 108
        }
      },
      {
        "char": "ӯ",
        "block": "minecraft:dark_oak_trapdoor[facing=south,half=bottom,open=true,powered=false,waterlogged=false]"
      },
      {
        "char": "v",
        "block": "minecraft:smooth_quartz"
      },
      {
        "char": "g",
        "block": "minecraft:redstone_lamp[lit=false]"
      },
      {
        "char": "f",
        "block": "minecraft:light_gray_concrete"
      },
      {
        "char": "q",
        "block": "minecraft:gold_block"
      }
    ]
  },
  "slices": [
    [
      "                ",
      "                ",
      "                ",
      "                ",
      "                ",
      "                ",
      "                ",
      "                ",
      "                ",
      "ed              ",
      "ebecebaa        ",
      "adebbcdaceebcb  ",
      "dedeaccdaddcaeaa",
      "adacbccccdaabeda",
      "ddeeecaaacbabecb",
      "dccabaeebbebad  "
    ],
    [
      "                ",
      "                ",
      "                ",
      "                ",
      "                ",
      "                ",
      "                ",
      "                ",
      "                ",
      "dd              ",
      "蝎eeadaac        ",
      "cacbcceeaaaace  ",
      "              cb",
      "                ",
      "              cb",
      "eeaebcbeecdcba  "
    ],
    [
      "                ",
      "                ",
      "                ",
      "                ",
      "                ",
      "                ",
      "                ",
      "                ",
      "aaa             ",
      "枪蝎dcddead       ",
      "ӯӯv    gccaeded ",
      "ffffffffffffffce",
      "                ",
      "                ",
      "                ",
      "ffffffffffffffda"
    ],
    [
      "                ",
      "                ",
      "                ",
      "                ",
      "                ",
      "                ",
      "                ",
      "                ",
      "abd             ",
      "  ebcdeae       ",
      "  g    gacaacea ",
      "ffffffffffffffbb",
      "                ",
      "                ",
      "                ",
      "ffffffffffffffee"
    ],
    [
      "                ",
      "                ",
      "                ",
      "                ",
      "                ",
      "                ",
      "                ",
      "becb            ",
      "cabcbbdccc      ",
      "ddabecaceedeeeed",
      "ddbccebaacdedace",
      "bdecdedbabaacbce",
      "caedebabacbeadda",
      "egggcdegggdecggg",
      "bcbbcbdccddddadb",
      "cadbedabdaebccdb"
    ],
    [
      "                ",
      "                ",
      "                ",
      "                ",
      "                ",
      "                ",
      "                ",
      "aeda            ",
      " qqeceeacb      ",
      " qq qq qqabcdebb",
      "               e",
      "abdedcadeaedabce",
      "                ",
      "                ",
      "                ",
      "dabcbcbcbecaeebd"
    ]
  ]
}