{
  "xsize": 16,
  "zsize": 16,
  "palette": {
    "palette": [
      {
        "char": " ",
        "block": "minecraft:air"
      },
      {
        "char": "d",
        "block": "minecraft:cobbled_deepslate"
      },
      {
        "char": "c",
        "block": "minecraft:deepslate[axis=y]"
      },
      {
        "char": "b",
        "block": "minecraft:basalt[axis=x]"
      },
      {
        "char": "e",
        "block": "minecraft:cyan_terracotta"
      },
      {
        "char": "a",
        "block": "minecraft:blackstone"
      },
      {
        "char": "l",
        "block": "minecraft:yellow_concrete"
      },
      {
        "char": "n",
        "block": "minecraft:black_concrete"
      },
      {
        "char": "y",
        "block": "minecraft:quartz_slab[type=top,waterlogged=false]"
      },
      {
        "char": "s",
        "block": "minecraft:quartz_slab[type=bottom,waterlogged=false]"
      },
      {
        "char": "o",
        "block": "minecraft:black_stained_glass"
      },
      {
        "char": "泛",
        "block": "minecraft:quartz_stairs[facing=south,half=bottom,shape=outer_right,waterlogged=false]"
      },
      {
        "char": "邻",
        "block": "minecraft:quartz_stairs[facing=south,half=bottom,shape=outer_left,waterlogged=false]"
      },
      {
        "char": "z",
        "block": "minecraft:quartz_stairs[facing=west,half=bottom,shape=straight,waterlogged=false]"
      },
      {
        "char": "C",
        "block": "minecraft:quartz_stairs[facing=east,half=bottom,shape=straight,waterlogged=false]"
      },
      {
        "char": "Q",
        "block": "minecraft:quartz_slab[type=double,waterlogged=false]"
      },
      {
        "char": "振",
        "block": "minecraft:smooth_quartz_slab[type=bottom,waterlogged=false]"
      },
      {
        "char": "秘",
        "block": "minecraft:furnace[facing=south,lit=false]",
        "tag": {
          "z": 983,
          "x": -458,
          "CookTimeTotal": 0,
          "ForgeData": {
            "LockFlag": "1b"
          },
          "CookTime": 0,
          "ForgeCaps": {
            "polymorph:block_entity_recipe_data": {}
          },
          "id": "minecraft:furnace",
          "y": 130,
          "Items": [],
          "BurnTime": 0,
          "RecipesUsed": {}
        }
      },
      {
        "char": "w",
        "block": "minecraft:quartz_stairs[facing=south,half=bottom,shape=straight,waterlogged=false]"
      },
      {
        "char": "ϓ",
        "block": "minecraft:quartz_stairs[facing=north,half=top,shape=straight,waterlogged=false]"
      }
    ]
  },
  "slices": [
    [
      "dcbceaaabadeeecb",
      "ecedcbdbdbbcbdbd",
      "ccedadcccddabaad",
      "eadceecddcaeaadb",
      "ebdaecdaebbbeadc",
      "deeeeaddbdadbebd",
      "bedddbadcacbcdaa",
      "lllllecddcecccba",
      "eabcllllllllllca",
      "bebblcelabedalea",
      "bdcdleeldbbeblll",
      "bacalbeldaccbllb",
      "ebbelcdlababdlle",
      "eacaleblaaccbllc",
      "dacbleelbeacallb",
      "bbbcleelcdcecllc"
    ],
    [
      "                ",
      "                ",
      "                ",
      "                ",
      "                ",
      "                ",
      "                ",
      "                ",
      "                ",
      "n        n      ",
      "y        y      ",
      "y        y      ",
      " y      y y    n",
      "               y",
      "               y",
      " n      n n   y "
    ],
    [
      "                ",
      "                ",
      "                ",
      "                ",
      "                ",
      "                ",
      "                ",
      "                ",
      "s        s      ",
      "s        s      ",
      "o泛      邻o泛     ",
      "oz      Coz    s",
      "Qss    ssQss   s",
      "Q振sC  zs振Q振sC 邻o",
      "Q        Q    Co",
      "秘z      C秘z  ssQ"
    ],
    [
      "                ",
      "                ",
      "                ",
      "                ",
      "                ",
      "                ",
      "                ",
      "                ",
      "                ",
      "                ",
      "                ",
      "                ",
      "                ",
      "                ",
      "w        w      ",
      "ϓy      yϓy     "
    ],
    [
      "                ",
      "                ",
      "                ",
      "                ",
      "                ",
      "                ",
      "                ",
      "                ",
      "                ",
      "                ",
      "                ",
      "                ",
      "                ",
      "                ",
      "                ",
      "                "
    ],
    [
      "                ",
      "                ",
      "                ",
      "                ",
      "                ",
      "                ",
      "                ",
      "                ",
      "                ",
      "                ",
      "                ",
      "                ",
      "                ",
      "                ",
      "                ",
      "                "
    ]
  ]
}