{
  "xsize": 16,
  "zsize": 16,
  "palette": {
    "palette": [
      {
        "char": " ",
        "block": "minecraft:air"
      },
      {
        "char": "m",
        "block": "minecraft:water[level=8]"
      },
      {
        "char": "җ",
        "block": "minecraft:water[level=1]"
      },
      {
        "char": "诞",
        "block": "minecraft:smooth_stone_slab[type=top,waterlogged=true]"
      },
      {
        "char": "坏",
        "block": "minecraft:smooth_stone"
      },
      {
        "char": "卿",
        "block": "minecraft:chest[facing=east,type=single,waterlogged=false]",
        "loot": "bigbuildingsloot",
        "tag": {
          "z": 963,
          "x": -456,
          "ForgeData": {
            "LockFlag": "1b"
          },
          "ForgeCaps": {},
          "id": "minecraft:chest",
          "y": 107,
          "Items": []
        }
      },
      {
        "char": "尚",
        "block": "minecraft:birch_wall_sign[facing=east,waterlogged=false]",
        "tag": {
          "z": 945,
          "x": -465,
          "is_waxed": "0b",
          "ForgeCaps": {
            "supplementaries:antique_ink": {
              "ink": "0b"
            }
          },
          "id": "minecraft:sign",
          "y": 109,
          "front_text": {
            "color": "black",
            "has_glowing_text": "0b",
            "messages": [
              "{\"extra\":[{\"text\":\"Battery:\"}],\"text\":\"\"}",
              "{\"extra\":[{\"text\":\"Charlie\"}],\"text\":\"\"}",
              "{\"text\":\"\"}",
              "{\"text\":\"\"}"
            ]
          },
          "back_text": {
            "color": "black",
            "has_glowing_text": "0b",
            "messages": [
              "{\"text\":\"\"}",
              "{\"text\":\"\"}",
              "{\"text\":\"\"}",
              "{\"text\":\"\"}"
            ]
          }
        }
      },
      {
        "char": "ћ",
        "block": "minecraft:smooth_stone_slab[type=double,waterlogged=false]"
      },
      {
        "char": "碌",
        "block": "minecraft:mossy_stone_brick_stairs[facing=west,half=bottom,shape=straight,waterlogged=false]"
      },
      {
        "char": "敛",
        "block": "minecraft:glass_pane[east=true,north=false,south=true,waterlogged=false,west=false]"
      },
      {
        "char": "挽",
        "block": "minecraft:grindstone[face=floor,facing=north]"
      },
      {
        "char": "骤",
        "block": "minecraft:lever[face=floor,facing=east,powered=false]"
      },
      {
        "char": "坛",
        "block": "minecraft:redstone_wall_torch[facing=west,lit=true]"
      },
      {
        "char": "乡",
        "block": "minecraft:ladder[facing=north,waterlogged=false]"
      },
      {
        "char": "叩",
        "block": "minecraft:glass_pane[east=true,north=true,south=false,waterlogged=false,west=false]"
      },
      {
        "char": "矫",
        "block": "minecraft:glass_pane[east=false,north=false,south=true,waterlogged=false,west=false]"
      },
      {
        "char": "哄",
        "block": "minecraft:glass_pane[east=false,north=true,south=true,waterlogged=false,west=false]"
      },
      {
        "char": "聆",
        "block": "minecraft:glass_pane[east=false,north=true,south=false,waterlogged=false,west=false]"
      },
      {
        "char": "腿",
        "block": "minecraft:barrier"
      }
    ]
  },
  "slices": [
    [
      "      mmmmmmmmmm",
      "    mmmmmmmmmmmm",
      "   mmmmmmmmmmmmm",
      "    mmmmmmmmmmmm",
      "      mmmmmmmmmm",
      "                ",
      "                ",
      "                ",
      "                ",
      "                ",
      "                ",
      "                ",
      "                ",
      "                ",
      "                ",
      "                "
    ],
    [
      "      mmmmmmmmmm",
      "    mmmmmmmmmmmm",
      "   mmmmmmmmmmmmm",
      "    mmmmmmmmmmmm",
      "      mmmmmmmmmm",
      "                ",
      "                ",
      "                ",
      "                ",
      "                ",
      "                ",
      "                ",
      "                ",
      "                ",
      "                ",
      "                "
    ],
    [
      "      mҗҗҗҗҗҗҗҗҗ",
      "    җmm诞诞诞诞诞诞诞诞诞",
      "   җ诞诞җ诞诞诞诞诞诞诞诞诞",
      "    җmm诞诞诞诞诞诞诞诞诞",
      "      mҗҗҗҗҗҗҗҗҗ",
      "                ",
      "                ",
      "                ",
      "                ",
      "                ",
      "                ",
      "                ",
      "                ",
      "                ",
      "                ",
      "                "
    ],
    [
      "      җ  坏坏坏坏坏坏坏",
      "     җ诞坏坏坏卿尚    ",
      "     坏ћ坏坏坏      ",
      "     җ诞坏坏碌      ",
      "      җ  坏坏坏坏坏坏坏",
      "                ",
      "                ",
      "                ",
      "                ",
      "                ",
      "                ",
      "                ",
      "                ",
      "                ",
      "                ",
      "                "
    ],
    [
      "     敛坏坏坏坏坏坏坏坏坏坏",
      "     坏碌 挽坏      ",
      "     坏 骤坛坏      ",
      "     坏    乡  乡  ",
      "     叩坏坏坏坏坏坏坏坏坏坏",
      "                ",
      "                ",
      "                ",
      "                ",
      "                ",
      "                ",
      "                ",
      "                ",
      "                ",
      "                ",
      "                "
    ],
    [
      "         矫      ",
      "         哄      ",
      "         聆      ",
      "          乡  乡  ",
      "          腿  腿  ",
      "          腿  腿  ",
      "                ",
      "                ",
      "                ",
      "                ",
      "                ",
      "                ",
      "                ",
      "                ",
      "                ",
      "                "
    ]
  ]
}