{
  "xsize": 16,
  "zsize": 16,
  "palette": {
    "palette": [
      {
        "char": " ",
        "block": "minecraft:air"
      },
      {
        "char": "h",
        "block": "minecraft:red_terracotta"
      },
      {
        "char": "e",
        "block": "minecraft:cyan_terracotta"
      },
      {
        "char": "a",
        "block": "minecraft:blackstone"
      },
      {
        "char": "d",
        "block": "minecraft:cobbled_deepslate"
      },
      {
        "char": "c",
        "block": "minecraft:deepslate[axis=y]"
      },
      {
        "char": "b",
        "block": "minecraft:basalt[axis=x]"
      },
      {
        "char": "j",
        "block": "minecraft:black_carpet"
      },
      {
        "char": "p",
        "block": "minecraft:gray_carpet"
      },
      {
        "char": "罩",
        "block": "minecraft:water[level=2]"
      },
      {
        "char": "җ",
        "block": "minecraft:water[level=1]"
      },
      {
        "char": "m",
        "block": "minecraft:water[level=8]"
      },
      {
        "char": "瘟",
        "block": "minecraft:water[level=3]"
      },
      {
        "char": "抖",
        "block": "minecraft:water[level=4]"
      },
      {
        "char": "g",
        "block": "minecraft:redstone_lamp[lit=false]"
      },
      {
        "char": "扎",
        "block": "minecraft:acacia_door[facing=north,half=lower,hinge=left,open=false,powered=false]"
      },
      {
        "char": "浦",
        "block": "minecraft:acacia_door[facing=north,half=lower,hinge=right,open=false,powered=false]"
      },
      {
        "char": "雁",
        "block": "minecraft:water[level=5]"
      },
      {
        "char": "w",
        "block": "minecraft:quartz_stairs[facing=south,half=bottom,shape=straight,waterlogged=false]"
      },
      {
        "char": "湘",
        "block": "minecraft:water[level=6]"
      },
      {
        "char": "瑛",
        "block": "minecraft:water[level=7]"
      },
      {
        "char": "趁",
        "block": "minecraft:sticky_piston[extended=false,facing=south]"
      },
      {
        "char": "ϔ",
        "block": "minecraft:observer[facing=south,powered=false]"
      },
      {
        "char": "恶",
        "block": "minecraft:lever[face=wall,facing=south,powered=false]"
      },
      {
        "char": "驳",
        "block": "minecraft:acacia_door[facing=north,half=upper,hinge=left,open=false,powered=false]"
      },
      {
        "char": "裸",
        "block": "minecraft:acacia_door[facing=north,half=upper,hinge=right,open=false,powered=false]"
      },
      {
        "char": "H",
        "block": "minecraft:quartz_stairs[facing=south,half=top,shape=straight,waterlogged=false]"
      },
      {
        "char": "Җ",
        "block": "minecraft:observer[facing=west,powered=false]"
      },
      {
        "char": "O",
        "block": "minecraft:observer[facing=east,powered=false]"
      },
      {
        "char": "陷",
        "block": "minecraft:observer[facing=up,powered=false]"
      },
      {
        "char": "蟑",
        "block": "minecraft:redstone_wire[east=side,north=none,power=0,south=side,west=none]"
      },
      {
        "char": "黎",
        "block": "minecraft:redstone_wire[east=none,north=side,power=0,south=side,west=none]"
      },
      {
        "char": "霖",
        "block": "minecraft:redstone_block"
      },
      {
        "char": "首",
        "block": "minecraft:sticky_piston[extended=false,facing=north]"
      }
    ]
  },
  "slices": [
    [
      "                ",
      "                ",
      "                ",
      "                ",
      "                ",
      "                ",
      "                ",
      "                ",
      "                ",
      "hhhhhhhhhhhhhhhh",
      "    hh       hh ",
      "                ",
      "                ",
      "                ",
      "                ",
      "                "
    ],
    [
      "                ",
      "                ",
      "                ",
      "                ",
      "                ",
      "                ",
      "                ",
      "                ",
      "                ",
      "hhhhhhhhhhhhhhhh",
      "    hh       hh ",
      "                ",
      "                ",
      "                ",
      "                ",
      "                "
    ],
    [
      "eaaeaedccbdbdbbe",
      "cdaddadcdeeebada",
      "badddddeabdaccbb",
      "dedcceccaadeedce",
      "daddddaadcaabcca",
      "bbdbacbcdaaeeaca",
      "bcdddbadedeebaac",
      "bcedceeadccbaace",
      "cedeabddaeeeebad",
      "bcccdaecbbacbacc",
      "hhhhhhhhhhhhhhhh",
      "   hhhh         ",
      "   hhhh         ",
      "   hhhh         ",
      "   hhhh         ",
      "   hhhh         "
    ],
    [
      "bjjjjjjjjjceedab",
      "djjjjjjjjjpppppp",
      "djjjjjjjjjbddddb",
      "bjjjjjjjjjd罩җmmm",
      "djjjjjjjjje瘟罩җҗҗ",
      "ajjjjjjjjjb抖瘟罩罩罩",
      "cg扎扎扎浦浦扎扎ga雁抖瘟瘟瘟",
      "egwwwwwwwgd湘雁抖抖抖",
      "gggggggggge瑛湘雁雁雁",
      "aaddeecadacbdccb",
      "aaeadbcaabdeacbd",
      "hhhhhhhhhhhhhhhh",
      "  hh  h     hhh ",
      "  hh  h     h   ",
      "  hh趁 h     hhh ",
      "hhhh  hhhhhhhhhh"
    ],
    [
      "e         bbbccϔ",
      "a              恶",
      "a         ceabad",
      "b         d  mmm",
      "b         c     ",
      "b         d     ",
      "dg驳驳驳裸裸驳驳ge     ",
      "cgHHHHHHHgd     ",
      "caedeeabebedcdca",
      "                ",
      "degeedacgecaeced",
      "         ccad dh",
      "hhhhhhhhhhhhhhhh",
      " g h  g    ghghh",
      "hhϔҖ趁O陷hhhhh趁O陷h",
      " hϔh       bbb h"
    ],
    [
      "c         d   m ",
      "a         eaddcb",
      "c         a  mmm",
      "c         c  җmҗ",
      "c         b     ",
      "a         a     ",
      "cg       gc     ",
      "egwwwwwwwgc     ",
      "bceadaecebadbebc",
      "                ",
      "cagbeadageccaabe",
      "         ebed a蟑",
      "              c黎",
      "hhhhhhhhhhhhhhh ",
      " hhh  ϔ       ϔ霖",
      " hhh ϔҖ    ecd陷首"
    ]
  ]
}