{
  "xsize": 16,
  "zsize": 16,
  "palette": {
    "palette": [
      {
        "char": " ",
        "block": "minecraft:air"
      },
      {
        "char": "c",
        "block": "minecraft:deepslate[axis=y]"
      },
      {
        "char": "e",
        "block": "minecraft:cyan_terracotta"
      },
      {
        "char": "b",
        "block": "minecraft:basalt[axis=x]"
      },
      {
        "char": "d",
        "block": "minecraft:cobbled_deepslate"
      },
      {
        "char": "a",
        "block": "minecraft:blackstone"
      },
      {
        "char": "i",
        "block": "minecraft:white_concrete"
      },
      {
        "char": "f",
        "block": "minecraft:light_gray_concrete"
      },
      {
        "char": "l",
        "block": "minecraft:yellow_concrete"
      },
      {
        "char": "n",
        "block": "minecraft:black_concrete"
      }
    ]
  },
  "slices": [
    [
      "ccebcdcdcbdcadba",
      "bcdaecdebadcaecc",
      "eedaeacabaebadce",
      "ccdeaaadeadcbeda",
      "dbdccbbbdbaedaca",
      "iiiiiiiiiiiiiiii",
      "ceedeaabeaaaaebb",
      "eedcffffffffffff",
      "bbbf            ",
      "ceef            ",
      "becf            ",
      "beaf            ",
      "bebf            ",
      "dadf            ",
      "ccbf            ",
      "cccf            "
    ],
    [
      "                ",
      "                ",
      "                ",
      "                ",
      "                ",
      "                ",
      "                ",
      "                ",
      "  f             ",
      "  l             ",
      "  n             ",
      "  l             ",
      "  n             ",
      "  l             ",
      "  n             ",
      "  l             "
    ],
    [
      "                ",
      "                ",
      "                ",
      "                ",
      "                ",
      "                ",
      "                ",
      "                ",
      "  f             ",
      "  n             ",
      "  l             ",
      "  n             ",
      "  l             ",
      "  n             ",
      "  l             ",
      "  n             "
    ],
    [
      "                ",
      "                ",
      "                ",
      "                ",
      "                ",
      "                ",
      "                ",
      "                ",
      "  f             ",
      "  l             ",
      "  n             ",
      "  l             ",
      "  n             ",
      "  l             ",
      "  n             ",
      "  l             "
    ],
    [
      "                ",
      "                ",
      "                ",
      "                ",
      "                ",
      "                ",
      "                ",
      "                ",
      "                ",
      "  f             ",
      "  f             ",
      "  f             ",
      "  f             ",
      "  f             ",
      "  f             ",
      "  f             "
    ],
    [
      "                ",
      "                ",
      "                ",
      "                ",
      "                ",
      "                ",
      "                ",
      "                ",
      "                ",
      "                ",
      "                ",
      "                ",
      "                ",
      "                ",
      "                ",
      "                "
    ]
  ]
}