{
  "xsize": 16,
  "zsize": 16,
  "palette": {
    "palette": [
      {
        "char": " ",
        "block": "minecraft:air"
      },
      {
        "char": "c",
        "block": "minecraft:deepslate[axis=y]"
      },
      {
        "char": "a",
        "block": "minecraft:blackstone"
      },
      {
        "char": "e",
        "block": "minecraft:cyan_terracotta"
      },
      {
        "char": "l",
        "block": "minecraft:yellow_concrete"
      },
      {
        "char": "d",
        "block": "minecraft:cobbled_deepslate"
      },
      {
        "char": "b",
        "block": "minecraft:basalt[axis=x]"
      },
      {
        "char": "n",
        "block": "minecraft:black_concrete"
      },
      {
        "char": "f",
        "block": "minecraft:light_gray_concrete"
      },
      {
        "char": "q",
        "block": "minecraft:gold_block"
      },
      {
        "char": "y",
        "block": "minecraft:quartz_slab[type=top,waterlogged=false]"
      },
      {
        "char": "C",
        "block": "minecraft:quartz_stairs[facing=east,half=bottom,shape=straight,waterlogged=false]"
      },
      {
        "char": "z",
        "block": "minecraft:quartz_stairs[facing=west,half=bottom,shape=straight,waterlogged=false]"
      },
      {
        "char": "s",
        "block": "minecraft:quartz_slab[type=bottom,waterlogged=false]"
      },
      {
        "char": "振",
        "block": "minecraft:smooth_quartz_slab[type=bottom,waterlogged=false]"
      },
      {
        "char": "弥",
        "block": "minecraft:lever[face=wall,facing=west,powered=true]"
      },
      {
        "char": "g",
        "block": "minecraft:redstone_lamp[lit=false]"
      }
    ]
  },
  "slices": [
    [
      "                ",
      "                ",
      "                ",
      "                ",
      "                ",
      "                ",
      "                ",
      "                ",
      "                ",
      "                ",
      "                ",
      "            caea",
      "        eeeacldd",
      "      bddbacdlbe",
      "    baedbedaelec",
      "  ddbbaddadeblab"
    ],
    [
      "                ",
      "                ",
      "                ",
      "                ",
      "                ",
      "                ",
      "                ",
      "                ",
      "                ",
      "               b",
      "           dcedc",
      "       ddece   n",
      "     cde        ",
      "   cdaf         ",
      " abcqqcf       y",
      "aceecbef        "
    ],
    [
      "                ",
      "                ",
      "                ",
      "                ",
      "                ",
      "                ",
      "                ",
      "                ",
      "              aa",
      "          dacee ",
      "      aacdd     ",
      "    dad        C",
      "  daef          ",
      "abe   f      zs振",
      "cf  qq f      ss",
      "nfeaa  f       C"
    ],
    [
      "                ",
      "                ",
      "                ",
      "                ",
      "                ",
      "                ",
      "                ",
      "             bbd",
      "         cbebb  ",
      "     ccaeb      ",
      "   dee          ",
      " dbc           y",
      "ad fff          ",
      "  f   f         ",
      "nf  qq f        ",
      "nfdbd 弥f        "
    ],
    [
      "                ",
      "                ",
      "                ",
      "                ",
      "                ",
      "                ",
      "            ebbd",
      "        eeedeg  ",
      "    bdcdcg      ",
      "  ceag          ",
      "edbg            ",
      "a               ",
      "   fff          ",
      "  f   f         ",
      "    qq f        ",
      " fabc  f        "
    ],
    [
      "                ",
      "                ",
      "                ",
      "                ",
      "                ",
      "                ",
      "            adac",
      "        caad    ",
      "    addc        ",
      "  ce            ",
      "de              ",
      "                ",
      "   fff          ",
      "  f   f         ",
      "    qq f        ",
      " fbaa  f        "
    ]
  ]
}