{
  "xsize": 16,
  "zsize": 16,
  "palette": {
    "palette": [
      {
        "char": " ",
        "block": "minecraft:air"
      },
      {
        "char": "d",
        "block": "minecraft:cobbled_deepslate"
      },
      {
        "char": "b",
        "block": "minecraft:basalt[axis=x]"
      },
      {
        "char": "a",
        "block": "minecraft:blackstone"
      },
      {
        "char": "c",
        "block": "minecraft:deepslate[axis=y]"
      },
      {
        "char": "e",
        "block": "minecraft:cyan_terracotta"
      },
      {
        "char": "g",
        "block": "minecraft:redstone_lamp[lit=false]"
      },
      {
        "char": "f",
        "block": "minecraft:light_gray_concrete"
      },
      {
        "char": "n",
        "block": "minecraft:black_concrete"
      },
      {
        "char": "y",
        "block": "minecraft:quartz_slab[type=top,waterlogged=false]"
      },
      {
        "char": "C",
        "block": "minecraft:quartz_stairs[facing=east,half=bottom,shape=straight,waterlogged=false]"
      },
      {
        "char": "乏",
        "block": "minecraft:furnace[facing=north,lit=false]",
        "tag": {
          "z": 946,
          "x": -346,
          "CookTimeTotal": 0,
          "ForgeData": {
            "LockFlag": "1b"
          },
          "CookTime": 0,
          "ForgeCaps": {
            "polymorph:block_entity_recipe_data": {}
          },
          "id": "minecraft:furnace",
          "y": 120,
          "Items": [],
          "BurnTime": 0,
          "RecipesUsed": {}
        }
      },
      {
        "char": "z",
        "block": "minecraft:quartz_stairs[facing=west,half=bottom,shape=straight,waterlogged=false]"
      },
      {
        "char": "Q",
        "block": "minecraft:quartz_slab[type=double,waterlogged=false]"
      },
      {
        "char": "s",
        "block": "minecraft:quartz_slab[type=bottom,waterlogged=false]"
      },
      {
        "char": "振",
        "block": "minecraft:smooth_quartz_slab[type=bottom,waterlogged=false]"
      },
      {
        "char": "o",
        "block": "minecraft:black_stained_glass"
      },
      {
        "char": "赠",
        "block": "minecraft:quartz_stairs[facing=north,half=bottom,shape=outer_right,waterlogged=false]"
      },
      {
        "char": "歪",
        "block": "minecraft:quartz_stairs[facing=north,half=bottom,shape=outer_left,waterlogged=false]"
      },
      {
        "char": "H",
        "block": "minecraft:quartz_stairs[facing=south,half=top,shape=straight,waterlogged=false]"
      },
      {
        "char": "x",
        "block": "minecraft:quartz_stairs[facing=north,half=bottom,shape=straight,waterlogged=false]"
      }
    ]
  },
  "slices": [
    [
      "dbad            ",
      "cecbedbbca      ",
      "badababbaadadaac",
      "gdbedcabacbbacbc",
      "abbabccadcacacdc",
      "bacaddbeecaaaebe",
      "dccccbcdbddbddbe",
      "acbcadabcccbadae",
      "eeacceabgbaedbbd",
      "ecccccbdecedaceg",
      "bbcecdbcdbdaacad",
      "aebadeddbacdaedb",
      "dabcaacaacabbecb",
      "egggcaegggeeaggg",
      "baecbcaadbaedbdb",
      "ababeaeecedaecda"
    ],
    [
      "fff ecadebe     ",
      "ff        baebcb",
      "f      n n      ",
      "              n ",
      "                ",
      "       y y      ",
      "        y     y ",
      "        y      y",
      "        n      y",
      "               n",
      "                ",
      "                ",
      "                ",
      "                ",
      "                ",
      "                "
    ],
    [
      "  f        cbcde",
      " f              ",
      "f      C乏z      ",
      "        Q     C乏",
      "     zs振Q振sC   Q",
      "      ssQss zs振Q",
      "       Coz   ssQ",
      "       赠o歪    Co",
      "        s     赠o",
      "        s      s",
      "               s",
      "                ",
      "                ",
      "                ",
      "                ",
      "                "
    ],
    [
      "  f             ",
      " f              ",
      "f      yHy      ",
      "        x     yH",
      "               x",
      "                ",
      "                ",
      "                ",
      "                ",
      "                ",
      "                ",
      "                ",
      "                ",
      "                ",
      "                ",
      "                "
    ],
    [
      "  f             ",
      " f              ",
      "f               ",
      "                ",
      "                ",
      "                ",
      "                ",
      "                ",
      "                ",
      "                ",
      "                ",
      "                ",
      "                ",
      "                ",
      "                ",
      "                "
    ],
    [
      "  f             ",
      " f              ",
      "f               ",
      "                ",
      "                ",
      "                ",
      "                ",
      "                ",
      "                ",
      "                ",
      "                ",
      "                ",
      "                ",
      "                ",
      "                ",
      "                "
    ]
  ]
}