{
  "xsize": 16,
  "zsize": 16,
  "palette": {
    "palette": [
      {
        "char": " ",
        "block": "minecraft:air"
      },
      {
        "char": "b",
        "block": "minecraft:basalt[axis=x]"
      },
      {
        "char": "e",
        "block": "minecraft:cyan_terracotta"
      },
      {
        "char": "c",
        "block": "minecraft:deepslate[axis=y]"
      },
      {
        "char": "a",
        "block": "minecraft:blackstone"
      },
      {
        "char": "d",
        "block": "minecraft:cobbled_deepslate"
      },
      {
        "char": "l",
        "block": "minecraft:yellow_concrete"
      },
      {
        "char": "n",
        "block": "minecraft:black_concrete"
      },
      {
        "char": "y",
        "block": "minecraft:quartz_slab[type=top,waterlogged=false]"
      },
      {
        "char": "C",
        "block": "minecraft:quartz_stairs[facing=east,half=bottom,shape=straight,waterlogged=false]"
      },
      {
        "char": "乏",
        "block": "minecraft:furnace[facing=north,lit=false]",
        "tag": {
          "z": 946,
          "x": -346,
          "CookTimeTotal": 0,
          "ForgeData": {
            "LockFlag": "1b"
          },
          "CookTime": 0,
          "ForgeCaps": {
            "polymorph:block_entity_recipe_data": {}
          },
          "id": "minecraft:furnace",
          "y": 120,
          "Items": [],
          "BurnTime": 0,
          "RecipesUsed": {}
        }
      },
      {
        "char": "z",
        "block": "minecraft:quartz_stairs[facing=west,half=bottom,shape=straight,waterlogged=false]"
      },
      {
        "char": "Q",
        "block": "minecraft:quartz_slab[type=double,waterlogged=false]"
      },
      {
        "char": "s",
        "block": "minecraft:quartz_slab[type=bottom,waterlogged=false]"
      },
      {
        "char": "振",
        "block": "minecraft:smooth_quartz_slab[type=bottom,waterlogged=false]"
      },
      {
        "char": "o",
        "block": "minecraft:black_stained_glass"
      },
      {
        "char": "赠",
        "block": "minecraft:quartz_stairs[facing=north,half=bottom,shape=outer_right,waterlogged=false]"
      },
      {
        "char": "歪",
        "block": "minecraft:quartz_stairs[facing=north,half=bottom,shape=outer_left,waterlogged=false]"
      },
      {
        "char": "H",
        "block": "minecraft:quartz_stairs[facing=south,half=top,shape=straight,waterlogged=false]"
      },
      {
        "char": "x",
        "block": "minecraft:quartz_stairs[facing=north,half=bottom,shape=straight,waterlogged=false]"
      },
      {
        "char": "g",
        "block": "minecraft:redstone_lamp[lit=false]"
      }
    ]
  },
  "slices": [
    [
      "                ",
      "                ",
      "                ",
      "                ",
      "              be",
      "        ceceeebc",
      "  acaceadedcdeee",
      "dbcabbdcbbleadae",
      "acaelebbbalcccda",
      "dablleddeclebccb",
      "bbcllaebdeledabc",
      "bcallabbcalbecee",
      "bdcllebcbdleebbd",
      "cbbllbeccblabbad",
      "aabllcaaddldedbc",
      "eeclldebecllllll"
    ],
    [
      "                ",
      "                ",
      "                ",
      "             acd",
      "       adcbaca  ",
      " abdaaaa        ",
      "bb          n n ",
      "      n n       ",
      " n              ",
      "            y y ",
      "      y y    y  ",
      " y     y     y  ",
      "y      y     n  ",
      "y      n        ",
      "n               ",
      "                "
    ],
    [
      "                ",
      "                ",
      "            eadd",
      "      addaeec   ",
      "deeadcc         ",
      "c               ",
      "            C乏z ",
      "      C乏z    Q  ",
      "乏z     Q  zs振Q振s",
      "Q   zs振Q振s ssQss",
      "Q振sC ssQss  Coz ",
      "Qss   Coz   赠o歪 ",
      "oz    赠o歪    s  ",
      "o歪     s     s  ",
      "s      s        ",
      "s               "
    ],
    [
      "                ",
      "           baabb",
      "     decdade    ",
      "aebdba          ",
      "                ",
      "                ",
      "            yHy ",
      "      yHy    x  ",
      "Hy     x        ",
      "x               ",
      "                ",
      "                ",
      "                ",
      "                ",
      "                ",
      "                "
    ],
    [
      "          bcccae",
      "    eebaeacg    ",
      "aeebbg          ",
      "                ",
      "                ",
      "                ",
      "                ",
      "                ",
      "                ",
      "                ",
      "                ",
      "                ",
      "                ",
      "                ",
      "                ",
      "                "
    ],
    [
      "          bebcad",
      "    caeaea      ",
      "edad            ",
      "                ",
      "                ",
      "                ",
      "                ",
      "                ",
      "                ",
      "                ",
      "                ",
      "                ",
      "                ",
      "                ",
      "                ",
      "                "
    ]
  ]
}