{
  "xsize": 16,
  "zsize": 16,
  "palette": {
    "palette": [
      {
        "char": " ",
        "block": "minecraft:air"
      },
      {
        "char": "a",
        "block": "minecraft:blackstone"
      },
      {
        "char": "d",
        "block": "minecraft:cobbled_deepslate"
      },
      {
        "char": "b",
        "block": "minecraft:basalt[axis=x]"
      },
      {
        "char": "c",
        "block": "minecraft:deepslate[axis=y]"
      },
      {
        "char": "f",
        "block": "minecraft:light_gray_concrete"
      },
      {
        "char": "e",
        "block": "minecraft:cyan_terracotta"
      },
      {
        "char": "C",
        "block": "minecraft:quartz_stairs[facing=east,half=bottom,shape=straight,waterlogged=false]"
      },
      {
        "char": "g",
        "block": "minecraft:redstone_lamp[lit=false]"
      },
      {
        "char": "淆",
        "block": "minecraft:redstone_wire[east=side,north=side,power=15,south=side,west=side]"
      },
      {
        "char": "蟑",
        "block": "minecraft:redstone_wire[east=side,north=none,power=0,south=side,west=none]"
      },
      {
        "char": "椅",
        "block": "minecraft:sticky_piston[extended=true,facing=south]"
      },
      {
        "char": "O",
        "block": "minecraft:observer[facing=east,powered=false]"
      },
      {
        "char": "黎",
        "block": "minecraft:redstone_wire[east=none,north=side,power=0,south=side,west=none]"
      },
      {
        "char": "o",
        "block": "minecraft:black_stained_glass"
      },
      {
        "char": "z",
        "block": "minecraft:quartz_stairs[facing=west,half=bottom,shape=straight,waterlogged=false]"
      }
    ]
  },
  "slices": [
    [
      "                ",
      "                ",
      "                ",
      "                ",
      "                ",
      "                ",
      "                ",
      "                ",
      "                ",
      "                ",
      "              a ",
      "       adbdcbfdb",
      "     cede       ",
      "   fa Cbae      ",
      "   dg   dba淆  蟑 ",
      "    e    cb椅Og黎 "
    ],
    [
      "                ",
      "                ",
      "                ",
      "                ",
      "                ",
      "                ",
      "                ",
      "                ",
      "                ",
      "                ",
      "              b ",
      "       daacadfea",
      "     aecacd     ",
      "   fc  Cacb     ",
      "   ba   dab     ",
      "    e   cbc     "
    ],
    [
      "                ",
      "                ",
      "                ",
      "                ",
      "                ",
      "                ",
      "                ",
      "              de",
      "            dcac",
      "    ecccadaedebb",
      "   aeeecadbbcebe",
      "  eaceabcdcbdabb",
      " dbbedccbcaacdcd",
      " cdc    Caadadea",
      " bda   eabedecbc",
      " cae    ccbebbab"
    ],
    [
      "                ",
      "                ",
      "                ",
      "                ",
      "                ",
      "                ",
      "              oo",
      "            oo  ",
      "    oooooooo    ",
      "   o           b",
      "  o          eed",
      " o   bdea  dba  ",
      "o   e           ",
      "o  c            ",
      "o  e            ",
      "o  e   cz       "
    ],
    [
      "                ",
      "                ",
      "                ",
      "                ",
      "                ",
      "                ",
      "                ",
      "                ",
      "                ",
      "               e",
      "             dde",
      "     bdea  ceb  ",
      "    a           ",
      "   e            ",
      "   a  a         ",
      "   c  az        "
    ],
    [
      "                ",
      "                ",
      "                ",
      "                ",
      "                ",
      "                ",
      "                ",
      "                ",
      "                ",
      "               a",
      "             aeb",
      "     bcba  eaa  ",
      "    e           ",
      "   cdaba        ",
      "   abbb         ",
      "   edaz         "
    ]
  ]
}