{
  "xsize": 16,
  "zsize": 16,
  "palette": {
    "palette": [
      {
        "char": " ",
        "block": "minecraft:air"
      },
      {
        "char": "m",
        "block": "minecraft:water[level=8]"
      },
      {
        "char": "җ",
        "block": "minecraft:water[level=1]"
      },
      {
        "char": "n",
        "block": "minecraft:black_concrete"
      },
      {
        "char": "佬",
        "block": "minecraft:quartz_slab[type=top,waterlogged=true]"
      },
      {
        "char": "罩",
        "block": "minecraft:water[level=2]"
      },
      {
        "char": "捏",
        "block": "minecraft:quartz_stairs[facing=north,half=bottom,shape=straight,waterlogged=true]"
      },
      {
        "char": "矢",
        "block": "minecraft:quartz_slab[type=bottom,waterlogged=true]"
      },
      {
        "char": "s",
        "block": "minecraft:quartz_slab[type=bottom,waterlogged=false]"
      },
      {
        "char": "庚",
        "block": "minecraft:quartz_stairs[facing=south,half=bottom,shape=straight,waterlogged=true]"
      },
      {
        "char": "翟",
        "block": "minecraft:smooth_quartz_slab[type=bottom,waterlogged=true]"
      },
      {
        "char": "w",
        "block": "minecraft:quartz_stairs[facing=south,half=bottom,shape=straight,waterlogged=false]"
      },
      {
        "char": "谜",
        "block": "minecraft:quartz_stairs[facing=west,half=bottom,shape=outer_left,waterlogged=false]"
      },
      {
        "char": "驻",
        "block": "minecraft:furnace[facing=west,lit=false]",
        "tag": {
          "z": 953,
          "x": -551,
          "CookTimeTotal": 0,
          "ForgeData": {
            "LockFlag": "1b"
          },
          "CookTime": 0,
          "ForgeCaps": {
            "polymorph:block_entity_recipe_data": {}
          },
          "id": "minecraft:furnace",
          "y": 120,
          "Items": [],
          "BurnTime": 0,
          "RecipesUsed": {}
        }
      },
      {
        "char": "Q",
        "block": "minecraft:quartz_slab[type=double,waterlogged=false]"
      },
      {
        "char": "o",
        "block": "minecraft:black_stained_glass"
      },
      {
        "char": "振",
        "block": "minecraft:smooth_quartz_slab[type=bottom,waterlogged=false]"
      },
      {
        "char": "x",
        "block": "minecraft:quartz_stairs[facing=north,half=bottom,shape=straight,waterlogged=false]"
      },
      {
        "char": "仿",
        "block": "minecraft:quartz_stairs[facing=west,half=bottom,shape=outer_right,waterlogged=false]"
      }
    ]
  },
  "slices": [
    [
      "                ",
      "                ",
      "       m m      ",
      "      mm mmm    ",
      "     m mmmmmmm  ",
      "     m  mmmm  m ",
      "     m mmmmmmm  ",
      "      mm mmm    ",
      "       m m      ",
      "                ",
      "                ",
      "                ",
      "                ",
      "                ",
      "                ",
      "                "
    ],
    [
      "                ",
      "                ",
      "       m m      ",
      "      mm mmm    ",
      "     m mmmmmmm  ",
      "     m  mmmm  m ",
      "     m mmmmmmm  ",
      "      mm mmm    ",
      "       m m      ",
      "                ",
      "                ",
      "                ",
      "                ",
      "                ",
      "                ",
      "                "
    ],
    [
      "                ",
      "                ",
      "       m m      ",
      "      mm mmm    ",
      "     m mmmmmmm  ",
      "     m  mmmm  m ",
      "     m mmmmmmm  ",
      "      mm mmm    ",
      "       m m      ",
      "                ",
      "                ",
      "                ",
      "                ",
      "                ",
      "                ",
      "                "
    ],
    [
      "                ",
      "                ",
      "       m m      ",
      "      mm mmm    ",
      "     m mmmmmmm  ",
      "     m  mmmm  m ",
      "     m mmmmmmm  ",
      "      mm mmm    ",
      "       m m      ",
      "                ",
      "                ",
      "                ",
      "                ",
      "                ",
      "                ",
      "                "
    ],
    [
      "                ",
      "                ",
      "       m m      ",
      "      mm җmm    ",
      "     mnmҗ佬җҗmm  ",
      "     m  罩җ佬佬n m ",
      "     mnmҗ佬җҗmm  ",
      "      mm җmm    ",
      "       m m      ",
      "                ",
      "                ",
      "                ",
      "                ",
      "                ",
      "                ",
      "                "
    ],
    [
      "                ",
      "                ",
      "       җ捏җ      ",
      "      mҗ矢smm    ",
      "     m庚m翟sw谜mҗ  ",
      "     m驻QQQoos矢җ ",
      "     m捏m振sx仿mҗ  ",
      "      mҗ矢矢mm    ",
      "       җ庚җ      ",
      "                ",
      "                ",
      "                ",
      "                ",
      "                ",
      "                ",
      "                "
    ]
  ]
}