{
  "xsize": 16,
  "zsize": 16,
  "palette": {
    "palette": [
      {
        "char": " ",
        "block": "minecraft:air"
      },
      {
        "char": "e",
        "block": "minecraft:cyan_terracotta"
      },
      {
        "char": "c",
        "block": "minecraft:deepslate[axis=y]"
      },
      {
        "char": "d",
        "block": "minecraft:cobbled_deepslate"
      },
      {
        "char": "a",
        "block": "minecraft:blackstone"
      },
      {
        "char": "b",
        "block": "minecraft:basalt[axis=x]"
      },
      {
        "char": "n",
        "block": "minecraft:black_concrete"
      },
      {
        "char": "g",
        "block": "minecraft:redstone_lamp[lit=false]"
      },
      {
        "char": "f",
        "block": "minecraft:light_gray_concrete"
      },
      {
        "char": "C",
        "block": "minecraft:quartz_stairs[facing=east,half=bottom,shape=straight,waterlogged=false]"
      },
      {
        "char": "x",
        "block": "minecraft:quartz_stairs[facing=north,half=bottom,shape=straight,waterlogged=false]"
      },
      {
        "char": "q",
        "block": "minecraft:gold_block"
      },
      {
        "char": "豆",
        "block": "minecraft:air"
      },
      {
        "char": "喘",
        "block": "minecraft:air"
      },
      {
        "char": "奉",
        "block": "minecraft:lever[face=wall,facing=east,powered=true]"
      },
      {
        "char": "y",
        "block": "minecraft:quartz_slab[type=top,waterlogged=false]"
      }
    ]
  },
  "slices": [
    [
      "          ecccdd",
      "   cccdeaabcaace",
      "acccaacabbdcaaad",
      "ccbdcbeeedbdbbee",
      "bcddeadeaacadebc",
      "aeccdeabbbbaeeea",
      "eedennnnnnnnnnnn",
      "aben            ",
      "dcdn            ",
      "ccen            ",
      "bden            ",
      "ecbn            ",
      "acan            ",
      "aggn            ",
      "bbdn            ",
      "edan            "
    ],
    [
      "  cbabeabbf    C",
      "beexfaacdef     ",
      "    faqq  f     ",
      "     f   f      ",
      "      fff       ",
      "                ",
      "   n            ",
      "                ",
      "                ",
      "                ",
      "                ",
      "                ",
      "                ",
      "                ",
      "                ",
      "                "
    ],
    [
      "bc  豆     f     ",
      "    f  ebcf     ",
      "    f qq        ",
      "     f   f      ",
      "      fff       ",
      "                ",
      "   n            ",
      "                ",
      "                ",
      "                ",
      "                ",
      "                ",
      "                ",
      "                ",
      "                ",
      "                "
    ],
    [
      "    喘     f     ",
      "    f奉 aaef     ",
      "    f qq        ",
      "     f   f      ",
      "      fff       ",
      "                ",
      "   n            ",
      "                ",
      "                ",
      "                ",
      "                ",
      "                ",
      "                ",
      "                ",
      "                ",
      "                "
    ],
    [
      "    f     f     ",
      "    f  b  f     ",
      "    f qq        ",
      "     f   f      ",
      "      fff       ",
      "                ",
      "   n            ",
      "                ",
      "                ",
      "                ",
      "                ",
      "                ",
      "                ",
      "                ",
      "                ",
      "                "
    ],
    [
      "    f     f     ",
      "    f  d  f     ",
      "    f qq  f     ",
      "     f   f      ",
      "      fff       ",
      "                ",
      "  gn            ",
      "  yg            ",
      "                ",
      "                ",
      "                ",
      "                ",
      "                ",
      "                ",
      "                ",
      "                "
    ]
  ]
}