{
  "xsize": 16,
  "zsize": 16,
  "palette": {
    "palette": [
      {
        "char": " ",
        "block": "minecraft:air"
      },
      {
        "char": "b",
        "block": "minecraft:basalt[axis=x]"
      },
      {
        "char": "d",
        "block": "minecraft:cobbled_deepslate"
      },
      {
        "char": "f",
        "block": "minecraft:light_gray_concrete"
      },
      {
        "char": "a",
        "block": "minecraft:blackstone"
      },
      {
        "char": "c",
        "block": "minecraft:deepslate[axis=y]"
      },
      {
        "char": "e",
        "block": "minecraft:cyan_terracotta"
      },
      {
        "char": "P",
        "block": "minecraft:dark_oak_trapdoor[facing=north,half=bottom,open=true,powered=false,waterlogged=false]"
      },
      {
        "char": "g",
        "block": "minecraft:redstone_lamp[lit=false]"
      },
      {
        "char": "ϖ",
        "block": "minecraft:cauldron"
      },
      {
        "char": "苗",
        "block": "minecraft:dark_oak_door[facing=west,half=lower,hinge=right,open=false,powered=false]"
      },
      {
        "char": "w",
        "block": "minecraft:quartz_stairs[facing=south,half=bottom,shape=straight,waterlogged=false]"
      },
      {
        "char": "缠",
        "block": "minecraft:dark_oak_door[facing=north,half=lower,hinge=left,open=false,powered=false]"
      },
      {
        "char": "渴",
        "block": "minecraft:dark_oak_door[facing=north,half=lower,hinge=right,open=false,powered=false]"
      },
      {
        "char": "嫁",
        "block": "minecraft:dark_oak_trapdoor[facing=east,half=bottom,open=false,powered=false,waterlogged=false]"
      },
      {
        "char": "汗",
        "block": "minecraft:dark_oak_door[facing=west,half=upper,hinge=right,open=false,powered=false]"
      },
      {
        "char": "叉",
        "block": "minecraft:dark_oak_door[facing=north,half=upper,hinge=left,open=false,powered=false]"
      },
      {
        "char": "琳",
        "block": "minecraft:dark_oak_door[facing=north,half=upper,hinge=right,open=false,powered=false]"
      },
      {
        "char": "ϑ",
        "block": "minecraft:birch_wall_sign[facing=south,waterlogged=false]",
        "tag": {
          "z": 953,
          "x": -527,
          "is_waxed": "0b",
          "ForgeCaps": {
            "supplementaries:antique_ink": {
              "ink": "0b"
            }
          },
          "id": "minecraft:sign",
          "y": 112,
          "front_text": {
            "color": "black",
            "has_glowing_text": "0b",
            "messages": [
              "{\"extra\":[{\"text\":\"Workshop\"}],\"text\":\"\"}",
              "{\"text\":\"\"}",
              "{\"text\":\"\"}",
              "{\"text\":\"\"}"
            ]
          },
          "back_text": {
            "color": "black",
            "has_glowing_text": "0b",
            "messages": [
              "{\"text\":\"\"}",
              "{\"text\":\"\"}",
              "{\"text\":\"\"}",
              "{\"text\":\"\"}"
            ]
          }
        }
      },
      {
        "char": "吉",
        "block": "minecraft:dark_oak_trapdoor[facing=west,half=bottom,open=true,powered=false,waterlogged=false]"
      }
    ]
  },
  "slices": [
    [
      "          bdb   ",
      "   f    bda     ",
      "ffff  cbb       ",
      "  ffebe         ",
      "  acc           ",
      "cdb             ",
      "c               ",
      "                ",
      "                ",
      "                ",
      "                ",
      "                ",
      "                ",
      "                ",
      "                ",
      "                "
    ],
    [
      "   f       f aae",
      "PPPf      gbca  ",
      "ffff    gaadc   ",
      "  ff  gaea      ",
      "  ff bdb        ",
      "  fecb          ",
      " ebc            ",
      "cd              ",
      "                ",
      "                ",
      "                ",
      "                ",
      "                ",
      "                ",
      "                ",
      "                "
    ],
    [
      "dcbeadacccbedebd",
      "daeacddbaadeceda",
      "eebcbbddabebbdb ",
      "edbaebbacdcddd  ",
      "acacabcdadb     ",
      "cecaaebbb       ",
      "acbedba         ",
      "bcbdb           ",
      "bbe             ",
      "b               ",
      "                ",
      "                ",
      "                ",
      "                ",
      "                ",
      "                "
    ],
    [
      "ϖ苗   f          ",
      "gf   fwww       ",
      "fff缠渴fbdb      a",
      "             ece",
      "           eba  ",
      "     f   dae    ",
      "     f edb      ",
      "     caa        ",
      "   dce          ",
      " eca            ",
      "ba              ",
      "                ",
      "                ",
      "                ",
      "                ",
      "                "
    ],
    [
      "嫁汗   f          ",
      "gf   f          ",
      "fff叉琳fwww      e",
      "  ϑ          ede",
      "           dec  ",
      "     f   dda    ",
      "     f cdc      ",
      "     bbe        ",
      "   bde          ",
      " cdd            ",
      "eb              ",
      "                ",
      "                ",
      "                ",
      "                ",
      "                "
    ],
    [
      " 吉   f          ",
      "gf   f          ",
      "fffggf          ",
      "     fwww    adg",
      "     faea   aeda",
      "     fccaabgdae ",
      "     fg   ebb   ",
      "        bed     ",
      "     gaac       ",
      "   gcaa         ",
      " gadd           ",
      "ace             ",
      "e               ",
      "                ",
      "                ",
      "                "
    ]
  ]
}