{
  "xsize": 16,
  "zsize": 16,
  "palette": {
    "palette": [
      {
        "char": " ",
        "block": "minecraft:air"
      },
      {
        "char": "a",
        "block": "minecraft:blackstone"
      },
      {
        "char": "b",
        "block": "minecraft:basalt[axis=x]"
      },
      {
        "char": "手",
        "block": "minecraft:observer[facing=down,powered=false]"
      },
      {
        "char": "o",
        "block": "minecraft:black_stained_glass"
      },
      {
        "char": "d",
        "block": "minecraft:cobbled_deepslate"
      },
      {
        "char": "c",
        "block": "minecraft:deepslate[axis=y]"
      },
      {
        "char": "e",
        "block": "minecraft:cyan_terracotta"
      },
      {
        "char": "g",
        "block": "minecraft:redstone_lamp[lit=false]"
      },
      {
        "char": "i",
        "block": "minecraft:white_concrete"
      },
      {
        "char": "Җ",
        "block": "minecraft:observer[facing=west,powered=false]"
      },
      {
        "char": "捧",
        "block": "minecraft:dispenser[facing=up,triggered=false]",
        "tag": {
          "z": 938,
          "x": -457,
          "ForgeData": {
            "LockFlag": "1b"
          },
          "ForgeCaps": {},
          "id": "minecraft:dispenser",
          "y": 111,
          "Items": []
        }
      },
      {
        "char": "n",
        "block": "minecraft:black_concrete"
      },
      {
        "char": "ϔ",
        "block": "minecraft:observer[facing=south,powered=false]"
      },
      {
        "char": "O",
        "block": "minecraft:observer[facing=east,powered=false]"
      }
    ]
  },
  "slices": [
    [
      "                ",
      "                ",
      "ab              ",
      " 手a            o",
      "  da          o ",
      "   cc        o  ",
      "    aedcbbbcd   ",
      "                ",
      "                ",
      "                ",
      "                ",
      "                ",
      "                ",
      "                ",
      "                ",
      "                "
    ],
    [
      "                ",
      "                ",
      "dc              ",
      " 手c            o",
      "  ea          o ",
      "   da        o  ",
      "    cedebdadd   ",
      "                ",
      "                ",
      "                ",
      "                ",
      "                ",
      "                ",
      "                ",
      "                ",
      "                "
    ],
    [
      "                ",
      "                ",
      "o               ",
      " 手             o",
      "  o           o ",
      "   o         o  ",
      "    ooooooooo   ",
      "                ",
      "                ",
      "                ",
      "                ",
      "                ",
      "                ",
      "                ",
      "                ",
      "                "
    ],
    [
      "                ",
      "g               ",
      "ebg            g",
      " 手e           gd",
      "  ed         ga ",
      "   cc       gb  ",
      "    dddcdacee   ",
      "                ",
      "                ",
      "                ",
      "                ",
      "                ",
      "                ",
      "                ",
      "                ",
      "                "
    ],
    [
      "cccbdecaggabdceb",
      " bacebddcdcabdde",
      "cccabdeaacceebdd",
      "i手abcebccbdaedab",
      " ieeadecadacacbb",
      "  ieecaaabdaceei",
      "   iddbbeaeeadi ",
      "                ",
      "                ",
      "                ",
      "                ",
      "                ",
      "                ",
      "                ",
      "                ",
      "                "
    ],
    [
      "Җ捧iniii     iic ",
      "Җ捧inniii   i ed ",
      "ϔ捧ini iiiiii    ",
      "O手 iiiibbc      ",
      "    e           ",
      "                ",
      "                ",
      "                ",
      "                ",
      "                ",
      "                ",
      "                ",
      "                ",
      "                ",
      "                ",
      "                "
    ]
  ]
}