{
  "xsize": 16,
  "zsize": 16,
  "palette": {
    "palette": [
      {
        "char": " ",
        "block": "minecraft:air"
      },
      {
        "char": "c",
        "block": "minecraft:deepslate[axis=y]"
      },
      {
        "char": "b",
        "block": "minecraft:basalt[axis=x]"
      },
      {
        "char": "a",
        "block": "minecraft:blackstone"
      },
      {
        "char": "d",
        "block": "minecraft:cobbled_deepslate"
      },
      {
        "char": "e",
        "block": "minecraft:cyan_terracotta"
      },
      {
        "char": "v",
        "block": "minecraft:smooth_quartz"
      },
      {
        "char": "栏",
        "block": "minecraft:light_gray_bed[facing=south,occupied=false,part=foot]",
        "tag": {
          "z": 960,
          "x": -393,
          "ForgeCaps": {},
          "id": "minecraft:bed",
          "y": 107
        }
      },
      {
        "char": "酸",
        "block": "minecraft:light_gray_bed[facing=south,occupied=false,part=head]",
        "tag": {
          "z": 963,
          "x": -405,
          "ForgeCaps": {},
          "id": "minecraft:bed",
          "y": 107
        }
      },
      {
        "char": "H",
        "block": "minecraft:quartz_stairs[facing=south,half=top,shape=straight,waterlogged=false]"
      },
      {
        "char": "胎",
        "block": "minecraft:chest[facing=north,type=single,waterlogged=false]",
        "loot": "bigbuildingsloot",
        "tag": {
          "z": 945,
          "x": -480,
          "ForgeData": {
            "LockFlag": "1b"
          },
          "ForgeCaps": {},
          "id": "minecraft:chest",
          "y": 112,
          "Items": []
        }
      },
      {
        "char": "g",
        "block": "minecraft:redstone_lamp[lit=false]"
      },
      {
        "char": "f",
        "block": "minecraft:light_gray_concrete"
      },
      {
        "char": "晨",
        "block": "minecraft:chest[facing=south,type=single,waterlogged=false]",
        "loot": "bigbuildingsloot",
        "tag": {
          "z": 947,
          "x": -390,
          "ForgeData": {
            "LockFlag": "1b"
          },
          "ForgeCaps": {},
          "id": "minecraft:chest",
          "y": 108,
          "Items": []
        }
      },
      {
        "char": "J",
        "block": "minecraft:quartz_stairs[facing=east,half=top,shape=straight,waterlogged=false]"
      },
      {
        "char": "K",
        "block": "minecraft:quartz_stairs[facing=west,half=top,shape=straight,waterlogged=false]"
      },
      {
        "char": "芝",
        "block": "minecraft:air"
      },
      {
        "char": "坎",
        "block": "minecraft:iron_door[facing=north,half=lower,hinge=right,open=false,powered=false]"
      },
      {
        "char": "谁",
        "block": "minecraft:chest[facing=north,type=left,waterlogged=false]",
        "loot": "bigbuildingsloot",
        "tag": {
          "z": 977,
          "x": -486,
          "ForgeData": {
            "LockFlag": "1b"
          },
          "ForgeCaps": {},
          "id": "minecraft:chest",
          "y": 115,
          "Items": []
        }
      },
      {
        "char": "活",
        "block": "minecraft:chest[facing=north,type=right,waterlogged=false]",
        "loot": "bigbuildingsloot",
        "tag": {
          "z": 958,
          "x": -361,
          "ForgeData": {
            "LockFlag": "1b"
          },
          "ForgeCaps": {},
          "id": "minecraft:chest",
          "y": 111,
          "Items": []
        }
      }
    ]
  },
  "slices": [
    [
      "cbadaebabdceecea",
      "acacdcdabdbbceae",
      "cedaccbbdcaecbbc",
      "ceabeedbaacdbcad",
      "dabebabbdbdebadd",
      "edeaacbaae      ",
      "bddac           ",
      "                ",
      "                ",
      "                ",
      "                ",
      "                ",
      "                ",
      "                ",
      "                ",
      "                "
    ],
    [
      "                ",
      "                ",
      "         v栏   栏 ",
      "    v栏  栏v酸H H酸b",
      "   栏v酸HH酸baddbce",
      "  H酸abcbae      ",
      "bcdad           ",
      "                ",
      "                ",
      "                ",
      "                ",
      "                ",
      "                ",
      "                ",
      "                ",
      "                "
    ],
    [
      "                ",
      "                ",
      "         v     v",
      "    v    v     v",
      "    v    v胎   胎g",
      "    v胎  胎gcacbad",
      "   胎gadbabc     ",
      "caaabc          ",
      "                ",
      "                ",
      "                ",
      "                ",
      "                ",
      "                ",
      "                ",
      "                "
    ],
    [
      "                ",
      "                ",
      "         v     v",
      "    v    v     g",
      "    v    g     g",
      "    g    gbdcbdb",
      "    geedcbb     ",
      "dedaec          ",
      "                ",
      "                ",
      "                ",
      "                ",
      "                ",
      "                ",
      "                ",
      "                "
    ],
    [
      "adbbeacccedbaeaa",
      "eadccebdeaaddacc",
      "deaadbabecaeabda",
      "ecaedabcaabbbeae",
      "bcbacbdbdecbddbe",
      "eccdedbcadddbbda",
      "baacaadaeedbcdce",
      "eabcacdabede    ",
      "daeccbe         ",
      "                ",
      "                ",
      "                ",
      "                ",
      "                ",
      "                ",
      "                "
    ],
    [
      " f晨JfK晨JfK晨JfK晨J",
      " f JfK JfK JfK J",
      " f芝JfK芝JfK芝JfK坎J",
      "                ",
      "                ",
      "f               ",
      "f        谁活cadbb",
      "f   谁活bdbceb    ",
      "eadcbeb         ",
      "                ",
      "                ",
      "                ",
      "                ",
      "                ",
      "                ",
      "                "
    ]
  ]
}