{
  "xsize": 16,
  "zsize": 16,
  "palette": {
    "palette": [
      {
        "char": " ",
        "block": "minecraft:air"
      },
      {
        "char": "b",
        "block": "minecraft:basalt[axis=x]"
      },
      {
        "char": "e",
        "block": "minecraft:cyan_terracotta"
      },
      {
        "char": "c",
        "block": "minecraft:deepslate[axis=y]"
      },
      {
        "char": "a",
        "block": "minecraft:blackstone"
      },
      {
        "char": "d",
        "block": "minecraft:cobbled_deepslate"
      },
      {
        "char": "i",
        "block": "minecraft:white_concrete"
      },
      {
        "char": "f",
        "block": "minecraft:light_gray_concrete"
      },
      {
        "char": "q",
        "block": "minecraft:gold_block"
      },
      {
        "char": "A",
        "block": "minecraft:iron_trapdoor[facing=south,half=bottom,open=false,powered=false,waterlogged=false]"
      },
      {
        "char": "约",
        "block": "minecraft:smooth_quartz_stairs[facing=south,half=bottom,shape=straight,waterlogged=false]"
      },
      {
        "char": "楼",
        "block": "minecraft:smooth_quartz_stairs[facing=east,half=bottom,shape=straight,waterlogged=false]"
      },
      {
        "char": "暴",
        "block": "minecraft:smooth_quartz_stairs[facing=west,half=bottom,shape=straight,waterlogged=false]"
      },
      {
        "char": "须",
        "block": "minecraft:smooth_quartz_stairs[facing=north,half=bottom,shape=straight,waterlogged=false]"
      },
      {
        "char": "M",
        "block": "minecraft:quartz_pillar[axis=y]"
      },
      {
        "char": "闯",
        "block": "minecraft:lever[face=ceiling,facing=west,powered=true]"
      },
      {
        "char": "穴",
        "block": "minecraft:air"
      },
      {
        "char": "救",
        "block": "minecraft:iron_trapdoor[facing=west,half=bottom,open=false,powered=false,waterlogged=false]"
      },
      {
        "char": "介",
        "block": "minecraft:iron_trapdoor[facing=east,half=bottom,open=false,powered=false,waterlogged=false]"
      }
    ]
  },
  "slices": [
    [
      "bebccadbeeddbeee",
      "deabbbdededacedd",
      "bbedecadddbbddbd",
      "bedaaeebeebeacce",
      "cdeddbabceeeeccd",
      "iiiiiiiiiiiiiiii",
      "ecedceddcadbdcee",
      "daaaceecebdaadda",
      "edcbaccebbebbaff",
      "fbbacdadccadefde",
      "afedaebabbebfc  ",
      " afddcaedebcfb d",
      " bfabccdabccfdqq",
      " bfedbabdeccef  ",
      " fdecacdadaabeff",
      "feaedabcdcdebAAA"
    ],
    [
      "                ",
      "                ",
      "                ",
      "                ",
      "                ",
      "                ",
      "                ",
      "                ",
      "              约约",
      "约            约ii",
      "i约          楼i f",
      "fi暴         楼i  ",
      "ci暴         楼iqq",
      " i暴          须ii",
      "i暴            须须",
      "须               "
    ],
    [
      "                ",
      "                ",
      "                ",
      "                ",
      "                ",
      "                ",
      "                ",
      "                ",
      "                ",
      "              ii",
      "i            i c",
      "bi           iqq",
      "Mi   闯       i  ",
      " i            ii",
      "i               ",
      "                "
    ],
    [
      "                ",
      "                ",
      "                ",
      "                ",
      "                ",
      "                ",
      "                ",
      "                ",
      "                ",
      "              约约",
      "约            楼bc",
      "c暴           楼db",
      "eedaaa穴      楼cb",
      "a暴            须须",
      "须               ",
      "                "
    ],
    [
      "                ",
      "                ",
      "                ",
      "                ",
      "                ",
      "                ",
      "                ",
      "                ",
      "                ",
      "                ",
      "              救救",
      "介             救救",
      "介             救救",
      "介               ",
      "                ",
      "                "
    ],
    [
      "                ",
      "                ",
      "                ",
      "                ",
      "                ",
      "                ",
      "                ",
      "                ",
      "                ",
      "                ",
      "                ",
      "                ",
      "                ",
      "                ",
      "                ",
      "                "
    ]
  ]
}