{
  "xsize": 16,
  "zsize": 16,
  "palette": {
    "palette": [
      {
        "char": " ",
        "block": "minecraft:air"
      },
      {
        "char": "d",
        "block": "minecraft:cobbled_deepslate"
      },
      {
        "char": "c",
        "block": "minecraft:deepslate[axis=y]"
      },
      {
        "char": "a",
        "block": "minecraft:blackstone"
      },
      {
        "char": "e",
        "block": "minecraft:cyan_terracotta"
      },
      {
        "char": "b",
        "block": "minecraft:basalt[axis=x]"
      },
      {
        "char": "爹",
        "block": "minecraft:quartz_stairs[facing=north,half=top,shape=inner_left,waterlogged=false]"
      },
      {
        "char": "ϓ",
        "block": "minecraft:quartz_stairs[facing=north,half=top,shape=straight,waterlogged=false]"
      },
      {
        "char": "K",
        "block": "minecraft:quartz_stairs[facing=west,half=top,shape=straight,waterlogged=false]"
      },
      {
        "char": "践",
        "block": "minecraft:lever[face=floor,facing=north,powered=false]"
      },
      {
        "char": "p",
        "block": "minecraft:gray_carpet"
      },
      {
        "char": "w",
        "block": "minecraft:quartz_stairs[facing=south,half=bottom,shape=straight,waterlogged=false]"
      },
      {
        "char": "f",
        "block": "minecraft:light_gray_concrete"
      },
      {
        "char": "g",
        "block": "minecraft:redstone_lamp[lit=false]"
      },
      {
        "char": "顽",
        "block": "minecraft:redstone_wire[east=side,north=none,power=0,south=none,west=side]"
      },
      {
        "char": "睁",
        "block": "minecraft:repeater[delay=1,facing=west,locked=false,powered=false]"
      },
      {
        "char": "遥",
        "block": "minecraft:cartography_table"
      },
      {
        "char": "锡",
        "block": "minecraft:iron_door[facing=east,half=lower,hinge=left,open=false,powered=false]"
      },
      {
        "char": "呦",
        "block": "minecraft:birch_pressure_plate[powered=false]"
      },
      {
        "char": "x",
        "block": "minecraft:quartz_stairs[facing=north,half=bottom,shape=straight,waterlogged=false]"
      },
      {
        "char": "吋",
        "block": "minecraft:iron_door[facing=east,half=lower,hinge=right,open=false,powered=false]"
      }
    ]
  },
  "slices": [
    [
      "                ",
      "                ",
      "                ",
      "                ",
      "                ",
      "                ",
      "                ",
      "                ",
      "                ",
      "dc              ",
      " ace            ",
      " edbeb          ",
      " ccebcaa        ",
      "cbceabbdda      ",
      "cddeadeedaca    ",
      " ccaccaaaeceac  "
    ],
    [
      "                ",
      "                ",
      "                ",
      "                ",
      "                ",
      "                ",
      "                ",
      "                ",
      "                ",
      "ba              ",
      " dea            ",
      " a dea          ",
      " b爹ϓϓbae        ",
      " cK践pϓϓdbb      ",
      " eKpw践pϓϓeda    ",
      " dKpppwppϓϓadd  "
    ],
    [
      "                ",
      "                ",
      "                ",
      "                ",
      "                ",
      "                ",
      "                ",
      "c               ",
      "bdc             ",
      " feea           ",
      " f gded         ",
      " f   gddb       ",
      " f     gbbb     ",
      " f     顽顽gcda   ",
      " f       睁 gbca ",
      " f           fab"
    ],
    [
      "                ",
      "                ",
      "                ",
      "                ",
      "                ",
      "                ",
      "                ",
      "e               ",
      "eda             ",
      " fbeb           ",
      " f gcba         ",
      " f   gbae       ",
      " f     gdae     ",
      " f       gaeb   ",
      " f         gede ",
      " f           fdb"
    ],
    [
      "                ",
      "                ",
      "                ",
      "                ",
      "                ",
      "e               ",
      "ed              ",
      "ccae            ",
      "ccccbe          ",
      "bbcacaed        ",
      "dedcdccad       ",
      "adbdeaeeeaeb    ",
      "dcacedabcbddca  ",
      "cdceacbedcdddadc",
      "dbeaeddaabacbccd",
      "ecbabdebedeacbee"
    ],
    [
      "                ",
      "                ",
      "                ",
      "                ",
      "                ",
      "c               ",
      "ae              ",
      " aca            ",
      "  gdeb          ",
      "ffff ade        ",
      "      ecdd      ",
      "          bc    ",
      "ffff      gfcb  ",
      "遥遥gf       f bac",
      " 遥遥f  dac  锡呦  e",
      "  遥f  xxx  吋呦   "
    ]
  ]
}