{
  "xsize": 16,
  "zsize": 16,
  "palette": {
    "palette": [
      {
        "char": " ",
        "block": "minecraft:air"
      },
      {
        "char": "b",
        "block": "minecraft:basalt[axis=x]"
      },
      {
        "char": "a",
        "block": "minecraft:blackstone"
      },
      {
        "char": "d",
        "block": "minecraft:cobbled_deepslate"
      },
      {
        "char": "c",
        "block": "minecraft:deepslate[axis=y]"
      },
      {
        "char": "n",
        "block": "minecraft:black_concrete"
      },
      {
        "char": "e",
        "block": "minecraft:cyan_terracotta"
      },
      {
        "char": "i",
        "block": "minecraft:white_concrete"
      },
      {
        "char": "z",
        "block": "minecraft:quartz_stairs[facing=west,half=bottom,shape=straight,waterlogged=false]"
      },
      {
        "char": "铜",
        "block": "minecraft:black_stained_glass_pane[east=true,north=false,south=false,waterlogged=false,west=false]"
      },
      {
        "char": "效",
        "block": "minecraft:black_stained_glass_pane[east=true,north=false,south=false,waterlogged=false,west=true]"
      },
      {
        "char": "蓉",
        "block": "minecraft:black_stained_glass_pane[east=false,north=false,south=true,waterlogged=false,west=true]"
      },
      {
        "char": "职",
        "block": "minecraft:black_stained_glass_pane[east=false,north=true,south=true,waterlogged=false,west=false]"
      },
      {
        "char": "刮",
        "block": "minecraft:black_stained_glass_pane[east=false,north=true,south=false,waterlogged=false,west=true]"
      },
      {
        "char": "w",
        "block": "minecraft:quartz_stairs[facing=south,half=bottom,shape=straight,waterlogged=false]"
      },
      {
        "char": "g",
        "block": "minecraft:redstone_lamp[lit=false]"
      },
      {
        "char": "y",
        "block": "minecraft:quartz_slab[type=top,waterlogged=false]"
      }
    ]
  },
  "slices": [
    [
      "babddcncebaedeec",
      "iiaebdncdbeaddae",
      "bddcbcnbaeacbaad",
      "bbbadbnecdebadaa",
      "nnnnnnbbddaeccea",
      "ebacaaabebdaabba",
      "eeebbcbacddaeebe",
      "dcz    bcbabbaae",
      "cbz    edeccaeda",
      "adabeeacabcdcdab",
      "eeececabeebabbbd",
      " dcbaaeaccdcebee",
      " aabddcceeabcdae",
      " ebcaeacccabeadb",
      "  cbcdaeadbcada ",
      "                "
    ],
    [
      "                ",
      "                ",
      "                ",
      "                ",
      "      n         ",
      "                ",
      "  铜效效效效蓉        ",
      "       职        ",
      "       职        ",
      "  铜效效效效刮        ",
      "                ",
      "e          a  c ",
      "ebcedbdd   ewwc ",
      "b      adcbcacb ",
      "cb            ac",
      "ddccbeabebedaeca"
    ],
    [
      "                ",
      "                ",
      "                ",
      "                ",
      "      n         ",
      "                ",
      "                ",
      "                ",
      "                ",
      "                ",
      "                ",
      "                ",
      "           b  a ",
      "deacdcb    cwwe ",
      "      acbbeabcb ",
      "            aaec"
    ],
    [
      "                ",
      "                ",
      "                ",
      "                ",
      "      n         ",
      "                ",
      "                ",
      "                ",
      "                ",
      "                ",
      "                ",
      "                ",
      "                ",
      "           c  a ",
      "ddcbad     e  a ",
      "     dddddac  c "
    ],
    [
      "                ",
      "                ",
      "                ",
      "                ",
      "      n         ",
      "                ",
      "                ",
      "                ",
      "                ",
      "                ",
      "                ",
      "                ",
      "                ",
      "                ",
      "                ",
      "adacag          "
    ],
    [
      "                ",
      "                ",
      "                ",
      "                ",
      "      ng        ",
      "      gy        ",
      "                ",
      "                ",
      "                ",
      "                ",
      "                ",
      "                ",
      "                ",
      "                ",
      "                ",
      "dada            "
    ]
  ]
}