{
  "xsize": 16,
  "zsize": 16,
  "palette": {
    "palette": [
      {
        "char": " ",
        "block": "minecraft:air"
      },
      {
        "char": "a",
        "block": "minecraft:blackstone"
      },
      {
        "char": "e",
        "block": "minecraft:cyan_terracotta"
      },
      {
        "char": "d",
        "block": "minecraft:cobbled_deepslate"
      },
      {
        "char": "c",
        "block": "minecraft:deepslate[axis=y]"
      },
      {
        "char": "b",
        "block": "minecraft:basalt[axis=x]"
      },
      {
        "char": "z",
        "block": "minecraft:quartz_stairs[facing=west,half=bottom,shape=straight,waterlogged=false]"
      },
      {
        "char": "n",
        "block": "minecraft:black_concrete"
      },
      {
        "char": "g",
        "block": "minecraft:redstone_lamp[lit=false]"
      },
      {
        "char": "f",
        "block": "minecraft:light_gray_concrete"
      },
      {
        "char": "铜",
        "block": "minecraft:black_stained_glass_pane[east=true,north=false,south=false,waterlogged=false,west=false]"
      },
      {
        "char": "效",
        "block": "minecraft:black_stained_glass_pane[east=true,north=false,south=false,waterlogged=false,west=true]"
      },
      {
        "char": "蓉",
        "block": "minecraft:black_stained_glass_pane[east=false,north=false,south=true,waterlogged=false,west=true]"
      },
      {
        "char": "职",
        "block": "minecraft:black_stained_glass_pane[east=false,north=true,south=true,waterlogged=false,west=false]"
      },
      {
        "char": "q",
        "block": "minecraft:gold_block"
      },
      {
        "char": "刮",
        "block": "minecraft:black_stained_glass_pane[east=false,north=true,south=false,waterlogged=false,west=true]"
      },
      {
        "char": "豆",
        "block": "minecraft:air"
      },
      {
        "char": "喘",
        "block": "minecraft:air"
      },
      {
        "char": "淘",
        "block": "minecraft:air",
        "tag": {
          "z": 938,
          "x": -369,
          "ForgeCaps": {},
          "id": "refurbished_furniture:computer",
          "y": 122,
          "NodePos": "-101429943820166L",
          "Connections": [
            "L"
          ]
        }
      },
      {
        "char": "奉",
        "block": "minecraft:lever[face=wall,facing=east,powered=true]"
      },
      {
        "char": "y",
        "block": "minecraft:quartz_slab[type=top,waterlogged=false]"
      }
    ]
  },
  "slices": [
    [
      "aedeccaddeaecbad",
      "ccdcecebdz    bd",
      "dccecbacbz    ad",
      "bdddbdabeaceeccc",
      "dbaacbddedaebdae",
      "addcdcccaadccccc",
      "nnnnnneecaaebbde",
      "      necdebeced",
      "      nbaedbcedb",
      "      nbcebadece",
      "      nbcddedead",
      "      nbebaceede",
      "      nbadcddead",
      "      nggacaaaec",
      "      neabggeecd",
      "      nccabacgga"
    ],
    [
      "fffffff  铜效效效效蓉 ",
      "fffbbaf       职 ",
      "ffqq  f       职 ",
      " f   f   铜效效效效刮 ",
      "  fff           ",
      "                ",
      "      n         ",
      "                ",
      "                ",
      "                ",
      "                ",
      "                ",
      "                ",
      "                ",
      "                ",
      "                "
    ],
    [
      "豆  z ef         ",
      "f  abbf         ",
      "  qq  f         ",
      " f   f          ",
      "  fff           ",
      "                ",
      "      n         ",
      "                ",
      "                ",
      "                ",
      "                ",
      "                ",
      "                ",
      "                ",
      "                ",
      "                "
    ],
    [
      "喘    淘f         ",
      "f奉 bbef         ",
      "  qq  f         ",
      " f   f          ",
      "  fff           ",
      "                ",
      "      n         ",
      "                ",
      "                ",
      "                ",
      "                ",
      "                ",
      "                ",
      "                ",
      "                ",
      "                "
    ],
    [
      "f     f         ",
      "f  a  f         ",
      "  qq  f         ",
      " f   f          ",
      "  fff           ",
      "                ",
      "      n         ",
      "                ",
      "                ",
      "                ",
      "                ",
      "                ",
      "                ",
      "                ",
      "                ",
      "                "
    ],
    [
      "f     f         ",
      "f  d  f         ",
      "f qq  f         ",
      " f   f          ",
      "  fff           ",
      "      gy        ",
      "      ng        ",
      "                ",
      "                ",
      "                ",
      "                ",
      "                ",
      "                ",
      "                ",
      "                ",
      "                "
    ]
  ]
}