{
  "xsize": 16,
  "zsize": 16,
  "palette": {
    "palette": [
      {
        "char": " ",
        "block": "minecraft:air"
      },
      {
        "char": "a",
        "block": "minecraft:blackstone"
      },
      {
        "char": "e",
        "block": "minecraft:cyan_terracotta"
      },
      {
        "char": "c",
        "block": "minecraft:deepslate[axis=y]"
      },
      {
        "char": "d",
        "block": "minecraft:cobbled_deepslate"
      },
      {
        "char": "b",
        "block": "minecraft:basalt[axis=x]"
      },
      {
        "char": "g",
        "block": "minecraft:redstone_lamp[lit=false]"
      },
      {
        "char": "C",
        "block": "minecraft:quartz_stairs[facing=east,half=bottom,shape=straight,waterlogged=false]"
      },
      {
        "char": "f",
        "block": "minecraft:light_gray_concrete"
      },
      {
        "char": "n",
        "block": "minecraft:black_concrete"
      },
      {
        "char": "q",
        "block": "minecraft:gold_block"
      },
      {
        "char": "咫",
        "block": "minecraft:air"
      },
      {
        "char": "z",
        "block": "minecraft:quartz_stairs[facing=west,half=bottom,shape=straight,waterlogged=false]"
      },
      {
        "char": "窕",
        "block": "minecraft:air"
      },
      {
        "char": "奉",
        "block": "minecraft:lever[face=wall,facing=east,powered=true]"
      },
      {
        "char": "w",
        "block": "minecraft:quartz_stairs[facing=south,half=bottom,shape=straight,waterlogged=false]"
      },
      {
        "char": "坛",
        "block": "minecraft:redstone_wall_torch[facing=west,lit=true]"
      },
      {
        "char": "x",
        "block": "minecraft:quartz_stairs[facing=north,half=bottom,shape=straight,waterlogged=false]"
      }
    ]
  },
  "slices": [
    [
      "aecdaeeeecebbdee",
      "dedbbcacdddbdaea",
      "bbbedcaddecbcebe",
      "bdbcadaaedddbdab",
      "eeeaacdcebbdbaea",
      "ceadbedcedbcbbdb",
      "becbaddaeabcaaea",
      "ccacebaabdddcbea",
      "abdabdcadddedegg",
      "dcceebacadedccbd",
      "dcdedcabbaacbacb",
      "ceaddeeeaacbcbdd",
      "eeebecddcdbdbced",
      "bbaececbcbdbbbbd",
      "edbaecebedab    ",
      "cecbed          "
    ],
    [
      "                ",
      "                ",
      "                ",
      "                ",
      "                ",
      "                ",
      "                ",
      "Cffff n         ",
      "                ",
      "              ff",
      "            ffff",
      "           Cffff",
      "            fffc",
      "            ffqq",
      "            abaa",
      "      decaeba   "
    ],
    [
      "                ",
      "                ",
      "                ",
      "                ",
      "                ",
      "                ",
      "                ",
      " Cfff n         ",
      "                ",
      "              ff",
      "            ff  ",
      "            咫  z",
      "            f  c",
      "            f qq",
      "             f  ",
      "             cda"
    ],
    [
      "                ",
      "                ",
      "                ",
      "                ",
      "                ",
      "                ",
      "                ",
      "  Cff n         ",
      "                ",
      "              ff",
      "            ff  ",
      "            窕   ",
      "            f奉 e",
      "            f qq",
      "             f  ",
      "              ff"
    ],
    [
      "                ",
      "                ",
      "                ",
      "                ",
      "                ",
      "                ",
      "                ",
      "   Cf n         ",
      "ffffff          ",
      "ffffff        ff",
      "fffffff      f  ",
      "fffffff     f   ",
      "fffffff     f  b",
      "fffffff     f qq",
      "fffffff      f  ",
      "ffffff        ff"
    ],
    [
      "                ",
      "                ",
      "                ",
      "                ",
      "                ",
      "                ",
      "fffff           ",
      "    ffn         ",
      "dbbwagf         ",
      "dccdcef       ff",
      "ccbb 坛af     f  ",
      "gegd  cf    f   ",
      "cgbaz bf    f  a",
      "gegc  df    f qq",
      "abca 坛df     f  ",
      "x x edf       ff"
    ]
  ]
}