{
  "xsize": 16,
  "zsize": 16,
  "palette": {
    "palette": [
      {
        "char": " ",
        "block": "minecraft:air"
      },
      {
        "char": "b",
        "block": "minecraft:basalt[axis=x]"
      },
      {
        "char": "d",
        "block": "minecraft:cobbled_deepslate"
      },
      {
        "char": "e",
        "block": "minecraft:cyan_terracotta"
      },
      {
        "char": "a",
        "block": "minecraft:blackstone"
      },
      {
        "char": "c",
        "block": "minecraft:deepslate[axis=y]"
      },
      {
        "char": "i",
        "block": "minecraft:white_concrete"
      },
      {
        "char": "y",
        "block": "minecraft:quartz_slab[type=top,waterlogged=false]"
      },
      {
        "char": "n",
        "block": "minecraft:black_concrete"
      },
      {
        "char": "s",
        "block": "minecraft:quartz_slab[type=bottom,waterlogged=false]"
      },
      {
        "char": "x",
        "block": "minecraft:quartz_stairs[facing=north,half=bottom,shape=straight,waterlogged=false]"
      },
      {
        "char": "葬",
        "block": "minecraft:quartz_stairs[facing=east,half=bottom,shape=outer_right,waterlogged=false]"
      },
      {
        "char": "w",
        "block": "minecraft:quartz_stairs[facing=south,half=bottom,shape=straight,waterlogged=false]"
      },
      {
        "char": "驻",
        "block": "minecraft:furnace[facing=west,lit=false]",
        "tag": {
          "z": 953,
          "x": -551,
          "CookTimeTotal": 0,
          "ForgeData": {
            "LockFlag": "1b"
          },
          "CookTime": 0,
          "ForgeCaps": {
            "polymorph:block_entity_recipe_data": {}
          },
          "id": "minecraft:furnace",
          "y": 120,
          "Items": [],
          "BurnTime": 0,
          "RecipesUsed": {}
        }
      },
      {
        "char": "澡",
        "block": "minecraft:furnace[facing=east,lit=false]",
        "tag": {
          "z": 971,
          "x": -525,
          "CookTimeTotal": 0,
          "ForgeData": {
            "LockFlag": "1b"
          },
          "CookTime": 0,
          "ForgeCaps": {
            "polymorph:block_entity_recipe_data": {}
          },
          "id": "minecraft:furnace",
          "y": 126,
          "Items": [],
          "BurnTime": 0,
          "RecipesUsed": {}
        }
      },
      {
        "char": "o",
        "block": "minecraft:black_stained_glass"
      },
      {
        "char": "Q",
        "block": "minecraft:quartz_slab[type=double,waterlogged=false]"
      },
      {
        "char": "K",
        "block": "minecraft:quartz_stairs[facing=west,half=top,shape=straight,waterlogged=false]"
      },
      {
        "char": "斩",
        "block": "minecraft:quartz_stairs[facing=east,half=bottom,shape=outer_left,waterlogged=false]"
      },
      {
        "char": "H",
        "block": "minecraft:quartz_stairs[facing=south,half=top,shape=straight,waterlogged=false]"
      },
      {
        "char": "ϓ",
        "block": "minecraft:quartz_stairs[facing=north,half=top,shape=straight,waterlogged=false]"
      },
      {
        "char": "g",
        "block": "minecraft:redstone_lamp[lit=false]"
      }
    ]
  },
  "slices": [
    [
      "                ",
      "                ",
      "                ",
      "                ",
      "                ",
      "bdbeeb          ",
      "badcecdaebacd   ",
      "aabadcaacebabed ",
      "cadbaedbebacbdb ",
      "bbbbdaccdebbcde ",
      "bedeababbccddec ",
      "ddddcdcbdbceebe ",
      "cabaddccbedbadc ",
      "iiaediiicaciiice",
      "bccddbbdeaaadbc ",
      "cbbcdcdccdeecde "
    ],
    [
      "                ",
      "                ",
      "                ",
      "                ",
      "baebedb         ",
      "      ecbcbddc  ",
      "             ade",
      "               d",
      "               b",
      "       y       d",
      "     y         d",
      "   y   n       c",
      " y             a",
      "nyyyyyyy       a",
      " y             e",
      "   y   n       c"
    ],
    [
      "                ",
      "                ",
      "                ",
      "abdedebe        ",
      "       dceddcad ",
      "              ea",
      "                ",
      "                ",
      "                ",
      "       sx       ",
      "     sss        ",
      "   sssss        ",
      " s葬www驻澡        ",
      "sooQQQQQQK      ",
      " s斩xxx驻澡        ",
      "   sssss        "
    ],
    [
      "                ",
      "                ",
      "baceabeab       ",
      "        cdccdeea",
      "               e",
      "                ",
      "                ",
      "                ",
      "                ",
      "                ",
      "                ",
      "           H    ",
      "           y    ",
      "     ss驻QQKy    ",
      "           y    ",
      "           ϓ    "
    ],
    [
      "                ",
      "ecbeadeadc      ",
      "        gceacedc",
      "               g",
      "                ",
      "                ",
      "                ",
      "                ",
      "                ",
      "                ",
      "                ",
      "           w    ",
      "                ",
      "          ss    ",
      "                ",
      "           x    "
    ],
    [
      "                ",
      "edacebcceae     ",
      "         ddeeaec",
      "                ",
      "                ",
      "                ",
      "                ",
      "                ",
      "                ",
      "                ",
      "                ",
      "                ",
      "                ",
      "                ",
      "                ",
      "                "
    ]
  ]
}