{
  "xsize": 16,
  "zsize": 16,
  "palette": {
    "palette": [
      {
        "char": " ",
        "block": "minecraft:air"
      },
      {
        "char": "e",
        "block": "minecraft:cyan_terracotta"
      },
      {
        "char": "b",
        "block": "minecraft:basalt[axis=x]"
      },
      {
        "char": "c",
        "block": "minecraft:deepslate[axis=y]"
      },
      {
        "char": "d",
        "block": "minecraft:cobbled_deepslate"
      },
      {
        "char": "a",
        "block": "minecraft:blackstone"
      },
      {
        "char": "i",
        "block": "minecraft:white_concrete"
      },
      {
        "char": "g",
        "block": "minecraft:redstone_lamp[lit=false]"
      },
      {
        "char": "o",
        "block": "minecraft:black_stained_glass"
      }
    ]
  },
  "slices": [
    [
      "ebcedabadc b    ",
      "bcbbecaebdcbd   ",
      "eacecadbbbdcb   ",
      "acdceddaabddacb ",
      "aadeebbabdadbebc",
      "iiiiiiiiiiiiiiii",
      "ccddcdcccddceeab",
      "beeecabecbbbccad",
      "aadeeaadbeeacdaa",
      "bcbcbdedbaeadcdd",
      "ddabedbdcddbbaad",
      "ececdadaccdcdcdb",
      "bbcadaeddaecacab",
      "digiadaigidadigi",
      "abcebcbdcecdacba",
      "adeebaceeeedebaa"
    ],
    [
      "           o    ",
      "            o   ",
      "            o   ",
      "             oo ",
      "               o",
      "                ",
      "                ",
      "                ",
      "                ",
      "                ",
      "                ",
      "                ",
      "                ",
      "                ",
      "                ",
      "                "
    ],
    [
      "            oooo",
      "             ooo",
      "             ooo",
      "               o",
      "                ",
      "                ",
      "                ",
      "                ",
      "                ",
      "                ",
      "                ",
      "                ",
      "                ",
      "                ",
      "                ",
      "                "
    ],
    [
      "                ",
      "                ",
      "                ",
      "                ",
      "                ",
      "                ",
      "                ",
      "                ",
      "                ",
      "                ",
      "                ",
      "                ",
      "                ",
      "                ",
      "                ",
      "                "
    ],
    [
      "                ",
      "                ",
      "                ",
      "                ",
      "                ",
      "                ",
      "                ",
      "                ",
      "                ",
      "                ",
      "                ",
      "                ",
      "                ",
      "                ",
      "                ",
      "                "
    ],
    [
      "                ",
      "                ",
      "                ",
      "                ",
      "                ",
      "                ",
      "                ",
      "                ",
      "                ",
      "                ",
      "                ",
      "                ",
      "                ",
      "                ",
      "                ",
      "                "
    ]
  ]
}