{
  "xsize": 16,
  "zsize": 16,
  "palette": {
    "palette": [
      {
        "char": " ",
        "block": "minecraft:air"
      },
      {
        "char": "a",
        "block": "minecraft:blackstone"
      },
      {
        "char": "d",
        "block": "minecraft:cobbled_deepslate"
      },
      {
        "char": "e",
        "block": "minecraft:cyan_terracotta"
      },
      {
        "char": "b",
        "block": "minecraft:basalt[axis=x]"
      },
      {
        "char": "c",
        "block": "minecraft:deepslate[axis=y]"
      },
      {
        "char": "x",
        "block": "minecraft:quartz_stairs[facing=north,half=bottom,shape=straight,waterlogged=false]"
      },
      {
        "char": "g",
        "block": "minecraft:redstone_lamp[lit=false]"
      },
      {
        "char": "颓",
        "block": "minecraft:black_stained_glass_pane[east=false,north=false,south=true,waterlogged=false,west=false]"
      },
      {
        "char": "职",
        "block": "minecraft:black_stained_glass_pane[east=false,north=true,south=true,waterlogged=false,west=false]"
      },
      {
        "char": "稀",
        "block": "minecraft:black_stained_glass_pane[east=true,north=true,south=false,waterlogged=false,west=false]"
      },
      {
        "char": "媚",
        "block": "minecraft:black_stained_glass_pane[east=true,north=false,south=true,waterlogged=false,west=true]"
      },
      {
        "char": "刮",
        "block": "minecraft:black_stained_glass_pane[east=false,north=true,south=false,waterlogged=false,west=true]"
      },
      {
        "char": "s",
        "block": "minecraft:quartz_slab[type=bottom,waterlogged=false]"
      },
      {
        "char": "z",
        "block": "minecraft:quartz_stairs[facing=west,half=bottom,shape=straight,waterlogged=false]"
      }
    ]
  },
  "slices": [
    [
      "adeadebc        ",
      "abcacdcabb      ",
      "caababdbdada    ",
      "cdadcaxxxcceaa  ",
      "bbbbgb   cgccede",
      "caedge   agcedbd",
      "aceage   cgbbbad",
      "cabagc   agecadd",
      "bbbege   dgbbbcb",
      "acabgc   cgebdbd",
      "decacabacbbecaca",
      "ddaadeeddaceedba",
      "accacadbdbeeccde",
      "edebedcbcdebceae",
      "dcebabdbceeabddd",
      "ebccbbccacacadcb"
    ],
    [
      "        ece     ",
      "          dca   ",
      "     颓   颓  eec ",
      "     职   职    ca",
      "     职   职      ",
      "     职   职      ",
      "     职   职      ",
      "     职   职      ",
      "     职   职      ",
      "     职   职      ",
      "     稀媚媚媚刮      ",
      "     sgggs      ",
      "      sss       ",
      "                ",
      "                ",
      "                "
    ],
    [
      "           aaa  ",
      "             dcc",
      "               e",
      "                ",
      "                ",
      "                ",
      "                ",
      "                ",
      "                ",
      "                ",
      "                ",
      "                ",
      "               z",
      "               s",
      "                ",
      "                "
    ],
    [
      "              de",
      "                ",
      "                ",
      "                ",
      "                ",
      "                ",
      "                ",
      "                ",
      "                ",
      "                ",
      "                ",
      "                ",
      "                ",
      "                ",
      "                ",
      "                "
    ],
    [
      "                ",
      "                ",
      "                ",
      "                ",
      "                ",
      "                ",
      "                ",
      "                ",
      "                ",
      "                ",
      "                ",
      "                ",
      "                ",
      "                ",
      "                ",
      "                "
    ],
    [
      "                ",
      "                ",
      "                ",
      "                ",
      "                ",
      "                ",
      "                ",
      "                ",
      "                ",
      "                ",
      "                ",
      "                ",
      "                ",
      "                ",
      "                ",
      "                "
    ]
  ]
}