{
  "xsize": 16,
  "zsize": 16,
  "palette": {
    "palette": [
      {
        "char": " ",
        "block": "minecraft:air"
      },
      {
        "char": "a",
        "block": "minecraft:blackstone"
      },
      {
        "char": "愈",
        "block": "minecraft:birch_wall_sign[facing=west,waterlogged=false]",
        "tag": {
          "z": 979,
          "x": -456,
          "is_waxed": "0b",
          "ForgeCaps": {
            "supplementaries:antique_ink": {
              "ink": "0b"
            }
          },
          "id": "minecraft:sign",
          "y": 116,
          "front_text": {
            "color": "black",
            "has_glowing_text": "0b",
            "messages": [
              "{\"extra\":[{\"text\":\"Officer's bunks\"}],\"text\":\"\"}",
              "{\"extra\":[{\"text\":\"^\"}],\"text\":\"\"}",
              "{\"extra\":[{\"text\":\"|\"}],\"text\":\"\"}",
              "{\"text\":\"\"}"
            ]
          },
          "back_text": {
            "color": "black",
            "has_glowing_text": "0b",
            "messages": [
              "{\"text\":\"\"}",
              "{\"text\":\"\"}",
              "{\"text\":\"\"}",
              "{\"text\":\"\"}"
            ]
          }
        }
      },
      {
        "char": "ϑ",
        "block": "minecraft:birch_wall_sign[facing=south,waterlogged=false]",
        "tag": {
          "z": 953,
          "x": -527,
          "is_waxed": "0b",
          "ForgeCaps": {
            "supplementaries:antique_ink": {
              "ink": "0b"
            }
          },
          "id": "minecraft:sign",
          "y": 112,
          "front_text": {
            "color": "black",
            "has_glowing_text": "0b",
            "messages": [
              "{\"extra\":[{\"text\":\"Workshop\"}],\"text\":\"\"}",
              "{\"text\":\"\"}",
              "{\"text\":\"\"}",
              "{\"text\":\"\"}"
            ]
          },
          "back_text": {
            "color": "black",
            "has_glowing_text": "0b",
            "messages": [
              "{\"text\":\"\"}",
              "{\"text\":\"\"}",
              "{\"text\":\"\"}",
              "{\"text\":\"\"}"
            ]
          }
        }
      },
      {
        "char": "c",
        "block": "minecraft:deepslate[axis=y]"
      },
      {
        "char": "鹤",
        "block": "minecraft:piston_head[facing=south,short=false,type=sticky]"
      },
      {
        "char": "L",
        "block": "minecraft:chiseled_quartz_block"
      },
      {
        "char": "M",
        "block": "minecraft:quartz_pillar[axis=y]"
      },
      {
        "char": "d",
        "block": "minecraft:cobbled_deepslate"
      },
      {
        "char": "恶",
        "block": "minecraft:lever[face=wall,facing=south,powered=false]"
      },
      {
        "char": "b",
        "block": "minecraft:basalt[axis=x]"
      },
      {
        "char": "e",
        "block": "minecraft:cyan_terracotta"
      },
      {
        "char": "效",
        "block": "minecraft:black_stained_glass_pane[east=true,north=false,south=false,waterlogged=false,west=true]"
      },
      {
        "char": "推",
        "block": "minecraft:quartz_block"
      },
      {
        "char": "g",
        "block": "minecraft:redstone_lamp[lit=false]"
      },
      {
        "char": "o",
        "block": "minecraft:black_stained_glass"
      },
      {
        "char": "ϔ",
        "block": "minecraft:observer[facing=south,powered=false]"
      }
    ]
  },
  "slices": [
    [
      "     a 愈aϑc鹤LLLM",
      "      d    M 恶恶 ",
      "       bdecL    ",
      "           bLL  ",
      "            edL效",
      "              d ",
      "                ",
      "                ",
      "                ",
      "                ",
      "                ",
      "                ",
      "                ",
      "                ",
      "                ",
      "                "
    ],
    [
      "     a  bdba推推推M",
      "      c  geg ϑϑ ",
      "      dgeade推   ",
      "       ba   e推  ",
      "             e推效",
      "              b ",
      "                ",
      "                ",
      "                ",
      "                ",
      "                ",
      "                ",
      "                ",
      "                ",
      "                ",
      "                "
    ],
    [
      " abbcaedaeedacda",
      "  abe bbdbadaeab",
      "   bce beddbbgcd",
      "    eacc     ege",
      "     dbccdae  dc",
      "      dccbdbdb d",
      "           beaa ",
      "            dcde",
      "              ba",
      "                ",
      "                ",
      "                ",
      "                ",
      "                ",
      "                ",
      "                "
    ],
    [
      "o   c           ",
      " o   b          ",
      "  o   c         ",
      "   o   cebaada  ",
      "    o       aabb",
      "     o       bd ",
      "      ooooo    a",
      "           o    ",
      "            oo  ",
      "              oo",
      "                ",
      "                ",
      "                ",
      "                ",
      "                ",
      "                "
    ],
    [
      "    e           ",
      "     c          ",
      "      a         ",
      "       cdbbccb  ",
      "            dbeϔ",
      "             cd ",
      "               e",
      "                ",
      "                ",
      "                ",
      "                ",
      "                ",
      "                ",
      "                ",
      "                ",
      "                "
    ],
    [
      "    d           ",
      "     d          ",
      "      e         ",
      "       bbbdebc  ",
      "            ebae",
      "             ede",
      "               b",
      "                ",
      "                ",
      "                ",
      "                ",
      "                ",
      "                ",
      "                ",
      "                ",
      "                "
    ]
  ]
}