{
  "xsize": 16,
  "zsize": 16,
  "palette": {
    "palette": [
      {
        "char": " ",
        "block": "minecraft:air"
      },
      {
        "char": "d",
        "block": "minecraft:cobbled_deepslate"
      },
      {
        "char": "b",
        "block": "minecraft:basalt[axis=x]"
      },
      {
        "char": "a",
        "block": "minecraft:blackstone"
      },
      {
        "char": "e",
        "block": "minecraft:cyan_terracotta"
      },
      {
        "char": "c",
        "block": "minecraft:deepslate[axis=y]"
      },
      {
        "char": "f",
        "block": "minecraft:light_gray_concrete"
      },
      {
        "char": "C",
        "block": "minecraft:quartz_stairs[facing=east,half=bottom,shape=straight,waterlogged=false]"
      },
      {
        "char": "q",
        "block": "minecraft:gold_block"
      },
      {
        "char": "蕊",
        "block": "minecraft:iron_door[facing=west,half=lower,hinge=left,open=true,powered=true]"
      },
      {
        "char": "淘",
        "block": "minecraft:air",
        "tag": {
          "z": 938,
          "x": -369,
          "ForgeCaps": {},
          "id": "refurbished_furniture:computer",
          "y": 122,
          "NodePos": "-101429943820166L",
          "Connections": [
            "L"
          ]
        }
      },
      {
        "char": "z",
        "block": "minecraft:quartz_stairs[facing=west,half=bottom,shape=straight,waterlogged=false]"
      },
      {
        "char": "囡",
        "block": "minecraft:iron_door[facing=west,half=upper,hinge=left,open=true,powered=true]"
      },
      {
        "char": "g",
        "block": "minecraft:redstone_lamp[lit=false]"
      }
    ]
  },
  "slices": [
    [
      "                ",
      "                ",
      "                ",
      "                ",
      "                ",
      "                ",
      "                ",
      "                ",
      "                ",
      "                ",
      "                ",
      "                ",
      "                ",
      "db              ",
      "addedacc        ",
      " acbdbaadcdbbe  "
    ],
    [
      "                ",
      "                ",
      "                ",
      "                ",
      "                ",
      "                ",
      "                ",
      "                ",
      "                ",
      "                ",
      "                ",
      "                ",
      "bea             ",
      "ffeeeeaac       ",
      "ff      adcdeeb ",
      " ff        Cffec"
    ],
    [
      "                ",
      "                ",
      "                ",
      "                ",
      "                ",
      "                ",
      "                ",
      "                ",
      "                ",
      "                ",
      "                ",
      "aaba            ",
      "ff cdaacbb      ",
      " bf    qqdccbcad",
      "  f         f Cd",
      "  f         蕊  a"
    ],
    [
      "                ",
      "                ",
      "                ",
      "                ",
      "                ",
      "                ",
      "                ",
      "                ",
      "                ",
      "                ",
      "eeacc           ",
      "    dbdacdc     ",
      "ff     qq deabac",
      " 淘f    qq    fz ",
      "  f         f   ",
      "  f         囡  c"
    ],
    [
      "                ",
      "                ",
      "                ",
      "                ",
      "                ",
      "                ",
      "                ",
      "                ",
      "                ",
      "ddaedd          ",
      "    gaadccceb   ",
      "       qq gdcbad",
      "ff     qq     ff",
      "  f    qq    f  ",
      "  f         f   ",
      "  f         f  e"
    ],
    [
      "                ",
      "                ",
      "                ",
      "                ",
      "                ",
      "                ",
      "                ",
      "                ",
      "                ",
      "cccebd          ",
      "      abdeeda   ",
      "       qq   edee",
      "ff     qq     ff",
      "  f    qq    f  ",
      "  f         f   ",
      "  f         f  e"
    ]
  ]
}