{
  "xsize": 16,
  "zsize": 16,
  "palette": {
    "palette": [
      {
        "char": " ",
        "block": "minecraft:air"
      },
      {
        "char": "m",
        "block": "minecraft:water[level=8]"
      }
    ]
  },
  "slices": [
    [
      "      mmmmmmmmmm",
      "    mmmmmmmmmmmm",
      "   mmmmmmmmmmmmm",
      "    mmmmmmmmmmmm",
      "      mmmmmmmmmm",
      "                ",
      "                ",
      "                ",
      "                ",
      "                ",
      "                ",
      "                ",
      "                ",
      "                ",
      "                ",
      "                "
    ],
    [
      "      mmmmmmmmmm",
      "    mmmmmmmmmmmm",
      "   mmmmmmmmmmmmm",
      "    mmmmmmmmmmmm",
      "      mmmmmmmmmm",
      "                ",
      "                ",
      "                ",
      "                ",
      "                ",
      "                ",
      "                ",
      "                ",
      "                ",
      "                ",
      "                "
    ],
    [
      "      mmmmmmmmmm",
      "    mmmmmmmmmmmm",
      "   mmmmmmmmmmmmm",
      "    mmmmmmmmmmmm",
      "      mmmmmmmmmm",
      "                ",
      "                ",
      "                ",
      "                ",
      "                ",
      "                ",
      "                ",
      "                ",
      "                ",
      "                ",
      "                "
    ],
    [
      "      mmmmmmmmmm",
      "    mmmmmmmmmmmm",
      "   mmmmmmmmmmmmm",
      "    mmmmmmmmmmmm",
      "      mmmmmmmmmm",
      "                ",
      "                ",
      "                ",
      "                ",
      "                ",
      "                ",
      "                ",
      "                ",
      "                ",
      "                ",
      "                "
    ],
    [
      "      mmmmmmmmmm",
      "    mmmmmmmmmmmm",
      "   mmmmmmmmmmmmm",
      "    mmmmmmmmmmmm",
      "      mmmmmmmmmm",
      "                ",
      "                ",
      "                ",
      "                ",
      "                ",
      "                ",
      "                ",
      "                ",
      "                ",
      "                ",
      "                "
    ],
    [
      "      mmmmmmmmmm",
      "    mmmmmmmmmmmm",
      "   mmmmmmmmmmmmm",
      "    mmmmmmmmmmmm",
      "      mmmmmmmmmm",
      "                ",
      "                ",
      "                ",
      "                ",
      "                ",
      "                ",
      "                ",
      "                ",
      "                ",
      "                ",
      "                "
    ]
  ]
}