{
  "xsize": 16,
  "zsize": 16,
  "palette": {
    "palette": [
      {
        "char": " ",
        "block": "minecraft:air"
      },
      {
        "char": "e",
        "block": "minecraft:cyan_terracotta"
      },
      {
        "char": "c",
        "block": "minecraft:deepslate[axis=y]"
      },
      {
        "char": "b",
        "block": "minecraft:basalt[axis=x]"
      },
      {
        "char": "d",
        "block": "minecraft:cobbled_deepslate"
      },
      {
        "char": "a",
        "block": "minecraft:blackstone"
      },
      {
        "char": "l",
        "block": "minecraft:yellow_concrete"
      },
      {
        "char": "g",
        "block": "minecraft:redstone_lamp[lit=false]"
      },
      {
        "char": "n",
        "block": "minecraft:black_concrete"
      },
      {
        "char": "f",
        "block": "minecraft:light_gray_concrete"
      },
      {
        "char": "z",
        "block": "minecraft:quartz_stairs[facing=west,half=bottom,shape=straight,waterlogged=false]"
      },
      {
        "char": "y",
        "block": "minecraft:quartz_slab[type=top,waterlogged=false]"
      },
      {
        "char": "C",
        "block": "minecraft:quartz_stairs[facing=east,half=bottom,shape=straight,waterlogged=false]"
      },
      {
        "char": "芹",
        "block": "minecraft:air"
      },
      {
        "char": "赠",
        "block": "minecraft:quartz_stairs[facing=north,half=bottom,shape=outer_right,waterlogged=false]"
      },
      {
        "char": "s",
        "block": "minecraft:quartz_slab[type=bottom,waterlogged=false]"
      },
      {
        "char": "o",
        "block": "minecraft:black_stained_glass"
      },
      {
        "char": "赎",
        "block": "minecraft:air",
        "tag": {
          "z": 969,
          "x": -541,
          "ForgeCaps": {},
          "id": "refurbished_furniture:computer",
          "y": 121,
          "NodePos": "-148708943687559L",
          "Connections": [
            "L"
          ]
        }
      },
      {
        "char": "眺",
        "block": "minecraft:air"
      }
    ]
  },
  "slices": [
    [
      "ecbcedadcccbelde",
      "ccaedacdcaddelcd",
      "ladaeadddcdbclde",
      "lcbaccbbcebedlca",
      "bdbabdcbccabblll",
      "bccbbbddcbeedada",
      "ldacbadeeeecbaec",
      "ldaeebcaadbaaeca",
      "bdbdbaaacbbadcdb",
      "bdacdbdbaababbec",
      "laaacebcbdebbbbc",
      "ldddeceabaecbabb",
      "aedeccccbdbcbbbc",
      "lcbgggcbbgggbedg",
      "dbcbcbeceeadcaba",
      "labbdacbbeccbcac"
    ],
    [
      "nfcdbaafz       ",
      "nfffcaff        ",
      "   ffff         ",
      "                ",
      "                ",
      "                ",
      "                ",
      "                ",
      "                ",
      "                ",
      "                ",
      "                ",
      "y               ",
      "yn              ",
      "y               ",
      "                "
    ],
    [
      "nfb C  芹       赠",
      "nff   ff        ",
      "   fff          ",
      "                ",
      "                ",
      "                ",
      "                ",
      "                ",
      "                ",
      "                ",
      "                ",
      "                ",
      "s               ",
      "oss             ",
      "s               ",
      "                "
    ],
    [
      "nf赎    眺        ",
      "  f   ff        ",
      "   fff          ",
      "                ",
      "                ",
      "                ",
      "                ",
      "                ",
      "                ",
      "                ",
      "                ",
      "                ",
      "                ",
      "                ",
      "                ",
      "                "
    ],
    [
      " f     f        ",
      "  f   f         ",
      "   fff          ",
      "                ",
      "                ",
      "                ",
      "                ",
      "                ",
      "                ",
      "                ",
      "                ",
      "                ",
      "                ",
      "                ",
      "                ",
      "                "
    ],
    [
      " f     f        ",
      "  f   f         ",
      "   fff          ",
      "                ",
      "                ",
      "                ",
      "                ",
      "                ",
      "                ",
      "                ",
      "                ",
      "                ",
      "                ",
      "                ",
      "                ",
      "                "
    ]
  ]
}