{
  "xsize": 16,
  "zsize": 16,
  "palette": {
    "palette": [
      {
        "char": " ",
        "block": "minecraft:air"
      },
      {
        "char": "h",
        "block": "minecraft:red_terracotta"
      },
      {
        "char": "e",
        "block": "minecraft:cyan_terracotta"
      },
      {
        "char": "c",
        "block": "minecraft:deepslate[axis=y]"
      },
      {
        "char": "a",
        "block": "minecraft:blackstone"
      },
      {
        "char": "b",
        "block": "minecraft:basalt[axis=x]"
      },
      {
        "char": "d",
        "block": "minecraft:cobbled_deepslate"
      },
      {
        "char": "ϖ",
        "block": "minecraft:cauldron"
      },
      {
        "char": "渴",
        "block": "minecraft:dark_oak_door[facing=north,half=lower,hinge=right,open=false,powered=false]"
      },
      {
        "char": "介",
        "block": "minecraft:iron_trapdoor[facing=east,half=bottom,open=false,powered=false,waterlogged=false]"
      },
      {
        "char": "A",
        "block": "minecraft:iron_trapdoor[facing=south,half=bottom,open=false,powered=false,waterlogged=false]"
      },
      {
        "char": "缠",
        "block": "minecraft:dark_oak_door[facing=north,half=lower,hinge=left,open=false,powered=false]"
      },
      {
        "char": "燃",
        "block": "minecraft:dark_oak_trapdoor[facing=south,half=top,open=true,powered=false,waterlogged=false]"
      },
      {
        "char": "签",
        "block": "minecraft:dark_oak_trapdoor[facing=south,half=bottom,open=false,powered=false,waterlogged=false]"
      },
      {
        "char": "g",
        "block": "minecraft:redstone_lamp[lit=false]"
      },
      {
        "char": "琳",
        "block": "minecraft:dark_oak_door[facing=north,half=upper,hinge=right,open=false,powered=false]"
      },
      {
        "char": "叉",
        "block": "minecraft:dark_oak_door[facing=north,half=upper,hinge=left,open=false,powered=false]"
      },
      {
        "char": "采",
        "block": "minecraft:tripwire_hook[attached=false,facing=north,powered=false]"
      },
      {
        "char": "胞",
        "block": "minecraft:dark_oak_trapdoor[facing=north,half=top,open=true,powered=false,waterlogged=false]"
      },
      {
        "char": "奔",
        "block": "minecraft:tripwire_hook[attached=false,facing=south,powered=false]"
      },
      {
        "char": "疲",
        "block": "minecraft:white_wall_banner[facing=north]",
        "tag": {
          "z": 951,
          "Patterns": [
            {
              "Color": 8,
              "Pattern": "ss"
            },
            {
              "Color": 0,
              "Pattern": "bo"
            },
            {
              "Color": 0,
              "Pattern": "gra"
            },
            {
              "Color": 0,
              "Pattern": "gru"
            }
          ],
          "x": -551,
          "ForgeCaps": {},
          "id": "minecraft:banner",
          "y": 117
        }
      }
    ]
  },
  "slices": [
    [
      "                ",
      "                ",
      "                ",
      "                ",
      "                ",
      "                ",
      "                ",
      "                ",
      "                ",
      "hhhhhhhhhh      ",
      "  hh            ",
      "                ",
      "                ",
      "                ",
      "                ",
      "         h      "
    ],
    [
      "                ",
      "                ",
      "                ",
      "                ",
      "                ",
      "                ",
      "                ",
      "                ",
      "                ",
      "hhhhhhhhhhhh    ",
      "  hh            ",
      "                ",
      "                ",
      "                ",
      "                ",
      "                "
    ],
    [
      "                ",
      "                ",
      "                ",
      "                ",
      "                ",
      "                ",
      " e              ",
      "ca  b a         ",
      "abaabde         ",
      "bdacecbcbcccca  ",
      "hhhhhhhhhhhh    ",
      "                ",
      "                ",
      "                ",
      "                ",
      "                "
    ],
    [
      "                ",
      "                ",
      "                ",
      "                ",
      "                ",
      " e              ",
      "bϖa e a         ",
      "a渴ee介dAa        ",
      "   b渴b缠ebceebbc ",
      "ϖϖ   燃 a     ccb",
      "cacbadb         ",
      "hhhhhhhhhhhhh   ",
      "                ",
      "                ",
      "                ",
      "hhhhhhhhh    h  "
    ],
    [
      "                ",
      "                ",
      "                ",
      "                ",
      "                ",
      "aada            ",
      "b签gcebdda       ",
      "c琳da c gcecbcaa ",
      "   b琳e叉e     gde",
      "采采     e        ",
      "dbccbba         ",
      "                ",
      "hhhhhhhhhhhhhhhh",
      " g   g    g     ",
      "hhhhhhhhh   hhhh",
      "        e       "
    ],
    [
      "                ",
      "                ",
      "                ",
      "                ",
      "                ",
      "babc            ",
      "d gadadbd       ",
      "a胞ee奔d奔gcbdbada ",
      "燃 燃c胞a胞d     gaa",
      "疲疲 燃   d        ",
      "edebbdea        ",
      "                ",
      "                ",
      "hhhhhhhhhhhhhhhh",
      "        e       ",
      "        e       "
    ]
  ]
}