{
  "xsize": 16,
  "zsize": 16,
  "palette": {
    "palette": [
      {
        "char": " ",
        "block": "minecraft:air"
      },
      {
        "char": "e",
        "block": "minecraft:cyan_terracotta"
      },
      {
        "char": "c",
        "block": "minecraft:deepslate[axis=y]"
      },
      {
        "char": "d",
        "block": "minecraft:cobbled_deepslate"
      },
      {
        "char": "b",
        "block": "minecraft:basalt[axis=x]"
      },
      {
        "char": "f",
        "block": "minecraft:light_gray_concrete"
      },
      {
        "char": "a",
        "block": "minecraft:blackstone"
      },
      {
        "char": "i",
        "block": "minecraft:white_concrete"
      },
      {
        "char": "g",
        "block": "minecraft:redstone_lamp[lit=false]"
      },
      {
        "char": "o",
        "block": "minecraft:black_stained_glass"
      },
      {
        "char": "须",
        "block": "minecraft:smooth_quartz_stairs[facing=north,half=bottom,shape=straight,waterlogged=false]"
      }
    ]
  },
  "slices": [
    [
      "       ecccdbf  ",
      "      ddadeebaff",
      "      bcbeccbcdb",
      "    eeacdcebeeac",
      "eaeecccadddacadb",
      "iiiiiiiiiiiiiiii",
      "aeecddcaeeddccae",
      "dbcedeaabcabddac",
      "eebbbadddcaddace",
      "bddeaadbaeebdeae",
      "ecbaaccebedadddc",
      "dddebaeacaacdcdb",
      "badaecabebdaccdb",
      "dbcigibbdigidbei",
      "bbbbcbbcacededad",
      "caeaeaedcbdecbde"
    ],
    [
      "       o     须ii",
      "      o       须须",
      "      o         ",
      "    oo          ",
      "oooo            ",
      "                ",
      "                ",
      "                ",
      "                ",
      "                ",
      "                ",
      "                ",
      "                ",
      "                ",
      "                ",
      "                "
    ],
    [
      "ooooooo       ii",
      "oooooo          ",
      "oooooo          ",
      "oooo            ",
      "                ",
      "                ",
      "                ",
      "                ",
      "                ",
      "                ",
      "                ",
      "                ",
      "                ",
      "                ",
      "                ",
      "                "
    ],
    [
      "              须须",
      "                ",
      "                ",
      "                ",
      "                ",
      "                ",
      "                ",
      "                ",
      "                ",
      "                ",
      "                ",
      "                ",
      "                ",
      "                ",
      "                ",
      "                "
    ],
    [
      "                ",
      "                ",
      "                ",
      "                ",
      "                ",
      "                ",
      "                ",
      "                ",
      "                ",
      "                ",
      "                ",
      "                ",
      "                ",
      "                ",
      "                ",
      "                "
    ],
    [
      "                ",
      "                ",
      "                ",
      "                ",
      "                ",
      "                ",
      "                ",
      "                ",
      "                ",
      "                ",
      "                ",
      "                ",
      "                ",
      "                ",
      "                ",
      "                "
    ]
  ]
}