{
  "xsize": 16,
  "zsize": 16,
  "palette": {
    "palette": [
      {
        "char": " ",
        "block": "minecraft:air"
      },
      {
        "char": "b",
        "block": "minecraft:basalt[axis=x]"
      },
      {
        "char": "a",
        "block": "minecraft:blackstone"
      },
      {
        "char": "c",
        "block": "minecraft:deepslate[axis=y]"
      },
      {
        "char": "d",
        "block": "minecraft:cobbled_deepslate"
      },
      {
        "char": "e",
        "block": "minecraft:cyan_terracotta"
      },
      {
        "char": "g",
        "block": "minecraft:redstone_lamp[lit=false]"
      },
      {
        "char": "n",
        "block": "minecraft:black_concrete"
      },
      {
        "char": "y",
        "block": "minecraft:quartz_slab[type=top,waterlogged=false]"
      },
      {
        "char": "z",
        "block": "minecraft:quartz_stairs[facing=west,half=bottom,shape=straight,waterlogged=false]"
      },
      {
        "char": "振",
        "block": "minecraft:smooth_quartz_slab[type=bottom,waterlogged=false]"
      },
      {
        "char": "s",
        "block": "minecraft:quartz_slab[type=bottom,waterlogged=false]"
      },
      {
        "char": "C",
        "block": "minecraft:quartz_stairs[facing=east,half=bottom,shape=straight,waterlogged=false]"
      },
      {
        "char": "乏",
        "block": "minecraft:furnace[facing=north,lit=false]",
        "tag": {
          "z": 946,
          "x": -346,
          "CookTimeTotal": 0,
          "ForgeData": {
            "LockFlag": "1b"
          },
          "CookTime": 0,
          "ForgeCaps": {
            "polymorph:block_entity_recipe_data": {}
          },
          "id": "minecraft:furnace",
          "y": 120,
          "Items": [],
          "BurnTime": 0,
          "RecipesUsed": {}
        }
      },
      {
        "char": "Q",
        "block": "minecraft:quartz_slab[type=double,waterlogged=false]"
      },
      {
        "char": "歪",
        "block": "minecraft:quartz_stairs[facing=north,half=bottom,shape=outer_left,waterlogged=false]"
      },
      {
        "char": "o",
        "block": "minecraft:black_stained_glass"
      },
      {
        "char": "赠",
        "block": "minecraft:quartz_stairs[facing=north,half=bottom,shape=outer_right,waterlogged=false]"
      },
      {
        "char": "H",
        "block": "minecraft:quartz_stairs[facing=south,half=top,shape=straight,waterlogged=false]"
      },
      {
        "char": "x",
        "block": "minecraft:quartz_stairs[facing=north,half=bottom,shape=straight,waterlogged=false]"
      }
    ]
  },
  "slices": [
    [
      "                ",
      "                ",
      "                ",
      "babcdc          ",
      "dcabddecbaaab   ",
      "cedbecaceddbcbdd",
      "eadcaaaeacbacdeb",
      "bcabdeabeeceaaed",
      "abecdebedaaabedd",
      "dddacbbdebbbbeee",
      "dcdbbbabedbbceed",
      "daceedbaeddddcca",
      "eacbcdedceabaaea",
      "ddagggaadgggceeg",
      "adabcddabaaceadc",
      "bebedebbdddcabde"
    ],
    [
      "                ",
      "c               ",
      "baeeacd         ",
      "n     aacdecbc  ",
      "             acd",
      "      n n       ",
      "y               ",
      "                ",
      "      y y       ",
      "       y        ",
      "       y        ",
      "       n        ",
      "                ",
      "                ",
      "                ",
      "       n        "
    ],
    [
      "ce              ",
      " edcbeee        ",
      "       aeddbee  ",
      "z             ce",
      "                ",
      "振sC   C乏z       ",
      "ss     Q        ",
      "z   zs振Q振sC     ",
      "歪    ssQss      ",
      "      Coz       ",
      "      赠o歪       ",
      "       s        ",
      "       s        ",
      "               s",
      "       s        ",
      "       s        "
    ],
    [
      "  abccddc       ",
      "        ceaceed ",
      "              bb",
      "y               ",
      "                ",
      "      yHy       ",
      "       x        ",
      "                ",
      "                ",
      "                ",
      "                ",
      "                ",
      "                ",
      "                ",
      "                ",
      "                "
    ],
    [
      "        gaeebaca",
      "              ga",
      "                ",
      "                ",
      "                ",
      "                ",
      "                ",
      "                ",
      "                ",
      "                ",
      "                ",
      "                ",
      "                ",
      "                ",
      "                ",
      "                "
    ],
    [
      "          eccbbc",
      "                ",
      "                ",
      "                ",
      "                ",
      "                ",
      "                ",
      "                ",
      "                ",
      "                ",
      "                ",
      "                ",
      "                ",
      "                ",
      "                ",
      "                "
    ]
  ]
}