{
  "xsize": 16,
  "zsize": 16,
  "palette": {
    "palette": [
      {
        "char": " ",
        "block": "minecraft:air"
      },
      {
        "char": "e",
        "block": "minecraft:cyan_terracotta"
      },
      {
        "char": "d",
        "block": "minecraft:cobbled_deepslate"
      },
      {
        "char": "c",
        "block": "minecraft:deepslate[axis=y]"
      },
      {
        "char": "b",
        "block": "minecraft:basalt[axis=x]"
      },
      {
        "char": "a",
        "block": "minecraft:blackstone"
      },
      {
        "char": "f",
        "block": "minecraft:light_gray_concrete"
      },
      {
        "char": "g",
        "block": "minecraft:redstone_lamp[lit=false]"
      },
      {
        "char": "刑",
        "block": "minecraft:air"
      },
      {
        "char": "u",
        "block": "minecraft:white_carpet"
      },
      {
        "char": "夜",
        "block": "minecraft:blue_carpet"
      },
      {
        "char": "赏",
        "block": "minecraft:air"
      },
      {
        "char": "r",
        "block": "minecraft:red_carpet"
      },
      {
        "char": "囊",
        "block": "minecraft:air"
      },
      {
        "char": "鸣",
        "block": "minecraft:air"
      },
      {
        "char": "钩",
        "block": "minecraft:air"
      },
      {
        "char": "k",
        "block": "minecraft:bookshelf"
      },
      {
        "char": "未",
        "block": "minecraft:air",
        "tag": {
          "z": 948,
          "x": -513,
          "ForgeCaps": {},
          "id": "refurbished_furniture:ceiling_light",
          "y": 117,
          "NodePos": "-141012362379147L",
          "Connections": [
            "L"
          ]
        }
      },
      {
        "char": "父",
        "block": "minecraft:air",
        "tag": {
          "z": 953,
          "x": -457,
          "ForgeCaps": {},
          "id": "refurbished_furniture:ceiling_light",
          "y": 117,
          "NodePos": "-125619199569803L",
          "Connections": [
            "L"
          ]
        }
      }
    ]
  },
  "slices": [
    [
      "                ",
      "                ",
      "                ",
      "                ",
      "                ",
      "                ",
      "                ",
      "                ",
      "                ",
      "                ",
      "                ",
      "                ",
      "                ",
      "             edc",
      "         ebdab  ",
      "     ddead fg   "
    ],
    [
      "                ",
      "                ",
      "                ",
      "                ",
      "                ",
      "                ",
      "                ",
      "                ",
      "                ",
      "                ",
      "                ",
      "                ",
      "            ebdb",
      "        bbdebg  ",
      "    deadeg fg   ",
      "cbebag     fg   "
    ],
    [
      "                ",
      "                ",
      "                ",
      "                ",
      "                ",
      "                ",
      "                ",
      "                ",
      "                ",
      "                ",
      "                ",
      "           eeccb",
      "       cbccbdbac",
      "   ececbdcdbeace",
      "bceecaaeabbbeddc",
      "cdcebaaaacadbaab"
    ],
    [
      "                ",
      "                ",
      "                ",
      "                ",
      "                ",
      "                ",
      "                ",
      "                ",
      "                ",
      "               b",
      "          aceddb",
      "      cbeab刑u夜赏夜",
      "  abaaaurur囊鸣鸣钩u",
      "ccd   f夜u夜u夜u夜u夜",
      "       ururururu",
      "       夜u夜u夜u夜kk"
    ],
    [
      "                ",
      "                ",
      "                ",
      "                ",
      "                ",
      "                ",
      "                ",
      "                ",
      "                ",
      "               d",
      "          deeeaa",
      "      acdde     ",
      "  acdea         ",
      "cea   f         ",
      "                ",
      "              kk"
    ],
    [
      "                ",
      "                ",
      "                ",
      "                ",
      "                ",
      "                ",
      "                ",
      "                ",
      "              dd",
      "         eabecbf",
      "     aceaaffffff",
      " abebaffggf 未未  ",
      "ccg   f父        ",
      "      f         ",
      "      f         ",
      "      f       kk"
    ]
  ]
}