{
  "xsize": 16,
  "zsize": 16,
  "palette": {
    "palette": [
      {
        "char": " ",
        "block": "minecraft:air"
      },
      {
        "char": "w",
        "block": "minecraft:quartz_pillar[axis=y]"
      },
      {
        "char": "y",
        "block": "minecraft:gray_concrete"
      },
      {
        "char": "o",
        "block": "minecraft:cyan_terracotta"
      },
      {
        "char": "i",
        "block": "minecraft:glass"
      },
      {
        "char": "u",
        "block": "minecraft:light_gray_concrete"
      },
      {
        "char": "r",
        "block": "minecraft:light_gray_carpet"
      },
      {
        "char": "m",
        "block": "minecraft:white_concrete"
      },
      {
        "char": "一",
        "block": "minecraft:vine[east=true,north=true,south=false,up=false,west=false]"
      },
      {
        "char": "ӻ",
        "block": "minecraft:vine[east=true,north=false,south=true,up=false,west=false]"
      },
      {
        "char": "ύ",
        "block": "minecraft:vine[east=false,north=false,south=false,up=false,west=true]"
      },
      {
        "char": "7",
        "block": "minecraft:vine[east=false,north=true,south=false,up=false,west=false]"
      },
      {
        "char": "s",
        "block": "minecraft:polished_diorite"
      },
      {
        "char": "G",
        "block": "minecraft:quartz_slab[type=bottom,waterlogged=false]"
      },
      {
        "char": "P",
        "block": "minecraft:diorite_slab[type=bottom,waterlogged=false]"
      },
      {
        "char": "v",
        "block": "minecraft:smooth_quartz"
      },
      {
        "char": "ͱ",
        "block": "minecraft:smooth_quartz_slab[type=bottom,waterlogged=false]"
      },
      {
        "char": "h",
        "block": "minecraft:polished_andesite"
      },
      {
        "char": "l",
        "block": "minecraft:andesite"
      },
      {
        "char": "A",
        "block": "minecraft:quartz_block"
      },
      {
        "char": "Е",
        "block": "minecraft:coarse_dirt"
      },
      {
        "char": "0",
        "block": "minecraft:diorite"
      },
      {
        "char": "D",
        "block": "minecraft:smooth_stone_slab[type=bottom,waterlogged=false]"
      },
      {
        "char": "O",
        "block": "minecraft:smooth_quartz_slab[type=top,waterlogged=false]"
      },
      {
        "char": "x",
        "block": "minecraft:oak_leaves[distance=7,persistent=true,waterlogged=false]"
      },
      {
        "char": "U",
        "block": "minecraft:air"
      },
      {
        "char": "主",
        "block": "minecraft:air"
      }
    ]
  },
  "slices": [
    [
      "w               ",
      "y               ",
      "oi              ",
      "o               ",
      "       i        ",
      "        i w     ",
      "         iuorrro",
      "          mmiiim",
      "                ",
      "一               ",
      " ӻ              ",
      "                ",
      " ύ              ",
      "7               ",
      "                ",
      "                "
    ],
    [
      "w               ",
      "o               ",
      "ui              ",
      "u               ",
      "      i         ",
      "        i w     ",
      "         ioorrru",
      "          ssi is",
      "                ",
      "一               ",
      " ӻ              ",
      "                ",
      " ύ              ",
      "7               ",
      "                ",
      "                "
    ],
    [
      "w               ",
      "uGG             ",
      "ommGGG          ",
      "ou mssPG        ",
      "  oo  ssG       ",
      "    y   mGw     ",
      "     o   suorrru",
      "      o   vsiiim",
      "       o        ",
      "一      u        ",
      " ӻ      o       ",
      "        u       ",
      " ύ      u       ",
      "7       u       ",
      "        u       ",
      "        u       "
    ],
    [
      "wͱP             ",
      "oouPGP          ",
      "ooooooGG        ",
      "uohmmlouP       ",
      "  uuhhlloP      ",
      "    uhhllywͱͱͱGP",
      "     uhhlsuoouyu",
      "      yhhlmvvvms",
      "       ohllhhhhh",
      "一      uhlllllll",
      " ӻ      olhhhhhh",
      "        ohlhllhl",
      " ύ      uhlhlhhl",
      "7       ylllllhl",
      "        ollhhhhh",
      "        ohhlhllh"
    ],
    [
      "AAA             ",
      "  ЕvAv          ",
      "yyoЕ  A0        ",
      "hhuooD  v       ",
      "OOhhuyDD A      ",
      "  OOhyu Dxvv0v00",
      "    OhyyxDxЕ    ",
      "     Ohoo DDDDDD",
      "      Ohy       ",
      "一     Ohoo      ",
      " ӻ     Oho      ",
      "       Oho      ",
      " ύ     Ohy      ",
      "7      Ohu      ",
      "       Ohu      ",
      "       Oho      "
    ],
    [
      "                ",
      "  U             ",
      "   U            ",
      "ii              ",
      "iiii            ",
      "  ii            ",
      "     i x   U    ",
      "     iix        ",
      "       i        ",
      "一     ii        ",
      " ӻ     ii       ",
      "       ii       ",
      " ύ     ii       ",
      "7     主iio      ",
      "       ii       ",
      "       ii       "
    ]
  ]
}