{
  "xsize": 16,
  "zsize": 16,
  "palette": {
    "palette": [
      {
        "char": " ",
        "block": "minecraft:air"
      },
      {
        "char": "u",
        "block": "minecraft:light_gray_concrete"
      },
      {
        "char": "v",
        "block": "minecraft:smooth_quartz"
      },
      {
        "char": "w",
        "block": "minecraft:quartz_pillar[axis=y]"
      },
      {
        "char": "o",
        "block": "minecraft:cyan_terracotta"
      },
      {
        "char": "s",
        "block": "minecraft:polished_diorite"
      },
      {
        "char": "m",
        "block": "minecraft:white_concrete"
      },
      {
        "char": "t",
        "block": "minecraft:acacia_wood[axis=y]"
      },
      {
        "char": "r",
        "block": "minecraft:light_gray_carpet"
      },
      {
        "char": "C",
        "block": "minecraft:jungle_planks"
      },
      {
        "char": "i",
        "block": "minecraft:glass"
      },
      {
        "char": "n",
        "block": "minecraft:birch_planks"
      },
      {
        "char": "3",
        "block": "minecraft:stone_brick_wall[east=none,north=none,south=none,up=true,waterlogged=false,weathering=false,west=none]"
      },
      {
        "char": "y",
        "block": "minecraft:gray_concrete"
      },
      {
        "char": "Ӫ",
        "block": "minecraft:polished_diorite_slab[type=bottom,waterlogged=false]"
      },
      {
        "char": "l",
        "block": "minecraft:andesite"
      },
      {
        "char": "h",
        "block": "minecraft:polished_andesite"
      },
      {
        "char": "G",
        "block": "minecraft:quartz_slab[type=bottom,waterlogged=false]"
      },
      {
        "char": "P",
        "block": "minecraft:diorite_slab[type=bottom,waterlogged=false]"
      },
      {
        "char": "A",
        "block": "minecraft:quartz_block"
      },
      {
        "char": "D",
        "block": "minecraft:smooth_stone_slab[type=bottom,waterlogged=false]"
      },
      {
        "char": "4",
        "block": "minecraft:red_carpet"
      },
      {
        "char": "0",
        "block": "minecraft:diorite"
      },
      {
        "char": "Е",
        "block": "minecraft:coarse_dirt"
      },
      {
        "char": "U",
        "block": "minecraft:air"
      }
    ]
  },
  "slices": [
    [
      "        uv      ",
      "       wos      ",
      "        om     t",
      "        r      C",
      "        ri     n",
      "        ri     t",
      "        om      ",
      "       wom      ",
      "         u      ",
      "         r      ",
      "          ri    ",
      "          3r i  ",
      "            rosm",
      "              oo",
      "              w ",
      "                "
    ],
    [
      "        um      ",
      "       wov      ",
      "        ov      ",
      "        ri      ",
      "        ri      ",
      "        ri      ",
      "        ym      ",
      "       wov      ",
      "         oi     ",
      "         ri     ",
      "          ri    ",
      "          3rii  ",
      "            rosm",
      "              oy",
      "              w ",
      "                "
    ],
    [
      "        um      ",
      "       wom      ",
      "        om      ",
      "        r       ",
      "        ri      ",
      "        ri      ",
      "        ys      ",
      "       wom      ",
      "         ui     ",
      "         ri     ",
      "          r     ",
      "          3r i  ",
      "            ryss",
      "              uo",
      "              w ",
      "                "
    ],
    [
      "       Ӫymlllhhl",
      "       wumlhlllh",
      "       Gomlhllhh",
      "       Pomlhllhh",
      "       Gumlhhlhh",
      "       Govllllll",
      "       Pomhhhhll",
      "       wymhhhhhh",
      "        Poshhlll",
      "        Pyvlllhl",
      "         Gumhlll",
      "         Gyyvvll",
      "          GGuumm",
      "            GPoo",
      "              wP",
      "                "
    ],
    [
      "       A D4     ",
      "       A D4     ",
      "       v D 4   4",
      "       v D  444 ",
      "       A D      ",
      "       v D      ",
      "       A D      ",
      "       v D      ",
      "        0 D     ",
      "        v D     ",
      "         A D    ",
      "         v ЕDD  ",
      "          vAЕ DD",
      "            AA  ",
      "              v0",
      "                "
    ],
    [
      "                ",
      "                ",
      "                ",
      "                ",
      "                ",
      "                ",
      "                ",
      "                ",
      "                ",
      "                ",
      "                ",
      "           U    ",
      "            U   ",
      "                ",
      "                ",
      "                "
    ]
  ]
}