{
  "xsize": 16,
  "zsize": 16,
  "palette": {
    "palette": [
      {
        "char": " ",
        "block": "minecraft:air"
      },
      {
        "char": "a",
        "block": "minecraft:stone[weathering=false]"
      },
      {
        "char": "d",
        "block": "minecraft:stone_bricks[weathering=false]"
      },
      {
        "char": "c",
        "block": "minecraft:mossy_stone_bricks"
      },
      {
        "char": "e",
        "block": "minecraft:cracked_stone_bricks"
      },
      {
        "char": "g",
        "block": "minecraft:mossy_cobblestone"
      },
      {
        "char": "j",
        "block": "minecraft:cobblestone[weathering=false]"
      }
    ]
  },
  "slices": [
    [
      "aaaaaaaaaaaaaaaa",
      "aaaaaaaaaaaaaaaa",
      "aaaaaaaaaaaaaaaa",
      "aaaaaaaaaaaaaaaa",
      "aaaaaaaaaaaaaaaa",
      "aaaaaaaaaaaaaaaa",
      "aaaaaaaaaaaaaaaa",
      "aaaaaaaaaaaaaaaa",
      "aaaaaaaaaaaaaaaa",
      "aaaaaaaaaaaaaaaa",
      "aaaaaaaaaaaaaaaa",
      "aaaaaaaaaaaaaaaa",
      "aaaaaaaaaaaaaaaa",
      "aaaaaaaaaaaaaaaa",
      "aaaaaaaaaaaaaaaa",
      "aaaaaaaaaaaaaaaa"
    ],
    [
      "aaaaaaaaaaaaaaaa",
      "aaaaaaaaaaaaaaaa",
      "aaaaaaaaaaaaaaaa",
      "aaaaaaaaaaaaaaaa",
      "aaaaaaaaaaaaaaaa",
      "aaaaaaaaaaaaaaaa",
      "aaaaaaaaaaaaaaaa",
      "aaaaaaaaaaaaaaaa",
      "aaaaaaaaaaaaaaaa",
      "aaaaaaaaaaaaaaaa",
      "aaaaaaaaaaaaaaaa",
      "aaaaaaaaaaaaaaaa",
      "aaaaaaaaaaaaaaaa",
      "aaaaaaaaaaaaaaaa",
      "aaaaaaaaaaaaaaaa",
      "aaaaaaaaaaaaaaaa"
    ],
    [
      "ddcceggjdddedccj",
      "ddcddeedeejddaaa",
      "ddgeedeeeeeddaaa",
      "dddcgddgjgjjgaaa",
      "ddcggddecccccaaa",
      "ddjdjgdjedddeaaa",
      "ddcddccddcdddaaa",
      "ddddgjgddjddjaaa",
      "ddccgcddjcddcaaa",
      "ddgcggcdcgejdaaa",
      "ddeejdccddddcaaa",
      "ddeggdgddgecjaaa",
      "ddddegcdgccgeaaa",
      "ddedgdcdgccgjaaa",
      "ddcegdccegcjcaaa",
      "ddecgcjgdggedaaa"
    ],
    [
      "ddccdedegdcjjddj",
      "ddddddedggddjaaa",
      "ddgecgjegjgggaaa",
      "ddeggcedcedcgaaa",
      "dddgcdjedccceaaa",
      "dddcjgddcjcdeaaa",
      "ddceejegjgjdgaaa",
      "ddejccdececccaaa",
      "ddgeeecccjccdaaa",
      "dddcegddddegeaaa",
      "ddjdggecceccgaaa",
      "dddcdeddeccggaaa",
      "ddddcdcegegjgaaa",
      "dddjcdcdddcceaaa",
      "ddecedgddeggeaaa",
      "ddgdcdecggccjaaa"
    ],
    [
      "ejcjgggddccdcedc",
      "ddecgdceecgccaaa",
      "gdddeeejeccecaaa",
      "ddjgedddcedcdaaa",
      "gjdggddddcccdaaa",
      "gcgecgdeceeddaaa",
      "ggggggdjddedcaaa",
      "cgjejgdgdcgcjaaa",
      "ccgcceccjejcdaaa",
      "jegjgdjecjdjeaaa",
      "gegjcedjcjedgaaa",
      "edcgjdjcddcddaaa",
      "egedjddecgcgeaaa",
      "jcjgccedgdjjgaaa",
      "dddcggecjdgggaaa",
      "dddeccdcjggjgaaa"
    ],
    [
      "dgggeddejjdjjegg",
      "cgeegcdccjccgaaa",
      "dceeccgcjddcdaaa",
      "gjdjcdjdecgejaaa",
      "deeceddjdedccaaa",
      "jjcdjddcgdjddaaa",
      "deeegecdjdggdaaa",
      "dgccgdcedcecdaaa",
      "edeegecdjcccgaaa",
      "dcggcdcgceeceaaa",
      "ggjecegcddcdgaaa",
      "jecjejedddjddaaa",
      "eejcjjjgedegeaaa",
      "gjeejeggjdccdaaa",
      "dddggecdjgggeaaa",
      "ddcdgccccjedcaaa"
    ]
  ]
}