{
  "xsize": 16,
  "zsize": 16,
  "palette": {
    "palette": [
      {
        "char": " ",
        "block": "minecraft:air"
      },
      {
        "char": "d",
        "block": "minecraft:stone_bricks[weathering=false]"
      },
      {
        "char": "e",
        "block": "minecraft:cracked_stone_bricks"
      },
      {
        "char": "c",
        "block": "minecraft:mossy_stone_bricks"
      },
      {
        "char": "j",
        "block": "minecraft:cobblestone[weathering=false]"
      },
      {
        "char": "g",
        "block": "minecraft:mossy_cobblestone"
      },
      {
        "char": "a",
        "block": "minecraft:stone[weathering=false]"
      },
      {
        "char": "n",
        "block": "minecraft:birch_planks"
      },
      {
        "char": "h",
        "block": "minecraft:polished_andesite"
      }
    ]
  },
  "slices": [
    [
      "ddedccjgcdcgjaaa",
      "dddeggdgedcddaaa",
      "ddcegejgggdcdaaa",
      "ddcjdecegeegdaaa",
      "ddgdcedcegcjcaaa",
      "dddddddddddddaaa",
      "dddddddddddddaaa",
      "dddddddddddddaaa",
      "dddddddddddddaaa",
      "dddddddddddddaaa",
      "aaaaaaaaaaaaaaaa",
      "aaaaaaaaaaaaaaaa",
      "aaaaaaaaaaaaaaaa",
      "aaaaaaaaaaaaaaaa",
      "aaaaaaaaaaaaaaaa",
      "aaaaaaaaaaaaaaaa"
    ],
    [
      "dddjjdeddgeegaaa",
      "ddegecdgejedeaaa",
      "dddegdcegedgcaaa",
      "ddcjcdddcdddjaaa",
      "ddedccddccdgdaaa",
      "dddddddddddddaaa",
      "dddddddddddddaaa",
      "dddddddddddddaaa",
      "dddddddddddddaaa",
      "dddddddddddddaaa",
      "aaaaaaaaaaaaaaaa",
      "aaaaaaaaaaaaaaaa",
      "aaaaaaaaaaaaaaaa",
      "aaaaaaaaaaaaaaaa",
      "aaaaaaaaaaaaaaaa",
      "aaaaaaaaaaaaaaaa"
    ],
    [
      "dddgejddjdgeeaaa",
      "dddcgcejddejdaaa",
      "ddjcjdceejjceaaa",
      "ddeccgggccjgcaaa",
      "ddgdedjgcecejaaa",
      "dddddddddddddaaa",
      "dddddddddddddaaa",
      "dddddddddddddaaa",
      "dddddddddddddaaa",
      "dddddddddddddaaa",
      "aaaaaaaaaaaaaaaa",
      "aaaaaaaaaaaaaaaa",
      "aaaaaaaaaaaaaaaa",
      "aaaaaaaaaaaaaaaa",
      "aaaaaaaaaaaaaaaa",
      "aaaaaaaaaaaaaaaa"
    ],
    [
      "ddjeedgdcejdcaaa",
      "dddgdccgeeddgaaa",
      "ddggedgegdcdcaaa",
      "ddddcjejcededaaa",
      "ddddedcdjgejcaaa",
      "dddddddddddddaaa",
      "dddddddddddddaaa",
      "dddddddddddddaaa",
      "dddddddddddddaaa",
      "dddddddddddddaaa",
      "aaaaaaaaaaaaaaaa",
      "aaaaaaaaaaaaaaaa",
      "aaaaaaaaaaaaaaaa",
      "aaaaaaaaaaaaaaaa",
      "aaaaaaaaaaaaaaaa",
      "aaaaaaaaaaaaaaaa"
    ],
    [
      "aaaaaaaaaaaaaaaa",
      "aaaaaaaaaaaaaaaa",
      "aaaaaaaaaaaaaaaa",
      "aaaaaaaaaaaaaaaa",
      "aaaaaaaaaaaaaaaa",
      "aaaaaaaaaaaaaaaa",
      "aaaaaaaaaaaaaaaa",
      "aaaaaaaaaaaaaaaa",
      "aaaaaaaaaaaaaaaa",
      "aaaaaaaaaaaaaaaa",
      "aaaaaaaaaaaaaaaa",
      "aaaaaaaaaaaaaaaa",
      "aaaaaaaaaaaaaaaa",
      "aaaaaaaaaaaaaaaa",
      "aaaaaaaaaaaaaaaa",
      "aaaaaaaaaaaaaaaa"
    ],
    [
      "aaaaaaaaaaanaehh",
      "aaaaaaaaaaaaaaaa",
      "aaaaaaaaaaaaaaaa",
      "aaaaaaaaaaaaaaaa",
      "aaaaaaaaaaaaaece",
      "aaaaaaaaaaaaahhc",
      "aaaaaaaaaaaaaceh",
      "aaaaaaaaaaaaaaaa",
      "aaaaaaaaaaaaaaaa",
      "aaaaaaaaaaaaaaaa",
      "aaaaaaaaaaaaaaaa",
      "aaaaaaaaaaaaaaaa",
      "aaaaaaaaaaaaaaaa",
      "aaaaaaaaaaaaaaaa",
      "aaaaaaaaaaaaaaaa",
      "aaaaaaaaaaaaaaaa"
    ]
  ]
}