{
  "xsize": 16,
  "zsize": 16,
  "palette": {
    "palette": [
      {
        "char": " ",
        "block": "minecraft:air"
      },
      {
        "char": "b",
        "block": "minecraft:dirt"
      },
      {
        "char": "a",
        "block": "minecraft:stone[weathering=false]"
      },
      {
        "char": "ђ",
        "block": "minecraft:spawner",
        "tag": {
          "SpawnData": {
            "entity": {}
          },
          "MaxNearbyEntities": "6s",
          "MinSpawnDelay": "200s",
          "z": 359,
          "x": 108,
          "MaxSpawnDelay": "800s",
          "RequiredPlayerRange": "16s",
          "SpawnCount": "4s",
          "ForgeCaps": {},
          "id": "minecraft:mob_spawner",
          "SpawnPotentials": [],
          "y": 132,
          "SpawnRange": "4s",
          "Delay": "416s"
        }
      },
      {
        "char": "j",
        "block": "minecraft:cobblestone[weathering=false]"
      },
      {
        "char": "g",
        "block": "minecraft:mossy_cobblestone"
      },
      {
        "char": "c",
        "block": "minecraft:mossy_stone_bricks"
      },
      {
        "char": "e",
        "block": "minecraft:cracked_stone_bricks"
      },
      {
        "char": "d",
        "block": "minecraft:stone_bricks[weathering=false]"
      }
    ]
  },
  "slices": [
    [
      "bbbbbbbbbbbbbbbb",
      "bbbbbbbbbbbbbbbb",
      "bbbbbbbbbbbbbbbb",
      "bbbbbbbbbbbbbbbb",
      "bbbbbbbbbbbbbbbb",
      "bbbbbbbbbbbbbbbb",
      "bbbbbbbbbbbbbbbb",
      "bbbbbbbbbbbbbbbb",
      "aaaaaaaaaabbbbbb",
      "babђbbbbbђbbbbbb",
      "aaaaaaaaaabbbbbb",
      "aaaaaaaaaabbbbbb",
      "aaaaaaaaaabbbbbb",
      "aaaaaaaaaabbbbbb",
      "aaaaaaaaaabbbbbb",
      "aaaaaaaaaabbbbbb"
    ],
    [
      "bbbbbbbbbbbbbbbb",
      "bbbbbbbbbbbbbbbb",
      "bbbbbbbbbbbbbbbb",
      "bbbbbbbbbbbbbbbb",
      "bbbbbbbbbbbbbbbb",
      "bbbbbbbbbbbbbbbb",
      "bbbbbbbbbbbbbbbb",
      "bbbbbbbbbbbbbbbb",
      "jjjjjjjjjjbbbbbb",
      "gcceecgjcebbbbbb",
      "aaaeaaaaaabbbbbb",
      "aaaaaaaaaabbbbbb",
      "aaaaaaaaaabbbbbb",
      "aaaaaaaaaabbbbbb",
      "aaaaaaaaaabbbbbb",
      "aaaaaaaaaabbbbbb"
    ],
    [
      "bbbbbbbbbbbbbbbb",
      "bbbbbbbbbbbbbbbb",
      "bbbbbbbbbbbbbbbb",
      "bbbbbbbbbbbbbbbb",
      "bbbbbbbbbbbbbbbb",
      "bbbbbbbbbbbbbbbb",
      "bbbbbbbbbbbbbbbb",
      "bbbbbbbbbbbbbbbb",
      "jjjjjjjjjjbbbbbb",
      "dcdjgceecjbbbbbb",
      "aaaaaaaaaabbbbbb",
      "aaaaaaaaaabbbbbb",
      "aaaaaaaaaabbbbbb",
      "aaaaaaaaaabbbbbb",
      "aaaaaaaaaabbbbbb",
      "aaaaaaaaaabbbbbb"
    ],
    [
      "bbbbbbbbbbbbbbbb",
      "bbbbbbbbbbbbbbbb",
      "bbbbbbbbbbbbbbbb",
      "bbbbbbbbbbbbbbbb",
      "bbbbbbbbbbbbbbbb",
      "bbbbbbbbbbbbbbbb",
      "bbbbbbbbbbbbbbbb",
      "bbbbbbbbbbbbbbbb",
      "ddddddddddbbbbbb",
      "bbbbbbbbbbbbbbbb",
      "aaaaaaaaaabbbbbb",
      "aaaaaaaaaabbbbbb",
      "aaaaaaaaaabbbbbb",
      "aaaaaaaaaabbbbbb",
      "aaaaaaaaaabbbbbb",
      "aaaaaaaaaabbbbbb"
    ],
    [
      "bbbbbbbbbbbbbbbb",
      "bbbbbbbbbbbbbbbb",
      "bbbbbbbbbbbbbbbb",
      "bbbbbbbbbbbbbbbb",
      "bbbbbbbbbbbbbbbb",
      "bbbbbbbbbbbbbbbb",
      "bbbbbbbbbbbbbbbb",
      "bbbbbbbbbbbbbbbb",
      "bbbbbbbbbbbbbbbb",
      "bbbbbbbbbbbbbbbb",
      "aaaaaaaaaabbbbbb",
      "aaaaaaaaaabbbbbb",
      "aaaaaaaaaabbbbbb",
      "aaaaaaaaaabbbbbb",
      "aaaaaaaaaabbbbbb",
      "aaaaaaaaaabbbbbb"
    ],
    [
      "bbbbbbbbbbbbbbbb",
      "bbbbbbbbbbbbbbbb",
      "bbbbbbbbbbbbbbbb",
      "bbbbbbbbbbbbbbbb",
      "bbbbbbbbbbbbbbbb",
      "bbbbbbbbbbbbbbbb",
      "bbbbbbbbbbbbbbbb",
      "bbbbbbbbbbbbbbbb",
      "bbbbbbbbbbbbbbbb",
      "bbbbbbbbbbbbbbbb",
      "aaaaaaaaaabbbbbb",
      "aaaaaaaaaabbbbbb",
      "aaaaaaaaaabbbbbb",
      "aaaaaaaaaabbbbbb",
      "aaaaaaaaaabbbbbb",
      "aaaaaaaaaabbbbbb"
    ]
  ]
}