{
  "xsize": 16,
  "zsize": 16,
  "palette": {
    "palette": [
      {
        "char": " ",
        "block": "minecraft:air"
      },
      {
        "char": "e",
        "block": "minecraft:cracked_stone_bricks"
      },
      {
        "char": "d",
        "block": "minecraft:stone_bricks[weathering=false]"
      },
      {
        "char": "j",
        "block": "minecraft:cobblestone[weathering=false]"
      },
      {
        "char": "c",
        "block": "minecraft:mossy_stone_bricks"
      },
      {
        "char": "g",
        "block": "minecraft:mossy_cobblestone"
      },
      {
        "char": "a",
        "block": "minecraft:stone[weathering=false]"
      },
      {
        "char": "n",
        "block": "minecraft:birch_planks"
      },
      {
        "char": "h",
        "block": "minecraft:polished_andesite"
      }
    ]
  },
  "slices": [
    [
      "edjdcddddcgccged",
      "gdcdgccdeeggdaaa",
      "cgeggcdceeeddaaa",
      "djggecdcedddgaaa",
      "edjcgjedecedeaaa",
      "ejccgcccjgdccaaa",
      "ggggcdcceecdgaaa",
      "jjgcjjjeeecdcaaa",
      "cegeedececccgaaa",
      "ccggedegdegcdaaa",
      "jgdeejgedgdgcaaa",
      "djcecedccejddaaa",
      "jdcdgecgdjcegaaa",
      "gdcdedjdegceeaaa",
      "ddgeccjeddddeaaa",
      "ddgggcjegdgdcaaa"
    ],
    [
      "ceecjdjegdeeccjj",
      "dccjjcjgccdcdaaa",
      "ccgcdjgdedgjcaaa",
      "ggeeeedejcgdgaaa",
      "cgeccjgccdedcaaa",
      "ccccjdgccdedcaaa",
      "cggjejcdeccjjaaa",
      "ddecjcdddddjjaaa",
      "egcdgcedgeedjaaa",
      "dcdeedcecdjedaaa",
      "ceggedjgdjggcaaa",
      "ecgdcgjeeddddaaa",
      "cgdcgccgdedgeaaa",
      "cgjgeddegddcdaaa",
      "ddecccedcdgeeaaa",
      "dddgddcdcjjdeaaa"
    ],
    [
      "ddcdgecjcgcdcjjd",
      "jdccjgedgcdccaaa",
      "jddccgdjcdddgaaa",
      "eeccecgddjdegaaa",
      "gddjgdgejjgecaaa",
      "gcecgcgdccdcgaaa",
      "cdcjggcjeecdjaaa",
      "egcjecdcdgeddaaa",
      "edgjegdcggddjaaa",
      "ccgcgddddgjddaaa",
      "ddgddjcggjcdgaaa",
      "djjcgdcccgddgaaa",
      "gjcgdgedcjeggaaa",
      "gdccgdggddcceaaa",
      "ddgjddeddcgcjaaa",
      "ddccdcececjcdaaa"
    ],
    [
      "dggdedddcdgjcedg",
      "jdcecgedgcdcgaaa",
      "egjcccdddgcccaaa",
      "dcccgcjddedccaaa",
      "cejgccdcegdgcaaa",
      "jccgcdedcggjcaaa",
      "edeecjcdcjdcdaaa",
      "eececcjggedeeaaa",
      "jcjeceddedcgeaaa",
      "jcgcjddjegdeeaaa",
      "gcdgcccddedgdaaa",
      "jddjdcegceecdaaa",
      "decdecdedcdgdaaa",
      "cjgcjdecjjjedaaa",
      "dddccedcjedgeaaa",
      "ddeejddgddddcaaa"
    ],
    [
      "caaaaaaaaaaaaaaa",
      "daaaaaaaaaaaaaaa",
      "caaaaaaaaaaaaaaa",
      "jaaaaaaaaaaaaaaa",
      "eaaaaaaaaaaaaaaa",
      "gaaaaaaaaaaaaaaa",
      "caaaaaaaaaaaaaaa",
      "caaaaaaaaaaaaaaa",
      "aaaaaaaaaaaaaaaa",
      "aaaaaaaaaaaaaaaa",
      "aaaaaaaaaaaaaaaa",
      "aaaaaaaaaaaaaaaa",
      "aaaaaaaaaaaaaaaa",
      "aaaaaaaaaaaaaaaa",
      "aaaaaaaaaaaaaaaa",
      "aaaaaaaaaaaaaaaa"
    ],
    [
      "aaaaaaaaaaaaaaaa",
      "aaaaaaaaaaaaaaaa",
      "aaaaaaaaaaaaaaaa",
      "aaaaaaaaaaaaaaaa",
      "aaaaaaaaaaaaaaaa",
      "aaaaaaaaaaaaaaaa",
      "aaaaaaaaaaaaaaaa",
      "aaaaaaaaaaaaaaaa",
      "aaaaaaaaaaaaaaaa",
      "aaaaaaaaaaaaaaaa",
      "aaaaaaaaaaaaaaaa",
      "aaaaaaaaaaaaaaaa",
      "aaaaaaaaaaaaaaaa",
      "aaaaaaaaaaaaaaaa",
      "aaaaaaaaaaanahce",
      "aaaaaaaaaaanahhh"
    ]
  ]
}