{
  "xsize": 16,
  "zsize": 16,
  "palette": {
    "palette": [
      {
        "char": " ",
        "block": "minecraft:air"
      },
      {
        "char": "f",
        "block": "minecraft:air"
      },
      {
        "char": "求",
        "block": "minecraft:air"
      },
      {
        "char": "b",
        "block": "minecraft:air"
      },
      {
        "char": "s",
        "block": "minecraft:air"
      },
      {
        "char": "k",
        "block": "minecraft:air"
      },
      {
        "char": "q",
        "block": "minecraft:grass"
      },
      {
        "char": "z",
        "block": "minecraft:air"
      },
      {
        "char": "ӛ",
        "block": "minecraft:air"
      },
      {
        "char": "断",
        "block": "minecraft:air"
      },
      {
        "char": "ӻ",
        "block": "minecraft:air"
      },
      {
        "char": "x",
        "block": "minecraft:air"
      },
      {
        "char": "I",
        "block": "minecraft:air"
      },
      {
        "char": "O",
        "block": "minecraft:air"
      },
      {
        "char": "Q",
        "block": "minecraft:air"
      },
      {
        "char": "w",
        "block": "minecraft:air"
      },
      {
        "char": "吗",
        "block": "minecraft:air"
      }
    ]
  },
  "slices": [
    [
      "ffffffffffffffff",
      "ffffffffffffffff",
      "ffffffffffffffff",
      "ffffffffffffffff",
      "ffffffffffffffff",
      "ffffffffffffffff",
      "ffffffffffffffff",
      "ffffffffffffffff",
      "ffffffffffffffff",
      "ffffffffffffffff",
      "ffffffffffffffff",
      "ffffffffffffffff",
      "ffffffffffffffff",
      "fffffffffff求ffff",
      "ffffffffffffffff",
      "ffffbffffffffffs"
    ],
    [
      "kkkkqkkkkqkqkqqq",
      "zqkzkkkqkkkk  qk",
      "qqqqkqkkkkqkzqqk",
      "zqkqzqkqzqkkkkkk",
      "qqkkqkz qkkkqkkk",
      "kzqqz q qqqqqzqk",
      "kkkkqkk kkkkkkqq",
      "qkqkkqkzzqqkkkqq",
      "qkzqzkqqqkqkqz k",
      "zkkkkkqq qkkkkkk",
      "kqkkqqzkkqkzkqqq",
      "zkqkqkqkkkqqkkzz",
      "qqkzq zkqqqzqkkq",
      "qq qzkzzkӛq kkkk",
      "kqkz断q kӻxqxkk k",
      "IOQQwqxxxxxxkzkz"
    ],
    [
      "                ",
      "                ",
      "                ",
      "                ",
      "                ",
      "                ",
      "                ",
      "                ",
      "                ",
      "                ",
      "                ",
      "                ",
      "                ",
      "                ",
      "    吗           ",
      "    wxx  x      "
    ],
    [
      "                ",
      "                ",
      "                ",
      "                ",
      "                ",
      "                ",
      "                ",
      "                ",
      "                ",
      "                ",
      "                ",
      "                ",
      "                ",
      "                ",
      "    吗           ",
      "    w           "
    ],
    [
      "                ",
      "                ",
      "                ",
      "                ",
      "                ",
      "                ",
      "                ",
      "                ",
      "                ",
      "                ",
      "                ",
      "                ",
      "                ",
      "                ",
      "    吗           ",
      "    wx          "
    ],
    [
      "                ",
      "                ",
      "                ",
      "                ",
      "                ",
      "                ",
      "                ",
      "                ",
      "                ",
      "                ",
      "                ",
      "                ",
      "                ",
      "                ",
      "    吗           ",
      "    w           "
    ]
  ]
}