{
  "xsize": 16,
  "zsize": 16,
  "palette": {
    "palette": [
      {
        "char": " ",
        "block": "minecraft:air"
      },
      {
        "char": "r",
        "block": "minecraft:air"
      },
      {
        "char": "m",
        "block": "minecraft:air"
      },
      {
        "char": "y",
        "block": "minecraft:air"
      },
      {
        "char": "s",
        "block": "minecraft:air"
      },
      {
        "char": "v",
        "block": "minecraft:air"
      },
      {
        "char": "u",
        "block": "minecraft:air"
      },
      {
        "char": "w",
        "block": "minecraft:air"
      },
      {
        "char": "ѕ",
        "block": "minecraft:air"
      },
      {
        "char": "E",
        "block": "minecraft:air"
      },
      {
        "char": "i",
        "block": "minecraft:air"
      },
      {
        "char": "o",
        "block": "minecraft:air"
      },
      {
        "char": "联",
        "block": "minecraft:air",
        "tag": {
          "z": 335,
          "Patterns": [
            {
              "Color": 14,
              "Pattern": "hhb"
            },
            {
              "Color": 0,
              "Pattern": "ls"
            },
            {
              "Color": 0,
              "Pattern": "ms"
            },
            {
              "Color": 0,
              "Pattern": "rs"
            },
            {
              "Color": 11,
              "Pattern": "bo"
            }
          ],
          "x": 175,
          "ForgeCaps": {},
          "id": "minecraft:banner",
          "y": 145
        }
      },
      {
        "char": "2",
        "block": "minecraft:air"
      },
      {
        "char": "x",
        "block": "minecraft:air"
      },
      {
        "char": "示",
        "block": "minecraft:air"
      },
      {
        "char": "关",
        "block": "minecraft:air"
      },
      {
        "char": "老",
        "block": "minecraft:air"
      },
      {
        "char": "l",
        "block": "minecraft:air"
      },
      {
        "char": "h",
        "block": "minecraft:air"
      },
      {
        "char": "P",
        "block": "minecraft:air"
      },
      {
        "char": "ͱ",
        "block": "minecraft:air"
      },
      {
        "char": "G",
        "block": "minecraft:air"
      },
      {
        "char": "D",
        "block": "minecraft:air"
      },
      {
        "char": "A",
        "block": "minecraft:air"
      },
      {
        "char": "0",
        "block": "minecraft:air"
      },
      {
        "char": "Е",
        "block": "minecraft:air"
      },
      {
        "char": "U",
        "block": "minecraft:tall_grass[half=lower]"
      }
    ]
  },
  "slices": [
    [
      "    r           ",
      "   my           ",
      "mmsvuw          ",
      "ѕ  Ey           ",
      "ѕ  ir           ",
      "ѕ  ir           ",
      "ѕ  ir           ",
      "ѕ  Eu           ",
      "ѕ  Eow          ",
      "ѕ  Eo           ",
      "ѕ  ir           ",
      "   ir           ",
      "    r           ",
      "   Ey           ",
      "vvmsow          ",
      "联  2oxx         "
    ],
    [
      "    r           ",
      "   so           ",
      "mmmvow          ",
      "ѕ  2y           ",
      "ѕ  ir           ",
      "ѕ  ir           ",
      "ѕ  ir           ",
      "ѕ  2u           ",
      "ѕ  2uw          ",
      "ѕ  2u           ",
      "ѕ  ir           ",
      "   ir           ",
      "   ir           ",
      "   2o           ",
      "mssmywx         ",
      "   2y           "
    ],
    [
      "   ir           ",
      "   mo           ",
      "mvvmuw          ",
      "示  2u           ",
      "关  ir           ",
      "    r           ",
      "老  ir           ",
      "关  2u           ",
      "   2uw          ",
      "老  2o           ",
      "关  ir           ",
      "   ir           ",
      "   ir           ",
      "   2uxx         ",
      "msssuwx         ",
      "   2u           "
    ],
    [
      "lhlsoP          ",
      "hhlvyP          ",
      "hhlsyw          ",
      "hhhmoͱ          ",
      "hhhmuP          ",
      "hlhvoͱ          ",
      "hllvyP          ",
      "hhlmyP          ",
      "hllsuw          ",
      "hlhmoG          ",
      "llhvuG          ",
      "hllsoG          ",
      "lllmoGx         ",
      "lhhvuͱx         ",
      "hhlsow          ",
      "lhhmuG          "
    ],
    [
      "   D v          ",
      "   D v          ",
      "   D v          ",
      "   D A          ",
      "   D v          ",
      "   D v          ",
      "   D A          ",
      "   D 0          ",
      "   D v          ",
      "   DЕA          ",
      "   DЕv          ",
      "   Dxv          ",
      "   DxAx         ",
      "   D v          ",
      "   D A          ",
      "   D A          "
    ],
    [
      "                ",
      "                ",
      "                ",
      "                ",
      "                ",
      "                ",
      "                ",
      "                ",
      "                ",
      "    U           ",
      "    U           ",
      "                ",
      "     xx         ",
      "                ",
      "                ",
      "                "
    ]
  ]
}