{
  "xsize": 16,
  "zsize": 16,
  "palette": {
    "palette": [
      {
        "char": " ",
        "block": "minecraft:air"
      },
      {
        "char": "a",
        "block": "minecraft:air"
      },
      {
        "char": "ό",
        "block": "minecraft:air"
      },
      {
        "char": "j",
        "block": "minecraft:air"
      },
      {
        "char": "d",
        "block": "minecraft:air"
      },
      {
        "char": "e",
        "block": "minecraft:air"
      },
      {
        "char": "g",
        "block": "minecraft:air"
      },
      {
        "char": "c",
        "block": "minecraft:air"
      },
      {
        "char": "f",
        "block": "minecraft:air"
      },
      {
        "char": "5",
        "block": "minecraft:air"
      },
      {
        "char": "ӝ",
        "block": "minecraft:air"
      },
      {
        "char": "8",
        "block": "minecraft:air"
      },
      {
        "char": "入",
        "block": "minecraft:air"
      },
      {
        "char": "M",
        "block": "minecraft:air"
      },
      {
        "char": "ђ",
        "block": "minecraft:air",
        "tag": {
          "SpawnData": {
            "entity": {}
          },
          "MaxNearbyEntities": "6s",
          "MinSpawnDelay": "200s",
          "z": 359,
          "x": 108,
          "MaxSpawnDelay": "800s",
          "RequiredPlayerRange": "16s",
          "SpawnCount": "4s",
          "ForgeCaps": {},
          "id": "minecraft:mob_spawner",
          "SpawnPotentials": [],
          "y": 132,
          "SpawnRange": "4s",
          "Delay": "416s"
        }
      },
      {
        "char": "q",
        "block": "minecraft:grass"
      },
      {
        "char": "式",
        "block": "minecraft:air"
      },
      {
        "char": "由",
        "block": "minecraft:air"
      },
      {
        "char": "U",
        "block": "minecraft:tall_grass[half=lower]"
      },
      {
        "char": "照",
        "block": "minecraft:air"
      },
      {
        "char": "ї",
        "block": "minecraft:air"
      },
      {
        "char": "耶",
        "block": "minecraft:air"
      },
      {
        "char": "萤",
        "block": "minecraft:air"
      },
      {
        "char": "科",
        "block": "minecraft:air"
      },
      {
        "char": "Ӫ",
        "block": "minecraft:air"
      },
      {
        "char": "G",
        "block": "minecraft:air"
      },
      {
        "char": "阳",
        "block": "minecraft:air"
      },
      {
        "char": "Ӻ",
        "block": "minecraft:air"
      },
      {
        "char": "m",
        "block": "minecraft:air"
      },
      {
        "char": "息",
        "block": "minecraft:air"
      },
      {
        "char": "首",
        "block": "minecraft:air"
      }
    ]
  },
  "slices": [
    [
      "aaaaaaaaaaaaaaaa",
      "aaaaaaaaaaaaaaaa",
      "aaaaaaaaaaaaaaaa",
      "aaaaaaaaaaaaaaaa",
      "aaaaaaaaaaaaaaaa",
      "aaaaaaaaaaaaaaaa",
      "aaaaaaaaaaaaaaaa",
      "aaaaaaaaaaaaaaaa",
      "aaaaaaaaaaaaaaaa",
      "aaaaaaaaaaaaaaaa",
      "aaaaaaaaaaaaaaaa",
      "aaaaaaaaaaaaaaaa",
      "aaaaaaaaaaaaaaaa",
      "aaaaaaaaaaaaaaaa",
      "aaaaaaaaaaaaaaaa",
      "aaaaaaaaaaaaaaaa"
    ],
    [
      "aaaaaaaaaaaaaaaa",
      "aaaaaaaaaaaaaaaa",
      "aaaaaaaaaaaaaaaa",
      "aaaaaaaaaaaaaaaa",
      "aaaaaaaaaaaaaaaa",
      "aaaaaaaaaaaaaaaa",
      "όaaaaaaaaaaaaaaa",
      "aaaaaaaaaaaaaaaa",
      "aaaaaaaaaaaaaaaa",
      "aaaaaaaaaaaaaaaa",
      "aaaaaaaaaaaaaaaa",
      "aaaaaaaaaaaaaaaa",
      "aaaaaaaaaaaaaaaa",
      "aaaaaaaaaaaaaaaa",
      "aaaaaaaaaaaaaaaa",
      "όaaaaaaaaaaaaaaa"
    ],
    [
      "jdegcejeegcgeccc",
      "jjdddjgdecgecjjg",
      "jjccgeeccecejccd",
      "jdcccdccggccejdc",
      "dgdedjjgcjcjegec",
      "cccccjcjejecjdcg",
      "gggejjcjgccjdege",
      "cdejcgcdejcgceeg",
      "ddjeecegjjccecje",
      "jdccegeceecccegj",
      "cjegeeecdjgjgcjc",
      "ecgdeegcdeejegec",
      "ddcjdgccdcjccegg",
      "dccjecjecgcjddee",
      "eggdcccegcdcgjgg",
      "cccgggggjjcccgcg"
    ],
    [
      "gjgcjegdggeejjcg",
      "ecjceddcecjgggje",
      "gccjcejgjceejegd",
      "gejjcdeecccecccj",
      "dcjgcegeeejegdje",
      "ceeedjgecjcecgjg",
      "dgegcgejeeedgcec",
      "cdgecgcgggeejjec",
      "ecddgcgeccegedec",
      "ddjccgjccecjcccc",
      "cejgddegdccdjcee",
      "cdccgddjjcjdjgdd",
      "ggjgccddeecgecjc",
      "egeccggjceccccec",
      "cddgcgceeccececc",
      "dcdgdceecdceedcg"
    ],
    [
      "cecddcgdgccgccgj",
      "dgeeegcdececejcc",
      "ecjecggegecggeeg",
      "ceceejceecedecdc",
      "ccececcegcejcjee",
      "edcgegecjdjccece",
      "ejgcejecjfffff5f",
      "dggeeedeeffff55c",
      "egejcjccjfffjӝӝ8",
      "dejcgegcgfff8入入c",
      "gcgecjdgdfff8gee",
      "jcgdcegjdfff8eMM",
      "ccgejgggefff8gMe",
      "jegejgcegdgcceђe",
      "cggegeddedceccMc",
      "ecgcgeeggeceeeMc"
    ],
    [
      "gcjcgdjjjejegggj",
      "cgcjcjjeegedgege",
      "cdggcdgcdcggdecg",
      "gcgjcgegcegegege",
      "gcgeccececeejdej",
      "ceccdejddcejeccg",
      "dgdceeccgq式q由q 式",
      "cceceejceqUU照 ї ",
      "ceeccggjcqU耶8  萤",
      "cejejeede q式科  Ӫ",
      "ecccjcjejq式q科 G ",
      "cecccggcgqUq科   ",
      "cecceeecdUqq科   ",
      "geeggjdeegcc8阳Ӫ ",
      "cccjjӺmӺmӺӺӺc   ",
      "gjjce息m首m   g   "
    ]
  ]
}