{
  "xsize": 16,
  "zsize": 16,
  "palette": {
    "palette": [
      {
        "char": " ",
        "block": "minecraft:air"
      },
      {
        "char": "i",
        "block": "minecraft:glass"
      },
      {
        "char": "r",
        "block": "minecraft:light_gray_carpet"
      },
      {
        "char": "2",
        "block": "minecraft:red_concrete"
      },
      {
        "char": "o",
        "block": "minecraft:cyan_terracotta"
      },
      {
        "char": "x",
        "block": "minecraft:oak_leaves[distance=7,persistent=true,waterlogged=false]"
      },
      {
        "char": "u",
        "block": "minecraft:light_gray_concrete"
      },
      {
        "char": "w",
        "block": "minecraft:quartz_pillar[axis=y]"
      },
      {
        "char": "ӧ",
        "block": "minecraft:blue_concrete"
      },
      {
        "char": "竹",
        "block": "minecraft:blue_wall_banner[facing=north]",
        "tag": {
          "z": 345,
          "Patterns": [
            {
              "Color": 14,
              "Pattern": "hhb"
            },
            {
              "Color": 0,
              "Pattern": "ls"
            },
            {
              "Color": 0,
              "Pattern": "mc"
            },
            {
              "Color": 0,
              "Pattern": "hhb"
            },
            {
              "Color": 14,
              "Pattern": "bts"
            },
            {
              "Color": 11,
              "Pattern": "bo"
            }
          ],
          "x": 178,
          "ForgeCaps": {},
          "id": "minecraft:banner",
          "y": 146
        }
      },
      {
        "char": "s",
        "block": "minecraft:polished_diorite"
      },
      {
        "char": "m",
        "block": "minecraft:white_concrete"
      },
      {
        "char": "y",
        "block": "minecraft:gray_concrete"
      },
      {
        "char": "v",
        "block": "minecraft:smooth_quartz"
      },
      {
        "char": "l",
        "block": "minecraft:andesite"
      },
      {
        "char": "h",
        "block": "minecraft:polished_andesite"
      },
      {
        "char": "G",
        "block": "minecraft:quartz_slab[type=bottom,waterlogged=false]"
      },
      {
        "char": "ͱ",
        "block": "minecraft:smooth_quartz_slab[type=bottom,waterlogged=false]"
      },
      {
        "char": "P",
        "block": "minecraft:diorite_slab[type=bottom,waterlogged=false]"
      },
      {
        "char": "D",
        "block": "minecraft:smooth_stone_slab[type=bottom,waterlogged=false]"
      },
      {
        "char": "A",
        "block": "minecraft:quartz_block"
      },
      {
        "char": "Е",
        "block": "minecraft:coarse_dirt"
      },
      {
        "char": "0",
        "block": "minecraft:diorite"
      },
      {
        "char": "U",
        "block": "minecraft:air"
      }
    ]
  },
  "slices": [
    [
      "   ir           ",
      "   ir           ",
      "   ir           ",
      "   2o x         ",
      "   2uwx         ",
      "   ӧoxx         ",
      "   ir           ",
      "   ir           ",
      "    r           ",
      "竹  ӧo           ",
      "smmsuw          ",
      "   my           ",
      "   ir           ",
      "   ir           ",
      "   ir           ",
      "    r           "
    ],
    [
      "   ir           ",
      "   ir           ",
      "   ir           ",
      "   2y           ",
      "   ӧow          ",
      "   ӧyx          ",
      "   irx          ",
      "    rx          ",
      "   ir           ",
      " 竹 ӧy           ",
      "msmvow          ",
      "   so           ",
      "    r           ",
      "    r           ",
      "   ir           ",
      "   ir           "
    ],
    [
      "   ir           ",
      "   ir           ",
      "   ir           ",
      "   2u           ",
      "   ӧow          ",
      "   ӧo           ",
      "    r           ",
      "    rxx         ",
      "   irxx         ",
      "  竹ӧy           ",
      "msvsow          ",
      "   su           ",
      "   ir           ",
      "   ir           ",
      "   ir           ",
      "   ir           "
    ],
    [
      "lhhsoG          ",
      "lllvyG          ",
      "hhhsoG          ",
      "hlhmoͱ          ",
      "hhlmuw          ",
      "hhlsoG          ",
      "lhhsoG          ",
      "lhlmoP          ",
      "lhhmyGx         ",
      "hhlmuPx         ",
      "hhhvow          ",
      "hllmuG          ",
      "lhhsyG          ",
      "lhlvoP          ",
      "hhlsyP          ",
      "hhlvuG          "
    ],
    [
      "   D v          ",
      "   D v          ",
      "   D v          ",
      "   D v          ",
      "   D v          ",
      "   D A          ",
      "   D v          ",
      "   D v          ",
      "   DЕA          ",
      "   D Ax         ",
      "   D vx         ",
      "   Dxv          ",
      "   DxA          ",
      "   D A          ",
      "   D 0          ",
      "   D A          "
    ],
    [
      "                ",
      "                ",
      "                ",
      "                ",
      "                ",
      "                ",
      "                ",
      "                ",
      "    U           ",
      "                ",
      "     x          ",
      "     x          ",
      "                ",
      "                ",
      "                ",
      "                "
    ]
  ]
}