{
  "xsize": 16,
  "zsize": 16,
  "palette": {
    "palette": [
      {
        "char": " ",
        "block": "minecraft:air"
      },
      {
        "char": "a",
        "block": "minecraft:stone[weathering=false]"
      },
      {
        "char": "b",
        "block": "minecraft:dirt"
      }
    ]
  },
  "slices": [
    [
      "aaaaaaaaaabbbbbb",
      "aaaaaaaaaabbbbbb",
      "aaaaaaaaaabbbbbb",
      "aaaaaaaaaabbbbbb",
      "aaaaaaaaaabbbbbb",
      "aaaaaaaaaabbbbbb",
      "aaaaaaaaaabbbbbb",
      "aaaaaaaaaabbbbbb",
      "aaaaaaaaaabbbbbb",
      "aaaaaaaaaabbbbbb",
      "aaaaaaaaaabbbbbb",
      "aaaaaaaaaabbbbbb",
      "aaaaaaaaaabbbbbb",
      "aaaaaaaaaabbbbbb",
      "aaaaaaaaaabbbbbb",
      "aaaaaaaaaabbbbbb"
    ],
    [
      "aaaaaaaaaabbbbbb",
      "aaaaaaaaaabbbbbb",
      "aaaaaaaaaabbbbbb",
      "aaaaaaaaaabbbbbb",
      "aaaaaaaaaabbbbbb",
      "aaaaaaaaaabbbbbb",
      "aaaaaaaaaabbbbbb",
      "aaaaaaaaaabbbbbb",
      "aaaaaaaaaabbbbbb",
      "aaaaaaaaaabbbbbb",
      "aaaaaaaaaabbbbbb",
      "aaaaaaaaaabbbbbb",
      "aaaaaaaaaabbbbbb",
      "aaaaaaaaaabbbbbb",
      "aaaaaaaaaabbbbbb",
      "aaaaaaaaaabbbbbb"
    ],
    [
      "aaaaaaaaaabbbbbb",
      "aaaaaaaaaabbbbbb",
      "aaaaaaaaaabbbbbb",
      "aaaaaaaaaabbbbbb",
      "aaaaaaaaaabbbbbb",
      "aaaaaaaaaabbbbbb",
      "aaaaaaaaaabbbbbb",
      "aaaaaaaaaabbbbbb",
      "aaaaaaaaaabbbbbb",
      "aaaaaaaaaabbbbbb",
      "aaaaaaaaaabbbbbb",
      "aaaaaaaaaabbbbbb",
      "aaaaaaaaaabbbbbb",
      "aaaaaaaaaabbbbbb",
      "aaaaaaaaaabbbbbb",
      "aaaaaaaaaabbbbbb"
    ],
    [
      "aaaaaaaaaabbbbbb",
      "aaaaaaaaaabbbbbb",
      "aaaaaaaaaabbbbbb",
      "aaaaaaaaaabbbbbb",
      "aaaaaaaaaabbbbbb",
      "aaaaaaaaaabbbbbb",
      "aaaaaaaaaabbbbbb",
      "aaaaaaaaaabbbbbb",
      "aaaaaaaaaabbbbbb",
      "aaaaaaaaaabbbbbb",
      "aaaaaaaaaabbbbbb",
      "aaaaaaaaaabbbbbb",
      "aaaaaaaaaabbbbbb",
      "aaaaaaaaaabbbbbb",
      "aaaaaaaaaabbbbbb",
      "aaaaaaaaaabbbbbb"
    ],
    [
      "aaaaaaaaaabbbbbb",
      "aaaaaaaaaabbbbbb",
      "aaaaaaaaaabbbbbb",
      "aaaaaaaaaabbbbbb",
      "aaaaaaaaaabbbbbb",
      "aaaaaaaaaabbbbbb",
      "aaaaaaaaaabbbbbb",
      "aaaaaaaaaabbbbbb",
      "aaaaaaaaaabbbbbb",
      "aaaaaaaaaabbbbbb",
      "aaaaaaaaaabbbbbb",
      "aaaaaaaaaabbbbbb",
      "bbbbbbbbbbbbbbbb",
      "bbbbbbbbbbbbbbbb",
      "bbbbbbbbbbbbbbbb",
      "bbbbbbbbbbbbbbbb"
    ],
    [
      "aaaaaaaaaabbbbbb",
      "aaaaaaaaaabbbbbb",
      "aaaaaaaaaabbbbbb",
      "aaaaaaaaaabbbbbb",
      "aaaaaaaaaabbbbbb",
      "aaaaaaaaaabbbbbb",
      "aaaaaaaaaabbbbbb",
      "aaaaaaaaaabbbbbb",
      "aaaaaaaaaabbbbbb",
      "aaaaaaaaaabbbbbb",
      "aaaaaaaaaabbbbbb",
      "aaaaaaaaaabbbbbb",
      "bbbbbbbbbbbbbbbb",
      "bbbbbbbbbbbbbbbb",
      "bbbbbbbbbbbbbbbb",
      "bbbbbbbbbbbbbbbb"
    ]
  ]
}