{
  "xsize": 16,
  "zsize": 16,
  "palette": {
    "palette": [
      {
        "char": " ",
        "block": "minecraft:air"
      },
      {
        "char": "海",
        "block": "minecraft:air"
      },
      {
        "char": "ӎ",
        "block": "minecraft:air"
      },
      {
        "char": "w",
        "block": "minecraft:air"
      },
      {
        "char": "o",
        "block": "minecraft:air"
      },
      {
        "char": "r",
        "block": "minecraft:air"
      },
      {
        "char": "意",
        "block": "minecraft:air"
      },
      {
        "char": "O",
        "block": "minecraft:air"
      },
      {
        "char": "着",
        "block": "minecraft:air"
      },
      {
        "char": "u",
        "block": "minecraft:air"
      },
      {
        "char": "v",
        "block": "minecraft:air"
      },
      {
        "char": "i",
        "block": "minecraft:air"
      },
      {
        "char": "m",
        "block": "minecraft:air"
      },
      {
        "char": "y",
        "block": "minecraft:air"
      },
      {
        "char": "Ӭ",
        "block": "minecraft:air"
      },
      {
        "char": "s",
        "block": "minecraft:air"
      },
      {
        "char": "反",
        "block": "minecraft:air"
      },
      {
        "char": "P",
        "block": "minecraft:air"
      },
      {
        "char": "G",
        "block": "minecraft:air"
      },
      {
        "char": "Ӫ",
        "block": "minecraft:air"
      },
      {
        "char": "ͱ",
        "block": "minecraft:air"
      },
      {
        "char": "l",
        "block": "minecraft:air"
      },
      {
        "char": "h",
        "block": "minecraft:air"
      },
      {
        "char": "A",
        "block": "minecraft:air"
      },
      {
        "char": "者",
        "block": "minecraft:air"
      },
      {
        "char": "妳",
        "block": "minecraft:air"
      },
      {
        "char": "D",
        "block": "minecraft:air"
      },
      {
        "char": "Е",
        "block": "minecraft:air"
      },
      {
        "char": "ӡ",
        "block": "minecraft:air"
      },
      {
        "char": "U",
        "block": "minecraft:tall_grass[half=lower]"
      },
      {
        "char": "了",
        "block": "minecraft:air"
      },
      {
        "char": "没",
        "block": "minecraft:air"
      },
      {
        "char": "中",
        "block": "minecraft:air"
      },
      {
        "char": "大",
        "block": "minecraft:air"
      }
    ]
  },
  "slices": [
    [
      "                ",
      "                ",
      "                ",
      "                ",
      "                ",
      "                ",
      "    海           ",
      "   ӎw           ",
      "   or           ",
      "意O着urrr         ",
      "   v irrr       ",
      "      i ro      ",
      "        imow    ",
      "         my     ",
      "         ir     ",
      "         ir     "
    ],
    [
      "                ",
      "                ",
      "                ",
      "                ",
      "                ",
      "                ",
      "                ",
      "   ӎw           ",
      "ӬӬӬyr           ",
      "wwwurrr         ",
      "   siirrr       ",
      "      iiro      ",
      "         syw    ",
      "         su     ",
      "         ir     ",
      "          r     "
    ],
    [
      "                ",
      "                ",
      "                ",
      "                ",
      "                ",
      "                ",
      "    海           ",
      "   ӎw           ",
      "反反反yr           ",
      "wwworrr         ",
      "   viirrr       ",
      "      iiro      ",
      "        imuw    ",
      "         mu     ",
      "         ir     ",
      "          r     "
    ],
    [
      "                ",
      "                ",
      "                ",
      "                ",
      "                ",
      "                ",
      "                ",
      "PGGӪw           ",
      "yyoooPG         ",
      "oyyyyoyͱӪ       ",
      "mmvmvsoooG      ",
      "lllhlhvmouͱ     ",
      "lhllhllhsmow    ",
      "hllhhhhllmuG    ",
      "llhhlhhhlmuP    ",
      "hhlhlhlhlvoP    "
    ],
    [
      "                ",
      "                ",
      "                ",
      "                ",
      "                ",
      "                ",
      "    海           ",
      "vvAvv           ",
      "    者vA         ",
      "    妳  vv       ",
      "DDDDDD  ЕA      ",
      "      DD  v     ",
      "yӡyy    DD v    ",
      "y yy     D v    ",
      "         D A    ",
      "yӡyy     D v    "
    ],
    [
      "                ",
      "                ",
      "                ",
      "                ",
      "                ",
      "                ",
      "                ",
      "                ",
      "                ",
      "                ",
      "        U       ",
      "                ",
      "了 没了            ",
      "中 大中            ",
      "                ",
      "了 没了            "
    ]
  ]
}