{
  "xsize": 16,
  "zsize": 16,
  "palette": {
    "palette": [
      {
        "char": " ",
        "block": "minecraft:air"
      },
      {
        "char": "w",
        "block": "minecraft:air"
      },
      {
        "char": "y",
        "block": "minecraft:air"
      },
      {
        "char": "o",
        "block": "minecraft:air"
      },
      {
        "char": "i",
        "block": "minecraft:air"
      },
      {
        "char": "u",
        "block": "minecraft:air"
      },
      {
        "char": "r",
        "block": "minecraft:air"
      },
      {
        "char": "m",
        "block": "minecraft:air"
      },
      {
        "char": "一",
        "block": "minecraft:air"
      },
      {
        "char": "ӻ",
        "block": "minecraft:air"
      },
      {
        "char": "ύ",
        "block": "minecraft:air"
      },
      {
        "char": "7",
        "block": "minecraft:air"
      },
      {
        "char": "s",
        "block": "minecraft:air"
      },
      {
        "char": "G",
        "block": "minecraft:air"
      },
      {
        "char": "P",
        "block": "minecraft:air"
      },
      {
        "char": "v",
        "block": "minecraft:air"
      },
      {
        "char": "ͱ",
        "block": "minecraft:air"
      },
      {
        "char": "h",
        "block": "minecraft:air"
      },
      {
        "char": "l",
        "block": "minecraft:air"
      },
      {
        "char": "A",
        "block": "minecraft:air"
      },
      {
        "char": "Е",
        "block": "minecraft:air"
      },
      {
        "char": "0",
        "block": "minecraft:air"
      },
      {
        "char": "D",
        "block": "minecraft:air"
      },
      {
        "char": "O",
        "block": "minecraft:air"
      },
      {
        "char": "x",
        "block": "minecraft:air"
      },
      {
        "char": "U",
        "block": "minecraft:tall_grass[half=lower]"
      },
      {
        "char": "主",
        "block": "minecraft:air"
      }
    ]
  },
  "slices": [
    [
      "w               ",
      "y               ",
      "oi              ",
      "o               ",
      "       i        ",
      "        i w     ",
      "         iuorrro",
      "          mmiiim",
      "                ",
      "一               ",
      " ӻ              ",
      "                ",
      " ύ              ",
      "7               ",
      "                ",
      "                "
    ],
    [
      "w               ",
      "o               ",
      "ui              ",
      "u               ",
      "      i         ",
      "        i w     ",
      "         ioorrru",
      "          ssi is",
      "                ",
      "一               ",
      " ӻ              ",
      "                ",
      " ύ              ",
      "7               ",
      "                ",
      "                "
    ],
    [
      "w               ",
      "uGG             ",
      "ommGGG          ",
      "ou mssPG        ",
      "  oo  ssG       ",
      "    y   mGw     ",
      "     o   suorrru",
      "      o   vsiiim",
      "       o        ",
      "一      u        ",
      " ӻ      o       ",
      "        u       ",
      " ύ      u       ",
      "7       u       ",
      "        u       ",
      "        u       "
    ],
    [
      "wͱP             ",
      "oouPGP          ",
      "ooooooGG        ",
      "uohmmlouP       ",
      "  uuhhlloP      ",
      "    uhhllywͱͱͱGP",
      "     uhhlsuoouyu",
      "      yhhlmvvvms",
      "       ohllhhhhh",
      "一      uhlllllll",
      " ӻ      olhhhhhh",
      "        ohlhllhl",
      " ύ      uhlhlhhl",
      "7       ylllllhl",
      "        ollhhhhh",
      "        ohhlhllh"
    ],
    [
      "AAA             ",
      "  ЕvAv          ",
      "yyoЕ  A0        ",
      "hhuooD  v       ",
      "OOhhuyDD A      ",
      "  OOhyu Dxvv0v00",
      "    OhyyxDxЕ    ",
      "     Ohoo DDDDDD",
      "      Ohy       ",
      "一     Ohoo      ",
      " ӻ     Oho      ",
      "       Oho      ",
      " ύ     Ohy      ",
      "7      Ohu      ",
      "       Ohu      ",
      "       Oho      "
    ],
    [
      "                ",
      "  U             ",
      "   U            ",
      "ii              ",
      "iiii            ",
      "  ii            ",
      "     i x   U    ",
      "     iix        ",
      "       i        ",
      "一     ii        ",
      " ӻ     ii       ",
      "       ii       ",
      " ύ     ii       ",
      "7     主iio      ",
      "       ii       ",
      "       ii       "
    ]
  ]
}