{
  "xsize": 16,
  "zsize": 16,
  "palette": {
    "palette": [
      {
        "char": " ",
        "block": "minecraft:air"
      },
      {
        "char": "u",
        "block": "minecraft:air"
      },
      {
        "char": "v",
        "block": "minecraft:air"
      },
      {
        "char": "w",
        "block": "minecraft:air"
      },
      {
        "char": "o",
        "block": "minecraft:air"
      },
      {
        "char": "s",
        "block": "minecraft:air"
      },
      {
        "char": "m",
        "block": "minecraft:air"
      },
      {
        "char": "t",
        "block": "minecraft:air"
      },
      {
        "char": "r",
        "block": "minecraft:air"
      },
      {
        "char": "C",
        "block": "minecraft:air"
      },
      {
        "char": "i",
        "block": "minecraft:air"
      },
      {
        "char": "n",
        "block": "minecraft:air"
      },
      {
        "char": "3",
        "block": "minecraft:air"
      },
      {
        "char": "y",
        "block": "minecraft:air"
      },
      {
        "char": "Ӫ",
        "block": "minecraft:air"
      },
      {
        "char": "l",
        "block": "minecraft:air"
      },
      {
        "char": "h",
        "block": "minecraft:air"
      },
      {
        "char": "G",
        "block": "minecraft:air"
      },
      {
        "char": "P",
        "block": "minecraft:air"
      },
      {
        "char": "A",
        "block": "minecraft:air"
      },
      {
        "char": "D",
        "block": "minecraft:air"
      },
      {
        "char": "4",
        "block": "minecraft:air"
      },
      {
        "char": "0",
        "block": "minecraft:air"
      },
      {
        "char": "Е",
        "block": "minecraft:air"
      },
      {
        "char": "U",
        "block": "minecraft:tall_grass[half=lower]"
      }
    ]
  },
  "slices": [
    [
      "        uv      ",
      "       wos      ",
      "        om     t",
      "        r      C",
      "        ri     n",
      "        ri     t",
      "        om      ",
      "       wom      ",
      "         u      ",
      "         r      ",
      "          ri    ",
      "          3r i  ",
      "            rosm",
      "              oo",
      "              w ",
      "                "
    ],
    [
      "        um      ",
      "       wov      ",
      "        ov      ",
      "        ri      ",
      "        ri      ",
      "        ri      ",
      "        ym      ",
      "       wov      ",
      "         oi     ",
      "         ri     ",
      "          ri    ",
      "          3rii  ",
      "            rosm",
      "              oy",
      "              w ",
      "                "
    ],
    [
      "        um      ",
      "       wom      ",
      "        om      ",
      "        r       ",
      "        ri      ",
      "        ri      ",
      "        ys      ",
      "       wom      ",
      "         ui     ",
      "         ri     ",
      "          r     ",
      "          3r i  ",
      "            ryss",
      "              uo",
      "              w ",
      "                "
    ],
    [
      "       Ӫymlllhhl",
      "       wumlhlllh",
      "       Gomlhllhh",
      "       Pomlhllhh",
      "       Gumlhhlhh",
      "       Govllllll",
      "       Pomhhhhll",
      "       wymhhhhhh",
      "        Poshhlll",
      "        Pyvlllhl",
      "         Gumhlll",
      "         Gyyvvll",
      "          GGuumm",
      "            GPoo",
      "              wP",
      "                "
    ],
    [
      "       A D4     ",
      "       A D4     ",
      "       v D 4   4",
      "       v D  444 ",
      "       A D      ",
      "       v D      ",
      "       A D      ",
      "       v D      ",
      "        0 D     ",
      "        v D     ",
      "         A D    ",
      "         v ЕDD  ",
      "          vAЕ DD",
      "            AA  ",
      "              v0",
      "                "
    ],
    [
      "                ",
      "                ",
      "                ",
      "                ",
      "                ",
      "                ",
      "                ",
      "                ",
      "                ",
      "                ",
      "                ",
      "           U    ",
      "            U   ",
      "                ",
      "                ",
      "                "
    ]
  ]
}