{
  "xsize": 16,
  "zsize": 16,
  "palette": {
    "palette": [
      {
        "char": " ",
        "block": "minecraft:air"
      },
      {
        "char": "a",
        "block": "minecraft:stone[weathering=false]"
      },
      {
        "char": "ό",
        "block": "minecraft:air"
      },
      {
        "char": "c",
        "block": "minecraft:mossy_stone_bricks"
      },
      {
        "char": "d",
        "block": "minecraft:stone_bricks[weathering=false]"
      },
      {
        "char": "e",
        "block": "minecraft:cracked_stone_bricks"
      },
      {
        "char": "g",
        "block": "minecraft:mossy_cobblestone"
      },
      {
        "char": "j",
        "block": "minecraft:cobblestone[weathering=false]"
      },
      {
        "char": "附",
        "block": "minecraft:lever[face=ceiling,facing=west,powered=true]"
      },
      {
        "char": "M",
        "block": "minecraft:blue_terracotta"
      },
      {
        "char": "f",
        "block": "minecraft:grass_block[snowy=false]"
      },
      {
        "char": "8",
        "block": "minecraft:chiseled_stone_bricks[weathering=false]"
      },
      {
        "char": "宣",
        "block": "minecraft:air"
      },
      {
        "char": "游",
        "block": "minecraft:air"
      },
      {
        "char": "杀",
        "block": "minecraft:birch_door[facing=south,half=lower,hinge=left,open=false,powered=false]"
      },
      {
        "char": "m",
        "block": "minecraft:white_concrete"
      },
      {
        "char": "Ӻ",
        "block": "minecraft:cauldron"
      },
      {
        "char": "十",
        "block": "minecraft:dark_oak_trapdoor[facing=east,half=bottom,open=true,powered=false,waterlogged=false]"
      },
      {
        "char": "q",
        "block": "minecraft:air"
      },
      {
        "char": "由",
        "block": "minecraft:dandelion"
      },
      {
        "char": "科",
        "block": "minecraft:white_stained_glass_pane[east=false,north=true,south=true,waterlogged=false,west=false]"
      },
      {
        "char": "U",
        "block": "minecraft:air"
      },
      {
        "char": "耶",
        "block": "minecraft:dark_oak_trapdoor[facing=west,half=top,open=true,powered=false,waterlogged=false]"
      },
      {
        "char": "ө",
        "block": "minecraft:white_stained_glass_pane[east=true,north=false,south=false,waterlogged=false,west=true]"
      },
      {
        "char": "政",
        "block": "minecraft:dark_oak_trapdoor[facing=south,half=top,open=true,powered=false,waterlogged=false]"
      },
      {
        "char": "式",
        "block": "minecraft:poppy"
      }
    ]
  },
  "slices": [
    [
      "aaaaaaaaaaaaaaaa",
      "aaaaaaaaaaaaaaaa",
      "aaaaaaaaaaaaaaaa",
      "aaaaaaaaaaaaaaaa",
      "aaaaaaaaaaaaaaaa",
      "aaaaaaaaaaaaaaaa",
      "aaaaaaaaaaaaaaaa",
      "aaaaaaaaaaaaaaaa",
      "aaaaaaaaaaaaaaaa",
      "aaaaaaaaaaaaaaaa",
      "aaaaaaaaaaaaaaaa",
      "aaaaaaaaaaaaaaaa",
      "aaaaaaaaaaaaaaaa",
      "aaaaaaaaaaaaaaaa",
      "aaaaaaaaaaaaaaaa",
      "aaaaaaaaaaaaaaaa"
    ],
    [
      "όaaaaaaaaaaaaaaa",
      "aaaaaaaaaaaaaaaa",
      "aaaaaaaaaaaaaaaa",
      "aaaaaaaaaaaaaaaa",
      "aaaaaaaaaaaaaaaa",
      "aaaaaaaaaaaaaaaa",
      "όaaaaaaaaaaaaaaa",
      "aaaaaaaaaaaaaaaa",
      "aaaaaaaaaaaaaaaa",
      "aaaaaaaaaaaaaaaa",
      "aaaaaaaaaaaaaaaa",
      "aaaaaaaaaaaaaaaa",
      "aaaaaaaaaaaaaaaa",
      "aaaaaaaaaaaaaaaa",
      "aaaaaaaaaaaaaaaa",
      "aaaaaaaaaaaaaaaa"
    ],
    [
      "cdecgceejccgcceg",
      "djjjecdcjjjjejge",
      "ddccecjceeeeccce",
      "dccdccdcceegcgcc",
      "ddgccgdgjgjcccjc",
      "djcccjdeejeecgcg",
      "ceejegjjecejgdcg",
      "gcgegdccdjdecdeg",
      "dccccggggjdccgcc",
      "ejeeecjecjedcgjd",
      "ddcgddcgjgcceeed",
      "ddddjgcegddcgceg",
      "ddceegcejdegedcc",
      "dddcdcdgggdgccec",
      "ddedgjdegeddjejj",
      "dddeggccedejcddg"
    ],
    [
      "cccejccgcjce附dcc",
      "ejccggcegdgdeeee",
      "cddgeeceggeececc",
      "gdejeccdeecc附ccc",
      "edcjeeeecjjggecc",
      "cdececjejgccccce",
      "dcdcjjdcjjgjecdg",
      "cddjgggecdjccjdc",
      "jddccgdcecececdc",
      "jjcjccgeeceegeec",
      "ddegceedccgedcgd",
      "ddgddjcceedjegde",
      "ddececddegceedjd",
      "ddeedccecdjegdgj",
      "dddgjdddcdejcjdg",
      "ddggcdgddjcdgcdg"
    ],
    [
      "eegegccjcjdcdMMe",
      "cccegcgceccdegMe",
      "dcgeeccggjjedcMe",
      "gcjecggdjceejMMc",
      "edceeceeeeegjcMg",
      "cjjjcdeegcccjgMc",
      "cjeccegcjjeceeMc",
      "deeegdgjdfff8cMe",
      "gececcdgcfff8jMM",
      "jgedgeeeefff8gec",
      "ggdcdgccdfff8dej",
      "cegcjecdgfffg888",
      "jdjecgedefffffff",
      "gcegejgdefffffff",
      "jgdjcdddeccegcdd",
      "ccjjggdjcjgegcgj"
    ],
    [
      "eeceg       宣   ",
      "cdgegeecejcjj   ",
      "cgjejgegjeggc   ",
      "dccej       游   ",
      "cccee杀m杀m   e   ",
      "jcegeӺmӺmӺӺӺc   ",
      "ggggjjecdejc8十  ",
      "decgggjceqq由科   ",
      "cdeecjjgcUUq科   ",
      "dejggjeeeUUq科   ",
      "ggjcccegdqq由科   ",
      "dccccjcjc U耶8өөө",
      "dgceeecdc 由U政式qq",
      "ddeegcdcgqqqq qq",
      "dgdjecdddccjejec",
      "ejcjecjdcdgddedc"
    ]
  ]
}