{
  "xsize": 16,
  "zsize": 16,
  "palette": {
    "palette": [
      {
        "char": " ",
        "block": "minecraft:air"
      },
      {
        "char": "ύ",
        "block": "minecraft:vine[east=false,north=false,south=false,up=false,west=true]"
      },
      {
        "char": "2",
        "block": "minecraft:red_concrete"
      },
      {
        "char": "i",
        "block": "minecraft:glass"
      },
      {
        "char": "m",
        "block": "minecraft:white_concrete"
      },
      {
        "char": "s",
        "block": "minecraft:polished_diorite"
      },
      {
        "char": "r",
        "block": "minecraft:light_gray_carpet"
      },
      {
        "char": "y",
        "block": "minecraft:gray_concrete"
      },
      {
        "char": "o",
        "block": "minecraft:cyan_terracotta"
      },
      {
        "char": "h",
        "block": "minecraft:polished_andesite"
      },
      {
        "char": "够",
        "block": "minecraft:stone_brick_wall[east=none,north=low,south=none,up=true,waterlogged=false,weathering=false,west=low]"
      },
      {
        "char": "界",
        "block": "minecraft:stone_brick_wall[east=low,north=none,south=none,up=true,waterlogged=false,weathering=false,west=none]"
      },
      {
        "char": "w",
        "block": "minecraft:quartz_pillar[axis=y]"
      },
      {
        "char": "u",
        "block": "minecraft:light_gray_concrete"
      },
      {
        "char": "v",
        "block": "minecraft:smooth_quartz"
      },
      {
        "char": "德",
        "block": "minecraft:stone_brick_wall[east=none,north=none,south=low,up=true,waterlogged=false,weathering=false,west=low]"
      },
      {
        "char": "注",
        "block": "minecraft:stone_brick_wall[east=none,north=none,south=low,up=true,waterlogged=false,weathering=false,west=none]"
      },
      {
        "char": "3",
        "block": "minecraft:stone_brick_wall[east=none,north=none,south=none,up=true,waterlogged=false,weathering=false,west=none]"
      },
      {
        "char": "l",
        "block": "minecraft:andesite"
      },
      {
        "char": "P",
        "block": "minecraft:diorite_slab[type=bottom,waterlogged=false]"
      },
      {
        "char": "ͱ",
        "block": "minecraft:smooth_quartz_slab[type=bottom,waterlogged=false]"
      },
      {
        "char": "G",
        "block": "minecraft:quartz_slab[type=bottom,waterlogged=false]"
      },
      {
        "char": "O",
        "block": "minecraft:smooth_quartz_slab[type=top,waterlogged=false]"
      },
      {
        "char": "D",
        "block": "minecraft:smooth_stone_slab[type=bottom,waterlogged=false]"
      },
      {
        "char": "A",
        "block": "minecraft:quartz_block"
      },
      {
        "char": "0",
        "block": "minecraft:diorite"
      },
      {
        "char": "Е",
        "block": "minecraft:coarse_dirt"
      },
      {
        "char": "吗",
        "block": "minecraft:air"
      },
      {
        "char": "U",
        "block": "minecraft:air"
      }
    ]
  },
  "slices": [
    [
      "           ύ    ",
      "                ",
      "                ",
      "            22 2",
      "imssm       iii ",
      "ryohhm      i够 界",
      "  whhm      i   ",
      "   wuv      i德 注",
      "     r      ii i",
      "     ri         ",
      "     3rrsmiiimsm",
      "        uurrrouu",
      "        w     w ",
      "                ",
      "                ",
      "                "
    ],
    [
      "           ύ    ",
      "                ",
      "                ",
      "            2   ",
      " mvsm       iiii",
      "ruohhm          ",
      "  whhv      i   ",
      "   wum      i   ",
      "     ri     ii i",
      "     r i        ",
      "     3rrmmii vmv",
      "        oorrruoo",
      "        w     w ",
      "                ",
      "                ",
      "                "
    ],
    [
      "    o      ύ    ",
      "     o          ",
      "     o          ",
      "      u         ",
      "imsmv  y    hhhh",
      "ryohhm  o   hhhh",
      "  whhv   oo hhhh",
      "   wos     yhhhh",
      "     ri     hhhh",
      "     r i        ",
      "     3rrmsiiissm",
      "        oyrrruyo",
      "        w     w ",
      "                ",
      "                ",
      "                "
    ],
    [
      "hlhhu      ύ    ",
      "lhhllo          ",
      "hhllhu          ",
      "hllllhu         ",
      "vvslhhho        ",
      "yuovslhhu       ",
      "Pͱwuvlhhhuu     ",
      "   wovhhhhhuoouo",
      "    Pymhhhhhhhhh",
      "    Pymvhhhhhhhh",
      "     Pyosmmsmmmm",
      "      PPoooououy",
      "        wGͱGGGwͱ",
      "                ",
      "                ",
      "                "
    ],
    [
      "   ohO     ύ    ",
      "   oohO         ",
      "    yhO         ",
      "    oohO        ",
      "DDD  uohO       ",
      "   DD oyhOO     ",
      "vAv D  oohhOOOOO",
      "   0 D  yoohhhhh",
      "    A D   oooooo",
      "    v DD        ",
      "     0 ЕDDDDDDDD",
      "      AvЕЕ      ",
      "        vAAvv0vA",
      "                ",
      "                ",
      "                "
    ],
    [
      "    ii     ύ    ",
      "     ii         ",
      "     ii         ",
      "      ii        ",
      "       ii       ",
      "        i     吗 ",
      "         iiii ii",
      "           iii i",
      "              y ",
      "                ",
      "       U        ",
      "        UU      ",
      "                ",
      "                ",
      "                ",
      "                "
    ]
  ]
}