{
  "xsize": 16,
  "zsize": 16,
  "palette": {
    "palette": [
      {
        "char": " ",
        "block": "minecraft:air"
      },
      {
        "char": "f",
        "block": "minecraft:grass_block[snowy=false]"
      },
      {
        "char": "求",
        "block": "minecraft:chiseled_quartz_block"
      },
      {
        "char": "b",
        "block": "minecraft:dirt"
      },
      {
        "char": "s",
        "block": "minecraft:polished_diorite"
      },
      {
        "char": "k",
        "block": "minecraft:air"
      },
      {
        "char": "q",
        "block": "minecraft:air"
      },
      {
        "char": "z",
        "block": "minecraft:air"
      },
      {
        "char": "ӛ",
        "block": "minecraft:vine[east=false,north=false,south=true,up=false,west=false]"
      },
      {
        "char": "断",
        "block": "minecraft:iron_bars[east=false,north=false,south=true,waterlogged=false,west=false]"
      },
      {
        "char": "ӻ",
        "block": "minecraft:vine[east=true,north=false,south=true,up=false,west=false]"
      },
      {
        "char": "x",
        "block": "minecraft:oak_leaves[distance=7,persistent=true,waterlogged=false]"
      },
      {
        "char": "I",
        "block": "minecraft:quartz_slab[type=top,waterlogged=false]"
      },
      {
        "char": "O",
        "block": "minecraft:smooth_quartz_slab[type=top,waterlogged=false]"
      },
      {
        "char": "Q",
        "block": "minecraft:diorite_slab[type=top,waterlogged=false]"
      },
      {
        "char": "w",
        "block": "minecraft:quartz_pillar[axis=y]"
      },
      {
        "char": "吗",
        "block": "minecraft:air"
      }
    ]
  },
  "slices": [
    [
      "ffffffffffffffff",
      "ffffffffffffffff",
      "ffffffffffffffff",
      "ffffffffffffffff",
      "ffffffffffffffff",
      "ffffffffffffffff",
      "ffffffffffffffff",
      "ffffffffffffffff",
      "ffffffffffffffff",
      "ffffffffffffffff",
      "ffffffffffffffff",
      "ffffffffffffffff",
      "ffffffffffffffff",
      "fffffffffff求ffff",
      "ffffffffffffffff",
      "ffffbffffffffffs"
    ],
    [
      "kkkkqkkkkqkqkqqq",
      "zqkzkkkqkkkk  qk",
      "qqqqkqkkkkqkzqqk",
      "zqkqzqkqzqkkkkkk",
      "qqkkqkz qkkkqkkk",
      "kzqqz q qqqqqzqk",
      "kkkkqkk kkkkkkqq",
      "qkqkkqkzzqqkkkqq",
      "qkzqzkqqqkqkqz k",
      "zkkkkkqq qkkkkkk",
      "kqkkqqzkkqkzkqqq",
      "zkqkqkqkkkqqkkzz",
      "qqkzq zkqqqzqkkq",
      "qq qzkzzkӛq kkkk",
      "kqkz断q kӻxqxkk k",
      "IOQQwqxxxxxxkzkz"
    ],
    [
      "                ",
      "                ",
      "                ",
      "                ",
      "                ",
      "                ",
      "                ",
      "                ",
      "                ",
      "                ",
      "                ",
      "                ",
      "                ",
      "                ",
      "    吗           ",
      "    wxx  x      "
    ],
    [
      "                ",
      "                ",
      "                ",
      "                ",
      "                ",
      "                ",
      "                ",
      "                ",
      "                ",
      "                ",
      "                ",
      "                ",
      "                ",
      "                ",
      "    吗           ",
      "    w           "
    ],
    [
      "                ",
      "                ",
      "                ",
      "                ",
      "                ",
      "                ",
      "                ",
      "                ",
      "                ",
      "                ",
      "                ",
      "                ",
      "                ",
      "                ",
      "    吗           ",
      "    wx          "
    ],
    [
      "                ",
      "                ",
      "                ",
      "                ",
      "                ",
      "                ",
      "                ",
      "                ",
      "                ",
      "                ",
      "                ",
      "                ",
      "                ",
      "                ",
      "    吗           ",
      "    w           "
    ]
  ]
}