{
  "xsize": 16,
  "zsize": 16,
  "palette": {
    "palette": [
      {
        "char": " ",
        "block": "minecraft:air"
      },
      {
        "char": "c",
        "block": "minecraft:mossy_stone_bricks"
      },
      {
        "char": "a",
        "block": "minecraft:stone[weathering=false]"
      },
      {
        "char": "b",
        "block": "minecraft:dirt"
      },
      {
        "char": "e",
        "block": "minecraft:cracked_stone_bricks"
      },
      {
        "char": "d",
        "block": "minecraft:stone_bricks[weathering=false]"
      },
      {
        "char": "g",
        "block": "minecraft:mossy_cobblestone"
      }
    ]
  },
  "slices": [
    [
      "caaaaaaaaabbbbbb",
      "caaaaaaaaabbbbbb",
      "caaaaaaaaabbbbbb",
      "caaaaaaaaabbbbbb",
      "eaaaaaaaaabbbbbb",
      "daaaaaaaaabbbbbb",
      "daaaaaaaaabbbbbb",
      "ddcdaaaaaabbbbbb",
      "aaaaaaaaaabbbbbb",
      "aaaaaaaaaabbbbbb",
      "aaaaaaaaaabbbbbb",
      "aaaaaaaaaabbbbbb",
      "aaaaaaaaaabbbbbb",
      "aaaaaaaaaabbbbbb",
      "aaaaaaaaaabbbbbb",
      "aaaaaaaaaabbbbbb"
    ],
    [
      "caaaaaaaaabbbbbb",
      "daaaaaaaaabbbbbb",
      "gaaaaaaaaabbbbbb",
      "eaaaaaaaaabbbbbb",
      "caaaaaaaaabbbbbb",
      "daaaaaaaaabbbbbb",
      "caaaaaaaaabbbbbb",
      "eaaaaaaaaabbbbbb",
      "aaaaaaaaaabbbbbb",
      "aaaaaaaaaabbbbbb",
      "aaaaaaaaaabbbbbb",
      "aaaaaaaaaabbbbbb",
      "aaaaaaaaaabbbbbb",
      "aaaaaaaaaabbbbbb",
      "aaaaaaaaaabbbbbb",
      "aaaaaaaaaabbbbbb"
    ],
    [
      "gaaaaaaaaabbbbbb",
      "daaaaaaaaabbbbbb",
      "eaaaaaaaaabbbbbb",
      "caaaaaaaaabbbbbb",
      "caaaaaaaaabbbbbb",
      "daaaaaaaaabbbbbb",
      "caaaaaaaaabbbbbb",
      "eaaaaaaaaabbbbbb",
      "aaaaaaaaaabbbbbb",
      "aaaaaaaaaabbbbbb",
      "aaaaaaaaaabbbbbb",
      "aaaaaaaaaabbbbbb",
      "aaaaaaaaaabbbbbb",
      "aaaaaaaaaabbbbbb",
      "aaaaaaaaaabbbbbb",
      "aaaaaaaaaabbbbbb"
    ],
    [
      "aaaaaaaaaabbbbbb",
      "aaaaaaaaaabbbbbb",
      "aaaaaaaaaabbbbbb",
      "aaaaaaaaaabbbbbb",
      "aaaaaaaaaabbbbbb",
      "aaaaaaaaaabbbbbb",
      "aaaaaaaaaabbbbbb",
      "aaaaaaaaaabbbbbb",
      "aaaaaaaaaabbbbbb",
      "aaaaaaaaaabbbbbb",
      "aaaaaaaaaabbbbbb",
      "aaaaaaaaaabbbbbb",
      "aaaaaaaaaabbbbbb",
      "aaaaaaaaaabbbbbb",
      "aaaaaaaaaabbbbbb",
      "aaaaaaaaaabbbbbb"
    ],
    [
      "aaaaaaaaaabbbbbb",
      "aaaaaaaaaabbbbbb",
      "aaaaaaaaaabbbbbb",
      "aaaaaaaaaabbbbbb",
      "aaaaaaaaaabbbbbb",
      "aaaaaaaaaabbbbbb",
      "aaaaaaaaaabbbbbb",
      "aaaaaaaaaabbbbbb",
      "aaaaaaaaaabbbbbb",
      "aaaaaaaaaabbbbbb",
      "aaaaaaaaaabbbbbb",
      "aaaaaaaaaabbbbbb",
      "aaaaaaaaaabbbbbb",
      "aaaaaaaaaabbbbbb",
      "aaaaaaaaaabbbbbb",
      "aaaaaaaaaabbbbbb"
    ],
    [
      "aaaaaaaaaabbbbbb",
      "aaaaaaaaaabbbbbb",
      "aaaaaaaaaabbbbbb",
      "aaaaaaaaaabbbbbb",
      "aaaaaaaaaabbbbbb",
      "aaaaaaaaaabbbbbb",
      "aaaaaaaaaabbbbbb",
      "aaaaaaaaaabbbbbb",
      "aaaaaaaaaabbbbbb",
      "aaaaaaaaaabbbbbb",
      "aaaaaaaaaabbbbbb",
      "aaaaaaaaaabbbbbb",
      "aaaaaaaaaabbbbbb",
      "aaaaaaaaaabbbbbb",
      "aaaaaaaaaabbbbbb",
      "aaaaaaaaaabbbbbb"
    ]
  ]
}