{
  "xsize": 16,
  "zsize": 16,
  "palette": {
    "palette": [
      {
        "char": " ",
        "block": "minecraft:air"
      },
      {
        "char": "a",
        "block": "minecraft:stone[weathering=false]"
      },
      {
        "char": "b",
        "block": "minecraft:dirt"
      }
    ]
  },
  "slices": [
    [
      "aaaaaaaaaaaaaaaa",
      "aaaaaaaaaaaaaaaa",
      "aaaaaaaaaaaaaaaa",
      "aaaaaaaaaaaaaaaa",
      "aaaaaaaaaaaaaaaa",
      "aaaaaaaaaaaaaaaa",
      "aaaaaaaaaaaaaaaa",
      "aaaaaaaaaaaaaaaa",
      "aaaaaaaaaaaaaaaa",
      "aaaaaaaaaaaaaaaa",
      "aaaaaaaaaaaaaaaa",
      "aaaaaaaaaaaaaaaa",
      "aaaaaaaaaaaaaaaa",
      "aaaaaaaaaaaaaaaa",
      "aaaaaaaaaaaaaaaa",
      "aaaaaaaaaaaaaaaa"
    ],
    [
      "aaaaaaaaaabbbbbb",
      "aaaaaaaaaabbbbbb",
      "aaaaaaaaaabbbbbb",
      "aaaaaaaaaabbbbbb",
      "aaaaaaaaaabbbbbb",
      "aaaaaaaaaabbbbbb",
      "aaaaaaaaaabbbbbb",
      "aaaaaaaaaabbbbbb",
      "aaaaaaaaaabbbbbb",
      "aaaaaaaaaabbbbbb",
      "aaaaaaaaaabbbbbb",
      "aaaaaaaaaabbbbbb",
      "aaaaaaaaaabbbbbb",
      "aaaaaaaaaabbbbbb",
      "aaaaaaaaaabbbbbb",
      "aaaaaaaaaabbbbbb"
    ],
    [
      "aaaaaaaaaabbbbbb",
      "aaaaaaaaaabbbbbb",
      "aaaaaaaaaabbbbbb",
      "aaaaaaaaaabbbbbb",
      "aaaaaaaaaabbbbbb",
      "aaaaaaaaaabbbbbb",
      "aaaaaaaaaabbbbbb",
      "aaaaaaaaaabbbbbb",
      "aaaaaaaaaabbbbbb",
      "aaaaaaaaaabbbbbb",
      "aaaaaaaaaabbbbbb",
      "aaaaaaaaaabbbbbb",
      "aaaaaaaaaabbbbbb",
      "aaaaaaaaaabbbbbb",
      "aaaaaaaaaabbbbbb",
      "aaaaaaaaaabbbbbb"
    ],
    [
      "aaaaaaaaaabbbbbb",
      "aaaaaaaaaabbbbbb",
      "aaaaaaaaaabbbbbb",
      "aaaaaaaaaabbbbbb",
      "aaaaaaaaaabbbbbb",
      "aaaaaaaaaabbbbbb",
      "aaaaaaaaaabbbbbb",
      "aaaaaaaaaabbbbbb",
      "aaaaaaaaaabbbbbb",
      "aaaaaaaaaabbbbbb",
      "aaaaaaaaaabbbbbb",
      "aaaaaaaaaabbbbbb",
      "aaaaaaaaaabbbbbb",
      "aaaaaaaaaabbbbbb",
      "aaaaaaaaaabbbbbb",
      "aaaaaaaaaabbbbbb"
    ],
    [
      "aaaaaaaaaabbbbbb",
      "aaaaaaaaaabbbbbb",
      "aaaaaaaaaabbbbbb",
      "aaaaaaaaaabbbbbb",
      "aaaaaaaaaabbbbbb",
      "aaaaaaaaaabbbbbb",
      "aaaaaaaaaabbbbbb",
      "aaaaaaaaaabbbbbb",
      "aaaaaaaaaabbbbbb",
      "aaaaaaaaaabbbbbb",
      "aaaaaaaaaabbbbbb",
      "aaaaaaaaaabbbbbb",
      "aaaaaaaaaabbbbbb",
      "aaaaaaaaaabbbbbb",
      "aaaaaaaaaabbbbbb",
      "aaaaaaaaaabbbbbb"
    ],
    [
      "aaaaaaaaaabbbbbb",
      "aaaaaaaaaabbbbbb",
      "aaaaaaaaaabbbbbb",
      "aaaaaaaaaabbbbbb",
      "aaaaaaaaaabbbbbb",
      "aaaaaaaaaabbbbbb",
      "aaaaaaaaaabbbbbb",
      "aaaaaaaaaabbbbbb",
      "aaaaaaaaaabbbbbb",
      "aaaaaaaaaabbbbbb",
      "aaaaaaaaaabbbbbb",
      "aaaaaaaaaabbbbbb",
      "aaaaaaaaaabbbbbb",
      "aaaaaaaaaabbbbbb",
      "aaaaaaaaaabbbbbb",
      "aaaaaaaaaabbbbbb"
    ]
  ]
}