{
  "xsize": 16,
  "zsize": 16,
  "palette": {
    "palette": [
      {
        "char": " ",
        "block": "minecraft:air"
      },
      {
        "char": "r",
        "block": "minecraft:air"
      },
      {
        "char": "v",
        "block": "minecraft:air"
      },
      {
        "char": "i",
        "block": "minecraft:air"
      },
      {
        "char": "t",
        "block": "minecraft:air"
      },
      {
        "char": "y",
        "block": "minecraft:air"
      },
      {
        "char": "2",
        "block": "minecraft:air"
      },
      {
        "char": "w",
        "block": "minecraft:air"
      },
      {
        "char": "o",
        "block": "minecraft:air"
      },
      {
        "char": "m",
        "block": "minecraft:air"
      },
      {
        "char": "s",
        "block": "minecraft:air"
      },
      {
        "char": "u",
        "block": "minecraft:air"
      },
      {
        "char": "ϐ",
        "block": "minecraft:air"
      },
      {
        "char": "骑",
        "block": "minecraft:air",
        "tag": {
          "z": 340,
          "Patterns": [],
          "x": 110,
          "ForgeCaps": {},
          "id": "minecraft:banner",
          "y": 146,
          "CustomName": "{\"text\":\"Carmicheal's\"}"
        }
      },
      {
        "char": "G",
        "block": "minecraft:air"
      },
      {
        "char": "l",
        "block": "minecraft:air"
      },
      {
        "char": "h",
        "block": "minecraft:air"
      },
      {
        "char": "P",
        "block": "minecraft:air"
      },
      {
        "char": "D",
        "block": "minecraft:air"
      },
      {
        "char": "4",
        "block": "minecraft:air"
      },
      {
        "char": "A",
        "block": "minecraft:air"
      },
      {
        "char": "Е",
        "block": "minecraft:air"
      },
      {
        "char": "U",
        "block": "minecraft:tall_grass[half=lower]"
      }
    ]
  },
  "slices": [
    [
      "        r      v",
      "        ri     v",
      "        ri     t",
      "        y2     t",
      "       wo2     t",
      "        o2     t",
      "        ri     t",
      "        ri     m",
      "        r      v",
      "        o2     s",
      "       wovvvsmvs",
      "        uv      ",
      "        ri      ",
      "        ri      ",
      "        ri      ",
      "        ri      "
    ],
    [
      "        r      s",
      "        ri     v",
      "        ri     t",
      "        oϐ      ",
      "       wuϐ      ",
      "        yϐ      ",
      "        ri     t",
      "        r      s",
      "        ri     s",
      "        oϐ     m",
      "       wymmvvssm",
      "        us      ",
      "        ri      ",
      "        ri      ",
      "        ri      ",
      "        ri      "
    ],
    [
      "        ri     s",
      "        ri     m",
      "        r      t",
      "        oϐ      ",
      "       wuϐ    骑i",
      "        oϐ     i",
      "        ri     t",
      "        r      m",
      "        ri     m",
      "        yϐ     v",
      "       wossmsmmm",
      "        ym      ",
      "        r       ",
      "        ri      ",
      "        ri      ",
      "        ri      "
    ],
    [
      "       Gosllllhl",
      "       Govllhllh",
      "       Gymlhhhhl",
      "       Gyvhlhhll",
      "       wovhllhhl",
      "       Gomhhhhhh",
      "       Gumhhllhl",
      "       Gomhhhlhl",
      "       Guvhlhllh",
      "       Gymlllhhh",
      "       woshlhllh",
      "       Gyslhlhll",
      "       Gomlhhhll",
      "       Gumhhlhhh",
      "       Gumhhllhh",
      "       Pymlhhhhl"
    ],
    [
      "       v D 4   4",
      "       v D  444 ",
      "       A D      ",
      "       v D      ",
      "       v D  4444",
      "       v D 4    ",
      "       A D4     ",
      "       A D4     ",
      "       v D4     ",
      "       AЕD 4    ",
      "       vЕD  4444",
      "       v D      ",
      "       v D      ",
      "       v D  4   ",
      "       v D 4    ",
      "       A D4     "
    ],
    [
      "                ",
      "                ",
      "                ",
      "                ",
      "                ",
      "                ",
      "                ",
      "                ",
      "                ",
      "        U       ",
      "        U       ",
      "                ",
      "                ",
      "                ",
      "                ",
      "                "
    ]
  ]
}