{
  "xsize": 16,
  "zsize": 16,
  "palette": {
    "palette": [
      {
        "char": " ",
        "block": "minecraft:air"
      },
      {
        "char": "ύ",
        "block": "minecraft:air"
      },
      {
        "char": "2",
        "block": "minecraft:air"
      },
      {
        "char": "i",
        "block": "minecraft:air"
      },
      {
        "char": "m",
        "block": "minecraft:air"
      },
      {
        "char": "s",
        "block": "minecraft:air"
      },
      {
        "char": "r",
        "block": "minecraft:air"
      },
      {
        "char": "y",
        "block": "minecraft:air"
      },
      {
        "char": "o",
        "block": "minecraft:air"
      },
      {
        "char": "h",
        "block": "minecraft:air"
      },
      {
        "char": "够",
        "block": "minecraft:air"
      },
      {
        "char": "界",
        "block": "minecraft:air"
      },
      {
        "char": "w",
        "block": "minecraft:air"
      },
      {
        "char": "u",
        "block": "minecraft:air"
      },
      {
        "char": "v",
        "block": "minecraft:air"
      },
      {
        "char": "德",
        "block": "minecraft:air"
      },
      {
        "char": "注",
        "block": "minecraft:air"
      },
      {
        "char": "3",
        "block": "minecraft:air"
      },
      {
        "char": "l",
        "block": "minecraft:air"
      },
      {
        "char": "P",
        "block": "minecraft:air"
      },
      {
        "char": "ͱ",
        "block": "minecraft:air"
      },
      {
        "char": "G",
        "block": "minecraft:air"
      },
      {
        "char": "O",
        "block": "minecraft:air"
      },
      {
        "char": "D",
        "block": "minecraft:air"
      },
      {
        "char": "A",
        "block": "minecraft:air"
      },
      {
        "char": "0",
        "block": "minecraft:air"
      },
      {
        "char": "Е",
        "block": "minecraft:air"
      },
      {
        "char": "吗",
        "block": "minecraft:air"
      },
      {
        "char": "U",
        "block": "minecraft:tall_grass[half=lower]"
      }
    ]
  },
  "slices": [
    [
      "           ύ    ",
      "                ",
      "                ",
      "            22 2",
      "imssm       iii ",
      "ryohhm      i够 界",
      "  whhm      i   ",
      "   wuv      i德 注",
      "     r      ii i",
      "     ri         ",
      "     3rrsmiiimsm",
      "        uurrrouu",
      "        w     w ",
      "                ",
      "                ",
      "                "
    ],
    [
      "           ύ    ",
      "                ",
      "                ",
      "            2   ",
      " mvsm       iiii",
      "ruohhm          ",
      "  whhv      i   ",
      "   wum      i   ",
      "     ri     ii i",
      "     r i        ",
      "     3rrmmii vmv",
      "        oorrruoo",
      "        w     w ",
      "                ",
      "                ",
      "                "
    ],
    [
      "    o      ύ    ",
      "     o          ",
      "     o          ",
      "      u         ",
      "imsmv  y    hhhh",
      "ryohhm  o   hhhh",
      "  whhv   oo hhhh",
      "   wos     yhhhh",
      "     ri     hhhh",
      "     r i        ",
      "     3rrmsiiissm",
      "        oyrrruyo",
      "        w     w ",
      "                ",
      "                ",
      "                "
    ],
    [
      "hlhhu      ύ    ",
      "lhhllo          ",
      "hhllhu          ",
      "hllllhu         ",
      "vvslhhho        ",
      "yuovslhhu       ",
      "Pͱwuvlhhhuu     ",
      "   wovhhhhhuoouo",
      "    Pymhhhhhhhhh",
      "    Pymvhhhhhhhh",
      "     Pyosmmsmmmm",
      "      PPoooououy",
      "        wGͱGGGwͱ",
      "                ",
      "                ",
      "                "
    ],
    [
      "   ohO     ύ    ",
      "   oohO         ",
      "    yhO         ",
      "    oohO        ",
      "DDD  uohO       ",
      "   DD oyhOO     ",
      "vAv D  oohhOOOOO",
      "   0 D  yoohhhhh",
      "    A D   oooooo",
      "    v DD        ",
      "     0 ЕDDDDDDDD",
      "      AvЕЕ      ",
      "        vAAvv0vA",
      "                ",
      "                ",
      "                "
    ],
    [
      "    ii     ύ    ",
      "     ii         ",
      "     ii         ",
      "      ii        ",
      "       ii       ",
      "        i     吗 ",
      "         iiii ii",
      "           iii i",
      "              y ",
      "                ",
      "       U        ",
      "        UU      ",
      "                ",
      "                ",
      "                ",
      "                "
    ]
  ]
}