{
  "xsize": 16,
  "zsize": 16,
  "palette": {
    "palette": [
      {
        "char": " ",
        "block": "minecraft:air"
      },
      {
        "char": "t",
        "block": "minecraft:acacia_wood[axis=y]"
      },
      {
        "char": "n",
        "block": "minecraft:birch_planks"
      },
      {
        "char": "C",
        "block": "minecraft:jungle_planks"
      },
      {
        "char": "际",
        "block": "minecraft:blast_furnace[facing=west,lit=false]",
        "tag": {
          "z": 356,
          "x": 115,
          "CookTimeTotal": 0,
          "ForgeData": {
            "LockFlag": "1b"
          },
          "CookTime": 0,
          "ForgeCaps": {
            "polymorph:block_entity_recipe_data": {}
          },
          "id": "minecraft:blast_furnace",
          "y": 144,
          "Items": [],
          "BurnTime": 0,
          "RecipesUsed": {}
        }
      },
      {
        "char": "p",
        "block": "minecraft:oak_planks"
      },
      {
        "char": "m",
        "block": "minecraft:white_concrete"
      },
      {
        "char": "v",
        "block": "minecraft:smooth_quartz"
      },
      {
        "char": "s",
        "block": "minecraft:polished_diorite"
      },
      {
        "char": "i",
        "block": "minecraft:glass"
      },
      {
        "char": "h",
        "block": "minecraft:polished_andesite"
      },
      {
        "char": "o",
        "block": "minecraft:cyan_terracotta"
      },
      {
        "char": "u",
        "block": "minecraft:light_gray_concrete"
      },
      {
        "char": "r",
        "block": "minecraft:light_gray_carpet"
      },
      {
        "char": "w",
        "block": "minecraft:quartz_pillar[axis=y]"
      },
      {
        "char": "3",
        "block": "minecraft:stone_brick_wall[east=none,north=none,south=none,up=true,waterlogged=false,weathering=false,west=none]"
      },
      {
        "char": "ӥ",
        "block": "minecraft:birch_slab[type=bottom,waterlogged=false]"
      },
      {
        "char": "理",
        "block": "minecraft:birch_slab[type=top,waterlogged=false]"
      },
      {
        "char": "y",
        "block": "minecraft:gray_concrete"
      },
      {
        "char": "l",
        "block": "minecraft:andesite"
      },
      {
        "char": "G",
        "block": "minecraft:quartz_slab[type=bottom,waterlogged=false]"
      },
      {
        "char": "P",
        "block": "minecraft:diorite_slab[type=bottom,waterlogged=false]"
      },
      {
        "char": "ͱ",
        "block": "minecraft:smooth_quartz_slab[type=bottom,waterlogged=false]"
      },
      {
        "char": "4",
        "block": "minecraft:red_carpet"
      },
      {
        "char": "D",
        "block": "minecraft:smooth_stone_slab[type=bottom,waterlogged=false]"
      },
      {
        "char": "A",
        "block": "minecraft:quartz_block"
      },
      {
        "char": "0",
        "block": "minecraft:diorite"
      }
    ]
  },
  "slices": [
    [
      "                ",
      "tnCt            ",
      "    t           ",
      "   际p           ",
      "   际C    mmvmsii",
      "    t    vhhourr",
      "tpnt     shhw   ",
      "         muw    ",
      "        io      ",
      "         r      ",
      "       ir       ",
      "     iir3       ",
      " iimsor         ",
      "rrroo           ",
      "    w           ",
      "                "
    ],
    [
      "                ",
      "                ",
      "ӥӥӥӥ            ",
      "ӥ理理ӥ            ",
      "ӥ理理ӥ     mmmvmii",
      "ӥӥӥӥ     vhhuurr",
      "         mhhw   ",
      "         vuw    ",
      "         o      ",
      "        ir      ",
      "       ir       ",
      "       r3       ",
      "i imsor         ",
      "rrrou           ",
      "    w           ",
      "                "
    ],
    [
      "                ",
      "                ",
      "                ",
      "                ",
      "         vvssmii",
      "         shhuorr",
      "         shhw   ",
      "         muw    ",
      "        iy      ",
      "        ir      ",
      "       ir       ",
      "      ir3       ",
      "iiimmyr         ",
      "rrruo           ",
      "    w           ",
      "                "
    ],
    [
      "hhlhhhhhlhllllll",
      "hlhllhhhhlhhhhll",
      "hhlllhllhlhlllhh",
      "lhlhlhlhhhlllhhh",
      "hlhhlhllhlhlmvmv",
      "llllhhhhllmmoouo",
      "lllhhlllhhmowGGP",
      "lllhhllhlmow    ",
      "llhhllhhsuG     ",
      "lllhllhhvyP     ",
      "hhhhhllsuG      ",
      "lhhhlmmyuP      ",
      "msvmmouPG       ",
      "ouyyoGG         ",
      "GGͱGw           ",
      "                "
    ],
    [
      "4     4         ",
      "4     4         ",
      "     4          ",
      "                ",
      "            DDDD",
      "          DD    ",
      "          D A00A",
      "         D A    ",
      "        D 0     ",
      "        D v     ",
      "       D A      ",
      "     DD  v      ",
      "DDDDD  v0       ",
      "     AA         ",
      "Avvvv           ",
      "                "
    ],
    [
      "                ",
      "                ",
      "                ",
      "                ",
      "                ",
      "                ",
      "                ",
      "                ",
      "                ",
      "                ",
      "                ",
      "                ",
      "                ",
      "                ",
      "                ",
      "                "
    ]
  ]
}