{
  "xsize": 16,
  "zsize": 16,
  "palette": {
    "palette": [
      {
        "char": " ",
        "block": "minecraft:air"
      },
      {
        "char": "h",
        "block": "minecraft:air"
      },
      {
        "char": "n",
        "block": "minecraft:air"
      },
      {
        "char": "p",
        "block": "minecraft:air"
      },
      {
        "char": "b",
        "block": "minecraft:air"
      },
      {
        "char": "f",
        "block": "minecraft:air"
      },
      {
        "char": "C",
        "block": "minecraft:air"
      },
      {
        "char": "遇",
        "block": "minecraft:air"
      },
      {
        "char": "D",
        "block": "minecraft:air"
      },
      {
        "char": "k",
        "block": "minecraft:air"
      },
      {
        "char": "功",
        "block": "minecraft:air"
      },
      {
        "char": "t",
        "block": "minecraft:air"
      },
      {
        "char": "o",
        "block": "minecraft:air"
      },
      {
        "char": "I",
        "block": "minecraft:air"
      },
      {
        "char": "U",
        "block": "minecraft:tall_grass[half=lower]"
      },
      {
        "char": "z",
        "block": "minecraft:air"
      },
      {
        "char": "地",
        "block": "minecraft:air"
      },
      {
        "char": "q",
        "block": "minecraft:tall_grass[half=lower]"
      },
      {
        "char": "ҕ",
        "block": "minecraft:air"
      },
      {
        "char": "w",
        "block": "minecraft:air"
      },
      {
        "char": "u",
        "block": "minecraft:air"
      },
      {
        "char": "兄",
        "block": "minecraft:air"
      },
      {
        "char": "Q",
        "block": "minecraft:air"
      },
      {
        "char": "y",
        "block": "minecraft:air"
      },
      {
        "char": "Ӥ",
        "block": "minecraft:air"
      },
      {
        "char": "护",
        "block": "minecraft:air",
        "tag": {
          "z": 303,
          "x": 137,
          "ForgeCaps": {},
          "id": "minecraft:skull",
          "y": 133
        }
      },
      {
        "char": "O",
        "block": "minecraft:air"
      },
      {
        "char": "狂",
        "block": "minecraft:air",
        "tag": {
          "z": 333,
          "x": 143,
          "ForgeCaps": {},
          "id": "minecraft:skull",
          "y": 133
        }
      },
      {
        "char": "m",
        "block": "minecraft:air"
      },
      {
        "char": "V",
        "block": "minecraft:tall_grass[half=upper]"
      },
      {
        "char": "s",
        "block": "minecraft:air"
      },
      {
        "char": "i",
        "block": "minecraft:air"
      },
      {
        "char": "r",
        "block": "minecraft:air"
      },
      {
        "char": "3",
        "block": "minecraft:air"
      },
      {
        "char": "v",
        "block": "minecraft:air"
      }
    ]
  },
  "slices": [
    [
      "hnpnbfffffffffff",
      "npCpbbffffffffff",
      "pnnpbfffffffffff",
      "pnnpbfffffffffff",
      "hpnnbfffffffffff",
      "hnnpbfffffffffff",
      "hpnCbfffffffffff",
      "npnpbbffffffffff",
      "nppbffffffffffff",
      "nnpbffffffffffff",
      "pnbfffffffffffff",
      "pbbfffffffffffff",
      "bfffffffffffffff",
      "fffffff遇ffffffff",
      "ffffffffffffffff",
      "ffffffffffffffff"
    ],
    [
      "Dk功toIkUz地zqkqqq",
      "Dqҕtowqzqqkzkqk ",
      "DkҕtoIqkqqkkkqzk",
      "DkҕtuIqzqkqkqqkq",
      "Dk兄toQqqzqzzzkzk",
      "DkqtoQkqkzqkqq z",
      "DkktyQk地zUqkqzkk",
      "DkqtuwqqkUqkqkqk",
      "  tyӤq护qkqqqzzqz",
      "qztuOkqkzkqkqzqk",
      "ktyIkkqzzqqqkqqq",
      "tooIkqkkUqkqqzqk",
      "oIӤqzq地kkqzkkqzk",
      "Iqqqkkz kqkkqzkk",
      "qUUqk地k地kqzkqqkq",
      "kqqqkqqkk狂kqqkkk"
    ],
    [
      "   my  V        ",
      "   mow          ",
      "   sy           ",
      "   ir           ",
      "   ir           ",
      "   ir           ",
      "   my    V      ",
      "   suw   V      ",
      "  iu            ",
      "  ir            ",
      " ir             ",
      " r3     V       ",
      "r               ",
      "                ",
      " VV             ",
      "                "
    ],
    [
      "   my           ",
      "   sow          ",
      "   my           ",
      "    r           ",
      "   ir           ",
      "   ir           ",
      "   mu           ",
      "   sow          ",
      "  iy            ",
      "  ir            ",
      " ir             ",
      "ir3             ",
      "r               ",
      "                ",
      "                ",
      "                "
    ],
    [
      "   so           ",
      "   suw          ",
      "   sy           ",
      "   ir           ",
      "   ir           ",
      "    r           ",
      "   su           ",
      "   vuw          ",
      "  iy            ",
      "  ir            ",
      " ir             ",
      "ir3             ",
      "r               ",
      "                ",
      "                ",
      "                "
    ],
    [
      "   mu           ",
      "   sow          ",
      "   mo           ",
      "   ir           ",
      "   ir           ",
      "   ir           ",
      "   vu           ",
      "   muw          ",
      "  iu            ",
      "  ir            ",
      " ir             ",
      "ir3             ",
      "r               ",
      "                ",
      "                ",
      "                "
    ]
  ]
}