{
  "xsize": 16,
  "zsize": 16,
  "palette": {
    "palette": [
      {
        "char": " ",
        "block": "minecraft:air"
      },
      {
        "char": "Y",
        "block": "minecraft:air"
      },
      {
        "char": "S",
        "block": "minecraft:air"
      },
      {
        "char": "T",
        "block": "minecraft:air"
      },
      {
        "char": "e",
        "block": "minecraft:air"
      },
      {
        "char": "0",
        "block": "minecraft:air"
      },
      {
        "char": "s",
        "block": "minecraft:air"
      },
      {
        "char": "f",
        "block": "minecraft:air"
      },
      {
        "char": "太",
        "block": "minecraft:air"
      },
      {
        "char": "Z",
        "block": "minecraft:air"
      },
      {
        "char": "A",
        "block": "minecraft:air"
      },
      {
        "char": "o",
        "block": "minecraft:air"
      },
      {
        "char": "m",
        "block": "minecraft:air"
      },
      {
        "char": "ђ",
        "block": "minecraft:air",
        "tag": {
          "SpawnData": {
            "entity": {}
          },
          "MaxNearbyEntities": "6s",
          "MinSpawnDelay": "200s",
          "z": 359,
          "x": 108,
          "MaxSpawnDelay": "800s",
          "RequiredPlayerRange": "16s",
          "SpawnCount": "4s",
          "ForgeCaps": {},
          "id": "minecraft:mob_spawner",
          "SpawnPotentials": [],
          "y": 132,
          "SpawnRange": "4s",
          "Delay": "416s"
        }
      },
      {
        "char": "k",
        "block": "minecraft:air"
      },
      {
        "char": "z",
        "block": "minecraft:air"
      },
      {
        "char": "q",
        "block": "minecraft:grass"
      },
      {
        "char": "吧",
        "block": "minecraft:air"
      },
      {
        "char": "下",
        "block": "minecraft:air"
      },
      {
        "char": "x",
        "block": "minecraft:air"
      },
      {
        "char": "ύ",
        "block": "minecraft:air"
      },
      {
        "char": "ӗ",
        "block": "minecraft:air"
      },
      {
        "char": "且",
        "block": "minecraft:air"
      }
    ]
  },
  "slices": [
    [
      "YSTe0sffffffffff",
      "太fTZ0Affffffffff",
      "ZYZTAsffffffffff",
      "ZoSSA0ffffffffff",
      "YTTfAfffffffffff",
      "ToeSA0ffffffffff",
      "YSTe0sffffffffff",
      "太fTZ0Affffffffff",
      "ZYZTAsffffffffff",
      "ZoSSA0ffffffffff",
      "YTTfAfffffffffff",
      "ToeSA0ffffffffff",
      "YSTe0sffffffffff",
      "太fTZ0Affffffffff",
      "ofeeA0ffffffffff",
      "mfmeђs0A0AAA0sђs"
    ],
    [
      "kzkk  qkkkzq q k",
      "zq k   qqkzzkk z",
      "k kkkkq kkqqkqkq",
      "k k kkkkkkkkqkqk",
      "kkzkzkk zkkkzzqz",
      "qzkk kq qkqqqkkk",
      "kzkk  kqqqzkqkkk",
      "zq k qkkqqkzkqzk",
      "k kkkkkk zzqkzk ",
      "k k kkkkqkzqkkqq",
      "kkzkzkkk qqkkzqq",
      "qzkk kq kkqkqqkq",
      "kzkk  kkkqqkqqkq",
      "zq k qzqkqkkqqkq",
      "qqqq吧下xxxxxύqkqk",
      "kkkk下xxxxxӗqzk且k"
    ],
    [
      "                ",
      "                ",
      "                ",
      "                ",
      "                ",
      "                ",
      "                ",
      "                ",
      "                ",
      "                ",
      "                ",
      "                ",
      "                ",
      "                ",
      "      xxxx      ",
      "       x        "
    ],
    [
      "                ",
      "                ",
      "                ",
      "                ",
      "                ",
      "                ",
      "                ",
      "                ",
      "                ",
      "                ",
      "                ",
      "                ",
      "                ",
      "                ",
      "                ",
      "                "
    ],
    [
      "                ",
      "                ",
      "                ",
      "                ",
      "                ",
      "                ",
      "                ",
      "                ",
      "                ",
      "                ",
      "                ",
      "                ",
      "                ",
      "                ",
      "                ",
      "                "
    ],
    [
      "                ",
      "                ",
      "                ",
      "                ",
      "                ",
      "                ",
      "                ",
      "                ",
      "                ",
      "                ",
      "                ",
      "                ",
      "                ",
      "                ",
      "                ",
      "                "
    ]
  ]
}