{
  "xsize": 16,
  "zsize": 16,
  "palette": {
    "palette": [
      {
        "char": " ",
        "block": "minecraft:air"
      },
      {
        "char": "a",
        "block": "minecraft:stone[weathering=false]"
      },
      {
        "char": "b",
        "block": "minecraft:dirt"
      },
      {
        "char": "c",
        "block": "minecraft:mossy_stone_bricks"
      },
      {
        "char": "d",
        "block": "minecraft:stone_bricks[weathering=false]"
      },
      {
        "char": "e",
        "block": "minecraft:cracked_stone_bricks"
      },
      {
        "char": "j",
        "block": "minecraft:cobblestone[weathering=false]"
      }
    ]
  },
  "slices": [
    [
      "aaaaaaaaaaaaaaaa",
      "aaaaaaaaaaaaaaaa",
      "aaaaaaaaaaaaaaaa",
      "aaaaaaaaaaaaaaaa",
      "aaaaaaaaaaaaaaaa",
      "aaaaaaaaaaaaaaaa",
      "aaaaaaaaaaaaaaaa",
      "aaaaaaaaaaaaaaaa",
      "aaaaaaaaaaaaaaaa",
      "aaaaaaaaaaaaaaaa",
      "aaaaaaaaaaaaaaaa",
      "aaaaaaaaaaaaaaaa",
      "aaaaaaaaaaaaaaaa",
      "aaaaaaaaaaaaaaaa",
      "aaaaaaaaaaaaaaaa",
      "aaaaaaaaaaaaaaaa"
    ],
    [
      "aaaaaaaaaabbbbbb",
      "aaaaaaaaaabbbbbb",
      "aaaaaaaaaabbbbbb",
      "aaaaaaaaaabbbbbb",
      "aaaaaaaaaabbbbbb",
      "aaaaaaaaaabbbbbb",
      "aaaaaaaaaabbbbbb",
      "aaaaaaaaaabbbbbb",
      "aaaaaaaaaabbbbbb",
      "aaaaaaaaaabbbbbb",
      "aaaaaaaaaabbbbbb",
      "aaaaaaaaaabbbbbb",
      "aaaaaaaaaabbbbbb",
      "aaaaaaaaaabbbbbb",
      "aaaaaaaaaabbbbbb",
      "aaaaaaaaaabbbbbb"
    ],
    [
      "aaaaaaaaaabbbbbb",
      "aaaaaaaaaabbbbbb",
      "aaaaaaaaaabbbbbb",
      "aaaaaaaaaabbbbbb",
      "aaaaaaaaaabbbbbb",
      "aaaaaaaaaabbbbbb",
      "aaaaaaaaaabbbbbb",
      "aaaaaaaaaabbbbbb",
      "aaaaaaaaaabbbbbb",
      "aaaaaaaaaabbbbbb",
      "aaaaaaaaaabbbbbb",
      "aaaaaaaaaabbbbbb",
      "aaaaaaaaaabbbbbb",
      "aaaaaaaaaabbbbbb",
      "aaaaaaaaaabbbbbb",
      "aaaaaaaaaabbbbbb"
    ],
    [
      "aaaaaaaaaabbbbbb",
      "aaaaaaaaaabbbbbb",
      "aaaaaaaaaabbbbbb",
      "aaaaaaaaaabbbbbb",
      "aaaaaaaaaabbbbbb",
      "aaaaaaaaaabbbbbb",
      "aaaaaaaaaabbbbbb",
      "aaaaaaaaaabbbbbb",
      "aaaaaaaaaabbbbbb",
      "aaaaaaaaaabbbbbb",
      "aaaaaaaaaabbbbbb",
      "aaaaaaaaaabbbbbb",
      "aaaaaaaaaabbbbbb",
      "aaaaaaaaaabbbbbb",
      "aaaaaaaaaabbbbbb",
      "aaaaaaaaaabbbbbb"
    ],
    [
      "aaaaaaaaaabbbbbb",
      "aaaaaaaaaabbbbbb",
      "aaaaaaaaaabbbbbb",
      "aaaaaaaaaabbbbbb",
      "aaaaaaaaaabbbbbb",
      "aaaaaaaaaabbbbbb",
      "aaaaaaaaaabbbbbb",
      "aaaaaaaaaabbbbbb",
      "aaaaaaaaaabbbbbb",
      "aaaaaaaaaabbbbbb",
      "aaaaaaaaaabbbbbb",
      "aaaaaaaaaabbbbbb",
      "aaaaaaaaaabbbbbb",
      "aaaaaaaaaabbbbbb",
      "aaaaaaaaaabbbbbb",
      "aaaaaaaaaabbbbbb"
    ],
    [
      "caaaaaaaaabbbbbb",
      "caaaaaaaaabbbbbb",
      "daaaaaaaaabbbbbb",
      "daaaaaaaaabbbbbb",
      "caaaaaaaaabbbbbb",
      "eaaaaaaaaabbbbbb",
      "caaaaaaaaabbbbbb",
      "jeeaaaaaaabbbbbb",
      "aaaaaaaaaabbbbbb",
      "aaaaaaaaaabbbbbb",
      "aaaaaaaaaabbbbbb",
      "aaaaaaaaaabbbbbb",
      "aaaaaaaaaabbbbbb",
      "aaaaaaaaaabbbbbb",
      "aaaaaaaaaabbbbbb",
      "aaaaaaaaaabbbbbb"
    ]
  ]
}