{
  "xsize": 16,
  "zsize": 16,
  "palette": {
    "palette": [
      {
        "char": " ",
        "block": "minecraft:air"
      },
      {
        "char": "s",
        "block": "minecraft:air"
      },
      {
        "char": "n",
        "block": "minecraft:air"
      },
      {
        "char": "b",
        "block": "minecraft:air"
      },
      {
        "char": "f",
        "block": "minecraft:air"
      },
      {
        "char": "长",
        "block": "minecraft:air",
        "loot": "bigbuildingsloot",
        "tag": {
          "z": 338,
          "x": 108,
          "ForgeData": {
            "LockFlag": "1b"
          },
          "ForgeCaps": {},
          "id": "minecraft:chest",
          "y": 133,
          "Items": []
        }
      },
      {
        "char": "p",
        "block": "minecraft:air"
      },
      {
        "char": "C",
        "block": "minecraft:air"
      },
      {
        "char": "h",
        "block": "minecraft:air"
      },
      {
        "char": "k",
        "block": "minecraft:air"
      },
      {
        "char": "t",
        "block": "minecraft:air"
      },
      {
        "char": "u",
        "block": "minecraft:air"
      },
      {
        "char": "Ӥ",
        "block": "minecraft:air"
      },
      {
        "char": "z",
        "block": "minecraft:air"
      },
      {
        "char": "q",
        "block": "minecraft:grass"
      },
      {
        "char": "幸",
        "block": "minecraft:air"
      },
      {
        "char": "o",
        "block": "minecraft:air"
      },
      {
        "char": "I",
        "block": "minecraft:air"
      },
      {
        "char": "U",
        "block": "minecraft:tall_grass[half=lower]"
      },
      {
        "char": "Q",
        "block": "minecraft:air"
      },
      {
        "char": "x",
        "block": "minecraft:air"
      },
      {
        "char": "w",
        "block": "minecraft:air"
      },
      {
        "char": "力",
        "block": "minecraft:air"
      },
      {
        "char": "啥",
        "block": "minecraft:air",
        "tag": {
          "z": 341,
          "x": 178,
          "ForgeCaps": {},
          "id": "refurbished_furniture:toilet",
          "y": 133,
          "FluidTank": {
            "FluidTank": {
              "Amount": 0,
              "FluidName": "minecraft:empty"
            }
          }
        }
      },
      {
        "char": "改",
        "block": "minecraft:air"
      },
      {
        "char": "目",
        "block": "minecraft:air"
      },
      {
        "char": "y",
        "block": "minecraft:air"
      },
      {
        "char": "看",
        "block": "minecraft:air"
      },
      {
        "char": "O",
        "block": "minecraft:air"
      },
      {
        "char": "Ӗ",
        "block": "minecraft:air"
      },
      {
        "char": "破",
        "block": "minecraft:air"
      },
      {
        "char": "D",
        "block": "minecraft:air"
      },
      {
        "char": "i",
        "block": "minecraft:air"
      },
      {
        "char": "r",
        "block": "minecraft:air"
      },
      {
        "char": "V",
        "block": "minecraft:tall_grass[half=upper]"
      },
      {
        "char": "ӫ",
        "block": "minecraft:air"
      },
      {
        "char": "v",
        "block": "minecraft:air"
      },
      {
        "char": "m",
        "block": "minecraft:air"
      },
      {
        "char": "报",
        "block": "minecraft:air"
      }
    ]
  },
  "slices": [
    [
      "sssnbfffffffffff",
      "长ssnbfffffffffff",
      "sssnbfffffffffff",
      "sssnbfffffffffff",
      "npnpbbffffffffff",
      "nnnpbfffffffffff",
      "ppnnbfffffffffff",
      "pppnbfffffffffff",
      "ppCnbfffffffffff",
      "pnnpbfffffffffff",
      "pCnpbbffffffffff",
      "nnnpbfffffffffff",
      "npnpbfffffffffff",
      "npppbfffffffffff",
      "hnnnbfffffffffff",
      "hnpCbfffffffffff"
    ],
    [
      "  ktuӤzkqqkqqqkk",
      "幸hhtoIUzkkqkqq k",
      "kkztoQqqkkqkqqqz",
      "   toQxzkkkqqqkq",
      "ttttowkqkkkqkqkk",
      "力k啥tuIkkkkk kkzz",
      "力  tuӤkqkkkkkzkq",
      "k改目tyQqkqkkkqkkk",
      "k ktoQqzkqqqzkkq",
      "看看看tuOkqkqqkqqzq",
      "ttttowkkkUkkqz q",
      "Ӗ破qtoIkkkqzzqqkk",
      "kqktoOzkkqzkkkkq",
      "DkktyIkkqkqzkqkk",
      "DqktuQkqqqzkqkqq",
      "DkktoIkkUUkkkqzz"
    ],
    [
      "   ir           ",
      "Ӗ  ir V         ",
      "   ir x         ",
      "   ӫo x         ",
      "vssmow          ",
      "力  vu           ",
      "力  ir           ",
      " 报目ir           ",
      "   ir           ",
      "   mo           ",
      "vsvsuw   V      ",
      "   mo           ",
      "   ir           ",
      "   ir           ",
      "    r           ",
      "   ir   VV      "
    ],
    [
      "    r           ",
      "   ir           ",
      "   ir           ",
      "   ӫoxx         ",
      "mmvmuw          ",
      "力  mu           ",
      "力  ir           ",
      " 目目ir           ",
      "    r           ",
      "   mo           ",
      "ssssyw          ",
      "   vu           ",
      "   ir           ",
      "   ir           ",
      "   ir           ",
      "    r           "
    ],
    [
      "    r           ",
      "   ir           ",
      "   ir           ",
      "   ӫox          ",
      "vsvmow          ",
      "   mo           ",
      "   ir           ",
      "    r           ",
      "   ir           ",
      "   my           ",
      "mvsmow          ",
      "   mo           ",
      "   ir           ",
      "   ir           ",
      "    r           ",
      "   ir           "
    ],
    [
      "    r           ",
      "   ir           ",
      "    rx          ",
      "   ӫox          ",
      "ssvmow          ",
      "   my           ",
      "    r           ",
      "   ir           ",
      "   ir           ",
      "   vo           ",
      "smmsyw          ",
      "   vy           ",
      "    r           ",
      "   ir           ",
      "   ir           ",
      "   ir           "
    ]
  ]
}