{
  "xsize": 16,
  "zsize": 16,
  "palette": {
    "palette": [
      {
        "char": " ",
        "block": "minecraft:air"
      },
      {
        "char": "2",
        "block": "minecraft:air"
      },
      {
        "char": "i",
        "block": "minecraft:air"
      },
      {
        "char": "m",
        "block": "minecraft:air"
      },
      {
        "char": "s",
        "block": "minecraft:air"
      },
      {
        "char": "h",
        "block": "minecraft:air"
      },
      {
        "char": "o",
        "block": "minecraft:air"
      },
      {
        "char": "r",
        "block": "minecraft:air"
      },
      {
        "char": "y",
        "block": "minecraft:air"
      },
      {
        "char": "w",
        "block": "minecraft:air"
      },
      {
        "char": "v",
        "block": "minecraft:air"
      },
      {
        "char": "u",
        "block": "minecraft:air"
      },
      {
        "char": "3",
        "block": "minecraft:air"
      },
      {
        "char": "ӊ",
        "block": "minecraft:air"
      },
      {
        "char": "Ͳ",
        "block": "minecraft:air"
      },
      {
        "char": "l",
        "block": "minecraft:air"
      },
      {
        "char": "G",
        "block": "minecraft:air"
      },
      {
        "char": "ͱ",
        "block": "minecraft:air"
      },
      {
        "char": "O",
        "block": "minecraft:air"
      },
      {
        "char": "D",
        "block": "minecraft:air"
      },
      {
        "char": "A",
        "block": "minecraft:air"
      },
      {
        "char": "0",
        "block": "minecraft:air"
      },
      {
        "char": "Е",
        "block": "minecraft:air"
      },
      {
        "char": "U",
        "block": "minecraft:tall_grass[half=lower]"
      }
    ]
  },
  "slices": [
    [
      "                ",
      "                ",
      "                ",
      "2               ",
      "i       mmmmi  s",
      "i      mhhoorrry",
      "       shhw     ",
      "       vuw      ",
      "i      r        ",
      "     iir        ",
      "i immrr3        ",
      "rrroo           ",
      "    w     ӊ     ",
      "         ӊͲӊ    ",
      "          ӊ     ",
      "                "
    ],
    [
      "                ",
      "                ",
      "                ",
      "2               ",
      "i       svssiiiv",
      "       shhyyrrro",
      "       shhw     ",
      "i      suw      ",
      "i     ir        ",
      "     iir        ",
      "iiimmrr3        ",
      "rrruo           ",
      "    w           ",
      "                ",
      "                ",
      "                "
    ],
    [
      "        o       ",
      "       o        ",
      "       u        ",
      "      o         ",
      "h    o  mmmsiiim",
      "h   u  mhhourrro",
      "h yy   shhw     ",
      "ho     muw      ",
      "h      r        ",
      "     iir        ",
      "iiismrr3        ",
      "rrruu           ",
      "    w           ",
      "                ",
      "                ",
      "                "
    ],
    [
      "        olhhhhll",
      "       uhllhhhhh",
      "       uhlhlhlll",
      "      ohhlhlllhl",
      "     yhhhlmvmssm",
      "    ohhlvsoouoou",
      "  oyhhhhmowGGGͱG",
      "ouhhhhhsuw      ",
      "hhhhhhmoG       ",
      "hhhhhvmoG       ",
      "mmvssuuG        ",
      "uuyouͱG         ",
      "GGGGw           ",
      "                ",
      "                ",
      "                "
    ],
    [
      "       Ohu      ",
      "      Ohyo      ",
      "      Ohu       ",
      "     Ohou       ",
      "    Ohou  DDDDDD",
      "  OOhyu DD      ",
      "OOhhou  D A0vvvv",
      "hhuyo  D A      ",
      "oou   D A       ",
      "     DD A       ",
      "DDDDD  v        ",
      " Е   vv         ",
      "AvvvA           ",
      "                ",
      "                ",
      "                "
    ],
    [
      "       i        ",
      "      i         ",
      "      i         ",
      "     ii         ",
      "    ii          ",
      "   ii           ",
      "iiii            ",
      "ii              ",
      "                ",
      "                ",
      "                ",
      " U              ",
      "                ",
      "                ",
      "                ",
      "                "
    ]
  ]
}