{
  "xsize": 16,
  "zsize": 16,
  "palette": {
    "palette": [
      {
        "char": " ",
        "block": "minecraft:air"
      },
      {
        "char": "m",
        "block": "minecraft:white_concrete"
      },
      {
        "char": "o",
        "block": "minecraft:cyan_terracotta"
      },
      {
        "char": "y",
        "block": "minecraft:gray_concrete"
      },
      {
        "char": "w",
        "block": "minecraft:quartz_pillar[axis=y]"
      },
      {
        "char": "v",
        "block": "minecraft:smooth_quartz"
      },
      {
        "char": "u",
        "block": "minecraft:light_gray_concrete"
      },
      {
        "char": "i",
        "block": "minecraft:glass"
      },
      {
        "char": "r",
        "block": "minecraft:light_gray_carpet"
      },
      {
        "char": "s",
        "block": "minecraft:polished_diorite"
      },
      {
        "char": "3",
        "block": "minecraft:stone_brick_wall[east=none,north=none,south=none,up=true,waterlogged=false,weathering=false,west=none]"
      },
      {
        "char": "l",
        "block": "minecraft:andesite"
      },
      {
        "char": "G",
        "block": "minecraft:quartz_slab[type=bottom,waterlogged=false]"
      },
      {
        "char": "h",
        "block": "minecraft:polished_andesite"
      },
      {
        "char": "ͱ",
        "block": "minecraft:smooth_quartz_slab[type=bottom,waterlogged=false]"
      },
      {
        "char": "P",
        "block": "minecraft:diorite_slab[type=bottom,waterlogged=false]"
      },
      {
        "char": "n",
        "block": "minecraft:birch_planks"
      },
      {
        "char": "p",
        "block": "minecraft:oak_planks"
      },
      {
        "char": "B",
        "block": "minecraft:smooth_stone"
      },
      {
        "char": "C",
        "block": "minecraft:jungle_planks"
      },
      {
        "char": "a",
        "block": "minecraft:stone[weathering=false]"
      },
      {
        "char": "j",
        "block": "minecraft:cobblestone[weathering=false]"
      },
      {
        "char": "ώ",
        "block": "minecraft:gray_carpet"
      },
      {
        "char": "兰",
        "block": "minecraft:dark_oak_stairs[facing=south,half=bottom,shape=inner_left,waterlogged=false]"
      },
      {
        "char": "t",
        "block": "minecraft:acacia_wood[axis=y]"
      },
      {
        "char": "Q",
        "block": "minecraft:diorite_slab[type=top,waterlogged=false]"
      },
      {
        "char": "方",
        "block": "minecraft:air"
      },
      {
        "char": "模",
        "block": "minecraft:air"
      },
      {
        "char": "北",
        "block": "minecraft:air"
      },
      {
        "char": "O",
        "block": "minecraft:smooth_quartz_slab[type=top,waterlogged=false]"
      },
      {
        "char": "I",
        "block": "minecraft:quartz_slab[type=top,waterlogged=false]"
      },
      {
        "char": "详",
        "block": "minecraft:air"
      },
      {
        "char": "k",
        "block": "minecraft:air"
      }
    ]
  },
  "slices": [
    [
      "   mo           ",
      "   myw          ",
      "   vu           ",
      "   ir           ",
      "   ir           ",
      "   ir           ",
      "   so           ",
      "   myw          ",
      "  io            ",
      "  ir            ",
      "  r             ",
      "ir3             ",
      "r               ",
      "                ",
      "                ",
      "                "
    ],
    [
      "lllmuG          ",
      "hllmow          ",
      "hhlmoG          ",
      "hlhsoͱ          ",
      "lhhsuͱ          ",
      "hllmuG          ",
      "lhlmuͱ          ",
      "lllmuw          ",
      "hhmoG           ",
      "hhsoG           ",
      "lsuG            ",
      "myoP            ",
      "oͱP             ",
      "P               ",
      "                ",
      "                "
    ],
    [
      "npnBm           ",
      "nCpamw          ",
      "npnas           ",
      "pCpBm           ",
      "nnnBm           ",
      "CCnjm           ",
      "ppCam           ",
      "nppBsw          ",
      "pCam            ",
      "nnBm            ",
      "nBs             ",
      "amv             ",
      "m               ",
      "                ",
      "                ",
      "                "
    ],
    [
      " ώ兰toQ          ",
      " 方模tuw          ",
      "  北toO          ",
      " 方北toO          ",
      "  北tuI          ",
      " 方北tuQ          ",
      "  北tyI          ",
      " 方详tyw          ",
      "  tyQ           ",
      "  toQ           ",
      " toI            ",
      "tyoI            ",
      "oIQ             ",
      "I               ",
      "                ",
      "                "
    ],
    [
      "   mu           ",
      "   mow          ",
      "   my           ",
      "    r           ",
      "   ir           ",
      "   ir           ",
      "   sy           ",
      "   myw          ",
      "  iy            ",
      "  irk           ",
      " irk            ",
      "ir3k            ",
      "r               ",
      "                ",
      "                ",
      "                "
    ],
    [
      "   mo           ",
      "   mow          ",
      "   mo           ",
      "   ir           ",
      "   ir           ",
      "   ir           ",
      "   mo           ",
      "   vow          ",
      "  io            ",
      "   r            ",
      " ir             ",
      " r3             ",
      "r               ",
      "                ",
      "                ",
      "                "
    ]
  ]
}