{
  "xsize": 16,
  "zsize": 16,
  "palette": {
    "palette": [
      {
        "char": " ",
        "block": "minecraft:air"
      },
      {
        "char": "d",
        "block": "minecraft:air"
      },
      {
        "char": "e",
        "block": "minecraft:air"
      },
      {
        "char": "c",
        "block": "minecraft:air"
      },
      {
        "char": "j",
        "block": "minecraft:air"
      },
      {
        "char": "g",
        "block": "minecraft:air"
      },
      {
        "char": "V",
        "block": "minecraft:tall_grass[half=upper]"
      },
      {
        "char": "ї",
        "block": "minecraft:air"
      },
      {
        "char": "8",
        "block": "minecraft:air"
      },
      {
        "char": "急",
        "block": "minecraft:air"
      },
      {
        "char": "m",
        "block": "minecraft:air"
      },
      {
        "char": "猪",
        "block": "minecraft:air"
      },
      {
        "char": "选",
        "block": "minecraft:air"
      },
      {
        "char": "毕",
        "block": "minecraft:air"
      },
      {
        "char": "压",
        "block": "minecraft:air"
      },
      {
        "char": "哥",
        "block": "minecraft:air",
        "tag": {
          "z": 318,
          "Patterns": [
            {
              "Color": 0,
              "Pattern": "dls"
            },
            {
              "Color": 3,
              "Pattern": "gru"
            },
            {
              "Color": 15,
              "Pattern": "bo"
            }
          ],
          "x": 107,
          "ForgeCaps": {},
          "id": "minecraft:banner",
          "y": 127
        }
      },
      {
        "char": "B",
        "block": "minecraft:air"
      },
      {
        "char": "但",
        "block": "minecraft:air"
      },
      {
        "char": "F",
        "block": "minecraft:air"
      },
      {
        "char": "H",
        "block": "minecraft:air"
      },
      {
        "char": "5",
        "block": "minecraft:air"
      },
      {
        "char": "人",
        "block": "minecraft:air"
      },
      {
        "char": "a",
        "block": "minecraft:air"
      },
      {
        "char": "G",
        "block": "minecraft:air"
      },
      {
        "char": "刻",
        "block": "minecraft:air"
      },
      {
        "char": "ӝ",
        "block": "minecraft:air"
      },
      {
        "char": "ό",
        "block": "minecraft:air"
      }
    ]
  },
  "slices": [
    [
      "ddecejgcjgeccegg",
      "gjgedgeggedcdjgj",
      "cgcejcgjcecjecdc",
      "jjcejjecjcjcgcec",
      "eceggcjcccgcegec",
      "jjgceegjcegceccc",
      "ccegcgggc       ",
      "ccgegcjjc VV  ї ",
      "gegcgeejc V 8   ",
      "ecgjgcgje       ",
      "egjeegcge       ",
      "cjjjjgjce V     ",
      "gceccgcecV      ",
      "gjjgcgcdjecg8   ",
      "ccgcc急m猪m选选选c   ",
      "djecc毕m压m   c   "
    ],
    [
      "ccgcgcejcdgdgeej",
      "jecedeccggdjcced",
      "cgecgeedccdejcjc",
      "gcgejgeejcjecgee",
      "gjggeecededdcccg",
      "gggegecgeggccgcg",
      "eggccccgg       ",
      "ggcecceee     ї ",
      "ccjgcggcc   8   ",
      "ecececjec       ",
      "cgeceeceg       ",
      "cceccggge       ",
      "jgecjjgcg       ",
      "ejegjccccgcg8   ",
      "ceece    哥哥哥g   ",
      "jecce       g   "
    ],
    [
      "dgdgdgcccejdjccc",
      "cgejcgjcgccjcccg",
      "jeeejjcdcdggccjc",
      "cccecdgjjgccjegc",
      "Bjccecgcgcjeeecc",
      "Bcccgcjjdeegceeg",
      "Bjdgegjce       ",
      "Beegecegj     ї ",
      "Bcegccded   8   ",
      "Bejcjgccc       ",
      "Bgcjgdejc       ",
      "Bgececdeg       ",
      "Bgcgccgjc       ",
      "Beecgegececg8但  ",
      "BdjgjgejgecgjF  ",
      "BcgecccjHeggjF  "
    ],
    [
      "dddjdgegdcdcgccc",
      "cegjjdjddeeeddce",
      "ccececgcggccgddd",
      "Bdeecgdddjcgddde",
      "BBjjegededcccdce",
      "BBceeddecdeecdgd",
      "BBggcedgggeeegdg",
      "BBedgdcggegcjd5d",
      "BBgecgedgjdHdded",
      "BBjccgejgeeegddj",
      "BBeejegccjdecHgd",
      "BBcgccgjgdgecHgg",
      "BBeeececcddgdHjg",
      "BBjcddedjgeece人H",
      "BBeeccggecdgdgcd",
      "BBjcgdcedgjejegg"
    ],
    [
      "aaaaaaaaaaaaaaaa",
      "aaaaaaaaaaaaaaaa",
      "aaaaaaaaaaaaaaaa",
      "Baaaaaaaaaaaaaaa",
      "jBaaaaaaaaaaaaaa",
      "jBaaaaaaaaaaaaaa",
      "jBaaaaaaaaaaaaaa",
      "jBaaaaaaaaaaaa5a",
      "jBaaaaaaaaaaaaaa",
      "jBaaaaaaaaaaaaaa",
      "jBaaaaaaaaaaaaaa",
      "jBaaaaaaaaaaaaaa",
      "jBaaaaaaaaaaaaaa",
      "jBaaaaaaaaaaaaaa",
      "jBaaaaaaaaaaaaaa",
      "jBaaaaaaaaaaaaaa"
    ],
    [
      "aaaaaaaaaaaaaaaa",
      "aaaaaaaaaaaaaaaa",
      "aaaaaaaaaaaaaaaa",
      "aaaaaaaaaaaaaaaa",
      "Baaaaaaaaaaaaaaa",
      "Baaaaaaaaaaaaaaa",
      "BaaaaaaaaaaaaaGa",
      "Baaaaaaaaaaaa刻5G",
      "Baaaaaaaaaaaaaӝό",
      "Baaaaaaaaaaaaaόa",
      "Baaaaaaaaaaaaaaa",
      "Baaaaaaaaaaaaaaa",
      "Baaaaaaaaaaaaaaa",
      "Baaaaaaaaaaaaaaa",
      "Baaaaaaaaaaaaaaa",
      "Baaaaaaaaaaaaaaa"
    ]
  ]
}