{
  "xsize": 16,
  "zsize": 16,
  "palette": {
    "palette": [
      {
        "char": " ",
        "block": "minecraft:air"
      },
      {
        "char": "Y",
        "block": "minecraft:blackstone"
      },
      {
        "char": "S",
        "block": "minecraft:cobbled_deepslate"
      },
      {
        "char": "T",
        "block": "minecraft:deepslate[axis=y]"
      },
      {
        "char": "e",
        "block": "minecraft:cracked_stone_bricks"
      },
      {
        "char": "0",
        "block": "minecraft:diorite"
      },
      {
        "char": "s",
        "block": "minecraft:polished_diorite"
      },
      {
        "char": "f",
        "block": "minecraft:grass_block[snowy=false]"
      },
      {
        "char": "太",
        "block": "minecraft:mossy_stone_brick_stairs[facing=south,half=bottom,shape=straight,waterlogged=false]"
      },
      {
        "char": "Z",
        "block": "minecraft:basalt[axis=x]"
      },
      {
        "char": "A",
        "block": "minecraft:quartz_block"
      },
      {
        "char": "o",
        "block": "minecraft:cyan_terracotta"
      },
      {
        "char": "m",
        "block": "minecraft:white_concrete"
      },
      {
        "char": "ђ",
        "block": "minecraft:spawner",
        "tag": {
          "SpawnData": {
            "entity": {}
          },
          "MaxNearbyEntities": "6s",
          "MinSpawnDelay": "200s",
          "z": 359,
          "x": 108,
          "MaxSpawnDelay": "800s",
          "RequiredPlayerRange": "16s",
          "SpawnCount": "4s",
          "ForgeCaps": {},
          "id": "minecraft:mob_spawner",
          "SpawnPotentials": [],
          "y": 132,
          "SpawnRange": "4s",
          "Delay": "416s"
        }
      },
      {
        "char": "k",
        "block": "minecraft:air"
      },
      {
        "char": "z",
        "block": "minecraft:air"
      },
      {
        "char": "q",
        "block": "minecraft:air"
      },
      {
        "char": "吧",
        "block": "minecraft:stone_brick_stairs[facing=east,half=bottom,shape=straight,waterlogged=false,weathering=false]"
      },
      {
        "char": "下",
        "block": "minecraft:stone_brick_slab[type=bottom,waterlogged=false,weathering=false]"
      },
      {
        "char": "x",
        "block": "minecraft:oak_leaves[distance=7,persistent=true,waterlogged=false]"
      },
      {
        "char": "ύ",
        "block": "minecraft:vine[east=false,north=false,south=false,up=false,west=true]"
      },
      {
        "char": "ӗ",
        "block": "minecraft:vine[east=false,north=true,south=false,up=false,west=true]"
      },
      {
        "char": "且",
        "block": "minecraft:andesite_slab[type=bottom,waterlogged=false]"
      }
    ]
  },
  "slices": [
    [
      "YSTe0sffffffffff",
      "太fTZ0Affffffffff",
      "ZYZTAsffffffffff",
      "ZoSSA0ffffffffff",
      "YTTfAfffffffffff",
      "ToeSA0ffffffffff",
      "YSTe0sffffffffff",
      "太fTZ0Affffffffff",
      "ZYZTAsffffffffff",
      "ZoSSA0ffffffffff",
      "YTTfAfffffffffff",
      "ToeSA0ffffffffff",
      "YSTe0sffffffffff",
      "太fTZ0Affffffffff",
      "ofeeA0ffffffffff",
      "mfmeђs0A0AAA0sђs"
    ],
    [
      "kzkk  qkkkzq q k",
      "zq k   qqkzzkk z",
      "k kkkkq kkqqkqkq",
      "k k kkkkkkkkqkqk",
      "kkzkzkk zkkkzzqz",
      "qzkk kq qkqqqkkk",
      "kzkk  kqqqzkqkkk",
      "zq k qkkqqkzkqzk",
      "k kkkkkk zzqkzk ",
      "k k kkkkqkzqkkqq",
      "kkzkzkkk qqkkzqq",
      "qzkk kq kkqkqqkq",
      "kzkk  kkkqqkqqkq",
      "zq k qzqkqkkqqkq",
      "qqqq吧下xxxxxύqkqk",
      "kkkk下xxxxxӗqzk且k"
    ],
    [
      "                ",
      "                ",
      "                ",
      "                ",
      "                ",
      "                ",
      "                ",
      "                ",
      "                ",
      "                ",
      "                ",
      "                ",
      "                ",
      "                ",
      "      xxxx      ",
      "       x        "
    ],
    [
      "                ",
      "                ",
      "                ",
      "                ",
      "                ",
      "                ",
      "                ",
      "                ",
      "                ",
      "                ",
      "                ",
      "                ",
      "                ",
      "                ",
      "                ",
      "                "
    ],
    [
      "                ",
      "                ",
      "                ",
      "                ",
      "                ",
      "                ",
      "                ",
      "                ",
      "                ",
      "                ",
      "                ",
      "                ",
      "                ",
      "                ",
      "                ",
      "                "
    ],
    [
      "                ",
      "                ",
      "                ",
      "                ",
      "                ",
      "                ",
      "                ",
      "                ",
      "                ",
      "                ",
      "                ",
      "                ",
      "                ",
      "                ",
      "                ",
      "                "
    ]
  ]
}