{
  "xsize": 16,
  "zsize": 16,
  "palette": {
    "palette": [
      {
        "char": " ",
        "block": "minecraft:air"
      },
      {
        "char": "a",
        "block": "minecraft:stone[weathering=false]"
      },
      {
        "char": "ό",
        "block": "minecraft:air"
      },
      {
        "char": "b",
        "block": "minecraft:dirt"
      },
      {
        "char": "e",
        "block": "minecraft:cracked_stone_bricks"
      },
      {
        "char": "j",
        "block": "minecraft:cobblestone[weathering=false]"
      },
      {
        "char": "g",
        "block": "minecraft:mossy_cobblestone"
      },
      {
        "char": "c",
        "block": "minecraft:mossy_stone_bricks"
      },
      {
        "char": "d",
        "block": "minecraft:stone_bricks[weathering=false]"
      },
      {
        "char": "线",
        "block": "minecraft:sticky_piston[extended=false,facing=east]"
      },
      {
        "char": "歌",
        "block": "minecraft:piston_head[facing=east,short=false,type=sticky]"
      },
      {
        "char": "命",
        "block": "minecraft:piston_head[facing=west,short=false,type=sticky]"
      },
      {
        "char": "儿",
        "block": "minecraft:sticky_piston[extended=false,facing=west]"
      }
    ]
  },
  "slices": [
    [
      "aaaaaaaaaaaaaaaa",
      "aaaaaaaaaaaaaaaa",
      "aaaaaaaaaaaaaaaa",
      "aaaaaaaaaaaaaaaa",
      "aaaaaaaaaaaaaaaa",
      "aaaaaaaaaaaaaaaa",
      "aaaaaaaaaaaaaaaa",
      "aaaaόόaaaaaaaaaa",
      "aaaaόaaaaaaaaaaό",
      "aaaaόaaaaaaaaaaa",
      "aaaaaaaaaaaaaaaa",
      "aaaaaaaaaaaaaaaa",
      "aaaaaaaaaaaaaaaa",
      "aaaaaaaaaaaaaaaa",
      "aaaaaaaaaaaaaaaa",
      "aaaaaaaaaaaaaaaa"
    ],
    [
      "bbbbbbbbbbbbbbbb",
      "bbbbbbbbbbbbbbbb",
      "bbbbbbbbbbbbbbbb",
      "bbbbbbbbbbbbbbbb",
      "bbbbbbbbbbbbbbbb",
      "bbbbbbbbbbbbbbbb",
      "bbbbbbbbbbbbbbbb",
      "bbbbbbbbbbbbbbbb",
      "aaaaόόόaaaaaaόaό",
      "aaaaaaaόaaaaaaaa",
      "aaaaaaaaaaaaaaaa",
      "aaaaaaaaaaaaaaaa",
      "aaaaaaaaaaaaaaaa",
      "aaaaaaaaaaaaaaaa",
      "aaaaaaaaaaaaaaaa",
      "aaaaaaaaaaaaaaaa"
    ],
    [
      "bbbbbbbbbbbbbbbb",
      "bbbbbbbbbbbbbbbb",
      "bbbbbbbbbbbbbbbb",
      "bbbbbbbbbbbbbbbb",
      "bbbbbbbbbbbbbbbb",
      "bbbbbbbbbbbbbbbb",
      "bbbbbbbbbbbbbbbb",
      "bbbbbbbbbbbbbbbb",
      "ejegeeegcegeeccc",
      "ddceeggecceddede",
      "edeeeegdjddccece",
      "dddddjddcggcedgg",
      "edcejcgcdgcjdecj",
      "cejjgjegdecceeec",
      "gcggggjgdcgceggj",
      "edccceejgecgegee"
    ],
    [
      "bbbbbbbbbbbbbbbb",
      "bbbbbbbbbbbbbbbb",
      "bbbbbbbbbbbbbbbb",
      "bbbbbbbbbbbbbbbb",
      "bbbbbbbbbbbbbbbb",
      "bbbbbbbbbbbbbbbb",
      "bbbbbbbbbbbbbbbb",
      "bbbbbbbbbbbbbbbb",
      "gedecejegddcgece",
      "geeecjdgeegjdjcd",
      "jeddcccjddjeecdd",
      "jcddccddgecddcjj",
      "gceeecdgdgcjcggc",
      "jejeggceccdgcggc",
      "ggcejgcceccgjjcg",
      "cgeggeccjjjgdccg"
    ],
    [
      "bbbbbbbbbbbbbbbb",
      "bbbbbbbbbbbbbbbb",
      "bbbbbbbbbbbbbbbb",
      "bbbbbbbbbbbbbbbb",
      "bbbbbbbbbbbbbbbb",
      "bbbbbbbbbbbbbbbb",
      "bbbbbbbbbbbbbbbb",
      "bbbbbbbbbbbbbbbb",
      "dceegdgcejecgdcg",
      "gdecgdcdecdcgggc",
      "ecdgccgegegdeceg",
      "ececdcdgdcgdgdcc",
      "jjgcgcjgccggcgcc",
      "jjgjgecjjcjecjde",
      "ggegeedjggccccjc",
      "cgcegcegcecggegj"
    ],
    [
      "bbbbbbbbbbbbbbbb",
      "bbbbbbbbbbbbbbbb",
      "bbbbbbbbbbbbbbbb",
      "bbbbbbbbbbbbbbbb",
      "bbbbbbbbbbbbbbbb",
      "bbbbbbbbbbbbbbbb",
      "bbbbbbbbbbbbbbbb",
      "bbbbbbbbbbbbbbbb",
      "egjjjjgcgeedgecg",
      "jjjjjjdccecddecd",
      "cdejjdcddegggcdc",
      "ccgjjegcgdgcjdgd",
      "jccjjc   cccecee",
      "egdjjccgecjcgdcc",
      "g线歌jj命儿ecccgecje",
      "c线歌jg命儿ejcjdcjjj"
    ]
  ]
}