{
  "xsize": 16,
  "zsize": 16,
  "palette": {
    "palette": [
      {
        "char": " ",
        "block": "minecraft:air"
      },
      {
        "char": "j",
        "block": "minecraft:air"
      },
      {
        "char": "c",
        "block": "minecraft:air"
      },
      {
        "char": "g",
        "block": "minecraft:air"
      },
      {
        "char": "e",
        "block": "minecraft:air"
      },
      {
        "char": "陆",
        "block": "minecraft:air"
      },
      {
        "char": "d",
        "block": "minecraft:air"
      },
      {
        "char": "督",
        "block": "minecraft:air"
      },
      {
        "char": "嘛",
        "block": "minecraft:air"
      },
      {
        "char": "m",
        "block": "minecraft:air"
      },
      {
        "char": "项",
        "block": "minecraft:air"
      },
      {
        "char": "斯",
        "block": "minecraft:air"
      },
      {
        "char": "8",
        "block": "minecraft:air"
      },
      {
        "char": "V",
        "block": "minecraft:tall_grass[half=upper]"
      },
      {
        "char": "元",
        "block": "minecraft:air"
      },
      {
        "char": "Е",
        "block": "minecraft:air"
      },
      {
        "char": "В",
        "block": "minecraft:air",
        "tag": {
          "z": 332,
          "x": 143,
          "is_waxed": "0b",
          "ForgeCaps": {
            "supplementaries:antique_ink": {
              "ink": "0b"
            }
          },
          "id": "minecraft:sign",
          "y": 126,
          "front_text": {
            "color": "black",
            "has_glowing_text": "0b",
            "messages": [
              "{\"extra\":[{\"text\":\"16th Century\"}],\"text\":\"\"}",
              "{\"extra\":[{\"text\":\"Loom\"}],\"text\":\"\"}",
              "{\"text\":\"\"}",
              "{\"extra\":[{\"text\":\"$530.99\"}],\"text\":\"\"}"
            ]
          },
          "back_text": {
            "color": "black",
            "has_glowing_text": "0b",
            "messages": [
              "{\"text\":\"\"}",
              "{\"text\":\"\"}",
              "{\"text\":\"\"}",
              "{\"text\":\"\"}"
            ]
          }
        }
      },
      {
        "char": "游",
        "block": "minecraft:air",
        "tag": {
          "z": 325,
          "Patterns": [
            {
              "Color": 0,
              "Pattern": "dls"
            },
            {
              "Color": 3,
              "Pattern": "gru"
            },
            {
              "Color": 15,
              "Pattern": "bo"
            }
          ],
          "x": 106,
          "ForgeCaps": {},
          "id": "minecraft:banner",
          "y": 127
        }
      },
      {
        "char": "请",
        "block": "minecraft:air"
      },
      {
        "char": "B",
        "block": "minecraft:air"
      },
      {
        "char": "F",
        "block": "minecraft:air"
      },
      {
        "char": "H",
        "block": "minecraft:air"
      },
      {
        "char": "但",
        "block": "minecraft:air"
      },
      {
        "char": "人",
        "block": "minecraft:air"
      },
      {
        "char": "a",
        "block": "minecraft:air"
      }
    ]
  },
  "slices": [
    [
      "jcgej       陆   ",
      "gcggjcjcjeggc   ",
      "jdcjccejejjec   ",
      "ecccg       督   ",
      "deece嘛m嘛m   c   ",
      "ceege项m项m斯斯斯c   ",
      "edcjcjcecdej8   ",
      "jdgeegdcc       ",
      "eceeejgceVV     ",
      "cdecjgeecVV     ",
      "ddedgegje       ",
      "ejcgecdde V 8   ",
      "g元geegjcc  V    ",
      "元Еejgcgdc       ",
      "dcceecddjjjecgcc",
      "cdcecddcddejdedc"
    ],
    [
      "dejje       cВ  ",
      "djcdgccegcecc   ",
      "jceejccgceggc   ",
      "jjeec       dВ  ",
      "jdgcg       g   ",
      "cgjce    游游游c   ",
      "jgggjceegece8   ",
      "ejgedjggc       ",
      "ЕЕcegccec       ",
      "ЕЕЕjjdcjc       ",
      "ЕЕЕdcdgge       ",
      "ЕЕ请jedgdc   8   ",
      "gjjggdeec       ",
      "gjjcjccdc       ",
      "cgcjgdccececcded",
      "ddeccccdcgecgddg"
    ],
    [
      "BccecccjegeecF  ",
      "BccgcjceejcgdF  ",
      "BggjgcgdccgeeF  ",
      "BgececccgcjdcF  ",
      "BgedcedcgHcegF  ",
      "BdceedcedgejcF  ",
      "Bdeecjccjdcc8但  ",
      "Еgecgcedc       ",
      "ЕЕccceecc       ",
      "ЕjЕccedcc       ",
      "jjЕjecdeg       ",
      "jjЕjgegee   8   ",
      "jjjjedcjj       ",
      "jjjjcgcdd       ",
      "Еcjjcdgdjdcdccde",
      "gdegegededgcjjgd"
    ],
    [
      "BBccegdeggcddcHH",
      "BBgddjdcdcddeccd",
      "BBjcjjdcgjdddjeg",
      "BBjgejejcdejcgHH",
      "BBcggcdgedegcjdd",
      "BBeecddecddjgcdd",
      "BBcceccedejcecHH",
      "BBjgegecjgjdjegc",
      "BЕcggceceggcecje",
      "jjЕgcccddedejedd",
      "jjЕjjjjeddcdeedd",
      "jjjjcdgegdd人eccc",
      "jjjdcejdddcdHede",
      "jjjjcgdgdcgcddcc",
      "jЕgecededgdcdccc",
      "jcdgcccjdeggcccc"
    ],
    [
      "jBaaaaaaaaaaaaaa",
      "jBaaaaaaaaaaaaaa",
      "jBaaaaaaaaaaaaaa",
      "jBaaaaaaaaaaaaaa",
      "jBaaaaaaaaaaaaaa",
      "jBaaaaaaaaaaaaaa",
      "jBaaaaaaaaaaaaaa",
      "jBaaaaaaaaaaaaaa",
      "jBaaaaaaaaaaaaaa",
      "jjaaaaaaaaaaaaaa",
      "gjaaaaaaaaaaaaaa",
      "gЕgaaaaaaaaaaaaa",
      "ggЕaaaaaaaaaaaaa",
      "eegaaaaaaaaaaaaa",
      "aaaaaaaaaaaaaaaa",
      "jaaaaaaaaaaaaaaa"
    ],
    [
      "Baaaaaaaaaaaaaaa",
      "Baaaaaaaaaaaaaaa",
      "Baaaaaaaaaaaaaaa",
      "Baaaaaaaaaaaaaaa",
      "Baaaaaaaaaaaaaaa",
      "Baaaaaaaaaaaaaaa",
      "Baaaaaaaaaaaaaaa",
      "Baaaaaaaaaaaaaaa",
      "jЕaaaaaaaaaaaaaa",
      "jaaaaaaaaaaaaaaa",
      "aaaaaaaaaaaaaaaa",
      "aaaaaaaaaaaaaaaa",
      "aaaaaaaaaaaaaaaa",
      "aaaaaaaaaaaaaaaa",
      "aaaaaaaaaaaaaaaa",
      "aaaaaaaaaaaaaaaa"
    ]
  ]
}