{
  "xsize": 16,
  "zsize": 16,
  "palette": {
    "palette": [
      {
        "char": " ",
        "block": "minecraft:air"
      },
      {
        "char": "r",
        "block": "minecraft:light_gray_carpet"
      },
      {
        "char": "v",
        "block": "minecraft:smooth_quartz"
      },
      {
        "char": "i",
        "block": "minecraft:glass"
      },
      {
        "char": "t",
        "block": "minecraft:acacia_wood[axis=y]"
      },
      {
        "char": "y",
        "block": "minecraft:gray_concrete"
      },
      {
        "char": "2",
        "block": "minecraft:red_concrete"
      },
      {
        "char": "w",
        "block": "minecraft:quartz_pillar[axis=y]"
      },
      {
        "char": "o",
        "block": "minecraft:cyan_terracotta"
      },
      {
        "char": "m",
        "block": "minecraft:white_concrete"
      },
      {
        "char": "s",
        "block": "minecraft:polished_diorite"
      },
      {
        "char": "u",
        "block": "minecraft:light_gray_concrete"
      },
      {
        "char": "ϐ",
        "block": "minecraft:green_wool"
      },
      {
        "char": "骑",
        "block": "minecraft:green_wall_banner[facing=west]",
        "tag": {
          "z": 340,
          "Patterns": [],
          "x": 110,
          "ForgeCaps": {},
          "id": "minecraft:banner",
          "y": 146,
          "CustomName": "{\"text\":\"Carmicheal's\"}"
        }
      },
      {
        "char": "G",
        "block": "minecraft:quartz_slab[type=bottom,waterlogged=false]"
      },
      {
        "char": "l",
        "block": "minecraft:andesite"
      },
      {
        "char": "h",
        "block": "minecraft:polished_andesite"
      },
      {
        "char": "P",
        "block": "minecraft:diorite_slab[type=bottom,waterlogged=false]"
      },
      {
        "char": "D",
        "block": "minecraft:smooth_stone_slab[type=bottom,waterlogged=false]"
      },
      {
        "char": "4",
        "block": "minecraft:red_carpet"
      },
      {
        "char": "A",
        "block": "minecraft:quartz_block"
      },
      {
        "char": "Е",
        "block": "minecraft:coarse_dirt"
      },
      {
        "char": "U",
        "block": "minecraft:air"
      }
    ]
  },
  "slices": [
    [
      "        r      v",
      "        ri     v",
      "        ri     t",
      "        y2     t",
      "       wo2     t",
      "        o2     t",
      "        ri     t",
      "        ri     m",
      "        r      v",
      "        o2     s",
      "       wovvvsmvs",
      "        uv      ",
      "        ri      ",
      "        ri      ",
      "        ri      ",
      "        ri      "
    ],
    [
      "        r      s",
      "        ri     v",
      "        ri     t",
      "        oϐ      ",
      "       wuϐ      ",
      "        yϐ      ",
      "        ri     t",
      "        r      s",
      "        ri     s",
      "        oϐ     m",
      "       wymmvvssm",
      "        us      ",
      "        ri      ",
      "        ri      ",
      "        ri      ",
      "        ri      "
    ],
    [
      "        ri     s",
      "        ri     m",
      "        r      t",
      "        oϐ      ",
      "       wuϐ    骑i",
      "        oϐ     i",
      "        ri     t",
      "        r      m",
      "        ri     m",
      "        yϐ     v",
      "       wossmsmmm",
      "        ym      ",
      "        r       ",
      "        ri      ",
      "        ri      ",
      "        ri      "
    ],
    [
      "       Gosllllhl",
      "       Govllhllh",
      "       Gymlhhhhl",
      "       Gyvhlhhll",
      "       wovhllhhl",
      "       Gomhhhhhh",
      "       Gumhhllhl",
      "       Gomhhhlhl",
      "       Guvhlhllh",
      "       Gymlllhhh",
      "       woshlhllh",
      "       Gyslhlhll",
      "       Gomlhhhll",
      "       Gumhhlhhh",
      "       Gumhhllhh",
      "       Pymlhhhhl"
    ],
    [
      "       v D 4   4",
      "       v D  444 ",
      "       A D      ",
      "       v D      ",
      "       v D  4444",
      "       v D 4    ",
      "       A D4     ",
      "       A D4     ",
      "       v D4     ",
      "       AЕD 4    ",
      "       vЕD  4444",
      "       v D      ",
      "       v D      ",
      "       v D  4   ",
      "       v D 4    ",
      "       A D4     "
    ],
    [
      "                ",
      "                ",
      "                ",
      "                ",
      "                ",
      "                ",
      "                ",
      "                ",
      "                ",
      "        U       ",
      "        U       ",
      "                ",
      "                ",
      "                ",
      "                ",
      "                "
    ]
  ]
}