{
  "xsize": 16,
  "zsize": 16,
  "palette": {
    "palette": [
      {
        "char": " ",
        "block": "minecraft:air"
      },
      {
        "char": "2",
        "block": "minecraft:red_concrete"
      },
      {
        "char": "i",
        "block": "minecraft:glass"
      },
      {
        "char": "m",
        "block": "minecraft:white_concrete"
      },
      {
        "char": "s",
        "block": "minecraft:polished_diorite"
      },
      {
        "char": "h",
        "block": "minecraft:polished_andesite"
      },
      {
        "char": "o",
        "block": "minecraft:cyan_terracotta"
      },
      {
        "char": "r",
        "block": "minecraft:light_gray_carpet"
      },
      {
        "char": "y",
        "block": "minecraft:gray_concrete"
      },
      {
        "char": "w",
        "block": "minecraft:quartz_pillar[axis=y]"
      },
      {
        "char": "v",
        "block": "minecraft:smooth_quartz"
      },
      {
        "char": "u",
        "block": "minecraft:light_gray_concrete"
      },
      {
        "char": "3",
        "block": "minecraft:stone_brick_wall[east=none,north=none,south=none,up=true,waterlogged=false,weathering=false,west=none]"
      },
      {
        "char": "ӊ",
        "block": "minecraft:oak_leaves[distance=5,persistent=false,waterlogged=false]"
      },
      {
        "char": "Ͳ",
        "block": "minecraft:oak_leaves[distance=4,persistent=false,waterlogged=false]"
      },
      {
        "char": "l",
        "block": "minecraft:andesite"
      },
      {
        "char": "G",
        "block": "minecraft:quartz_slab[type=bottom,waterlogged=false]"
      },
      {
        "char": "ͱ",
        "block": "minecraft:smooth_quartz_slab[type=bottom,waterlogged=false]"
      },
      {
        "char": "O",
        "block": "minecraft:smooth_quartz_slab[type=top,waterlogged=false]"
      },
      {
        "char": "D",
        "block": "minecraft:smooth_stone_slab[type=bottom,waterlogged=false]"
      },
      {
        "char": "A",
        "block": "minecraft:quartz_block"
      },
      {
        "char": "0",
        "block": "minecraft:diorite"
      },
      {
        "char": "Е",
        "block": "minecraft:coarse_dirt"
      },
      {
        "char": "U",
        "block": "minecraft:air"
      }
    ]
  },
  "slices": [
    [
      "                ",
      "                ",
      "                ",
      "2               ",
      "i       mmmmi  s",
      "i      mhhoorrry",
      "       shhw     ",
      "       vuw      ",
      "i      r        ",
      "     iir        ",
      "i immrr3        ",
      "rrroo           ",
      "    w     ӊ     ",
      "         ӊͲӊ    ",
      "          ӊ     ",
      "                "
    ],
    [
      "                ",
      "                ",
      "                ",
      "2               ",
      "i       svssiiiv",
      "       shhyyrrro",
      "       shhw     ",
      "i      suw      ",
      "i     ir        ",
      "     iir        ",
      "iiimmrr3        ",
      "rrruo           ",
      "    w           ",
      "                ",
      "                ",
      "                "
    ],
    [
      "        o       ",
      "       o        ",
      "       u        ",
      "      o         ",
      "h    o  mmmsiiim",
      "h   u  mhhourrro",
      "h yy   shhw     ",
      "ho     muw      ",
      "h      r        ",
      "     iir        ",
      "iiismrr3        ",
      "rrruu           ",
      "    w           ",
      "                ",
      "                ",
      "                "
    ],
    [
      "        olhhhhll",
      "       uhllhhhhh",
      "       uhlhlhlll",
      "      ohhlhlllhl",
      "     yhhhlmvmssm",
      "    ohhlvsoouoou",
      "  oyhhhhmowGGGͱG",
      "ouhhhhhsuw      ",
      "hhhhhhmoG       ",
      "hhhhhvmoG       ",
      "mmvssuuG        ",
      "uuyouͱG         ",
      "GGGGw           ",
      "                ",
      "                ",
      "                "
    ],
    [
      "       Ohu      ",
      "      Ohyo      ",
      "      Ohu       ",
      "     Ohou       ",
      "    Ohou  DDDDDD",
      "  OOhyu DD      ",
      "OOhhou  D A0vvvv",
      "hhuyo  D A      ",
      "oou   D A       ",
      "     DD A       ",
      "DDDDD  v        ",
      " Е   vv         ",
      "AvvvA           ",
      "                ",
      "                ",
      "                "
    ],
    [
      "       i        ",
      "      i         ",
      "      i         ",
      "     ii         ",
      "    ii          ",
      "   ii           ",
      "iiii            ",
      "ii              ",
      "                ",
      "                ",
      "                ",
      " U              ",
      "                ",
      "                ",
      "                ",
      "                "
    ]
  ]
}