{
  "xsize": 16,
  "zsize": 16,
  "palette": {
    "palette": [
      {
        "char": " ",
        "block": "minecraft:air"
      },
      {
        "char": "i",
        "block": "minecraft:air"
      },
      {
        "char": "r",
        "block": "minecraft:air"
      },
      {
        "char": "2",
        "block": "minecraft:air"
      },
      {
        "char": "o",
        "block": "minecraft:air"
      },
      {
        "char": "x",
        "block": "minecraft:air"
      },
      {
        "char": "u",
        "block": "minecraft:air"
      },
      {
        "char": "w",
        "block": "minecraft:air"
      },
      {
        "char": "ӧ",
        "block": "minecraft:air"
      },
      {
        "char": "竹",
        "block": "minecraft:air",
        "tag": {
          "z": 345,
          "Patterns": [
            {
              "Color": 14,
              "Pattern": "hhb"
            },
            {
              "Color": 0,
              "Pattern": "ls"
            },
            {
              "Color": 0,
              "Pattern": "mc"
            },
            {
              "Color": 0,
              "Pattern": "hhb"
            },
            {
              "Color": 14,
              "Pattern": "bts"
            },
            {
              "Color": 11,
              "Pattern": "bo"
            }
          ],
          "x": 178,
          "ForgeCaps": {},
          "id": "minecraft:banner",
          "y": 146
        }
      },
      {
        "char": "s",
        "block": "minecraft:air"
      },
      {
        "char": "m",
        "block": "minecraft:air"
      },
      {
        "char": "y",
        "block": "minecraft:air"
      },
      {
        "char": "v",
        "block": "minecraft:air"
      },
      {
        "char": "l",
        "block": "minecraft:air"
      },
      {
        "char": "h",
        "block": "minecraft:air"
      },
      {
        "char": "G",
        "block": "minecraft:air"
      },
      {
        "char": "ͱ",
        "block": "minecraft:air"
      },
      {
        "char": "P",
        "block": "minecraft:air"
      },
      {
        "char": "D",
        "block": "minecraft:air"
      },
      {
        "char": "A",
        "block": "minecraft:air"
      },
      {
        "char": "Е",
        "block": "minecraft:air"
      },
      {
        "char": "0",
        "block": "minecraft:air"
      },
      {
        "char": "U",
        "block": "minecraft:tall_grass[half=lower]"
      }
    ]
  },
  "slices": [
    [
      "   ir           ",
      "   ir           ",
      "   ir           ",
      "   2o x         ",
      "   2uwx         ",
      "   ӧoxx         ",
      "   ir           ",
      "   ir           ",
      "    r           ",
      "竹  ӧo           ",
      "smmsuw          ",
      "   my           ",
      "   ir           ",
      "   ir           ",
      "   ir           ",
      "    r           "
    ],
    [
      "   ir           ",
      "   ir           ",
      "   ir           ",
      "   2y           ",
      "   ӧow          ",
      "   ӧyx          ",
      "   irx          ",
      "    rx          ",
      "   ir           ",
      " 竹 ӧy           ",
      "msmvow          ",
      "   so           ",
      "    r           ",
      "    r           ",
      "   ir           ",
      "   ir           "
    ],
    [
      "   ir           ",
      "   ir           ",
      "   ir           ",
      "   2u           ",
      "   ӧow          ",
      "   ӧo           ",
      "    r           ",
      "    rxx         ",
      "   irxx         ",
      "  竹ӧy           ",
      "msvsow          ",
      "   su           ",
      "   ir           ",
      "   ir           ",
      "   ir           ",
      "   ir           "
    ],
    [
      "lhhsoG          ",
      "lllvyG          ",
      "hhhsoG          ",
      "hlhmoͱ          ",
      "hhlmuw          ",
      "hhlsoG          ",
      "lhhsoG          ",
      "lhlmoP          ",
      "lhhmyGx         ",
      "hhlmuPx         ",
      "hhhvow          ",
      "hllmuG          ",
      "lhhsyG          ",
      "lhlvoP          ",
      "hhlsyP          ",
      "hhlvuG          "
    ],
    [
      "   D v          ",
      "   D v          ",
      "   D v          ",
      "   D v          ",
      "   D v          ",
      "   D A          ",
      "   D v          ",
      "   D v          ",
      "   DЕA          ",
      "   D Ax         ",
      "   D vx         ",
      "   Dxv          ",
      "   DxA          ",
      "   D A          ",
      "   D 0          ",
      "   D A          "
    ],
    [
      "                ",
      "                ",
      "                ",
      "                ",
      "                ",
      "                ",
      "                ",
      "                ",
      "    U           ",
      "                ",
      "     x          ",
      "     x          ",
      "                ",
      "                ",
      "                ",
      "                "
    ]
  ]
}