{
  "xsize": 16,
  "zsize": 16,
  "palette": {
    "palette": [
      {
        "char": " ",
        "block": "minecraft:air"
      },
      {
        "char": "b",
        "block": "minecraft:dirt"
      },
      {
        "char": "e",
        "block": "minecraft:cracked_stone_bricks"
      },
      {
        "char": "8",
        "block": "minecraft:chiseled_stone_bricks[weathering=false]"
      },
      {
        "char": "j",
        "block": "minecraft:cobblestone[weathering=false]"
      },
      {
        "char": "d",
        "block": "minecraft:stone_bricks[weathering=false]"
      },
      {
        "char": "g",
        "block": "minecraft:mossy_cobblestone"
      },
      {
        "char": "c",
        "block": "minecraft:mossy_stone_bricks"
      },
      {
        "char": "充",
        "block": "minecraft:redstone_wire[east=none,north=up,power=15,south=side,west=none]"
      },
      {
        "char": "线",
        "block": "minecraft:sticky_piston[extended=false,facing=east]"
      },
      {
        "char": "歌",
        "block": "minecraft:piston_head[facing=east,short=false,type=sticky]"
      },
      {
        "char": "命",
        "block": "minecraft:piston_head[facing=west,short=false,type=sticky]"
      },
      {
        "char": "儿",
        "block": "minecraft:sticky_piston[extended=false,facing=west]"
      },
      {
        "char": "徵",
        "block": "minecraft:repeater[delay=1,facing=south,locked=false,powered=true]"
      },
      {
        "char": "嘻",
        "block": "minecraft:redstone_wire[east=none,north=none,power=14,south=side,west=up]"
      },
      {
        "char": "杂",
        "block": "minecraft:redstone_wire[east=side,north=none,power=9,south=side,west=none]"
      },
      {
        "char": "停",
        "block": "minecraft:redstone_wire[east=side,north=none,power=10,south=none,west=side]"
      },
      {
        "char": "智",
        "block": "minecraft:redstone_wire[east=side,north=none,power=11,south=none,west=side]"
      },
      {
        "char": "边",
        "block": "minecraft:redstone_wire[east=side,north=none,power=12,south=none,west=side]"
      },
      {
        "char": "治",
        "block": "minecraft:redstone_wire[east=side,north=none,power=13,south=none,west=side]"
      },
      {
        "char": "趣",
        "block": "minecraft:redstone_wire[east=none,north=side,power=8,south=side,west=none]"
      },
      {
        "char": "婚",
        "block": "minecraft:redstone_wire[east=side,north=none,power=15,south=side,west=none]"
      },
      {
        "char": "慧",
        "block": "minecraft:repeater[delay=2,facing=east,locked=false,powered=true]"
      },
      {
        "char": "消",
        "block": "minecraft:redstone_wire[east=side,north=none,power=6,south=none,west=side]"
      },
      {
        "char": "纪",
        "block": "minecraft:redstone_wire[east=side,north=side,power=7,south=none,west=side]"
      },
      {
        "char": "君",
        "block": "minecraft:repeater[delay=2,facing=west,locked=false,powered=true]"
      },
      {
        "char": "免",
        "block": "minecraft:redstone_wire[east=none,north=none,power=15,south=side,west=side]"
      },
      {
        "char": "园",
        "block": "minecraft:redstone_wire[east=none,north=side,power=14,south=side,west=none]"
      },
      {
        "char": "a",
        "block": "minecraft:stone[weathering=false]"
      }
    ]
  },
  "slices": [
    [
      "bbbbbbbbbbbbbbbb",
      "bbbbbbbbbbbbbbbb",
      "bbbbbbbbbbbbbbbb",
      "bbbbbbbbbbbbbbbb",
      "bbbbbbbbbbbbbbbb",
      "bbbbbbbbbbbbbbbb",
      "bbbbbbbbbbbbbbbb",
      "bbbbbbbbbbbbbbbb",
      "e8jjjj8dgeecccee",
      "g8jjjj8ddeeecece",
      "cgejjcccegcggged",
      "dcejjeedjeeddjee",
      "ecgjje   ejedjec",
      "eccjjcjcc充jecege",
      "c线歌jg命儿gg徵ccgdec",
      "g线歌jj命儿gjcgccgcc"
    ],
    [
      "bbbbbbbbbbbbbbbb",
      "bbbbbbbbbbbbbbbb",
      "bbbbbbbbbbbbbbbb",
      "bbbbbbbbbbbbbbbb",
      "bbbbbbbbbbbbbbbb",
      "bbbbbbbbbbbbbbbb",
      "bbbbbbbbbbbbbbbb",
      "bbbbbbbbbbbbbbbb",
      "ejejjdejdcgdcecg",
      "jcejjcecdcjjccee",
      "cgcdceejdgecdceg",
      "geeceedeedjedddj",
      "gcggcgdec嘻eeejcc",
      "jcegegece decdjc",
      "ejeggjgcd cggecc",
      "ggcgeeecdegdgcce"
    ],
    [
      "bbbbbbbbbbbbbbbb",
      "bbbbbbbbbbbbbbbb",
      "bbbbbbbbbbbbbbbb",
      "bbbbbbbbbbbbbbbb",
      "bbbbbbbbbbbbbbbb",
      "bbbbbbbbbbbbbbbb",
      "bbbbbbbbbbbbbbbb",
      "bbbbbbbbbbbbbbbb",
      "eeejjcdeejcjjccg",
      "dcdjjcgjddjceege",
      "eegdcccdcecgddcc",
      "edgccddggceeccdd",
      "jjg 杂停智边治 ccccjj",
      "ecc 趣cccj cegcce",
      "g婚慧消纪君免ecgcjegcg",
      "j园    园ecegcgjce"
    ],
    [
      "bbbbbbbbbbbbbbbb",
      "bbbbbbbbbbbbbbbb",
      "bbbbbbbbbbbbbbbb",
      "bbbbbbbbbbbbbbbb",
      "bbbbbbbbbbbbbbbb",
      "bbbbbbbbbbbbbbbb",
      "bbbbbbbbbbbbbbbb",
      "bbbbbbbbbbbbbbbb",
      "eddddddddddddddd",
      "dddddddddddddddd",
      "dddddddddddddddd",
      "dddddddccddddddd",
      "egge      dcdgdg",
      "gccececeedcgdecg",
      "ccccggcdcgcccedd",
      "cggeeccjejdgccjd"
    ],
    [
      "bbbbbbbbbbbbbbbb",
      "bbbbbbbbbbbbbbbb",
      "bbbbbbbbbbbbbbbb",
      "bbbbbbbbbbbbbbbb",
      "bbbbbbbbbbbbbbbb",
      "bbbbbbbbbbbbbbbb",
      "bbbbbbbbbbbbbbbb",
      "bbbbbbbbbbbbbbbb",
      "aaaaaaaaaaaaaaaa",
      "aaaaaaaaaaaaaaaa",
      "aaaaaaaaaaaaaaaa",
      "aaaaaaaaaaaaaaaa",
      "aaaaaaaaaaaaaaaa",
      "aaaaaaaaaaaaaaaa",
      "aaaaaaaaaaaaaaaa",
      "aaaaaaaaaaaaaaaa"
    ],
    [
      "bbbbbbbbbbbbbbbb",
      "bbbbbbbbbbbbbbbb",
      "bbbbbbbbbbbbbbbb",
      "bbbbbbbbbbbbbbbb",
      "bbbbbbbbbbbbbbbb",
      "bbbbbbbbbbbbbbbb",
      "bbbbbbbbbbbbbbbb",
      "bbbbbbbbbbbbbbbb",
      "aaaaaaaaaaaaaaaa",
      "aaaaaaaaaaaaaaaa",
      "aaaaaaaaaaaaaaaa",
      "aaaaaaaaaaaaaaaa",
      "aaaaaaaaaaaaaaaa",
      "aaaaaaaaaaaaaaaa",
      "aaaaaaaaaaaaaaaa",
      "aaaaaaaaaaaaaaaa"
    ]
  ]
}