{
  "xsize": 16,
  "zsize": 16,
  "palette": {
    "palette": [
      {
        "char": " ",
        "block": "minecraft:air"
      },
      {
        "char": "a",
        "block": "minecraft:air"
      },
      {
        "char": "N",
        "block": "minecraft:air"
      },
      {
        "char": "4",
        "block": "minecraft:air"
      },
      {
        "char": "Ϡ",
        "block": "minecraft:air"
      },
      {
        "char": "z",
        "block": "minecraft:air"
      },
      {
        "char": "n",
        "block": "minecraft:air"
      },
      {
        "char": "w",
        "block": "minecraft:air"
      },
      {
        "char": "λ",
        "block": "minecraft:air"
      },
      {
        "char": "K",
        "block": "minecraft:air"
      },
      {
        "char": "E",
        "block": "minecraft:air"
      },
      {
        "char": "k",
        "block": "minecraft:air"
      },
      {
        "char": "V",
        "block": "minecraft:air"
      },
      {
        "char": "e",
        "block": "minecraft:grass"
      },
      {
        "char": "h",
        "block": "minecraft:tall_grass[half=lower]"
      },
      {
        "char": "x",
        "block": "minecraft:air"
      },
      {
        "char": "m",
        "block": "minecraft:air"
      },
      {
        "char": "П",
        "block": "minecraft:air"
      },
      {
        "char": "6",
        "block": "minecraft:air"
      },
      {
        "char": "҃",
        "block": "minecraft:air"
      },
      {
        "char": "什",
        "block": "minecraft:air"
      },
      {
        "char": "人",
        "block": "minecraft:air"
      },
      {
        "char": "ѥ",
        "block": "minecraft:air"
      },
      {
        "char": "ϗ",
        "block": "minecraft:air"
      },
      {
        "char": "ͼ",
        "block": "minecraft:air"
      },
      {
        "char": "他",
        "block": "minecraft:air"
      },
      {
        "char": "Ϭ",
        "block": "minecraft:air"
      },
      {
        "char": "ϓ",
        "block": "minecraft:air"
      },
      {
        "char": "s",
        "block": "minecraft:air"
      },
      {
        "char": "可",
        "block": "minecraft:air"
      },
      {
        "char": "ʹ",
        "block": "minecraft:air"
      },
      {
        "char": "ó",
        "block": "minecraft:air"
      },
      {
        "char": "但",
        "block": "minecraft:air"
      },
      {
        "char": "ώ",
        "block": "minecraft:air"
      },
      {
        "char": "l",
        "block": "minecraft:tall_grass[half=upper]"
      },
      {
        "char": "Я",
        "block": "minecraft:air"
      },
      {
        "char": "ҝ",
        "block": "minecraft:air"
      },
      {
        "char": "θ",
        "block": "minecraft:air"
      }
    ]
  },
  "slices": [
    [
      "aaaaaaaaaN44ϠϠNz",
      "aaaaaaaaaNnnnnnz",
      "aaaaaaaaaNwnzznn",
      "aaaaaaaaaNnnznwn",
      "aaaaaaaaaNϠϠN4λz",
      "aaaaaaaaaNwnnnwn",
      "aaaaaaaaaNnwnwwn",
      "aaaaaaaaaNzznnzn",
      "aaaaaaaaa4NNλ4Ϡn",
      "aaaaaaaaaNznnnwz",
      "aaaaaaaaaNnnnwnn",
      "aaaaaaaaaNwznwnz",
      "aaaaaaaaaNNNλN4n",
      "aaaaaaaaaaKEaaaa",
      "aaaaaaaaaaEkaaaa",
      "Vaaaaaaaaakkaaaa"
    ],
    [
      "e eheheex       ",
      "emxhmeh hП   66 ",
      "ehxxeee h҃ 6    ",
      "ehmeeeemhП  6   ",
      "exhxxehme       ",
      "xehheheeeП  66  ",
      "eehxmhehe҃ 什  人6",
      "hhheemhehП   6  ",
      "eѥϗhemmhe  e    ",
      "heͼ他eemeeϬ  ϓ s ",
      "ee可ͼhehxeʹ ó  但6",
      "eeeώѥhmeeϬ ϓ6  s",
      "heeehmheh s  e s",
      "hhhhmmexehssexxe",
      "mheexhexhe sehem",
      "ehehmehhhm  hmmh"
    ],
    [
      "     l          ",
      "      l         ",
      "        l       ",
      "        l       ",
      "      l         ",
      "   l l          ",
      "  l  l l        ",
      "lll   l l       ",
      "   l m l        ",
      "l ͼЯ            ",
      "  ҝͼl l         ",
      "   ώ l          ",
      "l   lml l       ",
      "llll     l      ",
      " l   l  l    l  ",
      " l l  l l   l ml"
    ],
    [
      "                ",
      "                ",
      "                ",
      "                ",
      "                ",
      "                ",
      "                ",
      "                ",
      "                ",
      "  ϗ             ",
      "  ҝͼ            ",
      "                ",
      "                ",
      "                ",
      "                ",
      "                "
    ],
    [
      "                ",
      "                ",
      "                ",
      "                ",
      "                ",
      "                ",
      "                ",
      "                ",
      "                ",
      "                ",
      "  θͼ            ",
      "                ",
      "                ",
      "                ",
      "                ",
      "                "
    ],
    [
      "                ",
      "                ",
      "                ",
      "                ",
      "                ",
      "                ",
      "                ",
      "                ",
      "                ",
      "                ",
      "   ͼ            ",
      "                ",
      "                ",
      "                ",
      "                ",
      "                "
    ]
  ]
}