{
  "xsize": 16,
  "zsize": 16,
  "palette": {
    "palette": [
      {
        "char": " ",
        "block": "minecraft:air"
      },
      {
        "char": "a",
        "block": "minecraft:air"
      },
      {
        "char": "理",
        "block": "minecraft:air"
      },
      {
        "char": "T",
        "block": "minecraft:air"
      },
      {
        "char": "k",
        "block": "minecraft:air"
      },
      {
        "char": "N",
        "block": "minecraft:air"
      },
      {
        "char": "4",
        "block": "minecraft:air"
      },
      {
        "char": "B",
        "block": "minecraft:air"
      },
      {
        "char": "ѕ",
        "block": "minecraft:air"
      },
      {
        "char": "P",
        "block": "minecraft:air"
      },
      {
        "char": "c",
        "block": "minecraft:air"
      },
      {
        "char": "e",
        "block": "minecraft:grass"
      },
      {
        "char": "Ҷ",
        "block": "minecraft:air"
      },
      {
        "char": "ί",
        "block": "minecraft:air"
      },
      {
        "char": "为",
        "block": "minecraft:air"
      },
      {
        "char": "ͳ",
        "block": "minecraft:air"
      },
      {
        "char": "意",
        "block": "minecraft:air"
      },
      {
        "char": "υ",
        "block": "minecraft:air"
      },
      {
        "char": "Ϩ",
        "block": "minecraft:air"
      },
      {
        "char": "下",
        "block": "minecraft:air"
      },
      {
        "char": "ӗ",
        "block": "minecraft:air"
      },
      {
        "char": "h",
        "block": "minecraft:tall_grass[half=lower]"
      },
      {
        "char": "D",
        "block": "minecraft:air"
      },
      {
        "char": "Β",
        "block": "minecraft:air"
      },
      {
        "char": "x",
        "block": "minecraft:air"
      },
      {
        "char": "Ѻ",
        "block": "minecraft:air"
      },
      {
        "char": "U",
        "block": "minecraft:air"
      },
      {
        "char": "C",
        "block": "minecraft:air"
      },
      {
        "char": "Ͼ",
        "block": "minecraft:air"
      },
      {
        "char": "d",
        "block": "minecraft:air"
      },
      {
        "char": "g",
        "block": "minecraft:air"
      },
      {
        "char": "ҳ",
        "block": "minecraft:air"
      },
      {
        "char": "l",
        "block": "minecraft:tall_grass[half=upper]"
      },
      {
        "char": "i",
        "block": "minecraft:air"
      },
      {
        "char": "8",
        "block": "minecraft:air"
      },
      {
        "char": "9",
        "block": "minecraft:air"
      },
      {
        "char": "f",
        "block": "minecraft:air"
      },
      {
        "char": "o",
        "block": "minecraft:air"
      },
      {
        "char": "Ξ",
        "block": "minecraft:air"
      },
      {
        "char": "者",
        "block": "minecraft:air"
      },
      {
        "char": "ή",
        "block": "minecraft:air"
      },
      {
        "char": "Φ",
        "block": "minecraft:air"
      },
      {
        "char": "Σ",
        "block": "minecraft:air"
      }
    ]
  },
  "slices": [
    [
      "aaaaaaaaa理TTTTTT",
      "aakkkkkkkkkkkkkk",
      "aakkkkkkkkkkkkkk",
      "aakkkkkkkkkkkkkk",
      "aakkkkkkkkkkkkkk",
      "aakkkkkkkkkkkkkk",
      "aakkkkkkkkkkkkkk",
      "aaaaaaaaaaaaaaaa",
      "aaaaaaaaNN4NNN4N",
      "aaaaaaaa4BBNB4ѕ4",
      "aaaaaaaaNBB4BNѕN",
      "aaaaaaaaNBBNBB4B",
      "aaaaaaaaNBBB4BBB",
      "aaaaaaaaNBBBB4NN",
      "aaaaaaaa4BBBBBBB",
      "aaaaaaaaNBBBBBBB"
    ],
    [
      "Pccccccce       ",
      "Pe Ҷί Ҷ为        ",
      "Pͳ意  ίυ e   e   ",
      "P Ϩ            下",
      "Pͳ   e   ӗ      ",
      "Ph              ",
      "PD     e        ",
      "PhΒhxΒhѺUUUUUUUU",
      "PDeDhhDC      Ͼ ",
      "PhDΒeDeC        ",
      "PeDeDeDC  e   e ",
      "PDhDhehC        ",
      "PxxDxeDC e    e ",
      "PhDxeDxC        ",
      "PDeΒDDhC        ",
      "PhDhDeDC        "
    ],
    [
      "Pcddgddc        ",
      "P   ҳ           ",
      "PD              ",
      "P               ",
      "Pͳ              ",
      "P               ",
      "P               ",
      "PlDl ΒlѺUUUUUUUU",
      "P   l DC      Ͼ ",
      "Pl Β   C        ",
      "P      C        ",
      "P lDl lC        ",
      "P      C        ",
      "Pl   D C        ",
      "P  Β  lC        ",
      "Pl lD  C        "
    ],
    [
      "Pcdgdggc        ",
      "P     ҳ         ",
      "PD              ",
      "P               ",
      "PD              ",
      "P               ",
      "P               ",
      "P    Β ѺUUUUUUUU",
      "P      C      Ͼ ",
      "P  Β   C        ",
      "P      C        ",
      "P      C        ",
      "P      C        ",
      "P      C        ",
      "P  D   C        ",
      "P    D C        "
    ],
    [
      "icd8g9gci       ",
      "ii     ii       ",
      "                ",
      "                ",
      " D              ",
      "                ",
      "                ",
      "     D          ",
      "              Ͼ ",
      "   D            ",
      "                ",
      "                ",
      "                ",
      "                ",
      "   D            ",
      "     D          "
    ],
    [
      " focccof        ",
      " foi iof        ",
      "                ",
      "                ",
      "                ",
      "                ",
      "                ",
      "     D          ",
      "   ΞD         者 ",
      "  DήΦ           ",
      "   DΣ           ",
      "                ",
      "                ",
      "                ",
      "                ",
      "    ΒD          "
    ]
  ]
}