{
  "xsize": 16,
  "zsize": 16,
  "palette": {
    "palette": [
      {
        "char": " ",
        "block": "minecraft:air"
      },
      {
        "char": "a",
        "block": "minecraft:air"
      },
      {
        "char": "家",
        "block": "minecraft:air"
      },
      {
        "char": "S",
        "block": "minecraft:air"
      },
      {
        "char": "Υ",
        "block": "minecraft:air"
      },
      {
        "char": "w",
        "block": "minecraft:air"
      },
      {
        "char": "z",
        "block": "minecraft:air"
      },
      {
        "char": "n",
        "block": "minecraft:air"
      },
      {
        "char": "e",
        "block": "minecraft:grass"
      },
      {
        "char": "h",
        "block": "minecraft:tall_grass[half=lower]"
      },
      {
        "char": "x",
        "block": "minecraft:air"
      },
      {
        "char": "D",
        "block": "minecraft:air"
      },
      {
        "char": "6",
        "block": "minecraft:air"
      },
      {
        "char": "ϊ",
        "block": "minecraft:air"
      },
      {
        "char": "ͳ",
        "block": "minecraft:air"
      },
      {
        "char": "H",
        "block": "minecraft:air"
      },
      {
        "char": "Ξ",
        "block": "minecraft:air"
      },
      {
        "char": "ΐ",
        "block": "minecraft:air"
      },
      {
        "char": "ή",
        "block": "minecraft:air"
      },
      {
        "char": "1",
        "block": "minecraft:air"
      },
      {
        "char": "ӷ",
        "block": "minecraft:air"
      },
      {
        "char": "ͼ",
        "block": "minecraft:air"
      },
      {
        "char": "Я",
        "block": "minecraft:air"
      },
      {
        "char": "ѥ",
        "block": "minecraft:air"
      },
      {
        "char": "Һ",
        "block": "minecraft:air"
      },
      {
        "char": "ϒ",
        "block": "minecraft:air"
      },
      {
        "char": "θ",
        "block": "minecraft:air"
      },
      {
        "char": "Ϣ",
        "block": "minecraft:air"
      },
      {
        "char": "情",
        "block": "minecraft:air"
      },
      {
        "char": "l",
        "block": "minecraft:tall_grass[half=upper]"
      },
      {
        "char": "Σ",
        "block": "minecraft:air"
      },
      {
        "char": "Ѝ",
        "block": "minecraft:air"
      },
      {
        "char": "ώ",
        "block": "minecraft:air"
      },
      {
        "char": "s",
        "block": "minecraft:air"
      },
      {
        "char": "Ҡ",
        "block": "minecraft:air"
      },
      {
        "char": "i",
        "block": "minecraft:air"
      },
      {
        "char": "f",
        "block": "minecraft:air"
      },
      {
        "char": "o",
        "block": "minecraft:air"
      }
    ]
  },
  "slices": [
    [
      "aaaaaaaaaaaaaaaa",
      "aaaaaaaaa家SSSSSS",
      "aaaaaaaaaΥwwzwnn",
      "aaaaaaaaaΥzznznn",
      "aaaaaaaaaΥnwnwnn",
      "aaaaaaaaaΥznzwzz",
      "aaaaaaaaaΥzznznw",
      "aaaaaaaaaΥnwznzw",
      "aaaaaaaaaΥwwwnnn",
      "aaaaaaaaaΥnzwzwn",
      "aaaaaaaaaΥnzwnnw",
      "aaaaaaaaaΥnnzznn",
      "aaaaaaaaaΥnwznzn",
      "aaaaaaaaaΥnznnwn",
      "aaaaaaaaaΥwnznnz",
      "aaaaaaaaaΥzzwnwn"
    ],
    [
      "eehxexheehehexxe",
      "hhDhDhDhD       ",
      "hDDDxDhhh  6    ",
      "hD DeehDe 6  6  ",
      "Deϊͳeeeex       ",
      "xhHeΞehhe  ΐ   ΐ",
      "hDήHHxeDh    ΐ  ",
      "hDe1hhDDh 6 e ΐ ",
      "xhDheeDhe       ",
      " DhexӷhDe  6  ΐ ",
      "ehDehhxhe     ΐ ",
      "ee hͼЯѥhx      e",
      "ehDeҺͼϒh e  e   ",
      "ehDhθϢh情D e   ΐ ",
      "eDheehDDh      ΐ",
      "hxeDxeeDe    ΐ  "
    ],
    [
      "  l   l  l l    ",
      "ll l l          ",
      "l D  Dll        ",
      "l     l         ",
      "                ",
      " lΞ   ll        ",
      "l ήHH   l       ",
      "l  Σl   l       ",
      " lDl  Dl        ",
      "  l   l         ",
      " l  ll l        ",
      "   l            ",
      " l  Ѝͼ          ",
      " lDlώ l s       ",
      "  l  l Dl       ",
      "l               "
    ],
    [
      "                ",
      "                ",
      "                ",
      "                ",
      "                ",
      "                ",
      "   HҠ           ",
      "                ",
      "                ",
      "                ",
      "                ",
      "                ",
      "    θͼ          ",
      "                ",
      "                ",
      "                "
    ],
    [
      "                ",
      "                ",
      "                ",
      "                ",
      "                ",
      "                ",
      "   Hͳ           ",
      "                ",
      "                ",
      "                ",
      "                ",
      "                ",
      "     ͼ          ",
      "                ",
      "                ",
      "ii     ii       "
    ],
    [
      "                ",
      "                ",
      "                ",
      "                ",
      "                ",
      "                ",
      "   H            ",
      "                ",
      "                ",
      "                ",
      "                ",
      "                ",
      "     ͼ          ",
      "     ώ          ",
      "                ",
      " foi iof        "
    ]
  ]
}