{
  "xsize": 16,
  "zsize": 16,
  "palette": {
    "palette": [
      {
        "char": " ",
        "block": "minecraft:air"
      },
      {
        "char": "a",
        "block": "minecraft:grass_block[snowy=false]"
      },
      {
        "char": "4",
        "block": "minecraft:calcite"
      },
      {
        "char": "B",
        "block": "minecraft:terracotta"
      },
      {
        "char": "N",
        "block": "minecraft:diorite"
      },
      {
        "char": "о",
        "block": "minecraft:green_terracotta"
      },
      {
        "char": "қ",
        "block": "minecraft:lime_terracotta"
      },
      {
        "char": "ѕ",
        "block": "minecraft:light_blue_terracotta"
      },
      {
        "char": "P",
        "block": "minecraft:spruce_trapdoor[facing=west,half=bottom,open=true,powered=false,waterlogged=false]"
      },
      {
        "char": "e",
        "block": "minecraft:air"
      },
      {
        "char": "D",
        "block": "minecraft:dark_oak_leaves[distance=7,persistent=true,waterlogged=false]"
      },
      {
        "char": "Β",
        "block": "minecraft:spruce_fence[east=false,north=false,south=false,waterlogged=false,west=false]"
      },
      {
        "char": "C",
        "block": "minecraft:air"
      },
      {
        "char": "h",
        "block": "minecraft:air"
      },
      {
        "char": "x",
        "block": "minecraft:air"
      },
      {
        "char": "所",
        "block": "minecraft:dark_oak_leaves[distance=1,persistent=true,waterlogged=false]"
      },
      {
        "char": "в",
        "block": "minecraft:spruce_stairs[facing=south,half=bottom,shape=straight,waterlogged=false]"
      },
      {
        "char": "H",
        "block": "minecraft:oak_wood[axis=y]"
      },
      {
        "char": "之",
        "block": "minecraft:air"
      },
      {
        "char": "Ά",
        "block": "minecraft:spruce_trapdoor[facing=south,half=bottom,open=false,powered=false,waterlogged=false]"
      },
      {
        "char": "Σ",
        "block": "minecraft:spruce_fence[east=false,north=true,south=false,waterlogged=false,west=false]"
      },
      {
        "char": "Ͼ",
        "block": "minecraft:air"
      },
      {
        "char": "҄",
        "block": "minecraft:air"
      },
      {
        "char": "U",
        "block": "minecraft:air"
      },
      {
        "char": "A",
        "block": "minecraft:spruce_trapdoor[facing=south,half=bottom,open=true,powered=false,waterlogged=false]"
      },
      {
        "char": "l",
        "block": "minecraft:air"
      },
      {
        "char": "Ξ",
        "block": "minecraft:spruce_fence[east=false,north=false,south=true,waterlogged=false,west=false]"
      },
      {
        "char": "ј",
        "block": "minecraft:spruce_stairs[facing=east,half=bottom,shape=straight,waterlogged=false]"
      },
      {
        "char": "Ͷ",
        "block": "minecraft:spruce_fence[east=true,north=false,south=false,waterlogged=false,west=false]"
      },
      {
        "char": "ϊ",
        "block": "minecraft:spruce_fence[east=true,north=false,south=true,waterlogged=false,west=false]"
      },
      {
        "char": "ͳ",
        "block": "minecraft:spruce_fence[east=false,north=false,south=false,waterlogged=false,west=true]"
      },
      {
        "char": "ӱ",
        "block": "minecraft:air"
      }
    ]
  },
  "slices": [
    [
      "aaaaaaaa4BBBB4NN",
      "aaaaaaaa4BBBNооқ",
      "aaaaaaaa4NN4Nқ4о",
      "aaaaaaaaNBBB4қоо",
      "aaaaaaaa4BBBBN44",
      "aaaaaaaaNBBBBBBB",
      "aaaaaaaaNBBBBBBB",
      "aaaaaaaaNBBBBN44",
      "aaaaaaaa4BBBNBBB",
      "aaaaaaaa4BBNBBNB",
      "aaaaaaaa4BB4BNѕ4",
      "aaaaaaaaNBBNBNѕN",
      "aaaaaaaaN44NNNNN",
      "aaaaaaaaaaaaaaaa",
      "aaaaaaaaaaaaaaaa",
      "aaaaaaaaaaaaaaaa"
    ],
    [
      "PeeDeΒDC        ",
      "PDhhD eC        ",
      "PxΒDhhDC        ",
      "PeheDDeCe      e",
      "PDhDxehC     e  ",
      "PeDΒhxDC        ",
      "PhhDhDhC        ",
      "PeDhDhDC        ",
      "PhhDh所вC        ",
      "PDhDeHH之        ",
      "PDhΆxΣhC        ",
      "PhDeΆeΒC        ",
      "PDxhΆΆhC      Ͼ ",
      "PhDΆeex҄UUUUUUUU",
      "PeeΆΆeΆh heΆ hΆh",
      "eAAeeΆeΆΆxΆΆ eeΆ"
    ],
    [
      "P    D C        ",
      "P ll   C        ",
      "P Β ll C        ",
      "P l D  C        ",
      "P l   lC        ",
      "P  Βl  C        ",
      "P  Dl lC        ",
      "P  l lDC        ",
      "P l l ΞC        ",
      "P  D HHC        ",
      "P     lC        ",
      "PlD    C        ",
      "P  l  lC      Ͼ ",
      "Pl     ҄UUUUUUUU",
      "P      l l   l l",
      " A              "
    ],
    [
      "P    Β C        ",
      "P      C        ",
      "P D    C        ",
      "P      C        ",
      "P      C        ",
      "P  Β   C        ",
      "P      C        ",
      "P      C        ",
      "P      C        ",
      "P    јHC        ",
      "P      C        ",
      "P      C        ",
      "P      C      Ͼ ",
      "P      ҄UUUUUUUU",
      "P               ",
      " A              "
    ],
    [
      "    DDD         ",
      "     D          ",
      "                ",
      "                ",
      "                ",
      "   D            ",
      "                ",
      "                ",
      "                ",
      "     ͶH         ",
      "                ",
      "                ",
      "              Ͼ ",
      "                ",
      "                ",
      "                "
    ],
    [
      "    Dϊͳ         ",
      "    DΣD         ",
      "                ",
      "                ",
      "                ",
      "   D            ",
      "                ",
      "                ",
      "                ",
      "      H         ",
      "                ",
      "                ",
      "              ӱ ",
      "                ",
      "                ",
      "                "
    ]
  ]
}