{
  "xsize": 16,
  "zsize": 16,
  "palette": {
    "palette": [
      {
        "char": " ",
        "block": "minecraft:air"
      },
      {
        "char": "F",
        "block": "minecraft:air"
      },
      {
        "char": "a",
        "block": "minecraft:air"
      },
      {
        "char": "k",
        "block": "minecraft:air"
      },
      {
        "char": "J",
        "block": "minecraft:air"
      },
      {
        "char": "L",
        "block": "minecraft:air"
      },
      {
        "char": "I",
        "block": "minecraft:air"
      },
      {
        "char": "K",
        "block": "minecraft:air"
      },
      {
        "char": "E",
        "block": "minecraft:air"
      },
      {
        "char": "V",
        "block": "minecraft:air"
      },
      {
        "char": "T",
        "block": "minecraft:air"
      },
      {
        "char": "ʹ",
        "block": "minecraft:air"
      },
      {
        "char": "z",
        "block": "minecraft:air"
      },
      {
        "char": "n",
        "block": "minecraft:air"
      },
      {
        "char": "Ѹ",
        "block": "minecraft:air"
      },
      {
        "char": "w",
        "block": "minecraft:air"
      },
      {
        "char": "m",
        "block": "minecraft:air"
      },
      {
        "char": "e",
        "block": "minecraft:grass"
      },
      {
        "char": "h",
        "block": "minecraft:tall_grass[half=lower]"
      },
      {
        "char": "x",
        "block": "minecraft:air"
      },
      {
        "char": "s",
        "block": "minecraft:air"
      },
      {
        "char": "ϰ",
        "block": "minecraft:air"
      },
      {
        "char": "Ы",
        "block": "minecraft:air"
      },
      {
        "char": "H",
        "block": "minecraft:air"
      },
      {
        "char": "я",
        "block": "minecraft:air"
      },
      {
        "char": "Ό",
        "block": "minecraft:air"
      },
      {
        "char": "f",
        "block": "minecraft:air"
      },
      {
        "char": "A",
        "block": "minecraft:air"
      },
      {
        "char": "ӏ",
        "block": "minecraft:air"
      },
      {
        "char": "6",
        "block": "minecraft:air"
      },
      {
        "char": "Β",
        "block": "minecraft:air"
      },
      {
        "char": "l",
        "block": "minecraft:tall_grass[half=upper]"
      },
      {
        "char": "ϥ",
        "block": "minecraft:air"
      },
      {
        "char": "ҏ",
        "block": "minecraft:air"
      },
      {
        "char": "位",
        "block": "minecraft:air"
      },
      {
        "char": "Ͷ",
        "block": "minecraft:air"
      },
      {
        "char": "Φ",
        "block": "minecraft:air"
      },
      {
        "char": "Σ",
        "block": "minecraft:air"
      }
    ]
  },
  "slices": [
    [
      "FaaaaaaaaakJaaaa",
      "FaaaaaaaaakLaaaa",
      "IKJKEILkLkEkJkEJ",
      "KLLKkJLkkLKkEkKE",
      "LKEEELkkJkkKEJkk",
      "KEKKJEKLEkKLLEkE",
      "aaaaaaaaaakkaaaa",
      "FaaaaaaaaaKLaaaa",
      "VaaaaaaaaaJkaaTT",
      "aaaaaaaaaaEkaʹzn",
      "aaaaaaaaaakkʹznn",
      "aaaaaaaaaaLkʹzѸn",
      "aaaaaaaaaaJJʹnnz",
      "aaaaaaaaaaKLʹnnz",
      "aaaaaaaaaakkʹnnn",
      "aaaaaaaaaakKʹnnw"
    ],
    [
      "mmeheexemhs hmhe",
      "mhheexeexe sehee",
      " s  ϰϰϰ  s ss s ",
      "s ЫHaaaHя  s s  ",
      "   HaaaHΌss   s ",
      " fs AAA s  s  ss",
      "m xhehhexes eehe",
      "mmxeehmhees hmxӏ",
      "m heehmhex  mh  ",
      "hfxeeexmhe  e  s",
      "feeeeeehhee   s ",
      "eehx xhhmh s   6",
      "x eeheemmh s s  ",
      "x ee xhmhes  s6 ",
      " ehΒhhheehs  ss ",
      "exxh mhhmh   s  "
    ],
    [
      "m  l     l  l l ",
      " ll          l  ",
      "                ",
      "   ϥhmhs        ",
      "   ҏmhhϥΌ       ",
      "                ",
      "   l ll       l ",
      "m    l      l  ӏ",
      "  l   ml     l  ",
      "l       l       ",
      "       ll       ",
      "  l   l  l      ",
      "    l  m l      ",
      "      l l       ",
      "  lΒlll  l      ",
      "       l l      "
    ],
    [
      "                ",
      "                ",
      "                ",
      "   sl l         ",
      "                ",
      "                ",
      "                ",
      "               位",
      "                ",
      "                ",
      "                ",
      "                ",
      "                ",
      "                ",
      "   m            ",
      "                "
    ],
    [
      "                ",
      "                ",
      "                ",
      "                ",
      "                ",
      "                ",
      "                ",
      "                ",
      "                ",
      "                ",
      "                ",
      "                ",
      "                ",
      "   m            ",
      "   Β            ",
      "   m            "
    ],
    [
      "                ",
      "                ",
      "                ",
      "                ",
      "                ",
      "                ",
      "                ",
      "                ",
      "                ",
      "                ",
      "                ",
      "                ",
      "                ",
      "   m            ",
      "  ͶΦm           ",
      "  mΣ            "
    ]
  ]
}