{
  "xsize": 16,
  "zsize": 16,
  "palette": {
    "palette": [
      {
        "char": " ",
        "block": "minecraft:air"
      },
      {
        "char": "a",
        "block": "minecraft:air"
      },
      {
        "char": "S",
        "block": "minecraft:air"
      },
      {
        "char": "n",
        "block": "minecraft:air"
      },
      {
        "char": "z",
        "block": "minecraft:air"
      },
      {
        "char": "w",
        "block": "minecraft:air"
      },
      {
        "char": "T",
        "block": "minecraft:air"
      },
      {
        "char": "k",
        "block": "minecraft:air"
      },
      {
        "char": "E",
        "block": "minecraft:air"
      },
      {
        "char": "K",
        "block": "minecraft:air"
      },
      {
        "char": "I",
        "block": "minecraft:air"
      },
      {
        "char": "L",
        "block": "minecraft:air"
      },
      {
        "char": "J",
        "block": "minecraft:air"
      },
      {
        "char": "V",
        "block": "minecraft:air"
      },
      {
        "char": "F",
        "block": "minecraft:air"
      },
      {
        "char": "x",
        "block": "minecraft:air"
      },
      {
        "char": "e",
        "block": "minecraft:grass"
      },
      {
        "char": "6",
        "block": "minecraft:air"
      },
      {
        "char": "ς",
        "block": "minecraft:air"
      },
      {
        "char": "ϓ",
        "block": "minecraft:air"
      },
      {
        "char": "台",
        "block": "minecraft:air"
      },
      {
        "char": "而",
        "block": "minecraft:air"
      },
      {
        "char": "ΐ",
        "block": "minecraft:air"
      },
      {
        "char": "h",
        "block": "minecraft:tall_grass[half=lower]"
      },
      {
        "char": "s",
        "block": "minecraft:air"
      },
      {
        "char": "m",
        "block": "minecraft:air"
      },
      {
        "char": "Ή",
        "block": "minecraft:air"
      },
      {
        "char": "看",
        "block": "minecraft:air"
      },
      {
        "char": "в",
        "block": "minecraft:air"
      },
      {
        "char": "H",
        "block": "minecraft:air"
      },
      {
        "char": "Φ",
        "block": "minecraft:air"
      },
      {
        "char": "Ͱ",
        "block": "minecraft:air"
      },
      {
        "char": "Σ",
        "block": "minecraft:air"
      },
      {
        "char": "ϥ",
        "block": "minecraft:air"
      },
      {
        "char": "R",
        "block": "minecraft:air"
      },
      {
        "char": "Ͷ",
        "block": "minecraft:air"
      },
      {
        "char": "ψ",
        "block": "minecraft:air"
      },
      {
        "char": "l",
        "block": "minecraft:tall_grass[half=upper]"
      },
      {
        "char": "Ξ",
        "block": "minecraft:air"
      },
      {
        "char": "7",
        "block": "minecraft:air"
      },
      {
        "char": "ϕ",
        "block": "minecraft:air"
      },
      {
        "char": "ј",
        "block": "minecraft:air"
      },
      {
        "char": "Ό",
        "block": "minecraft:air"
      },
      {
        "char": "Ϛ",
        "block": "minecraft:air"
      },
      {
        "char": "ϗ",
        "block": "minecraft:air"
      },
      {
        "char": "ώ",
        "block": "minecraft:air"
      },
      {
        "char": "ҫ",
        "block": "minecraft:air"
      },
      {
        "char": "ύ",
        "block": "minecraft:air"
      }
    ]
  },
  "slices": [
    [
      "aaaaaaaaaaaaaaaa",
      "SSSSSSSSSSSSSSSS",
      "nnznnzzwwnnznnnn",
      "wwnwnnwwznnnwwnw",
      "wnnnznznnnwnwnnn",
      "nnnznwzzwnnwwnww",
      "TTTTTTTTTTTTTTTT",
      "aaaaaaaaaakkkaaa",
      "aaaaaaaaaakkkaaa",
      "aaaaaaaaaakkkaaa",
      "aaaaaaaaaaEKEaaa",
      "aaaaaaaaaaIKLaaa",
      "aaaaaaaaaaLJLaaV",
      "aaaaaaaaaakEIaFF",
      "aaaaaaaaaakEkaaF",
      "aaaaaaaaaaEIIaaV"
    ],
    [
      "xeeeeeeeeeeeeeee",
      "        e       ",
      "66    ς         ",
      "    ς    e  ς ϓ ",
      " e ς      ς 台  而",
      "       ΐΐ    ΐ ΐ",
      "           e    ",
      "exeeehxxees  ehe",
      "xexheehhmxs  ehe",
      "ehe eehmhe e xΉe",
      "eee看ememhx  seeh",
      "eexeeemhxh e ehm",
      "eemehmeвhxs  xhe",
      "eh  ehHHΦhs  emͰ",
      "emh ehΣϥHe s exR",
      "hmmx xmͶψhs  emm"
    ],
    [
      "                ",
      "                ",
      "                ",
      "                ",
      "                ",
      "                ",
      "                ",
      "     l        l ",
      "   l  ll      l ",
      " l            Ή ",
      "     s  l      l",
      "      ml l    l ",
      "  s l  Ξl     l ",
      " l   lHHΦl     Ͱ",
      "  l  l ϥΣ       ",
      "l m      l      "
    ],
    [
      "                ",
      "                ",
      "                ",
      "                ",
      "                ",
      "                ",
      "                ",
      "                ",
      "                ",
      "              7 ",
      "                ",
      "      s         ",
      "       ϕ        ",
      "      јHΌ      Ϛ",
      "                ",
      "                "
    ],
    [
      "                ",
      "                ",
      "                ",
      "                ",
      "                ",
      "                ",
      "                ",
      "                ",
      "                ",
      "              Ή7",
      "              7 ",
      "                ",
      "                ",
      "      ͶHΌ      Ϛ",
      "                ",
      "                "
    ],
    [
      "                ",
      "                ",
      "                ",
      "                ",
      "                ",
      "                ",
      "                ",
      "                ",
      "              7 ",
      "             7ϗ7",
      "              ώ ",
      "                ",
      "                ",
      "       HΌ      ҫ",
      "               ύ",
      "               R"
    ]
  ]
}