{
  "xsize": 16,
  "zsize": 16,
  "palette": {
    "palette": [
      {
        "char": " ",
        "block": "minecraft:air"
      },
      {
        "char": "a",
        "block": "minecraft:air"
      },
      {
        "char": "L",
        "block": "minecraft:air"
      },
      {
        "char": "K",
        "block": "minecraft:air"
      },
      {
        "char": "ʹ",
        "block": "minecraft:air"
      },
      {
        "char": "n",
        "block": "minecraft:air"
      },
      {
        "char": "w",
        "block": "minecraft:air"
      },
      {
        "char": "k",
        "block": "minecraft:air"
      },
      {
        "char": "J",
        "block": "minecraft:air"
      },
      {
        "char": "E",
        "block": "minecraft:air"
      },
      {
        "char": "Ѹ",
        "block": "minecraft:air"
      },
      {
        "char": "z",
        "block": "minecraft:air"
      },
      {
        "char": "S",
        "block": "minecraft:air"
      },
      {
        "char": "h",
        "block": "minecraft:tall_grass[half=lower]"
      },
      {
        "char": "x",
        "block": "minecraft:air"
      },
      {
        "char": "e",
        "block": "minecraft:grass"
      },
      {
        "char": "m",
        "block": "minecraft:air"
      },
      {
        "char": "s",
        "block": "minecraft:air"
      },
      {
        "char": "6",
        "block": "minecraft:air"
      },
      {
        "char": "ΐ",
        "block": "minecraft:air"
      },
      {
        "char": "ͼ",
        "block": "minecraft:air"
      },
      {
        "char": "Я",
        "block": "minecraft:air"
      },
      {
        "char": "ѥ",
        "block": "minecraft:air"
      },
      {
        "char": "Һ",
        "block": "minecraft:air"
      },
      {
        "char": "ϒ",
        "block": "minecraft:air"
      },
      {
        "char": "θ",
        "block": "minecraft:air"
      },
      {
        "char": "Ϣ",
        "block": "minecraft:air"
      },
      {
        "char": "Β",
        "block": "minecraft:air"
      },
      {
        "char": "l",
        "block": "minecraft:tall_grass[half=upper]"
      },
      {
        "char": "Ѝ",
        "block": "minecraft:air"
      },
      {
        "char": "ώ",
        "block": "minecraft:air"
      },
      {
        "char": "Ξ",
        "block": "minecraft:air"
      },
      {
        "char": "ϊ",
        "block": "minecraft:air"
      },
      {
        "char": "ψ",
        "block": "minecraft:air"
      },
      {
        "char": "Σ",
        "block": "minecraft:air"
      }
    ]
  },
  "slices": [
    [
      "aaaaaaaaaaLKʹnwn",
      "aaaaaaaaaaLkʹnnn",
      "aaaaaaaaaaJkʹnnw",
      "aaaaaaaaaaJEʹnwn",
      "aaaaaaaaaaKkʹwnn",
      "aaaaaaaaaakkʹѸnn",
      "aaaaaaaaaaLkʹnnѸ",
      "aaaaaaaaaaEJʹznn",
      "aaaaaaaaaaJkʹnwn",
      "aaaaaaaaaakkʹnnn",
      "aaaaaaaaaaJkʹѸnz",
      "aaaaaaaaaakkaʹzn",
      "EKKKKEkKEkKKaaSS",
      "aaaaaaaaaaaaaaaa",
      "aaaaaaaaaaaaaaaa",
      "aaaaaaaaaaaaaaaa"
    ],
    [
      "hxxhehemmhs  6 e",
      "xeeehheemhs  s  ",
      "eeeehmhhehs   6 ",
      "xehhmhemhe   e ΐ",
      "eͼЯѥmmhhees    s",
      "xҺͼϒhmhexe    6s",
      "eθϢhxheehe s 6  ",
      "ehhheexemhs     ",
      "ehmmhheh xs  s ΐ",
      "ehemmheΒ hs  s 6",
      "mehhxmheme s  e ",
      "ehexhhhehe  x  s",
      "ss e ss s s he  ",
      "eeexeehxehhmmmee",
      "hehhhe xhemhhhme",
      "eeexeexeexeee xe"
    ],
    [
      "l      m l      ",
      "                ",
      "                ",
      "  ll l  l       ",
      "     m l        ",
      " Ѝͼ l           ",
      " ώ l l  l       ",
      "  l      l      ",
      "       l        ",
      " l m l m l      ",
      "  ll  l         ",
      " l  lll l       ",
      "            l   ",
      "      l  ll m   ",
      "l lll   l  ll   ",
      "                "
    ],
    [
      "                ",
      "                ",
      "                ",
      "                ",
      "                ",
      " θͼ             ",
      "                ",
      "                ",
      "       m        ",
      "       mm       ",
      "       m        ",
      "                ",
      "                ",
      "                ",
      "                ",
      "                "
    ],
    [
      "                ",
      "                ",
      "                ",
      "                ",
      "                ",
      "  ͼ             ",
      "                ",
      "                ",
      "       mΞ       ",
      "      mϊψ       ",
      "       Σm       ",
      "                ",
      "                ",
      "                ",
      "                ",
      "                "
    ],
    [
      "                ",
      "                ",
      "                ",
      "                ",
      "                ",
      "  ͼ             ",
      "  ώ             ",
      "                ",
      "                ",
      "       m        ",
      "                ",
      "                ",
      "                ",
      "                ",
      "                ",
      "                "
    ]
  ]
}