{
  "xsize": 16,
  "zsize": 16,
  "palette": {
    "palette": [
      {
        "char": " ",
        "block": "minecraft:air"
      },
      {
        "char": "a",
        "block": "minecraft:dirt"
      },
      {
        "char": "d",
        "block": "minecraft:stone[weathering=false]"
      },
      {
        "char": "B",
        "block": "minecraft:black_wool"
      },
      {
        "char": "b",
        "block": "minecraft:grass_block[snowy=false]"
      },
      {
        "char": "i",
        "block": "minecraft:gray_wool"
      },
      {
        "char": "P",
        "block": "minecraft:dispenser[facing=south,triggered=false]",
        "tag": {
          "z": 739,
          "x": 189,
          "ForgeData": {
            "LockFlag": "1b"
          },
          "ForgeCaps": {},
          "id": "minecraft:dispenser",
          "y": 132,
          "Items": []
        }
      },
      {
        "char": "o",
        "block": "minecraft:podzol[snowy=false]"
      },
      {
        "char": "g",
        "block": "minecraft:coarse_dirt"
      },
      {
        "char": "c",
        "block": "minecraft:air"
      },
      {
        "char": "f",
        "block": "minecraft:air"
      },
      {
        "char": "n",
        "block": "minecraft:vine[east=true,north=false,south=false,up=false,west=false]"
      },
      {
        "char": "e",
        "block": "minecraft:gray_concrete"
      },
      {
        "char": "C",
        "block": "minecraft:quartz_stairs[facing=north,half=bottom,shape=straight,waterlogged=false]"
      },
      {
        "char": "Z",
        "block": "minecraft:zombie_head[rotation=14]",
        "tag": {
          "z": 738,
          "x": 189,
          "ForgeCaps": {},
          "id": "minecraft:skull",
          "y": 133
        }
      },
      {
        "char": "M",
        "block": "minecraft:brown_mushroom"
      },
      {
        "char": "6",
        "block": "minecraft:stone_button[face=floor,facing=south,powered=false]"
      },
      {
        "char": "t",
        "block": "minecraft:stone_button[face=floor,facing=east,powered=false]"
      },
      {
        "char": "q",
        "block": "minecraft:glass"
      },
      {
        "char": "X",
        "block": "minecraft:stone_button[face=wall,facing=south,powered=false]"
      },
      {
        "char": "l",
        "block": "minecraft:vine[east=false,north=false,south=false,up=false,west=true]"
      },
      {
        "char": "h",
        "block": "minecraft:smooth_stone_slab[type=bottom,waterlogged=false]"
      },
      {
        "char": "R",
        "block": "minecraft:fern"
      }
    ]
  },
  "slices": [
    [
      "aaaaaddddddddddd",
      "aaaaaddddddddddd",
      "aaaaaddddddddddd",
      "aaaaaddddddddddd",
      "aaaaaddddddddddd",
      "aaaaaddddddddddd",
      "aaaaaddddddddddd",
      "aaaaaddddddddddd",
      "aaaaaddddddddddd",
      "aaaaaddddddddddd",
      "aaaaaddddddddddd",
      "aaaaaddddddddddd",
      "aaaaaaaaaaaaaaaa",
      "aaaaaaaaaaaaaaaa",
      "aaaaaaaaaaaaaaaa",
      "aaaaaaaaaaaaaaaa"
    ],
    [
      "aaaaaaaaaaaaaaaa",
      "aaaaaaaaaaaaBaaa",
      "aaaaaaaaaaaaBaaa",
      "aaaaaaaaaaaaaaaa",
      "aaaaaaaaaaaaaaaa",
      "aaaaaaaaaaaaaaaa",
      "aaaaaaaaaaaaaaaa",
      "aaaaaddddddddddd",
      "aaaaaddddddddddd",
      "aaaaaddddddddddd",
      "aaaaaddddddddddd",
      "aaaaaddddddddddd",
      "aaaaaaaaaaaaaaaa",
      "aaaaaaaaaaaaaaaa",
      "aaaaaaaaaaaaaaaa",
      "aaaaaaaaaaaaaaaa"
    ],
    [
      "bbbbbbbbbbaiiiab",
      "bbbbbbbbbbaiiiab",
      "bbbbbbbbbaaiiiaa",
      "bbbbbabbbaaPiPaa",
      "bbbbbbbbbaaaaaaa",
      "bbbbbbbbbaaaaaaa",
      "bbbbbbbbboaaaaab",
      "bbbbbbbbbbaaaaab",
      "bbbbbbbbbbbbgbbb",
      "bbbbbbabbbbbbbbb",
      "bbbbbbbbbbbbbbbb",
      "bbbbbbbbbabbbbab",
      "bbbbbbbbbbbbbbbb",
      "bbbbbbbbbbbbbbbb",
      "bbbbbbbbbbbbbbbb",
      "bbbbbbbbbbbbbbbb"
    ],
    [
      "cff cccc ne   ec",
      "fffffc ccneC Cec",
      " fc fcc cge  Zeg",
      "fcfffgcfcoe   eg",
      "f fffccccgaeeeag",
      "ccfcfccfcgaaaaag",
      "cffcf cc Mgaaagc",
      " fccc 6cc oggggc",
      "ccfcfc ccc c c c",
      "fcf f gcc ct   c",
      "ccf c  c  c    c",
      " cfffcc co  cfg ",
      "cccccccfcf cffc ",
      "ccfcfcfcffcfcfcc",
      "fffcfcf c fc ccc",
      " fcfccccfcf    f"
    ],
    [
      "         nq  Xql",
      "         ne   el",
      "         cq   q ",
      "         cqq qq ",
      "          gg  g ",
      "          ggogoc",
      "          tgggc ",
      "          c  ct ",
      "                ",
      "                ",
      "                ",
      "         M      ",
      "                ",
      "                ",
      "                ",
      "                "
    ],
    [
      "         neeeeel",
      "         neeeeel",
      "          heeeh ",
      "           hhh  ",
      "           ogg  ",
      "            Rcc ",
      "                ",
      "                ",
      "                ",
      "                ",
      "                ",
      "                ",
      "                ",
      "                ",
      "                ",
      "                "
    ]
  ]
}