{
  "xsize": 16,
  "zsize": 16,
  "palette": {
    "palette": [
      {
        "char": " ",
        "block": "minecraft:air"
      },
      {
        "char": "d",
        "block": "minecraft:stone[weathering=false]"
      },
      {
        "char": "a",
        "block": "minecraft:dirt"
      },
      {
        "char": "b",
        "block": "minecraft:grass_block[snowy=false]"
      },
      {
        "char": "N",
        "block": "minecraft:cracked_stone_bricks"
      },
      {
        "char": "A",
        "block": "minecraft:spawner",
        "tag": {
          "SpawnData": {
            "entity": {}
          },
          "MaxNearbyEntities": "6s",
          "MinSpawnDelay": "200s",
          "z": 730,
          "x": 186,
          "MaxSpawnDelay": "800s",
          "RequiredPlayerRange": "16s",
          "SpawnCount": "4s",
          "ForgeCaps": {},
          "id": "minecraft:mob_spawner",
          "SpawnPotentials": [],
          "y": 136,
          "SpawnRange": "4s",
          "Delay": "287s"
        }
      },
      {
        "char": "5",
        "block": "minecraft:campfire[facing=east,lit=true,signal_fire=false,waterlogged=false]",
        "tag": {
          "CookingTotalTimes": [
            "I",
            0,
            0,
            0,
            0
          ],
          "z": 746,
          "x": 196,
          "CookingTimes": [
            "I",
            0,
            0,
            0,
            0
          ],
          "ForgeCaps": {},
          "id": "minecraft:campfire",
          "y": 132,
          "Items": []
        }
      },
      {
        "char": "c",
        "block": "minecraft:air"
      },
      {
        "char": "h",
        "block": "minecraft:smooth_stone_slab[type=bottom,waterlogged=false]"
      },
      {
        "char": "r",
        "block": "minecraft:stone_button[face=floor,facing=north,powered=false]"
      },
      {
        "char": "t",
        "block": "minecraft:stone_button[face=floor,facing=east,powered=false]"
      },
      {
        "char": "f",
        "block": "minecraft:air"
      },
      {
        "char": "g",
        "block": "minecraft:coarse_dirt"
      },
      {
        "char": "j",
        "block": "minecraft:air"
      }
    ]
  },
  "slices": [
    [
      "dddddddddddddddd",
      "dddddddddddddddd",
      "dddddddddddddddd",
      "dddddddddddddddd",
      "dddddddddddddddd",
      "dddddddddddddddd",
      "dddddddddddddddd",
      "dddddddddddddddd",
      "dddddddddddddddd",
      "dddddddddddddddd",
      "dddddddddddddddd",
      "dddddddddddddddd",
      "aaaaaaaaaaaaaaaa",
      "aaaaaaaaaaaaaaaa",
      "aaaaaaaaaaaaaaaa",
      "aaaaaaaaaaaaaaaa"
    ],
    [
      "aaaaaaaaaddddddd",
      "aaaaaaaaaddddddd",
      "aaaaaaaaaddddddd",
      "aaaaaaabaddddddd",
      "aaaaaaabaddddddd",
      "aaaaaaaaaddddddd",
      "aaaaaaaaNddddddd",
      "dddddddddddddddd",
      "dddddddddddddddd",
      "dddddddddddddddd",
      "dddddddddddddddd",
      "dddddddddddddddd",
      "aaaaaaaaaaaaaaaa",
      "aaaaaaaaaaaaaaaa",
      "aaaaaaaaaaaaaaaa",
      "aaaaaaaaaaaaaaaa"
    ],
    [
      "bbbbbbbbbbaaAbbb",
      "bbbbbbbbbaaAbbbb",
      "bbbbbabbaaAbbbab",
      "bbabbbbAaabbbbbb",
      "bbbbbbbAabbbbbbb",
      "bbbbbbbbbbbbbbbb",
      "bbbbbbbbNbbbbbbb",
      "bbbbbbbbbbbbbbbb",
      "bbbbbbbbbbbbbbbb",
      "babbbbbbbbbdbbbb",
      "bbbb5bbbbbbdbbbb",
      "bbbbbbbbbbbbbbbb",
      "bbbbbbbbbbbbbbbb",
      "bbbbbbbbbbbbbbbb",
      "bbbbbbbbbbbbbbbb",
      "bbbbbbbbbbbbbbbb"
    ],
    [
      "cccccccccchhhccc",
      "cccrctccchhhffc ",
      "cccccgcfhhhc cg ",
      "rcgfc chhhccfccf",
      "  cccfchhccfcc c",
      "cccccf cccccc   ",
      "ccffcc    ffcccc",
      "cctccc  c cfcccc",
      "  cccf  cccccccf",
      " g c c ccc  ccf ",
      "ccc h c ff   ccc",
      "cccc cccccc  c c",
      "f  ffccf c cfc  ",
      "f  cc cf  fcffff",
      "c ff f fff f  cf",
      "cfc      f  cfc "
    ],
    [
      "                ",
      "            jj  ",
      "       j        ",
      "            j  j",
      "                ",
      "     j          ",
      "          jj    ",
      "           j    ",
      "     j         j",
      "              j ",
      "        jj      ",
      "                ",
      "                ",
      "                ",
      "                ",
      "                "
    ],
    [
      "                ",
      "                ",
      "                ",
      "                ",
      "                ",
      "                ",
      "                ",
      "                ",
      "                ",
      "                ",
      "                ",
      "                ",
      "                ",
      "                ",
      "                ",
      "                "
    ]
  ]
}