{
  "xsize": 16,
  "zsize": 16,
  "palette": {
    "palette": [
      {
        "char": " ",
        "block": "minecraft:air"
      },
      {
        "char": "a",
        "block": "minecraft:dirt"
      },
      {
        "char": "g",
        "block": "minecraft:coarse_dirt"
      },
      {
        "char": "S",
        "block": "minecraft:stone_slab[type=bottom,waterlogged=false,weathering=false]"
      },
      {
        "char": "o",
        "block": "minecraft:podzol[snowy=false]"
      },
      {
        "char": "b",
        "block": "minecraft:grass_block[snowy=false]"
      },
      {
        "char": "c",
        "block": "minecraft:air"
      },
      {
        "char": "R",
        "block": "minecraft:fern"
      },
      {
        "char": "f",
        "block": "minecraft:air"
      },
      {
        "char": "h",
        "block": "minecraft:smooth_stone_slab[type=bottom,waterlogged=false]"
      },
      {
        "char": "k",
        "block": "minecraft:smooth_stone_slab[type=top,waterlogged=false]"
      }
    ]
  },
  "slices": [
    [
      "aaaaaaaaaaaaaaaa",
      "aaaaaaaaaaaaaaaa",
      "aaaaaaaaaaaaaaaa",
      "aaaaaaaaaaaaaaaa",
      "aaaaaaaaaaagggga",
      "aaaaaaaaaaggggga",
      "aaaaaaaaaaggggga",
      "aaaaaaaaaaggSgga",
      "aaaaaaaaaagg oga",
      "aaaaaaaaaagg gga",
      "aaaaaaagaagg gga",
      "aaaaaaaaaagg gga",
      "aaaaaaabaagg gga",
      "aaaaabaaaagg gga",
      "aaaaabaaaaog gga",
      "aaaaaaaabbggggga"
    ],
    [
      "aaaaaaaaaaaaaaaa",
      "aaaaaaaaaaaaaaaa",
      "aaaaaaaaaaaaaaaa",
      "aaaaaaaaaaabobab",
      "aaaaaaaaaag   gb",
      "aaaaaaaaag    cg",
      "aaaaaaaaag  c cg",
      "aaaaaaaaag    cg",
      "aaaaaaaaag     g",
      "aaaaaabaagc  c g",
      "aaaaaag ao    cg",
      "aaaaaaaaag     g",
      "aaaaagg ggcc   g",
      "aaaaacgggg     o",
      "aaaaacggggg    g",
      "aaaaagggccc  cgg"
    ],
    [
      "bbbbbbbbbbbbabbb",
      "bbbbbbbbbbbbbbbb",
      "bbbbbbbbbbbbbbbb",
      "bbbbbbbbbbbcc b ",
      "bbbbbbbbbb      ",
      "bbbbbbbab       ",
      "bbbbbabbb       ",
      "bbbbbbbbb      c",
      "bbbbbbbbbc      ",
      "bbbbbb bb       ",
      "bbbbbb  bR      ",
      "bbbbbabbb       ",
      "bbbbbbbbb       ",
      "bbbbb bbb       ",
      "bbbbb  b        ",
      "bbbbbb c        "
    ],
    [
      "fffc cc  c ch cc",
      " fcfc  ccc   ccc",
      "cccff  c c c   c",
      " ffffcccc       ",
      "ccfccfcfc       ",
      "ccfcf  hc       ",
      "ccccfgccc       ",
      "cccccccc        ",
      "cccff           ",
      "ffccc  c        ",
      "c cccc          ",
      "cffccgc         ",
      "ccc c c c       ",
      "fffcf c         ",
      "cfff            ",
      "ccffcc          "
    ],
    [
      "                ",
      "                ",
      "                ",
      "                ",
      "                ",
      "                ",
      "                ",
      "                ",
      "                ",
      "                ",
      "                ",
      "                ",
      "                ",
      "                ",
      "                ",
      "                "
    ],
    [
      "                ",
      "                ",
      "                ",
      "                ",
      "                ",
      "                ",
      "                ",
      "                ",
      "                ",
      "                ",
      "                ",
      "                ",
      "                ",
      "                ",
      "                ",
      "            k   "
    ]
  ]
}