{
  "xsize": 16,
  "zsize": 16,
  "palette": {
    "palette": [
      {
        "char": " ",
        "block": "minecraft:air"
      },
      {
        "char": "d",
        "block": "minecraft:air"
      },
      {
        "char": "a",
        "block": "minecraft:air"
      },
      {
        "char": "b",
        "block": "minecraft:air"
      },
      {
        "char": "N",
        "block": "minecraft:air"
      },
      {
        "char": "A",
        "block": "minecraft:air",
        "tag": {
          "SpawnData": {
            "entity": {}
          },
          "MaxNearbyEntities": "6s",
          "MinSpawnDelay": "200s",
          "z": 730,
          "x": 186,
          "MaxSpawnDelay": "800s",
          "RequiredPlayerRange": "16s",
          "SpawnCount": "4s",
          "ForgeCaps": {},
          "id": "minecraft:mob_spawner",
          "SpawnPotentials": [],
          "y": 136,
          "SpawnRange": "4s",
          "Delay": "287s"
        }
      },
      {
        "char": "5",
        "block": "minecraft:air",
        "tag": {
          "CookingTotalTimes": [
            "I",
            0,
            0,
            0,
            0
          ],
          "z": 746,
          "x": 196,
          "CookingTimes": [
            "I",
            0,
            0,
            0,
            0
          ],
          "ForgeCaps": {},
          "id": "minecraft:campfire",
          "y": 132,
          "Items": []
        }
      },
      {
        "char": "c",
        "block": "minecraft:grass"
      },
      {
        "char": "h",
        "block": "minecraft:air"
      },
      {
        "char": "r",
        "block": "minecraft:air"
      },
      {
        "char": "t",
        "block": "minecraft:air"
      },
      {
        "char": "f",
        "block": "minecraft:tall_grass[half=lower]"
      },
      {
        "char": "g",
        "block": "minecraft:air"
      },
      {
        "char": "j",
        "block": "minecraft:tall_grass[half=upper]"
      }
    ]
  },
  "slices": [
    [
      "dddddddddddddddd",
      "dddddddddddddddd",
      "dddddddddddddddd",
      "dddddddddddddddd",
      "dddddddddddddddd",
      "dddddddddddddddd",
      "dddddddddddddddd",
      "dddddddddddddddd",
      "dddddddddddddddd",
      "dddddddddddddddd",
      "dddddddddddddddd",
      "dddddddddddddddd",
      "aaaaaaaaaaaaaaaa",
      "aaaaaaaaaaaaaaaa",
      "aaaaaaaaaaaaaaaa",
      "aaaaaaaaaaaaaaaa"
    ],
    [
      "aaaaaaaaaddddddd",
      "aaaaaaaaaddddddd",
      "aaaaaaaaaddddddd",
      "aaaaaaabaddddddd",
      "aaaaaaabaddddddd",
      "aaaaaaaaaddddddd",
      "aaaaaaaaNddddddd",
      "dddddddddddddddd",
      "dddddddddddddddd",
      "dddddddddddddddd",
      "dddddddddddddddd",
      "dddddddddddddddd",
      "aaaaaaaaaaaaaaaa",
      "aaaaaaaaaaaaaaaa",
      "aaaaaaaaaaaaaaaa",
      "aaaaaaaaaaaaaaaa"
    ],
    [
      "bbbbbbbbbbaaAbbb",
      "bbbbbbbbbaaAbbbb",
      "bbbbbabbaaAbbbab",
      "bbabbbbAaabbbbbb",
      "bbbbbbbAabbbbbbb",
      "bbbbbbbbbbbbbbbb",
      "bbbbbbbbNbbbbbbb",
      "bbbbbbbbbbbbbbbb",
      "bbbbbbbbbbbbbbbb",
      "babbbbbbbbbdbbbb",
      "bbbb5bbbbbbdbbbb",
      "bbbbbbbbbbbbbbbb",
      "bbbbbbbbbbbbbbbb",
      "bbbbbbbbbbbbbbbb",
      "bbbbbbbbbbbbbbbb",
      "bbbbbbbbbbbbbbbb"
    ],
    [
      "cccccccccchhhccc",
      "cccrctccchhhffc ",
      "cccccgcfhhhc cg ",
      "rcgfc chhhccfccf",
      "  cccfchhccfcc c",
      "cccccf cccccc   ",
      "ccffcc    ffcccc",
      "cctccc  c cfcccc",
      "  cccf  cccccccf",
      " g c c ccc  ccf ",
      "ccc h c ff   ccc",
      "cccc cccccc  c c",
      "f  ffccf c cfc  ",
      "f  cc cf  fcffff",
      "c ff f fff f  cf",
      "cfc      f  cfc "
    ],
    [
      "                ",
      "            jj  ",
      "       j        ",
      "            j  j",
      "                ",
      "     j          ",
      "          jj    ",
      "           j    ",
      "     j         j",
      "              j ",
      "        jj      ",
      "                ",
      "                ",
      "                ",
      "                ",
      "                "
    ],
    [
      "                ",
      "                ",
      "                ",
      "                ",
      "                ",
      "                ",
      "                ",
      "                ",
      "                ",
      "                ",
      "                ",
      "                ",
      "                ",
      "                ",
      "                ",
      "                "
    ]
  ]
}