{
  "xsize": 16,
  "zsize": 16,
  "palette": {
    "palette": [
      {
        "char": " ",
        "block": "minecraft:air"
      },
      {
        "char": "a",
        "block": "minecraft:air"
      },
      {
        "char": "d",
        "block": "minecraft:air"
      },
      {
        "char": "B",
        "block": "minecraft:air"
      },
      {
        "char": "b",
        "block": "minecraft:air"
      },
      {
        "char": "i",
        "block": "minecraft:air"
      },
      {
        "char": "P",
        "block": "minecraft:air",
        "tag": {
          "z": 739,
          "x": 189,
          "ForgeData": {
            "LockFlag": "1b"
          },
          "ForgeCaps": {},
          "id": "minecraft:dispenser",
          "y": 132,
          "Items": []
        }
      },
      {
        "char": "o",
        "block": "minecraft:air"
      },
      {
        "char": "g",
        "block": "minecraft:air"
      },
      {
        "char": "c",
        "block": "minecraft:grass"
      },
      {
        "char": "f",
        "block": "minecraft:tall_grass[half=lower]"
      },
      {
        "char": "n",
        "block": "minecraft:air"
      },
      {
        "char": "e",
        "block": "minecraft:air"
      },
      {
        "char": "C",
        "block": "minecraft:air"
      },
      {
        "char": "Z",
        "block": "minecraft:air",
        "tag": {
          "z": 738,
          "x": 189,
          "ForgeCaps": {},
          "id": "minecraft:skull",
          "y": 133
        }
      },
      {
        "char": "M",
        "block": "minecraft:air"
      },
      {
        "char": "6",
        "block": "minecraft:air"
      },
      {
        "char": "t",
        "block": "minecraft:air"
      },
      {
        "char": "q",
        "block": "minecraft:air"
      },
      {
        "char": "X",
        "block": "minecraft:air"
      },
      {
        "char": "l",
        "block": "minecraft:air"
      },
      {
        "char": "h",
        "block": "minecraft:air"
      },
      {
        "char": "R",
        "block": "minecraft:air"
      }
    ]
  },
  "slices": [
    [
      "aaaaaddddddddddd",
      "aaaaaddddddddddd",
      "aaaaaddddddddddd",
      "aaaaaddddddddddd",
      "aaaaaddddddddddd",
      "aaaaaddddddddddd",
      "aaaaaddddddddddd",
      "aaaaaddddddddddd",
      "aaaaaddddddddddd",
      "aaaaaddddddddddd",
      "aaaaaddddddddddd",
      "aaaaaddddddddddd",
      "aaaaaaaaaaaaaaaa",
      "aaaaaaaaaaaaaaaa",
      "aaaaaaaaaaaaaaaa",
      "aaaaaaaaaaaaaaaa"
    ],
    [
      "aaaaaaaaaaaaaaaa",
      "aaaaaaaaaaaaBaaa",
      "aaaaaaaaaaaaBaaa",
      "aaaaaaaaaaaaaaaa",
      "aaaaaaaaaaaaaaaa",
      "aaaaaaaaaaaaaaaa",
      "aaaaaaaaaaaaaaaa",
      "aaaaaddddddddddd",
      "aaaaaddddddddddd",
      "aaaaaddddddddddd",
      "aaaaaddddddddddd",
      "aaaaaddddddddddd",
      "aaaaaaaaaaaaaaaa",
      "aaaaaaaaaaaaaaaa",
      "aaaaaaaaaaaaaaaa",
      "aaaaaaaaaaaaaaaa"
    ],
    [
      "bbbbbbbbbbaiiiab",
      "bbbbbbbbbbaiiiab",
      "bbbbbbbbbaaiiiaa",
      "bbbbbabbbaaPiPaa",
      "bbbbbbbbbaaaaaaa",
      "bbbbbbbbbaaaaaaa",
      "bbbbbbbbboaaaaab",
      "bbbbbbbbbbaaaaab",
      "bbbbbbbbbbbbgbbb",
      "bbbbbbabbbbbbbbb",
      "bbbbbbbbbbbbbbbb",
      "bbbbbbbbbabbbbab",
      "bbbbbbbbbbbbbbbb",
      "bbbbbbbbbbbbbbbb",
      "bbbbbbbbbbbbbbbb",
      "bbbbbbbbbbbbbbbb"
    ],
    [
      "cff cccc ne   ec",
      "fffffc ccneC Cec",
      " fc fcc cge  Zeg",
      "fcfffgcfcoe   eg",
      "f fffccccgaeeeag",
      "ccfcfccfcgaaaaag",
      "cffcf cc Mgaaagc",
      " fccc 6cc oggggc",
      "ccfcfc ccc c c c",
      "fcf f gcc ct   c",
      "ccf c  c  c    c",
      " cfffcc co  cfg ",
      "cccccccfcf cffc ",
      "ccfcfcfcffcfcfcc",
      "fffcfcf c fc ccc",
      " fcfccccfcf    f"
    ],
    [
      "         nq  Xql",
      "         ne   el",
      "         cq   q ",
      "         cqq qq ",
      "          gg  g ",
      "          ggogoc",
      "          tgggc ",
      "          c  ct ",
      "                ",
      "                ",
      "                ",
      "         M      ",
      "                ",
      "                ",
      "                ",
      "                "
    ],
    [
      "         neeeeel",
      "         neeeeel",
      "          heeeh ",
      "           hhh  ",
      "           ogg  ",
      "            Rcc ",
      "                ",
      "                ",
      "                ",
      "                ",
      "                ",
      "                ",
      "                ",
      "                ",
      "                ",
      "                "
    ]
  ]
}