{
  "xsize": 16,
  "zsize": 16,
  "palette": {
    "palette": [
      {
        "char": " ",
        "block": "minecraft:air"
      },
      {
        "char": "h",
        "block": "minecraft:vine[east=true,north=false,south=false,up=false,west=false]"
      },
      {
        "char": "y",
        "block": "minecraft:oak_leaves[distance=7,persistent=true,waterlogged=false]"
      },
      {
        "char": "c",
        "block": "minecraft:vine[east=false,north=true,south=false,up=false,west=false]"
      },
      {
        "char": "E",
        "block": "minecraft:vine[east=false,north=false,south=true,up=true,west=false]"
      },
      {
        "char": "H",
        "block": "minecraft:vine[east=true,north=false,south=false,up=true,west=false]"
      },
      {
        "char": "i",
        "block": "minecraft:diorite"
      },
      {
        "char": "G",
        "block": "minecraft:vine[east=false,north=false,south=true,up=false,west=true]"
      },
      {
        "char": "d",
        "block": "minecraft:vine[east=false,north=false,south=true,up=false,west=false]"
      },
      {
        "char": "Χ",
        "block": "minecraft:air"
      },
      {
        "char": "ͽ",
        "block": "minecraft:loom[facing=west]"
      },
      {
        "char": "v",
        "block": "minecraft:gray_stained_glass"
      },
      {
        "char": "a",
        "block": "minecraft:smooth_quartz"
      },
      {
        "char": "R",
        "block": "minecraft:stone_slab[type=bottom,waterlogged=false,weathering=false]"
      },
      {
        "char": "e",
        "block": "minecraft:polished_andesite"
      },
      {
        "char": "Q",
        "block": "minecraft:vine[east=false,north=true,south=false,up=false,west=true]"
      },
      {
        "char": "n",
        "block": "minecraft:stone[weathering=false]"
      },
      {
        "char": "2",
        "block": "minecraft:polished_andesite_slab[type=bottom,waterlogged=false]"
      },
      {
        "char": "4",
        "block": "minecraft:air"
      },
      {
        "char": "x",
        "block": "minecraft:white_concrete"
      },
      {
        "char": "ͺ",
        "block": "minecraft:air"
      },
      {
        "char": "A",
        "block": "minecraft:air"
      },
      {
        "char": "s",
        "block": "minecraft:vine[east=false,north=false,south=false,up=true,west=false]"
      },
      {
        "char": "K",
        "block": "minecraft:vine[east=false,north=true,south=false,up=true,west=false]"
      },
      {
        "char": "ѩ",
        "block": "minecraft:air"
      },
      {
        "char": "Ј",
        "block": "minecraft:air"
      }
    ]
  },
  "slices": [
    [
      " hy  cEEE HiGddE",
      "   ΧͽvvvvvaRaaaa",
      "     cccccheQc  ",
      "         ccc    ",
      "                ",
      "                ",
      "                ",
      "                ",
      "                ",
      "                ",
      "                ",
      "                ",
      "                ",
      "                ",
      "                ",
      "                "
    ],
    [
      "     caaaaaaGdda",
      "     Χiiiiinaaaa",
      "      c cch2Qc  ",
      "         ccc    ",
      "                ",
      "                ",
      "                ",
      "                ",
      "                ",
      "                ",
      "                ",
      "                ",
      "                ",
      "                ",
      "                ",
      "                "
    ],
    [
      "  4   ͽdd  addda",
      "      vvvvx2iaaa",
      "          hnQc  ",
      "         ccc    ",
      "                ",
      "                ",
      "                ",
      "                ",
      "                ",
      "                ",
      "                ",
      "                ",
      "                ",
      "                ",
      "                ",
      "                "
    ],
    [
      "  ͺ   ͽdd  add a",
      "      vvvvaeivaa",
      "          hAQc  ",
      "         ccc    ",
      "                ",
      "                ",
      "                ",
      "                ",
      "                ",
      "                ",
      "                ",
      "                ",
      "                ",
      "                ",
      "                ",
      "                "
    ],
    [
      "  4  sEEE  iEE a",
      "     aaaxaanaiii",
      "           n K  ",
      "         ccc    ",
      "                ",
      "                ",
      "                ",
      "                ",
      "                ",
      "                ",
      "                ",
      "                ",
      "                ",
      "                ",
      "                ",
      "                "
    ],
    [
      "  Raaaaaiaaiiaai",
      "   ѩeeeeeAnneeee",
      "   ЈnneneAAARenn",
      "         ccc    ",
      "                ",
      "                ",
      "                ",
      "                ",
      "                ",
      "                ",
      "                ",
      "                ",
      "                ",
      "                ",
      "                ",
      "                "
    ]
  ]
}