{
  "xsize": 16,
  "zsize": 16,
  "palette": {
    "palette": [
      {
        "char": " ",
        "block": "minecraft:air"
      },
      {
        "char": "d",
        "block": "minecraft:vine[east=false,north=false,south=true,up=false,west=false]"
      },
      {
        "char": "y",
        "block": "minecraft:oak_leaves[distance=7,persistent=true,waterlogged=false]"
      },
      {
        "char": "b",
        "block": "minecraft:bricks[weathering=false]"
      },
      {
        "char": "o",
        "block": "minecraft:air"
      },
      {
        "char": "k",
        "block": "minecraft:terracotta"
      },
      {
        "char": "l",
        "block": "minecraft:granite"
      },
      {
        "char": "ϼ",
        "block": "minecraft:air"
      },
      {
        "char": "c",
        "block": "minecraft:vine[east=false,north=true,south=false,up=false,west=false]"
      },
      {
        "char": "g",
        "block": "minecraft:vine[east=false,north=false,south=false,up=false,west=true]"
      },
      {
        "char": "h",
        "block": "minecraft:vine[east=true,north=false,south=false,up=false,west=false]"
      },
      {
        "char": "Ί",
        "block": "minecraft:rail[shape=south_east,waterlogged=false]"
      },
      {
        "char": "Ό",
        "block": "minecraft:rail[shape=south_west,waterlogged=false]"
      },
      {
        "char": "L",
        "block": "minecraft:rail[shape=north_south,waterlogged=false]"
      },
      {
        "char": "E",
        "block": "minecraft:vine[east=false,north=false,south=true,up=true,west=false]"
      },
      {
        "char": "Φ",
        "block": "minecraft:brick_slab[type=bottom,waterlogged=false,weathering=false]"
      },
      {
        "char": "K",
        "block": "minecraft:vine[east=false,north=true,south=false,up=true,west=false]"
      },
      {
        "char": "s",
        "block": "minecraft:vine[east=false,north=false,south=false,up=true,west=false]"
      },
      {
        "char": "·",
        "block": "minecraft:cobblestone_wall[east=none,north=none,south=tall,up=true,waterlogged=false,weathering=false,west=none]"
      },
      {
        "char": "F",
        "block": "minecraft:cobblestone_wall[east=none,north=tall,south=tall,up=false,waterlogged=false,weathering=false,west=none]"
      },
      {
        "char": "H",
        "block": "minecraft:vine[east=true,north=false,south=false,up=true,west=false]"
      },
      {
        "char": "ζ",
        "block": "minecraft:mossy_cobblestone_wall[east=none,north=tall,south=tall,up=false,waterlogged=false,west=none]"
      },
      {
        "char": "G",
        "block": "minecraft:vine[east=false,north=false,south=true,up=false,west=true]"
      },
      {
        "char": "u",
        "block": "minecraft:smooth_stone_slab[type=bottom,waterlogged=false]"
      },
      {
        "char": "f",
        "block": "minecraft:gray_concrete"
      },
      {
        "char": "I",
        "block": "minecraft:yellow_concrete"
      },
      {
        "char": "щ",
        "block": "minecraft:air"
      }
    ]
  },
  "slices": [
    [
      "                ",
      "                ",
      "d               ",
      " ddy  ddddy     ",
      "bokkbbbkolbyϼ   ",
      " ccc  c  g  d   ",
      "           hbg  ",
      "            bg  ",
      "            k   ",
      "            k   ",
      "      ΊΌ    bg  ",
      "      LL   hl   ",
      "      LL   hk   ",
      "      LL    b   ",
      "      LL   hl   ",
      "      LL    k   "
    ],
    [
      "                ",
      "                ",
      "d               ",
      " EEy  dddd      ",
      "lkbbbbkkkby     ",
      "  c      g      ",
      "            d   ",
      "            bg  ",
      "            b   ",
      "            b   ",
      "            k   ",
      "           hl   ",
      "           ho   ",
      "            b   ",
      "           hk   ",
      "            b   "
    ],
    [
      "                ",
      "                ",
      "d               ",
      " yyd   dd       ",
      "llokbkbooΦ      ",
      "  K      g      ",
      "                ",
      "      sss       ",
      "        sss k   ",
      "   ·     ·s b   ",
      "   F     F sl   ",
      "   F     F Hk   ",
      "   F     F Hb   ",
      "   F     F sb   ",
      "   F     FsHo   ",
      "   F     ζs l   "
    ],
    [
      "                ",
      "                ",
      "d               ",
      "yGdd   dd       ",
      "boblkbookg      ",
      "bbllbllbbg      ",
      "kbkbbbkbbkΦ     ",
      "bbbbkblkobb Φ   ",
      "bkklbkbboobkb   ",
      "kbbbbkkklbobb   ",
      "bbkbbblbbbbbk   ",
      "obbbblbbbbbol   ",
      "obbbkblkbbbkk   ",
      "lllbkblkkokol   ",
      "oolbbbblboblb   ",
      "bllbbkbbkklkb   "
    ],
    [
      "                ",
      "                ",
      "                ",
      "                ",
      "yuuuuuuuu       ",
      "                ",
      "                ",
      "                ",
      " fffff      u   ",
      "fffffff     u   ",
      "fIfffIff    u   ",
      "fIfffIff    u   ",
      "fIIIIIff    u   ",
      "fIfffIff    u   ",
      "fIfffIff    u   ",
      "fffffff щ   u   "
    ],
    [
      "                ",
      "                ",
      "                ",
      "                ",
      "                ",
      "                ",
      "                ",
      "                ",
      "                ",
      "                ",
      "                ",
      "                ",
      "                ",
      "                ",
      "                ",
      "                "
    ]
  ]
}