{
  "xsize": 16,
  "zsize": 16,
  "palette": {
    "palette": [
      {
        "char": " ",
        "block": "minecraft:structure_voiducture_void"
      },
      {
        "char": "a",
        "block": "minecraft:dirt"
      },
      {
        "char": "g",
        "block": "minecraft:smooth_stone"
      },
      {
        "char": "t",
        "block": "minecraft:air"
      },
      {
        "char": "D",
        "block": "minecraft:stone[weathering=false]"
      },
      {
        "char": "C",
        "block": "minecraft:cobblestone[weathering=false]"
      },
      {
        "char": "w",
        "block": "minecraft:stone[weathering=true]"
      },
      {
        "char": "y",
        "block": "minecraft:cobblestone[weathering=true]"
      },
      {
        "char": "i",
        "block": "minecraft:basalt[axis=y]"
      },
      {
        "char": "n",
        "block": "minecraft:polished_basalt[axis=y]"
      },
      {
        "char": "d",
        "block": "minecraft:stone_bricks[weathering=true]"
      },
      {
        "char": "k",
        "block": "minecraft:cracked_deepslate_bricks"
      },
      {
        "char": "b",
        "block": "minecraft:water[level=0]"
      },
      {
        "char": "E",
        "block": "minecraft:deepslate_bricks[weathering=false]"
      },
      {
        "char": "q",
        "block": "minecraft:deepslate_bricks[weathering=true]"
      },
      {
        "char": "Q",
        "block": "minecraft:oak_leaves[distance=7,persistent=true,waterlogged=true]"
      },
      {
        "char": "Ӯ",
        "block": "minecraft:air"
      },
      {
        "char": "х",
        "block": "minecraft:air"
      },
      {
        "char": "I",
        "block": "minecraft:kelp_plant"
      },
      {
        "char": "M",
        "block": "minecraft:seagrass"
      },
      {
        "char": "ϗ",
        "block": "minecraft:air"
      },
      {
        "char": "а",
        "block": "minecraft:air"
      },
      {
        "char": "ж",
        "block": "minecraft:air"
      },
      {
        "char": "m",
        "block": "minecraft:cracked_stone_bricks"
      },
      {
        "char": "ҿ",
        "block": "minecraft:kelp[age=3]"
      },
      {
        "char": "子",
        "block": "minecraft:kelp[age=8]"
      }
    ]
  },
  "slices": [
    [
      "aaaaaaaaaaaaaaaa",
      "aaaaaaaaaaaaaaaa",
      "aaaaaaaaaaaaaaaa",
      "aaaaaaaaaaaaaaaa",
      "aaaaaaaaaaaaaaaa",
      "aaaaaaaaaaaaaaaa",
      "aaaaaaaaaaaaaaaa",
      "aaaaaaaaaaaaaaaa",
      "aaaaaaaaaaaaaaaa",
      "aaaaaaaaaaaaaaaa",
      "aaaaaaaaaaaaaaaa",
      "aaaaaaaaaaaaaaaa",
      "aaaaaaaaaaaaaaaa",
      "aaaaaaaaaaaaaaaa",
      "aaaaaaaaaaaaaaaa",
      "aaaaaaaaaaaaaaaa"
    ],
    [
      "aaaaaaaaaaaaaaaa",
      "aaaaaaaaaaaaaaaa",
      "aaaaaaaaaaaaaaaa",
      "aaaaaaaaaaaaaaaa",
      "aaaaaaaaaaaaaaaa",
      "aaaaaaaaaaaaaaaa",
      "aaaaaaaaaaaaaaaa",
      "aaaaaaaaaaaaaaaa",
      "aaaaaaaaaaaaaaaa",
      "aaaaaaaaaaaaaaaa",
      "gtgDgtCCgCDttgDg",
      "ggwggwygtwggyggy",
      "wgwytwttggggggwy",
      "gyygygtgwttyggwg",
      "DgCggtwgtgggggCg",
      "ggywggygtgtgggyy"
    ],
    [
      "aaaaaaaaaaaaaaaa",
      "aaaaaaaaaaaaaaaa",
      "aaaaaaaaaaaaaaaa",
      "aaaaaaaaaaaaaaaa",
      "aaaaaaaaaaaaaaaa",
      "aaaaaaaaaaaaaaaa",
      "aaaaaaaaaaaaaaaa",
      "aaaaaaaaaaaaaaaa",
      "aaaaaaaaaaaaaaaa",
      "aaaaaaaaaaaaaaaa",
      "indiikdiiddinnki",
      "bbbbbbbbbbbbbbbb",
      "bbbbbbbbbbbbbbbb",
      "bbbbbbbbbbbbbbbb",
      "EnniiibqkinqkdEn",
      "QӮхIQQbMkQbӮхIbb"
    ],
    [
      "aaaaaaaaaaaaaaaa",
      "aaaaaaaaaaaaaaaa",
      "aaaaaaaaaaaaaaaa",
      "aaaaaaaaaaaaaaaa",
      "aaaaaaaaaaaaaaaa",
      "aaaaaaaaaaaaaaaa",
      "aaaaaaaaaaaaaaaa",
      "aaaaaaaaaaaaaaaa",
      "aaaaaaaaaaaaaaaa",
      "aaaaaaaaaaaaaaaa",
      "knndkdikndddkqin",
      "bbbbbbbbbbbbbbbb",
      "bbbbbbbbbbbbbbbb",
      "bbbbbbbbbbbbbbbb",
      "ikikikbEikniqidi",
      "bbϗIQbbbiQbbϗIbb"
    ],
    [
      "aaaaaaaaaaaaaaaa",
      "aaaaaaaaaaaaaaaa",
      "aaaaaaaaaaaaaaaa",
      "aaaaaaaaaaaaaaaa",
      "aaaaaaaaaaaaaaaa",
      "aaaaaaaaaaaaaaaa",
      "aaaaaaaaaaaaaaaa",
      "aaaaaaaaaaaaaaaa",
      "aaaaaaaaaaaaaaaa",
      "aaaaaaaaaaaaaaaa",
      "diEnkndnEEidkqnk",
      "bbbbbbbbbbbbbbbb",
      "bbbbbbbbbbbbbbbb",
      "bbbbbbbbbbbbbbbb",
      "Enqqiqbqqkikkkqi",
      "ϗажIbbbbkbϗажIbb"
    ],
    [
      "aaaaaaaaaaaaaaaa",
      "aaaaaaaaaaaaaaaa",
      "aaaaaaaaaaaaaaaa",
      "aaaaaaaaaaaaaaaa",
      "aaaaaaaaaaaaaaaa",
      "aaaaaaaaaaaaaaaa",
      "aaaaaaaaaaaaaaaa",
      "aaaaaaaaaaaaaaaa",
      "aaaaaaaaaaaaaaaa",
      "aaaaaaaaaaaaaaaa",
      "dniidqinniqEiimi",
      "bbbbbbbbbbbbbbbb",
      "bbbbbbbbbbbbbbbb",
      "bbbbbbbbbbbbbbbb",
      "qkinkqnkkqkqiikq",
      "bbbҿbbbbdbbbb子bb"
    ]
  ]
}