{
  "xsize": 16,
  "zsize": 16,
  "palette": {
    "palette": [
      {
        "char": " ",
        "block": "minecraft:air"
      },
      {
        "char": "F",
        "block": "minecraft:air"
      },
      {
        "char": "Σ",
        "block": "minecraft:air"
      },
      {
        "char": "ϛ",
        "block": "minecraft:air"
      },
      {
        "char": "f",
        "block": "minecraft:grass"
      },
      {
        "char": "Ϧ",
        "block": "minecraft:air"
      },
      {
        "char": "G",
        "block": "minecraft:air"
      },
      {
        "char": "Ο",
        "block": "minecraft:air"
      },
      {
        "char": "ϕ",
        "block": "minecraft:air"
      },
      {
        "char": "S",
        "block": "minecraft:air"
      },
      {
        "char": "έ",
        "block": "minecraft:air"
      },
      {
        "char": "Ρ",
        "block": "minecraft:air"
      },
      {
        "char": "Ξ",
        "block": "minecraft:air"
      },
      {
        "char": "Π",
        "block": "minecraft:air"
      },
      {
        "char": "Τ",
        "block": "minecraft:air"
      },
      {
        "char": "q",
        "block": "minecraft:air"
      },
      {
        "char": "m",
        "block": "minecraft:air"
      },
      {
        "char": "d",
        "block": "minecraft:air"
      },
      {
        "char": "k",
        "block": "minecraft:air"
      },
      {
        "char": "i",
        "block": "minecraft:air"
      },
      {
        "char": "E",
        "block": "minecraft:air"
      },
      {
        "char": "j",
        "block": "minecraft:air"
      },
      {
        "char": "l",
        "block": "minecraft:air"
      },
      {
        "char": "h",
        "block": "minecraft:air"
      },
      {
        "char": "p",
        "block": "minecraft:air"
      },
      {
        "char": "R",
        "block": "minecraft:air"
      },
      {
        "char": "р",
        "block": "minecraft:air"
      },
      {
        "char": "Ω",
        "block": "minecraft:air"
      },
      {
        "char": "Ϝ",
        "block": "minecraft:air"
      },
      {
        "char": "o",
        "block": "minecraft:air"
      },
      {
        "char": "Ӵ",
        "block": "minecraft:air"
      },
      {
        "char": "Ψ",
        "block": "minecraft:air"
      },
      {
        "char": "c",
        "block": "minecraft:air"
      },
      {
        "char": "O",
        "block": "minecraft:air"
      },
      {
        "char": "Φ",
        "block": "minecraft:air"
      },
      {
        "char": "凰",
        "block": "minecraft:air"
      },
      {
        "char": "x",
        "block": "minecraft:air"
      },
      {
        "char": "v",
        "block": "minecraft:air"
      },
      {
        "char": "ϲ",
        "block": "minecraft:air"
      },
      {
        "char": "Ϭ",
        "block": "minecraft:air"
      },
      {
        "char": "e",
        "block": "minecraft:air"
      },
      {
        "char": "D",
        "block": "minecraft:air"
      },
      {
        "char": "J",
        "block": "minecraft:air"
      },
      {
        "char": "L",
        "block": "minecraft:air"
      },
      {
        "char": "K",
        "block": "minecraft:air"
      },
      {
        "char": "C",
        "block": "minecraft:air"
      }
    ]
  },
  "slices": [
    [
      "                ",
      "              F ",
      "          ΣϛΣ  f",
      "             ΣϦG",
      "            Ο GG",
      "          ϕSϕ  F",
      "         G  έ ϕ ",
      "          ΡΞΟΞ  ",
      "          Σ ΠΤ f",
      "      f         ",
      "qmddkiiikikdEjEd",
      "                ",
      "                ",
      "                ",
      "ddjddl lddmmdmdj",
      "hhh  phhdRR  р р"
    ],
    [
      "                ",
      "               G",
      "          Ρ Ρ GG",
      "         ΡΞΩΠ FG",
      "          ΟϕΟΠ  ",
      "           Sϕ   ",
      "        fF έ ΠΩ ",
      "          Σ  Ρ F",
      "          ϛF    ",
      "                ",
      "lldjdljjdkdddddd",
      "                ",
      "                ",
      "                ",
      "mmljdd dmmddldjd",
      "hϜp  pohmpӴ     "
    ],
    [
      "                ",
      "             G f",
      "           ϦΨϛ F",
      "         Σ  ΡΨ  ",
      "          Π   G ",
      "         F έΟΠ  ",
      "         ϛ  ΠΤ Σ",
      "          ϦΣΤ   ",
      "          G Ψ   ",
      "                ",
      "dlmldjldjddmdmdm",
      "                ",
      "                ",
      "                ",
      "dljddj jddmdjdld",
      "op p p olppp  pp"
    ],
    [
      "                ",
      "                ",
      "            ϛGFG",
      "          Σ Σ  G",
      "         ΣΤ  GGF",
      "          ΠΟ  G ",
      "         ΣΡΞ Ψ  ",
      "          Ψ ΣϦ  ",
      "                ",
      "     cc         ",
      "OOmdOΦOmldOOOmdO",
      "                ",
      "                ",
      "                ",
      "lddmlddldldmddmm",
      " pp  pp m凰p   p "
    ],
    [
      "                ",
      "             f  ",
      "                ",
      "             G  ",
      "          Σ F   ",
      "           Π FF ",
      "                ",
      "                ",
      "                ",
      "ccxxxf xccccccxx",
      "djdmddmdmdmdjldm",
      "cccccccccccccccc",
      "cccccccccccccccc",
      "cccccccccccccccc",
      "dmllmmmldddmdljl",
      "ccccccccdccccccc"
    ],
    [
      "                ",
      "                ",
      "                ",
      "              GG",
      "               F",
      "                ",
      "                ",
      "                ",
      "                ",
      "f       v   f   ",
      "ϲϲϲϲϬϬϲϬdϬϲϬϬϬϬϲ",
      "eeeeDeeJDJJDLJJK",
      "eeJeeDKKLeeeeLee",
      "eKKCKeCCCJDJJeCJ",
      "eJJeJeDKeeLLeKDe",
      "eCJJJJJCeCeJeeDe"
    ]
  ]
}