{
  "xsize": 16,
  "zsize": 16,
  "palette": {
    "palette": [
      {
        "char": " ",
        "block": "minecraft:structure_voiducture_voiducture_void"
      },
      {
        "char": "a",
        "block": "minecraft:dirt"
      },
      {
        "char": "D",
        "block": "minecraft:stone[weathering=false]"
      },
      {
        "char": "t",
        "block": "minecraft:air"
      },
      {
        "char": "C",
        "block": "minecraft:cobblestone[weathering=false]"
      },
      {
        "char": "g",
        "block": "minecraft:smooth_stone"
      },
      {
        "char": "y",
        "block": "minecraft:cobblestone[weathering=true]"
      },
      {
        "char": "w",
        "block": "minecraft:stone[weathering=true]"
      },
      {
        "char": "n",
        "block": "minecraft:polished_basalt[axis=y]"
      },
      {
        "char": "E",
        "block": "minecraft:deepslate_bricks[weathering=false]"
      },
      {
        "char": "i",
        "block": "minecraft:basalt[axis=y]"
      },
      {
        "char": "d",
        "block": "minecraft:stone_bricks[weathering=true]"
      },
      {
        "char": "b",
        "block": "minecraft:water[level=0]"
      },
      {
        "char": "q",
        "block": "minecraft:deepslate_bricks[weathering=true]"
      },
      {
        "char": "k",
        "block": "minecraft:cracked_deepslate_bricks"
      },
      {
        "char": "I",
        "block": "minecraft:kelp_plant"
      },
      {
        "char": "Q",
        "block": "minecraft:oak_leaves[distance=7,persistent=true,waterlogged=true]"
      },
      {
        "char": "m",
        "block": "minecraft:cracked_stone_bricks"
      },
      {
        "char": "ҿ",
        "block": "minecraft:kelp[age=3]"
      },
      {
        "char": "à",
        "block": "minecraft:kelp[age=13]"
      }
    ]
  },
  "slices": [
    [
      "aaaaaaaaaaaaaaaa",
      "aaaaaaaaaaaaaaaa",
      "aaaaaaaaaaaaaaaa",
      "aaaaaaaaaaaaaaaa",
      "aaaaaaaaaaaaaaaa",
      "aaaaaaaaaaaaaaaa",
      "aaaaaaaaaaaaaaaa",
      "aaaaaaaaaaaaaaaa",
      "aaaaaaaaaaaaaaaa",
      "aaaaaaaaaaaaaaaa",
      "aaaaaaaaaaaaaaaa",
      "aaaaaaaaaaaaaaaa",
      "aaaaaaaaaaaaaaaa",
      "aaaaaaaaaaaaaaaa",
      "aaaaaaaaaaaaaaaa",
      "aaaaaaaaaaaaaaaa"
    ],
    [
      "aaaaaaaaaaaaaaaa",
      "aaaaaaaaaaaaaaaa",
      "aaaaaaaaaaaaaaaa",
      "aaaaaaaaaaaaaaaa",
      "aaaaaaaaaaaaaaaa",
      "aaaaaaaaaaaaaaaa",
      "aaaaaaaaaaaaaaaa",
      "aaaaaaaaaaaaaaaa",
      "aaaaaaaaaaaaaaaa",
      "aaaaaaaaaaaaaaaa",
      "DtCCggggtgCgaaaa",
      "ygwtwtyttggtaaaa",
      "gtytgwtwyggtaaaa",
      "gygwggygwwwCaaaa",
      "DwttggwygygDaaaa",
      "tgttytgggwgDaaaa"
    ],
    [
      "aaaaaaaaaaaaaaaa",
      "aaaaaaaaaaaaaaaa",
      "aaaaaaaaaaaaaaaa",
      "aaaaaaaaaaaaaaaa",
      "aaaaaaaaaaaaaaaa",
      "aaaaaaaaaaaaaaaa",
      "aaaaaaaaaaaaaaaa",
      "aaaaaaaaaaaaaaaa",
      "aaaaaaaaaaaaaaaa",
      "aaaaaaaaaaaaaaaa",
      "nEididddidEdaaaa",
      "bbbbbbbbbbbEaaaa",
      "bbbbbbbbbbbqaaaa",
      "bbbbbbbbbbbkaaaa",
      "kbEdbbbbbbbiaaaa",
      "IQIibbbbbbbqaaaa"
    ],
    [
      "aaaaaaaaaaaaaaaa",
      "aaaaaaaaaaaaaaaa",
      "aaaaaaaaaaaaaaaa",
      "aaaaaaaaaaaaaaaa",
      "aaaaaaaaaaaaaaaa",
      "aaaaaaaaaaaaaaaa",
      "aaaaaaaaaaaaaaaa",
      "aaaaaaaaaaaaaaaa",
      "aaaaaaaaaaaaaaaa",
      "aaaaaaaaaaaaaaaa",
      "kdiEddqkniikaaaa",
      "bbbbbbbbbbbdaaaa",
      "bbbbbbbbbbbiaaaa",
      "bbbbbbbbbbbqaaaa",
      "nbiibbbbbbbqaaaa",
      "IbIdbbbbbbbmaaaa"
    ],
    [
      "aaaaaaaaaaaaaaaa",
      "aaaaaaaaaaaaaaaa",
      "aaaaaaaaaaaaaaaa",
      "aaaaaaaaaaaaaaaa",
      "aaaaaaaaaaaaaaaa",
      "aaaaaaaaaaaaaaaa",
      "aaaaaaaaaaaaaaaa",
      "aaaaaaaaaaaaaaaa",
      "aaaaaaaaaaaaaaaa",
      "aaaaaaaaaaaaaaaa",
      "nkdndEikkiqkaaaa",
      "bbbbbbbbbbbdaaaa",
      "bbbbbbbbbbbkaaaa",
      "bbbbbbbbbbbiaaaa",
      "nbEibbbbbbbqaaaa",
      "ҿbInbbbbbbbiaaaa"
    ],
    [
      "aaaaaaaaaaaaaaaa",
      "aaaaaaaaaaaaaaaa",
      "aaaaaaaaaaaaaaaa",
      "aaaaaaaaaaaaaaaa",
      "aaaaaaaaaaaaaaaa",
      "aaaaaaaaaaaaaaaa",
      "aaaaaaaaaaaaaaaa",
      "aaaaaaaaaaaaaaaa",
      "aaaaaaaaaaaaaaaa",
      "aaaaaaaaaaaaaaaa",
      "EinddnkddqEiaaaa",
      "bbbbbbbbbbbkaaaa",
      "bbbbbbbbbbbnaaaa",
      "bbbbbbbbbbbdaaaa",
      "Edqibbbbbbbkaaaa",
      "bbàkbbbbbbbkaaaa"
    ]
  ]
}