{
  "xsize": 16,
  "zsize": 16,
  "palette": {
    "palette": [
      {
        "char": " ",
        "block": "minecraft:structure_void"
      },
      {
        "char": "a",
        "block": "minecraft:dirt"
      },
      {
        "char": "t",
        "block": "minecraft:air"
      },
      {
        "char": "g",
        "block": "minecraft:smooth_stone"
      },
      {
        "char": "w",
        "block": "minecraft:stone[weathering=true]"
      },
      {
        "char": "y",
        "block": "minecraft:cobblestone[weathering=true]"
      },
      {
        "char": "D",
        "block": "minecraft:stone[weathering=false]"
      },
      {
        "char": "C",
        "block": "minecraft:cobblestone[weathering=false]"
      },
      {
        "char": "b",
        "block": "minecraft:water[level=0]"
      },
      {
        "char": "q",
        "block": "minecraft:deepslate_bricks[weathering=true]"
      },
      {
        "char": "k",
        "block": "minecraft:cracked_deepslate_bricks"
      },
      {
        "char": "n",
        "block": "minecraft:polished_basalt[axis=y]"
      },
      {
        "char": "E",
        "block": "minecraft:deepslate_bricks[weathering=false]"
      },
      {
        "char": "d",
        "block": "minecraft:stone_bricks[weathering=true]"
      },
      {
        "char": "i",
        "block": "minecraft:basalt[axis=y]"
      },
      {
        "char": "l",
        "block": "minecraft:mossy_stone_bricks"
      },
      {
        "char": "m",
        "block": "minecraft:cracked_stone_bricks"
      },
      {
        "char": "e",
        "block": "minecraft:grass_block[snowy=false]"
      },
      {
        "char": "H",
        "block": "minecraft:cobbled_deepslate"
      },
      {
        "char": "z",
        "block": "minecraft:cyan_terracotta"
      },
      {
        "char": "j",
        "block": "minecraft:stone_bricks[weathering=false]"
      },
      {
        "char": "u",
        "block": "minecraft:deepslate[axis=y]"
      }
    ]
  },
  "slices": [
    [
      "aaaaaaaaaaaaaaaa",
      "aaaaaaaaaaaaaaaa",
      "aaaaaaaaaaaaaaaa",
      "aaaaaaaaaaaaaaaa",
      "aaaaaaaaaaaaaaaa",
      "aaaaaaaaaaaaaaaa",
      "aaaaaaaaaaaaaaaa",
      "aaaaaaaaaaaaaaaa",
      "aaaaaaaaaaaaaaaa",
      "aaaaaaaaaaaaaaaa",
      "aaaaaaaaaaaaaaaa",
      "aaaaaaaaaaaaaaaa",
      "aaaaaaaaaaaaaaaa",
      "aaaaaaaaaaaaaaaa",
      "aaaaaaaaaaaaaaaa",
      "aaaaaaaaaaaaaaaa"
    ],
    [
      "tgggwyyywggtaaaa",
      "yggtgggtgtgDaaaa",
      "ggCCtCggCgggaaaa",
      "aaaaaaaaaaaaaaaa",
      "aaaaaaaaaaaaaaaa",
      "aaaaaaaaaaaaaaaa",
      "aaaaaaaaaaaaaaaa",
      "aaaaaaaaaaaaaaaa",
      "aaaaaaaaaaaaaaaa",
      "aaaaaaaaaaaaaaaa",
      "aaaaaaaaaaaaaaaa",
      "aaaaaaaaaaaaaaaa",
      "aaaaaaaaaaaaaaaa",
      "aaaaaaaaaaaaaaaa",
      "aaaaaaaaaaaaaaaa",
      "aaaaaaaaaaaaaaaa"
    ],
    [
      "bbbbbbbbbbbqaaaa",
      "bbbbbbbbbbbkaaaa",
      "nEEdniqlinEiaaaa",
      "aaaaaaaaaaaaaaaa",
      "aaaaaaaaaaaaaaaa",
      "aaaaaaaaaaaaaaaa",
      "aaaaaaaaaaaaaaaa",
      "aaaaaaaaaaaaaaaa",
      "aaaaaaaaaaaaaaaa",
      "aaaaaaaaaaaaaaaa",
      "aaaaaaaaaaaaaaaa",
      "aaaaaaaaaaaaaaaa",
      "aaaaaaaaaaaaaaaa",
      "aaaaaaaaaaaaaaaa",
      "aaaaaaaaaaaaaaaa",
      "aaaaaaaaaaaaaaaa"
    ],
    [
      "bbbbbbbbbbbdaaaa",
      "bbbbbbbbbbbdaaaa",
      "kndddqmiqkdnaaaa",
      "aaaaaaaaaaaaaaaa",
      "aaaaaaaaaaaaaaaa",
      "aaaaaaaaaaaaaaaa",
      "aaaaaaaaaaaaaaaa",
      "aaaaaaaaaaaaaaaa",
      "aaaaaaaaaaaaaaaa",
      "aaaaaaaaaaaaaaaa",
      "aaaaaaaaaaaaaaaa",
      "aaaaaaaaaaaaaaaa",
      "aaaaaaaaaaaaaaaa",
      "aaaaaaaaaaaaaaaa",
      "aaaaaaaaaaaaaaaa",
      "aaaaaaaaaaaaaaaa"
    ],
    [
      "bbbbbbbbbbbkaaaa",
      "bbbbbbbbbbbkaaaa",
      "knkinkknnqEnaaaa",
      "aaaaaaaaaaaaaaaa",
      "aaaaaaaaaaaaaaaa",
      "aaaaaaaaaaaaaaaa",
      "aaaaaaaaaaaaaaaa",
      "aaaaaaaaaaaaaaaa",
      "aaaaaaaaaaaaaaaa",
      "aaaaaaaaaaaaaaaa",
      "aaaaaaaaaaaaaaaa",
      "aaaaaaaaaaaaaaaa",
      "aaaaaaaaaaaaaaaa",
      "aaaaaaaaaaaaaaaa",
      "aaaaaaaaaaaaaaaa",
      "aaaaaaaaaaaaaaaa"
    ],
    [
      "bbbbbbbbbbbdaaaa",
      "bbbbbbbbbbbiaaaa",
      "iinkqiknkdnkaaaa",
      "eeeeaaaaaaaaaaaa",
      "gggggaaaaaaaaaaa",
      "HHzHHaaaajjjjjaa",
      "uHzHzaaaajjjjjaa",
      "uuuuzaaaajjjjjaa",
      "zHHuzaaaajjjjjaa",
      "uuuzzaaaajjjjjaa",
      "HzuHzaaaajjjjjaa",
      "gggggaaaaaaaaaaa",
      "aaaaaaaaaaaaaaaa",
      "aaaaaaaaaaaaaaaa",
      "aaaaaaaaaaaaaaaa",
      "aaaaaaaaaaaaaaaa"
    ]
  ]
}