{
  "xsize": 16,
  "zsize": 16,
  "palette": {
    "palette": [
      {
        "char": " ",
        "block": "minecraft:air"
      },
      {
        "char": "k",
        "block": "minecraft:blackstone"
      },
      {
        "char": "g",
        "block": "minecraft:cyan_terracotta"
      },
      {
        "char": "j",
        "block": "minecraft:cobbled_deepslate"
      },
      {
        "char": "l",
        "block": "minecraft:basalt[axis=x]"
      },
      {
        "char": "h",
        "block": "minecraft:deepslate[axis=y]"
      },
      {
        "char": "a",
        "block": "minecraft:grass_block[snowy=false]"
      },
      {
        "char": "R",
        "block": "minecraft:polished_diorite"
      },
      {
        "char": "M",
        "block": "minecraft:diorite"
      },
      {
        "char": "m",
        "block": "minecraft:dirt"
      },
      {
        "char": "d",
        "block": "minecraft:quartz_block"
      },
      {
        "char": "ε",
        "block": "minecraft:white_concrete"
      },
      {
        "char": "c",
        "block": "minecraft:air"
      },
      {
        "char": "G",
        "block": "minecraft:air"
      },
      {
        "char": "e",
        "block": "minecraft:vine[east=false,north=false,south=true,up=false,west=false]"
      },
      {
        "char": "q",
        "block": "minecraft:vine[east=true,north=false,south=false,up=false,west=false]"
      },
      {
        "char": "s",
        "block": "minecraft:cracked_stone_bricks"
      },
      {
        "char": "f",
        "block": "minecraft:vine[east=false,north=false,south=false,up=false,west=true]"
      },
      {
        "char": "b",
        "block": "minecraft:stone_bricks[weathering=false]"
      },
      {
        "char": "i",
        "block": "minecraft:vine[east=false,north=true,south=false,up=false,west=false]"
      },
      {
        "char": "β",
        "block": "minecraft:azure_bluet"
      },
      {
        "char": "r",
        "block": "minecraft:smooth_stone_slab[type=bottom,waterlogged=false]"
      },
      {
        "char": "Φ",
        "block": "minecraft:cobblestone_slab[type=double,waterlogged=false,weathering=false]"
      },
      {
        "char": "o",
        "block": "minecraft:mossy_stone_bricks"
      },
      {
        "char": "Θ",
        "block": "minecraft:mossy_cobblestone"
      },
      {
        "char": "έ",
        "block": "minecraft:stone_brick_stairs[facing=north,half=top,shape=straight,waterlogged=false,weathering=false]"
      },
      {
        "char": "Ε",
        "block": "minecraft:stone_brick_stairs[facing=south,half=top,shape=straight,waterlogged=false,weathering=false]"
      }
    ]
  },
  "slices": [
    [
      "kgjlghgahhhjghgh",
      "RRMmRdjεhlkgggjg",
      "ddddddgεjkjjgahl",
      "aaddddjεjhhlhhha",
      "aaamddhggjjjhlkc",
      "jhGGkkgkhglhhlgg",
      "lllGddagljjkjgkk",
      "jalgaagagahhkkhj",
      "jjghddgakhajjgjg",
      "ljgkkalkghggljkj",
      "kaghddlgkllgjhhh",
      "gajaggglkglhklhg",
      "mmaaddggagghhaaa",
      "mmaaaGgkklgkggka",
      "mmaaddlggjhjkkhh",
      "glgaghjljgkljglk"
    ],
    [
      "   e  cc        ",
      "  qsf           ",
      "  q f  c        ",
      " cq f     c   cc",
      " ccbf           ",
      "   i            ",
      "                ",
      "ece cc c c c    ",
      "     f c  β     ",
      "     f          ",
      " c   f          ",
      " c ccf    c     ",
      "rr c    c    ccc",
      "Φrcccf         c",
      "rrcc f  c       ",
      "   c f          "
    ],
    [
      "   e            ",
      "  qsf           ",
      "  q f           ",
      "  q f           ",
      "  qof           ",
      "   i            ",
      "                ",
      "e e e           ",
      "     f          ",
      "     f          ",
      "     f          ",
      "     f          ",
      "                ",
      "Θf   f          ",
      "i    f          ",
      "     f          "
    ],
    [
      "   e            ",
      "  qbf           ",
      "  q f           ",
      "  q f           ",
      "  qof           ",
      "   i            ",
      "                ",
      "e e e           ",
      "     f          ",
      "     f          ",
      "     f          ",
      "     f          ",
      "                ",
      "of   f          ",
      "i    f          ",
      "     f          "
    ],
    [
      "   e            ",
      "  qbf           ",
      "  qέf           ",
      "  qΕf           ",
      "  qof           ",
      "   i            ",
      "                ",
      "e e e           ",
      "     f          ",
      "     f          ",
      "     f          ",
      "     f          ",
      "                ",
      "of   f          ",
      "i    f          ",
      "     f          "
    ],
    [
      "                ",
      "  qsf           ",
      "  qsf           ",
      "  qsf           ",
      "  qof           ",
      "   i            ",
      "                ",
      "e e e           ",
      "     f          ",
      "     f          ",
      "     f          ",
      "     f          ",
      "                ",
      "b    f          ",
      "i    f          ",
      "     f          "
    ]
  ]
}