{
  "xsize": 16,
  "zsize": 16,
  "palette": {
    "palette": [
      {
        "char": " ",
        "block": "minecraft:air"
      },
      {
        "char": "耻",
        "block": "minecraft:air"
      },
      {
        "char": "d",
        "block": "minecraft:diorite"
      },
      {
        "char": "c",
        "block": "minecraft:smooth_quartz"
      },
      {
        "char": "Q",
        "block": "minecraft:smooth_stone_slab[type=bottom,waterlogged=false]"
      },
      {
        "char": "b",
        "block": "minecraft:polished_diorite"
      },
      {
        "char": "喃",
        "block": "minecraft:cobblestone_slab[type=bottom,waterlogged=false,weathering=false]"
      },
      {
        "char": "锁",
        "block": "minecraft:stone_slab[type=bottom,waterlogged=false,weathering=false]"
      },
      {
        "char": "e",
        "block": "minecraft:quartz_block"
      },
      {
        "char": "牒",
        "block": "minecraft:air"
      },
      {
        "char": "芥",
        "block": "minecraft:air"
      },
      {
        "char": "迫",
        "block": "minecraft:air"
      },
      {
        "char": "槐",
        "block": "minecraft:air"
      },
      {
        "char": "训",
        "block": "minecraft:air"
      },
      {
        "char": "L",
        "block": "minecraft:air"
      },
      {
        "char": "禹",
        "block": "minecraft:air"
      },
      {
        "char": "噹",
        "block": "minecraft:air"
      },
      {
        "char": "i",
        "block": "minecraft:cobbled_deepslate"
      },
      {
        "char": "f",
        "block": "minecraft:basalt[axis=x]"
      },
      {
        "char": "h",
        "block": "minecraft:deepslate[axis=y]"
      },
      {
        "char": "q",
        "block": "minecraft:blackstone"
      },
      {
        "char": "a",
        "block": "minecraft:smooth_stone_slab[type=top,waterlogged=false]"
      },
      {
        "char": "g",
        "block": "minecraft:cyan_terracotta"
      },
      {
        "char": "B",
        "block": "minecraft:moss_block"
      },
      {
        "char": "G",
        "block": "minecraft:cobblestone_slab[type=double,waterlogged=false,weathering=false]"
      },
      {
        "char": "唆",
        "block": "minecraft:quartz_stairs[facing=south,half=bottom,shape=straight,waterlogged=false]"
      },
      {
        "char": "蜒",
        "block": "minecraft:quartz_stairs[facing=west,half=bottom,shape=outer_left,waterlogged=false]"
      },
      {
        "char": "嗅",
        "block": "minecraft:quartz_stairs[facing=west,half=bottom,shape=straight,waterlogged=false]"
      },
      {
        "char": "擂",
        "block": "minecraft:diorite_stairs[facing=north,half=bottom,shape=straight,waterlogged=false]"
      },
      {
        "char": "鼬",
        "block": "minecraft:diorite_stairs[facing=north,half=bottom,shape=outer_left,waterlogged=false]"
      },
      {
        "char": "珈",
        "block": "minecraft:rail[shape=south_west,waterlogged=false]"
      },
      {
        "char": "峨",
        "block": "minecraft:rail[shape=north_west,waterlogged=false]"
      }
    ]
  },
  "slices": [
    [
      "                ",
      " 耻              ",
      "                ",
      "ddc             ",
      "QQb             ",
      "QQc             ",
      "QQc             ",
      "喃锁e             ",
      "ece             ",
      "                ",
      " 耻              ",
      "     牒芥迫迫芥迫迫芥槐  ",
      "锁            训  ",
      "Q            训  ",
      "cecdddbeedd  训  ",
      "bededdceedd  训  "
    ],
    [
      "                ",
      " L              ",
      "                ",
      "cQe             ",
      "  b             ",
      "  b             ",
      "  e             ",
      "  c             ",
      "eQe             ",
      "                ",
      " 耻              ",
      "     牒芥芥芥芥芥迫芥槐  ",
      "             训  ",
      "             训  ",
      "deecdeccbbc  训  ",
      "eddbdbdddcc  禹  "
    ],
    [
      "                ",
      " 耻              ",
      " 耻              ",
      "edb             ",
      "  c             ",
      "  e             ",
      "  c             ",
      "  e             ",
      "bcc             ",
      " 噹              ",
      " 耻              ",
      "     牒芥芥芥芥芥芥芥槐  ",
      "             禹  ",
      "             禹  ",
      "cdeddeddedd  禹  ",
      "bifiiiihiqb  禹  "
    ],
    [
      "                ",
      "                ",
      "                ",
      "bac             ",
      "  e             ",
      "  d             ",
      "  d             ",
      "  d             ",
      "bad             ",
      "                ",
      "                ",
      "                ",
      "                ",
      "                ",
      "iiifhghgBhG     ",
      "G         h     "
    ],
    [
      "                ",
      "                ",
      "                ",
      "锁QQ             ",
      "唆蜒喃             ",
      "d嗅锁             ",
      "d嗅锁             ",
      "擂鼬Q             ",
      "QQQ             ",
      "                ",
      "                ",
      "                ",
      "                ",
      "                ",
      "                ",
      "                "
    ],
    [
      "                ",
      "                ",
      "                ",
      "                ",
      "                ",
      "珈               ",
      "峨               ",
      "                ",
      "                ",
      "                ",
      "                ",
      "                ",
      "                ",
      "                ",
      "                ",
      "                "
    ]
  ]
}