{
  "xsize": 16,
  "zsize": 16,
  "palette": {
    "palette": [
      {
        "char": " ",
        "block": "minecraft:air"
      },
      {
        "char": "麒",
        "block": "minecraft:vine[east=false,north=false,south=false,up=true,west=false]"
      },
      {
        "char": "b",
        "block": "minecraft:polished_diorite"
      },
      {
        "char": "e",
        "block": "minecraft:quartz_block"
      },
      {
        "char": "d",
        "block": "minecraft:diorite"
      },
      {
        "char": "l",
        "block": "minecraft:vine[east=false,north=false,south=false,up=false,west=true]"
      },
      {
        "char": "c",
        "block": "minecraft:smooth_quartz"
      },
      {
        "char": "C",
        "block": "minecraft:air"
      },
      {
        "char": "i",
        "block": "minecraft:cobbled_deepslate"
      },
      {
        "char": "h",
        "block": "minecraft:deepslate[axis=y]"
      },
      {
        "char": "q",
        "block": "minecraft:blackstone"
      },
      {
        "char": "f",
        "block": "minecraft:basalt[axis=x]"
      },
      {
        "char": "g",
        "block": "minecraft:cyan_terracotta"
      },
      {
        "char": "v",
        "block": "minecraft:red_terracotta"
      },
      {
        "char": "蕤",
        "block": "minecraft:powered_rail[powered=true,shape=ascending_west,waterlogged=false]"
      },
      {
        "char": "珈",
        "block": "minecraft:rail[shape=south_west,waterlogged=false]"
      },
      {
        "char": "獠",
        "block": "minecraft:rail[shape=ascending_south,waterlogged=false]"
      },
      {
        "char": "挹",
        "block": "minecraft:powered_rail[powered=true,shape=ascending_east,waterlogged=false]"
      },
      {
        "char": "捂",
        "block": "minecraft:lever[face=wall,facing=east,powered=true]"
      },
      {
        "char": "耻",
        "block": "minecraft:air"
      },
      {
        "char": "膝",
        "block": "minecraft:cobblestone_wall[east=none,north=none,south=none,up=true,waterlogged=false,weathering=false,west=none]"
      },
      {
        "char": "u",
        "block": "minecraft:red_concrete"
      },
      {
        "char": "M",
        "block": "minecraft:air"
      }
    ]
  },
  "slices": [
    [
      " 麒be dbl        ",
      "dee  bcl        ",
      "     cdl        ",
      "     bcl        ",
      "     ee         ",
      "     dc         ",
      "     cc         ",
      "     bc         ",
      "     dd         ",
      "     dc         ",
      "     db         ",
      "     ee         ",
      "     bb         ",
      "     cd         ",
      "     cb         ",
      "     cc         "
    ],
    [
      "bedc db         ",
      "     ddl        ",
      "     bel        ",
      "     eel        ",
      "     eb         ",
      "     bb         ",
      "     bd         ",
      "     ee         ",
      "     ec         ",
      "     bb         ",
      "     db         ",
      "     cc         ",
      "     dd         ",
      "     bd         ",
      "     ce         ",
      "     eb         "
    ],
    [
      "     ed         ",
      "      bl        ",
      "     cbl        ",
      "     ccl        ",
      "     cb         ",
      "     dc         ",
      "     cd         ",
      "     dd         ",
      "     db         ",
      "     ce         ",
      "     ee         ",
      "     bb         ",
      "     bb         ",
      "     bd         ",
      "     bd         ",
      "     dd         "
    ],
    [
      "     be         ",
      "     cd         ",
      "     dbl        ",
      "     edl        ",
      "     dc         ",
      "     bc         ",
      "     bb         ",
      "     cc         ",
      "     bd         ",
      "     ce         ",
      "     cc         ",
      "     db         ",
      "     ec         ",
      "     cd         ",
      "     bd         ",
      "     dc         "
    ],
    [
      "Ciihqce         ",
      "fhhgibb         ",
      "ggCqhec         ",
      "hhigibd         ",
      "fhhCfdc         ",
      "giqffeb         ",
      "igqghbc         ",
      "hgifhdc         ",
      "qhgqCec         ",
      "qqiifee         ",
      "iigfgec         ",
      "qqhghddv        ",
      "ghhqqee         ",
      "ghhghed         ",
      "fCfggbb         ",
      "Cqgqhdd         "
    ],
    [
      "bccc de         ",
      "蕤珈 d ec         ",
      " 獠 e bb         ",
      "挹q捂c ce         ",
      "cbde ce         ",
      "     bc         ",
      " 耻   eb         ",
      "     be         ",
      "  膝  db         ",
      "     ed         ",
      "     ccu        ",
      "     bbv        ",
      "     edv        ",
      "  膝  de         ",
      "     bd         ",
      " M   eb         "
    ]
  ]
}