{
  "xsize": 16,
  "zsize": 16,
  "palette": {
    "palette": [
      {
        "char": " ",
        "block": "minecraft:air"
      },
      {
        "char": "n",
        "block": "minecraft:vine[east=false,north=false,south=true,up=false,west=false]"
      },
      {
        "char": "p",
        "block": "minecraft:quartz_pillar[axis=y]"
      },
      {
        "char": "c",
        "block": "minecraft:smooth_quartz"
      },
      {
        "char": "b",
        "block": "minecraft:polished_diorite"
      },
      {
        "char": "歉",
        "block": "minecraft:vine[east=false,north=false,south=true,up=false,west=true]"
      },
      {
        "char": "l",
        "block": "minecraft:vine[east=false,north=false,south=false,up=false,west=true]"
      },
      {
        "char": "d",
        "block": "minecraft:diorite"
      },
      {
        "char": "e",
        "block": "minecraft:quartz_block"
      },
      {
        "char": "a",
        "block": "minecraft:smooth_stone_slab[type=top,waterlogged=false]"
      },
      {
        "char": "k",
        "block": "minecraft:stone_slab[type=top,waterlogged=false,weathering=false]"
      },
      {
        "char": "r",
        "block": "minecraft:cobblestone_slab[type=top,waterlogged=false,weathering=false]"
      },
      {
        "char": "A",
        "block": "minecraft:smooth_stone_slab[type=double,waterlogged=false]"
      },
      {
        "char": "x",
        "block": "minecraft:redstone_lamp[lit=false]"
      },
      {
        "char": "D",
        "block": "minecraft:redstone_wire[east=none,north=side,power=0,south=side,west=none]"
      },
      {
        "char": "E",
        "block": "minecraft:redstone_wire[east=side,north=none,power=0,south=none,west=side]"
      },
      {
        "char": "怨",
        "block": "minecraft:repeater[delay=1,facing=west,locked=false,powered=false]"
      },
      {
        "char": "y",
        "block": "minecraft:quartz_slab[type=top,waterlogged=false]"
      },
      {
        "char": "i",
        "block": "minecraft:cobbled_deepslate"
      },
      {
        "char": "g",
        "block": "minecraft:cyan_terracotta"
      },
      {
        "char": "B",
        "block": "minecraft:moss_block"
      },
      {
        "char": "h",
        "block": "minecraft:deepslate[axis=y]"
      },
      {
        "char": "烤",
        "block": "minecraft:oak_leaves[distance=7,persistent=true,waterlogged=false]"
      },
      {
        "char": "u",
        "block": "minecraft:red_concrete"
      },
      {
        "char": "裔",
        "block": "minecraft:vine[east=false,north=false,south=false,up=true,west=true]"
      },
      {
        "char": "w",
        "block": "minecraft:quartz_slab[type=bottom,waterlogged=false]"
      }
    ]
  },
  "slices": [
    [
      "    npcb歉l      ",
      " deeceddpl      ",
      "ceebceedbl      ",
      "dcbbcddcpl      ",
      "aaaaaacd        ",
      "kaararbel       ",
      "akaakadc        ",
      "aaaarrccl       ",
      "AaraAabdl       ",
      "araaaace        ",
      "aaararbel       ",
      "aakaaabcl       ",
      "AaaaAade        ",
      "AaaaAkecl       ",
      "araaaabel       ",
      "akkakabd        "
    ],
    [
      "    ndcp歉l      ",
      " ddeccddpl      ",
      "eecccdebdl      ",
      "dccdbceepl      ",
      "      cc        ",
      "      cel       ",
      "      ed        ",
      "      cdl       ",
      "x   x dcl       ",
      "D   D ed        ",
      "D   D cel       ",
      "D   D cd        ",
      "xEE怨x dd        ",
      "x   x bcl       ",
      "      bbl       ",
      "      ed        "
    ],
    [
      "yy  npee歉l      ",
      "yeebdbbbel      ",
      "edbeeddecl      ",
      "igBBhbbcpl      ",
      "      cc        ",
      "      cdl       ",
      "      bd        ",
      "      ccl       ",
      "      ebl       ",
      "      bc        ",
      "      bbl       ",
      "      dd        ",
      "      ec        ",
      "      ecl       ",
      "      cdl       ",
      "      de烤       "
    ],
    [
      "u   npbc歉l      ",
      "bbcecedcdl      ",
      "edbbedddel      ",
      "     debpl      ",
      "      db        ",
      "      eel       ",
      "      ce        ",
      "      bdl       ",
      "      cbl       ",
      "      be        ",
      "      del       ",
      "      be        ",
      "      ee        ",
      "      bcl       ",
      "      be裔       ",
      "      be烤       "
    ],
    [
      "dw  npdp歉l      ",
      "cdecdcbdbl      ",
      "cebbbeebdl      ",
      "     bbdpl      ",
      "      ed        ",
      "      edl       ",
      "      cc        ",
      "      ebl       ",
      "      cel       ",
      "      cc        ",
      "      ccl       ",
      "      ec        ",
      "      ec        ",
      "      cel       ",
      "      cb烤       ",
      "      bb烤       "
    ],
    [
      "    npcp歉l      ",
      "ccdbbcdepl      ",
      "cdbecebddl      ",
      "     dbdbl      ",
      "      de        ",
      "      dbl       ",
      "      ed        ",
      "      cel       ",
      "      ddl       ",
      "      cb        ",
      "      bdl       ",
      "      bc        ",
      "      db        ",
      "      del       ",
      "      bbl       ",
      "      bc烤       "
    ]
  ]
}