{
  "xsize": 16,
  "zsize": 16,
  "palette": {
    "palette": [
      {
        "char": " ",
        "block": "minecraft:air"
      },
      {
        "char": "j",
        "block": "minecraft:vine[east=true,north=false,south=false,up=false,west=false]"
      },
      {
        "char": "e",
        "block": "minecraft:quartz_block"
      },
      {
        "char": "p",
        "block": "minecraft:quartz_pillar[axis=y]"
      },
      {
        "char": "b",
        "block": "minecraft:polished_diorite"
      },
      {
        "char": "d",
        "block": "minecraft:diorite"
      },
      {
        "char": "伟",
        "block": "minecraft:vine[east=true,north=false,south=true,up=false,west=false]"
      },
      {
        "char": "y",
        "block": "minecraft:quartz_slab[type=top,waterlogged=false]"
      },
      {
        "char": "N",
        "block": "minecraft:diorite_slab[type=top,waterlogged=false]"
      },
      {
        "char": "w",
        "block": "minecraft:quartz_slab[type=bottom,waterlogged=false]"
      },
      {
        "char": "m",
        "block": "minecraft:vine[east=false,north=true,south=false,up=false,west=false]"
      },
      {
        "char": "c",
        "block": "minecraft:smooth_quartz"
      },
      {
        "char": "v",
        "block": "minecraft:red_terracotta"
      },
      {
        "char": "u",
        "block": "minecraft:red_concrete"
      },
      {
        "char": "K",
        "block": "minecraft:diorite_slab[type=bottom,waterlogged=false]"
      }
    ]
  },
  "slices": [
    [
      "            jepb",
      "            jebe",
      "             ppe",
      "              dd",
      "             伟bb",
      "            j  d",
      "              yb",
      "              Ny",
      "                ",
      "                ",
      "                ",
      "                ",
      "             jwb",
      "             伟wd",
      "            jeed",
      "             mdd"
    ],
    [
      "            jpcb",
      "            jdde",
      "             pcb",
      "              db",
      "             伟ee",
      "            j ed",
      "               b",
      "                ",
      "                ",
      "                ",
      "                ",
      "                ",
      "             jwe",
      "             伟yb",
      "            jpbc",
      "             mdd"
    ],
    [
      "            jpde",
      "            jddb",
      "             ebc",
      "              cb",
      "             伟cc",
      "            jpeb",
      "             N e",
      "               y",
      "                ",
      "                ",
      "                ",
      "                ",
      "             j v",
      "             伟eu",
      "            jbbv",
      "             mev"
    ],
    [
      "            jped",
      "            jebb",
      "             ppd",
      "              cd",
      "             伟ee",
      "            jpee",
      "              dc",
      "               c",
      "                ",
      "                ",
      "                ",
      "               b",
      "             jde",
      "             伟dd",
      "            jpbc",
      "             mbd"
    ],
    [
      "            jbpc",
      "            jebb",
      "             ppc",
      "              bc",
      "             伟bd",
      "            jpeb",
      "             wdc",
      "              dd",
      "              be",
      "              yd",
      "               b",
      "              Kb",
      "             jdd",
      "             伟db",
      "            jpcb",
      "             mbc"
    ],
    [
      "             ppb",
      "             bbd",
      "             pcd",
      "              ee",
      "             伟eb",
      "             bcd",
      "              be",
      "              de",
      "             pbc",
      "              ec",
      "               d",
      "             pdd",
      "              ee",
      "             yde",
      "            jpbc",
      "             mcc"
    ]
  ]
}