{
  "xsize": 16,
  "zsize": 16,
  "palette": {
    "palette": [
      {
        "char": " ",
        "block": "minecraft:air"
      },
      {
        "char": "E",
        "block": "minecraft:redstone_wire[east=side,north=none,power=0,south=none,west=side]"
      },
      {
        "char": "捏",
        "block": "minecraft:redstone_wire[east=none,north=side,power=0,south=none,west=side]"
      },
      {
        "char": "q",
        "block": "minecraft:blackstone"
      },
      {
        "char": "y",
        "block": "minecraft:quartz_slab[type=top,waterlogged=false]"
      },
      {
        "char": "l",
        "block": "minecraft:vine[east=false,north=false,south=false,up=false,west=true]"
      },
      {
        "char": "役",
        "block": "minecraft:dead_fire_coral_block"
      },
      {
        "char": "x",
        "block": "minecraft:redstone_lamp[lit=false]"
      },
      {
        "char": "b",
        "block": "minecraft:polished_diorite"
      },
      {
        "char": "c",
        "block": "minecraft:smooth_quartz"
      },
      {
        "char": "z",
        "block": "minecraft:clay"
      },
      {
        "char": "N",
        "block": "minecraft:diorite_slab[type=top,waterlogged=false]"
      },
      {
        "char": "d",
        "block": "minecraft:diorite"
      },
      {
        "char": "e",
        "block": "minecraft:quartz_block"
      },
      {
        "char": "h",
        "block": "minecraft:deepslate[axis=y]"
      },
      {
        "char": "J",
        "block": "minecraft:polished_blackstone"
      },
      {
        "char": "w",
        "block": "minecraft:quartz_slab[type=bottom,waterlogged=false]"
      },
      {
        "char": "f",
        "block": "minecraft:basalt[axis=x]"
      },
      {
        "char": "g",
        "block": "minecraft:cyan_terracotta"
      },
      {
        "char": "i",
        "block": "minecraft:cobbled_deepslate"
      },
      {
        "char": "K",
        "block": "minecraft:diorite_slab[type=bottom,waterlogged=false]"
      },
      {
        "char": "I",
        "block": "minecraft:black_concrete"
      },
      {
        "char": "G",
        "block": "minecraft:cobblestone_slab[type=double,waterlogged=false,weathering=false]"
      },
      {
        "char": "剖",
        "block": "minecraft:glass_pane[east=false,north=false,south=false,waterlogged=false,west=false]"
      },
      {
        "char": "a",
        "block": "minecraft:smooth_stone_slab[type=top,waterlogged=false]"
      },
      {
        "char": "r",
        "block": "minecraft:cobblestone_slab[type=top,waterlogged=false,weathering=false]"
      },
      {
        "char": "k",
        "block": "minecraft:stone_slab[type=top,waterlogged=false,weathering=false]"
      },
      {
        "char": "辽",
        "block": "minecraft:glass_pane[east=true,north=false,south=false,waterlogged=false,west=false]"
      },
      {
        "char": "暗",
        "block": "minecraft:glass_pane[east=false,north=false,south=false,waterlogged=false,west=true]"
      },
      {
        "char": "醉",
        "block": "minecraft:repeater[delay=1,facing=north,locked=false,powered=false]"
      },
      {
        "char": "逛",
        "block": "minecraft:repeater[delay=1,facing=east,locked=false,powered=false]"
      },
      {
        "char": "C",
        "block": "minecraft:air"
      }
    ]
  },
  "slices": [
    [
      "E捏 qy  l        ",
      "   役y  l        ",
      "x  bcl          ",
      "   役y           ",
      "   zy           ",
      "   cbl          ",
      "   zN           ",
      "   zy           ",
      "x  dbl          ",
      "   zy  l        ",
      "   zy  l        ",
      "   dc  l        ",
      "   zN  l        ",
      "   役y  l        ",
      "x  del          ",
      "   zy           "
    ],
    [
      "bdhJw  l        ",
      "dbfqw  l        ",
      "ebfecl          ",
      "cegJw           ",
      "ddhJw           ",
      "dcicc           ",
      "bdfqw           ",
      "cehJK           ",
      "cegedl          ",
      "dbhqw  l        ",
      "bdiqK  l        ",
      "ccgee  l        ",
      "cbfqw  l        ",
      "iihIw  l        ",
      "ggiccl          ",
      "fhGJw           "
    ],
    [
      "剖 azw  l        ",
      "aaazK  l        ",
      "raabd           ",
      "akazw           ",
      " 剖azw           ",
      "akaed           ",
      "aaagw           ",
      "aakgw           ",
      "辽暗acc           ",
      "aakzw  l        ",
      "aka役w  l        ",
      "kakde  l        ",
      "aaazw  l        ",
      "arazw  l        ",
      "cbdde           ",
      "aaa役w           "
    ],
    [
      "xx zN  l        ",
      "   zN  l        ",
      "   be           ",
      "醉  zN           ",
      "xx iy           ",
      "   ec           ",
      "   zN           ",
      "醉  zy           ",
      "xx dd           ",
      "   zy  l        ",
      "   qy  l        ",
      "逛  ec  l        ",
      "   zN  l        ",
      "   fN  l        ",
      "   dd           ",
      "   役y           "
    ],
    [
      "giqqqbcl        ",
      "ffhgqdbl        ",
      "fCigfed         ",
      "hhiifbd         ",
      "qqihfbe         ",
      "gqqgqcc         ",
      "gfqhqdb         ",
      "ifhqhbe         ",
      "gCfgfed         ",
      "iqhgfdbl        ",
      "qqgiCdcl        ",
      "qCqffdel        ",
      "fghhicbl        ",
      "qhiqgbdl        ",
      "qffChbd         ",
      "qgggqbb         "
    ],
    [
      "     dbl        ",
      "     dbl        ",
      "     bb         ",
      "     ee         ",
      "     dd         ",
      "     dd         ",
      "     ec         ",
      "     db         ",
      "     bd         ",
      "     edl        ",
      "     edl        ",
      "     dbl        ",
      "     del        ",
      "     bcl        ",
      "     bc         ",
      "     cb         "
    ]
  ]
}