{
  "xsize": 16,
  "zsize": 16,
  "palette": {
    "palette": [
      {
        "char": " ",
        "block": "minecraft:air"
      },
      {
        "char": "j",
        "block": "minecraft:vine[east=true,north=false,south=false,up=false,west=false]"
      },
      {
        "char": "y",
        "block": "minecraft:quartz_slab[type=top,waterlogged=false]"
      },
      {
        "char": "z",
        "block": "minecraft:clay"
      },
      {
        "char": "役",
        "block": "minecraft:dead_fire_coral_block"
      },
      {
        "char": "d",
        "block": "minecraft:diorite"
      },
      {
        "char": "e",
        "block": "minecraft:quartz_block"
      },
      {
        "char": "q",
        "block": "minecraft:blackstone"
      },
      {
        "char": "f",
        "block": "minecraft:basalt[axis=x]"
      },
      {
        "char": "m",
        "block": "minecraft:vine[east=false,north=true,south=false,up=false,west=false]"
      },
      {
        "char": "c",
        "block": "minecraft:smooth_quartz"
      },
      {
        "char": "N",
        "block": "minecraft:diorite_slab[type=top,waterlogged=false]"
      },
      {
        "char": "i",
        "block": "minecraft:cobbled_deepslate"
      },
      {
        "char": "w",
        "block": "minecraft:quartz_slab[type=bottom,waterlogged=false]"
      },
      {
        "char": "J",
        "block": "minecraft:polished_blackstone"
      },
      {
        "char": "I",
        "block": "minecraft:black_concrete"
      },
      {
        "char": "b",
        "block": "minecraft:polished_diorite"
      },
      {
        "char": "涨",
        "block": "minecraft:glass_pane[east=false,north=false,south=true,waterlogged=false,west=false]"
      },
      {
        "char": "繁",
        "block": "minecraft:cobblestone_wall[east=tall,north=none,south=none,up=true,waterlogged=false,weathering=false,west=none]"
      },
      {
        "char": "H",
        "block": "minecraft:glass_pane[east=false,north=true,south=true,waterlogged=false,west=false]"
      },
      {
        "char": "瀑",
        "block": "minecraft:mossy_cobblestone_wall[east=tall,north=none,south=none,up=true,waterlogged=false,west=none]"
      },
      {
        "char": "捕",
        "block": "minecraft:glass_pane[east=false,north=true,south=false,waterlogged=false,west=false]"
      },
      {
        "char": "K",
        "block": "minecraft:diorite_slab[type=bottom,waterlogged=false]"
      }
    ]
  },
  "slices": [
    [
      "           j  yz",
      "              y役",
      "              de",
      "           j  yq",
      "         j    yf",
      "          mj jce",
      "              yz",
      "              yz",
      "             jde",
      "              Nz",
      "              Nz",
      "             jec",
      "              yi",
      "              yz",
      "             jde",
      "              yz"
    ],
    [
      "           j  wJ",
      "              wI",
      "              ec",
      "           j  wI",
      "         j    wJ",
      "          mj jbc",
      "              wq",
      "              wq",
      "             jed",
      "              wI",
      "              wq",
      "             jed",
      "              wI",
      "              wJ",
      "             jcb",
      "              wI"
    ],
    [
      "           j  Nq",
      "              y ",
      "              cb",
      "           j  y ",
      "         j    NJ",
      "          mj jbc",
      "              yq",
      "              y ",
      "             jeb",
      "              N ",
      "              yq",
      "             jec",
      "              yI",
      "              y ",
      "             jbd",
      "              N "
    ],
    [
      "           j    ",
      "               涨",
      "              繁b",
      "           j   H",
      "         j     H",
      "          mj j繁b",
      "               H",
      "               H",
      "             j瀑d",
      "               捕",
      "                ",
      "             j瀑c",
      "               H",
      "               H",
      "             j瀑c",
      "                "
    ],
    [
      "           j    ",
      "               涨",
      "              繁b",
      "           j    ",
      "         j     涨",
      "          mj j瀑e",
      "               H",
      "               H",
      "             j瀑c",
      "               H",
      "               H",
      "             j瀑c",
      "                ",
      "               涨",
      "             j繁e",
      "               H"
    ],
    [
      "           j  wz",
      "              Kz",
      "              dd",
      "           j  wz",
      "         j    w役",
      "          mj jed",
      "              w役",
      "              Kz",
      "             jcc",
      "              wi",
      "              wz",
      "             jdc",
      "              Kz",
      "              Kz",
      "             jbe",
      "              Kz"
    ]
  ]
}