{
  "xsize": 16,
  "zsize": 16,
  "palette": {
    "palette": [
      {
        "char": " ",
        "block": "minecraft:air"
      },
      {
        "char": "d",
        "block": "minecraft:diorite"
      },
      {
        "char": "b",
        "block": "minecraft:polished_diorite"
      },
      {
        "char": "c",
        "block": "minecraft:smooth_quartz"
      },
      {
        "char": "e",
        "block": "minecraft:quartz_block"
      },
      {
        "char": "迫",
        "block": "minecraft:air"
      },
      {
        "char": "芥",
        "block": "minecraft:air"
      },
      {
        "char": "于",
        "block": "minecraft:air"
      },
      {
        "char": "训",
        "block": "minecraft:air"
      },
      {
        "char": "禹",
        "block": "minecraft:air"
      },
      {
        "char": "Q",
        "block": "minecraft:smooth_stone_slab[type=bottom,waterlogged=false]"
      },
      {
        "char": "锁",
        "block": "minecraft:stone_slab[type=bottom,waterlogged=false,weathering=false]"
      },
      {
        "char": "a",
        "block": "minecraft:smooth_stone_slab[type=top,waterlogged=false]"
      },
      {
        "char": "耻",
        "block": "minecraft:air"
      },
      {
        "char": "L",
        "block": "minecraft:air"
      },
      {
        "char": "M",
        "block": "minecraft:air"
      },
      {
        "char": "噹",
        "block": "minecraft:air"
      },
      {
        "char": "h",
        "block": "minecraft:deepslate[axis=y]"
      },
      {
        "char": "f",
        "block": "minecraft:basalt[axis=x]"
      },
      {
        "char": "i",
        "block": "minecraft:cobbled_deepslate"
      },
      {
        "char": "C",
        "block": "minecraft:air"
      },
      {
        "char": "g",
        "block": "minecraft:cyan_terracotta"
      },
      {
        "char": "q",
        "block": "minecraft:blackstone"
      },
      {
        "char": "滂",
        "block": "minecraft:stone_slab[type=top,waterlogged=false,weathering=true]"
      },
      {
        "char": "G",
        "block": "minecraft:cobblestone_slab[type=double,waterlogged=false,weathering=false]"
      },
      {
        "char": "p",
        "block": "minecraft:quartz_pillar[axis=y]"
      },
      {
        "char": "染",
        "block": "minecraft:mossy_cobblestone_slab[type=double,waterlogged=false]"
      },
      {
        "char": "B",
        "block": "minecraft:moss_block"
      },
      {
        "char": "稽",
        "block": "minecraft:rail[shape=south_east,waterlogged=false]"
      },
      {
        "char": "珈",
        "block": "minecraft:rail[shape=south_west,waterlogged=false]"
      },
      {
        "char": "鹃",
        "block": "minecraft:rail[shape=north_east,waterlogged=false]"
      },
      {
        "char": "峨",
        "block": "minecraft:rail[shape=north_west,waterlogged=false]"
      }
    ]
  },
  "slices": [
    [
      "dbcecbedccc迫芥于  ",
      "cbecdbedbdc  训  ",
      "cebbdbdcecd  训  ",
      "dcebdceceed  禹  ",
      "dbbbbbdedce  训  ",
      "bQb锁d锁bdabe  训  ",
      "             禹  ",
      " 耻 耻 L       训  ",
      "             训  ",
      "             禹  ",
      "             训  ",
      "             训  ",
      "             禹  ",
      "             禹  ",
      "             训  ",
      "             训  "
    ],
    [
      "cebdeeccedd芥芥于  ",
      "cdeceedebcd  训  ",
      "edddbbeddbe  禹  ",
      "bcbeccdccdd  禹  ",
      "dcdcdedebed  禹  ",
      "c耻cMd耻cebdc  禹  ",
      " L L M       禹  ",
      " 噹 耻 耻       训  ",
      "             禹  ",
      "             禹  ",
      "             禹  ",
      "             训  ",
      "             禹  ",
      "             禹  ",
      "             训  ",
      "             训  "
    ],
    [
      "dhfhihffffd  禹  ",
      "cfCgCqiqqCe  禹  ",
      "hhffCghqCfc  禹  ",
      "ghfhfCChgfc  禹  ",
      "Cgghqqhfigd  禹  ",
      "cad滂caebdcb  禹  ",
      "             禹  ",
      "             禹  ",
      "             禹  ",
      "             禹  ",
      "             禹  ",
      "             禹  ",
      "             禹  ",
      "             禹  ",
      "             禹  ",
      "             禹  "
    ],
    [
      "G  pp  cp h     ",
      "h  pd  cd f     ",
      "          f     ",
      "          染     ",
      "          B     ",
      "gfgBiffiigf     ",
      "                ",
      "                ",
      "                ",
      "                ",
      "                ",
      "                ",
      "                ",
      "                ",
      "                ",
      "                "
    ],
    [
      "   稽珈  稽珈       ",
      "   鹃峨  鹃峨       ",
      "                ",
      "                ",
      "                ",
      "                ",
      "                ",
      "                ",
      "                ",
      "                ",
      "                ",
      "                ",
      "                ",
      "                ",
      "                ",
      "                "
    ],
    [
      "                ",
      "                ",
      "                ",
      "                ",
      "                ",
      "                ",
      "                ",
      "                ",
      "                ",
      "                ",
      "                ",
      "                ",
      "                ",
      "                ",
      "                ",
      "                "
    ]
  ]
}