{
  "xsize": 16,
  "zsize": 16,
  "palette": {
    "palette": [
      {
        "char": " ",
        "block": "minecraft:air"
      },
      {
        "char": "c",
        "block": "minecraft:smooth_quartz"
      },
      {
        "char": "e",
        "block": "minecraft:quartz_block"
      },
      {
        "char": "d",
        "block": "minecraft:diorite"
      },
      {
        "char": "j",
        "block": "minecraft:vine[east=true,north=false,south=false,up=false,west=false]"
      },
      {
        "char": "b",
        "block": "minecraft:polished_diorite"
      },
      {
        "char": "m",
        "block": "minecraft:vine[east=false,north=true,south=false,up=false,west=false]"
      },
      {
        "char": "f",
        "block": "minecraft:basalt[axis=x]"
      },
      {
        "char": "i",
        "block": "minecraft:cobbled_deepslate"
      },
      {
        "char": "h",
        "block": "minecraft:deepslate[axis=y]"
      },
      {
        "char": "q",
        "block": "minecraft:blackstone"
      },
      {
        "char": "g",
        "block": "minecraft:cyan_terracotta"
      },
      {
        "char": "C",
        "block": "minecraft:air"
      }
    ]
  },
  "slices": [
    [
      "    ce          ",
      "    dd          ",
      "   jbe          ",
      "   jcc          ",
      "    dd          ",
      "    eb          ",
      "   jdc          ",
      "   jdc          ",
      "   jbcebdbebeeee",
      "   jbdeeeebdebdb",
      "         mmmmm  ",
      "                ",
      "                ",
      "                ",
      "                ",
      "                "
    ],
    [
      "    ec          ",
      "    bb          ",
      "   jbb          ",
      "   jde          ",
      "    cb          ",
      "    cb          ",
      "   jdb          ",
      "   jcd          ",
      "   jddeeeebbdeec",
      "   jebbececceced",
      "         mmmm   ",
      "                ",
      "                ",
      "                ",
      "                ",
      "                "
    ],
    [
      "    db          ",
      "    cd          ",
      "   jce          ",
      "   jdd          ",
      "    ec          ",
      "    bd          ",
      "   jbd          ",
      "   jec          ",
      "   jbdbbecbebccc",
      "   jbbbeedcbbcdb",
      "         mmmm   ",
      "                ",
      "                ",
      "                ",
      "                ",
      "                "
    ],
    [
      "    bc          ",
      "    ee          ",
      "   jde          ",
      "   jeb          ",
      "    bd          ",
      "    be          ",
      "   jcc          ",
      "   jbd          ",
      "   jebdddbbedbbb",
      "    eecbddcccbbe",
      "         mmmm   ",
      "                ",
      "                ",
      "                ",
      "                ",
      "                "
    ],
    [
      "    befifhqebcee",
      "    cbqhghfbdbce",
      "    bchfgfqbebec",
      "    eefhCfiqggih",
      "    dcCCfgggfiii",
      "    defhghhfhffg",
      "   jcdqqfCgigggg",
      "   jdcgqhCggiqgg",
      "   jdddcbebeeebe",
      "    ebbdeccebbdc",
      "         mmmm   ",
      "                ",
      "                ",
      "                ",
      "                ",
      "                "
    ],
    [
      "    dd   jb     ",
      "    be    d     ",
      "    ee    d     ",
      "    dc   jecbcce",
      "    ec    mmmmm ",
      "    ec          ",
      "   jed          ",
      "   jbc          ",
      "   jbdcbcdebbbde",
      "    cccdedcbcdcd",
      "         mm m   ",
      "                ",
      "                ",
      "                ",
      "                ",
      "                "
    ]
  ]
}