{
  "xsize": 16,
  "zsize": 16,
  "palette": {
    "palette": [
      {
        "char": " ",
        "block": "minecraft:air"
      },
      {
        "char": "b",
        "block": "minecraft:polished_diorite"
      },
      {
        "char": "e",
        "block": "minecraft:quartz_block"
      },
      {
        "char": "c",
        "block": "minecraft:smooth_quartz"
      },
      {
        "char": "d",
        "block": "minecraft:diorite"
      },
      {
        "char": "t",
        "block": "minecraft:grass_block[snowy=false]"
      },
      {
        "char": "h",
        "block": "minecraft:deepslate[axis=y]"
      },
      {
        "char": "i",
        "block": "minecraft:cobbled_deepslate"
      },
      {
        "char": "串",
        "block": "minecraft:spawner",
        "tag": {
          "SpawnData": {
            "entity": {}
          },
          "MaxNearbyEntities": "6s",
          "MinSpawnDelay": "200s",
          "z": 451,
          "x": -63,
          "MaxSpawnDelay": "800s",
          "RequiredPlayerRange": "16s",
          "SpawnCount": "4s",
          "ForgeCaps": {},
          "id": "minecraft:mob_spawner",
          "SpawnPotentials": [],
          "y": 139,
          "SpawnRange": "4s",
          "Delay": "20s"
        }
      },
      {
        "char": "q",
        "block": "minecraft:blackstone"
      },
      {
        "char": "f",
        "block": "minecraft:basalt[axis=x]"
      },
      {
        "char": "g",
        "block": "minecraft:cyan_terracotta"
      },
      {
        "char": "o",
        "block": "minecraft:dirt"
      },
      {
        "char": "s",
        "block": "minecraft:air"
      },
      {
        "char": "w",
        "block": "minecraft:quartz_slab[type=bottom,waterlogged=false]"
      },
      {
        "char": "皈",
        "block": "minecraft:quartz_slab[type=double,waterlogged=false]"
      },
      {
        "char": "K",
        "block": "minecraft:diorite_slab[type=bottom,waterlogged=false]"
      },
      {
        "char": "n",
        "block": "minecraft:vine[east=false,north=false,south=true,up=false,west=false]"
      },
      {
        "char": "p",
        "block": "minecraft:quartz_pillar[axis=y]"
      },
      {
        "char": "伟",
        "block": "minecraft:vine[east=true,north=false,south=true,up=false,west=false]"
      },
      {
        "char": "l",
        "block": "minecraft:vine[east=false,north=false,south=false,up=false,west=true]"
      },
      {
        "char": "u",
        "block": "minecraft:red_concrete"
      },
      {
        "char": "v",
        "block": "minecraft:red_terracotta"
      }
    ]
  },
  "slices": [
    [
      "bbeecdbdbdbddbdb",
      "tbbbbbdbbbbbbbec",
      "tcbbbccdbbbbbbcb",
      "hi串qftttigfhfiif",
      "q串fqitigffqqhgfg",
      "hqhqgifqqhihqght",
      "qhqgigfifqhfgiot",
      "tgiiqhgigtfiqtqi",
      "iqggfiiqqqfiitgq",
      "qghifqhifggighih",
      "hqgffthfffhifffg",
      "edboebdcbeccdebe",
      "bebbccdbbccdbcdt",
      "bbeedcbdcbecccbb",
      "oottttooottttttt",
      "oooooooooooooooo"
    ],
    [
      "                ",
      "s     wsw       ",
      "s               ",
      " 皈ws sss  ww  w ",
      " w   s s        ",
      "     s wc      s",
      "     w        ds",
      "    e    s d swd",
      "  c w       wss ",
      "       c     c  ",
      "s         bs    ",
      "w  Kw       K sd",
      "cs   nbn     nbs",
      "nn wwsnnn       ",
      "bbssssddbsssssss",
      "epdcdbdcbeccbbce"
    ],
    [
      "                ",
      "                ",
      "                ",
      "                ",
      "                ",
      "                ",
      "                ",
      "                ",
      "                ",
      "       w        ",
      "                ",
      "                ",
      "     nnn     nnn",
      "nn    nnn       ",
      "ep  n伟bdpl     n",
      "epdeedpcuedecbdd"
    ],
    [
      "                ",
      "                ",
      "                ",
      "                ",
      "                ",
      "                ",
      "                ",
      "                ",
      "                ",
      "                ",
      "                ",
      "                ",
      "     nnn     nnn",
      "nn    nnn       ",
      "cp  n伟pcbl     n",
      "cbdbebeevbcdbbcc"
    ],
    [
      "                ",
      "                ",
      "                ",
      "                ",
      "                ",
      "                ",
      "                ",
      "                ",
      "                ",
      "                ",
      "                ",
      "                ",
      "     nnn     nnn",
      "nn    nnn       ",
      "dp  n伟bccl     n",
      "epceccpddddbeedd"
    ],
    [
      "                ",
      "                ",
      "                ",
      "                ",
      "                ",
      "                ",
      "                ",
      "                ",
      "                ",
      "                ",
      "                ",
      "                ",
      "     nnn     nnn",
      "nn    nnn       ",
      "dp  n伟pcpl     n",
      "epcdbepcecbbbecd"
    ]
  ]
}