{
  "xsize": 16,
  "zsize": 16,
  "palette": {
    "palette": [
      {
        "char": " ",
        "block": "minecraft:air"
      },
      {
        "char": "y",
        "block": "minecraft:quartz_slab[type=top,waterlogged=false]"
      },
      {
        "char": "h",
        "block": "minecraft:deepslate[axis=y]"
      },
      {
        "char": "c",
        "block": "minecraft:smooth_quartz"
      },
      {
        "char": "e",
        "block": "minecraft:quartz_block"
      },
      {
        "char": "N",
        "block": "minecraft:diorite_slab[type=top,waterlogged=false]"
      },
      {
        "char": "q",
        "block": "minecraft:blackstone"
      },
      {
        "char": "g",
        "block": "minecraft:cyan_terracotta"
      },
      {
        "char": "j",
        "block": "minecraft:vine[east=true,north=false,south=false,up=false,west=false]"
      },
      {
        "char": "z",
        "block": "minecraft:clay"
      },
      {
        "char": "p",
        "block": "minecraft:quartz_pillar[axis=y]"
      },
      {
        "char": "d",
        "block": "minecraft:diorite"
      },
      {
        "char": "b",
        "block": "minecraft:polished_diorite"
      },
      {
        "char": "m",
        "block": "minecraft:vine[east=false,north=true,south=false,up=false,west=false]"
      },
      {
        "char": "w",
        "block": "minecraft:quartz_slab[type=bottom,waterlogged=false]"
      },
      {
        "char": "I",
        "block": "minecraft:black_concrete"
      },
      {
        "char": "J",
        "block": "minecraft:polished_blackstone"
      },
      {
        "char": "H",
        "block": "minecraft:glass_pane[east=false,north=true,south=true,waterlogged=false,west=false]"
      },
      {
        "char": "繁",
        "block": "minecraft:cobblestone_wall[east=tall,north=none,south=none,up=true,waterlogged=false,weathering=false,west=none]"
      },
      {
        "char": "瀑",
        "block": "minecraft:mossy_cobblestone_wall[east=tall,north=none,south=none,up=true,waterlogged=false,west=none]"
      },
      {
        "char": "沿",
        "block": "minecraft:cobblestone_wall[east=tall,north=none,south=tall,up=true,waterlogged=false,weathering=false,west=none]"
      },
      {
        "char": "羚",
        "block": "minecraft:cobblestone_wall[east=low,north=none,south=none,up=true,waterlogged=false,weathering=false,west=none]"
      },
      {
        "char": "捕",
        "block": "minecraft:glass_pane[east=false,north=true,south=false,waterlogged=false,west=false]"
      },
      {
        "char": "甬",
        "block": "minecraft:cobblestone_wall[east=low,north=none,south=low,up=true,waterlogged=false,weathering=false,west=none]"
      },
      {
        "char": "K",
        "block": "minecraft:diorite_slab[type=bottom,waterlogged=false]"
      },
      {
        "char": "埠",
        "block": "minecraft:vine[east=true,north=false,south=false,up=true,west=false]"
      }
    ]
  },
  "slices": [
    [
      "              yh",
      "              ce",
      "              Nq",
      "              yg",
      "             jee",
      "              yz",
      "              yh",
      "              cc",
      "             pec",
      "           j dbc",
      "           j dbd",
      "           j  pb",
      "           j    ",
      "            mmm ",
      "                ",
      "                "
    ],
    [
      "              wI",
      "              ee",
      "              wJ",
      "              wI",
      "             jde",
      "              wq",
      "              wJ",
      "              cd",
      "             eec",
      "           j ddc",
      "           j ebb",
      "           j  cd",
      "           j    ",
      "            mmm ",
      "                ",
      "                "
    ],
    [
      "              yJ",
      "              ce",
      "              yq",
      "              y ",
      "             jcb",
      "              y ",
      "              yJ",
      "              ce",
      "             ebe",
      "           j cdc",
      "           j ped",
      "           j  ce",
      "           j    ",
      "            mmm ",
      "                ",
      "                "
    ],
    [
      "               H",
      "              繁c",
      "               H",
      "               H",
      "             j瀑e",
      "               H",
      "               H",
      "              沿e",
      "             edb",
      "           j dcc",
      "           j pee",
      "           j  pd",
      "           j    ",
      "            mmm ",
      "                ",
      "                "
    ],
    [
      "                ",
      "              繁e",
      "               H",
      "               H",
      "             j羚b",
      "               捕",
      "                ",
      "              甬b",
      "              bb",
      "           j bec",
      "           j ped",
      "           j  pc",
      "           j    ",
      "            mmm ",
      "                ",
      "                "
    ],
    [
      "              Kg",
      "              db",
      "              wz",
      "              Kz",
      "             j埠c",
      "              wz",
      "              wz",
      "               c",
      "               b",
      "           j dcd",
      "           j cce",
      "           j  ce",
      "           j    ",
      "            mmm ",
      "                ",
      "                "
    ]
  ]
}