{
  "xsize": 16,
  "zsize": 16,
  "palette": {
    "palette": [
      {
        "char": " ",
        "block": "minecraft:air"
      },
      {
        "char": "儸",
        "block": "minecraft:diorite_stairs[facing=east,half=top,shape=straight,waterlogged=false]"
      },
      {
        "char": "b",
        "block": "minecraft:polished_diorite"
      },
      {
        "char": "d",
        "block": "minecraft:diorite"
      },
      {
        "char": "c",
        "block": "minecraft:smooth_quartz"
      },
      {
        "char": "绮",
        "block": "minecraft:oak_fence[east=false,north=false,south=false,waterlogged=false,west=false]"
      },
      {
        "char": "j",
        "block": "minecraft:vine[east=true,north=false,south=false,up=false,west=false]"
      },
      {
        "char": "m",
        "block": "minecraft:vine[east=false,north=true,south=false,up=false,west=false]"
      },
      {
        "char": "袱",
        "block": "minecraft:quartz_stairs[facing=east,half=top,shape=straight,waterlogged=false]"
      },
      {
        "char": "e",
        "block": "minecraft:quartz_block"
      },
      {
        "char": "n",
        "block": "minecraft:vine[east=false,north=false,south=true,up=false,west=false]"
      },
      {
        "char": "w",
        "block": "minecraft:quartz_slab[type=bottom,waterlogged=false]"
      },
      {
        "char": "q",
        "block": "minecraft:blackstone"
      },
      {
        "char": "J",
        "block": "minecraft:polished_blackstone"
      },
      {
        "char": "I",
        "block": "minecraft:black_concrete"
      },
      {
        "char": "K",
        "block": "minecraft:diorite_slab[type=bottom,waterlogged=false]"
      },
      {
        "char": "H",
        "block": "minecraft:glass_pane[east=false,north=true,south=true,waterlogged=false,west=false]"
      },
      {
        "char": "p",
        "block": "minecraft:quartz_pillar[axis=y]"
      },
      {
        "char": "C",
        "block": "minecraft:air"
      },
      {
        "char": "z",
        "block": "minecraft:clay"
      },
      {
        "char": "役",
        "block": "minecraft:dead_fire_coral_block"
      },
      {
        "char": "h",
        "block": "minecraft:deepslate[axis=y]"
      }
    ]
  },
  "slices": [
    [
      "            儸bdd",
      "             bbc",
      "          绮 儸cdc",
      "           j bdd",
      "         j   ccc",
      "          mj袱bcc",
      "             bec",
      "             ceb",
      "          绮 袱bed",
      "          j  bdc",
      "             edc",
      "            袱dec",
      "           n bdd",
      "          j  bdc",
      "          绮 袱cbc",
      "           n bdc"
    ],
    [
      "              wq",
      "              wJ",
      "          www ed",
      "           j  wJ",
      "         j    wI",
      "          mj jbe",
      "              wq",
      "              wJ",
      "          wwK dd",
      "          j   KI",
      "              wI",
      "              cb",
      "           n  wJ",
      "          j   wJ",
      "          KwK eb",
      "           n  wq"
    ],
    [
      "              mJ",
      "                ",
      "              be",
      "           j    ",
      "         j    nI",
      "          mj jec",
      "              mq",
      "                ",
      "           m  eb",
      "          j    I",
      "                ",
      "              cd",
      "           n   q",
      "          j    J",
      "              cd",
      "           n   J"
    ],
    [
      "              mH",
      "               H",
      "              dc",
      "           j   H",
      "         j    nH",
      "          mj jeb",
      "              mH",
      "               H",
      "           m  dd",
      "          j     ",
      "                ",
      "              pc",
      "           n   H",
      "          j    H",
      "              pd",
      "           n   H"
    ],
    [
      "              mH",
      "               H",
      "              pc",
      "           j   H",
      "         j    nH",
      "          mj jcb",
      "              mH",
      "               H",
      "           m  bd",
      "          j    H",
      "               H",
      "              pb",
      "           n   H",
      "          j    H",
      "              cd",
      "           n   H"
    ],
    [
      "               C",
      "               z",
      "              dd",
      "           j   z",
      "         j    nz",
      "          mj jdb",
      "              mz",
      "               z",
      "           m  ec",
      "          j    z",
      "               役",
      "              ec",
      "           n   h",
      "          j    h",
      "              bc",
      "           n   z"
    ]
  ]
}