{
  "xsize": 16,
  "zsize": 16,
  "palette": {
    "palette": [
      {
        "char": " ",
        "block": "minecraft:air"
      },
      {
        "char": "j",
        "block": "minecraft:vine[east=true,north=false,south=false,up=false,west=false]"
      },
      {
        "char": "b",
        "block": "minecraft:polished_diorite"
      },
      {
        "char": "d",
        "block": "minecraft:diorite"
      },
      {
        "char": "c",
        "block": "minecraft:smooth_quartz"
      },
      {
        "char": "e",
        "block": "minecraft:quartz_block"
      },
      {
        "char": "n",
        "block": "minecraft:vine[east=false,north=false,south=true,up=false,west=false]"
      },
      {
        "char": "g",
        "block": "minecraft:cyan_terracotta"
      },
      {
        "char": "C",
        "block": "minecraft:air"
      },
      {
        "char": "f",
        "block": "minecraft:basalt[axis=x]"
      },
      {
        "char": "q",
        "block": "minecraft:blackstone"
      },
      {
        "char": "i",
        "block": "minecraft:cobbled_deepslate"
      },
      {
        "char": "h",
        "block": "minecraft:deepslate[axis=y]"
      },
      {
        "char": "Q",
        "block": "minecraft:smooth_stone_slab[type=bottom,waterlogged=false]"
      },
      {
        "char": "M",
        "block": "minecraft:air"
      },
      {
        "char": "耻",
        "block": "minecraft:air"
      },
      {
        "char": "锁",
        "block": "minecraft:stone_slab[type=bottom,waterlogged=false,weathering=false]"
      },
      {
        "char": "喃",
        "block": "minecraft:cobblestone_slab[type=bottom,waterlogged=false,weathering=false]"
      },
      {
        "char": "霾",
        "block": "minecraft:lever[face=wall,facing=north,powered=true]"
      }
    ]
  },
  "slices": [
    [
      "   jbd          ",
      "   jcd          ",
      "    bb          ",
      "   jcd          ",
      "   jcc          ",
      "   jcc          ",
      "    ee          ",
      "    be          ",
      "    bb          ",
      "n  jeb          ",
      "beeced          ",
      "dededd          ",
      "                ",
      "                ",
      "                ",
      "                "
    ],
    [
      "   jdb          ",
      "   jed          ",
      "    eb          ",
      "   jec          ",
      "   jdd          ",
      "   jbd          ",
      "    ce          ",
      "    dc          ",
      "    dd          ",
      "n   dc          ",
      "dcdcdd          ",
      "cdbbce          ",
      "                ",
      "                ",
      "                ",
      "                "
    ],
    [
      "   jed          ",
      "   jbc          ",
      "    bd          ",
      "   jcc          ",
      "   jcb          ",
      "   jbb          ",
      "    ed          ",
      "    de          ",
      "    cd          ",
      "n   cb          ",
      "ccbceb          ",
      "eedbbd          ",
      "                ",
      "                ",
      "                ",
      "                "
    ],
    [
      "   jcd          ",
      "   jeb          ",
      "    ec          ",
      "    bc          ",
      "   jdd          ",
      "   jdb          ",
      "    ee          ",
      "    bd          ",
      "    db          ",
      "n   ee          ",
      "dccbed          ",
      "ddceeb          ",
      "                ",
      "                ",
      "                ",
      "                "
    ],
    [
      "   jeegggCfqCCiq",
      "   jedhqhggifChf",
      "    ebhCfCqfqChf",
      "    edqhiiiiggCq",
      "   jcdCghfgfgiqf",
      "   jbefqfCfiiiqh",
      "    ccghfhqffffC",
      "    bbqihqqqgCfg",
      "    bcgqhgqqifqi",
      "    bbfiqiiiqghq",
      "cebdcbqiiqiiqggq",
      "dbeedehhfghfhqii",
      "hhqfqqgigiCgffig",
      "ifggqgiCggfffigg",
      "CggfCiqfhhifighq",
      "gqgCfCiififCCqgq"
    ],
    [
      "   jbe e   Q    ",
      "   jbe b   Q    ",
      "    ed bebcc    ",
      "    bb  M 耻     ",
      "   jcc          ",
      "   jbd          ",
      "    ec  耻 M     ",
      "    dd ddeee    ",
      "    eb e   锁    ",
      "    cd c   喃    ",
      "ebeede bdbbc    ",
      "cbbeee  耻 M     ",
      "                ",
      "                ",
      "dddd            ",
      "  霾c            "
    ]
  ]
}