{
  "xsize": 16,
  "zsize": 16,
  "palette": {
    "palette": [
      {
        "char": " ",
        "block": "minecraft:air"
      },
      {
        "char": "b",
        "block": "minecraft:polished_diorite"
      },
      {
        "char": "d",
        "block": "minecraft:diorite"
      },
      {
        "char": "c",
        "block": "minecraft:smooth_quartz"
      },
      {
        "char": "e",
        "block": "minecraft:quartz_block"
      },
      {
        "char": "t",
        "block": "minecraft:grass_block[snowy=false]"
      },
      {
        "char": "q",
        "block": "minecraft:blackstone"
      },
      {
        "char": "g",
        "block": "minecraft:cyan_terracotta"
      },
      {
        "char": "f",
        "block": "minecraft:basalt[axis=x]"
      },
      {
        "char": "h",
        "block": "minecraft:deepslate[axis=y]"
      },
      {
        "char": "i",
        "block": "minecraft:cobbled_deepslate"
      },
      {
        "char": "锁",
        "block": "minecraft:stone_slab[type=bottom,waterlogged=false,weathering=false]"
      },
      {
        "char": "o",
        "block": "minecraft:dirt"
      },
      {
        "char": "串",
        "block": "minecraft:spawner",
        "tag": {
          "SpawnData": {
            "entity": {}
          },
          "MaxNearbyEntities": "6s",
          "MinSpawnDelay": "200s",
          "z": 451,
          "x": -63,
          "MaxSpawnDelay": "800s",
          "RequiredPlayerRange": "16s",
          "SpawnCount": "4s",
          "ForgeCaps": {},
          "id": "minecraft:mob_spawner",
          "SpawnPotentials": [],
          "y": 139,
          "SpawnRange": "4s",
          "Delay": "20s"
        }
      },
      {
        "char": "s",
        "block": "minecraft:air"
      },
      {
        "char": "w",
        "block": "minecraft:quartz_slab[type=bottom,waterlogged=false]"
      },
      {
        "char": "舱",
        "block": "minecraft:air"
      },
      {
        "char": "歛",
        "block": "minecraft:air"
      },
      {
        "char": "怯",
        "block": "minecraft:air"
      },
      {
        "char": "慵",
        "block": "minecraft:air"
      },
      {
        "char": "K",
        "block": "minecraft:diorite_slab[type=bottom,waterlogged=false]"
      },
      {
        "char": "n",
        "block": "minecraft:vine[east=false,north=false,south=true,up=false,west=false]"
      },
      {
        "char": "p",
        "block": "minecraft:quartz_pillar[axis=y]"
      },
      {
        "char": "歉",
        "block": "minecraft:vine[east=false,north=false,south=true,up=false,west=true]"
      },
      {
        "char": "l",
        "block": "minecraft:vine[east=false,north=false,south=false,up=false,west=true]"
      }
    ]
  },
  "slices": [
    [
      "bbdbcebdbbbcbced",
      "dbcbcbbcdbcdbbte",
      "ctbdctbtbetbbbbd",
      "qgfqfqqqhifftgti",
      "ttt锁锁锁ghhfggitft",
      "hf锁锁锁fftgfohfqfh",
      "qq锁qqightgghfigh",
      "iigthftiqiftittq",
      "tfqgigfqqqhtqqtg",
      "qfqiqfqifiigiffi",
      "itqhhghhiiiitfgf",
      "bbeebcebdcdbcebb",
      "cbbddbbbeddcedee",
      "etbeecbcbtd串e串bb",
      "ttttttttooottttt",
      "ttoooooooooottot"
    ],
    [
      "        s       ",
      "              s ",
      " s   s s  s s  s",
      "            s s ",
      "sss          s s",
      "       s  w     ",
      "e    s  s       ",
      "   s  s   ss ss ",
      "舱s         s  s ",
      "歛怯 b  w   ws    ",
      "慵s    s     s   ",
      "sK          w  w",
      "  s      w      ",
      " sw nnnsnnnw K s",
      "sssssssspbp歉ssss",
      "sseedceedbcplsws"
    ],
    [
      "                ",
      "                ",
      "                ",
      "                ",
      "                ",
      "                ",
      "                ",
      "                ",
      "                ",
      "                ",
      "                ",
      "                ",
      "                ",
      "    nnn nnn     ",
      "s      lpdp歉    ",
      "  bbbceceddpl   "
    ],
    [
      "                ",
      "                ",
      "                ",
      "                ",
      "                ",
      "                ",
      "                ",
      "                ",
      "                ",
      "                ",
      "                ",
      "                ",
      "                ",
      "    nnn nnn     ",
      "       lpep歉    ",
      "  dcdccbcccpl   "
    ],
    [
      "                ",
      "                ",
      "                ",
      "                ",
      "                ",
      "                ",
      "                ",
      "                ",
      "                ",
      "                ",
      "                ",
      "                ",
      "                ",
      "    nnn nnn     ",
      "       lpep歉    ",
      "   deedeccdpl   "
    ],
    [
      "                ",
      "                ",
      "                ",
      "                ",
      "                ",
      "                ",
      "                ",
      "                ",
      "                ",
      "                ",
      "                ",
      "                ",
      "                ",
      "    nnn nnn     ",
      "       lcdc歉    ",
      "  eeecececbpl   "
    ]
  ]
}