{
  "xsize": 16,
  "zsize": 16,
  "palette": {
    "palette": [
      {
        "char": " ",
        "block": "minecraft:air"
      },
      {
        "char": "j",
        "block": "minecraft:vine[east=true,north=false,south=false,up=false,west=false]"
      },
      {
        "char": "y",
        "block": "minecraft:quartz_slab[type=top,waterlogged=false]"
      },
      {
        "char": "役",
        "block": "minecraft:dead_fire_coral_block"
      },
      {
        "char": "z",
        "block": "minecraft:clay"
      },
      {
        "char": "d",
        "block": "minecraft:diorite"
      },
      {
        "char": "e",
        "block": "minecraft:quartz_block"
      },
      {
        "char": "m",
        "block": "minecraft:vine[east=false,north=true,south=false,up=false,west=false]"
      },
      {
        "char": "c",
        "block": "minecraft:smooth_quartz"
      },
      {
        "char": "b",
        "block": "minecraft:polished_diorite"
      },
      {
        "char": "N",
        "block": "minecraft:diorite_slab[type=top,waterlogged=false]"
      },
      {
        "char": "g",
        "block": "minecraft:cyan_terracotta"
      },
      {
        "char": "w",
        "block": "minecraft:quartz_slab[type=bottom,waterlogged=false]"
      },
      {
        "char": "I",
        "block": "minecraft:black_concrete"
      },
      {
        "char": "J",
        "block": "minecraft:polished_blackstone"
      },
      {
        "char": "K",
        "block": "minecraft:diorite_slab[type=bottom,waterlogged=false]"
      },
      {
        "char": "q",
        "block": "minecraft:blackstone"
      },
      {
        "char": "捕",
        "block": "minecraft:glass_pane[east=false,north=true,south=false,waterlogged=false,west=false]"
      },
      {
        "char": "繁",
        "block": "minecraft:cobblestone_wall[east=tall,north=none,south=none,up=true,waterlogged=false,weathering=false,west=none]"
      },
      {
        "char": "H",
        "block": "minecraft:glass_pane[east=false,north=true,south=true,waterlogged=false,west=false]"
      },
      {
        "char": "瀑",
        "block": "minecraft:mossy_cobblestone_wall[east=tall,north=none,south=none,up=true,waterlogged=false,west=none]"
      },
      {
        "char": "涨",
        "block": "minecraft:glass_pane[east=false,north=false,south=true,waterlogged=false,west=false]"
      }
    ]
  },
  "slices": [
    [
      "           j  y役",
      "              yz",
      "              de",
      "           j  yz",
      "         j    yz",
      "          mj jec",
      "              yz",
      "              y役",
      "             jdb",
      "              Nz",
      "              yz",
      "             jdc",
      "              y役",
      "              yg",
      "             jdc",
      "              Nz"
    ],
    [
      "           j  wI",
      "              wJ",
      "              dd",
      "           j  KJ",
      "         j    wq",
      "          mj jcc",
      "              wI",
      "              wJ",
      "             jdb",
      "              wJ",
      "              wJ",
      "             jcd",
      "              wq",
      "              wq",
      "             jbc",
      "              wJ"
    ],
    [
      "           j  yq",
      "              y ",
      "              ec",
      "           j  y ",
      "         j    yJ",
      "          mj jbc",
      "              yI",
      "              y ",
      "             jdc",
      "              y ",
      "              NI",
      "             jdd",
      "              yq",
      "              y ",
      "             jdc",
      "              N "
    ],
    [
      "           j   捕",
      "                ",
      "              繁b",
      "           j   H",
      "         j     H",
      "          mj j繁c",
      "               捕",
      "                ",
      "             j瀑c",
      "               H",
      "               H",
      "             j繁d",
      "               H",
      "               H",
      "             j繁c",
      "                "
    ],
    [
      "           j    ",
      "               涨",
      "              繁e",
      "           j   H",
      "         j     H",
      "          mj j繁c",
      "               H",
      "               H",
      "             j繁e",
      "                ",
      "               涨",
      "             j瀑d",
      "               H",
      "               H",
      "             j繁e",
      "               H"
    ],
    [
      "           j  wz",
      "              Kz",
      "              cd",
      "           j  K役",
      "         j    wz",
      "          mj jbe",
      "              wz",
      "              wz",
      "             jbc",
      "              wg",
      "              Kz",
      "             jec",
      "              wq",
      "              wz",
      "             jde",
      "              wq"
    ]
  ]
}