{
  "xsize": 16,
  "zsize": 16,
  "palette": {
    "palette": [
      {
        "char": " ",
        "block": "minecraft:air"
      },
      {
        "char": "d",
        "block": "minecraft:diorite"
      },
      {
        "char": "c",
        "block": "minecraft:smooth_quartz"
      },
      {
        "char": "e",
        "block": "minecraft:quartz_block"
      },
      {
        "char": "b",
        "block": "minecraft:polished_diorite"
      },
      {
        "char": "t",
        "block": "minecraft:grass_block[snowy=false]"
      },
      {
        "char": "g",
        "block": "minecraft:cyan_terracotta"
      },
      {
        "char": "q",
        "block": "minecraft:blackstone"
      },
      {
        "char": "串",
        "block": "minecraft:spawner",
        "tag": {
          "SpawnData": {
            "entity": {}
          },
          "MaxNearbyEntities": "6s",
          "MinSpawnDelay": "200s",
          "z": 451,
          "x": -63,
          "MaxSpawnDelay": "800s",
          "RequiredPlayerRange": "16s",
          "SpawnCount": "4s",
          "ForgeCaps": {},
          "id": "minecraft:mob_spawner",
          "SpawnPotentials": [],
          "y": 139,
          "SpawnRange": "4s",
          "Delay": "20s"
        }
      },
      {
        "char": "h",
        "block": "minecraft:deepslate[axis=y]"
      },
      {
        "char": "i",
        "block": "minecraft:cobbled_deepslate"
      },
      {
        "char": "f",
        "block": "minecraft:basalt[axis=x]"
      },
      {
        "char": "o",
        "block": "minecraft:dirt"
      },
      {
        "char": "皈",
        "block": "minecraft:quartz_slab[type=double,waterlogged=false]"
      },
      {
        "char": "s",
        "block": "minecraft:air"
      },
      {
        "char": "w",
        "block": "minecraft:quartz_slab[type=bottom,waterlogged=false]"
      },
      {
        "char": "堉",
        "block": "minecraft:air"
      },
      {
        "char": "瘀",
        "block": "minecraft:air"
      },
      {
        "char": "崧",
        "block": "minecraft:air"
      },
      {
        "char": "妃",
        "block": "minecraft:air"
      },
      {
        "char": "惕",
        "block": "minecraft:air"
      },
      {
        "char": "K",
        "block": "minecraft:diorite_slab[type=bottom,waterlogged=false]"
      },
      {
        "char": "n",
        "block": "minecraft:vine[east=false,north=false,south=true,up=false,west=false]"
      },
      {
        "char": "N",
        "block": "minecraft:diorite_slab[type=top,waterlogged=false]"
      },
      {
        "char": "暸",
        "block": "minecraft:vine[east=false,north=false,south=true,up=true,west=false]"
      }
    ]
  },
  "slices": [
    [
      "dcddeedbdebccdtd",
      "edtdbbcbcbcbebcc",
      "bctcbcbbebbebecc",
      "gtqqg串ggqhhhthgq",
      "iqfi串qqigtiggghi",
      "tfqfqqigfigtfhth",
      "httfhgfqiffgffqt",
      "gfifqiiqqqgqgtqh",
      "hgqqffghtgqhthqi",
      "qfftqfqitqfhiqhq",
      "gtfgfhqohfqqifgq",
      "bebccbcedeeeeddd",
      "串bedebcdebedebbb",
      "c串tbcbbdbcbbbc皈c",
      "串tttottotttttttt",
      "oooooooooooooooo"
    ],
    [
      " s           ss ",
      "  s             ",
      "  s    w        ",
      " s   w      s   ",
      "  wsw    s      ",
      "s       s  s  s ",
      " ss w ww  皈w  ss",
      "  s 堉        s皈 ",
      "  w瘀崧皈  s   s   ",
      "  ss妃惕  s 皈 s   ",
      " s w   K    w K ",
      "s  w            ",
      "K       Knnnw   ",
      " ws w    s      ",
      "wssswsswssssssss",
      "edccdbdbeeecbbee"
    ],
    [
      "                ",
      "                ",
      "                ",
      "                ",
      "                ",
      "                ",
      "                ",
      "                ",
      "                ",
      "                ",
      "                ",
      "                ",
      "n        nnnn   ",
      "                ",
      "nnn   nnns    n ",
      "ebecedeedddbedce"
    ],
    [
      "                ",
      "                ",
      "                ",
      "                ",
      "                ",
      "                ",
      "                ",
      "                ",
      "                ",
      "                ",
      "                ",
      "                ",
      "n        nnnn   ",
      "                ",
      "nnn   nnn     n ",
      "ceebdbecdcbeecbc"
    ],
    [
      "                ",
      "                ",
      "                ",
      "                ",
      "                ",
      "                ",
      "                ",
      "                ",
      "                ",
      "                ",
      "                ",
      "                ",
      "n        nnnn   ",
      "                ",
      "nnn w nnn     n ",
      "dbbddcddbcdbbecc"
    ],
    [
      "                ",
      "                ",
      "                ",
      "                ",
      "                ",
      "                ",
      "                ",
      "                ",
      "                ",
      "                ",
      "                ",
      "                ",
      "n        nnnn   ",
      "                ",
      "nNn    暸n     n ",
      "ccK w wdcbbcccde"
    ]
  ]
}