{
  "xsize": 16,
  "zsize": 16,
  "palette": {
    "palette": [
      {
        "char": " ",
        "block": "minecraft:air"
      },
      {
        "char": "m",
        "block": "minecraft:vine[east=false,north=true,south=false,up=false,west=false]"
      },
      {
        "char": "忐",
        "block": "minecraft:air"
      },
      {
        "char": "划",
        "block": "minecraft:air",
        "tag": {
          "z": 453,
          "x": -27,
          "ForgeCaps": {},
          "id": "refurbished_furniture:ceiling_light",
          "y": 148,
          "NodePos": "-7421701631852L",
          "Connections": [
            "L"
          ]
        }
      },
      {
        "char": "谱",
        "block": "minecraft:air",
        "tag": {
          "z": 465,
          "x": -59,
          "ForgeCaps": {},
          "id": "refurbished_furniture:ceiling_light",
          "y": 136,
          "NodePos": "-16217794604920L",
          "Connections": [
            "L"
          ]
        }
      },
      {
        "char": "法",
        "block": "minecraft:air",
        "tag": {
          "z": 483,
          "x": -73,
          "ForgeCaps": {},
          "id": "refurbished_furniture:ceiling_light",
          "y": 160,
          "NodePos": "-20066085228384L",
          "Connections": [
            "L"
          ]
        }
      },
      {
        "char": "a",
        "block": "minecraft:smooth_stone_slab[type=top,waterlogged=false]"
      },
      {
        "char": "k",
        "block": "minecraft:stone_slab[type=top,waterlogged=false,weathering=false]"
      },
      {
        "char": "A",
        "block": "minecraft:smooth_stone_slab[type=double,waterlogged=false]"
      },
      {
        "char": "r",
        "block": "minecraft:cobblestone_slab[type=top,waterlogged=false,weathering=false]"
      },
      {
        "char": "h",
        "block": "minecraft:deepslate[axis=y]"
      }
    ]
  },
  "slices": [
    [
      "mmmmmmmmm     mm",
      "                ",
      "                ",
      "                ",
      "                ",
      "                ",
      "                ",
      "                ",
      "                ",
      "                ",
      "                ",
      "                ",
      "                ",
      "                ",
      "                ",
      "                "
    ],
    [
      "  mmmmmm      mm",
      "                ",
      "                ",
      "                ",
      "                ",
      "                ",
      "                ",
      "                ",
      "                ",
      "                ",
      "                ",
      "                ",
      "                ",
      "                ",
      "                ",
      "                "
    ],
    [
      "  m  mm         ",
      "                ",
      "                ",
      "                ",
      "                ",
      "                ",
      "                ",
      "                ",
      "                ",
      "                ",
      "                ",
      "                ",
      "                ",
      "                ",
      "                ",
      "                "
    ],
    [
      "  m  mm         ",
      "                ",
      "                ",
      "                ",
      "                ",
      "                ",
      "                ",
      "                ",
      "         忐      ",
      "                ",
      "                ",
      "                ",
      "                ",
      "                ",
      "                ",
      "                "
    ],
    [
      "     mm         ",
      "划  谱谱  划划  划谱  划",
      "                ",
      "                ",
      "划  划划  谱谱  法法  谱",
      "                ",
      "                ",
      "划  划划  法法  法法  法",
      "                ",
      "                ",
      "划  划划  法法  法法  法",
      "                ",
      "                ",
      "划  划划  法法  法法  法",
      "                ",
      "                "
    ],
    [
      "akkkkakaaka kaka",
      "AaaAAaaAAaaAAakA",
      "aakaaaaaakaraakk",
      "kakkkaaaaaaaaakk",
      "AarAAaaAAarAAaaA",
      "arrkarkkaakrkraa",
      "aaakaakaaaakaaak",
      "AakAAarAAkkAAaaA",
      "aakakaaarhaaaara",
      "akarkaaakkkakaar",
      "AarAAaaAAaaAAakA",
      "raraakkakrakakra",
      "akaaaaaakrkakkaa",
      "AaaAAkaAAarAAakA",
      "aarkaaaaarrkrraa",
      "aaaaaarkakaakkaa"
    ]
  ]
}