{
  "xsize": 16,
  "zsize": 16,
  "palette": {
    "palette": [
      {
        "char": " ",
        "block": "minecraft:air"
      },
      {
        "char": "t",
        "block": "minecraft:air"
      },
      {
        "char": "o",
        "block": "minecraft:air"
      },
      {
        "char": "i",
        "block": "minecraft:air"
      },
      {
        "char": "f",
        "block": "minecraft:air"
      },
      {
        "char": "h",
        "block": "minecraft:air"
      },
      {
        "char": "g",
        "block": "minecraft:air"
      },
      {
        "char": "q",
        "block": "minecraft:air"
      },
      {
        "char": "s",
        "block": "minecraft:grass"
      },
      {
        "char": "胡",
        "block": "minecraft:air"
      },
      {
        "char": "c",
        "block": "minecraft:air"
      },
      {
        "char": "b",
        "block": "minecraft:air"
      },
      {
        "char": "d",
        "block": "minecraft:air"
      },
      {
        "char": "e",
        "block": "minecraft:air"
      },
      {
        "char": "j",
        "block": "minecraft:air"
      },
      {
        "char": "p",
        "block": "minecraft:air"
      },
      {
        "char": "俎",
        "block": "minecraft:air"
      },
      {
        "char": "淅",
        "block": "minecraft:air"
      },
      {
        "char": "瓣",
        "block": "minecraft:air"
      },
      {
        "char": "恁",
        "block": "minecraft:air"
      },
      {
        "char": "劲",
        "block": "minecraft:air"
      },
      {
        "char": "床",
        "block": "minecraft:air"
      },
      {
        "char": "m",
        "block": "minecraft:air"
      },
      {
        "char": "嘹",
        "block": "minecraft:air"
      },
      {
        "char": "箍",
        "block": "minecraft:air"
      },
      {
        "char": "袅",
        "block": "minecraft:air"
      },
      {
        "char": "竺",
        "block": "minecraft:air"
      },
      {
        "char": "狩",
        "block": "minecraft:air"
      },
      {
        "char": "擂",
        "block": "minecraft:air"
      },
      {
        "char": "K",
        "block": "minecraft:air"
      },
      {
        "char": "谟",
        "block": "minecraft:air"
      },
      {
        "char": "蒙",
        "block": "minecraft:air"
      },
      {
        "char": "伟",
        "block": "minecraft:air"
      },
      {
        "char": "巡",
        "block": "minecraft:air"
      },
      {
        "char": "调",
        "block": "minecraft:air"
      }
    ]
  },
  "slices": [
    [
      "ttttttttttttoooo",
      "ttttttttttttoooo",
      "ttttttttttttoooo",
      "tttttttttttttooo",
      "tttttttttttttooo",
      "tttttttttttttooo",
      "tttttttttttttooo",
      "tttttttttttttooo",
      "tttttttttotttooo",
      "tttttttttttttttt",
      "tttttttttttttttt",
      "ifhihgggtgiqhqfg",
      "ififqffigiithiif",
      "ghiitqggqitfqfht",
      "qfqqgtgihhqhghhf",
      "ghhgqqgfqfhgggqf"
    ],
    [
      "ssss胡胡sssssscbdb",
      "ssssssssssssdecc",
      "ssssssssssssdcdd",
      "ssssssssssssjebb",
      "ssssssssssssjcpc",
      "ssssssssssssjcbd",
      "ssssssss胡胡s胡jbee",
      "ssssssss胡ssssbed",
      "sssssss俎淅瓣s胡sbbe",
      "sssssss胡sss胡ssss",
      "ssssssssss胡胡ssss",
      "        s       ",
      "           s    ",
      "    ss s  s    s",
      "     s          ",
      "s           s   "
    ],
    [
      "   恁劲床劲恁    cdee",
      "            decc",
      "            cbce",
      "             eeb",
      "            jpdd",
      "            jcde",
      "            jdpb",
      "             cbd",
      "         瓣   cdp",
      "               m",
      "                ",
      "                ",
      "                ",
      "                ",
      "                ",
      "                "
    ],
    [
      "   恁劲床劲恁    嘹箍cc",
      "            袅竺be",
      "            狩擂bb",
      "             Kbc",
      "            jped",
      "            jbeb",
      "            jppc",
      "             袅dp",
      "         瓣   谟蒙p",
      "               m",
      "                ",
      "                ",
      "                ",
      "                ",
      "                ",
      "                "
    ],
    [
      "             伟db",
      "            jpec",
      "             mde",
      "              cd",
      "            jppd",
      "            jdee",
      "        劲床劲 jppb",
      "       劲床巡床劲 调ed",
      "       床巡瓣巡床  调p",
      "       劲床巡床劲   m",
      "       恁劲床劲     ",
      "                ",
      "                ",
      "                ",
      "                ",
      "                "
    ],
    [
      "             伟cb",
      "            jbcd",
      "             mec",
      "              cd",
      "            jbec",
      "            jcee",
      "       恁劲床劲恁jdpd",
      "       劲床巡床劲 调pe",
      "       床巡瓣巡床  调p",
      "       劲床巡床劲   m",
      "        劲床劲恁    ",
      "                ",
      "                ",
      "                ",
      "                ",
      "                "
    ]
  ]
}