{
  "xsize": 16,
  "zsize": 16,
  "palette": {
    "palette": [
      {
        "char": " ",
        "block": "minecraft:air"
      },
      {
        "char": "y",
        "block": "minecraft:quartz_slab[type=top,waterlogged=false]"
      },
      {
        "char": "z",
        "block": "minecraft:clay"
      },
      {
        "char": "b",
        "block": "minecraft:polished_diorite"
      },
      {
        "char": "N",
        "block": "minecraft:diorite_slab[type=top,waterlogged=false]"
      },
      {
        "char": "j",
        "block": "minecraft:vine[east=true,north=false,south=false,up=false,west=false]"
      },
      {
        "char": "e",
        "block": "minecraft:quartz_block"
      },
      {
        "char": "d",
        "block": "minecraft:diorite"
      },
      {
        "char": "役",
        "block": "minecraft:dead_fire_coral_block"
      },
      {
        "char": "h",
        "block": "minecraft:deepslate[axis=y]"
      },
      {
        "char": "c",
        "block": "minecraft:smooth_quartz"
      },
      {
        "char": "p",
        "block": "minecraft:quartz_pillar[axis=y]"
      },
      {
        "char": "m",
        "block": "minecraft:vine[east=false,north=true,south=false,up=false,west=false]"
      },
      {
        "char": "w",
        "block": "minecraft:quartz_slab[type=bottom,waterlogged=false]"
      },
      {
        "char": "I",
        "block": "minecraft:black_concrete"
      },
      {
        "char": "q",
        "block": "minecraft:blackstone"
      },
      {
        "char": "J",
        "block": "minecraft:polished_blackstone"
      },
      {
        "char": "H",
        "block": "minecraft:glass_pane[east=false,north=true,south=true,waterlogged=false,west=false]"
      },
      {
        "char": "繁",
        "block": "minecraft:cobblestone_wall[east=tall,north=none,south=none,up=true,waterlogged=false,weathering=false,west=none]"
      },
      {
        "char": "瀑",
        "block": "minecraft:mossy_cobblestone_wall[east=tall,north=none,south=none,up=true,waterlogged=false,west=none]"
      },
      {
        "char": "沿",
        "block": "minecraft:cobblestone_wall[east=tall,north=none,south=tall,up=true,waterlogged=false,weathering=false,west=none]"
      },
      {
        "char": "涨",
        "block": "minecraft:glass_pane[east=false,north=false,south=true,waterlogged=false,west=false]"
      },
      {
        "char": "K",
        "block": "minecraft:diorite_slab[type=bottom,waterlogged=false]"
      }
    ]
  },
  "slices": [
    [
      "              yz",
      "              bb",
      "              Nz",
      "              yz",
      "             jed",
      "              y役",
      "              yh",
      "              dc",
      "             pde",
      "           j dbe",
      "           j cec",
      "           j  bb",
      "           j    ",
      "            mmm ",
      "                ",
      "                "
    ],
    [
      "              wI",
      "              ee",
      "              wI",
      "              wq",
      "             jbd",
      "              wI",
      "              wJ",
      "              ec",
      "             ccc",
      "           j cbe",
      "           j pcb",
      "           j  pd",
      "           j    ",
      "            mmm ",
      "                ",
      "                "
    ],
    [
      "              yJ",
      "              ce",
      "              yI",
      "              y ",
      "             jbc",
      "              y ",
      "              yJ",
      "              bd",
      "             edc",
      "           j ccd",
      "           j peb",
      "           j  pe",
      "           j    ",
      "            mmm ",
      "                ",
      "                "
    ],
    [
      "               H",
      "              繁d",
      "               H",
      "               H",
      "             j瀑b",
      "               H",
      "               H",
      "              沿e",
      "             pce",
      "           j ded",
      "           j pde",
      "           j  pe",
      "           j    ",
      "            mmm ",
      "                ",
      "                "
    ],
    [
      "               H",
      "              繁c",
      "               H",
      "               H",
      "             j瀑d",
      "                ",
      "               涨",
      "              沿d",
      "             cee",
      "           j cbb",
      "           j pcd",
      "           j  pe",
      "           j    ",
      "            mmm ",
      "                ",
      "                "
    ],
    [
      "              K役",
      "              dc",
      "              K役",
      "              wz",
      "             jcc",
      "              wz",
      "              K役",
      "              cc",
      "             bcc",
      "           j dbb",
      "           j pee",
      "           j  pd",
      "           j    ",
      "            mmm ",
      "                ",
      "                "
    ]
  ]
}