{
  "xsize": 16,
  "zsize": 16,
  "palette": {
    "palette": [
      {
        "char": " ",
        "block": "minecraft:air"
      },
      {
        "char": "d",
        "block": "minecraft:air"
      },
      {
        "char": "c",
        "block": "minecraft:air"
      },
      {
        "char": "e",
        "block": "minecraft:air"
      },
      {
        "char": "b",
        "block": "minecraft:air"
      },
      {
        "char": "t",
        "block": "minecraft:air"
      },
      {
        "char": "g",
        "block": "minecraft:air"
      },
      {
        "char": "q",
        "block": "minecraft:air"
      },
      {
        "char": "串",
        "block": "minecraft:air",
        "tag": {
          "SpawnData": {
            "entity": {}
          },
          "MaxNearbyEntities": "6s",
          "MinSpawnDelay": "200s",
          "z": 451,
          "x": -63,
          "MaxSpawnDelay": "800s",
          "RequiredPlayerRange": "16s",
          "SpawnCount": "4s",
          "ForgeCaps": {},
          "id": "minecraft:mob_spawner",
          "SpawnPotentials": [],
          "y": 139,
          "SpawnRange": "4s",
          "Delay": "20s"
        }
      },
      {
        "char": "h",
        "block": "minecraft:air"
      },
      {
        "char": "i",
        "block": "minecraft:air"
      },
      {
        "char": "f",
        "block": "minecraft:air"
      },
      {
        "char": "o",
        "block": "minecraft:air"
      },
      {
        "char": "皈",
        "block": "minecraft:air"
      },
      {
        "char": "s",
        "block": "minecraft:grass"
      },
      {
        "char": "w",
        "block": "minecraft:air"
      },
      {
        "char": "堉",
        "block": "minecraft:air"
      },
      {
        "char": "瘀",
        "block": "minecraft:air"
      },
      {
        "char": "崧",
        "block": "minecraft:air"
      },
      {
        "char": "妃",
        "block": "minecraft:air"
      },
      {
        "char": "惕",
        "block": "minecraft:air"
      },
      {
        "char": "K",
        "block": "minecraft:air"
      },
      {
        "char": "n",
        "block": "minecraft:air"
      },
      {
        "char": "N",
        "block": "minecraft:air"
      },
      {
        "char": "暸",
        "block": "minecraft:air"
      }
    ]
  },
  "slices": [
    [
      "dcddeedbdebccdtd",
      "edtdbbcbcbcbebcc",
      "bctcbcbbebbebecc",
      "gtqqg串ggqhhhthgq",
      "iqfi串qqigtiggghi",
      "tfqfqqigfigtfhth",
      "httfhgfqiffgffqt",
      "gfifqiiqqqgqgtqh",
      "hgqqffghtgqhthqi",
      "qfftqfqitqfhiqhq",
      "gtfgfhqohfqqifgq",
      "bebccbcedeeeeddd",
      "串bedebcdebedebbb",
      "c串tbcbbdbcbbbc皈c",
      "串tttottotttttttt",
      "oooooooooooooooo"
    ],
    [
      " s           ss ",
      "  s             ",
      "  s    w        ",
      " s   w      s   ",
      "  wsw    s      ",
      "s       s  s  s ",
      " ss w ww  皈w  ss",
      "  s 堉        s皈 ",
      "  w瘀崧皈  s   s   ",
      "  ss妃惕  s 皈 s   ",
      " s w   K    w K ",
      "s  w            ",
      "K       Knnnw   ",
      " ws w    s      ",
      "wssswsswssssssss",
      "edccdbdbeeecbbee"
    ],
    [
      "                ",
      "                ",
      "                ",
      "                ",
      "                ",
      "                ",
      "                ",
      "                ",
      "                ",
      "                ",
      "                ",
      "                ",
      "n        nnnn   ",
      "                ",
      "nnn   nnns    n ",
      "ebecedeedddbedce"
    ],
    [
      "                ",
      "                ",
      "                ",
      "                ",
      "                ",
      "                ",
      "                ",
      "                ",
      "                ",
      "                ",
      "                ",
      "                ",
      "n        nnnn   ",
      "                ",
      "nnn   nnn     n ",
      "ceebdbecdcbeecbc"
    ],
    [
      "                ",
      "                ",
      "                ",
      "                ",
      "                ",
      "                ",
      "                ",
      "                ",
      "                ",
      "                ",
      "                ",
      "                ",
      "n        nnnn   ",
      "                ",
      "nnn w nnn     n ",
      "dbbddcddbcdbbecc"
    ],
    [
      "                ",
      "                ",
      "                ",
      "                ",
      "                ",
      "                ",
      "                ",
      "                ",
      "                ",
      "                ",
      "                ",
      "                ",
      "n        nnnn   ",
      "                ",
      "nNn    暸n     n ",
      "ccK w wdcbbcccde"
    ]
  ]
}