{
  "xsize": 16,
  "zsize": 16,
  "palette": {
    "palette": [
      {
        "char": " ",
        "block": "minecraft:air"
      },
      {
        "char": "j",
        "block": "minecraft:vine[east=true,north=false,south=false,up=false,west=false]"
      },
      {
        "char": "y",
        "block": "minecraft:quartz_slab[type=top,waterlogged=false]"
      },
      {
        "char": "z",
        "block": "minecraft:clay"
      },
      {
        "char": "N",
        "block": "minecraft:diorite_slab[type=top,waterlogged=false]"
      },
      {
        "char": "f",
        "block": "minecraft:basalt[axis=x]"
      },
      {
        "char": "b",
        "block": "minecraft:polished_diorite"
      },
      {
        "char": "d",
        "block": "minecraft:diorite"
      },
      {
        "char": "h",
        "block": "minecraft:deepslate[axis=y]"
      },
      {
        "char": "m",
        "block": "minecraft:vine[east=false,north=true,south=false,up=false,west=false]"
      },
      {
        "char": "c",
        "block": "minecraft:smooth_quartz"
      },
      {
        "char": "g",
        "block": "minecraft:cyan_terracotta"
      },
      {
        "char": "e",
        "block": "minecraft:quartz_block"
      },
      {
        "char": "役",
        "block": "minecraft:dead_fire_coral_block"
      },
      {
        "char": "w",
        "block": "minecraft:quartz_slab[type=bottom,waterlogged=false]"
      },
      {
        "char": "I",
        "block": "minecraft:black_concrete"
      },
      {
        "char": "K",
        "block": "minecraft:diorite_slab[type=bottom,waterlogged=false]"
      },
      {
        "char": "J",
        "block": "minecraft:polished_blackstone"
      },
      {
        "char": "q",
        "block": "minecraft:blackstone"
      },
      {
        "char": "H",
        "block": "minecraft:glass_pane[east=false,north=true,south=true,waterlogged=false,west=false]"
      },
      {
        "char": "繁",
        "block": "minecraft:cobblestone_wall[east=tall,north=none,south=none,up=true,waterlogged=false,weathering=false,west=none]"
      },
      {
        "char": "捕",
        "block": "minecraft:glass_pane[east=false,north=true,south=false,waterlogged=false,west=false]"
      },
      {
        "char": "瀑",
        "block": "minecraft:mossy_cobblestone_wall[east=tall,north=none,south=none,up=true,waterlogged=false,west=none]"
      },
      {
        "char": "涨",
        "block": "minecraft:glass_pane[east=false,north=false,south=true,waterlogged=false,west=false]"
      }
    ]
  },
  "slices": [
    [
      "           j  yz",
      "              Nf",
      "              bd",
      "           j  yz",
      "         j    yh",
      "          mj jcd",
      "              yf",
      "              yz",
      "             jcc",
      "              yg",
      "              Nz",
      "             jec",
      "              yh",
      "              N役",
      "             jdb",
      "              yz"
    ],
    [
      "           j  wI",
      "              KJ",
      "              db",
      "           j  wI",
      "         j    KJ",
      "          mj jcb",
      "              wI",
      "              wJ",
      "             jcb",
      "              wJ",
      "              wJ",
      "             jdd",
      "              KI",
      "              wq",
      "             jde",
      "              wq"
    ],
    [
      "           j  yI",
      "              y ",
      "              ee",
      "           j  N ",
      "         j    yI",
      "          mj jbc",
      "              yJ",
      "              y ",
      "             jdc",
      "              y ",
      "              yJ",
      "             jed",
      "              NI",
      "              y ",
      "             jec",
      "              y "
    ],
    [
      "           j   H",
      "               H",
      "              繁c",
      "           j   捕",
      "         j      ",
      "          mj j瀑e",
      "               H",
      "               H",
      "             j繁e",
      "               H",
      "               H",
      "             j繁b",
      "                ",
      "               涨",
      "             j繁d",
      "               H"
    ],
    [
      "           j   H",
      "               H",
      "              繁b",
      "           j   H",
      "         j     H",
      "          mj j瀑c",
      "                ",
      "               涨",
      "             j瀑e",
      "               H",
      "               H",
      "             j繁e",
      "               H",
      "               H",
      "             j瀑c",
      "               H"
    ],
    [
      "           j  Kz",
      "              wz",
      "              ce",
      "           j  Kz",
      "         j    Kz",
      "          mj jbc",
      "              wz",
      "              Kz",
      "             jeb",
      "              wz",
      "              K役",
      "             jcc",
      "              wz",
      "              wz",
      "             jce",
      "              K役"
    ]
  ]
}