{
  "xsize": 16,
  "zsize": 16,
  "palette": {
    "palette": [
      {
        "char": " ",
        "block": "minecraft:air"
      },
      {
        "char": "t",
        "block": "minecraft:grass_block[snowy=false]"
      },
      {
        "char": "o",
        "block": "minecraft:dirt"
      },
      {
        "char": "i",
        "block": "minecraft:cobbled_deepslate"
      },
      {
        "char": "q",
        "block": "minecraft:blackstone"
      },
      {
        "char": "f",
        "block": "minecraft:basalt[axis=x]"
      },
      {
        "char": "g",
        "block": "minecraft:cyan_terracotta"
      },
      {
        "char": "h",
        "block": "minecraft:deepslate[axis=y]"
      },
      {
        "char": "s",
        "block": "minecraft:air"
      },
      {
        "char": "m",
        "block": "minecraft:vine[east=false,north=true,south=false,up=false,west=false]"
      },
      {
        "char": "e",
        "block": "minecraft:quartz_block"
      },
      {
        "char": "b",
        "block": "minecraft:polished_diorite"
      },
      {
        "char": "p",
        "block": "minecraft:quartz_pillar[axis=y]"
      },
      {
        "char": "捻",
        "block": "minecraft:air"
      },
      {
        "char": "d",
        "block": "minecraft:diorite"
      },
      {
        "char": "窿",
        "block": "minecraft:air"
      },
      {
        "char": "c",
        "block": "minecraft:smooth_quartz"
      }
    ]
  },
  "slices": [
    [
      "tttttoootttiqfiq",
      "tttttttttttigiqi",
      "ttttttttttthfiqq",
      "ttttttttttthffqf",
      "tttttttttttfgfhi",
      "tttttttttttfqiii",
      "ttttttttttthqigq",
      "ttttttttttthhggg",
      "tttttttttttigfqf",
      "ttttttttttttifii",
      "tttttttttttiihhq",
      "ffigftigqqfghggf",
      "fgfhqqttghfgqihg",
      "igqitiqqqiigqiig",
      "hhhihgiggffiiihq",
      "hqiiihggfgfigftf"
    ],
    [
      "smsssebpsss     ",
      "sssssmmmsss     ",
      "sssssssssss    s",
      "sssssssssss     ",
      "sssssssssss     ",
      "sssssssssss     ",
      "sssssssssss     ",
      "sssssssss捻s     ",
      "sssssssssss     ",
      "ssssssssssss    ",
      "sssssssss捻s     ",
      "     s          ",
      "      sss      s",
      "    s           ",
      "       s        ",
      "              s "
    ],
    [
      " m   pdp        ",
      "     mmm        ",
      "                ",
      "                ",
      "                ",
      "                ",
      "                ",
      "         窿      ",
      "                ",
      "                ",
      "         窿      ",
      "                ",
      "                ",
      "                ",
      "                ",
      "                "
    ],
    [
      " m   pcp        ",
      "     mmm        ",
      "                ",
      "                ",
      "                ",
      "                ",
      "                ",
      "                ",
      "                ",
      "                ",
      "                ",
      "                ",
      "                ",
      "                ",
      "                ",
      "                "
    ],
    [
      " m   bbb        ",
      "     mmm        ",
      "                ",
      "                ",
      "                ",
      "                ",
      "                ",
      "                ",
      "                ",
      "                ",
      "                ",
      "                ",
      "                ",
      "                ",
      "                ",
      "                "
    ],
    [
      " m   pde        ",
      "     mmm        ",
      "                ",
      "                ",
      "                ",
      "                ",
      "                ",
      "                ",
      "                ",
      "                ",
      "                ",
      "                ",
      "                ",
      "                ",
      "                ",
      "                "
    ]
  ]
}