{
  "xsize": 16,
  "zsize": 16,
  "palette": {
    "palette": [
      {
        "char": " ",
        "block": "minecraft:air"
      },
      {
        "char": "t",
        "block": "minecraft:air"
      },
      {
        "char": "b",
        "block": "minecraft:air"
      },
      {
        "char": "d",
        "block": "minecraft:air"
      },
      {
        "char": "莉",
        "block": "minecraft:air"
      },
      {
        "char": "c",
        "block": "minecraft:air"
      },
      {
        "char": "o",
        "block": "minecraft:air"
      },
      {
        "char": "e",
        "block": "minecraft:air"
      },
      {
        "char": "s",
        "block": "minecraft:grass"
      },
      {
        "char": "庇",
        "block": "minecraft:air"
      },
      {
        "char": "袅",
        "block": "minecraft:air"
      },
      {
        "char": "胡",
        "block": "minecraft:air"
      },
      {
        "char": "j",
        "block": "minecraft:air"
      },
      {
        "char": "瓣",
        "block": "minecraft:air"
      },
      {
        "char": "俎",
        "block": "minecraft:air"
      },
      {
        "char": "蒙",
        "block": "minecraft:air"
      },
      {
        "char": "w",
        "block": "minecraft:air"
      },
      {
        "char": "箍",
        "block": "minecraft:air"
      },
      {
        "char": "K",
        "block": "minecraft:air"
      },
      {
        "char": "p",
        "block": "minecraft:air"
      },
      {
        "char": "调",
        "block": "minecraft:air"
      },
      {
        "char": "H",
        "block": "minecraft:air"
      },
      {
        "char": "n",
        "block": "minecraft:air"
      },
      {
        "char": "l",
        "block": "minecraft:air"
      },
      {
        "char": "嘹",
        "block": "minecraft:air"
      },
      {
        "char": "唆",
        "block": "minecraft:air"
      },
      {
        "char": "狩",
        "block": "minecraft:air"
      },
      {
        "char": "擂",
        "block": "minecraft:air"
      },
      {
        "char": "y",
        "block": "minecraft:air"
      },
      {
        "char": "甕",
        "block": "minecraft:air"
      },
      {
        "char": "竺",
        "block": "minecraft:air"
      },
      {
        "char": "麒",
        "block": "minecraft:air"
      },
      {
        "char": "劲",
        "block": "minecraft:air"
      },
      {
        "char": "床",
        "block": "minecraft:air"
      },
      {
        "char": "涨",
        "block": "minecraft:air"
      },
      {
        "char": "巡",
        "block": "minecraft:air"
      },
      {
        "char": "m",
        "block": "minecraft:air"
      },
      {
        "char": "N",
        "block": "minecraft:air"
      },
      {
        "char": "袱",
        "block": "minecraft:air"
      },
      {
        "char": "儸",
        "block": "minecraft:air"
      },
      {
        "char": "恁",
        "block": "minecraft:air"
      },
      {
        "char": "佯",
        "block": "minecraft:air"
      },
      {
        "char": "椎",
        "block": "minecraft:air"
      }
    ]
  },
  "slices": [
    [
      "tttttttttbdbb莉莉莉",
      "tttttttttbbbd莉莉莉",
      "tttttttttccdd莉莉莉",
      "tttttttttdbbc莉莉莉",
      "tttotttttbbcb莉莉莉",
      "tttttttttbceb莉莉莉",
      "tttttttotbbcd莉莉莉",
      "tttttttttecdd莉莉莉",
      "ttttottttdbbb莉莉莉",
      "tttttttttebbb莉莉莉",
      "ottttttttcccb莉莉莉",
      "tttotttttcbcb莉莉莉",
      "tttttttottbbe莉莉莉",
      "tttttttttctee莉莉莉",
      "totttotttdbeb莉莉莉",
      "ttttttttteecb莉莉莉"
    ],
    [
      "sssssssss 庇eecce",
      "sssssssss 袅edebb",
      "sss胡胡ssssjdeccce",
      "s胡ss胡ssssjcdbdbc",
      "s胡s瓣俎胡sssjdb蒙蒙ec",
      "s胡sss胡sss www箍bd",
      "s胡s胡s胡scs wKwdcd",
      "sssssssss www蒙dd",
      "ssssbssss dddpdb",
      "sssssssss beccbe",
      "wssssssss ecbpbc",
      "sssKsssss  jjdbc",
      "sssssssdss jjccc",
      "sssssssss ss调ebb",
      "swsssKsss   scdd",
      "sssssssssw   bcb"
    ],
    [
      "               H",
      "               H",
      "          w箍  nH",
      "          wdljbc",
      "   瓣      K蒙 jdc",
      "             nde",
      "             ccc",
      "              ce",
      "          嘹唆唆pdc",
      "          庇ceded",
      "          狩蒙擂pbe",
      "           jjcbd",
      "           j ed ",
      "            调cbd",
      "             cbc",
      "             cc "
    ],
    [
      "               H",
      "               H",
      "           n  nH",
      "          jpljcd",
      "   瓣         jbe",
      "             ncb",
      "             pdd",
      "              dc",
      "             cee",
      "          yd甕edb",
      "           jjeed",
      "           jjwdb",
      "           j 唆bc",
      "            调cce",
      "             cdb",
      "             竺be"
    ],
    [
      "               麒",
      "               麒",
      "  劲床劲      n   涨",
      " 劲床巡床劲    jeljec",
      " 床巡瓣巡床        be",
      " 劲床巡床劲       nee",
      "  劲床劲        eed",
      "              cb",
      "             eed",
      "         wwwjbbb",
      "           jjpbd",
      "           jj调cb",
      "           j  db",
      "            mpdb",
      "             袅ec",
      "             pbe"
    ],
    [
      "           N  袱d",
      "           y  儸d",
      " 恁劲床劲      佯  袱b",
      " 劲床巡床劲    j竺yybd",
      " 床巡瓣巡床     椎  cd",
      " 劲床巡床劲       nbb",
      " 恁劲床劲恁       bce",
      "              de",
      "             pcc",
      "            jddd",
      "           jjpcb",
      "           jj调bc",
      "           j  cd",
      "            mpdd",
      "              bd",
      "             dcc"
    ]
  ]
}