{
  "xsize": 16,
  "zsize": 16,
  "palette": {
    "palette": [
      {
        "char": " ",
        "block": "minecraft:air"
      },
      {
        "char": "c",
        "block": "minecraft:smooth_quartz"
      },
      {
        "char": "b",
        "block": "minecraft:polished_diorite"
      },
      {
        "char": "j",
        "block": "minecraft:vine[east=true,north=false,south=false,up=false,west=false]"
      },
      {
        "char": "d",
        "block": "minecraft:diorite"
      },
      {
        "char": "e",
        "block": "minecraft:quartz_block"
      },
      {
        "char": "g",
        "block": "minecraft:cyan_terracotta"
      },
      {
        "char": "q",
        "block": "minecraft:blackstone"
      },
      {
        "char": "f",
        "block": "minecraft:basalt[axis=x]"
      },
      {
        "char": "C",
        "block": "minecraft:air"
      },
      {
        "char": "h",
        "block": "minecraft:deepslate[axis=y]"
      },
      {
        "char": "i",
        "block": "minecraft:cobbled_deepslate"
      }
    ]
  },
  "slices": [
    [
      "    cb          ",
      "   jde          ",
      "    ed          ",
      "   jce          ",
      "   jee          ",
      "   jde          ",
      "   jde          ",
      "    bb          ",
      "    dd          ",
      "    de          ",
      "   jbd          ",
      "   jbb          ",
      "   jdc          ",
      "   jdb          ",
      "   jcd          ",
      "   jcd          "
    ],
    [
      "    ed          ",
      "   jbc          ",
      "    db          ",
      "   jbc          ",
      "   jbb          ",
      "   jce          ",
      "   jcd          ",
      "    cb          ",
      "    ec          ",
      "    ec          ",
      "   jbe          ",
      "   jde          ",
      "   jdb          ",
      "    bc          ",
      "   jbc          ",
      "   jbb          "
    ],
    [
      "    de          ",
      "    ec          ",
      "    db          ",
      "   jcd          ",
      "   jdd          ",
      "   jee          ",
      "   jcb          ",
      "    ed          ",
      "    bc          ",
      "    eb          ",
      "   jec          ",
      "   jbd          ",
      "   jed          ",
      "    ec          ",
      "   jbd          ",
      "    cb          "
    ],
    [
      "    ec          ",
      "    be          ",
      "    db          ",
      "   jeb          ",
      "   jdc          ",
      "   jbc          ",
      "   jcb          ",
      "    ee          ",
      "    db          ",
      "    eb          ",
      "   jcc          ",
      "   jbe          ",
      "   jbd          ",
      "    cd          ",
      "   jdb          ",
      "    bb          "
    ],
    [
      "    degqgqfddeee",
      "    dbqChffedccc",
      "    dcqiifhcddbe",
      "    deqhqhqccecd",
      "   jbbhCqghdedbe",
      "   jdcqhhgieeecc",
      "   jbehhfiCeeced",
      "    edChCCbeddeb",
      "    edgfgCCbdede",
      "    cdghifhdebcd",
      "   jdegiCChbccec",
      "   jedfhfChedecb",
      "   jdcqigCCcbcbc",
      "    edihgChbeceb",
      "   jbbqqffqcceeb",
      "    begfCfhbbdcb"
    ],
    [
      "    ee   jd     ",
      "    bd    e     ",
      "    bb    c     ",
      "    cc    c     ",
      "    cb    c     ",
      "    de    bdbcc ",
      "    dc    c   b ",
      "    cc   je   c ",
      "    cb   je   c ",
      "    bc   jbbdbd ",
      "    bb   je     ",
      "   jbd   jc     ",
      "   jbb   jc     ",
      "    de   jd     ",
      "   jec   je     ",
      "    bd   jc     "
    ]
  ]
}