{
  "xsize": 16,
  "zsize": 16,
  "palette": {
    "palette": [
      {
        "char": " ",
        "block": "minecraft:air"
      },
      {
        "char": "y",
        "block": "minecraft:quartz_slab[type=top,waterlogged=false]"
      },
      {
        "char": "h",
        "block": "minecraft:deepslate[axis=y]"
      },
      {
        "char": "c",
        "block": "minecraft:smooth_quartz"
      },
      {
        "char": "d",
        "block": "minecraft:diorite"
      },
      {
        "char": "g",
        "block": "minecraft:cyan_terracotta"
      },
      {
        "char": "z",
        "block": "minecraft:clay"
      },
      {
        "char": "j",
        "block": "minecraft:vine[east=true,north=false,south=false,up=false,west=false]"
      },
      {
        "char": "b",
        "block": "minecraft:polished_diorite"
      },
      {
        "char": "役",
        "block": "minecraft:dead_fire_coral_block"
      },
      {
        "char": "N",
        "block": "minecraft:diorite_slab[type=top,waterlogged=false]"
      },
      {
        "char": "e",
        "block": "minecraft:quartz_block"
      },
      {
        "char": "p",
        "block": "minecraft:quartz_pillar[axis=y]"
      },
      {
        "char": "m",
        "block": "minecraft:vine[east=false,north=true,south=false,up=false,west=false]"
      },
      {
        "char": "w",
        "block": "minecraft:quartz_slab[type=bottom,waterlogged=false]"
      },
      {
        "char": "q",
        "block": "minecraft:blackstone"
      },
      {
        "char": "J",
        "block": "minecraft:polished_blackstone"
      },
      {
        "char": "I",
        "block": "minecraft:black_concrete"
      },
      {
        "char": "K",
        "block": "minecraft:diorite_slab[type=bottom,waterlogged=false]"
      },
      {
        "char": "f",
        "block": "minecraft:basalt[axis=x]"
      },
      {
        "char": "麒",
        "block": "minecraft:vine[east=false,north=false,south=false,up=true,west=false]"
      },
      {
        "char": "埠",
        "block": "minecraft:vine[east=true,north=false,south=false,up=true,west=false]"
      },
      {
        "char": "i",
        "block": "minecraft:cobbled_deepslate"
      },
      {
        "char": "C",
        "block": "minecraft:air"
      }
    ]
  },
  "slices": [
    [
      "              yh",
      "              cd",
      "              yg",
      "              yz",
      "             jbd",
      "              y役",
      "              Nz",
      "              be",
      "             dec",
      "           j ecb",
      "           j pdd",
      "           j  ce",
      "           j    ",
      "            mmm ",
      "                ",
      "                "
    ],
    [
      "              wq",
      "              dc",
      "              wJ",
      "              wI",
      "             jcb",
      "              wI",
      "              wq",
      "              bb",
      "             bdb",
      "           j ecc",
      "           j cdb",
      "           j  be",
      "           j    ",
      "            mmm ",
      "                ",
      "                "
    ],
    [
      "              w役",
      "              ce",
      "              Kf",
      "              wz",
      "             jed",
      "              wz",
      "              Kz",
      "              bd",
      "             pdc",
      "           j ecb",
      "           j pbd",
      "           j  bd",
      "           j    ",
      "            mmm ",
      "                ",
      "                "
    ],
    [
      "              yz",
      "              be",
      "              y役",
      "            麒麒yz",
      "            麒埠be",
      "              yz",
      "              yz",
      "              dd",
      "             bce",
      "           j cdd",
      "           j ped",
      "           j  pe",
      "           j    ",
      "            mmm ",
      "                ",
      "                "
    ],
    [
      "            cdii",
      "            eeqf",
      "            cbgq",
      "            dbii",
      "            cbgh",
      "            ecqq",
      "            edgh",
      "            edhC",
      "            edfq",
      "           jcbfC",
      "           jedff",
      "           jcccb",
      "           jbcde",
      "            mmm ",
      "                ",
      "                "
    ],
    [
      "            dc  ",
      "            dc  ",
      "            ee  ",
      "            cd  ",
      "            de  ",
      "          麒 be  ",
      "            cd  ",
      "            ec  ",
      "            ed  ",
      "           jcc  ",
      "           jeb  ",
      "           jdbcd",
      "           jedec",
      "            mmm ",
      "                ",
      "                "
    ]
  ]
}