{
  "xsize": 16,
  "zsize": 16,
  "palette": {
    "palette": [
      {
        "char": " ",
        "block": "minecraft:air"
      },
      {
        "char": "c",
        "block": "minecraft:smooth_quartz"
      },
      {
        "char": "g",
        "block": "minecraft:cyan_terracotta"
      },
      {
        "char": "h",
        "block": "minecraft:deepslate[axis=y]"
      },
      {
        "char": "b",
        "block": "minecraft:polished_diorite"
      },
      {
        "char": "d",
        "block": "minecraft:diorite"
      },
      {
        "char": "e",
        "block": "minecraft:quartz_block"
      },
      {
        "char": "m",
        "block": "minecraft:vine[east=false,north=true,south=false,up=false,west=false]"
      },
      {
        "char": "u",
        "block": "minecraft:red_concrete"
      },
      {
        "char": "Q",
        "block": "minecraft:smooth_stone_slab[type=bottom,waterlogged=false]"
      },
      {
        "char": "f",
        "block": "minecraft:basalt[axis=x]"
      },
      {
        "char": "C",
        "block": "minecraft:air"
      },
      {
        "char": "q",
        "block": "minecraft:blackstone"
      },
      {
        "char": "i",
        "block": "minecraft:cobbled_deepslate"
      }
    ]
  },
  "slices": [
    [
      "      c  g h h  ",
      "      c         ",
      "      b         ",
      "cbccdcdccdcecbde",
      "  mmmmm   mmmmmm",
      "                ",
      "                ",
      "                ",
      "                ",
      "                ",
      "     u          ",
      "                ",
      "                ",
      "                ",
      "                ",
      "                "
    ],
    [
      "      c  Q Q Q  ",
      "      c         ",
      "      b         ",
      "eebeeccbdecbecee",
      "  mmmmm   mmmmmm",
      "                ",
      "                ",
      "                ",
      "                ",
      "                ",
      "                ",
      "                ",
      "                ",
      "                ",
      "                ",
      "                "
    ],
    [
      "cdebbeeedbebdbbb",
      "dbcbcbcdcbcecdcc",
      "eebdebcdebcbeeeb",
      "beccebebcdddcebb",
      "  mmmmm     mmmm",
      "                ",
      "                ",
      "                ",
      "                ",
      "                ",
      "                ",
      "                ",
      "                ",
      "                ",
      "                ",
      "                "
    ],
    [
      "fChggqfqhiqgggff",
      "hCiqqfCqfffChfif",
      "hqgCgggfghiCiffh",
      "eddddcbcdccbdded",
      "  mmmm       mmm",
      "                ",
      "                ",
      "                ",
      "                ",
      "                ",
      "                ",
      "                ",
      "                ",
      "                ",
      "                ",
      "                "
    ],
    [
      "                ",
      "                ",
      "                ",
      "ebeedcbcdcebddcc",
      "  mmmm          ",
      "                ",
      "                ",
      "                ",
      "                ",
      "                ",
      "                ",
      "                ",
      "                ",
      "                ",
      "                ",
      "                "
    ],
    [
      "                ",
      "                ",
      "                ",
      "                ",
      "                ",
      "                ",
      "                ",
      "                ",
      "                ",
      "                ",
      "                ",
      "                ",
      "                ",
      "                ",
      "                ",
      "                "
    ]
  ]
}