{
  "xsize": 16,
  "zsize": 16,
  "palette": {
    "palette": [
      {
        "char": " ",
        "block": "minecraft:air"
      },
      {
        "char": "x",
        "block": "minecraft:redstone_lamp[lit=false]"
      },
      {
        "char": "b",
        "block": "minecraft:polished_diorite"
      },
      {
        "char": "z",
        "block": "minecraft:clay"
      },
      {
        "char": "y",
        "block": "minecraft:quartz_slab[type=top,waterlogged=false]"
      },
      {
        "char": "醉",
        "block": "minecraft:repeater[delay=1,facing=north,locked=false,powered=false]"
      },
      {
        "char": "c",
        "block": "minecraft:smooth_quartz"
      },
      {
        "char": "N",
        "block": "minecraft:diorite_slab[type=top,waterlogged=false]"
      },
      {
        "char": "l",
        "block": "minecraft:vine[east=false,north=false,south=false,up=false,west=true]"
      },
      {
        "char": "i",
        "block": "minecraft:cobbled_deepslate"
      },
      {
        "char": "e",
        "block": "minecraft:quartz_block"
      },
      {
        "char": "d",
        "block": "minecraft:diorite"
      },
      {
        "char": "g",
        "block": "minecraft:cyan_terracotta"
      },
      {
        "char": "f",
        "block": "minecraft:basalt[axis=x]"
      },
      {
        "char": "h",
        "block": "minecraft:deepslate[axis=y]"
      },
      {
        "char": "q",
        "block": "minecraft:blackstone"
      },
      {
        "char": "C",
        "block": "minecraft:air"
      },
      {
        "char": "蒙",
        "block": "minecraft:vine[east=false,north=true,south=true,up=false,west=false]"
      },
      {
        "char": "m",
        "block": "minecraft:vine[east=false,north=true,south=false,up=false,west=false]"
      },
      {
        "char": "n",
        "block": "minecraft:vine[east=false,north=false,south=true,up=false,west=false]"
      },
      {
        "char": "刍",
        "block": "minecraft:stone_button[face=floor,facing=north,powered=false]"
      },
      {
        "char": "Q",
        "block": "minecraft:smooth_stone_slab[type=bottom,waterlogged=false]"
      },
      {
        "char": "埵",
        "block": "minecraft:stone_button[face=floor,facing=west,powered=false]"
      },
      {
        "char": "w",
        "block": "minecraft:quartz_slab[type=bottom,waterlogged=false]"
      }
    ]
  },
  "slices": [
    [
      "x        bb     ",
      "         zy     ",
      "         zy     ",
      "     醉   bc     ",
      "x    x   zN     ",
      "         zN     ",
      "         cc     ",
      "         zy l   ",
      "x        iy l   ",
      "         ed l   ",
      "         zN l   ",
      "         zy     ",
      "x        ee     ",
      "     x   zN     ",
      "         zN     ",
      "         be     "
    ],
    [
      "gffhqfCfgfgd    ",
      "ChqhCgqqhqhe    ",
      "hhCihqgihqfb    ",
      "qfifCqiqqqfe    ",
      "gqhfhfiiCigb    ",
      "fiqhiffqqqCc    ",
      "iifhqhggfhqd    ",
      "figCffffqigbl   ",
      "qCfgqhCqgggel   ",
      "qqffgifgqqgcl   ",
      "fqgifhqfhqgcl   ",
      "hgiigfgfiChc    ",
      "hhCifgCCfqqe    ",
      "hiqffggiiqie    ",
      "iCihqCiggCfc    ",
      "hfgihqihihgb    "
    ],
    [
      "蒙          c    ",
      " l         b    ",
      " l         d    ",
      " l         d    ",
      "           e    ",
      " l         d    ",
      " l         d    ",
      "ml         e    ",
      "n          e    ",
      "ll         b    ",
      "           e    ",
      "        刍  c    ",
      "    Q    刍 d    ",
      "     刍     d    ",
      "        Q       ",
      "l 埵        w    "
    ],
    [
      "蒙               ",
      " l              ",
      " l              ",
      " l              ",
      "                ",
      " l              ",
      " l              ",
      "ml              ",
      "n               ",
      " l              ",
      "                ",
      "                ",
      "                ",
      "                ",
      "                ",
      "                "
    ],
    [
      "蒙               ",
      " l              ",
      " l              ",
      " l              ",
      "                ",
      " l              ",
      " l              ",
      "ml              ",
      "n               ",
      " l              ",
      "                ",
      "                ",
      "                ",
      "                ",
      "                ",
      "                "
    ],
    [
      "蒙               ",
      " l              ",
      " l              ",
      " l              ",
      "                ",
      " l              ",
      " l              ",
      "ml              ",
      "n               ",
      " l              ",
      "                ",
      "                ",
      "                ",
      "                ",
      "                ",
      "                "
    ]
  ]
}