{
  "xsize": 16,
  "zsize": 16,
  "palette": {
    "palette": [
      {
        "char": " ",
        "block": "minecraft:air"
      },
      {
        "char": "e",
        "block": "minecraft:air"
      },
      {
        "char": "b",
        "block": "minecraft:air"
      },
      {
        "char": "d",
        "block": "minecraft:air"
      },
      {
        "char": "c",
        "block": "minecraft:air"
      },
      {
        "char": "t",
        "block": "minecraft:air"
      },
      {
        "char": "g",
        "block": "minecraft:air"
      },
      {
        "char": "h",
        "block": "minecraft:air"
      },
      {
        "char": "f",
        "block": "minecraft:air"
      },
      {
        "char": "i",
        "block": "minecraft:air"
      },
      {
        "char": "q",
        "block": "minecraft:air"
      },
      {
        "char": "o",
        "block": "minecraft:air"
      },
      {
        "char": "串",
        "block": "minecraft:air",
        "tag": {
          "SpawnData": {
            "entity": {}
          },
          "MaxNearbyEntities": "6s",
          "MinSpawnDelay": "200s",
          "z": 451,
          "x": -63,
          "MaxSpawnDelay": "800s",
          "RequiredPlayerRange": "16s",
          "SpawnCount": "4s",
          "ForgeCaps": {},
          "id": "minecraft:mob_spawner",
          "SpawnPotentials": [],
          "y": 139,
          "SpawnRange": "4s",
          "Delay": "20s"
        }
      },
      {
        "char": "s",
        "block": "minecraft:grass"
      },
      {
        "char": "w",
        "block": "minecraft:air"
      },
      {
        "char": "皈",
        "block": "minecraft:air"
      },
      {
        "char": "喙",
        "block": "minecraft:air"
      },
      {
        "char": "n",
        "block": "minecraft:air"
      },
      {
        "char": "l",
        "block": "minecraft:air"
      },
      {
        "char": "K",
        "block": "minecraft:air"
      },
      {
        "char": "j",
        "block": "minecraft:air"
      },
      {
        "char": "p",
        "block": "minecraft:air"
      },
      {
        "char": "歉",
        "block": "minecraft:air"
      }
    ]
  },
  "slices": [
    [
      "eeeebbdcbbbbceeb",
      "dbtbbbtbdbbbbece",
      "ebebbbcebdbcbebb",
      "ghtfggiifihhhqhg",
      "hgqhthqqgfqghftq",
      "fqiiittfhihihggi",
      "toqiitqhfhhfigtt",
      "qqtgghffgfitgqgt",
      "higggqhihfghifft",
      "hohqtqhqhhhhfgig",
      "htqgiqhgg串串gfqft",
      "bbdbcdbbbedcbbbb",
      "cbdcbtcebdbcbddb",
      "bddebebcceebctbt",
      "ttoootttttttttto",
      "ooooooooooooottt"
    ],
    [
      "s     s       s ",
      "  s  ss  w      ",
      "s     sw     sc ",
      "  sws   sb      ",
      "ws  s   b     s ",
      "w皈   ss    d c  ",
      "sw wss  w     ss",
      "  s    ws  ss  s",
      "   s皈  s       s",
      " w  s        e喙e",
      " s  s    wws  ss",
      "        b    w  ",
      "w sw sn         ",
      "  nnnnsl  w ws s",
      "ssbcbsnnsssssssK",
      "cdcbdecdbeeeesss"
    ],
    [
      "                ",
      "                ",
      "                ",
      "                ",
      "                ",
      "                ",
      "                ",
      "                ",
      "                ",
      "                ",
      "                ",
      "                ",
      "     nn         ",
      "  nnnn l        ",
      " jpbp歉nnsnnnn   ",
      "ecdcbcddced     "
    ],
    [
      "                ",
      "                ",
      "                ",
      "                ",
      "                ",
      "                ",
      "                ",
      "                ",
      "                ",
      "                ",
      "                ",
      "                ",
      "     nn         ",
      "  nnnn l        ",
      " jbdb歉nn nnnn   ",
      "ebebbdccbd      "
    ],
    [
      "                ",
      "                ",
      "                ",
      "                ",
      "                ",
      "                ",
      "                ",
      "                ",
      "                ",
      "                ",
      "                ",
      "                ",
      "     nn         ",
      "  nnnn l        ",
      " jpbp歉nn nnnn   ",
      "dbedcedeed      "
    ],
    [
      "                ",
      "                ",
      "                ",
      "                ",
      "                ",
      "                ",
      "                ",
      "                ",
      "                ",
      "                ",
      "                ",
      "                ",
      "     nn         ",
      "  nnnn l        ",
      " jbbp歉nn nnnn   ",
      "ecbedbcbbb      "
    ]
  ]
}