{
  "xsize": 16,
  "zsize": 16,
  "palette": {
    "palette": [
      {
        "char": " ",
        "block": "minecraft:air"
      },
      {
        "char": "j",
        "block": "minecraft:vine[east=true,north=false,south=false,up=false,west=false]"
      },
      {
        "char": "y",
        "block": "minecraft:quartz_slab[type=top,waterlogged=false]"
      },
      {
        "char": "z",
        "block": "minecraft:clay"
      },
      {
        "char": "N",
        "block": "minecraft:diorite_slab[type=top,waterlogged=false]"
      },
      {
        "char": "i",
        "block": "minecraft:cobbled_deepslate"
      },
      {
        "char": "e",
        "block": "minecraft:quartz_block"
      },
      {
        "char": "b",
        "block": "minecraft:polished_diorite"
      },
      {
        "char": "役",
        "block": "minecraft:dead_fire_coral_block"
      },
      {
        "char": "m",
        "block": "minecraft:vine[east=false,north=true,south=false,up=false,west=false]"
      },
      {
        "char": "d",
        "block": "minecraft:diorite"
      },
      {
        "char": "c",
        "block": "minecraft:smooth_quartz"
      },
      {
        "char": "w",
        "block": "minecraft:quartz_slab[type=bottom,waterlogged=false]"
      },
      {
        "char": "q",
        "block": "minecraft:blackstone"
      },
      {
        "char": "I",
        "block": "minecraft:black_concrete"
      },
      {
        "char": "J",
        "block": "minecraft:polished_blackstone"
      },
      {
        "char": "K",
        "block": "minecraft:diorite_slab[type=bottom,waterlogged=false]"
      },
      {
        "char": "g",
        "block": "minecraft:cyan_terracotta"
      },
      {
        "char": "C",
        "block": "minecraft:air"
      },
      {
        "char": "h",
        "block": "minecraft:deepslate[axis=y]"
      },
      {
        "char": "麒",
        "block": "minecraft:vine[east=false,north=false,south=false,up=true,west=false]"
      },
      {
        "char": "埠",
        "block": "minecraft:vine[east=true,north=false,south=false,up=true,west=false]"
      },
      {
        "char": "f",
        "block": "minecraft:basalt[axis=x]"
      }
    ]
  },
  "slices": [
    [
      "           j  yz",
      "              Ni",
      "              eb",
      "           j  yz",
      "         j    y役",
      "          mj jdd",
      "              yi",
      "              yz",
      "             jcc",
      "              yz",
      "              yz",
      "             jce",
      "              Nz",
      "              yz",
      "             jcd",
      "              yz"
    ],
    [
      "           j  wq",
      "              wI",
      "              ed",
      "           j  wJ",
      "         j    wI",
      "          mj jbc",
      "              wI",
      "              Kq",
      "             jbd",
      "              KJ",
      "              KI",
      "             jed",
      "              wI",
      "              KJ",
      "             jdd",
      "              wq"
    ],
    [
      "           j  Kz",
      "              wi",
      "              ed",
      "           j  wg",
      "         j    Kz",
      "          mj  dd",
      "              KC",
      "              wh",
      "              bc",
      "              wq",
      "              wz",
      "              db",
      "              Kq",
      "              wz",
      "             jeb",
      "              Kg"
    ],
    [
      "           j  Nz",
      "              Nz",
      "              bc",
      "           j  yz",
      "         j    Nh",
      "          mj  bc",
      "              yg",
      "              yz",
      "              eb",
      "              yz",
      "              yz",
      "              ec",
      "             麒yz",
      "             麒yz",
      "             埠ee",
      "             麒yz"
    ],
    [
      "           jddfh",
      "            deqh",
      "            cegg",
      "           jbdhg",
      "         j  edih",
      "          mjdbfC",
      "            bdqh",
      "            cegq",
      "            bcqg",
      "            cbhq",
      "            ccgf",
      "            ebqi",
      "            deqg",
      "            eeih",
      "            cdgi",
      "            bchh"
    ],
    [
      "           jcd  ",
      "            cd  ",
      "            ec  ",
      "           jde  ",
      "         j  ed  ",
      "          mjeb  ",
      "            bb  ",
      "            dc  ",
      "            ce  ",
      "            ec  ",
      "            bc  ",
      "            bd  ",
      "            eb  ",
      "            ee  ",
      "            cc  ",
      "            dd  "
    ]
  ]
}