{
  "xsize": 16,
  "zsize": 16,
  "palette": {
    "palette": [
      {
        "char": " ",
        "block": "minecraft:air"
      },
      {
        "char": "y",
        "block": "minecraft:quartz_slab[type=top,waterlogged=false]"
      },
      {
        "char": "z",
        "block": "minecraft:clay"
      },
      {
        "char": "皈",
        "block": "minecraft:quartz_slab[type=double,waterlogged=false]"
      },
      {
        "char": "i",
        "block": "minecraft:cobbled_deepslate"
      },
      {
        "char": "j",
        "block": "minecraft:vine[east=true,north=false,south=false,up=false,west=false]"
      },
      {
        "char": "e",
        "block": "minecraft:quartz_block"
      },
      {
        "char": "d",
        "block": "minecraft:diorite"
      },
      {
        "char": "N",
        "block": "minecraft:diorite_slab[type=top,waterlogged=false]"
      },
      {
        "char": "c",
        "block": "minecraft:smooth_quartz"
      },
      {
        "char": "伟",
        "block": "minecraft:vine[east=true,north=false,south=true,up=false,west=false]"
      },
      {
        "char": "袱",
        "block": "minecraft:quartz_stairs[facing=east,half=top,shape=straight,waterlogged=false]"
      },
      {
        "char": "p",
        "block": "minecraft:quartz_pillar[axis=y]"
      },
      {
        "char": "b",
        "block": "minecraft:polished_diorite"
      },
      {
        "char": "v",
        "block": "minecraft:red_terracotta"
      },
      {
        "char": "q",
        "block": "minecraft:blackstone"
      },
      {
        "char": "f",
        "block": "minecraft:basalt[axis=x]"
      },
      {
        "char": "h",
        "block": "minecraft:deepslate[axis=y]"
      },
      {
        "char": "C",
        "block": "minecraft:air"
      },
      {
        "char": "儸",
        "block": "minecraft:diorite_stairs[facing=east,half=top,shape=straight,waterlogged=false]"
      },
      {
        "char": "袅",
        "block": "minecraft:quartz_stairs[facing=east,half=bottom,shape=straight,waterlogged=false]"
      },
      {
        "char": "u",
        "block": "minecraft:red_concrete"
      },
      {
        "char": "K",
        "block": "minecraft:diorite_slab[type=bottom,waterlogged=false]"
      },
      {
        "char": "n",
        "block": "minecraft:vine[east=false,north=false,south=true,up=false,west=false]"
      },
      {
        "char": "拭",
        "block": "minecraft:cobblestone_wall[east=low,north=none,south=none,up=false,waterlogged=false,weathering=false,west=low]"
      },
      {
        "char": "调",
        "block": "minecraft:vine[east=true,north=true,south=false,up=false,west=false]"
      },
      {
        "char": "鲸",
        "block": "minecraft:mossy_cobblestone_wall[east=tall,north=tall,south=none,up=true,waterlogged=false,west=none]"
      }
    ]
  },
  "slices": [
    [
      "              yz",
      "              皈i",
      "            j  e",
      "            j y ",
      "            j y ",
      "              dd",
      "            j Nz",
      "              Ny",
      "               c",
      "            伟 yz",
      "           j  皈z",
      "           j 袱dd",
      "           jjpdc",
      "           jjbcc",
      "          jv ped",
      "             袱be"
    ],
    [
      "             eqf",
      "             dhf",
      "            jdqq",
      "            jdqi",
      "            j Cq",
      "            儸dqh",
      "            jchf",
      "             Niq",
      "            袅 fh",
      "            伟cqf",
      "           j cCC",
      "           j袅eeb",
      "           jjceb",
      "           jjdce",
      "           v pcb",
      "           u Kec"
    ],
    [
      "             e  ",
      "             b  ",
      "            jd  ",
      "            jd  ",
      "            jd  ",
      "             d  ",
      "             b  ",
      "             b  ",
      "             c  ",
      "            nbn ",
      "           j cnn",
      "           j bbd",
      "           jjdbc",
      "           jjcdd",
      "           u拭bce",
      "           j 调bc"
    ],
    [
      "                ",
      "                ",
      "                ",
      "                ",
      "                ",
      "                ",
      "                ",
      "                ",
      "                ",
      "            nnn ",
      "           j  nn",
      "           j 伟pb",
      "           jjcbb",
      "           jjeed",
      "           jjbce",
      "           j 调鲸b"
    ],
    [
      "                ",
      "                ",
      "                ",
      "                ",
      "                ",
      "                ",
      "                ",
      "                ",
      "                ",
      "            nnn ",
      "           j  nn",
      "           j 伟eb",
      "           jjpbc",
      "           jjedd",
      "           jjcee",
      "           j 调鲸d"
    ],
    [
      "                ",
      "                ",
      "                ",
      "                ",
      "                ",
      "                ",
      "                ",
      "                ",
      "                ",
      "            nnn ",
      "           j  nn",
      "           j 伟ed",
      "           jjpec",
      "           jjcbd",
      "           jjpdc",
      "           j 调de"
    ]
  ]
}