{
  "xsize": 16,
  "zsize": 16,
  "palette": {
    "palette": [
      {
        "char": " ",
        "block": "minecraft:air"
      },
      {
        "char": "d",
        "block": "minecraft:diorite"
      },
      {
        "char": "e",
        "block": "minecraft:quartz_block"
      },
      {
        "char": "l",
        "block": "minecraft:vine[east=false,north=false,south=false,up=false,west=true]"
      },
      {
        "char": "c",
        "block": "minecraft:smooth_quartz"
      },
      {
        "char": "b",
        "block": "minecraft:polished_diorite"
      },
      {
        "char": "g",
        "block": "minecraft:cyan_terracotta"
      },
      {
        "char": "C",
        "block": "minecraft:air"
      },
      {
        "char": "q",
        "block": "minecraft:blackstone"
      },
      {
        "char": "i",
        "block": "minecraft:cobbled_deepslate"
      },
      {
        "char": "f",
        "block": "minecraft:basalt[axis=x]"
      },
      {
        "char": "h",
        "block": "minecraft:deepslate[axis=y]"
      },
      {
        "char": "潢",
        "block": "minecraft:air"
      },
      {
        "char": "Q",
        "block": "minecraft:smooth_stone_slab[type=bottom,waterlogged=false]"
      },
      {
        "char": "拔",
        "block": "minecraft:mossy_cobblestone_slab[type=top,waterlogged=false]"
      },
      {
        "char": "a",
        "block": "minecraft:smooth_stone_slab[type=top,waterlogged=false]"
      },
      {
        "char": "膝",
        "block": "minecraft:cobblestone_wall[east=none,north=none,south=none,up=true,waterlogged=false,weathering=false,west=none]"
      }
    ]
  },
  "slices": [
    [
      "     del        ",
      "     del        ",
      "     ed         ",
      "     cc         ",
      "     bb         ",
      "     ed         ",
      "     ec         ",
      "     bd         ",
      "     db         ",
      "     dbl        ",
      "     cel        ",
      "     bel        ",
      "     dcl        ",
      "     eel        ",
      "     bd         ",
      "     bd         "
    ],
    [
      "     ebl        ",
      "     cbl        ",
      "     bc         ",
      "     ee         ",
      "     ee         ",
      "     cd         ",
      "     eb         ",
      "     cc         ",
      "     dd         ",
      "     edl        ",
      "     eel        ",
      "     cel        ",
      "     ddl        ",
      "     cdl        ",
      "     cc         ",
      "     cc         "
    ],
    [
      "     edl        ",
      "     edl        ",
      "     bb         ",
      "     bc         ",
      "     ec         ",
      "     cb         ",
      "     cd         ",
      "     bd         ",
      "     ed         ",
      "     cdl        ",
      "     bdl        ",
      "     cel        ",
      "     ccl        ",
      "     ec         ",
      "     eb         ",
      "     bc         "
    ],
    [
      "     edl        ",
      "     ddl        ",
      "     ec         ",
      "     bd         ",
      "     cd         ",
      "     ec         ",
      "     bd         ",
      "     cc         ",
      "     de         ",
      "     ecl        ",
      "     ccl        ",
      "     ecl        ",
      "     cdl        ",
      "     be         ",
      "     bd         ",
      "     cb         "
    ],
    [
      "gCqgidel        ",
      "CCqCibel        ",
      "Cigiidb         ",
      "ffqgfdb         ",
      "biCggcb         ",
      "gCCfqbd         ",
      "fCffide         ",
      "fqCiCde         ",
      "hqqhfbe         ",
      "fqCghccl        ",
      "fCqffddl        ",
      "iigiieel        ",
      "ghhqicel        ",
      "hqiCicc         ",
      "ghhqibd         ",
      "iiqifed         "
    ],
    [
      "c    dbl        ",
      "dl   cdl        ",
      "el   ec         ",
      "dl   cd         ",
      "潢l   bd         ",
      "cl   db         ",
      "el   bb         ",
      "cQQ  dc         ",
      "d拔a  ee         ",
      "b    cbl        ",
      "d    dcl        ",
      "b 膝  ee         ",
      "e    cd         ",
      "d 膝  bc         ",
      "e    db         ",
      "d 膝  bc         "
    ]
  ]
}