{
  "xsize": 16,
  "zsize": 16,
  "palette": {
    "palette": [
      {
        "char": " ",
        "block": "minecraft:air"
      },
      {
        "char": "z",
        "block": "minecraft:clay"
      },
      {
        "char": "y",
        "block": "minecraft:quartz_slab[type=top,waterlogged=false]"
      },
      {
        "char": "贷",
        "block": "minecraft:redstone_wire[east=none,north=none,power=0,south=side,west=side]"
      },
      {
        "char": "e",
        "block": "minecraft:quartz_block"
      },
      {
        "char": "l",
        "block": "minecraft:vine[east=false,north=false,south=false,up=false,west=true]"
      },
      {
        "char": "醉",
        "block": "minecraft:repeater[delay=1,facing=north,locked=false,powered=false]"
      },
      {
        "char": "x",
        "block": "minecraft:redstone_lamp[lit=false]"
      },
      {
        "char": "c",
        "block": "minecraft:smooth_quartz"
      },
      {
        "char": "歉",
        "block": "minecraft:vine[east=false,north=false,south=true,up=false,west=true]"
      },
      {
        "char": "p",
        "block": "minecraft:quartz_pillar[axis=y]"
      },
      {
        "char": "役",
        "block": "minecraft:dead_fire_coral_block"
      },
      {
        "char": "d",
        "block": "minecraft:diorite"
      },
      {
        "char": "b",
        "block": "minecraft:polished_diorite"
      },
      {
        "char": "T",
        "block": "minecraft:vine[east=false,north=true,south=false,up=false,west=true]"
      },
      {
        "char": "m",
        "block": "minecraft:vine[east=false,north=true,south=false,up=false,west=false]"
      },
      {
        "char": "i",
        "block": "minecraft:cobbled_deepslate"
      },
      {
        "char": "f",
        "block": "minecraft:basalt[axis=x]"
      },
      {
        "char": "h",
        "block": "minecraft:deepslate[axis=y]"
      },
      {
        "char": "J",
        "block": "minecraft:polished_blackstone"
      },
      {
        "char": "K",
        "block": "minecraft:diorite_slab[type=bottom,waterlogged=false]"
      },
      {
        "char": "G",
        "block": "minecraft:cobblestone_slab[type=double,waterlogged=false,weathering=false]"
      },
      {
        "char": "I",
        "block": "minecraft:black_concrete"
      },
      {
        "char": "w",
        "block": "minecraft:quartz_slab[type=bottom,waterlogged=false]"
      },
      {
        "char": "B",
        "block": "minecraft:moss_block"
      },
      {
        "char": "q",
        "block": "minecraft:blackstone"
      },
      {
        "char": "a",
        "block": "minecraft:smooth_stone_slab[type=top,waterlogged=false]"
      },
      {
        "char": "r",
        "block": "minecraft:cobblestone_slab[type=top,waterlogged=false,weathering=false]"
      },
      {
        "char": "k",
        "block": "minecraft:stone_slab[type=top,waterlogged=false,weathering=false]"
      },
      {
        "char": "g",
        "block": "minecraft:cyan_terracotta"
      },
      {
        "char": "N",
        "block": "minecraft:diorite_slab[type=top,waterlogged=false]"
      },
      {
        "char": "C",
        "block": "minecraft:air"
      }
    ]
  },
  "slices": [
    [
      "   zy           ",
      "贷  eel          ",
      "醉  zy           ",
      "x  zy  l        ",
      "   ec歉 l        ",
      "   eepll        ",
      "役ddcbdll        ",
      "yeeebpl         ",
      "  bepT          ",
      "   mm           ",
      "mmmm            ",
      "                ",
      "                ",
      "                ",
      "                ",
      "                "
    ],
    [
      "ifhJK           ",
      "hficel          ",
      "fGhIw           ",
      "fiBqK  l        ",
      "hhhdc  l        ",
      "ffhccbll        ",
      "qceeebll        ",
      "Kbedcpl         ",
      "  pceT          ",
      "   mm           ",
      "mmmm            ",
      "                ",
      "                ",
      "                ",
      "                ",
      "                "
    ],
    [
      "aaazw           ",
      "aaade           ",
      "rakzK           ",
      "aaafw  l        ",
      "aaadc  l        ",
      "aaaebp l        ",
      "zebcbd l        ",
      "wecbcc          ",
      "  eep           ",
      "                ",
      "mmmm            ",
      "                ",
      "                ",
      "                ",
      "                ",
      "                "
    ],
    [
      "   gy           ",
      "   dd           ",
      "   zy           ",
      "   hy  l        ",
      "   be  l        ",
      "   cec l        ",
      "iccebe l        ",
      "Nbdbed          ",
      "  pep           ",
      "                ",
      "mmmm            ",
      "                ",
      "                ",
      "                ",
      "                ",
      "                "
    ],
    [
      "Chgihcc         ",
      "qgifgbe         ",
      "gqhihed         ",
      "hhgficdl        ",
      "Cgigqbbl        ",
      "qgfqfbdl        ",
      "ggfCfbcl        ",
      "ihCfqcc         ",
      "deecebe         ",
      "bbcceec         ",
      "mmmm            ",
      "                ",
      "                ",
      "                ",
      "                ",
      "                "
    ],
    [
      "     bd         ",
      "     eb         ",
      "     bd         ",
      "     ddl        ",
      "     cdl        ",
      "     cel        ",
      "     bbl        ",
      "     dd         ",
      "bddcbeb         ",
      "edccbbe         ",
      "mmmm            ",
      "                ",
      "                ",
      "                ",
      "                ",
      "                "
    ]
  ]
}