{
  "xsize": 16,
  "zsize": 16,
  "palette": {
    "palette": [
      {
        "char": " ",
        "block": "minecraft:air"
      },
      {
        "char": "y",
        "block": "minecraft:quartz_slab[type=top,waterlogged=false]"
      },
      {
        "char": "z",
        "block": "minecraft:clay"
      },
      {
        "char": "袱",
        "block": "minecraft:quartz_stairs[facing=east,half=top,shape=straight,waterlogged=false]"
      },
      {
        "char": "d",
        "block": "minecraft:diorite"
      },
      {
        "char": "e",
        "block": "minecraft:quartz_block"
      },
      {
        "char": "N",
        "block": "minecraft:diorite_slab[type=top,waterlogged=false]"
      },
      {
        "char": "i",
        "block": "minecraft:cobbled_deepslate"
      },
      {
        "char": "儸",
        "block": "minecraft:diorite_stairs[facing=east,half=top,shape=straight,waterlogged=false]"
      },
      {
        "char": "b",
        "block": "minecraft:polished_diorite"
      },
      {
        "char": "c",
        "block": "minecraft:smooth_quartz"
      },
      {
        "char": "p",
        "block": "minecraft:quartz_pillar[axis=y]"
      },
      {
        "char": "j",
        "block": "minecraft:vine[east=true,north=false,south=false,up=false,west=false]"
      },
      {
        "char": "调",
        "block": "minecraft:vine[east=true,north=true,south=false,up=false,west=false]"
      },
      {
        "char": "w",
        "block": "minecraft:quartz_slab[type=bottom,waterlogged=false]"
      },
      {
        "char": "q",
        "block": "minecraft:blackstone"
      },
      {
        "char": "袅",
        "block": "minecraft:quartz_stairs[facing=east,half=bottom,shape=straight,waterlogged=false]"
      },
      {
        "char": "I",
        "block": "minecraft:black_concrete"
      },
      {
        "char": "K",
        "block": "minecraft:diorite_slab[type=bottom,waterlogged=false]"
      },
      {
        "char": "J",
        "block": "minecraft:polished_blackstone"
      },
      {
        "char": "H",
        "block": "minecraft:glass_pane[east=false,north=true,south=true,waterlogged=false,west=false]"
      },
      {
        "char": "训",
        "block": "minecraft:air"
      }
    ]
  },
  "slices": [
    [
      "              yz",
      "             袱de",
      "              yz",
      "              Ni",
      "             儸bd",
      "              yz",
      "              yz",
      "              dd",
      "             deb",
      "              de",
      "              cb",
      "             pdd",
      "             jbc",
      "             jbe",
      "            jpcd",
      "             调eb"
    ],
    [
      "              wq",
      "            袅wce",
      "              wI",
      "              wq",
      "            袅Kdd",
      "              Kq",
      "              wq",
      "              ce",
      "             cbe",
      "              dd",
      "              db",
      "             bdc",
      "              eb",
      "              de",
      "            jdcb",
      "             调cc"
    ],
    [
      "               I",
      "              eb",
      "               I",
      "                ",
      "              de",
      "                ",
      "               J",
      "              ce",
      "             deb",
      "              cc",
      "              db",
      "             dce",
      "              db",
      "              bc",
      "            jpcb",
      "             调eb"
    ],
    [
      "                ",
      "              pd",
      "               H",
      "               训",
      "              be",
      "               训",
      "               H",
      "              bc",
      "             edb",
      "              dd",
      "              de",
      "             bee",
      "              cc",
      "              bb",
      "            jpdc",
      "             调ee"
    ],
    [
      "               训",
      "              pb",
      "               H",
      "               训",
      "              pc",
      "               H",
      "               训",
      "              db",
      "             pcd",
      "              be",
      "              bd",
      "             cde",
      "              ed",
      "              cb",
      "            jpdc",
      "             调bd"
    ],
    [
      "               z",
      "              de",
      "               z",
      "               z",
      "              de",
      "               z",
      "               z",
      "              bd",
      "             pce",
      "              ec",
      "              eb",
      "             pbc",
      "              ce",
      "              ed",
      "            jpcc",
      "             调cc"
    ]
  ]
}