{
  "xsize": 16,
  "zsize": 16,
  "palette": {
    "palette": [
      {
        "char": " ",
        "block": "minecraft:air"
      },
      {
        "char": "串",
        "block": "minecraft:air",
        "tag": {
          "SpawnData": {
            "entity": {}
          },
          "MaxNearbyEntities": "6s",
          "MinSpawnDelay": "200s",
          "z": 451,
          "x": -63,
          "MaxSpawnDelay": "800s",
          "RequiredPlayerRange": "16s",
          "SpawnCount": "4s",
          "ForgeCaps": {},
          "id": "minecraft:mob_spawner",
          "SpawnPotentials": [],
          "y": 139,
          "SpawnRange": "4s",
          "Delay": "20s"
        }
      },
      {
        "char": "t",
        "block": "minecraft:air"
      },
      {
        "char": "o",
        "block": "minecraft:air"
      },
      {
        "char": "i",
        "block": "minecraft:air"
      },
      {
        "char": "q",
        "block": "minecraft:air"
      },
      {
        "char": "g",
        "block": "minecraft:air"
      },
      {
        "char": "f",
        "block": "minecraft:air"
      },
      {
        "char": "h",
        "block": "minecraft:air"
      },
      {
        "char": "孜",
        "block": "minecraft:air"
      },
      {
        "char": "s",
        "block": "minecraft:grass"
      },
      {
        "char": "m",
        "block": "minecraft:air"
      },
      {
        "char": "b",
        "block": "minecraft:air"
      },
      {
        "char": "舱",
        "block": "minecraft:air"
      }
    ]
  },
  "slices": [
    [
      "串串tttttttttttttt",
      "ttottttttttttttt",
      "tttttttttttttttt",
      "tttttttttttttttt",
      "tttttttttttttttt",
      "tttttttttttttttt",
      "tttttttttttttttt",
      "tttttttttttttttt",
      "tttttttttttttttt",
      "tttttttttttttttt",
      "tttttttttttttttt",
      "itqgigfgiqifihqf",
      "gtftffqqhgqihqqi",
      "figfgiqqftgftfig",
      "ggihigqihgfhggif",
      "qqqhtgqhqihggqqi"
    ],
    [
      "孜孜ssmmms mmmmmss",
      "mmbsssssssssssss",
      "舱sssssssssssssss",
      "ssssssssssssssss",
      "ssssssssssssssss",
      "ssssssssssssssss",
      "ssssssssssssssss",
      "ssssssssssssssss",
      "ssssssssssssssss",
      "ssssssssssssssss",
      "ssssssssssssssss",
      " s s s          ",
      " s s            ",
      "         s  s   ",
      "                ",
      "    ss        s "
    ],
    [
      "    mmm  mmmmm  ",
      "mm              ",
      "                ",
      "                ",
      "                ",
      "                ",
      "                ",
      "                ",
      "                ",
      "                ",
      "                ",
      "                ",
      "                ",
      "                ",
      "                ",
      "                "
    ],
    [
      "    mmm   mmmm  ",
      "mm              ",
      "                ",
      "                ",
      "                ",
      "                ",
      "                ",
      "                ",
      "                ",
      "                ",
      "                ",
      "                ",
      "                ",
      "                ",
      "                ",
      "                "
    ],
    [
      "    mmm   mmmm  ",
      "mm              ",
      "                ",
      "                ",
      "                ",
      "                ",
      "                ",
      "                ",
      "                ",
      "                ",
      "                ",
      "                ",
      "                ",
      "                ",
      "                ",
      "                "
    ],
    [
      "    mm    mm    ",
      "mm              ",
      "                ",
      "                ",
      "                ",
      "                ",
      "                ",
      "                ",
      "                ",
      "                ",
      "                ",
      "                ",
      "                ",
      "                ",
      "                ",
      "                "
    ]
  ]
}