{
  "xsize": 16,
  "zsize": 16,
  "palette": {
    "palette": [
      {
        "char": " ",
        "block": "minecraft:air"
      },
      {
        "char": "床",
        "block": "minecraft:oak_leaves[distance=2,persistent=false,waterlogged=false]"
      },
      {
        "char": "巡",
        "block": "minecraft:oak_leaves[distance=1,persistent=false,waterlogged=false]"
      },
      {
        "char": "d",
        "block": "minecraft:diorite"
      },
      {
        "char": "e",
        "block": "minecraft:quartz_block"
      },
      {
        "char": "瓣",
        "block": "minecraft:oak_log[axis=y]"
      },
      {
        "char": "p",
        "block": "minecraft:quartz_pillar[axis=y]"
      },
      {
        "char": "b",
        "block": "minecraft:polished_diorite"
      },
      {
        "char": "j",
        "block": "minecraft:vine[east=true,north=false,south=false,up=false,west=false]"
      },
      {
        "char": "m",
        "block": "minecraft:vine[east=false,north=true,south=false,up=false,west=false]"
      },
      {
        "char": "c",
        "block": "minecraft:smooth_quartz"
      },
      {
        "char": "伟",
        "block": "minecraft:vine[east=true,north=false,south=true,up=false,west=false]"
      },
      {
        "char": "N",
        "block": "minecraft:diorite_slab[type=top,waterlogged=false]"
      },
      {
        "char": "焢",
        "block": "minecraft:vine[east=false,north=true,south=true,up=true,west=false]"
      },
      {
        "char": "u",
        "block": "minecraft:red_concrete"
      },
      {
        "char": "v",
        "block": "minecraft:red_terracotta"
      },
      {
        "char": "蒙",
        "block": "minecraft:quartz_stairs[facing=north,half=bottom,shape=straight,waterlogged=false]"
      },
      {
        "char": "儸",
        "block": "minecraft:diorite_stairs[facing=east,half=top,shape=straight,waterlogged=false]"
      },
      {
        "char": "狡",
        "block": "minecraft:vine[east=false,north=true,south=false,up=true,west=false]"
      },
      {
        "char": "袱",
        "block": "minecraft:quartz_stairs[facing=east,half=top,shape=straight,waterlogged=false]"
      },
      {
        "char": "佯",
        "block": "minecraft:diorite_stairs[facing=south,half=top,shape=straight,waterlogged=false]"
      },
      {
        "char": "竺",
        "block": "minecraft:quartz_pillar[axis=z]"
      },
      {
        "char": "椎",
        "block": "minecraft:quartz_stairs[facing=north,half=top,shape=straight,waterlogged=false]"
      },
      {
        "char": "亥",
        "block": "minecraft:quartz_stairs[facing=south,half=top,shape=straight,waterlogged=false]"
      },
      {
        "char": "桨",
        "block": "minecraft:diorite_stairs[facing=north,half=top,shape=straight,waterlogged=false]"
      }
    ]
  },
  "slices": [
    [
      "  床巡床         de",
      "  巡瓣巡        pbe",
      "  床巡床       j de",
      "            jdeb",
      "            jmee",
      "              bd",
      "            j de",
      "             pcc",
      "              dd",
      "            伟pdd",
      "      床    j  dc",
      "     床巡床   j  db",
      "      床    jjbdd",
      "             ebb",
      "          j jebb",
      "            jNcb"
    ],
    [
      "   床          ec",
      "  床巡床        pee",
      "   床        j bb",
      "            jpbe",
      "            jmbb",
      "              cb",
      "            j bc",
      "             pde",
      "              ee",
      "            伟pce",
      "           j  ee",
      "           j  ce",
      "           jjpdc",
      "             dcc",
      "          j jdeb",
      "            j焢ee"
    ],
    [
      "              du",
      "             pbu",
      "            j bv",
      "            jpcv",
      "            jmcv",
      "              du",
      "            j cv",
      "             bbv",
      "              bu",
      "            伟pcu",
      "           j  cv",
      "           j  bu",
      "           jjebu",
      "          u  bdv",
      "          j jpev",
      "            j蒙ev"
    ],
    [
      "              cb",
      "             dbc",
      "            j ce",
      "            jeed",
      "            jmdb",
      "              cc",
      "            j cc",
      "             pee",
      "              db",
      "            伟eeb",
      "           j  dd",
      "           j  dc",
      "           jjpdb",
      "          v  dbc",
      "          j jdbc",
      "            jmbb"
    ],
    [
      "              be",
      "             cbd",
      "            j儸eb",
      "            jped",
      "            j狡bc",
      "             儸bc",
      "            j db",
      "             dbb",
      "             袱be",
      "            伟pcd",
      "           j  ec",
      "           j  dc",
      "           jjpbd",
      "          u  cec",
      "          j jdee",
      "            j狡db"
    ],
    [
      "              bb",
      "             佯cd",
      "            j竺cc",
      "            j椎cb",
      "            j亥be",
      "             ebb",
      "            j桨bd",
      "             亥bb",
      "             cbe",
      "            伟桨cd",
      "           j  ed",
      "           j  db",
      "           jjbee",
      "          u  bde",
      "          j jdeb",
      "            j椎dc"
    ]
  ]
}