{
  "xsize": 16,
  "zsize": 16,
  "palette": {
    "palette": [
      {
        "char": " ",
        "block": "minecraft:air"
      },
      {
        "char": "f",
        "block": "minecraft:air"
      },
      {
        "char": "i",
        "block": "minecraft:air"
      },
      {
        "char": "g",
        "block": "minecraft:air"
      },
      {
        "char": "q",
        "block": "minecraft:air"
      },
      {
        "char": "h",
        "block": "minecraft:air"
      },
      {
        "char": "d",
        "block": "minecraft:air"
      },
      {
        "char": "c",
        "block": "minecraft:air"
      },
      {
        "char": "t",
        "block": "minecraft:air"
      },
      {
        "char": "o",
        "block": "minecraft:air"
      },
      {
        "char": "b",
        "block": "minecraft:air"
      },
      {
        "char": "呗",
        "block": "minecraft:air"
      },
      {
        "char": "e",
        "block": "minecraft:air"
      },
      {
        "char": "锁",
        "block": "minecraft:air"
      },
      {
        "char": "串",
        "block": "minecraft:air",
        "tag": {
          "SpawnData": {
            "entity": {}
          },
          "MaxNearbyEntities": "6s",
          "MinSpawnDelay": "200s",
          "z": 451,
          "x": -63,
          "MaxSpawnDelay": "800s",
          "RequiredPlayerRange": "16s",
          "SpawnCount": "4s",
          "ForgeCaps": {},
          "id": "minecraft:mob_spawner",
          "SpawnPotentials": [],
          "y": 139,
          "SpawnRange": "4s",
          "Delay": "20s"
        }
      },
      {
        "char": "s",
        "block": "minecraft:grass"
      },
      {
        "char": "瓣",
        "block": "minecraft:air"
      },
      {
        "char": "胡",
        "block": "minecraft:air"
      },
      {
        "char": "俎",
        "block": "minecraft:air"
      },
      {
        "char": "庖",
        "block": "minecraft:air"
      },
      {
        "char": "痣",
        "block": "minecraft:air"
      },
      {
        "char": "拧",
        "block": "minecraft:air"
      },
      {
        "char": "w",
        "block": "minecraft:air"
      },
      {
        "char": "床",
        "block": "minecraft:air"
      },
      {
        "char": "巡",
        "block": "minecraft:air"
      },
      {
        "char": "劲",
        "block": "minecraft:air"
      }
    ]
  },
  "slices": [
    [
      "figqhqhgdcdtottt",
      "cbbi呗g呗fbbbttttt",
      "cbth呗t呗qbbbtottt",
      "cbbf呗f呗qbbbtottt",
      "bcbfgqtqdebtottt",
      "cddhfiiqdbctottt",
      "cbeqhgh锁锁bctottt",
      "eebgtfiqbbdtottt",
      "cbbthghg锁锁etottt",
      "eccitqiheecttttt",
      "dtbhhitgbbbttttt",
      "dcbiqqgfbcdttttt",
      "edbfitgfebbttttt",
      "dbctqftfdbbttttt",
      "beeqffttdbbttttt",
      "bbbgfhfhbddtt串tt"
    ],
    [
      "        s ss瓣s胡s",
      "          胡s俎胡ss",
      "  s  ss    胡庖sss",
      "           s痣sss",
      "s     s    s痣sss",
      "         锁 s痣sss",
      " s   s     s痣sss",
      "    s 锁    s痣sss",
      "           s拧sss",
      "    s      sssss",
      "ss    s锁  锁sssss",
      "           sssss",
      "     s     sssss",
      "   s  s    sssss",
      "      ss   sssss",
      "           sswss"
    ],
    [
      "            瓣   ",
      "                ",
      "                ",
      "                ",
      "                ",
      "                ",
      "                ",
      "                ",
      "                ",
      "                ",
      "                ",
      "                ",
      "                ",
      "                ",
      "                ",
      "                "
    ],
    [
      "            瓣   ",
      "                ",
      "                ",
      "                ",
      "                ",
      "                ",
      "                ",
      "                ",
      "                ",
      "                ",
      "                ",
      "                ",
      "                ",
      "                ",
      "                ",
      "                "
    ],
    [
      "          床巡瓣巡床 ",
      "          劲床巡床劲 ",
      "           劲床劲  ",
      "                ",
      "                ",
      "                ",
      "                ",
      "                ",
      "                ",
      "                ",
      "                ",
      "                ",
      "                ",
      "                ",
      "                ",
      "                "
    ],
    [
      "          床巡瓣巡床 ",
      "          劲床巡床劲 ",
      "           劲床劲  ",
      "                ",
      "                ",
      "                ",
      "                ",
      "                ",
      "                ",
      "                ",
      "                ",
      "                ",
      "                ",
      "                ",
      "                ",
      "                "
    ]
  ]
}