{
  "xsize": 16,
  "zsize": 16,
  "palette": {
    "palette": [
      {
        "char": " ",
        "block": "minecraft:air"
      },
      {
        "char": "b",
        "block": "minecraft:air"
      },
      {
        "char": "t",
        "block": "minecraft:air"
      },
      {
        "char": "i",
        "block": "minecraft:air"
      },
      {
        "char": "q",
        "block": "minecraft:air"
      },
      {
        "char": "f",
        "block": "minecraft:air"
      },
      {
        "char": "h",
        "block": "minecraft:air"
      },
      {
        "char": "d",
        "block": "minecraft:air"
      },
      {
        "char": "g",
        "block": "minecraft:air"
      },
      {
        "char": "c",
        "block": "minecraft:air"
      },
      {
        "char": "o",
        "block": "minecraft:air"
      },
      {
        "char": "e",
        "block": "minecraft:air"
      },
      {
        "char": "串",
        "block": "minecraft:air",
        "tag": {
          "SpawnData": {
            "entity": {}
          },
          "MaxNearbyEntities": "6s",
          "MinSpawnDelay": "200s",
          "z": 451,
          "x": -63,
          "MaxSpawnDelay": "800s",
          "RequiredPlayerRange": "16s",
          "SpawnCount": "4s",
          "ForgeCaps": {},
          "id": "minecraft:mob_spawner",
          "SpawnPotentials": [],
          "y": 139,
          "SpawnRange": "4s",
          "Delay": "20s"
        }
      },
      {
        "char": "s",
        "block": "minecraft:grass"
      },
      {
        "char": "捻",
        "block": "minecraft:tall_grass[half=lower]"
      },
      {
        "char": "K",
        "block": "minecraft:air"
      },
      {
        "char": "w",
        "block": "minecraft:air"
      },
      {
        "char": "戟",
        "block": "minecraft:air"
      },
      {
        "char": "n",
        "block": "minecraft:air"
      },
      {
        "char": "窿",
        "block": "minecraft:tall_grass[half=upper]"
      }
    ]
  },
  "slices": [
    [
      "btttttttttttiqfh",
      "dttttttttttgthtf",
      "btttttttttthgiii",
      "cttttttttttggffq",
      "bttttttttttgfgii",
      "ctttttttottifftt",
      "tcttttottttfhiff",
      "ecbdttttotthtfgt",
      "tbddtttttttqffff",
      "oebeottototiftit",
      "oebbtttttttfgghf",
      "obbdtttotttitfhf",
      "odcbt串tttttiqigq",
      "obbc串ttttottgigt",
      "obebtttottoiqfih",
      "otdbtttttttqttqf"
    ],
    [
      " sssssssssss  s ",
      " ssssssssss s s ",
      " sssssssss捻 s   ",
      " ssssssssss     ",
      " ssssssssss     ",
      " ssssssscss   ss",
      "sKssssessss     ",
      "    ssssw捻s s  s",
      "s w sssssss     ",
      "K   Kss戟sds  s s",
      "w  cssssssss    ",
      "K   ssscsss s   ",
      "K   sKsssss     ",
      "we  Kssss戟ss  ss",
      "ws  ssswssb     ",
      "wsscsnnssss ss  "
    ],
    [
      "                ",
      "                ",
      "          窿     ",
      "                ",
      "                ",
      "                ",
      "                ",
      "         窿      ",
      "                ",
      "                ",
      "                ",
      "                ",
      "                ",
      "                ",
      "                ",
      "     nnn        "
    ],
    [
      "                ",
      "                ",
      "                ",
      "                ",
      "                ",
      "                ",
      "                ",
      "                ",
      "                ",
      "                ",
      "                ",
      "                ",
      "                ",
      "                ",
      "                ",
      "     nnn        "
    ],
    [
      "                ",
      "                ",
      "                ",
      "                ",
      "                ",
      "                ",
      "                ",
      "                ",
      "                ",
      "                ",
      "                ",
      "                ",
      "                ",
      "                ",
      "                ",
      "     nnn        "
    ],
    [
      "                ",
      "                ",
      "                ",
      "                ",
      "                ",
      "                ",
      "                ",
      "                ",
      "                ",
      "                ",
      "                ",
      "                ",
      "                ",
      "                ",
      "                ",
      "     nnn        "
    ]
  ]
}