{
  "xsize": 16,
  "zsize": 16,
  "palette": {
    "palette": [
      {
        "char": " ",
        "block": "minecraft:air"
      },
      {
        "char": "t",
        "block": "minecraft:air"
      },
      {
        "char": "o",
        "block": "minecraft:air"
      },
      {
        "char": "d",
        "block": "minecraft:air"
      },
      {
        "char": "p",
        "block": "minecraft:air"
      },
      {
        "char": "b",
        "block": "minecraft:air"
      },
      {
        "char": "c",
        "block": "minecraft:air"
      },
      {
        "char": "e",
        "block": "minecraft:air"
      },
      {
        "char": "莉",
        "block": "minecraft:air"
      },
      {
        "char": "s",
        "block": "minecraft:grass"
      },
      {
        "char": "胡",
        "block": "minecraft:air"
      },
      {
        "char": "淅",
        "block": "minecraft:air"
      },
      {
        "char": "K",
        "block": "minecraft:air"
      },
      {
        "char": "瓣",
        "block": "minecraft:air"
      },
      {
        "char": "j",
        "block": "minecraft:air"
      },
      {
        "char": "w",
        "block": "minecraft:air"
      },
      {
        "char": "椎",
        "block": "minecraft:air"
      },
      {
        "char": "蹑",
        "block": "minecraft:air"
      },
      {
        "char": "伟",
        "block": "minecraft:air"
      },
      {
        "char": "唆",
        "block": "minecraft:air"
      },
      {
        "char": "u",
        "block": "minecraft:air"
      },
      {
        "char": "v",
        "block": "minecraft:air"
      },
      {
        "char": "踵",
        "block": "minecraft:air"
      },
      {
        "char": "袅",
        "block": "minecraft:air"
      },
      {
        "char": "狩",
        "block": "minecraft:air"
      },
      {
        "char": "蒙",
        "block": "minecraft:air"
      },
      {
        "char": "擂",
        "block": "minecraft:air"
      },
      {
        "char": "邑",
        "block": "minecraft:air"
      },
      {
        "char": "箍",
        "block": "minecraft:air"
      },
      {
        "char": "竺",
        "block": "minecraft:air"
      },
      {
        "char": "恁",
        "block": "minecraft:air"
      },
      {
        "char": "劲",
        "block": "minecraft:air"
      },
      {
        "char": "床",
        "block": "minecraft:air"
      },
      {
        "char": "巡",
        "block": "minecraft:air"
      },
      {
        "char": "y",
        "block": "minecraft:air"
      },
      {
        "char": "嗅",
        "block": "minecraft:air"
      },
      {
        "char": "m",
        "block": "minecraft:air"
      },
      {
        "char": "n",
        "block": "minecraft:air"
      }
    ]
  },
  "slices": [
    [
      "ttttttttttottdpp",
      "tttottttottttbpp",
      "ttttttottttttpce",
      "tttttttttototbbp",
      "tttotttotttttbec",
      "tttttttttottopbe",
      "tttttttotttttooo",
      "tttttttttbccd莉莉莉",
      "ttttttottddet莉莉莉",
      "tttttttttbdte莉莉莉",
      "tttttttttbcbt莉莉莉",
      "ttttttottbbbb莉莉莉",
      "tttttttttecob莉莉莉",
      "tttttttttbbee莉莉莉",
      "tttttttttbecb莉莉莉",
      "tttttttttcebe莉莉莉"
    ],
    [
      "s胡胡淅ssssssKssecc",
      "ss胡瓣s胡ssbsssjddd",
      "sssss胡csssssjdcd",
      "s胡胡s胡ssssespjeec",
      "ssswsssws椎sssccc",
      "ssssssssswsswbbc",
      "sssssss蹑sssssedb",
      "sssssssss dsjbed",
      "ssssssKss   sded",
      "ssss胡s胡胡胡 Ks伟cbe",
      "ssss胡sss胡  jsddb",
      "ssss胡s瓣ss  jsbdd",
      "ssss胡胡s胡胡 ddepdb",
      "sssss胡s胡胡sdecedd",
      "sssssssss dddpcd",
      "胡ssssssss www唆dd"
    ],
    [
      "             ecu",
      "   瓣         bcu",
      "            jccu",
      "            jdbv",
      "            jbbv",
      "             bdv",
      "            jebu",
      "             bd ",
      "             bbu",
      "            伟bdv",
      "           j eb ",
      "      瓣    j ccu",
      "          踵唆唆bbe",
      "          袅cccee",
      "          狩蒙擂cdd",
      "            j邑ec"
    ],
    [
      "             箍cd",
      "   瓣         cdd",
      "            jbbb",
      "            jdee",
      "            j蒙de",
      "             wbd",
      "            j唆bd",
      "             竺dc",
      "             cce",
      "    恁劲床劲恁   伟竺ec",
      "    劲床巡床劲  j 蒙de",
      "    床巡瓣巡床  j web",
      "    劲床巡床劲  jjpcb",
      "    恁劲床劲恁 ye嗅eec",
      "          j jbce",
      "            j邑eb"
    ],
    [
      " 劲床巡床劲        db",
      " 床巡瓣巡床       pcd",
      " 劲床巡床劲      j袅cc",
      " 恁劲床劲       jpcb",
      "            jmcb",
      "              ee",
      "            j cd",
      "             pdb",
      "             袅bb",
      "    恁劲床劲    伟ebc",
      "    劲床巡床劲  j  db",
      "    床巡瓣巡床  j  dd",
      "    劲床巡床劲  jjpdd",
      "    恁劲床劲恁wKw edc",
      "          j jpbb",
      "劲           j邑cd"
    ],
    [
      " 劲床巡床劲        de",
      " 床巡瓣巡床       pbd",
      " 劲床巡床劲      jnce",
      "  劲床劲       jpbe",
      "            jmee",
      "              bd",
      "            j ee",
      "             pbc",
      "              ee",
      "            伟cbb",
      "     床巡    j  bd",
      "     巡瓣巡   j  dc",
      "      巡    jjpcd",
      "             eec",
      "          j jpdb",
      "劲           j邑ee"
    ]
  ]
}