{
  "xsize": 16,
  "zsize": 16,
  "palette": {
    "palette": [
      {
        "char": " ",
        "block": "minecraft:air"
      },
      {
        "char": "d",
        "block": "minecraft:diorite"
      },
      {
        "char": "b",
        "block": "minecraft:polished_diorite"
      },
      {
        "char": "e",
        "block": "minecraft:quartz_block"
      },
      {
        "char": "g",
        "block": "minecraft:cyan_terracotta"
      },
      {
        "char": "i",
        "block": "minecraft:cobbled_deepslate"
      },
      {
        "char": "f",
        "block": "minecraft:basalt[axis=x]"
      },
      {
        "char": "c",
        "block": "minecraft:smooth_quartz"
      },
      {
        "char": "t",
        "block": "minecraft:grass_block[snowy=false]"
      },
      {
        "char": "锁",
        "block": "minecraft:stone_slab[type=bottom,waterlogged=false,weathering=false]"
      },
      {
        "char": "h",
        "block": "minecraft:deepslate[axis=y]"
      },
      {
        "char": "q",
        "block": "minecraft:blackstone"
      },
      {
        "char": "o",
        "block": "minecraft:dirt"
      },
      {
        "char": "s",
        "block": "minecraft:air"
      },
      {
        "char": "胡",
        "block": "minecraft:air"
      },
      {
        "char": "瓣",
        "block": "minecraft:oak_log[axis=y]"
      },
      {
        "char": "恁",
        "block": "minecraft:oak_leaves[distance=4,persistent=false,waterlogged=false]"
      },
      {
        "char": "劲",
        "block": "minecraft:oak_leaves[distance=3,persistent=false,waterlogged=false]"
      },
      {
        "char": "床",
        "block": "minecraft:oak_leaves[distance=2,persistent=false,waterlogged=false]"
      },
      {
        "char": "巡",
        "block": "minecraft:oak_leaves[distance=1,persistent=false,waterlogged=false]"
      }
    ]
  },
  "slices": [
    [
      "dbegiiffcbbttttt",
      "锁锁锁gghffbebttttt",
      "hqfithhgbdbttttt",
      "gqhqfgthbbbttttt",
      "hgiqggihbbdttttt",
      "fqftgiqqcebttttt",
      "bbettqifbcbttttt",
      "cebgfhhgtecttttt",
      "debggg锁锁bebttttt",
      "bbbgqf锁锁beettott",
      "tbbhqigfccbttttt",
      "bcbiithhdeettttt",
      "bectiqqgbbbttttt",
      "bdbfqiihecbttttt",
      "ceeiihigebettttt",
      "dbbigithccettttt"
    ],
    [
      "     锁     sssss",
      "           sssss",
      " s  s      sssss",
      "  锁   s    sssss",
      "        s  sssss",
      "   s       sssss",
      "   ss      sssss",
      "        s ss胡sss",
      "           sssss",
      "           ss瓣ss",
      "s          胡ssss",
      "     s   s sssss",
      "   s       sssss",
      "           sssss",
      "           sssss",
      "      s    sssss"
    ],
    [
      "                ",
      "                ",
      "                ",
      "                ",
      "                ",
      "                ",
      "                ",
      "           恁劲床劲恁",
      "           劲床巡床劲",
      "           床巡瓣巡床",
      "           劲床巡床劲",
      "            劲床劲 ",
      "                ",
      "                ",
      "                ",
      "                "
    ],
    [
      "                ",
      "                ",
      "                ",
      "                ",
      "                ",
      "                ",
      "                ",
      "           恁劲床劲 ",
      "           劲床巡床劲",
      "           床巡瓣巡床",
      "           劲床巡床劲",
      "            劲床劲 ",
      "                ",
      "                ",
      "                ",
      "                "
    ],
    [
      "                ",
      "                ",
      "                ",
      "                ",
      "                ",
      "                ",
      "                ",
      "                ",
      "            床巡  ",
      "            巡瓣巡 ",
      "             巡  ",
      "                ",
      "                ",
      "                ",
      "                ",
      "                "
    ],
    [
      "                ",
      "                ",
      "                ",
      "                ",
      "                ",
      "                ",
      "                ",
      "                ",
      "             床  ",
      "            床巡床 ",
      "             床  ",
      "                ",
      "                ",
      "                ",
      "                ",
      "                "
    ]
  ]
}