{
  "xsize": 16,
  "zsize": 16,
  "palette": {
    "palette": [
      {
        "char": " ",
        "block": "minecraft:air"
      },
      {
        "char": "e",
        "block": "minecraft:quartz_block"
      },
      {
        "char": "d",
        "block": "minecraft:diorite"
      },
      {
        "char": "c",
        "block": "minecraft:smooth_quartz"
      },
      {
        "char": "b",
        "block": "minecraft:polished_diorite"
      },
      {
        "char": "膝",
        "block": "minecraft:cobblestone_wall[east=none,north=none,south=none,up=true,waterlogged=false,weathering=false,west=none]"
      },
      {
        "char": "耻",
        "block": "minecraft:air"
      },
      {
        "char": "a",
        "block": "minecraft:smooth_stone_slab[type=top,waterlogged=false]"
      },
      {
        "char": "Q",
        "block": "minecraft:smooth_stone_slab[type=bottom,waterlogged=false]"
      },
      {
        "char": "r",
        "block": "minecraft:cobblestone_slab[type=top,waterlogged=false,weathering=false]"
      },
      {
        "char": "m",
        "block": "minecraft:vine[east=false,north=true,south=false,up=false,west=false]"
      },
      {
        "char": "q",
        "block": "minecraft:blackstone"
      },
      {
        "char": "h",
        "block": "minecraft:deepslate[axis=y]"
      },
      {
        "char": "g",
        "block": "minecraft:cyan_terracotta"
      },
      {
        "char": "i",
        "block": "minecraft:cobbled_deepslate"
      },
      {
        "char": "f",
        "block": "minecraft:basalt[axis=x]"
      },
      {
        "char": "j",
        "block": "minecraft:vine[east=true,north=false,south=false,up=false,west=false]"
      },
      {
        "char": "C",
        "block": "minecraft:air"
      },
      {
        "char": "喃",
        "block": "minecraft:cobblestone_slab[type=bottom,waterlogged=false,weathering=false]"
      },
      {
        "char": "M",
        "block": "minecraft:air"
      },
      {
        "char": "锁",
        "block": "minecraft:stone_slab[type=bottom,waterlogged=false,weathering=false]"
      },
      {
        "char": "k",
        "block": "minecraft:stone_slab[type=top,waterlogged=false,weathering=false]"
      },
      {
        "char": "槁",
        "block": "minecraft:lever[face=wall,facing=north,powered=false]"
      },
      {
        "char": "赈",
        "block": "minecraft:air"
      },
      {
        "char": "蹼",
        "block": "minecraft:powered_rail[powered=true,shape=ascending_north,waterlogged=false]"
      },
      {
        "char": "峨",
        "block": "minecraft:rail[shape=north_west,waterlogged=false]"
      },
      {
        "char": "桀",
        "block": "minecraft:air"
      },
      {
        "char": "砾",
        "block": "minecraft:air"
      },
      {
        "char": "珈",
        "block": "minecraft:rail[shape=south_west,waterlogged=false]"
      },
      {
        "char": "泷",
        "block": "minecraft:redstone_wall_torch[facing=west,lit=true]"
      }
    ]
  },
  "slices": [
    [
      "edecc       edcc",
      "ebdec 膝      耻 耻",
      "cdddbaa         ",
      "cbbedQQ         ",
      "ecbec           ",
      "cdebe        Qa膝",
      "edcbd        Qr ",
      "dbbdb      膝 膝 膝",
      "mmmm            ",
      "          cedbcb",
      "          dqqhgh",
      "          bihfff",
      "         jbCqhhq",
      "         jbqCfqg",
      "         jehihCi",
      "         jccbbed"
    ],
    [
      "bdcebaa     ebeb",
      "cbcbc喃Q      M耻耻",
      "eeecd           ",
      "dddec           ",
      "bbede           ",
      "cdeeb          锁",
      "eebcd          Q",
      "eecce      膝 膝 膝",
      "mmmm            ",
      "          edbdcd",
      "          chhfiq",
      "          dgChff",
      "         jcfiigq",
      "         jcCiigh",
      "         jchgihq",
      "         jcebccd"
    ],
    [
      "edcdc       dedb",
      "bceec           ",
      "edbde           ",
      "ebcee           ",
      "dcdee           ",
      "cecec           ",
      "beccb           ",
      "ddbbe      膝 膝a喃",
      " mmm          k喃",
      "          bdedcd",
      "          dgqggi",
      "          eCgqiq",
      "          chhiqi",
      "         jdfgqgg",
      "         jeCiqhi",
      "         jcddcdc"
    ],
    [
      "gCfhe       ccde",
      "gqfge           ",
      "hCfCc           ",
      "gqCqc           ",
      "Cihqe           ",
      "hfiib           ",
      "Cqgfb           ",
      "cbcbe      ga锁  ",
      " mmm       aaQ  ",
      "          cqfddb",
      "          cfqihg",
      "          dChgfg",
      "          biiCqC",
      "         jdqffqq",
      "         jdhCiii",
      "         jdhqqfg"
    ],
    [
      "    g       iiff",
      "bd  i           ",
      "槁c  i           ",
      "fc 赈g           ",
      "蹼b  h           ",
      "峨e 桀i           ",
      " b  g           ",
      "dc砾gg           ",
      " mmm            ",
      "          e  bbc",
      "          c     ",
      "          c     ",
      "          d     ",
      "          b   膝 ",
      "          d     ",
      "          c     "
    ],
    [
      "                ",
      "bc              ",
      " e              ",
      "珈bM桀            ",
      "泷c              ",
      " cM桀            ",
      " b              ",
      "bb              ",
      "                ",
      "                ",
      "                ",
      "                ",
      "                ",
      "              hk",
      "              aa",
      "              ra"
    ]
  ]
}