{
  "xsize": 16,
  "zsize": 16,
  "palette": {
    "palette": [
      {
        "char": " ",
        "block": "minecraft:air"
      },
      {
        "char": "c",
        "block": "minecraft:smooth_quartz"
      },
      {
        "char": "d",
        "block": "minecraft:diorite"
      },
      {
        "char": "b",
        "block": "minecraft:polished_diorite"
      },
      {
        "char": "e",
        "block": "minecraft:quartz_block"
      },
      {
        "char": "f",
        "block": "minecraft:basalt[axis=x]"
      },
      {
        "char": "q",
        "block": "minecraft:blackstone"
      },
      {
        "char": "g",
        "block": "minecraft:cyan_terracotta"
      },
      {
        "char": "h",
        "block": "minecraft:deepslate[axis=y]"
      },
      {
        "char": "r",
        "block": "minecraft:cobblestone_slab[type=top,waterlogged=false,weathering=false]"
      },
      {
        "char": "a",
        "block": "minecraft:smooth_stone_slab[type=top,waterlogged=false]"
      },
      {
        "char": "跺",
        "block": "minecraft:oak_stairs[facing=west,half=top,shape=straight,waterlogged=false]"
      },
      {
        "char": "锂",
        "block": "minecraft:oak_slab[type=top,waterlogged=false]"
      },
      {
        "char": "嫦",
        "block": "minecraft:air"
      },
      {
        "char": "G",
        "block": "minecraft:cobblestone_slab[type=double,waterlogged=false,weathering=false]"
      },
      {
        "char": "k",
        "block": "minecraft:stone_slab[type=top,waterlogged=false,weathering=false]"
      }
    ]
  },
  "slices": [
    [
      "                ",
      "                ",
      "                ",
      "                ",
      "                ",
      "                ",
      "                ",
      "                ",
      "                ",
      "                ",
      "                ",
      "                ",
      "                ",
      "                ",
      "                ",
      "                "
    ],
    [
      "                ",
      "                ",
      "                ",
      "                ",
      "                ",
      "                ",
      "                ",
      "                ",
      "                ",
      "                ",
      "                ",
      "                ",
      "                ",
      "                ",
      "                ",
      "                "
    ],
    [
      "                ",
      "                ",
      "                ",
      "                ",
      "                ",
      "                ",
      "                ",
      "                ",
      "                ",
      "                ",
      "                ",
      "                ",
      "                ",
      "                ",
      "                ",
      "                "
    ],
    [
      "                ",
      "                ",
      "                ",
      "                ",
      "                ",
      "                ",
      "                ",
      "                ",
      "                ",
      "                ",
      "                ",
      "                ",
      "                ",
      "                ",
      "                ",
      "                "
    ],
    [
      "cdbbcefbddebbcec",
      "ededceqeecdbccbb",
      "eeeebcgcbdccceec",
      "ddeedegcbbddbceb",
      "beecdcgcdcbcedee",
      "eccecehcbdedcbce",
      "eebeedheccbdbccb",
      "ebbdecgcbdcdbeeb",
      "dcecedhccbcbdbeb",
      "ceedeceecdedbcdc",
      "cdeebdbbecddbccc",
      "cdddedbedbddcdec",
      "cccdebdddebeccce",
      "bcdbedbceccddccc",
      "cdbccceddcccbbed",
      "dcddecbdecebedec"
    ],
    [
      "      cddcbcraah",
      "      debcbca   ",
      "      dcdddea   ",
      "      ebeccef   ",
      "      edcedb跺   ",
      "      cbcbbe锂   ",
      "      ebeedd锂   ",
      "      bbcdde锂   ",
      "      dccedb跺   ",
      "      dceceece嫦b",
      "      d         ",
      "      d         ",
      "      c  G g f  ",
      "      c  a a a  ",
      "      b  k a a  ",
      "      e  a a k  "
    ]
  ]
}