{
  "xsize": 16,
  "zsize": 16,
  "palette": {
    "palette": [
      {
        "char": " ",
        "block": "minecraft:air"
      },
      {
        "char": "y",
        "block": "minecraft:quartz_slab[type=top,waterlogged=false]"
      },
      {
        "char": "z",
        "block": "minecraft:clay"
      },
      {
        "char": "c",
        "block": "minecraft:smooth_quartz"
      },
      {
        "char": "d",
        "block": "minecraft:diorite"
      },
      {
        "char": "N",
        "block": "minecraft:diorite_slab[type=top,waterlogged=false]"
      },
      {
        "char": "j",
        "block": "minecraft:vine[east=true,north=false,south=false,up=false,west=false]"
      },
      {
        "char": "e",
        "block": "minecraft:quartz_block"
      },
      {
        "char": "役",
        "block": "minecraft:dead_fire_coral_block"
      },
      {
        "char": "b",
        "block": "minecraft:polished_diorite"
      },
      {
        "char": "p",
        "block": "minecraft:quartz_pillar[axis=y]"
      },
      {
        "char": "m",
        "block": "minecraft:vine[east=false,north=true,south=false,up=false,west=false]"
      },
      {
        "char": "w",
        "block": "minecraft:quartz_slab[type=bottom,waterlogged=false]"
      },
      {
        "char": "q",
        "block": "minecraft:blackstone"
      },
      {
        "char": "J",
        "block": "minecraft:polished_blackstone"
      },
      {
        "char": "K",
        "block": "minecraft:diorite_slab[type=bottom,waterlogged=false]"
      },
      {
        "char": "I",
        "block": "minecraft:black_concrete"
      },
      {
        "char": "繁",
        "block": "minecraft:cobblestone_wall[east=tall,north=none,south=none,up=true,waterlogged=false,weathering=false,west=none]"
      },
      {
        "char": "捕",
        "block": "minecraft:glass_pane[east=false,north=true,south=false,waterlogged=false,west=false]"
      },
      {
        "char": "H",
        "block": "minecraft:glass_pane[east=false,north=true,south=true,waterlogged=false,west=false]"
      },
      {
        "char": "沿",
        "block": "minecraft:cobblestone_wall[east=tall,north=none,south=tall,up=true,waterlogged=false,weathering=false,west=none]"
      },
      {
        "char": "瀑",
        "block": "minecraft:mossy_cobblestone_wall[east=tall,north=none,south=none,up=true,waterlogged=false,west=none]"
      },
      {
        "char": "g",
        "block": "minecraft:cyan_terracotta"
      }
    ]
  },
  "slices": [
    [
      "              yz",
      "              cd",
      "              yz",
      "              Nz",
      "             jed",
      "              yz",
      "              N役",
      "              bd",
      "             eec",
      "           j ddb",
      "           j bbc",
      "           j  pe",
      "           j    ",
      "            mmm ",
      "                ",
      "                "
    ],
    [
      "              wq",
      "              dd",
      "              wJ",
      "              Kq",
      "             jce",
      "              KI",
      "              wI",
      "              bc",
      "             cee",
      "           j bbb",
      "           j ebc",
      "           j  cc",
      "           j    ",
      "            mmm ",
      "                ",
      "                "
    ],
    [
      "              NJ",
      "              db",
      "              yq",
      "              yq",
      "             jec",
      "              NJ",
      "              yq",
      "              be",
      "             ecc",
      "           j cdc",
      "           j bdd",
      "           j  pe",
      "           j    ",
      "            mmm ",
      "                ",
      "                "
    ],
    [
      "                ",
      "              繁e",
      "               捕",
      "                ",
      "             j繁b",
      "               H",
      "               H",
      "              沿e",
      "             ped",
      "           j dec",
      "           j ped",
      "           j  pd",
      "           j    ",
      "            mmm ",
      "                ",
      "                "
    ],
    [
      "                ",
      "              繁b",
      "               捕",
      "                ",
      "             j瀑e",
      "               H",
      "               H",
      "              沿d",
      "             pee",
      "           j dec",
      "           j dec",
      "           j  pb",
      "           j    ",
      "            mmm ",
      "                ",
      "                "
    ],
    [
      "              w役",
      "              eb",
      "              Kz",
      "              wz",
      "             jbd",
      "              Kg",
      "              wz",
      "              db",
      "             pbe",
      "           j dbb",
      "           j peb",
      "           j  pc",
      "           j    ",
      "            mmm ",
      "                ",
      "                "
    ]
  ]
}