{
  "xsize": 16,
  "zsize": 16,
  "palette": {
    "palette": [
      {
        "char": " ",
        "block": "minecraft:air"
      },
      {
        "char": "v",
        "block": "minecraft:red_terracotta"
      },
      {
        "char": "拭",
        "block": "minecraft:cobblestone_wall[east=low,north=none,south=none,up=false,waterlogged=false,weathering=false,west=low]"
      },
      {
        "char": "e",
        "block": "minecraft:quartz_block"
      },
      {
        "char": "d",
        "block": "minecraft:diorite"
      },
      {
        "char": "c",
        "block": "minecraft:smooth_quartz"
      },
      {
        "char": "b",
        "block": "minecraft:polished_diorite"
      },
      {
        "char": "u",
        "block": "minecraft:red_concrete"
      },
      {
        "char": "j",
        "block": "minecraft:vine[east=true,north=false,south=false,up=false,west=false]"
      },
      {
        "char": "m",
        "block": "minecraft:vine[east=false,north=true,south=false,up=false,west=false]"
      },
      {
        "char": "h",
        "block": "minecraft:deepslate[axis=y]"
      },
      {
        "char": "i",
        "block": "minecraft:cobbled_deepslate"
      },
      {
        "char": "f",
        "block": "minecraft:basalt[axis=x]"
      },
      {
        "char": "q",
        "block": "minecraft:blackstone"
      },
      {
        "char": "C",
        "block": "minecraft:air"
      }
    ]
  },
  "slices": [
    [
      "          v拭ee  ",
      "            dc  ",
      "            bd  ",
      "          u拭cd  ",
      "            cc  ",
      "          v拭de  ",
      "            eb  ",
      "          v拭ed  ",
      "          v eb  ",
      "           jcd  ",
      "           jbd  ",
      "           jdbcd",
      "           jdcbc",
      "            mmm ",
      "                ",
      "                "
    ],
    [
      "          u cd  ",
      "            ed  ",
      "            cd  ",
      "          u cc  ",
      "          u cc  ",
      "          v db  ",
      "            cc  ",
      "          u de  ",
      "            db  ",
      "           jbe  ",
      "           jdc  ",
      "           jdebc",
      "           jcbec",
      "            mmm ",
      "                ",
      "                "
    ],
    [
      "          v dc  ",
      "            ed  ",
      "            dd  ",
      "          u dd  ",
      "            ec  ",
      "          v db  ",
      "            ee  ",
      "          v dd  ",
      "            dd  ",
      "           jbc  ",
      "           jdd  ",
      "           jdcdb",
      "           jecdb",
      "            mmm ",
      "                ",
      "                "
    ],
    [
      "          v bc  ",
      "          v拭bd  ",
      "            cb  ",
      "          v拭ce  ",
      "          v bc  ",
      "          v拭de  ",
      "            de  ",
      "          u拭bd  ",
      "            cb  ",
      "           jbb  ",
      "           jee  ",
      "            ebbd",
      "           jbdec",
      "            mmm ",
      "                ",
      "                "
    ],
    [
      "            ebhi",
      "            dbhf",
      "            bdif",
      "            beqC",
      "            deif",
      "            dbqf",
      "            cdfq",
      "            edhf",
      "            dcCq",
      "           jedqf",
      "            befq",
      "            edde",
      "           jeced",
      "            mmm ",
      "                ",
      "                "
    ],
    [
      "            bebb",
      "            dded",
      "            ecdc",
      "            bceb",
      "            cdeb",
      "            eedc",
      "            cedc",
      "            cdeb",
      "            dcmm",
      "           jee  ",
      "            bc  ",
      "            eede",
      "           jbecd",
      "            mmm ",
      "                ",
      "                "
    ]
  ]
}