{
  "xsize": 16,
  "zsize": 16,
  "palette": {
    "palette": [
      {
        "char": " ",
        "block": "minecraft:air"
      },
      {
        "char": "y",
        "block": "minecraft:quartz_slab[type=top,waterlogged=false]"
      },
      {
        "char": "d",
        "block": "minecraft:diorite"
      },
      {
        "char": "b",
        "block": "minecraft:polished_diorite"
      },
      {
        "char": "c",
        "block": "minecraft:smooth_quartz"
      },
      {
        "char": "e",
        "block": "minecraft:quartz_block"
      },
      {
        "char": "l",
        "block": "minecraft:vine[east=false,north=false,south=false,up=false,west=true]"
      },
      {
        "char": "p",
        "block": "minecraft:quartz_pillar[axis=y]"
      },
      {
        "char": "w",
        "block": "minecraft:quartz_slab[type=bottom,waterlogged=false]"
      },
      {
        "char": "m",
        "block": "minecraft:vine[east=false,north=true,south=false,up=false,west=false]"
      },
      {
        "char": "j",
        "block": "minecraft:vine[east=true,north=false,south=false,up=false,west=false]"
      },
      {
        "char": "训",
        "block": "minecraft:air"
      },
      {
        "char": "N",
        "block": "minecraft:diorite_slab[type=top,waterlogged=false]"
      },
      {
        "char": "伤",
        "block": "minecraft:air",
        "tag": {
          "z": 411,
          "x": -94,
          "ForgeCaps": {},
          "id": "refurbished_furniture:ceiling_light",
          "y": 136,
          "NodePos": "-25838521569144L",
          "Connections": [
            "L"
          ]
        }
      },
      {
        "char": "谱",
        "block": "minecraft:air",
        "tag": {
          "z": 465,
          "x": -59,
          "ForgeCaps": {},
          "id": "refurbished_furniture:ceiling_light",
          "y": 136,
          "NodePos": "-16217794604920L",
          "Connections": [
            "L"
          ]
        }
      },
      {
        "char": "K",
        "block": "minecraft:diorite_slab[type=bottom,waterlogged=false]"
      },
      {
        "char": "k",
        "block": "minecraft:stone_slab[type=top,waterlogged=false,weathering=false]"
      },
      {
        "char": "a",
        "block": "minecraft:smooth_stone_slab[type=top,waterlogged=false]"
      },
      {
        "char": "r",
        "block": "minecraft:cobblestone_slab[type=top,waterlogged=false,weathering=false]"
      },
      {
        "char": "A",
        "block": "minecraft:smooth_stone_slab[type=double,waterlogged=false]"
      },
      {
        "char": "酷",
        "block": "minecraft:air"
      },
      {
        "char": "x",
        "block": "minecraft:redstone_lamp[lit=false]"
      },
      {
        "char": "怨",
        "block": "minecraft:repeater[delay=1,facing=west,locked=false,powered=false]"
      },
      {
        "char": "E",
        "block": "minecraft:redstone_wire[east=side,north=none,power=0,south=none,west=side]"
      },
      {
        "char": "糸",
        "block": "minecraft:repeater[delay=2,facing=west,locked=false,powered=false]"
      }
    ]
  },
  "slices": [
    [
      " ydbbbcecdcel   ",
      " ydedecdbcepl   ",
      " wdcebbccbem    ",
      "     mm jd      ",
      "        j训      ",
      "         训      ",
      "         训 l    ",
      "        j训 l    ",
      "        j训 l    ",
      "         训 l    ",
      "         训 l    ",
      "         训 l    ",
      "        j训      ",
      "         训 l    ",
      "         训 l    ",
      "         训      "
    ],
    [
      " bbdccbedcdcl   ",
      " ccdbececbbpl   ",
      "bdddbcdedbbm    ",
      "N N      c      ",
      "y伤    谱 jd      ",
      " 伤    谱  e      ",
      "         d l    ",
      "        je l    ",
      "        je l    ",
      " 伤    谱  e l    ",
      " 伤    谱  e l    ",
      "         d l    ",
      "        jc      ",
      "         e l    ",
      " 伤    谱  d l    ",
      " 伤    谱  c      "
    ],
    [
      "ccdbdcecbe Kl   ",
      "ddeeebdcbbdpl   ",
      "dedbbbedecdm    ",
      "kakkkaaared     ",
      "aAakkaAaadd     ",
      "aAaraaAkacd     ",
      "kaaaaaakaebl    ",
      "rkaakaraaccl    ",
      "akaaaaaa酷bbl    ",
      "kAaaarArrecl    ",
      "aAaarkAkkcbl    ",
      "aaaakakkaeel    ",
      "aaaakakkaeb     ",
      "rkarakrkabel    ",
      "kAraakAaabcl    ",
      "aAakkaAakdc     "
    ],
    [
      "bdddccedcK  l   ",
      "dddeeeedecw l   ",
      "cbccdbdccdem    ",
      "         bb     ",
      " x    x  db     ",
      "怨xEEE怨x  cb     ",
      "         bcl    ",
      "         bdl    ",
      "         eel    ",
      " x    x  del    ",
      "怨xEEE怨x  cbl    ",
      "         bbl    ",
      "         ec     ",
      "         bbl    ",
      " x    x  dwl    ",
      "糸xEEE怨x  e      "
    ],
    [
      "cbedbeebb   l   ",
      "cebedddcdcdbl   ",
      "deedecbecbcm    ",
      "         db     ",
      "         dc     ",
      "         ec     ",
      "         bel    ",
      "         ddl    ",
      "         eel    ",
      "         bbl    ",
      "         cdl    ",
      "         dcl    ",
      "         eb     ",
      "         cdl    ",
      "         e l    ",
      "         dw     "
    ],
    [
      "ebebbbeddy yl   ",
      "bdbcecbedcbpl   ",
      "ebebdcbceecm    ",
      "         de     ",
      "         cb     ",
      "         bd     ",
      "         cbl    ",
      "         ddl    ",
      "         cel    ",
      "         bbl    ",
      "         ddl    ",
      "         dcl    ",
      "         bb     ",
      "         eel    ",
      "         bwl    ",
      "         d      "
    ]
  ]
}