{
  "xsize": 16,
  "zsize": 16,
  "palette": {
    "palette": [
      {
        "char": " ",
        "block": "minecraft:air"
      },
      {
        "char": "c",
        "block": "minecraft:air"
      },
      {
        "char": "b",
        "block": "minecraft:air"
      },
      {
        "char": "g",
        "block": "minecraft:air"
      },
      {
        "char": "q",
        "block": "minecraft:air"
      },
      {
        "char": "i",
        "block": "minecraft:air"
      },
      {
        "char": "h",
        "block": "minecraft:air"
      },
      {
        "char": "f",
        "block": "minecraft:air"
      },
      {
        "char": "t",
        "block": "minecraft:air"
      },
      {
        "char": "e",
        "block": "minecraft:air"
      },
      {
        "char": "d",
        "block": "minecraft:air"
      },
      {
        "char": "o",
        "block": "minecraft:air"
      },
      {
        "char": "s",
        "block": "minecraft:grass"
      },
      {
        "char": "w",
        "block": "minecraft:air"
      },
      {
        "char": "K",
        "block": "minecraft:air"
      },
      {
        "char": "u",
        "block": "minecraft:air"
      },
      {
        "char": "v",
        "block": "minecraft:air"
      },
      {
        "char": "p",
        "block": "minecraft:air"
      },
      {
        "char": "缰",
        "block": "minecraft:air",
        "tag": {
          "z": 446,
          "x": -20,
          "is_waxed": "0b",
          "ForgeCaps": {
            "supplementaries:antique_ink": {
              "ink": "0b"
            }
          },
          "id": "minecraft:sign",
          "y": 134,
          "front_text": {
            "color": "black",
            "has_glowing_text": "0b",
            "messages": [
              "{\"extra\":[{\"text\":\"DON'T ENTER\"}],\"text\":\"\"}",
              "{\"text\":\"\"}",
              "{\"extra\":[{\"text\":\"DEAD INSIDE\"}],\"text\":\"\"}",
              "{\"text\":\"\"}"
            ]
          },
          "back_text": {
            "color": "black",
            "has_glowing_text": "0b",
            "messages": [
              "{\"text\":\"\"}",
              "{\"text\":\"\"}",
              "{\"text\":\"\"}",
              "{\"text\":\"\"}"
            ]
          }
        }
      },
      {
        "char": "甥",
        "block": "minecraft:air",
        "tag": {
          "z": 447,
          "x": -27,
          "is_waxed": "0b",
          "ForgeCaps": {
            "supplementaries:antique_ink": {
              "ink": "0b"
            }
          },
          "id": "minecraft:sign",
          "y": 134,
          "front_text": {
            "color": "black",
            "has_glowing_text": "0b",
            "messages": [
              "{\"extra\":[{\"text\":\"OVERRUN BY \"}],\"text\":\"\"}",
              "{\"text\":\"\"}",
              "{\"extra\":[{\"text\":\"ZOMBIES\"}],\"text\":\"\"}",
              "{\"text\":\"\"}"
            ]
          },
          "back_text": {
            "color": "black",
            "has_glowing_text": "0b",
            "messages": [
              "{\"text\":\"\"}",
              "{\"text\":\"\"}",
              "{\"text\":\"\"}",
              "{\"text\":\"\"}"
            ]
          }
        }
      }
    ]
  },
  "slices": [
    [
      "cbcgqgihiiiqgfbb",
      "bttghhqqhifiggbe",
      "bdbqgqifttthfttb",
      "dcctfihftfhffhbd",
      "bbcgfqqqggqqifbc",
      "dccfiighggfiqice",
      "cbeqiifftiqihtdd",
      "bdcfqighghihhgeb",
      "bcbhiiftqfqiigdc",
      "oooooooooooooooo",
      "oooooooooooooooo",
      "oooooooooooooooo",
      "oooooooooooooooo",
      "oooooooooooooooo",
      "oooooooooooooooo",
      "oooooooooooooooo"
    ],
    [
      "  s             ",
      " ss             ",
      "        sss  ss ",
      "   ss   s       ",
      "                ",
      "s      s        ",
      "        s    s  ",
      " s         s  sw",
      "      ss  s     ",
      "KKwwwKKwKwKwKwwK",
      "wbeeeebedebcddce",
      "Kebdcdccceeceedc",
      "weeeccbddedddddc",
      "wdcceedecdccceed",
      "Kcceccduuuebedbe",
      "Kbbdeeevuueceeec"
    ],
    [
      "                ",
      "                ",
      "                ",
      "                ",
      "                ",
      "                ",
      "                ",
      "                ",
      "                ",
      "                ",
      " ee           pp",
      " pp           cp",
      "                ",
      "                ",
      "            缰   ",
      "     甥          "
    ],
    [
      "                ",
      "                ",
      "                ",
      "                ",
      "                ",
      "                ",
      "                ",
      "                ",
      "                ",
      "                ",
      " dc           pp",
      " pd           pp",
      "                ",
      "                ",
      "                ",
      "                "
    ],
    [
      "                ",
      "                ",
      "                ",
      "                ",
      "                ",
      "                ",
      "                ",
      "                ",
      "                ",
      "                ",
      " pe           ed",
      " bp           pp",
      "                ",
      "                ",
      "                ",
      "                "
    ],
    [
      "                ",
      "                ",
      "                ",
      "                ",
      "                ",
      "                ",
      "                ",
      "                ",
      "                ",
      "                ",
      " bb           pc",
      " cp           pb",
      "                ",
      "                ",
      "                ",
      "                "
    ]
  ]
}