{
  "xsize": 16,
  "zsize": 16,
  "palette": {
    "palette": [
      {
        "char": " ",
        "block": "minecraft:air"
      },
      {
        "char": "t",
        "block": "minecraft:air"
      },
      {
        "char": "o",
        "block": "minecraft:air"
      },
      {
        "char": "p",
        "block": "minecraft:air"
      },
      {
        "char": "c",
        "block": "minecraft:air"
      },
      {
        "char": "b",
        "block": "minecraft:air"
      },
      {
        "char": "e",
        "block": "minecraft:air"
      },
      {
        "char": "s",
        "block": "minecraft:grass"
      },
      {
        "char": "胡",
        "block": "minecraft:air"
      },
      {
        "char": "j",
        "block": "minecraft:air"
      },
      {
        "char": "d",
        "block": "minecraft:air"
      },
      {
        "char": "瓣",
        "block": "minecraft:air"
      },
      {
        "char": "K",
        "block": "minecraft:air"
      },
      {
        "char": "w",
        "block": "minecraft:air"
      },
      {
        "char": "恁",
        "block": "minecraft:air"
      },
      {
        "char": "劲",
        "block": "minecraft:air"
      },
      {
        "char": "床",
        "block": "minecraft:air"
      },
      {
        "char": "巡",
        "block": "minecraft:air"
      },
      {
        "char": "u",
        "block": "minecraft:air"
      },
      {
        "char": "v",
        "block": "minecraft:air"
      },
      {
        "char": "踵",
        "block": "minecraft:air"
      },
      {
        "char": "唆",
        "block": "minecraft:air"
      },
      {
        "char": "庇",
        "block": "minecraft:air"
      },
      {
        "char": "狩",
        "block": "minecraft:air"
      },
      {
        "char": "擂",
        "block": "minecraft:air"
      },
      {
        "char": "躅",
        "block": "minecraft:air"
      },
      {
        "char": "袅",
        "block": "minecraft:air"
      },
      {
        "char": "竺",
        "block": "minecraft:air"
      },
      {
        "char": "谟",
        "block": "minecraft:air"
      },
      {
        "char": "蒙",
        "block": "minecraft:air"
      },
      {
        "char": "雎",
        "block": "minecraft:air"
      },
      {
        "char": "伟",
        "block": "minecraft:air"
      },
      {
        "char": "m",
        "block": "minecraft:air"
      },
      {
        "char": "调",
        "block": "minecraft:air"
      }
    ]
  },
  "slices": [
    [
      "tttttttttttttooo",
      "ttttottttttotooo",
      "tttttttttttttooo",
      "tttttttttotttooo",
      "tttttttttttooooo",
      "tttottttttttoooo",
      "ttttotttttttoooo",
      "ttttttttotttoooo",
      "ttttttttttttoooo",
      "ttottottttotpppp",
      "tttttttttottpppp",
      "tttttottottocppp",
      "ttttttttttttppcp",
      "ttototttttttbppp",
      "tttttttototopppp",
      "ttttttotttttpepp"
    ],
    [
      "ss胡s胡胡胡sssssjpde",
      "ssss瓣ssssssbsbde",
      "ssssss胡sssssjcpc",
      "ss胡胡胡胡胡ssbssscbd",
      "sssssssssssKedcd",
      "ssscssssss胡sdbce",
      "sssscssssssscbdc",
      "ssssss胡s瓣sssdcdc",
      "sssssssssssseced",
      "sswsswsssswscecb",
      "ssssssssscssbcbd",
      "sssssbssdssccddc",
      "ssssssssssssdedb",
      "sscswsssssssecce",
      "ssssssswswsKbbbd",
      "ssss胡胡bsssssdbbd"
    ],
    [
      "            jpbd",
      "    瓣       jcce",
      "            jpde",
      "             ebd",
      "            eded",
      "      恁劲床劲  bddd",
      "      劲床巡床劲 ecdc",
      "      床巡瓣巡床 bede",
      "      劲床巡床劲 dbee",
      "       劲床劲恁 edbu",
      "            dbbv",
      "            edcu",
      "            bbbv",
      "            ebbc",
      "            becv",
      "            dbdu"
    ],
    [
      "  劲床巡床劲     jppb",
      "  床巡瓣巡床     jcdb",
      "  劲床巡床劲     jppb",
      "   劲床劲恁      wec",
      "            踵唆de",
      "      恁劲床劲恁 庇bbb",
      "      劲床巡床劲 狩擂db",
      "      床巡瓣巡床 躅唆de",
      "      劲床巡床劲 袅竺ce",
      "      恁劲床劲恁 谟蒙dc",
      "            雎唆eb",
      "            庇ecd",
      "            谟蒙dd",
      "            雎唆dc",
      "            袅竺cb",
      "            谟擂bb"
    ],
    [
      "  劲床巡床劲     jced",
      "  床巡瓣巡床     jddb",
      "  劲床巡床劲     jppd",
      "  恁劲床劲        bc",
      "             伟ce",
      "            jdcc",
      "       床巡    mcc",
      "       巡瓣巡    cd",
      "       床巡床   pbb",
      "              db",
      "              ce",
      "            jpde",
      "             调cc",
      "             伟de",
      "            jcdb",
      "  劲床劲恁        bb"
    ],
    [
      "    巡       jppe",
      "   巡瓣巡      jddd",
      "   床巡       jbpc",
      "              eb",
      "             伟ce",
      "            jpce",
      "        床    mdd",
      "       床巡床    bc",
      "        床    pdd",
      "              cd",
      "              db",
      "            jpbd",
      "             调cd",
      "             伟ee",
      "            jpbc",
      "  劲床劲         eb"
    ]
  ]
}