{
  "xsize": 16,
  "zsize": 16,
  "palette": {
    "palette": [
      {
        "char": " ",
        "block": "minecraft:air"
      },
      {
        "char": "b",
        "block": "minecraft:polished_diorite"
      },
      {
        "char": "d",
        "block": "minecraft:diorite"
      },
      {
        "char": "e",
        "block": "minecraft:quartz_block"
      },
      {
        "char": "c",
        "block": "minecraft:smooth_quartz"
      },
      {
        "char": "m",
        "block": "minecraft:vine[east=false,north=true,south=false,up=false,west=false]"
      },
      {
        "char": "f",
        "block": "minecraft:basalt[axis=x]"
      },
      {
        "char": "g",
        "block": "minecraft:cyan_terracotta"
      },
      {
        "char": "q",
        "block": "minecraft:blackstone"
      },
      {
        "char": "h",
        "block": "minecraft:deepslate[axis=y]"
      },
      {
        "char": "i",
        "block": "minecraft:cobbled_deepslate"
      },
      {
        "char": "C",
        "block": "minecraft:air"
      },
      {
        "char": "v",
        "block": "minecraft:red_terracotta"
      },
      {
        "char": "u",
        "block": "minecraft:red_concrete"
      }
    ]
  },
  "slices": [
    [
      "                ",
      "                ",
      "                ",
      "                ",
      "                ",
      "                ",
      "                ",
      "                ",
      "bbdedecbebbdcdeb",
      "eeebdbbeddcebdbb",
      "   mmm          ",
      "                ",
      "                ",
      "                ",
      "                ",
      "                "
    ],
    [
      "                ",
      "                ",
      "                ",
      "                ",
      "                ",
      "                ",
      "                ",
      "                ",
      "beeecbdccbbceddc",
      "bccedbdebbbbebcb",
      "   mmm          ",
      "                ",
      "                ",
      "                ",
      "                ",
      "                "
    ],
    [
      "                ",
      "                ",
      "                ",
      "                ",
      "                ",
      "                ",
      "                ",
      "                ",
      "dccbcdeccbeddcbc",
      "bbcddbceddbbbcec",
      "    mm          ",
      "                ",
      "                ",
      "                ",
      "                ",
      "                "
    ],
    [
      "                ",
      "                ",
      "                ",
      "                ",
      "                ",
      "                ",
      "                ",
      "                ",
      "bdcdcebebcebdbdb",
      "dcbbccccdcbeeddb",
      "                ",
      "                ",
      "                ",
      "                ",
      "                ",
      "                "
    ],
    [
      "ececddcbcbdcecbc",
      "dcbdbedbbccbeecd",
      "ebddedcdbedddecc",
      "fgfqhiqgifiqCggf",
      "iiCiiqiggCghfhih",
      "iChfiiqiqhghgigf",
      "qggiffCfqqghfChq",
      "Ciiihqigfqhhqhhf",
      "eccbbcbcdebcedbc",
      "ddbbddccbebbebde",
      "     v          ",
      "                ",
      "                ",
      "                ",
      "                ",
      "                "
    ],
    [
      "      e  f i g  ",
      "      e         ",
      "      c         ",
      "dcceddceebcbdebb",
      "  mmmmm   mmmmmm",
      "                ",
      "                ",
      "                ",
      "edbbbbbdbbebedbd",
      "ebeeebdbdedeeede",
      "    uvv         ",
      "                ",
      "                ",
      "                ",
      "                ",
      "                "
    ]
  ]
}