{
  "xsize": 16,
  "zsize": 16,
  "palette": {
    "palette": [
      {
        "char": " ",
        "block": "minecraft:air"
      },
      {
        "char": "d",
        "block": "minecraft:air"
      },
      {
        "char": "b",
        "block": "minecraft:air"
      },
      {
        "char": "e",
        "block": "minecraft:air"
      },
      {
        "char": "g",
        "block": "minecraft:air"
      },
      {
        "char": "i",
        "block": "minecraft:air"
      },
      {
        "char": "f",
        "block": "minecraft:air"
      },
      {
        "char": "c",
        "block": "minecraft:air"
      },
      {
        "char": "t",
        "block": "minecraft:air"
      },
      {
        "char": "锁",
        "block": "minecraft:air"
      },
      {
        "char": "h",
        "block": "minecraft:air"
      },
      {
        "char": "q",
        "block": "minecraft:air"
      },
      {
        "char": "o",
        "block": "minecraft:air"
      },
      {
        "char": "s",
        "block": "minecraft:grass"
      },
      {
        "char": "胡",
        "block": "minecraft:air"
      },
      {
        "char": "瓣",
        "block": "minecraft:air"
      },
      {
        "char": "恁",
        "block": "minecraft:air"
      },
      {
        "char": "劲",
        "block": "minecraft:air"
      },
      {
        "char": "床",
        "block": "minecraft:air"
      },
      {
        "char": "巡",
        "block": "minecraft:air"
      }
    ]
  },
  "slices": [
    [
      "dbegiiffcbbttttt",
      "锁锁锁gghffbebttttt",
      "hqfithhgbdbttttt",
      "gqhqfgthbbbttttt",
      "hgiqggihbbdttttt",
      "fqftgiqqcebttttt",
      "bbettqifbcbttttt",
      "cebgfhhgtecttttt",
      "debggg锁锁bebttttt",
      "bbbgqf锁锁beettott",
      "tbbhqigfccbttttt",
      "bcbiithhdeettttt",
      "bectiqqgbbbttttt",
      "bdbfqiihecbttttt",
      "ceeiihigebettttt",
      "dbbigithccettttt"
    ],
    [
      "     锁     sssss",
      "           sssss",
      " s  s      sssss",
      "  锁   s    sssss",
      "        s  sssss",
      "   s       sssss",
      "   ss      sssss",
      "        s ss胡sss",
      "           sssss",
      "           ss瓣ss",
      "s          胡ssss",
      "     s   s sssss",
      "   s       sssss",
      "           sssss",
      "           sssss",
      "      s    sssss"
    ],
    [
      "                ",
      "                ",
      "                ",
      "                ",
      "                ",
      "                ",
      "                ",
      "           恁劲床劲恁",
      "           劲床巡床劲",
      "           床巡瓣巡床",
      "           劲床巡床劲",
      "            劲床劲 ",
      "                ",
      "                ",
      "                ",
      "                "
    ],
    [
      "                ",
      "                ",
      "                ",
      "                ",
      "                ",
      "                ",
      "                ",
      "           恁劲床劲 ",
      "           劲床巡床劲",
      "           床巡瓣巡床",
      "           劲床巡床劲",
      "            劲床劲 ",
      "                ",
      "                ",
      "                ",
      "                "
    ],
    [
      "                ",
      "                ",
      "                ",
      "                ",
      "                ",
      "                ",
      "                ",
      "                ",
      "            床巡  ",
      "            巡瓣巡 ",
      "             巡  ",
      "                ",
      "                ",
      "                ",
      "                ",
      "                "
    ],
    [
      "                ",
      "                ",
      "                ",
      "                ",
      "                ",
      "                ",
      "                ",
      "                ",
      "             床  ",
      "            床巡床 ",
      "             床  ",
      "                ",
      "                ",
      "                ",
      "                ",
      "                "
    ]
  ]
}