{
  "xsize": 16,
  "zsize": 16,
  "palette": {
    "palette": [
      {
        "char": " ",
        "block": "minecraft:air"
      },
      {
        "char": "o",
        "block": "minecraft:air"
      },
      {
        "char": "t",
        "block": "minecraft:air"
      },
      {
        "char": "h",
        "block": "minecraft:air"
      },
      {
        "char": "q",
        "block": "minecraft:air"
      },
      {
        "char": "i",
        "block": "minecraft:air"
      },
      {
        "char": "f",
        "block": "minecraft:air"
      },
      {
        "char": "g",
        "block": "minecraft:air"
      },
      {
        "char": "无",
        "block": "minecraft:air"
      },
      {
        "char": "串",
        "block": "minecraft:air",
        "tag": {
          "SpawnData": {
            "entity": {}
          },
          "MaxNearbyEntities": "6s",
          "MinSpawnDelay": "200s",
          "z": 451,
          "x": -63,
          "MaxSpawnDelay": "800s",
          "RequiredPlayerRange": "16s",
          "SpawnCount": "4s",
          "ForgeCaps": {},
          "id": "minecraft:mob_spawner",
          "SpawnPotentials": [],
          "y": 139,
          "SpawnRange": "4s",
          "Delay": "20s"
        }
      },
      {
        "char": "e",
        "block": "minecraft:air"
      },
      {
        "char": "c",
        "block": "minecraft:air"
      },
      {
        "char": "b",
        "block": "minecraft:air"
      },
      {
        "char": "d",
        "block": "minecraft:air"
      },
      {
        "char": "m",
        "block": "minecraft:air"
      },
      {
        "char": "s",
        "block": "minecraft:grass"
      },
      {
        "char": "嫩",
        "block": "minecraft:air"
      },
      {
        "char": "浚",
        "block": "minecraft:air"
      },
      {
        "char": "弛",
        "block": "minecraft:air"
      },
      {
        "char": "猥",
        "block": "minecraft:air"
      },
      {
        "char": "K",
        "block": "minecraft:air"
      },
      {
        "char": "w",
        "block": "minecraft:air"
      },
      {
        "char": "n",
        "block": "minecraft:air"
      },
      {
        "char": "v",
        "block": "minecraft:air"
      },
      {
        "char": "u",
        "block": "minecraft:air"
      },
      {
        "char": "晒",
        "block": "minecraft:air"
      },
      {
        "char": "讴",
        "block": "minecraft:air"
      },
      {
        "char": "慑",
        "block": "minecraft:air"
      },
      {
        "char": "苳",
        "block": "minecraft:air"
      },
      {
        "char": "箍",
        "block": "minecraft:air"
      },
      {
        "char": "唆",
        "block": "minecraft:air"
      },
      {
        "char": "蒙",
        "block": "minecraft:air"
      },
      {
        "char": "擂",
        "block": "minecraft:air"
      }
    ]
  },
  "slices": [
    [
      "oooooooooooooooo",
      "oooooooooooooooo",
      "oooooooooooooooo",
      "oooooooooooooooo",
      "oooooooooooooooo",
      "oooooooooooooooo",
      "oooooooooooooooo",
      "oooooooooooooooo",
      "tttttttttttttttt",
      "tttttttttttttttt",
      "tttttttttttttttt",
      "hhhhqiiffqqhhqgg",
      "qqitthggffghhghq",
      "gfqfhtqqqgtghgqi",
      "fffqhgffffitghhf",
      "hgqihigthfhhgtiq"
    ],
    [
      "无无无无无无无无无无无无无无无无",
      "无无无无无无无无无无无无无无无无",
      "无无无无无无无串串无无无无无无无",
      "无无无无无无无无无无无无无无无无",
      "无无无无无无无无无无无无无无无无",
      "无无无无无无无无无无无无无无无无",
      "ecbceccdbeddcbbe",
      "bbddcdbcdedececd",
      "mmmsssssssmssmmm",
      "sssssssssssssss嫩",
      "sssmssssssssssss",
      "   s            ",
      "   ss           ",
      "     s    s     ",
      "       s   s    ",
      "       s     s  "
    ],
    [
      " 浚弛 猥弛 猥弛 猥弛 浚弛 ",
      "                ",
      " Kw wK ww wK wK ",
      " cb bd be ce cc ",
      "                ",
      "nnnn nn nnn n nn",
      "vuvuvuuvvuvuuuvu",
      "bdeccdcddbccedeb",
      "mmm     m mmmmm ",
      "                ",
      "   mmm          ",
      "                ",
      "                ",
      "                ",
      "                ",
      "                "
    ],
    [
      "  晒 讴慑 晒   苳    ",
      "                ",
      "                ",
      "                ",
      "                ",
      "nnn   n nnn n nn",
      "eebdebbbccceecbb",
      "dcbbdebbcbecdbee",
      "mmm     m mmmmm ",
      "                ",
      "   mmm          ",
      "                ",
      "                ",
      "                ",
      "                ",
      "                "
    ],
    [
      "                ",
      "                ",
      "                ",
      "                ",
      "                ",
      "nnn   n nnn n nn",
      "bdcbbdcddeebbbcb",
      "bbebbcdbceccbbcb",
      "mmm     m mmmmm ",
      "                ",
      "   mmm          ",
      "                ",
      "                ",
      "                ",
      "                ",
      "                "
    ],
    [
      "                ",
      "                ",
      "                ",
      "                ",
      "                ",
      " nn      nn   n ",
      "箍bb唆唆bc唆唆bc箍箍bb唆",
      "蒙cd蒙蒙cc蒙蒙ec擂蒙bc蒙",
      "mmm     m mmmmm ",
      "                ",
      "   mmm          ",
      "                ",
      "                ",
      "                ",
      "                ",
      "                "
    ]
  ]
}