{
  "xsize": 16,
  "zsize": 16,
  "palette": {
    "palette": [
      {
        "char": " ",
        "block": "minecraft:air"
      },
      {
        "char": "床",
        "block": "minecraft:oak_leaves[distance=2,persistent=false,waterlogged=false]"
      },
      {
        "char": "j",
        "block": "minecraft:vine[east=true,north=false,south=false,up=false,west=false]"
      },
      {
        "char": "p",
        "block": "minecraft:quartz_pillar[axis=y]"
      },
      {
        "char": "b",
        "block": "minecraft:polished_diorite"
      },
      {
        "char": "c",
        "block": "minecraft:smooth_quartz"
      },
      {
        "char": "巡",
        "block": "minecraft:oak_leaves[distance=1,persistent=false,waterlogged=false]"
      },
      {
        "char": "e",
        "block": "minecraft:quartz_block"
      },
      {
        "char": "伟",
        "block": "minecraft:vine[east=true,north=false,south=true,up=false,west=false]"
      },
      {
        "char": "m",
        "block": "minecraft:vine[east=false,north=true,south=false,up=false,west=false]"
      },
      {
        "char": "d",
        "block": "minecraft:diorite"
      },
      {
        "char": "调",
        "block": "minecraft:vine[east=true,north=true,south=false,up=false,west=false]"
      },
      {
        "char": "u",
        "block": "minecraft:red_concrete"
      },
      {
        "char": "v",
        "block": "minecraft:red_terracotta"
      }
    ]
  },
  "slices": [
    [
      "    床       jpbc",
      "   床巡床      jcec",
      "    床       jepb",
      "              eb",
      "             伟eb",
      "            jece",
      "             mdb",
      "              ed",
      "             dbc",
      "              dc",
      "              be",
      "            jpcd",
      "             调ee",
      "             伟be",
      "            jeec",
      "              cb"
    ],
    [
      "            jpdc",
      "            jdee",
      "            jpbe",
      "              ee",
      "             伟bd",
      "            jpdb",
      "             mcb",
      "              ed",
      "             pde",
      "              db",
      "              cc",
      "            jdbb",
      "             调eb",
      "             伟db",
      "            jdee",
      "              eb"
    ],
    [
      "            jppb",
      "            jebc",
      "            jcpc",
      "              dd",
      "             伟ec",
      "            jpeb",
      "             mdc",
      "              db",
      "             pbu",
      "              bv",
      "              dv",
      "            jpdu",
      "             调eu",
      "             伟dv",
      "            jpdu",
      "              cu"
    ],
    [
      "            jppd",
      "            jcdb",
      "            jppb",
      "              be",
      "             伟eb",
      "            jpcc",
      "             mec",
      "              cc",
      "             bbe",
      "              eb",
      "              bc",
      "            jddd",
      "             调bb",
      "             伟bb",
      "            jebc",
      "              de"
    ],
    [
      "            jpee",
      "            jedb",
      "            jcec",
      "              cd",
      "             伟cd",
      "            jpdd",
      "             mdc",
      "              dd",
      "             pcc",
      "              ce",
      "              bc",
      "            jebc",
      "             调ce",
      "             伟bc",
      "            jbcc",
      "              dd"
    ],
    [
      "            jdpd",
      "            jebe",
      "            jpeb",
      "              cb",
      "             伟eb",
      "            jpdd",
      "             mdc",
      "              bd",
      "             pcc",
      "              de",
      "              cc",
      "            jpdd",
      "             调dc",
      "             伟ee",
      "            jpbd",
      "              ee"
    ]
  ]
}