{
  "xsize": 16,
  "zsize": 16,
  "palette": {
    "palette": [
      {
        "char": " ",
        "block": "minecraft:air"
      },
      {
        "char": "c",
        "block": "minecraft:smooth_quartz"
      },
      {
        "char": "e",
        "block": "minecraft:quartz_block"
      },
      {
        "char": "d",
        "block": "minecraft:diorite"
      },
      {
        "char": "j",
        "block": "minecraft:vine[east=true,north=false,south=false,up=false,west=false]"
      },
      {
        "char": "b",
        "block": "minecraft:polished_diorite"
      },
      {
        "char": "伟",
        "block": "minecraft:vine[east=true,north=false,south=true,up=false,west=false]"
      },
      {
        "char": "绮",
        "block": "minecraft:oak_fence[east=false,north=false,south=false,waterlogged=false,west=false]"
      },
      {
        "char": "袱",
        "block": "minecraft:quartz_stairs[facing=east,half=top,shape=straight,waterlogged=false]"
      },
      {
        "char": "w",
        "block": "minecraft:quartz_slab[type=bottom,waterlogged=false]"
      },
      {
        "char": "J",
        "block": "minecraft:polished_blackstone"
      },
      {
        "char": "I",
        "block": "minecraft:black_concrete"
      },
      {
        "char": "K",
        "block": "minecraft:diorite_slab[type=bottom,waterlogged=false]"
      },
      {
        "char": "q",
        "block": "minecraft:blackstone"
      },
      {
        "char": "p",
        "block": "minecraft:quartz_pillar[axis=y]"
      },
      {
        "char": "调",
        "block": "minecraft:vine[east=true,north=true,south=false,up=false,west=false]"
      },
      {
        "char": "m",
        "block": "minecraft:vine[east=false,north=true,south=false,up=false,west=false]"
      },
      {
        "char": "v",
        "block": "minecraft:red_terracotta"
      },
      {
        "char": "u",
        "block": "minecraft:red_concrete"
      },
      {
        "char": "捕",
        "block": "minecraft:glass_pane[east=false,north=true,south=false,waterlogged=false,west=false]"
      },
      {
        "char": "H",
        "block": "minecraft:glass_pane[east=false,north=true,south=true,waterlogged=false,west=false]"
      },
      {
        "char": "涨",
        "block": "minecraft:glass_pane[east=false,north=false,south=true,waterlogged=false,west=false]"
      },
      {
        "char": "z",
        "block": "minecraft:clay"
      },
      {
        "char": "役",
        "block": "minecraft:dead_fire_coral_block"
      },
      {
        "char": "f",
        "block": "minecraft:basalt[axis=x]"
      }
    ]
  },
  "slices": [
    [
      "             cce",
      "             dcd",
      "            jeec",
      "            jbbd",
      "            jbce",
      "             edb",
      "            jdbe",
      "             ecb",
      "             edb",
      "            伟cbb",
      "           j bcb",
      "           j ded",
      "           jjbeb",
      "          绮 袱ccd",
      "          j jdde",
      "            jece"
    ],
    [
      "              wJ",
      "              wI",
      "            j cc",
      "            j KJ",
      "            j wq",
      "              de",
      "            j wq",
      "              KJ",
      "             jbb",
      "            伟 wq",
      "           j  wJ",
      "           j  ec",
      "           jjpde",
      "          wwwcce",
      "          j jceb",
      "             调ec"
    ],
    [
      "               J",
      "                ",
      "            j ec",
      "            j   ",
      "            j  q",
      "              eb",
      "            j  I",
      "                ",
      "             jbc",
      "            伟 m ",
      "           j  jI",
      "           j  dv",
      "           jjpeu",
      "           jjcee",
      "          j  pev",
      "             调bv"
    ],
    [
      "               捕",
      "                ",
      "            j ed",
      "            j  H",
      "            j  H",
      "              pd",
      "            j  H",
      "               H",
      "              pd",
      "            伟  H",
      "           j   H",
      "           j  pd",
      "           jjedc",
      "           jjddb",
      "          j  pee",
      "             调pb"
    ],
    [
      "                ",
      "               涨",
      "            j  d",
      "            j   ",
      "            j   ",
      "              pc",
      "            j  捕",
      "                ",
      "              pe",
      "            伟   ",
      "           j    ",
      "           j  pc",
      "           jjbcd",
      "           jjcbd",
      "          j  pbd",
      "              ee"
    ],
    [
      "               z",
      "               z",
      "            j eb",
      "            j  z",
      "            j  役",
      "              eb",
      "            j  z",
      "               f",
      "              cd",
      "            伟  z",
      "           j   z",
      "           j  be",
      "           jjpcb",
      "           jjede",
      "          j  ped",
      "              cd"
    ]
  ]
}