{
  "xsize": 16,
  "zsize": 16,
  "palette": {
    "palette": [
      {
        "char": " ",
        "block": "minecraft:air"
      },
      {
        "char": "c",
        "block": "minecraft:smooth_quartz"
      },
      {
        "char": "贞",
        "block": "minecraft:stone_brick_stairs[facing=north,half=top,shape=straight,waterlogged=false,weathering=false]"
      },
      {
        "char": "d",
        "block": "minecraft:diorite"
      },
      {
        "char": "e",
        "block": "minecraft:quartz_block"
      },
      {
        "char": "b",
        "block": "minecraft:polished_diorite"
      },
      {
        "char": "闹",
        "block": "minecraft:stone_brick_stairs[facing=south,half=bottom,shape=straight,waterlogged=false,weathering=false]"
      },
      {
        "char": "么",
        "block": "minecraft:stone_brick_stairs[facing=south,half=top,shape=straight,waterlogged=false,weathering=false]"
      },
      {
        "char": "i",
        "block": "minecraft:cobbled_deepslate"
      },
      {
        "char": "G",
        "block": "minecraft:cobblestone_slab[type=double,waterlogged=false,weathering=false]"
      },
      {
        "char": "f",
        "block": "minecraft:basalt[axis=x]"
      },
      {
        "char": "h",
        "block": "minecraft:deepslate[axis=y]"
      },
      {
        "char": "g",
        "block": "minecraft:cyan_terracotta"
      },
      {
        "char": "震",
        "block": "minecraft:stone_brick_stairs[facing=north,half=bottom,shape=straight,waterlogged=false,weathering=false]"
      },
      {
        "char": "q",
        "block": "minecraft:blackstone"
      },
      {
        "char": "C",
        "block": "minecraft:air"
      },
      {
        "char": "a",
        "block": "minecraft:smooth_stone_slab[type=top,waterlogged=false]"
      },
      {
        "char": "k",
        "block": "minecraft:stone_slab[type=top,waterlogged=false,weathering=false]"
      },
      {
        "char": "l",
        "block": "minecraft:vine[east=false,north=false,south=false,up=false,west=true]"
      },
      {
        "char": "r",
        "block": "minecraft:cobblestone_slab[type=top,waterlogged=false,weathering=false]"
      },
      {
        "char": "滂",
        "block": "minecraft:stone_slab[type=top,waterlogged=false,weathering=true]"
      },
      {
        "char": "膝",
        "block": "minecraft:cobblestone_wall[east=none,north=none,south=none,up=true,waterlogged=false,weathering=false,west=none]"
      },
      {
        "char": "耻",
        "block": "minecraft:air"
      },
      {
        "char": "谆",
        "block": "minecraft:mossy_cobblestone_wall[east=none,north=none,south=tall,up=true,waterlogged=false,west=none]"
      },
      {
        "char": "n",
        "block": "minecraft:vine[east=false,north=false,south=true,up=false,west=false]"
      },
      {
        "char": "伟",
        "block": "minecraft:vine[east=true,north=false,south=true,up=false,west=false]"
      }
    ]
  },
  "slices": [
    [
      "      c贞贞贞d   e ",
      "      e       c ",
      "      d       d ",
      "      b       e ",
      "      beecccccd ",
      "                ",
      "                ",
      "                ",
      "                ",
      "                ",
      "                ",
      "                ",
      "                ",
      "                ",
      "                ",
      "                "
    ],
    [
      "      d闹闹闹b么么么d ",
      "      biGfififc ",
      "      bGhggfffb ",
      "      eihgigiGb ",
      "      ebbdeedcc ",
      "                ",
      "                ",
      "                ",
      "                ",
      "                ",
      "                ",
      "                ",
      "                ",
      "                ",
      "                ",
      "                "
    ],
    [
      "      e   b震震震b ",
      "      b       d ",
      "      b       c ",
      "      d       d ",
      "      bcccddcbd ",
      "                ",
      "                ",
      "                ",
      "                ",
      "                ",
      "                ",
      "                ",
      "                ",
      "                ",
      "                ",
      "                "
    ],
    [
      "      e   b   c ",
      "      d       e ",
      "      c       d ",
      "      b       c ",
      "      bcbbedbbb ",
      "                ",
      "                ",
      "                ",
      "                ",
      "                ",
      "                ",
      "                ",
      "                ",
      "                ",
      "                ",
      "                "
    ],
    [
      "fqhgCCe   b   cC",
      "ihifqqe       eg",
      "fgqgiib       cC",
      "qhqghhd       bC",
      "qfgfqfbbbccbcdci",
      "ghCiffhqhhiffhhq",
      "iqqfCqgqfqfifggi",
      "Ciiqqffghifgggfi",
      "qCgfhChghqgfqqif",
      "gfhqqhhfqififqiq",
      "qfqqifqiffgChfih",
      "CfigqqgiChffhhqq",
      "hfiqCffgqfiggqgh",
      "gqhhiiqhghghqqhq",
      "fgghhgqqfgCgqhiq",
      "fCifChqhgihiiiCi"
    ],
    [
      "deeeebbakad   cl",
      "     eekkra   el",
      "     dbaaaa   cl",
      "     bbk滂aa   e ",
      "     ebcbcddddb ",
      " 膝   cebbec     ",
      "     ecebec 耻   ",
      "     ccbced     ",
      " 谆nn伟beeecc 耻   ",
      "cdcecdddddcdebee",
      "ebcddddbdbbbbcde",
      "dbdcecccebebbcdb",
      "dcddccbedceeedce",
      "bcebdbbbccbeebdc",
      "dbbcbedcdebdedeb",
      "dcbcececedceebcc"
    ]
  ]
}