{
  "xsize": 16,
  "zsize": 16,
  "palette": {
    "palette": [
      {
        "char": " ",
        "block": "minecraft:air"
      },
      {
        "char": "b",
        "block": "minecraft:polished_diorite"
      },
      {
        "char": "c",
        "block": "minecraft:smooth_quartz"
      },
      {
        "char": "e",
        "block": "minecraft:quartz_block"
      },
      {
        "char": "d",
        "block": "minecraft:diorite"
      },
      {
        "char": "l",
        "block": "minecraft:vine[east=false,north=false,south=false,up=false,west=true]"
      },
      {
        "char": "m",
        "block": "minecraft:vine[east=false,north=true,south=false,up=false,west=false]"
      },
      {
        "char": "f",
        "block": "minecraft:basalt[axis=x]"
      },
      {
        "char": "i",
        "block": "minecraft:cobbled_deepslate"
      },
      {
        "char": "g",
        "block": "minecraft:cyan_terracotta"
      },
      {
        "char": "q",
        "block": "minecraft:blackstone"
      },
      {
        "char": "h",
        "block": "minecraft:deepslate[axis=y]"
      },
      {
        "char": "C",
        "block": "minecraft:air"
      },
      {
        "char": "膝",
        "block": "minecraft:cobblestone_wall[east=none,north=none,south=none,up=true,waterlogged=false,weathering=false,west=none]"
      }
    ]
  },
  "slices": [
    [
      "     bb         ",
      "     bc         ",
      "     ce         ",
      "     dbl        ",
      "     edl        ",
      "     cel        ",
      "     dcl        ",
      "     de         ",
      "bcbcddc         ",
      "cedebcb         ",
      "mmmm            ",
      "                ",
      "                ",
      "                ",
      "                ",
      "                "
    ],
    [
      "     cb         ",
      "     dd         ",
      "     bd         ",
      "     ecl        ",
      "     cdl        ",
      "     cdl        ",
      "     dcl        ",
      "     cc         ",
      "cbecebc         ",
      "cedbbcc         ",
      "mmmm            ",
      "                ",
      "                ",
      "                ",
      "                ",
      "                "
    ],
    [
      "     bb         ",
      "     cb         ",
      "     de         ",
      "     bcl        ",
      "     cel        ",
      "     ccl        ",
      "     bel        ",
      "     dc         ",
      "ecedccb         ",
      "cecbede         ",
      "mmmm            ",
      "                ",
      "                ",
      "                ",
      "                ",
      "                "
    ],
    [
      "     dc         ",
      "     eb         ",
      "     eb         ",
      "     bbl        ",
      "     eel        ",
      "     cel        ",
      "     bcl        ",
      "     ee         ",
      "bccbded         ",
      "ecbbceb         ",
      "mmmm            ",
      "                ",
      "                ",
      "                ",
      "                ",
      "                "
    ],
    [
      "figigdc         ",
      "qqhgidb         ",
      "iggiqec         ",
      "qCqCice         ",
      "gqifhecl        ",
      "hfhiiebl        ",
      "higChcdl        ",
      "hgffgdc         ",
      "ebddbbc         ",
      "ccbdbec         ",
      "mmmm            ",
      "                ",
      "                ",
      "                ",
      "                ",
      "                "
    ],
    [
      "c    bc         ",
      "e 膝  ec         ",
      "c    cc         ",
      "d    eb         ",
      "     be         ",
      "     ed         ",
      "     eel        ",
      "     bd         ",
      "dbbebbc         ",
      "cdbbbbb         ",
      "mmmm            ",
      "                ",
      "                ",
      "                ",
      "                ",
      "                "
    ]
  ]
}