{
  "xsize": 16,
  "zsize": 16,
  "palette": {
    "palette": [
      {
        "char": " ",
        "block": "minecraft:air"
      },
      {
        "char": "b",
        "block": "minecraft:air"
      },
      {
        "char": "e",
        "block": "minecraft:air"
      },
      {
        "char": "c",
        "block": "minecraft:air"
      },
      {
        "char": "d",
        "block": "minecraft:air"
      },
      {
        "char": "t",
        "block": "minecraft:air"
      },
      {
        "char": "h",
        "block": "minecraft:air"
      },
      {
        "char": "i",
        "block": "minecraft:air"
      },
      {
        "char": "串",
        "block": "minecraft:air",
        "tag": {
          "SpawnData": {
            "entity": {}
          },
          "MaxNearbyEntities": "6s",
          "MinSpawnDelay": "200s",
          "z": 451,
          "x": -63,
          "MaxSpawnDelay": "800s",
          "RequiredPlayerRange": "16s",
          "SpawnCount": "4s",
          "ForgeCaps": {},
          "id": "minecraft:mob_spawner",
          "SpawnPotentials": [],
          "y": 139,
          "SpawnRange": "4s",
          "Delay": "20s"
        }
      },
      {
        "char": "q",
        "block": "minecraft:air"
      },
      {
        "char": "f",
        "block": "minecraft:air"
      },
      {
        "char": "g",
        "block": "minecraft:air"
      },
      {
        "char": "o",
        "block": "minecraft:air"
      },
      {
        "char": "s",
        "block": "minecraft:grass"
      },
      {
        "char": "w",
        "block": "minecraft:air"
      },
      {
        "char": "皈",
        "block": "minecraft:air"
      },
      {
        "char": "K",
        "block": "minecraft:air"
      },
      {
        "char": "n",
        "block": "minecraft:air"
      },
      {
        "char": "p",
        "block": "minecraft:air"
      },
      {
        "char": "伟",
        "block": "minecraft:air"
      },
      {
        "char": "l",
        "block": "minecraft:air"
      },
      {
        "char": "u",
        "block": "minecraft:air"
      },
      {
        "char": "v",
        "block": "minecraft:air"
      }
    ]
  },
  "slices": [
    [
      "bbeecdbdbdbddbdb",
      "tbbbbbdbbbbbbbec",
      "tcbbbccdbbbbbbcb",
      "hi串qftttigfhfiif",
      "q串fqitigffqqhgfg",
      "hqhqgifqqhihqght",
      "qhqgigfifqhfgiot",
      "tgiiqhgigtfiqtqi",
      "iqggfiiqqqfiitgq",
      "qghifqhifggighih",
      "hqgffthfffhifffg",
      "edboebdcbeccdebe",
      "bebbccdbbccdbcdt",
      "bbeedcbdcbecccbb",
      "oottttooottttttt",
      "oooooooooooooooo"
    ],
    [
      "                ",
      "s     wsw       ",
      "s               ",
      " 皈ws sss  ww  w ",
      " w   s s        ",
      "     s wc      s",
      "     w        ds",
      "    e    s d swd",
      "  c w       wss ",
      "       c     c  ",
      "s         bs    ",
      "w  Kw       K sd",
      "cs   nbn     nbs",
      "nn wwsnnn       ",
      "bbssssddbsssssss",
      "epdcdbdcbeccbbce"
    ],
    [
      "                ",
      "                ",
      "                ",
      "                ",
      "                ",
      "                ",
      "                ",
      "                ",
      "                ",
      "       w        ",
      "                ",
      "                ",
      "     nnn     nnn",
      "nn    nnn       ",
      "ep  n伟bdpl     n",
      "epdeedpcuedecbdd"
    ],
    [
      "                ",
      "                ",
      "                ",
      "                ",
      "                ",
      "                ",
      "                ",
      "                ",
      "                ",
      "                ",
      "                ",
      "                ",
      "     nnn     nnn",
      "nn    nnn       ",
      "cp  n伟pcbl     n",
      "cbdbebeevbcdbbcc"
    ],
    [
      "                ",
      "                ",
      "                ",
      "                ",
      "                ",
      "                ",
      "                ",
      "                ",
      "                ",
      "                ",
      "                ",
      "                ",
      "     nnn     nnn",
      "nn    nnn       ",
      "dp  n伟bccl     n",
      "epceccpddddbeedd"
    ],
    [
      "                ",
      "                ",
      "                ",
      "                ",
      "                ",
      "                ",
      "                ",
      "                ",
      "                ",
      "                ",
      "                ",
      "                ",
      "     nnn     nnn",
      "nn    nnn       ",
      "dp  n伟pcpl     n",
      "epcdbepcecbbbecd"
    ]
  ]
}