{
  "xsize": 16,
  "zsize": 16,
  "palette": {
    "palette": [
      {
        "char": " ",
        "block": "minecraft:air"
      },
      {
        "char": "袱",
        "block": "minecraft:quartz_stairs[facing=east,half=top,shape=straight,waterlogged=false]"
      },
      {
        "char": "c",
        "block": "minecraft:smooth_quartz"
      },
      {
        "char": "b",
        "block": "minecraft:polished_diorite"
      },
      {
        "char": "d",
        "block": "minecraft:diorite"
      },
      {
        "char": "e",
        "block": "minecraft:quartz_block"
      },
      {
        "char": "巡",
        "block": "minecraft:oak_leaves[distance=1,persistent=false,waterlogged=false]"
      },
      {
        "char": "瓣",
        "block": "minecraft:oak_log[axis=y]"
      },
      {
        "char": "迵",
        "block": "minecraft:diorite_stairs[facing=east,half=top,shape=outer_left,waterlogged=false]"
      },
      {
        "char": "椎",
        "block": "minecraft:quartz_stairs[facing=north,half=top,shape=straight,waterlogged=false]"
      },
      {
        "char": "床",
        "block": "minecraft:oak_leaves[distance=2,persistent=false,waterlogged=false]"
      },
      {
        "char": "y",
        "block": "minecraft:quartz_slab[type=top,waterlogged=false]"
      },
      {
        "char": "p",
        "block": "minecraft:quartz_pillar[axis=y]"
      },
      {
        "char": "j",
        "block": "minecraft:vine[east=true,north=false,south=false,up=false,west=false]"
      },
      {
        "char": "调",
        "block": "minecraft:vine[east=true,north=true,south=false,up=false,west=false]"
      },
      {
        "char": "m",
        "block": "minecraft:vine[east=false,north=true,south=false,up=false,west=false]"
      },
      {
        "char": "w",
        "block": "minecraft:quartz_slab[type=bottom,waterlogged=false]"
      },
      {
        "char": "u",
        "block": "minecraft:red_concrete"
      },
      {
        "char": "v",
        "block": "minecraft:red_terracotta"
      },
      {
        "char": "箍",
        "block": "minecraft:diorite_stairs[facing=south,half=bottom,shape=straight,waterlogged=false]"
      },
      {
        "char": "竺",
        "block": "minecraft:quartz_pillar[axis=z]"
      },
      {
        "char": "蒙",
        "block": "minecraft:quartz_stairs[facing=north,half=bottom,shape=straight,waterlogged=false]"
      },
      {
        "char": "唆",
        "block": "minecraft:quartz_stairs[facing=south,half=bottom,shape=straight,waterlogged=false]"
      },
      {
        "char": "儸",
        "block": "minecraft:diorite_stairs[facing=east,half=top,shape=straight,waterlogged=false]"
      },
      {
        "char": "袅",
        "block": "minecraft:quartz_stairs[facing=east,half=bottom,shape=straight,waterlogged=false]"
      },
      {
        "char": "庇",
        "block": "minecraft:diorite_stairs[facing=east,half=bottom,shape=straight,waterlogged=false]"
      },
      {
        "char": "N",
        "block": "minecraft:diorite_slab[type=top,waterlogged=false]"
      },
      {
        "char": "佯",
        "block": "minecraft:diorite_stairs[facing=south,half=top,shape=straight,waterlogged=false]"
      },
      {
        "char": "桨",
        "block": "minecraft:diorite_stairs[facing=north,half=top,shape=straight,waterlogged=false]"
      },
      {
        "char": "亥",
        "block": "minecraft:quartz_stairs[facing=south,half=top,shape=straight,waterlogged=false]"
      }
    ]
  },
  "slices": [
    [
      "          袱cbcdc",
      "          袱bbcbd",
      "          袱beecc",
      "   巡      袱ebeed",
      "  巡瓣巡     迵椎椎椎bc",
      "   巡床        ybe",
      "             dcb",
      "             ydb",
      "             pec",
      "             ece",
      "           jjcdc",
      "           jj调bb",
      "           j  de",
      "            mddd",
      "              dd",
      "             pbd"
    ],
    [
      "          j  pcc",
      "              dd",
      "             pdb",
      "   床          dc",
      "  床巡床        pbc",
      "   床          bd",
      "             pbb",
      "              de",
      "             bbc",
      "             cdb",
      "           jjpec",
      "           jjmce",
      "           j  cc",
      "            medb",
      "              cb",
      "             dbe"
    ],
    [
      "          j  wcu",
      "             wev",
      "             wdu",
      "             箍cu",
      "          u  竺du",
      "             蒙du",
      "             wcu",
      "             唆bv",
      "             pev",
      "          u  eev",
      "           jjcdu",
      "           jjmeu",
      "           j  ev",
      "            mpbu",
      "              bu",
      "             pbu"
    ],
    [
      "          j  袱de",
      "              cd",
      "             袱be",
      "              bd",
      "          v  peb",
      "              ed",
      "             儸ce",
      "              de",
      "             pbd",
      "          u  dec",
      "           jjpbb",
      "           jj de",
      "           j  be",
      "            mpce",
      "              bb",
      "             ped"
    ],
    [
      "          j  袅ec",
      "              eb",
      "             袅bc",
      "              de",
      "          v  pbe",
      "              ce",
      "             庇bb",
      "              cc",
      "             pec",
      "          u  cbb",
      "           jjecd",
      "           jj ee",
      "           j  ed",
      "            mpcb",
      "             儸cd",
      "             dec"
    ],
    [
      "          j  ycc",
      "             Ncc",
      "             Ndc",
      "             佯dc",
      "          u  竺ed",
      "             桨dc",
      "             ybb",
      "             亥ce",
      "             pde",
      "          v  ddd",
      "           jjeed",
      "           jj cc",
      "           j  ed",
      "            m亥cc",
      "             竺cd",
      "             椎ec"
    ]
  ]
}