{
  "xsize": 16,
  "zsize": 16,
  "palette": {
    "palette": [
      {
        "char": " ",
        "block": "minecraft:air"
      },
      {
        "char": "d",
        "block": "minecraft:diorite"
      },
      {
        "char": "b",
        "block": "minecraft:polished_diorite"
      },
      {
        "char": "q",
        "block": "minecraft:blackstone"
      },
      {
        "char": "f",
        "block": "minecraft:basalt[axis=x]"
      },
      {
        "char": "i",
        "block": "minecraft:cobbled_deepslate"
      },
      {
        "char": "h",
        "block": "minecraft:deepslate[axis=y]"
      },
      {
        "char": "e",
        "block": "minecraft:quartz_block"
      },
      {
        "char": "t",
        "block": "minecraft:grass_block[snowy=false]"
      },
      {
        "char": "o",
        "block": "minecraft:dirt"
      },
      {
        "char": "g",
        "block": "minecraft:cyan_terracotta"
      },
      {
        "char": "c",
        "block": "minecraft:smooth_quartz"
      },
      {
        "char": "呗",
        "block": "minecraft:white_concrete"
      },
      {
        "char": "x",
        "block": "minecraft:redstone_lamp[lit=false]"
      },
      {
        "char": "锁",
        "block": "minecraft:stone_slab[type=bottom,waterlogged=false,weathering=false]"
      },
      {
        "char": "s",
        "block": "minecraft:air"
      },
      {
        "char": "痣",
        "block": "minecraft:spruce_stairs[facing=east,half=bottom,shape=straight,waterlogged=false]"
      },
      {
        "char": "胡",
        "block": "minecraft:air"
      },
      {
        "char": "瓣",
        "block": "minecraft:oak_log[axis=y]"
      },
      {
        "char": "拧",
        "block": "minecraft:spruce_stairs[facing=south,half=bottom,shape=inner_left,waterlogged=false]"
      },
      {
        "char": "捱",
        "block": "minecraft:birch_trapdoor[facing=north,half=bottom,open=true,powered=false,waterlogged=false]"
      },
      {
        "char": "淅",
        "block": "minecraft:air"
      },
      {
        "char": "芥",
        "block": "minecraft:air"
      },
      {
        "char": "迫",
        "block": "minecraft:air"
      },
      {
        "char": "俎",
        "block": "minecraft:air"
      },
      {
        "char": "酝",
        "block": "minecraft:birch_trapdoor[facing=south,half=bottom,open=true,powered=false,waterlogged=false]"
      },
      {
        "char": "埂",
        "block": "minecraft:birch_trapdoor[facing=west,half=bottom,open=true,powered=false,waterlogged=false]"
      },
      {
        "char": "劲",
        "block": "minecraft:oak_leaves[distance=3,persistent=false,waterlogged=false]"
      },
      {
        "char": "床",
        "block": "minecraft:oak_leaves[distance=2,persistent=false,waterlogged=false]"
      },
      {
        "char": "恁",
        "block": "minecraft:oak_leaves[distance=4,persistent=false,waterlogged=false]"
      },
      {
        "char": "巡",
        "block": "minecraft:oak_leaves[distance=1,persistent=false,waterlogged=false]"
      }
    ]
  },
  "slices": [
    [
      "dbbqfqihebbtottt",
      "bbbhgthhbdctotto",
      "ddditggfbbbtottt",
      "eedq呗f呗ibbctottt",
      "dbef呗q呗idbctottt",
      "eeeq呗t呗ibcbttttt",
      "tqiigqfqbbdttttt",
      "hqfgithgebbttttt",
      "gftitqfheceoxbbb",
      "锁tiiqfghebbedcdb",
      "thgqtigftbebcbbb",
      "qqgighqibcebddde",
      "fifqqfg锁bbeeebbd",
      "gtiqggiidbbceecd",
      "gffht锁锁fbebtxbbb",
      "figtiqhqdtbttttt"
    ],
    [
      "           s痣ss胡",
      "s    s    ss痣胡s瓣",
      "    s      s痣s胡s",
      "           s痣s胡s",
      "s          s拧sss",
      "    ss     sssss",
      "s         胡胡胡胡ss",
      "     s     s捱胡ss",
      "  s锁s    胡淅瓣x芥芥迫",
      " s  s     俎s酝胡  ",
      "ss  s   s 胡 胡   ",
      "                ",
      " s  s锁          ",
      " ss         捱   ",
      "    ss    胡埂x迫迫芥",
      "   s    锁s胡胡酝胡ss"
    ],
    [
      "                ",
      "               瓣",
      "                ",
      "                ",
      "                ",
      "                ",
      "                ",
      "                ",
      "           瓣    ",
      "                ",
      "                ",
      "                ",
      "                ",
      "                ",
      "            胡   ",
      "                "
    ],
    [
      "                ",
      "               瓣",
      "                ",
      "                ",
      "                ",
      "                ",
      "          劲床劲恁  ",
      "         劲床巡床劲  ",
      "         床巡瓣巡床  ",
      "         劲床巡床劲  ",
      "          劲床劲   ",
      "                ",
      "                ",
      "                ",
      "                ",
      "                "
    ],
    [
      "             劲床巡",
      "             床巡瓣",
      "             劲床巡",
      "              劲床",
      "                ",
      "                ",
      "          劲床劲   ",
      "         劲床巡床劲  ",
      "         床巡瓣巡床  ",
      "         劲床巡床劲  ",
      "          劲床劲   ",
      "                ",
      "                ",
      "                ",
      "           劲床劲  ",
      "          劲床巡床劲 "
    ],
    [
      "             劲床巡",
      "             床巡瓣",
      "             劲床巡",
      "              劲床",
      "                ",
      "                ",
      "                ",
      "          床巡床   ",
      "          巡瓣巡   ",
      "           巡床   ",
      "                ",
      "                ",
      "                ",
      "                ",
      "          恁劲床劲  ",
      "          劲床巡床劲 "
    ]
  ]
}