{
  "xsize": 16,
  "zsize": 16,
  "palette": {
    "palette": [
      {
        "char": " ",
        "block": "minecraft:air"
      },
      {
        "char": "j",
        "block": "minecraft:vine[east=true,north=false,south=false,up=false,west=false]"
      },
      {
        "char": "y",
        "block": "minecraft:quartz_slab[type=top,waterlogged=false]"
      },
      {
        "char": "f",
        "block": "minecraft:basalt[axis=x]"
      },
      {
        "char": "袱",
        "block": "minecraft:quartz_stairs[facing=east,half=top,shape=straight,waterlogged=false]"
      },
      {
        "char": "c",
        "block": "minecraft:smooth_quartz"
      },
      {
        "char": "d",
        "block": "minecraft:diorite"
      },
      {
        "char": "z",
        "block": "minecraft:clay"
      },
      {
        "char": "h",
        "block": "minecraft:deepslate[axis=y]"
      },
      {
        "char": "b",
        "block": "minecraft:polished_diorite"
      },
      {
        "char": "p",
        "block": "minecraft:quartz_pillar[axis=y]"
      },
      {
        "char": "e",
        "block": "minecraft:quartz_block"
      },
      {
        "char": "m",
        "block": "minecraft:vine[east=false,north=true,south=false,up=false,west=false]"
      },
      {
        "char": "N",
        "block": "minecraft:diorite_slab[type=top,waterlogged=false]"
      },
      {
        "char": "w",
        "block": "minecraft:quartz_slab[type=bottom,waterlogged=false]"
      },
      {
        "char": "I",
        "block": "minecraft:black_concrete"
      },
      {
        "char": "袅",
        "block": "minecraft:quartz_stairs[facing=east,half=bottom,shape=straight,waterlogged=false]"
      },
      {
        "char": "q",
        "block": "minecraft:blackstone"
      },
      {
        "char": "K",
        "block": "minecraft:diorite_slab[type=bottom,waterlogged=false]"
      },
      {
        "char": "J",
        "block": "minecraft:polished_blackstone"
      },
      {
        "char": "庇",
        "block": "minecraft:diorite_stairs[facing=east,half=bottom,shape=straight,waterlogged=false]"
      },
      {
        "char": "u",
        "block": "minecraft:red_concrete"
      },
      {
        "char": "训",
        "block": "minecraft:air"
      },
      {
        "char": "H",
        "block": "minecraft:glass_pane[east=false,north=true,south=true,waterlogged=false,west=false]"
      },
      {
        "char": "穿",
        "block": "minecraft:air"
      },
      {
        "char": "拭",
        "block": "minecraft:cobblestone_wall[east=low,north=none,south=none,up=false,waterlogged=false,weathering=false,west=low]"
      },
      {
        "char": "飒",
        "block": "minecraft:cobblestone_wall[east=low,north=none,south=low,up=true,waterlogged=false,weathering=false,west=low]"
      },
      {
        "char": "v",
        "block": "minecraft:red_terracotta"
      },
      {
        "char": "翌",
        "block": "minecraft:cobblestone_wall[east=low,north=low,south=none,up=true,waterlogged=false,weathering=false,west=low]"
      }
    ]
  },
  "slices": [
    [
      "          j   yf",
      "             袱cd",
      "              yz",
      "              yh",
      "             袱bd",
      "              yz",
      "              yz",
      "             袱bb",
      "             pde",
      "           j bcc",
      "           j pbb",
      "           j 袱cc",
      "           j  yh",
      "            m yz",
      "             袱ec",
      "              Nz"
    ],
    [
      "          j   wI",
      "            袅wed",
      "              wI",
      "              wq",
      "            袅wed",
      "              KJ",
      "              wJ",
      "            庇wbe",
      "             eed",
      "           j bde",
      "           j pdd",
      "           j袅wbd",
      "           j  wJ",
      "            m wq",
      "            庇wcd",
      "              KJ"
    ],
    [
      "          j     ",
      "              ed",
      "                ",
      "               q",
      "              db",
      "                ",
      "               J",
      "              bu",
      "             pdu",
      "           j bce",
      "           j peu",
      "           j  cu",
      "           j   q",
      "            m   ",
      "              ec",
      "                "
    ],
    [
      "          j    训",
      "              pc",
      "               训",
      "               训",
      "              de",
      "               H",
      "               训",
      "              pd",
      "             pcb",
      "           j ddc",
      "           j pbd",
      "           j  pe",
      "           j   H",
      "            m  训",
      "              bd",
      "               穿"
    ],
    [
      "          j    训",
      "              pb",
      "               训",
      "               训",
      "              pe",
      "               穿",
      "                ",
      "              be",
      "             pcd",
      "           j dde",
      "           j pce",
      "           j  cc",
      "           j   训",
      "            m  训",
      "              pb",
      "               H"
    ],
    [
      "          ju拭拭飒z",
      "              ee",
      "               h",
      "           u拭拭飒z",
      "              bd",
      "           v拭拭翌z",
      "               z",
      "           v拭飒cd",
      "           v pdb",
      "           j dee",
      "           j pee",
      "           j  db",
      "           j   z",
      "            m  z",
      "              eb",
      "               z"
    ]
  ]
}