{
  "xsize": 16,
  "zsize": 16,
  "palette": {
    "palette": [
      {
        "char": " ",
        "block": "minecraft:air"
      },
      {
        "char": "b",
        "block": "minecraft:air"
      },
      {
        "char": "d",
        "block": "minecraft:air"
      },
      {
        "char": "c",
        "block": "minecraft:air"
      },
      {
        "char": "e",
        "block": "minecraft:air"
      },
      {
        "char": "t",
        "block": "minecraft:air"
      },
      {
        "char": "q",
        "block": "minecraft:air"
      },
      {
        "char": "g",
        "block": "minecraft:air"
      },
      {
        "char": "f",
        "block": "minecraft:air"
      },
      {
        "char": "h",
        "block": "minecraft:air"
      },
      {
        "char": "i",
        "block": "minecraft:air"
      },
      {
        "char": "锁",
        "block": "minecraft:air"
      },
      {
        "char": "o",
        "block": "minecraft:air"
      },
      {
        "char": "串",
        "block": "minecraft:air",
        "tag": {
          "SpawnData": {
            "entity": {}
          },
          "MaxNearbyEntities": "6s",
          "MinSpawnDelay": "200s",
          "z": 451,
          "x": -63,
          "MaxSpawnDelay": "800s",
          "RequiredPlayerRange": "16s",
          "SpawnCount": "4s",
          "ForgeCaps": {},
          "id": "minecraft:mob_spawner",
          "SpawnPotentials": [],
          "y": 139,
          "SpawnRange": "4s",
          "Delay": "20s"
        }
      },
      {
        "char": "s",
        "block": "minecraft:grass"
      },
      {
        "char": "w",
        "block": "minecraft:air"
      },
      {
        "char": "舱",
        "block": "minecraft:air"
      },
      {
        "char": "歛",
        "block": "minecraft:air"
      },
      {
        "char": "怯",
        "block": "minecraft:air"
      },
      {
        "char": "慵",
        "block": "minecraft:air"
      },
      {
        "char": "K",
        "block": "minecraft:air"
      },
      {
        "char": "n",
        "block": "minecraft:air"
      },
      {
        "char": "p",
        "block": "minecraft:air"
      },
      {
        "char": "歉",
        "block": "minecraft:air"
      },
      {
        "char": "l",
        "block": "minecraft:air"
      }
    ]
  },
  "slices": [
    [
      "bbdbcebdbbbcbced",
      "dbcbcbbcdbcdbbte",
      "ctbdctbtbetbbbbd",
      "qgfqfqqqhifftgti",
      "ttt锁锁锁ghhfggitft",
      "hf锁锁锁fftgfohfqfh",
      "qq锁qqightgghfigh",
      "iigthftiqiftittq",
      "tfqgigfqqqhtqqtg",
      "qfqiqfqifiigiffi",
      "itqhhghhiiiitfgf",
      "bbeebcebdcdbcebb",
      "cbbddbbbeddcedee",
      "etbeecbcbtd串e串bb",
      "ttttttttooottttt",
      "ttoooooooooottot"
    ],
    [
      "        s       ",
      "              s ",
      " s   s s  s s  s",
      "            s s ",
      "sss          s s",
      "       s  w     ",
      "e    s  s       ",
      "   s  s   ss ss ",
      "舱s         s  s ",
      "歛怯 b  w   ws    ",
      "慵s    s     s   ",
      "sK          w  w",
      "  s      w      ",
      " sw nnnsnnnw K s",
      "sssssssspbp歉ssss",
      "sseedceedbcplsws"
    ],
    [
      "                ",
      "                ",
      "                ",
      "                ",
      "                ",
      "                ",
      "                ",
      "                ",
      "                ",
      "                ",
      "                ",
      "                ",
      "                ",
      "    nnn nnn     ",
      "s      lpdp歉    ",
      "  bbbceceddpl   "
    ],
    [
      "                ",
      "                ",
      "                ",
      "                ",
      "                ",
      "                ",
      "                ",
      "                ",
      "                ",
      "                ",
      "                ",
      "                ",
      "                ",
      "    nnn nnn     ",
      "       lpep歉    ",
      "  dcdccbcccpl   "
    ],
    [
      "                ",
      "                ",
      "                ",
      "                ",
      "                ",
      "                ",
      "                ",
      "                ",
      "                ",
      "                ",
      "                ",
      "                ",
      "                ",
      "    nnn nnn     ",
      "       lpep歉    ",
      "   deedeccdpl   "
    ],
    [
      "                ",
      "                ",
      "                ",
      "                ",
      "                ",
      "                ",
      "                ",
      "                ",
      "                ",
      "                ",
      "                ",
      "                ",
      "                ",
      "    nnn nnn     ",
      "       lcdc歉    ",
      "  eeecececbpl   "
    ]
  ]
}