{
  "xsize": 16,
  "zsize": 16,
  "palette": {
    "palette": [
      {
        "char": " ",
        "block": "minecraft:air"
      },
      {
        "char": "d",
        "block": "minecraft:diorite"
      },
      {
        "char": "c",
        "block": "minecraft:smooth_quartz"
      },
      {
        "char": "e",
        "block": "minecraft:quartz_block"
      },
      {
        "char": "b",
        "block": "minecraft:polished_diorite"
      },
      {
        "char": "m",
        "block": "minecraft:vine[east=false,north=true,south=false,up=false,west=false]"
      },
      {
        "char": "调",
        "block": "minecraft:vine[east=true,north=true,south=false,up=false,west=false]"
      },
      {
        "char": "j",
        "block": "minecraft:vine[east=true,north=false,south=false,up=false,west=false]"
      },
      {
        "char": "g",
        "block": "minecraft:cyan_terracotta"
      },
      {
        "char": "C",
        "block": "minecraft:air"
      },
      {
        "char": "i",
        "block": "minecraft:cobbled_deepslate"
      },
      {
        "char": "f",
        "block": "minecraft:basalt[axis=x]"
      },
      {
        "char": "h",
        "block": "minecraft:deepslate[axis=y]"
      },
      {
        "char": "q",
        "block": "minecraft:blackstone"
      },
      {
        "char": "膝",
        "block": "minecraft:cobblestone_wall[east=none,north=none,south=none,up=true,waterlogged=false,weathering=false,west=none]"
      },
      {
        "char": "M",
        "block": "minecraft:air"
      },
      {
        "char": "a",
        "block": "minecraft:smooth_stone_slab[type=top,waterlogged=false]"
      },
      {
        "char": "r",
        "block": "minecraft:cobblestone_slab[type=top,waterlogged=false,weathering=false]"
      },
      {
        "char": "Q",
        "block": "minecraft:smooth_stone_slab[type=bottom,waterlogged=false]"
      },
      {
        "char": "堐",
        "block": "minecraft:cobblestone_slab[type=bottom,waterlogged=false,weathering=true]"
      }
    ]
  },
  "slices": [
    [
      "                ",
      "                ",
      "                ",
      "                ",
      "                ",
      "                ",
      "                ",
      "                ",
      "                ",
      "                ",
      "                ",
      "dcebde          ",
      "cddcbd          ",
      " mm调be          ",
      "   jbd          ",
      "    ed          "
    ],
    [
      "                ",
      "                ",
      "                ",
      "                ",
      "                ",
      "                ",
      "                ",
      "                ",
      "                ",
      "                ",
      "                ",
      "dcbebc          ",
      "dcdebb          ",
      " mm调ee          ",
      "   jbb          ",
      "    cb          "
    ],
    [
      "                ",
      "                ",
      "                ",
      "                ",
      "                ",
      "                ",
      "                ",
      "                ",
      "                ",
      "                ",
      "                ",
      "cbcbeb          ",
      "decdcc          ",
      " mm调bc          ",
      "   jdd          ",
      "    de          "
    ],
    [
      "                ",
      "                ",
      "                ",
      "                ",
      "                ",
      "                ",
      "                ",
      "                ",
      "                ",
      "                ",
      "                ",
      "ededbc          ",
      "dcdece          ",
      "  m调ec          ",
      "   jcc          ",
      "    ce          "
    ],
    [
      "gCCifhihhihffqfh",
      "fghqhhqqCqifCqiq",
      "fiChiqfqiqqhfqgf",
      "gqifhfhfCigfqiqg",
      "ggqiCihqqhggCChh",
      "ihqiigCCqfghhiCq",
      "CffffCfgigiCqhqg",
      "hiCgqhfqCggfhiqg",
      "fCChqfihihfiqqff",
      "hqhqhiifgiqgiifg",
      "fChiqifigiihqghg",
      "dddbceihhqfiqqqf",
      "bdbdbegqggiqCCii",
      "  m调befhhfhiiqhg",
      "   jcbfhhfqgffig",
      "    cdhgqihCiifh"
    ],
    [
      "cdddc       eeeb",
      "bddcb 膝      M M",
      "dbcdd           ",
      "ecdbb 膝         ",
      "deeecar         ",
      "dbebbQQ    Qa膝 膝",
      "cbccc      堐a   ",
      "bcdbc      膝 膝 膝",
      "mmmm            ",
      "          dbddde",
      "          dccdbd",
      "cddcdc    dedcdc",
      "dccbdd   jbccedb",
      "  m调cb   jddccbd",
      "   jdb   jdbcecb",
      "    cd   jebbecc"
    ]
  ]
}