{
  "xsize": 16,
  "zsize": 16,
  "palette": {
    "palette": [
      {
        "char": " ",
        "block": "minecraft:air"
      },
      {
        "char": "o",
        "block": "minecraft:air"
      },
      {
        "char": "t",
        "block": "minecraft:air"
      },
      {
        "char": "h",
        "block": "minecraft:air"
      },
      {
        "char": "f",
        "block": "minecraft:air"
      },
      {
        "char": "g",
        "block": "minecraft:air"
      },
      {
        "char": "i",
        "block": "minecraft:air"
      },
      {
        "char": "q",
        "block": "minecraft:air"
      },
      {
        "char": "c",
        "block": "minecraft:air"
      },
      {
        "char": "w",
        "block": "minecraft:air"
      },
      {
        "char": "d",
        "block": "minecraft:air"
      },
      {
        "char": "b",
        "block": "minecraft:air"
      },
      {
        "char": "e",
        "block": "minecraft:air"
      },
      {
        "char": "s",
        "block": "minecraft:grass"
      },
      {
        "char": "l",
        "block": "minecraft:air"
      },
      {
        "char": "Q",
        "block": "minecraft:air"
      },
      {
        "char": "锁",
        "block": "minecraft:air"
      },
      {
        "char": "K",
        "block": "minecraft:air"
      },
      {
        "char": "堐",
        "block": "minecraft:air"
      },
      {
        "char": "串",
        "block": "minecraft:air",
        "tag": {
          "SpawnData": {
            "entity": {}
          },
          "MaxNearbyEntities": "6s",
          "MinSpawnDelay": "200s",
          "z": 451,
          "x": -63,
          "MaxSpawnDelay": "800s",
          "RequiredPlayerRange": "16s",
          "SpawnCount": "4s",
          "ForgeCaps": {},
          "id": "minecraft:mob_spawner",
          "SpawnPotentials": [],
          "y": 139,
          "SpawnRange": "4s",
          "Delay": "20s"
        }
      },
      {
        "char": "C",
        "block": "minecraft:air"
      },
      {
        "char": "B",
        "block": "minecraft:air"
      },
      {
        "char": "猾",
        "block": "minecraft:air"
      },
      {
        "char": "染",
        "block": "minecraft:air"
      },
      {
        "char": "蹬",
        "block": "minecraft:air"
      },
      {
        "char": "G",
        "block": "minecraft:air"
      },
      {
        "char": "烤",
        "block": "minecraft:air"
      },
      {
        "char": "m",
        "block": "minecraft:air"
      },
      {
        "char": "y",
        "block": "minecraft:air"
      },
      {
        "char": "r",
        "block": "minecraft:air"
      },
      {
        "char": "k",
        "block": "minecraft:air"
      },
      {
        "char": "褐",
        "block": "minecraft:air"
      },
      {
        "char": "调",
        "block": "minecraft:air"
      },
      {
        "char": "j",
        "block": "minecraft:air"
      },
      {
        "char": "训",
        "block": "minecraft:air"
      },
      {
        "char": "喃",
        "block": "minecraft:air"
      },
      {
        "char": "妃",
        "block": "minecraft:air"
      },
      {
        "char": "p",
        "block": "minecraft:air"
      },
      {
        "char": "拔",
        "block": "minecraft:air"
      },
      {
        "char": "a",
        "block": "minecraft:air"
      },
      {
        "char": "皈",
        "block": "minecraft:air"
      }
    ]
  },
  "slices": [
    [
      "ooooooooooootttt",
      "ooooooooooootttt",
      "oooooooooootttot",
      "ooooooooooottttt",
      "ooooooooooohtfgi",
      "oooooooooooqigqt",
      "ooooooooooohghhq",
      "oooooooooooqigig",
      "ooooooooooogfhtt",
      "ooooooooooogihfh",
      "ooooooooooofigft",
      "oooooooooooffhig",
      "oooooooooooifiit",
      "ooooooooooofqiti",
      "oooooooooooiqtfh",
      "oooooooooooqqqht"
    ],
    [
      "cwdbbbbccebdssss",
      "iiqfghffoecclsss",
      "ihggohhqhddsssws",
      "qftoiigghbQsssss",
      "fiqhgiqqhg锁 sKs ",
      "gqhqfqihgg锁s   s",
      "hqgqtggqfg堐l  s ",
      "ifiqthgfhiQl    ",
      "hqgg串hgCCB猾l  ss",
      "fhfihgifi染Ql    ",
      "ihiq串itiggQl   s",
      "ihiftfihhgQl    ",
      "tqqhqqqqfh蹬   ws",
      "gqfhtfgqhh蹬l ws ",
      "hffthgfqhGQl s 烤",
      "tigifiitqg锁s   s"
    ],
    [
      "  dbeceecddel   ",
      "  ccdbccbbcel   ",
      " eebecdcccem    ",
      "  yKhrk褐调d      ",
      " s mm   j训      ",
      " b w     训s     ",
      "   Qs w  训 l    ",
      "  喃 s  堐j训 l    ",
      " K锁 w   j训 l    ",
      "妃        训 l    ",
      "妃   w s  训 l    ",
      "  w s i  训 l    ",
      "s   QQ喃 j训      ",
      "    s Q  训 l    ",
      "   s     训 l    ",
      "ss     s 训      "
    ],
    [
      " wddbbddedbdl   ",
      "  dddecbcedpl   ",
      "  cbbbddcdem    ",
      "     拔af调e      ",
      "   m    j训      ",
      "         训      ",
      "         训 l    ",
      "        j训 l    ",
      "        j训 l    ",
      "         训 l    ",
      "         训 l    ",
      "         训 l    ",
      "        j训      ",
      "         训 l    ",
      "         训 l    ",
      "         训      "
    ],
    [
      "  dcddbeccdbl   ",
      "  wccedbdddpl   ",
      "   cbdebddbm    ",
      "     mkB调b      ",
      "   m    j训      ",
      "         训      ",
      "         训 l    ",
      "        j训 l    ",
      "        j训 l    ",
      "         训 l    ",
      "         训 l    ",
      "         训 l    ",
      "        j训      ",
      "         训 l    ",
      "         训 l    ",
      "         训      "
    ],
    [
      "   cbbdddeeel   ",
      "  ededcecbbpl   ",
      "  cdceeddccm    ",
      "   皈 mmQjb      ",
      "   m    j训      ",
      "         训      ",
      "         训 l    ",
      "        j训 l    ",
      "        j训 l    ",
      "         训 l    ",
      "         训 l    ",
      "         训 l    ",
      "        j训      ",
      "         训 l    ",
      "         训 l    ",
      "         训      "
    ]
  ]
}