{
  "xsize": 16,
  "zsize": 16,
  "palette": {
    "palette": [
      {
        "char": " ",
        "block": "minecraft:air"
      },
      {
        "char": "N",
        "block": "minecraft:diorite_slab[type=top,waterlogged=false]"
      },
      {
        "char": "z",
        "block": "minecraft:clay"
      },
      {
        "char": "b",
        "block": "minecraft:polished_diorite"
      },
      {
        "char": "c",
        "block": "minecraft:smooth_quartz"
      },
      {
        "char": "y",
        "block": "minecraft:quartz_slab[type=top,waterlogged=false]"
      },
      {
        "char": "j",
        "block": "minecraft:vine[east=true,north=false,south=false,up=false,west=false]"
      },
      {
        "char": "d",
        "block": "minecraft:diorite"
      },
      {
        "char": "p",
        "block": "minecraft:quartz_pillar[axis=y]"
      },
      {
        "char": "e",
        "block": "minecraft:quartz_block"
      },
      {
        "char": "m",
        "block": "minecraft:vine[east=false,north=true,south=false,up=false,west=false]"
      },
      {
        "char": "w",
        "block": "minecraft:quartz_slab[type=bottom,waterlogged=false]"
      },
      {
        "char": "q",
        "block": "minecraft:blackstone"
      },
      {
        "char": "J",
        "block": "minecraft:polished_blackstone"
      },
      {
        "char": "I",
        "block": "minecraft:black_concrete"
      },
      {
        "char": "涨",
        "block": "minecraft:glass_pane[east=false,north=false,south=true,waterlogged=false,west=false]"
      },
      {
        "char": "繁",
        "block": "minecraft:cobblestone_wall[east=tall,north=none,south=none,up=true,waterlogged=false,weathering=false,west=none]"
      },
      {
        "char": "H",
        "block": "minecraft:glass_pane[east=false,north=true,south=true,waterlogged=false,west=false]"
      },
      {
        "char": "瀑",
        "block": "minecraft:mossy_cobblestone_wall[east=tall,north=none,south=none,up=true,waterlogged=false,west=none]"
      },
      {
        "char": "沿",
        "block": "minecraft:cobblestone_wall[east=tall,north=none,south=tall,up=true,waterlogged=false,weathering=false,west=none]"
      },
      {
        "char": "K",
        "block": "minecraft:diorite_slab[type=bottom,waterlogged=false]"
      },
      {
        "char": "i",
        "block": "minecraft:cobbled_deepslate"
      },
      {
        "char": "g",
        "block": "minecraft:cyan_terracotta"
      }
    ]
  },
  "slices": [
    [
      "              Nz",
      "              bc",
      "              yz",
      "              yz",
      "             jcd",
      "              yz",
      "              yz",
      "              bc",
      "             pcc",
      "           j ebc",
      "           j pec",
      "           j  bd",
      "           j    ",
      "            mmm ",
      "                ",
      "                "
    ],
    [
      "              wq",
      "              dd",
      "              wq",
      "              wq",
      "             jcc",
      "              wJ",
      "              wq",
      "              bd",
      "             pde",
      "           j deb",
      "           j pec",
      "           j  ed",
      "           j    ",
      "            mmm ",
      "                ",
      "                "
    ],
    [
      "              yq",
      "              bb",
      "              yJ",
      "              y ",
      "             jdb",
      "              y ",
      "              NI",
      "              de",
      "             pbd",
      "           j edd",
      "           j cee",
      "           j  pc",
      "           j    ",
      "            mmm ",
      "                ",
      "                "
    ],
    [
      "               涨",
      "              繁d",
      "               H",
      "               H",
      "             j瀑c",
      "               H",
      "               H",
      "              沿d",
      "             edb",
      "           j bcb",
      "           j ped",
      "           j  bc",
      "           j    ",
      "            mmm ",
      "                ",
      "                "
    ],
    [
      "               H",
      "              繁d",
      "               H",
      "               H",
      "             j瀑e",
      "                ",
      "               涨",
      "              沿e",
      "             edc",
      "           j eeb",
      "           j pde",
      "           j  pc",
      "           j    ",
      "            mmm ",
      "                ",
      "                "
    ],
    [
      "              wz",
      "              bb",
      "              Ki",
      "              wz",
      "             jde",
      "              Kz",
      "              wg",
      "              cb",
      "             deb",
      "           j ccd",
      "           j peb",
      "           j  bc",
      "           j    ",
      "            mmm ",
      "                ",
      "                "
    ]
  ]
}