{
  "xsize": 16,
  "zsize": 16,
  "palette": {
    "palette": [
      {
        "char": " ",
        "block": "minecraft:air"
      },
      {
        "char": "n",
        "block": "minecraft:vine[east=false,north=false,south=true,up=false,west=false]"
      },
      {
        "char": "b",
        "block": "minecraft:polished_diorite"
      },
      {
        "char": "p",
        "block": "minecraft:quartz_pillar[axis=y]"
      },
      {
        "char": "伟",
        "block": "minecraft:vine[east=true,north=false,south=true,up=false,west=false]"
      },
      {
        "char": "c",
        "block": "minecraft:smooth_quartz"
      },
      {
        "char": "l",
        "block": "minecraft:vine[east=false,north=false,south=false,up=false,west=true]"
      },
      {
        "char": "e",
        "block": "minecraft:quartz_block"
      },
      {
        "char": "d",
        "block": "minecraft:diorite"
      },
      {
        "char": "w",
        "block": "minecraft:quartz_slab[type=bottom,waterlogged=false]"
      }
    ]
  },
  "slices": [
    [
      "                ",
      "                ",
      "                ",
      "                ",
      "                ",
      "                ",
      "                ",
      "                ",
      "                ",
      "                ",
      "                ",
      "                ",
      "     nnn     nnn",
      "nn    nnn       ",
      "bp  n伟pcpl      ",
      "epdeddpeeedcdbbe"
    ],
    [
      "                ",
      "                ",
      "                ",
      "                ",
      "                ",
      "                ",
      "                ",
      "                ",
      "                ",
      "                ",
      "                ",
      "                ",
      "     nnn     nnn",
      "nn    nnn       ",
      "ep  n伟pepl     w",
      "deebdcpcdecbdebb"
    ],
    [
      "                ",
      "                ",
      "                ",
      "                ",
      "                ",
      "                ",
      "                ",
      "                ",
      "                ",
      "                ",
      "                ",
      "                ",
      "     nnn     nnn",
      "nn    nnn       ",
      "be  n伟cdpl      ",
      "epdceedbbbededdc"
    ],
    [
      "                ",
      "                ",
      "                ",
      "                ",
      "                ",
      "                ",
      "                ",
      "                ",
      "                ",
      "                ",
      "                ",
      "                ",
      "     nnn     nnn",
      "nn    nnn       ",
      "de  n伟pdpl      ",
      "cpbdeepdeeccbdbe"
    ],
    [
      "                ",
      "                ",
      "                ",
      "                ",
      "                ",
      "                ",
      "                ",
      "                ",
      "                ",
      "                ",
      "                ",
      "                ",
      "     nnn     nnn",
      "nn    nnn       ",
      "ee  n伟ebpl      ",
      "bpbccepbdcccdbbe"
    ],
    [
      "                ",
      "                ",
      "                ",
      "                ",
      "                ",
      "                ",
      "                ",
      "                ",
      "                ",
      "                ",
      "                ",
      "                ",
      "     nnn     nnn",
      "nn    nnn       ",
      "cp  n伟pdel      ",
      "bpcddbcddebbbcbc"
    ]
  ]
}