{
  "xsize": 16,
  "zsize": 16,
  "palette": {
    "palette": [
      {
        "char": " ",
        "block": "minecraft:air"
      },
      {
        "char": "y",
        "block": "minecraft:quartz_slab[type=top,waterlogged=false]"
      },
      {
        "char": "z",
        "block": "minecraft:clay"
      },
      {
        "char": "d",
        "block": "minecraft:diorite"
      },
      {
        "char": "e",
        "block": "minecraft:quartz_block"
      },
      {
        "char": "j",
        "block": "minecraft:vine[east=true,north=false,south=false,up=false,west=false]"
      },
      {
        "char": "b",
        "block": "minecraft:polished_diorite"
      },
      {
        "char": "N",
        "block": "minecraft:diorite_slab[type=top,waterlogged=false]"
      },
      {
        "char": "役",
        "block": "minecraft:dead_fire_coral_block"
      },
      {
        "char": "p",
        "block": "minecraft:quartz_pillar[axis=y]"
      },
      {
        "char": "c",
        "block": "minecraft:smooth_quartz"
      },
      {
        "char": "m",
        "block": "minecraft:vine[east=false,north=true,south=false,up=false,west=false]"
      },
      {
        "char": "w",
        "block": "minecraft:quartz_slab[type=bottom,waterlogged=false]"
      },
      {
        "char": "J",
        "block": "minecraft:polished_blackstone"
      },
      {
        "char": "I",
        "block": "minecraft:black_concrete"
      },
      {
        "char": "K",
        "block": "minecraft:diorite_slab[type=bottom,waterlogged=false]"
      },
      {
        "char": "q",
        "block": "minecraft:blackstone"
      },
      {
        "char": "繁",
        "block": "minecraft:cobblestone_wall[east=tall,north=none,south=none,up=true,waterlogged=false,weathering=false,west=none]"
      },
      {
        "char": "H",
        "block": "minecraft:glass_pane[east=false,north=true,south=true,waterlogged=false,west=false]"
      },
      {
        "char": "捕",
        "block": "minecraft:glass_pane[east=false,north=true,south=false,waterlogged=false,west=false]"
      },
      {
        "char": "沿",
        "block": "minecraft:cobblestone_wall[east=tall,north=none,south=tall,up=true,waterlogged=false,weathering=false,west=none]"
      },
      {
        "char": "瀑",
        "block": "minecraft:mossy_cobblestone_wall[east=tall,north=none,south=none,up=true,waterlogged=false,west=none]"
      },
      {
        "char": "f",
        "block": "minecraft:basalt[axis=x]"
      },
      {
        "char": "g",
        "block": "minecraft:cyan_terracotta"
      },
      {
        "char": "i",
        "block": "minecraft:cobbled_deepslate"
      }
    ]
  },
  "slices": [
    [
      "              yz",
      "              de",
      "              yz",
      "              yz",
      "             jeb",
      "              Nz",
      "              N役",
      "              bd",
      "             pbc",
      "           j bbc",
      "           j pec",
      "           j  pb",
      "           j    ",
      "            mmm ",
      "                ",
      "                "
    ],
    [
      "              wJ",
      "              dd",
      "              wI",
      "              Kq",
      "             jee",
      "              wI",
      "              wI",
      "              cb",
      "             pdd",
      "           j dbb",
      "           j ccc",
      "           j  dc",
      "           j    ",
      "            mmm ",
      "                ",
      "                "
    ],
    [
      "              yq",
      "              bb",
      "              yI",
      "              N ",
      "             jbc",
      "              y ",
      "              yI",
      "              ec",
      "             cdd",
      "           j dbc",
      "           j pcc",
      "           j  pd",
      "           j    ",
      "            mmm ",
      "                ",
      "                "
    ],
    [
      "                ",
      "              繁b",
      "               H",
      "               H",
      "             j繁c",
      "               捕",
      "                ",
      "              沿c",
      "             pee",
      "           j eec",
      "           j cdb",
      "           j  de",
      "           j    ",
      "            mmm ",
      "                ",
      "                "
    ],
    [
      "               H",
      "              繁b",
      "               H",
      "               H",
      "             j瀑c",
      "               H",
      "               H",
      "              沿c",
      "             ebd",
      "           j bbc",
      "           j bee",
      "           j  pe",
      "           j    ",
      "            mmm ",
      "                ",
      "                "
    ],
    [
      "              wz",
      "              db",
      "              wz",
      "              wf",
      "             jcb",
      "              wg",
      "              Ki",
      "              ed",
      "             eeb",
      "           j dbc",
      "           j pbb",
      "           j  ee",
      "           j    ",
      "            mmm ",
      "                ",
      "                "
    ]
  ]
}