{
  "xsize": 16,
  "zsize": 16,
  "palette": {
    "palette": [
      {
        "char": " ",
        "block": "minecraft:air"
      },
      {
        "char": "j",
        "block": "minecraft:vine[east=true,north=false,south=false,up=false,west=false]"
      },
      {
        "char": "y",
        "block": "minecraft:quartz_slab[type=top,waterlogged=false]"
      },
      {
        "char": "z",
        "block": "minecraft:clay"
      },
      {
        "char": "e",
        "block": "minecraft:quartz_block"
      },
      {
        "char": "b",
        "block": "minecraft:polished_diorite"
      },
      {
        "char": "f",
        "block": "minecraft:basalt[axis=x]"
      },
      {
        "char": "N",
        "block": "minecraft:diorite_slab[type=top,waterlogged=false]"
      },
      {
        "char": "m",
        "block": "minecraft:vine[east=false,north=true,south=false,up=false,west=false]"
      },
      {
        "char": "d",
        "block": "minecraft:diorite"
      },
      {
        "char": "c",
        "block": "minecraft:smooth_quartz"
      },
      {
        "char": "K",
        "block": "minecraft:diorite_slab[type=bottom,waterlogged=false]"
      },
      {
        "char": "I",
        "block": "minecraft:black_concrete"
      },
      {
        "char": "q",
        "block": "minecraft:blackstone"
      },
      {
        "char": "w",
        "block": "minecraft:quartz_slab[type=bottom,waterlogged=false]"
      },
      {
        "char": "J",
        "block": "minecraft:polished_blackstone"
      },
      {
        "char": "捕",
        "block": "minecraft:glass_pane[east=false,north=true,south=false,waterlogged=false,west=false]"
      },
      {
        "char": "繁",
        "block": "minecraft:cobblestone_wall[east=tall,north=none,south=none,up=true,waterlogged=false,weathering=false,west=none]"
      },
      {
        "char": "H",
        "block": "minecraft:glass_pane[east=false,north=true,south=true,waterlogged=false,west=false]"
      },
      {
        "char": "瀑",
        "block": "minecraft:mossy_cobblestone_wall[east=tall,north=none,south=none,up=true,waterlogged=false,west=none]"
      },
      {
        "char": "涨",
        "block": "minecraft:glass_pane[east=false,north=false,south=true,waterlogged=false,west=false]"
      },
      {
        "char": "h",
        "block": "minecraft:deepslate[axis=y]"
      },
      {
        "char": "g",
        "block": "minecraft:cyan_terracotta"
      }
    ]
  },
  "slices": [
    [
      "           j  yz",
      "              yz",
      "              eb",
      "           j  yf",
      "         j    Nz",
      "          mj jbd",
      "              yf",
      "              yz",
      "             jec",
      "              Nz",
      "              yz",
      "             jde",
      "              yf",
      "              yz",
      "             jee",
      "              yz"
    ],
    [
      "           j  KI",
      "              Kq",
      "              cc",
      "           j  wI",
      "         j    wq",
      "          mj jcc",
      "              wJ",
      "              wq",
      "             jbb",
      "              wI",
      "              KJ",
      "             jbc",
      "              wq",
      "              wI",
      "             jbd",
      "              KI"
    ],
    [
      "           j  yq",
      "              y ",
      "              ee",
      "           j  y ",
      "         j    yq",
      "          mj jbe",
      "              yJ",
      "              y ",
      "             jee",
      "              N ",
      "              NI",
      "             jdd",
      "              yq",
      "              y ",
      "             jbd",
      "              y "
    ],
    [
      "           j   捕",
      "                ",
      "              繁c",
      "           j   H",
      "         j     H",
      "          mj j瀑d",
      "               捕",
      "                ",
      "             j繁c",
      "               H",
      "               H",
      "             j瀑c",
      "                ",
      "               涨",
      "             j繁d",
      "               H"
    ],
    [
      "           j   H",
      "               H",
      "              繁c",
      "           j   H",
      "         j     H",
      "          mj j繁e",
      "               H",
      "               H",
      "             j瀑d",
      "                ",
      "                ",
      "             j繁c",
      "               H",
      "               H",
      "             j繁c",
      "               捕"
    ],
    [
      "           j  wz",
      "              wz",
      "              bc",
      "           j  wh",
      "         j    wz",
      "          mj jde",
      "              Kz",
      "              Kz",
      "             jbe",
      "              wz",
      "              Kz",
      "             jbb",
      "              wz",
      "              Kg",
      "             jdc",
      "              wz"
    ]
  ]
}