{
  "xsize": 16,
  "zsize": 16,
  "palette": {
    "palette": [
      {
        "char": " ",
        "block": "minecraft:air"
      },
      {
        "char": "j",
        "block": "minecraft:vine[east=true,north=false,south=false,up=false,west=false]"
      },
      {
        "char": "p",
        "block": "minecraft:quartz_pillar[axis=y]"
      },
      {
        "char": "c",
        "block": "minecraft:smooth_quartz"
      },
      {
        "char": "e",
        "block": "minecraft:quartz_block"
      },
      {
        "char": "d",
        "block": "minecraft:diorite"
      },
      {
        "char": "b",
        "block": "minecraft:polished_diorite"
      },
      {
        "char": "伟",
        "block": "minecraft:vine[east=true,north=false,south=true,up=false,west=false]"
      },
      {
        "char": "m",
        "block": "minecraft:vine[east=false,north=true,south=false,up=false,west=false]"
      },
      {
        "char": "调",
        "block": "minecraft:vine[east=true,north=true,south=false,up=false,west=false]"
      },
      {
        "char": "u",
        "block": "minecraft:red_concrete"
      },
      {
        "char": "v",
        "block": "minecraft:red_terracotta"
      },
      {
        "char": "y",
        "block": "minecraft:quartz_slab[type=top,waterlogged=false]"
      },
      {
        "char": "w",
        "block": "minecraft:quartz_slab[type=bottom,waterlogged=false]"
      },
      {
        "char": "N",
        "block": "minecraft:diorite_slab[type=top,waterlogged=false]"
      }
    ]
  },
  "slices": [
    [
      "            jpce",
      "            jccd",
      "            jpdd",
      "              bd",
      "             伟db",
      "            jebe",
      "             mdc",
      "              ee",
      "             pee",
      "              cb",
      "              bd",
      "            jpcd",
      "             调de",
      "             伟bd",
      "            jpeb",
      "             bcd"
    ],
    [
      "            jpbc",
      "            jbee",
      "            jcpe",
      "              dc",
      "             伟bd",
      "            jceb",
      "             mdc",
      "              ed",
      "             bdb",
      "              de",
      "              ec",
      "            jddc",
      "             调de",
      "             伟ce",
      "            jcbb",
      "             mdd"
    ],
    [
      "            jpbb",
      "            jbcc",
      "            jppd",
      "              ce",
      "             伟cc",
      "            jpeb",
      "             mcd",
      "              cc",
      "             bbu",
      "              bv",
      "              bu",
      "            jpbu",
      "             调du",
      "             伟ev",
      "            jpcu",
      "             mcv"
    ],
    [
      "            jppd",
      "            jdcb",
      "            jppe",
      "              cc",
      "             伟dc",
      "            jpbc",
      "             mdb",
      "              dc",
      "             pbb",
      "              dd",
      "              dd",
      "              cc",
      "             jde",
      "             伟ed",
      "            jccc",
      "             mcd"
    ],
    [
      "            jppc",
      "            jbcb",
      "             pcb",
      "              bd",
      "             伟cb",
      "            jpbe",
      "              eb",
      "              db",
      "              yb",
      "               e",
      "               b",
      "              wb",
      "             j c",
      "             伟ce",
      "            jpee",
      "             mpe"
    ],
    [
      "            jepc",
      "            jedb",
      "             dpd",
      "              be",
      "             伟dd",
      "            jpdc",
      "              db",
      "               w",
      "                ",
      "               N",
      "                ",
      "               y",
      "             j d",
      "             伟cc",
      "            jbec",
      "             med"
    ]
  ]
}