{
  "xsize": 16,
  "zsize": 16,
  "palette": {
    "palette": [
      {
        "char": " ",
        "block": "minecraft:air"
      },
      {
        "char": "j",
        "block": "minecraft:vine[east=true,north=false,south=false,up=false,west=false]"
      },
      {
        "char": "y",
        "block": "minecraft:quartz_slab[type=top,waterlogged=false]"
      },
      {
        "char": "z",
        "block": "minecraft:clay"
      },
      {
        "char": "e",
        "block": "minecraft:quartz_block"
      },
      {
        "char": "c",
        "block": "minecraft:smooth_quartz"
      },
      {
        "char": "N",
        "block": "minecraft:diorite_slab[type=top,waterlogged=false]"
      },
      {
        "char": "m",
        "block": "minecraft:vine[east=false,north=true,south=false,up=false,west=false]"
      },
      {
        "char": "b",
        "block": "minecraft:polished_diorite"
      },
      {
        "char": "役",
        "block": "minecraft:dead_fire_coral_block"
      },
      {
        "char": "d",
        "block": "minecraft:diorite"
      },
      {
        "char": "C",
        "block": "minecraft:air"
      },
      {
        "char": "w",
        "block": "minecraft:quartz_slab[type=bottom,waterlogged=false]"
      },
      {
        "char": "J",
        "block": "minecraft:polished_blackstone"
      },
      {
        "char": "q",
        "block": "minecraft:blackstone"
      },
      {
        "char": "K",
        "block": "minecraft:diorite_slab[type=bottom,waterlogged=false]"
      },
      {
        "char": "I",
        "block": "minecraft:black_concrete"
      },
      {
        "char": "H",
        "block": "minecraft:glass_pane[east=false,north=true,south=true,waterlogged=false,west=false]"
      },
      {
        "char": "繁",
        "block": "minecraft:cobblestone_wall[east=tall,north=none,south=none,up=true,waterlogged=false,weathering=false,west=none]"
      },
      {
        "char": "瀑",
        "block": "minecraft:mossy_cobblestone_wall[east=tall,north=none,south=none,up=true,waterlogged=false,west=none]"
      },
      {
        "char": "捕",
        "block": "minecraft:glass_pane[east=false,north=true,south=false,waterlogged=false,west=false]"
      },
      {
        "char": "涨",
        "block": "minecraft:glass_pane[east=false,north=false,south=true,waterlogged=false,west=false]"
      },
      {
        "char": "h",
        "block": "minecraft:deepslate[axis=y]"
      }
    ]
  },
  "slices": [
    [
      "           j  yz",
      "              yz",
      "              ec",
      "           j  Nz",
      "         j    yz",
      "          mj jbe",
      "              N役",
      "              yz",
      "             jbe",
      "              yz",
      "              yz",
      "             jdb",
      "              yz",
      "              yC",
      "             jcc",
      "              Nz"
    ],
    [
      "           j  wJ",
      "              wq",
      "              dc",
      "           j  KI",
      "         j    wI",
      "          mj jcd",
      "              wq",
      "              KJ",
      "             jdd",
      "              wq",
      "              wJ",
      "             jcd",
      "              wq",
      "              wI",
      "             jdc",
      "              wJ"
    ],
    [
      "           j  NI",
      "              yJ",
      "              de",
      "           j  Nq",
      "         j    yJ",
      "          mj jcd",
      "              yJ",
      "              yJ",
      "             jec",
      "              yq",
      "              yI",
      "             jeb",
      "              NJ",
      "              yq",
      "             jcc",
      "              yI"
    ],
    [
      "           j   H",
      "               H",
      "              繁e",
      "           j    ",
      "         j      ",
      "          mj j繁d",
      "               H",
      "               H",
      "             j瀑d",
      "               捕",
      "                ",
      "             j繁c",
      "               H",
      "               H",
      "             j瀑b",
      "               捕"
    ],
    [
      "           j   H",
      "               H",
      "              繁b",
      "           j    ",
      "         j     涨",
      "          mj j繁e",
      "               捕",
      "                ",
      "             j瀑e",
      "               捕",
      "                ",
      "             j瀑d",
      "               H",
      "               H",
      "             j瀑b",
      "               捕"
    ],
    [
      "           j  w役",
      "              wh",
      "              bb",
      "           j  Kz",
      "         j    wz",
      "          mj jcb",
      "              Kz",
      "              Kz",
      "             jcb",
      "              wq",
      "              wz",
      "             jbb",
      "              wz",
      "              wz",
      "             jbd",
      "              wz"
    ]
  ]
}