{
  "xsize": 16,
  "zsize": 16,
  "palette": {
    "palette": [
      {
        "char": " ",
        "block": "minecraft:air"
      },
      {
        "char": "役",
        "block": "minecraft:dead_fire_coral_block"
      },
      {
        "char": "e",
        "block": "minecraft:quartz_block"
      },
      {
        "char": "i",
        "block": "minecraft:cobbled_deepslate"
      },
      {
        "char": "z",
        "block": "minecraft:clay"
      },
      {
        "char": "b",
        "block": "minecraft:polished_diorite"
      },
      {
        "char": "帷",
        "block": "minecraft:diorite_slab[type=double,waterlogged=false]"
      },
      {
        "char": "皈",
        "block": "minecraft:quartz_slab[type=double,waterlogged=false]"
      },
      {
        "char": "w",
        "block": "minecraft:quartz_slab[type=bottom,waterlogged=false]"
      },
      {
        "char": "y",
        "block": "minecraft:quartz_slab[type=top,waterlogged=false]"
      },
      {
        "char": "x",
        "block": "minecraft:redstone_lamp[lit=false]"
      },
      {
        "char": "c",
        "block": "minecraft:smooth_quartz"
      },
      {
        "char": "N",
        "block": "minecraft:diorite_slab[type=top,waterlogged=false]"
      },
      {
        "char": "d",
        "block": "minecraft:diorite"
      },
      {
        "char": "摸",
        "block": "minecraft:repeater[delay=1,facing=south,locked=false,powered=false]"
      },
      {
        "char": "h",
        "block": "minecraft:deepslate[axis=y]"
      },
      {
        "char": "f",
        "block": "minecraft:basalt[axis=x]"
      },
      {
        "char": "C",
        "block": "minecraft:air"
      },
      {
        "char": "g",
        "block": "minecraft:cyan_terracotta"
      },
      {
        "char": "q",
        "block": "minecraft:blackstone"
      }
    ]
  },
  "slices": [
    [
      "役eizbz帷         ",
      "      皈ww       ",
      "       皈        ",
      "        帷zy     ",
      "     x   zy     ",
      "         cb     ",
      "         zN     ",
      "         zy     ",
      "         db     ",
      "         役y     ",
      "         役N     ",
      "     x   db     ",
      "x    摸   hy     ",
      "         fy     ",
      "         cc     ",
      "         zy     "
    ],
    [
      "CfCgCgh         ",
      "gqihqih         ",
      "hCCgqhif w      ",
      "fqCgfhifqfq     ",
      "qhffgCgghgge    ",
      "igqfihgqCqfd    ",
      "ggiCiiqqhffc    ",
      "qqhgqiggihhb    ",
      "gihifgighfCe    ",
      "ihCCgigiifqc    ",
      "hffhgCqiiffb    ",
      "iCqgqCCCggie    ",
      "fqChhqqqhhhc    ",
      "fhiqghfiChCe    ",
      "iqiffffffhgd    ",
      "ffggiChfCfib    "
    ],
    [
      "                ",
      "                ",
      "                ",
      "                ",
      "                ",
      "                ",
      "           c    ",
      "           b    ",
      "           e    ",
      "           d    ",
      "           e    ",
      "           e    ",
      "           e    ",
      "           d    ",
      "           b    ",
      "           e    "
    ],
    [
      "                ",
      "                ",
      "                ",
      "                ",
      "                ",
      "                ",
      "                ",
      "                ",
      "                ",
      "                ",
      "                ",
      "                ",
      "                ",
      "                ",
      "                ",
      "                "
    ],
    [
      "                ",
      "                ",
      "                ",
      "                ",
      "                ",
      "                ",
      "                ",
      "                ",
      "                ",
      "                ",
      "                ",
      "                ",
      "                ",
      "                ",
      "                ",
      "                "
    ],
    [
      "                ",
      "                ",
      "                ",
      "                ",
      "                ",
      "                ",
      "                ",
      "                ",
      "                ",
      "                ",
      "                ",
      "                ",
      "                ",
      "                ",
      "                ",
      "                "
    ]
  ]
}