{
  "xsize": 16,
  "zsize": 16,
  "palette": {
    "palette": [
      {
        "char": " ",
        "block": "minecraft:air"
      },
      {
        "char": "f",
        "block": "minecraft:basalt[axis=x]"
      },
      {
        "char": "i",
        "block": "minecraft:cobbled_deepslate"
      },
      {
        "char": "g",
        "block": "minecraft:cyan_terracotta"
      },
      {
        "char": "q",
        "block": "minecraft:blackstone"
      },
      {
        "char": "h",
        "block": "minecraft:deepslate[axis=y]"
      },
      {
        "char": "d",
        "block": "minecraft:diorite"
      },
      {
        "char": "c",
        "block": "minecraft:smooth_quartz"
      },
      {
        "char": "t",
        "block": "minecraft:grass_block[snowy=false]"
      },
      {
        "char": "o",
        "block": "minecraft:dirt"
      },
      {
        "char": "b",
        "block": "minecraft:polished_diorite"
      },
      {
        "char": "呗",
        "block": "minecraft:white_concrete"
      },
      {
        "char": "e",
        "block": "minecraft:quartz_block"
      },
      {
        "char": "锁",
        "block": "minecraft:stone_slab[type=bottom,waterlogged=false,weathering=false]"
      },
      {
        "char": "串",
        "block": "minecraft:spawner",
        "tag": {
          "SpawnData": {
            "entity": {}
          },
          "MaxNearbyEntities": "6s",
          "MinSpawnDelay": "200s",
          "z": 451,
          "x": -63,
          "MaxSpawnDelay": "800s",
          "RequiredPlayerRange": "16s",
          "SpawnCount": "4s",
          "ForgeCaps": {},
          "id": "minecraft:mob_spawner",
          "SpawnPotentials": [],
          "y": 139,
          "SpawnRange": "4s",
          "Delay": "20s"
        }
      },
      {
        "char": "s",
        "block": "minecraft:air"
      },
      {
        "char": "瓣",
        "block": "minecraft:oak_log[axis=y]"
      },
      {
        "char": "胡",
        "block": "minecraft:air"
      },
      {
        "char": "俎",
        "block": "minecraft:air"
      },
      {
        "char": "庖",
        "block": "minecraft:spruce_stairs[facing=north,half=bottom,shape=inner_right,waterlogged=false]"
      },
      {
        "char": "痣",
        "block": "minecraft:spruce_stairs[facing=east,half=bottom,shape=straight,waterlogged=false]"
      },
      {
        "char": "拧",
        "block": "minecraft:spruce_stairs[facing=south,half=bottom,shape=inner_left,waterlogged=false]"
      },
      {
        "char": "w",
        "block": "minecraft:quartz_slab[type=bottom,waterlogged=false]"
      },
      {
        "char": "床",
        "block": "minecraft:oak_leaves[distance=2,persistent=false,waterlogged=false]"
      },
      {
        "char": "巡",
        "block": "minecraft:oak_leaves[distance=1,persistent=false,waterlogged=false]"
      },
      {
        "char": "劲",
        "block": "minecraft:oak_leaves[distance=3,persistent=false,waterlogged=false]"
      }
    ]
  },
  "slices": [
    [
      "figqhqhgdcdtottt",
      "cbbi呗g呗fbbbttttt",
      "cbth呗t呗qbbbtottt",
      "cbbf呗f呗qbbbtottt",
      "bcbfgqtqdebtottt",
      "cddhfiiqdbctottt",
      "cbeqhgh锁锁bctottt",
      "eebgtfiqbbdtottt",
      "cbbthghg锁锁etottt",
      "eccitqiheecttttt",
      "dtbhhitgbbbttttt",
      "dcbiqqgfbcdttttt",
      "edbfitgfebbttttt",
      "dbctqftfdbbttttt",
      "beeqffttdbbttttt",
      "bbbgfhfhbddtt串tt"
    ],
    [
      "        s ss瓣s胡s",
      "          胡s俎胡ss",
      "  s  ss    胡庖sss",
      "           s痣sss",
      "s     s    s痣sss",
      "         锁 s痣sss",
      " s   s     s痣sss",
      "    s 锁    s痣sss",
      "           s拧sss",
      "    s      sssss",
      "ss    s锁  锁sssss",
      "           sssss",
      "     s     sssss",
      "   s  s    sssss",
      "      ss   sssss",
      "           sswss"
    ],
    [
      "            瓣   ",
      "                ",
      "                ",
      "                ",
      "                ",
      "                ",
      "                ",
      "                ",
      "                ",
      "                ",
      "                ",
      "                ",
      "                ",
      "                ",
      "                ",
      "                "
    ],
    [
      "            瓣   ",
      "                ",
      "                ",
      "                ",
      "                ",
      "                ",
      "                ",
      "                ",
      "                ",
      "                ",
      "                ",
      "                ",
      "                ",
      "                ",
      "                ",
      "                "
    ],
    [
      "          床巡瓣巡床 ",
      "          劲床巡床劲 ",
      "           劲床劲  ",
      "                ",
      "                ",
      "                ",
      "                ",
      "                ",
      "                ",
      "                ",
      "                ",
      "                ",
      "                ",
      "                ",
      "                ",
      "                "
    ],
    [
      "          床巡瓣巡床 ",
      "          劲床巡床劲 ",
      "           劲床劲  ",
      "                ",
      "                ",
      "                ",
      "                ",
      "                ",
      "                ",
      "                ",
      "                ",
      "                ",
      "                ",
      "                ",
      "                ",
      "                "
    ]
  ]
}