{
  "xsize": 16,
  "zsize": 16,
  "palette": {
    "palette": [
      {
        "char": " ",
        "block": "minecraft:air"
      },
      {
        "char": "y",
        "block": "minecraft:quartz_slab[type=top,waterlogged=false]"
      },
      {
        "char": "z",
        "block": "minecraft:clay"
      },
      {
        "char": "g",
        "block": "minecraft:cyan_terracotta"
      },
      {
        "char": "j",
        "block": "minecraft:vine[east=true,north=false,south=false,up=false,west=false]"
      },
      {
        "char": "e",
        "block": "minecraft:quartz_block"
      },
      {
        "char": "袱",
        "block": "minecraft:quartz_stairs[facing=east,half=top,shape=straight,waterlogged=false]"
      },
      {
        "char": "d",
        "block": "minecraft:diorite"
      },
      {
        "char": "b",
        "block": "minecraft:polished_diorite"
      },
      {
        "char": "伟",
        "block": "minecraft:vine[east=true,north=false,south=true,up=false,west=false]"
      },
      {
        "char": "N",
        "block": "minecraft:diorite_slab[type=top,waterlogged=false]"
      },
      {
        "char": "c",
        "block": "minecraft:smooth_quartz"
      },
      {
        "char": "p",
        "block": "minecraft:quartz_pillar[axis=y]"
      },
      {
        "char": "w",
        "block": "minecraft:quartz_slab[type=bottom,waterlogged=false]"
      },
      {
        "char": "I",
        "block": "minecraft:black_concrete"
      },
      {
        "char": "皈",
        "block": "minecraft:quartz_slab[type=double,waterlogged=false]"
      },
      {
        "char": "a",
        "block": "minecraft:smooth_stone_slab[type=top,waterlogged=false]"
      },
      {
        "char": "锁",
        "block": "minecraft:stone_slab[type=bottom,waterlogged=false,weathering=false]"
      },
      {
        "char": "J",
        "block": "minecraft:polished_blackstone"
      },
      {
        "char": "庇",
        "block": "minecraft:diorite_stairs[facing=east,half=bottom,shape=straight,waterlogged=false]"
      },
      {
        "char": "u",
        "block": "minecraft:red_concrete"
      },
      {
        "char": "v",
        "block": "minecraft:red_terracotta"
      },
      {
        "char": "捕",
        "block": "minecraft:glass_pane[east=false,north=true,south=false,waterlogged=false,west=false]"
      },
      {
        "char": "涨",
        "block": "minecraft:glass_pane[east=false,north=false,south=true,waterlogged=false,west=false]"
      },
      {
        "char": "训",
        "block": "minecraft:air"
      },
      {
        "char": "H",
        "block": "minecraft:glass_pane[east=false,north=true,south=true,waterlogged=false,west=false]"
      },
      {
        "char": "f",
        "block": "minecraft:basalt[axis=x]"
      },
      {
        "char": "吒",
        "block": "minecraft:mossy_cobblestone_wall[east=low,north=none,south=none,up=false,waterlogged=false,west=low]"
      }
    ]
  },
  "slices": [
    [
      "              yz",
      "              yg",
      "            j  e",
      "            j  z",
      "            j  z",
      "             袱dd",
      "            j yz",
      "               z",
      "               b",
      "            伟 Nz",
      "           j  yz",
      "           j 袱ec",
      "           jjpcd",
      "           jjdbb",
      "          j  pcc",
      "             袱ce"
    ],
    [
      "              wI",
      "              皈I",
      "            j   ",
      "            j  a",
      "            j   ",
      "                ",
      "            j   ",
      "               锁",
      "                ",
      "            伟 wJ",
      "           j  wJ",
      "           j庇wce",
      "           jjbdd",
      "           jjeec",
      "          j  pcc",
      "            庇wbb"
    ],
    [
      "               I",
      "                ",
      "            j   ",
      "            j   ",
      "            j   ",
      "               y",
      "            j   ",
      "                ",
      "                ",
      "            伟   ",
      "           j   J",
      "           j  bu",
      "           jjpdu",
      "           jjded",
      "          j  ebu",
      "              ev"
    ],
    [
      "               捕",
      "                ",
      "            j   ",
      "            j   ",
      "            j   ",
      "                ",
      "            j   ",
      "                ",
      "                ",
      "            伟   ",
      "           j   涨",
      "           j  bd",
      "           jjped",
      "           jjbbe",
      "          j  pcb",
      "              ed"
    ],
    [
      "              N训",
      "               捕",
      "            j   ",
      "            j   ",
      "            j   ",
      "               w",
      "            j   ",
      "                ",
      "                ",
      "            伟  涨",
      "           j   H",
      "           j  bb",
      "           jjpdb",
      "           jjddd",
      "          j  ped",
      "              pe"
    ],
    [
      "               z",
      "               g",
      "            j   ",
      "            j   ",
      "            j   ",
      "              y ",
      "            j   ",
      "                ",
      "                ",
      "            伟  f",
      "           j   z",
      "           j  de",
      "           jjpeb",
      "           jjddd",
      "          jv吒pec",
      "              bb"
    ]
  ]
}