{
  "xsize": 16,
  "zsize": 16,
  "palette": {
    "palette": [
      {
        "char": " ",
        "block": "minecraft:air"
      },
      {
        "char": "d",
        "block": "minecraft:diorite"
      },
      {
        "char": "b",
        "block": "minecraft:polished_diorite"
      },
      {
        "char": "e",
        "block": "minecraft:quartz_block"
      },
      {
        "char": "c",
        "block": "minecraft:smooth_quartz"
      },
      {
        "char": "p",
        "block": "minecraft:quartz_pillar[axis=y]"
      },
      {
        "char": "j",
        "block": "minecraft:vine[east=true,north=false,south=false,up=false,west=false]"
      },
      {
        "char": "伟",
        "block": "minecraft:vine[east=true,north=false,south=true,up=false,west=false]"
      },
      {
        "char": "调",
        "block": "minecraft:vine[east=true,north=true,south=false,up=false,west=false]"
      },
      {
        "char": "K",
        "block": "minecraft:diorite_slab[type=bottom,waterlogged=false]"
      },
      {
        "char": "J",
        "block": "minecraft:polished_blackstone"
      },
      {
        "char": "w",
        "block": "minecraft:quartz_slab[type=bottom,waterlogged=false]"
      },
      {
        "char": "I",
        "block": "minecraft:black_concrete"
      },
      {
        "char": "q",
        "block": "minecraft:blackstone"
      },
      {
        "char": "H",
        "block": "minecraft:glass_pane[east=false,north=true,south=true,waterlogged=false,west=false]"
      },
      {
        "char": "涨",
        "block": "minecraft:glass_pane[east=false,north=false,south=true,waterlogged=false,west=false]"
      },
      {
        "char": "z",
        "block": "minecraft:clay"
      },
      {
        "char": "役",
        "block": "minecraft:dead_fire_coral_block"
      }
    ]
  },
  "slices": [
    [
      "             ddd",
      "             bed",
      "             eee",
      "             cdd",
      "             beb",
      "             ebd",
      "             ede",
      "             ddb",
      "             pbc",
      "              cc",
      "              cc",
      "             beb",
      "             jcb",
      "             伟bb",
      "            jced",
      "             调eb"
    ],
    [
      "              KJ",
      "              cb",
      "              wI",
      "              wJ",
      "              cb",
      "              KJ",
      "              wJ",
      "              ee",
      "             cee",
      "              db",
      "              ce",
      "             edd",
      "             jee",
      "             伟cd",
      "            jpbd",
      "             调bb"
    ],
    [
      "              伟J",
      "              dd",
      "               q",
      "               J",
      "              bd",
      "               J",
      "               J",
      "              bd",
      "             dce",
      "              ec",
      "              bc",
      "             bdb",
      "             jcd",
      "             伟dc",
      "            jedb",
      "             调ec"
    ],
    [
      "              伟H",
      "              pc",
      "                ",
      "                ",
      "              pb",
      "               H",
      "               H",
      "              cc",
      "             pce",
      "              bb",
      "              cd",
      "             dce",
      "             jde",
      "             jed",
      "            jpbc",
      "             调bc"
    ],
    [
      "              伟涨",
      "              pe",
      "               H",
      "               H",
      "              pe",
      "                ",
      "               涨",
      "              cb",
      "             bcb",
      "              bc",
      "              dc",
      "             pdd",
      "             jdd",
      "             jbc",
      "            jpec",
      "             调db"
    ],
    [
      "              伟z",
      "              cd",
      "               z",
      "               z",
      "              dd",
      "               役",
      "               z",
      "              eb",
      "             pec",
      "              ec",
      "              ee",
      "             eed",
      "             jbd",
      "             jdd",
      "            jdbe",
      "             调dd"
    ]
  ]
}