{
  "xsize": 16,
  "zsize": 16,
  "palette": {
    "palette": [
      {
        "char": " ",
        "block": "minecraft:air"
      },
      {
        "char": "j",
        "block": "minecraft:vine[east=true,north=false,south=false,up=false,west=false]"
      },
      {
        "char": "b",
        "block": "minecraft:polished_diorite"
      },
      {
        "char": "d",
        "block": "minecraft:diorite"
      },
      {
        "char": "c",
        "block": "minecraft:smooth_quartz"
      },
      {
        "char": "e",
        "block": "minecraft:quartz_block"
      },
      {
        "char": "i",
        "block": "minecraft:cobbled_deepslate"
      },
      {
        "char": "h",
        "block": "minecraft:deepslate[axis=y]"
      },
      {
        "char": "f",
        "block": "minecraft:basalt[axis=x]"
      },
      {
        "char": "g",
        "block": "minecraft:cyan_terracotta"
      },
      {
        "char": "C",
        "block": "minecraft:air"
      },
      {
        "char": "q",
        "block": "minecraft:blackstone"
      },
      {
        "char": "诒",
        "block": "minecraft:lever[face=wall,facing=west,powered=true]"
      },
      {
        "char": "蕤",
        "block": "minecraft:powered_rail[powered=true,shape=ascending_west,waterlogged=false]"
      },
      {
        "char": "珈",
        "block": "minecraft:rail[shape=south_west,waterlogged=false]"
      },
      {
        "char": "M",
        "block": "minecraft:air"
      },
      {
        "char": "烩",
        "block": "minecraft:rail[shape=ascending_north,waterlogged=false]"
      },
      {
        "char": "獠",
        "block": "minecraft:rail[shape=ascending_south,waterlogged=false]"
      },
      {
        "char": "鹃",
        "block": "minecraft:rail[shape=north_east,waterlogged=false]"
      },
      {
        "char": "挹",
        "block": "minecraft:powered_rail[powered=true,shape=ascending_east,waterlogged=false]"
      },
      {
        "char": "捂",
        "block": "minecraft:lever[face=wall,facing=east,powered=true]"
      },
      {
        "char": "噹",
        "block": "minecraft:air"
      },
      {
        "char": "耻",
        "block": "minecraft:air"
      },
      {
        "char": "Q",
        "block": "minecraft:smooth_stone_slab[type=bottom,waterlogged=false]"
      }
    ]
  },
  "slices": [
    [
      "   jbd          ",
      "    dc          ",
      "   jbc          ",
      "   jed          ",
      "   jdc          ",
      "    eb          ",
      "    ce          ",
      "    ed          ",
      "   jdb          ",
      "   jed          ",
      "   jdd          ",
      "    cd          ",
      "   jbd          ",
      "   jdb          ",
      "   jee          ",
      "   jee          "
    ],
    [
      "   jbe          ",
      "    de          ",
      "   jec          ",
      "   jcb          ",
      "   jbc          ",
      "    eb          ",
      "    cc          ",
      "    de          ",
      "   jdc          ",
      "   jce          ",
      "   jbe          ",
      "    ec          ",
      "   jcb          ",
      "   jeb          ",
      "   jbc          ",
      "   jdb          "
    ],
    [
      "   jce          ",
      "    cc          ",
      "   jee          ",
      "    dd          ",
      "    dc          ",
      "    ce          ",
      "    db          ",
      "    de          ",
      "   jdb          ",
      "   jbb          ",
      "   jcc          ",
      "    dd          ",
      "   jdc          ",
      "   jdb          ",
      "    db          ",
      "   jee          "
    ],
    [
      "    dc          ",
      "    ec          ",
      "    ce          ",
      "    cc          ",
      "    ed          ",
      "    bd          ",
      "    eb          ",
      "    ce          ",
      "   jcd          ",
      "   jcc          ",
      "   jcd          ",
      "    cb          ",
      "   jdb          ",
      "    ec          ",
      "    ec          ",
      "   jeb          "
    ],
    [
      "    ebihhihhhhhf",
      "    cegfCgqqfqih",
      "    eegghfhChgqq",
      "    beqhfqqhhhiC",
      "    dcChgfiigqiq",
      "    edhhigghqqhf",
      "    edqfCgfghghf",
      "    dbhffqfifqgq",
      "    eefCChgiiggq",
      "    dehgqigfqhhq",
      "    ccifgiqgCfgi",
      "    cdffhqgfiqhg",
      "    ebfghffghghi",
      "    dehChgigfgif",
      "    eeffgfhighCf",
      "   jcchgqhCifChh"
    ],
    [
      "    ee cdbbdce  ",
      "    cb b诒g蕤珈 cMM",
      "    ee d 烩 獠 c  ",
      "    de d 鹃挹g捂c噹M",
      "    be cedbcde  ",
      "    dc          ",
      "    cd  耻 M     ",
      "    cc cceeb    ",
      "    dd d   Q    ",
      "    be d   Q    ",
      "    bb ccbdd    ",
      "    ec  噹 耻     ",
      "    be          ",
      "    cd          ",
      "    de  噹 耻     ",
      "   jde cddce    "
    ]
  ]
}