{
  "xsize": 16,
  "zsize": 16,
  "palette": {
    "palette": [
      {
        "char": " ",
        "block": "minecraft:air"
      },
      {
        "char": "j",
        "block": "minecraft:vine[east=true,north=false,south=false,up=false,west=false]"
      },
      {
        "char": "e",
        "block": "minecraft:quartz_block"
      },
      {
        "char": "c",
        "block": "minecraft:smooth_quartz"
      },
      {
        "char": "袱",
        "block": "minecraft:quartz_stairs[facing=east,half=top,shape=straight,waterlogged=false]"
      },
      {
        "char": "d",
        "block": "minecraft:diorite"
      },
      {
        "char": "b",
        "block": "minecraft:polished_diorite"
      },
      {
        "char": "绮",
        "block": "minecraft:oak_fence[east=false,north=false,south=false,waterlogged=false,west=false]"
      },
      {
        "char": "儸",
        "block": "minecraft:diorite_stairs[facing=east,half=top,shape=straight,waterlogged=false]"
      },
      {
        "char": "m",
        "block": "minecraft:vine[east=false,north=true,south=false,up=false,west=false]"
      },
      {
        "char": "w",
        "block": "minecraft:quartz_slab[type=bottom,waterlogged=false]"
      },
      {
        "char": "J",
        "block": "minecraft:polished_blackstone"
      },
      {
        "char": "K",
        "block": "minecraft:diorite_slab[type=bottom,waterlogged=false]"
      },
      {
        "char": "I",
        "block": "minecraft:black_concrete"
      },
      {
        "char": "q",
        "block": "minecraft:blackstone"
      },
      {
        "char": "p",
        "block": "minecraft:quartz_pillar[axis=y]"
      },
      {
        "char": "调",
        "block": "minecraft:vine[east=true,north=true,south=false,up=false,west=false]"
      },
      {
        "char": "n",
        "block": "minecraft:vine[east=false,north=false,south=true,up=false,west=false]"
      },
      {
        "char": "v",
        "block": "minecraft:red_terracotta"
      },
      {
        "char": "u",
        "block": "minecraft:red_concrete"
      },
      {
        "char": "H",
        "block": "minecraft:glass_pane[east=false,north=true,south=true,waterlogged=false,west=false]"
      },
      {
        "char": "涨",
        "block": "minecraft:glass_pane[east=false,north=false,south=true,waterlogged=false,west=false]"
      },
      {
        "char": "捕",
        "block": "minecraft:glass_pane[east=false,north=true,south=false,waterlogged=false,west=false]"
      },
      {
        "char": "z",
        "block": "minecraft:clay"
      },
      {
        "char": "役",
        "block": "minecraft:dead_fire_coral_block"
      },
      {
        "char": "h",
        "block": "minecraft:deepslate[axis=y]"
      }
    ]
  },
  "slices": [
    [
      "          j  eec",
      "            袱cdb",
      "             bce",
      "             cdc",
      "          绮 儸ddb",
      "             edc",
      "            儸cdd",
      "             bdd",
      "             beb",
      "          绮 袱dde",
      "           jjdce",
      "           jjbde",
      "           j bcc",
      "            mcee",
      "             dde",
      "             beb"
    ],
    [
      "          j   wJ",
      "             jce",
      "              KI",
      "              wq",
      "          www de",
      "              wI",
      "              wJ",
      "              bc",
      "             pbb",
      "          wwwdce",
      "           jjpdc",
      "           j 调cd",
      "           j  wq",
      "            m wI",
      "             jec",
      "              wJ"
    ],
    [
      "          j   n ",
      "             jbc",
      "              m ",
      "               J",
      "              bc",
      "                ",
      "               J",
      "              bv",
      "             cdu",
      "           jjcdb",
      "           jjbdv",
      "           j 调eu",
      "           j   I",
      "            m   ",
      "             jdd",
      "              调 "
    ],
    [
      "          j   nH",
      "             jbb",
      "              mH",
      "               H",
      "              pd",
      "               H",
      "               H",
      "              bb",
      "             ece",
      "           j ceb",
      "           jjpcb",
      "           j jdb",
      "           j   H",
      "            m  H",
      "             jpd",
      "              调H"
    ],
    [
      "          j   nH",
      "             jpb",
      "              m ",
      "               涨",
      "              pd",
      "               捕",
      "                ",
      "              bb",
      "             pbb",
      "           j dbe",
      "           j pdc",
      "           j  bb",
      "           j   H",
      "            m  H",
      "             jpe",
      "              调 "
    ],
    [
      "          j    z",
      "             jdb",
      "              m役",
      "               z",
      "              cc",
      "               z",
      "               z",
      "              be",
      "             pdb",
      "           j dbe",
      "           j pbc",
      "           j  cb",
      "           j   z",
      "            m  h",
      "             jcc",
      "              调z"
    ]
  ]
}