{
  "xsize": 16,
  "zsize": 16,
  "palette": {
    "palette": [
      {
        "char": " ",
        "block": "minecraft:air"
      },
      {
        "char": "d",
        "block": "minecraft:air"
      },
      {
        "char": "b",
        "block": "minecraft:air"
      },
      {
        "char": "q",
        "block": "minecraft:air"
      },
      {
        "char": "f",
        "block": "minecraft:air"
      },
      {
        "char": "i",
        "block": "minecraft:air"
      },
      {
        "char": "h",
        "block": "minecraft:air"
      },
      {
        "char": "e",
        "block": "minecraft:air"
      },
      {
        "char": "t",
        "block": "minecraft:air"
      },
      {
        "char": "o",
        "block": "minecraft:air"
      },
      {
        "char": "g",
        "block": "minecraft:air"
      },
      {
        "char": "c",
        "block": "minecraft:air"
      },
      {
        "char": "呗",
        "block": "minecraft:air"
      },
      {
        "char": "x",
        "block": "minecraft:air"
      },
      {
        "char": "锁",
        "block": "minecraft:air"
      },
      {
        "char": "s",
        "block": "minecraft:grass"
      },
      {
        "char": "痣",
        "block": "minecraft:air"
      },
      {
        "char": "胡",
        "block": "minecraft:air"
      },
      {
        "char": "瓣",
        "block": "minecraft:air"
      },
      {
        "char": "拧",
        "block": "minecraft:air"
      },
      {
        "char": "捱",
        "block": "minecraft:air"
      },
      {
        "char": "淅",
        "block": "minecraft:air"
      },
      {
        "char": "芥",
        "block": "minecraft:air"
      },
      {
        "char": "迫",
        "block": "minecraft:air"
      },
      {
        "char": "俎",
        "block": "minecraft:air"
      },
      {
        "char": "酝",
        "block": "minecraft:air"
      },
      {
        "char": "埂",
        "block": "minecraft:air"
      },
      {
        "char": "劲",
        "block": "minecraft:air"
      },
      {
        "char": "床",
        "block": "minecraft:air"
      },
      {
        "char": "恁",
        "block": "minecraft:air"
      },
      {
        "char": "巡",
        "block": "minecraft:air"
      }
    ]
  },
  "slices": [
    [
      "dbbqfqihebbtottt",
      "bbbhgthhbdctotto",
      "ddditggfbbbtottt",
      "eedq呗f呗ibbctottt",
      "dbef呗q呗idbctottt",
      "eeeq呗t呗ibcbttttt",
      "tqiigqfqbbdttttt",
      "hqfgithgebbttttt",
      "gftitqfheceoxbbb",
      "锁tiiqfghebbedcdb",
      "thgqtigftbebcbbb",
      "qqgighqibcebddde",
      "fifqqfg锁bbeeebbd",
      "gtiqggiidbbceecd",
      "gffht锁锁fbebtxbbb",
      "figtiqhqdtbttttt"
    ],
    [
      "           s痣ss胡",
      "s    s    ss痣胡s瓣",
      "    s      s痣s胡s",
      "           s痣s胡s",
      "s          s拧sss",
      "    ss     sssss",
      "s         胡胡胡胡ss",
      "     s     s捱胡ss",
      "  s锁s    胡淅瓣x芥芥迫",
      " s  s     俎s酝胡  ",
      "ss  s   s 胡 胡   ",
      "                ",
      " s  s锁          ",
      " ss         捱   ",
      "    ss    胡埂x迫迫芥",
      "   s    锁s胡胡酝胡ss"
    ],
    [
      "                ",
      "               瓣",
      "                ",
      "                ",
      "                ",
      "                ",
      "                ",
      "                ",
      "           瓣    ",
      "                ",
      "                ",
      "                ",
      "                ",
      "                ",
      "            胡   ",
      "                "
    ],
    [
      "                ",
      "               瓣",
      "                ",
      "                ",
      "                ",
      "                ",
      "          劲床劲恁  ",
      "         劲床巡床劲  ",
      "         床巡瓣巡床  ",
      "         劲床巡床劲  ",
      "          劲床劲   ",
      "                ",
      "                ",
      "                ",
      "                ",
      "                "
    ],
    [
      "             劲床巡",
      "             床巡瓣",
      "             劲床巡",
      "              劲床",
      "                ",
      "                ",
      "          劲床劲   ",
      "         劲床巡床劲  ",
      "         床巡瓣巡床  ",
      "         劲床巡床劲  ",
      "          劲床劲   ",
      "                ",
      "                ",
      "                ",
      "           劲床劲  ",
      "          劲床巡床劲 "
    ],
    [
      "             劲床巡",
      "             床巡瓣",
      "             劲床巡",
      "              劲床",
      "                ",
      "                ",
      "                ",
      "          床巡床   ",
      "          巡瓣巡   ",
      "           巡床   ",
      "                ",
      "                ",
      "                ",
      "                ",
      "          恁劲床劲  ",
      "          劲床巡床劲 "
    ]
  ]
}