{
  "xsize": 16,
  "zsize": 16,
  "palette": {
    "palette": [
      {
        "char": " ",
        "block": "minecraft:air"
      },
      {
        "char": "e",
        "block": "minecraft:quartz_block"
      },
      {
        "char": "i",
        "block": "minecraft:cobbled_deepslate"
      },
      {
        "char": "q",
        "block": "minecraft:blackstone"
      },
      {
        "char": "h",
        "block": "minecraft:deepslate[axis=y]"
      },
      {
        "char": "g",
        "block": "minecraft:cyan_terracotta"
      },
      {
        "char": "f",
        "block": "minecraft:basalt[axis=x]"
      },
      {
        "char": "C",
        "block": "minecraft:air"
      },
      {
        "char": "b",
        "block": "minecraft:polished_diorite"
      },
      {
        "char": "c",
        "block": "minecraft:smooth_quartz"
      },
      {
        "char": "d",
        "block": "minecraft:diorite"
      },
      {
        "char": "耻",
        "block": "minecraft:air"
      },
      {
        "char": "噹",
        "block": "minecraft:air"
      },
      {
        "char": "诒",
        "block": "minecraft:lever[face=wall,facing=west,powered=true]"
      },
      {
        "char": "蕤",
        "block": "minecraft:powered_rail[powered=true,shape=ascending_west,waterlogged=false]"
      },
      {
        "char": "珈",
        "block": "minecraft:rail[shape=south_west,waterlogged=false]"
      },
      {
        "char": "烩",
        "block": "minecraft:rail[shape=ascending_north,waterlogged=false]"
      },
      {
        "char": "獠",
        "block": "minecraft:rail[shape=ascending_south,waterlogged=false]"
      },
      {
        "char": "M",
        "block": "minecraft:air"
      },
      {
        "char": "鹃",
        "block": "minecraft:rail[shape=north_east,waterlogged=false]"
      },
      {
        "char": "挹",
        "block": "minecraft:powered_rail[powered=true,shape=ascending_east,waterlogged=false]"
      },
      {
        "char": "捂",
        "block": "minecraft:lever[face=wall,facing=east,powered=true]"
      },
      {
        "char": "膝",
        "block": "minecraft:cobblestone_wall[east=none,north=none,south=none,up=true,waterlogged=false,weathering=false,west=none]"
      },
      {
        "char": "芩",
        "block": "minecraft:cobblestone_wall[east=none,north=none,south=none,up=true,waterlogged=false,weathering=true,west=none]"
      }
    ]
  },
  "slices": [
    [
      "               e",
      "                ",
      "                ",
      "                ",
      "                ",
      "                ",
      "                ",
      "                ",
      "                ",
      "                ",
      "                ",
      "                ",
      "                ",
      "                ",
      "                ",
      "                "
    ],
    [
      "                ",
      "                ",
      "                ",
      "                ",
      "                ",
      "                ",
      "                ",
      "                ",
      "                ",
      "                ",
      "                ",
      "                ",
      "                ",
      "                ",
      "                ",
      "                "
    ],
    [
      "                ",
      "                ",
      "                ",
      "                ",
      "                ",
      "                ",
      "                ",
      "                ",
      "                ",
      "                ",
      "                ",
      "                ",
      "                ",
      "                ",
      "                ",
      "                "
    ],
    [
      "                ",
      "                ",
      "                ",
      "                ",
      "                ",
      "                ",
      "                ",
      "                ",
      "                ",
      "                ",
      "                ",
      "                ",
      "                ",
      "                ",
      "                ",
      "                "
    ],
    [
      "iqhgfggihgiifggh",
      "gghihCgqfhCCqiCq",
      "fiiCgfhhfffCiCqf",
      "qgiqfhqqifgqiqfq",
      "hqgiffghCqhfqgih",
      "CqhqqqqCfihfgghq",
      "fiqfhfiqhiifhqCq",
      "fggfhqfgfghfqiih",
      "hiiqhqqqqgiCqChh",
      "qfhghggfffqqCfCC",
      "qgggifqCCfqqgihq",
      "igChgCgCChqiffhh",
      "hfgghiqqggiqCqhq",
      "ihqffhCfhhCghhqq",
      "ghfgfffhqqhffigg",
      "fffgiihCqhhhhhqi"
    ],
    [
      "  bccdbce    dde",
      "耻噹e诒C蕤珈 e耻耻噹耻c诒f",
      "  d 烩 獠 e    e 烩",
      "MMc 鹃挹g捂e耻M耻耻c 鹃",
      "  cdbbdbe    cbc",
      "                ",
      "    M  耻      耻 ",
      "                ",
      "   膝    膝    芩  ",
      "                ",
      "                ",
      "                ",
      "                ",
      "   膝    膝    膝  ",
      "                ",
      "    M  噹      耻 "
    ]
  ]
}