{
  "xsize": 16,
  "zsize": 16,
  "palette": {
    "palette": [
      {
        "char": " ",
        "block": "minecraft:air"
      },
      {
        "char": "t",
        "block": "minecraft:air"
      },
      {
        "char": "o",
        "block": "minecraft:air"
      },
      {
        "char": "i",
        "block": "minecraft:air"
      },
      {
        "char": "q",
        "block": "minecraft:air"
      },
      {
        "char": "f",
        "block": "minecraft:air"
      },
      {
        "char": "g",
        "block": "minecraft:air"
      },
      {
        "char": "h",
        "block": "minecraft:air"
      },
      {
        "char": "s",
        "block": "minecraft:grass"
      },
      {
        "char": "m",
        "block": "minecraft:air"
      },
      {
        "char": "e",
        "block": "minecraft:air"
      },
      {
        "char": "b",
        "block": "minecraft:air"
      },
      {
        "char": "p",
        "block": "minecraft:air"
      },
      {
        "char": "捻",
        "block": "minecraft:tall_grass[half=lower]"
      },
      {
        "char": "d",
        "block": "minecraft:air"
      },
      {
        "char": "窿",
        "block": "minecraft:tall_grass[half=upper]"
      },
      {
        "char": "c",
        "block": "minecraft:air"
      }
    ]
  },
  "slices": [
    [
      "tttttoootttiqfiq",
      "tttttttttttigiqi",
      "ttttttttttthfiqq",
      "ttttttttttthffqf",
      "tttttttttttfgfhi",
      "tttttttttttfqiii",
      "ttttttttttthqigq",
      "ttttttttttthhggg",
      "tttttttttttigfqf",
      "ttttttttttttifii",
      "tttttttttttiihhq",
      "ffigftigqqfghggf",
      "fgfhqqttghfgqihg",
      "igqitiqqqiigqiig",
      "hhhihgiggffiiihq",
      "hqiiihggfgfigftf"
    ],
    [
      "smsssebpsss     ",
      "sssssmmmsss     ",
      "sssssssssss    s",
      "sssssssssss     ",
      "sssssssssss     ",
      "sssssssssss     ",
      "sssssssssss     ",
      "sssssssss捻s     ",
      "sssssssssss     ",
      "ssssssssssss    ",
      "sssssssss捻s     ",
      "     s          ",
      "      sss      s",
      "    s           ",
      "       s        ",
      "              s "
    ],
    [
      " m   pdp        ",
      "     mmm        ",
      "                ",
      "                ",
      "                ",
      "                ",
      "                ",
      "         窿      ",
      "                ",
      "                ",
      "         窿      ",
      "                ",
      "                ",
      "                ",
      "                ",
      "                "
    ],
    [
      " m   pcp        ",
      "     mmm        ",
      "                ",
      "                ",
      "                ",
      "                ",
      "                ",
      "                ",
      "                ",
      "                ",
      "                ",
      "                ",
      "                ",
      "                ",
      "                ",
      "                "
    ],
    [
      " m   bbb        ",
      "     mmm        ",
      "                ",
      "                ",
      "                ",
      "                ",
      "                ",
      "                ",
      "                ",
      "                ",
      "                ",
      "                ",
      "                ",
      "                ",
      "                ",
      "                "
    ],
    [
      " m   pde        ",
      "     mmm        ",
      "                ",
      "                ",
      "                ",
      "                ",
      "                ",
      "                ",
      "                ",
      "                ",
      "                ",
      "                ",
      "                ",
      "                ",
      "                ",
      "                "
    ]
  ]
}