{
  "xsize": 16,
  "zsize": 16,
  "palette": {
    "palette": [
      {
        "char": " ",
        "block": "minecraft:air"
      },
      {
        "char": "j",
        "block": "minecraft:vine[east=true,north=false,south=false,up=false,west=false]"
      },
      {
        "char": "y",
        "block": "minecraft:quartz_slab[type=top,waterlogged=false]"
      },
      {
        "char": "z",
        "block": "minecraft:clay"
      },
      {
        "char": "e",
        "block": "minecraft:quartz_block"
      },
      {
        "char": "c",
        "block": "minecraft:smooth_quartz"
      },
      {
        "char": "q",
        "block": "minecraft:blackstone"
      },
      {
        "char": "m",
        "block": "minecraft:vine[east=false,north=true,south=false,up=false,west=false]"
      },
      {
        "char": "d",
        "block": "minecraft:diorite"
      },
      {
        "char": "N",
        "block": "minecraft:diorite_slab[type=top,waterlogged=false]"
      },
      {
        "char": "w",
        "block": "minecraft:quartz_slab[type=bottom,waterlogged=false]"
      },
      {
        "char": "J",
        "block": "minecraft:polished_blackstone"
      },
      {
        "char": "K",
        "block": "minecraft:diorite_slab[type=bottom,waterlogged=false]"
      },
      {
        "char": "I",
        "block": "minecraft:black_concrete"
      },
      {
        "char": "b",
        "block": "minecraft:polished_diorite"
      },
      {
        "char": "繁",
        "block": "minecraft:cobblestone_wall[east=tall,north=none,south=none,up=true,waterlogged=false,weathering=false,west=none]"
      },
      {
        "char": "瀑",
        "block": "minecraft:mossy_cobblestone_wall[east=tall,north=none,south=none,up=true,waterlogged=false,west=none]"
      },
      {
        "char": "H",
        "block": "minecraft:glass_pane[east=false,north=true,south=true,waterlogged=false,west=false]"
      },
      {
        "char": "捕",
        "block": "minecraft:glass_pane[east=false,north=true,south=false,waterlogged=false,west=false]"
      },
      {
        "char": "涨",
        "block": "minecraft:glass_pane[east=false,north=false,south=true,waterlogged=false,west=false]"
      },
      {
        "char": "i",
        "block": "minecraft:cobbled_deepslate"
      },
      {
        "char": "役",
        "block": "minecraft:dead_fire_coral_block"
      },
      {
        "char": "f",
        "block": "minecraft:basalt[axis=x]"
      }
    ]
  },
  "slices": [
    [
      "           j  yz",
      "              yz",
      "              ec",
      "           j  yq",
      "         j    yz",
      "          mj jdd",
      "              yz",
      "              yz",
      "             jdd",
      "              yz",
      "              yq",
      "             jcc",
      "              Nz",
      "              yz",
      "             jdc",
      "              yz"
    ],
    [
      "           j  wJ",
      "              Kq",
      "              ee",
      "           j  Kq",
      "         j    Kq",
      "          mj jed",
      "              wI",
      "              Kq",
      "             jbe",
      "              Kq",
      "              KJ",
      "             jdb",
      "              wI",
      "              KJ",
      "             jde",
      "              Kq"
    ],
    [
      "           j  yJ",
      "              y ",
      "              db",
      "           j  y ",
      "         j    Nq",
      "          mj jbb",
      "              yI",
      "              N ",
      "             jbb",
      "              y ",
      "              yI",
      "             jcc",
      "              yJ",
      "              y ",
      "             jdb",
      "              y "
    ],
    [
      "           j    ",
      "                ",
      "              繁c",
      "           j    ",
      "         j      ",
      "          mj j瀑c",
      "                ",
      "                ",
      "             j繁e",
      "               H",
      "               H",
      "             j瀑b",
      "               捕",
      "                ",
      "             j繁b",
      "               H"
    ],
    [
      "           j   H",
      "               H",
      "              繁b",
      "           j    ",
      "         j     涨",
      "          mj j繁e",
      "               捕",
      "                ",
      "             j繁c",
      "               H",
      "               H",
      "             j繁c",
      "                ",
      "               涨",
      "             j瀑e",
      "               H"
    ],
    [
      "           j  wz",
      "              wi",
      "              bb",
      "           j  wz",
      "         j    wz",
      "          mj jdd",
      "              wz",
      "              K役",
      "             jed",
      "              wz",
      "              wf",
      "             jdc",
      "              wz",
      "              wz",
      "             jee",
      "              wi"
    ]
  ]
}