{
  "xsize": 16,
  "zsize": 16,
  "palette": {
    "palette": [
      {
        "char": " ",
        "block": "minecraft:air"
      },
      {
        "char": "e",
        "block": "minecraft:quartz_block"
      },
      {
        "char": "c",
        "block": "minecraft:smooth_quartz"
      },
      {
        "char": "d",
        "block": "minecraft:diorite"
      },
      {
        "char": "b",
        "block": "minecraft:polished_diorite"
      },
      {
        "char": "拭",
        "block": "minecraft:cobblestone_wall[east=low,north=none,south=none,up=false,waterlogged=false,weathering=false,west=low]"
      },
      {
        "char": "g",
        "block": "minecraft:cyan_terracotta"
      },
      {
        "char": "f",
        "block": "minecraft:basalt[axis=x]"
      },
      {
        "char": "q",
        "block": "minecraft:blackstone"
      },
      {
        "char": "i",
        "block": "minecraft:cobbled_deepslate"
      },
      {
        "char": "h",
        "block": "minecraft:deepslate[axis=y]"
      },
      {
        "char": "C",
        "block": "minecraft:air"
      },
      {
        "char": "噹",
        "block": "minecraft:air"
      },
      {
        "char": "膝",
        "block": "minecraft:cobblestone_wall[east=none,north=none,south=none,up=true,waterlogged=false,weathering=false,west=none]"
      },
      {
        "char": "耻",
        "block": "minecraft:air"
      },
      {
        "char": "r",
        "block": "minecraft:cobblestone_slab[type=top,waterlogged=false,weathering=false]"
      },
      {
        "char": "Q",
        "block": "minecraft:smooth_stone_slab[type=bottom,waterlogged=false]"
      },
      {
        "char": "a",
        "block": "minecraft:smooth_stone_slab[type=top,waterlogged=false]"
      }
    ]
  },
  "slices": [
    [
      "     ee         ",
      "     ce         ",
      "     db         ",
      "     ed         ",
      "     ec         ",
      "     bc         ",
      "     ec         ",
      "     de         ",
      "     ec         ",
      "     db         ",
      "     dcebbecddd ",
      "     beedcebbec ",
      "             bd ",
      "             ec ",
      "             de ",
      "             ee拭"
    ],
    [
      "     ed         ",
      "     ce         ",
      "     bb         ",
      "     dd         ",
      "     ce         ",
      "     be         ",
      "     bd         ",
      "     eb         ",
      "     cc         ",
      "     de         ",
      "     bcdbeeeebe ",
      "     cebdbdebdb ",
      "             dd ",
      "             be ",
      "             ed ",
      "             ce "
    ],
    [
      "     de         ",
      "     ee         ",
      "     bd         ",
      "     dc         ",
      "     dc         ",
      "     eb         ",
      "     cb         ",
      "     cd         ",
      "     ed         ",
      "     cb         ",
      "     dededcddcb ",
      "     cbcdcbcdeb ",
      "             dd ",
      "             dd ",
      "             bd ",
      "             db "
    ],
    [
      "     cd         ",
      "     dd         ",
      "     dd         ",
      "     ee         ",
      "     dc         ",
      "     eb         ",
      "     db         ",
      "     dd         ",
      "     ed         ",
      "     ce         ",
      "     bbcddeddeb ",
      "     dbecccbdeb ",
      "             cb ",
      "             bd ",
      "             ed ",
      "             bb拭"
    ],
    [
      "gffgqcd         ",
      "ihhCicc         ",
      "hghiqcd         ",
      "fggfqcd         ",
      "hfihicd         ",
      "hfhqfcc         ",
      "hqChfdd         ",
      "fCqigeb         ",
      "gigghde         ",
      "fgCfidd         ",
      "qfCgfbcdedbddee ",
      "higfheceddbdddc ",
      "qihfihighqghidd ",
      "hfhfhiffhgCiiec ",
      "hffhqfqhhhhhhdb ",
      "fhhqiifCgihhhce "
    ],
    [
      "     de         ",
      " 噹   ce         ",
      "     eb         ",
      "  膝  ce         ",
      "     ee         ",
      "     bb         ",
      "     cb         ",
      "     eb         ",
      "  膝  cc         ",
      "     db         ",
      " 耻   eddcececcd ",
      "     eddddbcdbd ",
      "膝rQ          bc ",
      " aQ          bd ",
      "bebecebbddd  db ",
      "cedecbcdcec  de "
    ]
  ]
}