{
  "xsize": 16,
  "zsize": 16,
  "palette": {
    "palette": [
      {
        "char": " ",
        "block": "minecraft:air"
      },
      {
        "char": "i",
        "block": "minecraft:vine[east=false,north=false,south=true,up=false,west=false]"
      },
      {
        "char": "z",
        "block": "minecraft:cracked_stone_bricks"
      },
      {
        "char": "h",
        "block": "minecraft:vine[east=false,north=false,south=false,up=false,west=true]"
      },
      {
        "char": "b",
        "block": "minecraft:glass"
      },
      {
        "char": "d",
        "block": "minecraft:mossy_cobblestone"
      },
      {
        "char": "c",
        "block": "minecraft:stone[weathering=false]"
      },
      {
        "char": "a",
        "block": "minecraft:cobblestone[weathering=false]"
      },
      {
        "char": "g",
        "block": "minecraft:vine[east=true,north=false,south=false,up=false,west=false]"
      },
      {
        "char": "f",
        "block": "minecraft:vine[east=false,north=true,south=false,up=false,west=false]"
      },
      {
        "char": "ΐ",
        "block": "minecraft:vine[east=true,north=true,south=false,up=false,west=false]"
      },
      {
        "char": "e",
        "block": "minecraft:smooth_stone_slab[type=double,waterlogged=false]"
      },
      {
        "char": "Ϛ",
        "block": "minecraft:vine[east=false,north=true,south=false,up=false,west=true]"
      },
      {
        "char": "M",
        "block": "minecraft:cobblestone_slab[type=bottom,waterlogged=false,weathering=false]"
      },
      {
        "char": "j",
        "block": "minecraft:bookshelf"
      },
      {
        "char": "k",
        "block": "minecraft:stone_bricks[weathering=false]"
      },
      {
        "char": "C",
        "block": "minecraft:stone_brick_stairs[facing=north,half=bottom,shape=straight,waterlogged=false,weathering=false]"
      },
      {
        "char": "y",
        "block": "minecraft:mossy_stone_bricks"
      },
      {
        "char": "Ы",
        "block": "minecraft:vine[east=false,north=true,south=false,up=true,west=true]"
      }
    ]
  },
  "slices": [
    [
      "                ",
      "                ",
      "                ",
      "                ",
      "                ",
      "                ",
      "                ",
      "   iii  i       ",
      "        zh      ",
      "bdbcbcba h      ",
      "       b        ",
      "       c        ",
      "       b h      ",
      "       d h      ",
      "g      b h      ",
      " fΐ    d h      "
    ],
    [
      "                ",
      "                ",
      "                ",
      "                ",
      "                ",
      "                ",
      "                ",
      "   iii  i       ",
      "eeeeeeeeeh      ",
      "aaaaaaaaeh      ",
      "acddddcae       ",
      "addcadcae       ",
      "cdadccaaeh      ",
      "acdaccaaeh      ",
      "gdcddadaeh      ",
      " fΐddadaeh      "
    ],
    [
      "                ",
      "                ",
      "                ",
      "                ",
      "                ",
      "                ",
      "                ",
      "   iii  i       ",
      "        zh      ",
      "babdbabaϚ       ",
      "Maa  jjb        ",
      "  g  kkc        ",
      "d a  kkb h      ",
      "a    kkc h      ",
      "     CCb h      ",
      "       c h      "
    ],
    [
      "                ",
      "                ",
      "                ",
      "                ",
      "                ",
      "                ",
      "                ",
      "   iii  i       ",
      "        kh      ",
      "bdbcbcbdϚ       ",
      "  a  jjb        ",
      "  g  kkd        ",
      "  M  kkb h      ",
      "     CCa h      ",
      "       b h      ",
      "       c h      "
    ],
    [
      "                ",
      "                ",
      "                ",
      "                ",
      "                ",
      "                ",
      "                ",
      "   iii  i       ",
      "        yh      ",
      "bdbabdbcЫ       ",
      "     jjb        ",
      "  g  kkc        ",
      "     CCb h      ",
      "       c h      ",
      "       b h      ",
      "       d h      "
    ],
    [
      "                ",
      "                ",
      "                ",
      "                ",
      "                ",
      "                ",
      "                ",
      "   iii  i       ",
      " eeeeeeeeh      ",
      "MM aaaaae       ",
      "   adaaae       ",
      "  gccCCae       ",
      "    a  aeh      ",
      "   aa  aeh      ",
      " aadc  aeh      ",
      "daddcccaeh      "
    ]
  ]
}