{
  "xsize": 16,
  "zsize": 16,
  "palette": {
    "palette": [
      {
        "char": " ",
        "block": "minecraft:air"
      },
      {
        "char": "v",
        "block": "minecraft:stone_brick_stairs[facing=south,half=bottom,shape=straight,waterlogged=false,weathering=false]"
      },
      {
        "char": "b",
        "block": "minecraft:glass"
      },
      {
        "char": "a",
        "block": "minecraft:cobblestone[weathering=false]"
      },
      {
        "char": "ΰ",
        "block": "minecraft:vine[east=true,north=true,south=true,up=false,west=false]"
      },
      {
        "char": "d",
        "block": "minecraft:mossy_cobblestone"
      },
      {
        "char": "g",
        "block": "minecraft:vine[east=true,north=false,south=false,up=false,west=false]"
      },
      {
        "char": "k",
        "block": "minecraft:stone_bricks[weathering=false]"
      },
      {
        "char": "j",
        "block": "minecraft:bookshelf"
      },
      {
        "char": "c",
        "block": "minecraft:stone[weathering=false]"
      },
      {
        "char": "y",
        "block": "minecraft:mossy_stone_bricks"
      },
      {
        "char": "f",
        "block": "minecraft:vine[east=false,north=true,south=false,up=false,west=false]"
      },
      {
        "char": "u",
        "block": "minecraft:stone_brick_slab[type=top,waterlogged=false,weathering=false]"
      },
      {
        "char": "e",
        "block": "minecraft:smooth_stone_slab[type=double,waterlogged=false]"
      },
      {
        "char": "A",
        "block": "minecraft:air"
      },
      {
        "char": "͵",
        "block": "minecraft:glass_pane[east=true,north=false,south=false,waterlogged=false,west=true]"
      },
      {
        "char": "ϣ",
        "block": "minecraft:glass_pane[east=false,north=false,south=true,waterlogged=false,west=true]"
      },
      {
        "char": "I",
        "block": "minecraft:iron_bars[east=false,north=true,south=true,waterlogged=false,west=false]"
      },
      {
        "char": "K",
        "block": "minecraft:glass_pane[east=false,north=true,south=true,waterlogged=false,west=false]"
      },
      {
        "char": "·",
        "block": "minecraft:air"
      },
      {
        "char": "w",
        "block": "minecraft:air"
      },
      {
        "char": "N",
        "block": "minecraft:iron_bars[east=true,north=false,south=false,waterlogged=false,west=true]"
      },
      {
        "char": "Δ",
        "block": "minecraft:glass_pane[east=false,north=true,south=false,waterlogged=false,west=false]"
      }
    ]
  },
  "slices": [
    [
      "       v b      ",
      "         a      ",
      "         b   ΰ  ",
      "         d      ",
      "       g bvv    ",
      "       g akk    ",
      "       g bjj    ",
      "       g cbcbcbc",
      "        y       ",
      "        ffffffff",
      "                ",
      "                ",
      "                ",
      "                ",
      "                ",
      "                "
    ],
    [
      "      u eadcc  c",
      "      uveacadc  ",
      "      uuea  dΰa ",
      "        ea  ddcc",
      "       gea  dcda",
      "       geavvdcdd",
      "       geadaddac",
      "       geaaaaaaa",
      "        eeeeeeee",
      "        ffffffff",
      "                ",
      "                ",
      "                ",
      "                ",
      "                ",
      "                "
    ],
    [
      "     A   b      ",
      "     A   a͵͵ϣ   ",
      "     I   b  K   ",
      "     ·wNwa  K   ",
      "       g b  K   ",
      "       g a  Δ   ",
      "       g b      ",
      "       g dbcbabd",
      "        y       ",
      "        ffffffff",
      "                ",
      "                ",
      "                ",
      "                ",
      "                ",
      "                "
    ],
    [
      "         b      ",
      "         d      ",
      "         b      ",
      "         a      ",
      "       g b      ",
      "       g c      ",
      "       g b      ",
      "       g abababa",
      "        k       ",
      "        ffffffff",
      "                ",
      "                ",
      "                ",
      "                ",
      "                ",
      "                "
    ],
    [
      "       v b      ",
      "         d      ",
      "         b      ",
      "         d      ",
      "       g b      ",
      "       g a      ",
      "       g b      ",
      "       g cbdbcba",
      "        y       ",
      "        ffffffff",
      "                ",
      "                ",
      "                ",
      "                ",
      "                ",
      "                "
    ],
    [
      "      u eaacdadc",
      "      uveadaadca",
      "      uueaadccdd",
      "        eaadacaa",
      "       geaddacda",
      "       geaccadcc",
      "       geaaddaad",
      "       geaaaaaaa",
      "        eeeeeeee",
      "        ffffffff",
      "                ",
      "                ",
      "                ",
      "                ",
      "                ",
      "                "
    ]
  ]
}