{
  "xsize": 16,
  "zsize": 16,
  "palette": {
    "palette": [
      {
        "char": " ",
        "block": "minecraft:air"
      },
      {
        "char": "B",
        "block": "minecraft:glass_pane[east=true,north=true,south=true,waterlogged=false,west=false]"
      },
      {
        "char": "c",
        "block": "minecraft:cobblestone[weathering=false]"
      },
      {
        "char": "b",
        "block": "minecraft:stone[weathering=false]"
      },
      {
        "char": "τ",
        "block": "minecraft:cobblestone_slab[type=double,waterlogged=false,weathering=false]"
      },
      {
        "char": "i",
        "block": "minecraft:vine[east=true,north=false,south=false,up=false,west=false]"
      },
      {
        "char": "a",
        "block": "minecraft:stone_bricks[weathering=false]"
      },
      {
        "char": "e",
        "block": "minecraft:mossy_stone_bricks"
      },
      {
        "char": "k",
        "block": "minecraft:chiseled_stone_bricks[weathering=false]"
      },
      {
        "char": "x",
        "block": "minecraft:dark_oak_fence[east=true,north=false,south=true,waterlogged=false,west=false]"
      },
      {
        "char": "d",
        "block": "minecraft:cracked_stone_bricks"
      },
      {
        "char": "M",
        "block": "minecraft:glass_pane[east=true,north=true,south=false,waterlogged=false,west=true]"
      },
      {
        "char": "y",
        "block": "minecraft:dark_oak_fence[east=false,north=true,south=false,waterlogged=false,west=true]"
      },
      {
        "char": "l",
        "block": "minecraft:vine[east=false,north=true,south=false,up=false,west=false]"
      },
      {
        "char": "g",
        "block": "minecraft:glass_pane[east=false,north=true,south=true,waterlogged=false,west=false]"
      },
      {
        "char": "o",
        "block": "minecraft:gray_carpet"
      },
      {
        "char": "V",
        "block": "minecraft:black_carpet"
      },
      {
        "char": "Ҕ",
        "block": "minecraft:furnace[facing=east,lit=false]",
        "tag": {
          "z": 593,
          "x": 138,
          "CookTimeTotal": 0,
          "ForgeData": {
            "LockFlag": "1b"
          },
          "CookTime": 0,
          "ForgeCaps": {
            "polymorph:block_entity_recipe_data": {}
          },
          "id": "minecraft:furnace",
          "y": 169,
          "Items": [],
          "BurnTime": 0,
          "RecipesUsed": {}
        }
      },
      {
        "char": "E",
        "block": "minecraft:cobblestone_slab[type=bottom,waterlogged=false,weathering=false]"
      },
      {
        "char": "h",
        "block": "minecraft:glass_pane[east=true,north=false,south=false,waterlogged=false,west=true]"
      },
      {
        "char": "p",
        "block": "minecraft:mossy_cobblestone"
      },
      {
        "char": "Έ",
        "block": "minecraft:cobblestone_slab[type=top,waterlogged=false,weathering=false]"
      }
    ]
  },
  "slices": [
    [
      "         Bcbb τ ",
      "        iabb    ",
      "         Bcc    ",
      "        iebcb   ",
      "         Bccbcb ",
      "        ikbcbbcb",
      "        xdaMkMeM",
      "       icy  l   ",
      "        l       ",
      "                ",
      "                ",
      "                ",
      "                ",
      "                ",
      "                ",
      "                "
    ],
    [
      "         g oV o ",
      "        iaҔE    ",
      "         goV    ",
      "        iaVcV   ",
      "         gV EoV ",
      "        idτττoEV",
      "        xadMehdh",
      "       icy  l   ",
      "        l       ",
      "                ",
      "                ",
      "                ",
      "                ",
      "                ",
      "                ",
      "                "
    ],
    [
      "         g      ",
      "        id      ",
      "         g      ",
      "        ie      ",
      "         g      ",
      "        idEEτ   ",
      "        xddhahdh",
      "       ipy  l   ",
      "        l       ",
      "                ",
      "                ",
      "                ",
      "                ",
      "                ",
      "                ",
      "                "
    ],
    [
      "         g      ",
      "        id      ",
      "         g      ",
      "        id      ",
      "         g      ",
      "        ie      ",
      "        xakhkhah",
      "       ipy  l   ",
      "        l       ",
      "                ",
      "                ",
      "                ",
      "                ",
      "                ",
      "                ",
      "                "
    ],
    [
      "         g      ",
      "        id      ",
      "         g      ",
      "        id      ",
      "         g      ",
      "        ie      ",
      "        xaahehdh",
      "       icy  l   ",
      "        l       ",
      "                ",
      "                ",
      "                ",
      "                ",
      "                ",
      "                ",
      "                "
    ],
    [
      "         Bbbc   ",
      "        ikccEE  ",
      "         Bcbc   ",
      "        iebbcΈ  ",
      "         Bcbc   ",
      "        idbc    ",
      "        xdeMehdh",
      "       ipy  l   ",
      "        l       ",
      "                ",
      "                ",
      "                ",
      "                ",
      "                ",
      "                ",
      "                "
    ]
  ]
}