{
  "xsize": 16,
  "zsize": 16,
  "palette": {
    "palette": [
      {
        "char": " ",
        "block": "minecraft:air"
      },
      {
        "char": "b",
        "block": "minecraft:glass"
      },
      {
        "char": "h",
        "block": "minecraft:vine[east=false,north=false,south=false,up=false,west=true]"
      },
      {
        "char": "j",
        "block": "minecraft:bookshelf"
      },
      {
        "char": "a",
        "block": "minecraft:cobblestone[weathering=false]"
      },
      {
        "char": "΄",
        "block": "minecraft:green_carpet"
      },
      {
        "char": "V",
        "block": "minecraft:stone_brick_stairs[facing=east,half=bottom,shape=straight,waterlogged=false,weathering=false]"
      },
      {
        "char": "k",
        "block": "minecraft:stone_bricks[weathering=false]"
      },
      {
        "char": "d",
        "block": "minecraft:mossy_cobblestone"
      },
      {
        "char": "Ϫ",
        "block": "minecraft:chest[facing=north,type=single,waterlogged=false]",
        "loot": "bigbuildingsloot",
        "tag": {
          "z": 598,
          "x": 47,
          "ForgeData": {
            "LockFlag": "1b"
          },
          "ForgeCaps": {},
          "id": "minecraft:chest",
          "y": 154,
          "Items": []
        }
      },
      {
        "char": "c",
        "block": "minecraft:stone[weathering=false]"
      },
      {
        "char": "z",
        "block": "minecraft:cracked_stone_bricks"
      },
      {
        "char": "f",
        "block": "minecraft:vine[east=false,north=true,south=false,up=false,west=false]"
      },
      {
        "char": "ͻ",
        "block": "minecraft:vine[east=false,north=false,south=false,up=true,west=false]"
      },
      {
        "char": "Π",
        "block": "minecraft:vine[east=false,north=false,south=false,up=true,west=true]"
      },
      {
        "char": "e",
        "block": "minecraft:smooth_stone_slab[type=double,waterlogged=false]"
      },
      {
        "char": "Ή",
        "block": "minecraft:air"
      },
      {
        "char": "i",
        "block": "minecraft:vine[east=false,north=false,south=true,up=false,west=false]"
      },
      {
        "char": "ί",
        "block": "minecraft:air"
      },
      {
        "char": "ά",
        "block": "minecraft:stone_brick_stairs[facing=west,half=top,shape=straight,waterlogged=false,weathering=false]"
      },
      {
        "char": "N",
        "block": "minecraft:iron_bars[east=true,north=false,south=false,waterlogged=false,west=true]"
      },
      {
        "char": "Ν",
        "block": "minecraft:air"
      },
      {
        "char": "Ф",
        "block": "minecraft:iron_bars[east=true,north=true,south=false,waterlogged=false,west=true]"
      },
      {
        "char": "ϫ",
        "block": "minecraft:air"
      },
      {
        "char": "y",
        "block": "minecraft:mossy_stone_bricks"
      },
      {
        "char": "Ϩ",
        "block": "minecraft:vine[east=false,north=false,south=true,up=true,west=false]"
      }
    ]
  },
  "slices": [
    [
      "       bh       ",
      "j  jjj ah       ",
      "       b        ",
      "       a        ",
      "       b        ",
      "΄Vk kj d        ",
      "΄VkϪkj b        ",
      "bcbababc h      ",
      "        zh      ",
      " fff    f       ",
      "                ",
      "                ",
      "                ",
      "                ",
      "                ",
      "                "
    ],
    [
      "       b        ",
      "j  jjj ah       ",
      "       b        ",
      "       c        ",
      "       b        ",
      "  Vkkj a        ",
      "  V kj b        ",
      "babdbdba h      ",
      "        kh      ",
      " fff    f       ",
      "                ",
      "                ",
      "                ",
      "                ",
      "                ",
      "                "
    ],
    [
      "       bͻ       ",
      "       aΠ       ",
      "       bͻ       ",
      "       cͻ       ",
      "       b        ",
      "   Vkj a        ",
      "   Vkj b        ",
      "babcbcbd h      ",
      "        zh      ",
      " fff    f       ",
      "                ",
      "                ",
      "                ",
      "                ",
      "                ",
      "                "
    ],
    [
      "dcccaadae       ",
      "ccccdcdae       ",
      "caadcdaae       ",
      "ddcdcccae       ",
      "dadcdddae       ",
      "a   Vddae       ",
      "a   Vdaae       ",
      "aaaaaaaaeh      ",
      "eeeeeeeeeh      ",
      " fff    f       ",
      "                ",
      "                ",
      "                ",
      "                ",
      "                ",
      "                "
    ],
    [
      "        Ή       ",
      "        Ή       ",
      "        Ή       ",
      "  iiii  Ή       ",
      "Vkkkkk kί       ",
      "Vά     kί       ",
      "Vά   i kί       ",
      "Vkkkkkkkί       ",
      "NΝΝΝФΝΝΝϫ       ",
      "                ",
      "                ",
      "                ",
      "                ",
      "                ",
      "                ",
      "                "
    ],
    [
      "                ",
      "                ",
      "                ",
      "  iii           ",
      " Vyk   y        ",
      " Vά    k        ",
      " Vά  Ϩ k        ",
      " Vkkkyyk        ",
      "                ",
      "                ",
      "                ",
      "                ",
      "                ",
      "                ",
      "                ",
      "                "
    ]
  ]
}