{
  "xsize": 16,
  "zsize": 16,
  "palette": {
    "palette": [
      {
        "char": " ",
        "block": "minecraft:air"
      },
      {
        "char": "i",
        "block": "minecraft:vine[east=false,north=false,south=true,up=false,west=false]"
      },
      {
        "char": "g",
        "block": "minecraft:vine[east=true,north=false,south=false,up=false,west=false]"
      },
      {
        "char": "k",
        "block": "minecraft:stone_bricks[weathering=false]"
      },
      {
        "char": "a",
        "block": "minecraft:cobblestone[weathering=false]"
      },
      {
        "char": "b",
        "block": "minecraft:glass"
      },
      {
        "char": "c",
        "block": "minecraft:stone[weathering=false]"
      },
      {
        "char": "d",
        "block": "minecraft:mossy_cobblestone"
      },
      {
        "char": "B",
        "block": "minecraft:water[level=8]"
      },
      {
        "char": "ͻ",
        "block": "minecraft:vine[east=false,north=false,south=false,up=true,west=false]"
      },
      {
        "char": "Ε",
        "block": "minecraft:vine[east=true,north=false,south=false,up=true,west=false]"
      },
      {
        "char": "e",
        "block": "minecraft:smooth_stone_slab[type=double,waterlogged=false]"
      },
      {
        "char": "u",
        "block": "minecraft:stone_brick_slab[type=top,waterlogged=false,weathering=false]"
      },
      {
        "char": "j",
        "block": "minecraft:bookshelf"
      },
      {
        "char": ";",
        "block": "minecraft:air"
      },
      {
        "char": "w",
        "block": "minecraft:air"
      },
      {
        "char": "A",
        "block": "minecraft:air"
      },
      {
        "char": "v",
        "block": "minecraft:stone_brick_stairs[facing=south,half=bottom,shape=straight,waterlogged=false,weathering=false]"
      }
    ]
  },
  "slices": [
    [
      "                ",
      "                ",
      "                ",
      "                ",
      "                ",
      "                ",
      "                ",
      "        i       ",
      "       gk       ",
      "       g ababcbd",
      "       g bBb    ",
      "         ab     ",
      "         b      ",
      "         d      ",
      "        ͻb      ",
      "        Εa      "
    ],
    [
      "                ",
      "                ",
      "                ",
      "                ",
      "                ",
      "                ",
      "                ",
      "        i       ",
      "       geeeeeeee",
      "       geaaaaaaa",
      "       geaBbadac",
      "        eabcaccc",
      "        eaadcdcd",
      "      uueaacacda",
      "      u eadcadcd",
      "      u eadaddca"
    ],
    [
      "                ",
      "                ",
      "                ",
      "                ",
      "                ",
      "                ",
      "                ",
      "        i       ",
      "       gk       ",
      "       g dbdbcba",
      "       g bBbj   ",
      "         cbj    ",
      "     ;wwwbj  jjj",
      "     A   d      ",
      "     A v b      ",
      "     A   a   jjj"
    ],
    [
      "                ",
      "                ",
      "                ",
      "                ",
      "                ",
      "                ",
      "                ",
      "        i       ",
      "       gk       ",
      "       g dbdba d",
      "       g bBbj   ",
      "         cbj    ",
      "       g bj  jjj",
      "         c      ",
      "         b      ",
      "       v a   jjj"
    ],
    [
      "                ",
      "                ",
      "                ",
      "                ",
      "                ",
      "                ",
      "                ",
      "        i       ",
      "       gk       ",
      "       g cbabcba",
      "       g bBb    ",
      "         cb     ",
      "       g b      ",
      "         a      ",
      "         b      ",
      "         c      "
    ],
    [
      "                ",
      "                ",
      "                ",
      "                ",
      "                ",
      "                ",
      "                ",
      "        i       ",
      "       geeeeeeee",
      "       geaaaaaaa",
      "       geaBbaccd",
      "        eabcdddc",
      "       geaddcadd",
      "      uueacddaac",
      "      u eaadddac",
      "      u eacaacaa"
    ]
  ]
}