{
  "xsize": 16,
  "zsize": 16,
  "palette": {
    "palette": [
      {
        "char": " ",
        "block": "minecraft:air"
      },
      {
        "char": "v",
        "block": "minecraft:stone_brick_stairs[facing=south,half=bottom,shape=straight,waterlogged=false,weathering=false]"
      },
      {
        "char": "ͻ",
        "block": "minecraft:vine[east=false,north=false,south=false,up=true,west=false]"
      },
      {
        "char": "b",
        "block": "minecraft:glass"
      },
      {
        "char": "d",
        "block": "minecraft:mossy_cobblestone"
      },
      {
        "char": "g",
        "block": "minecraft:vine[east=true,north=false,south=false,up=false,west=false]"
      },
      {
        "char": "a",
        "block": "minecraft:cobblestone[weathering=false]"
      },
      {
        "char": "c",
        "block": "minecraft:stone[weathering=false]"
      },
      {
        "char": "y",
        "block": "minecraft:mossy_stone_bricks"
      },
      {
        "char": "f",
        "block": "minecraft:vine[east=false,north=true,south=false,up=false,west=false]"
      },
      {
        "char": "u",
        "block": "minecraft:stone_brick_slab[type=top,waterlogged=false,weathering=false]"
      },
      {
        "char": "e",
        "block": "minecraft:smooth_stone_slab[type=double,waterlogged=false]"
      },
      {
        "char": "A",
        "block": "minecraft:air"
      },
      {
        "char": "ͺ",
        "block": "minecraft:gray_carpet"
      },
      {
        "char": "j",
        "block": "minecraft:bookshelf"
      },
      {
        "char": "·",
        "block": "minecraft:air"
      },
      {
        "char": "w",
        "block": "minecraft:air"
      },
      {
        "char": "k",
        "block": "minecraft:stone_bricks[weathering=false]"
      },
      {
        "char": "z",
        "block": "minecraft:cracked_stone_bricks"
      }
    ]
  },
  "slices": [
    [
      "       vͻb      ",
      "        ͻd      ",
      "         b      ",
      "       g a      ",
      "       g b      ",
      "       g d      ",
      "       g b      ",
      "       g ababdbc",
      "        y       ",
      "         ff f   ",
      "                ",
      "                ",
      "                ",
      "                ",
      "                ",
      "                "
    ],
    [
      "      u eaaadaaa",
      "      uveaadcacd",
      "      uueaaacaac",
      "       geacaccca",
      "       geaccddad",
      "       geacaadac",
      "       geaaaccda",
      "       geaaaaaaa",
      "        eeeeeeee",
      "         ff f   ",
      "                ",
      "                ",
      "                ",
      "                ",
      "                ",
      "                "
    ],
    [
      "     A   bͺͺ    ",
      "     A   dͺͺ    ",
      "     A   bvv jjj",
      "     ·wwwakk    ",
      "       g bkk    ",
      "       g dkk jjj",
      "       g bjj    ",
      "       g abcbcbd",
      "        y       ",
      "          f     ",
      "                ",
      "                ",
      "                ",
      "                ",
      "                ",
      "                "
    ],
    [
      "         b      ",
      "         c      ",
      "         b   jjj",
      "         avv    ",
      "       g bkk    ",
      "       g akk jjj",
      "       g bjj    ",
      "       g abcbdbd",
      "        z       ",
      "          f     ",
      "                ",
      "                ",
      "                ",
      "                ",
      "                ",
      "                "
    ],
    [
      "       v b      ",
      "         c      ",
      "         b      ",
      "         c      ",
      "       g bvv    ",
      "       g dkk    ",
      "       g bjj    ",
      "       g cbcbaba",
      "        z       ",
      "          f     ",
      "                ",
      "                ",
      "                ",
      "                ",
      "                ",
      "                "
    ],
    [
      "      u eaaaccdd",
      "      uveacadaca",
      "      uuea  dada",
      "        ea  cccd",
      "       gea  ddcc",
      "       geavvddcd",
      "       geadadccc",
      "       geaaaaaaa",
      "        eeeeeeee",
      "          f     ",
      "                ",
      "                ",
      "                ",
      "                ",
      "                ",
      "                "
    ]
  ]
}