{
  "xsize": 16,
  "zsize": 16,
  "palette": {
    "palette": [
      {
        "char": " ",
        "block": "minecraft:air"
      },
      {
        "char": "I",
        "block": "minecraft:iron_bars[east=false,north=true,south=true,waterlogged=false,west=false]"
      },
      {
        "char": "b",
        "block": "minecraft:glass"
      },
      {
        "char": "a",
        "block": "minecraft:cobblestone[weathering=false]"
      },
      {
        "char": "v",
        "block": "minecraft:stone_brick_stairs[facing=south,half=bottom,shape=straight,waterlogged=false,weathering=false]"
      },
      {
        "char": "Κ",
        "block": "minecraft:iron_bars[east=true,north=true,south=false,waterlogged=false,west=false]"
      },
      {
        "char": "N",
        "block": "minecraft:iron_bars[east=true,north=false,south=false,waterlogged=false,west=true]"
      },
      {
        "char": "c",
        "block": "minecraft:stone[weathering=false]"
      },
      {
        "char": "k",
        "block": "minecraft:stone_bricks[weathering=false]"
      },
      {
        "char": "g",
        "block": "minecraft:vine[east=true,north=false,south=false,up=false,west=false]"
      },
      {
        "char": "H",
        "block": "minecraft:oak_stairs[facing=north,half=bottom,shape=straight,waterlogged=false]"
      },
      {
        "char": "j",
        "block": "minecraft:bookshelf"
      },
      {
        "char": "E",
        "block": "minecraft:oak_stairs[facing=south,half=bottom,shape=straight,waterlogged=false]"
      },
      {
        "char": "d",
        "block": "minecraft:mossy_cobblestone"
      },
      {
        "char": "f",
        "block": "minecraft:vine[east=false,north=true,south=false,up=false,west=false]"
      },
      {
        "char": "U",
        "block": "minecraft:flower_pot"
      },
      {
        "char": "y",
        "block": "minecraft:mossy_stone_bricks"
      },
      {
        "char": "z",
        "block": "minecraft:cracked_stone_bricks"
      },
      {
        "char": "u",
        "block": "minecraft:stone_brick_slab[type=top,waterlogged=false,weathering=false]"
      },
      {
        "char": "e",
        "block": "minecraft:smooth_stone_slab[type=double,waterlogged=false]"
      },
      {
        "char": "Q",
        "block": "minecraft:oak_stairs[facing=west,half=bottom,shape=straight,waterlogged=false]"
      },
      {
        "char": "G",
        "block": "minecraft:oak_stairs[facing=east,half=bottom,shape=straight,waterlogged=false]"
      },
      {
        "char": "K",
        "block": "minecraft:glass_pane[east=false,north=true,south=true,waterlogged=false,west=false]"
      },
      {
        "char": "w",
        "block": "minecraft:air"
      },
      {
        "char": "Δ",
        "block": "minecraft:glass_pane[east=false,north=true,south=false,waterlogged=false,west=false]"
      },
      {
        "char": "Ϫ",
        "block": "minecraft:chest[facing=north,type=single,waterlogged=false]",
        "loot": "bigbuildingsloot",
        "tag": {
          "z": 598,
          "x": 47,
          "ForgeData": {
            "LockFlag": "1b"
          },
          "ForgeCaps": {},
          "id": "minecraft:chest",
          "y": 154,
          "Items": []
        }
      }
    ]
  },
  "slices": [
    [
      "     I   b      ",
      "     I   a      ",
      "     I   bvv    ",
      "     ΚNNNckk    ",
      "       g bkkHH H",
      "       g akkkk k",
      "       g b jEE E",
      "       g abdbaba",
      "        k       ",
      "        ffffff f",
      "                ",
      "                ",
      "                ",
      "                ",
      "                ",
      "                "
    ],
    [
      "         b      ",
      "         a      ",
      "         b      ",
      "         dvv    ",
      "       g bkk    ",
      "       g dkkUU  ",
      "       g bjj    ",
      "       g dbabdba",
      "        y       ",
      "        ffffff f",
      "                ",
      "                ",
      "                ",
      "                ",
      "                ",
      "                "
    ],
    [
      "       v b      ",
      "         d      ",
      "         b      ",
      "         a      ",
      "       g bvv    ",
      "       g ckk    ",
      "       g bjj    ",
      "       g dbabdba",
      "        z       ",
      "        ffffff f",
      "                ",
      "                ",
      "                ",
      "                ",
      "                ",
      "                "
    ],
    [
      "      u eacacddc",
      "      uveaccaacc",
      "      uuea  ccac",
      "        ed  dacd",
      "       gea  cdac",
      "       geavvcddc",
      "       geaaadcda",
      "       geaaaaaaa",
      "        eeeeeeee",
      "        ffffff f",
      "                ",
      "                ",
      "                ",
      "                ",
      "                ",
      "                "
    ],
    [
      "     I   bQkkG  ",
      "     I   a EE   ",
      "     I   b  K   ",
      "     ΚNwwd  K   ",
      "       g b  K   ",
      "       g a  Δ   ",
      "       g b     Ϫ",
      "       g cbcbcbc",
      "        z       ",
      "        fffff  f",
      "                ",
      "                ",
      "                ",
      "                ",
      "                ",
      "                "
    ],
    [
      "         b      ",
      "                ",
      "         b      ",
      "         d      ",
      "       g b      ",
      "       g c      ",
      "       g b      ",
      "       g dbcbdbc",
      "        z       ",
      "        fffff  f",
      "                ",
      "                ",
      "                ",
      "                ",
      "                ",
      "                "
    ]
  ]
}