{
  "xsize": 16,
  "zsize": 16,
  "palette": {
    "palette": [
      {
        "char": " ",
        "block": "minecraft:air"
      },
      {
        "char": "ϩ",
        "block": "minecraft:player_head[rotation=0]",
        "tag": {
          "z": 592,
          "x": 145,
          "ForgeCaps": {},
          "id": "minecraft:skull",
          "y": 160
        }
      },
      {
        "char": "a",
        "block": "minecraft:stone_bricks[weathering=false]"
      },
      {
        "char": "g",
        "block": "minecraft:glass_pane[east=false,north=true,south=true,waterlogged=false,west=false]"
      },
      {
        "char": "f",
        "block": "minecraft:vine[east=false,north=false,south=false,up=false,west=true]"
      },
      {
        "char": "Y",
        "block": "minecraft:stone_brick_slab[type=bottom,waterlogged=false,weathering=false]"
      },
      {
        "char": "e",
        "block": "minecraft:mossy_stone_bricks"
      },
      {
        "char": "k",
        "block": "minecraft:chiseled_stone_bricks[weathering=false]"
      },
      {
        "char": "й",
        "block": "minecraft:potted_blue_orchid"
      },
      {
        "char": "d",
        "block": "minecraft:cracked_stone_bricks"
      },
      {
        "char": "h",
        "block": "minecraft:glass_pane[east=true,north=false,south=false,waterlogged=false,west=true]"
      },
      {
        "char": "r",
        "block": "minecraft:dark_oak_fence[east=false,north=false,south=true,waterlogged=false,west=true]"
      },
      {
        "char": "l",
        "block": "minecraft:vine[east=false,north=true,south=false,up=false,west=false]"
      },
      {
        "char": "s",
        "block": "minecraft:dark_oak_fence[east=true,north=true,south=false,waterlogged=false,west=false]"
      },
      {
        "char": "c",
        "block": "minecraft:cobblestone[weathering=false]"
      },
      {
        "char": "J",
        "block": "minecraft:stone_brick_slab[type=top,waterlogged=false,weathering=false]"
      },
      {
        "char": "ό",
        "block": "minecraft:vine[east=true,north=true,south=false,up=false,west=false]"
      },
      {
        "char": "·",
        "block": "minecraft:stone_brick_stairs[facing=east,half=top,shape=straight,waterlogged=false,weathering=false]"
      },
      {
        "char": "δ",
        "block": "minecraft:stone_brick_stairs[facing=south,half=top,shape=straight,waterlogged=false,weathering=false]"
      },
      {
        "char": "b",
        "block": "minecraft:stone[weathering=false]"
      },
      {
        "char": "H",
        "block": "minecraft:glass_pane[east=false,north=true,south=true,waterlogged=false,west=true]"
      },
      {
        "char": "M",
        "block": "minecraft:glass_pane[east=true,north=true,south=false,waterlogged=false,west=true]"
      },
      {
        "char": "ϋ",
        "block": "minecraft:green_carpet"
      },
      {
        "char": "S",
        "block": "minecraft:lime_carpet"
      },
      {
        "char": "F",
        "block": "minecraft:cobblestone_stairs[facing=west,half=bottom,shape=straight,waterlogged=false,weathering=false]"
      },
      {
        "char": "т",
        "block": "minecraft:lever[face=wall,facing=west,powered=false]"
      },
      {
        "char": "p",
        "block": "minecraft:mossy_cobblestone"
      }
    ]
  },
  "slices": [
    [
      "ϩ a  gf         ",
      "aY   ef         ",
      "     g          ",
      "     k          ",
      "     g          ",
      "    йa          ",
      "dhkhddr         ",
      "  l lscf        ",
      "      l         ",
      "                ",
      "                ",
      "                ",
      "                ",
      "                ",
      "                ",
      "                "
    ],
    [
      "  J  gf         ",
      "Ja   ef         ",
      "     g          ",
      "     d          ",
      "     g          ",
      "     e          ",
      "dhehdd          ",
      "  l lό f        ",
      "      l         ",
      "                ",
      "                ",
      "                ",
      "                ",
      "                ",
      "                ",
      "                "
    ],
    [
      "  a  gf         ",
      "dd  ·ef         ",
      "    Jg          ",
      "    ·k          ",
      "    Jg          ",
      "δJδJJe          ",
      "ahahae          ",
      "  l lόcf        ",
      "      l         ",
      "                ",
      "                ",
      "                ",
      "                ",
      "                ",
      "                ",
      "                "
    ],
    [
      " cbccHf         ",
      "bcccbef         ",
      "cbbbbH          ",
      "ccbcck          ",
      "ccbcbH          ",
      "cbcccd          ",
      "eMeMakr         ",
      "  l lόcf        ",
      "      l         ",
      "                ",
      "                ",
      "                ",
      "                ",
      "                ",
      "                ",
      "                "
    ],
    [
      " ϋS  gf         ",
      "SSS  kf         ",
      "S S  g          ",
      "SSϋ  a          ",
      "aaF  g          ",
      "  F  d          ",
      "khehad          ",
      "  l lό f        ",
      "      l         ",
      "                ",
      "                ",
      "                ",
      "                ",
      "                ",
      "                ",
      "                "
    ],
    [
      "     gf         ",
      "    тef         ",
      "     g          ",
      "     e          ",
      "aF   g          ",
      " F   e          ",
      "ahahddr         ",
      "  l lόpf        ",
      "      l         ",
      "                ",
      "                ",
      "                ",
      "                ",
      "                ",
      "                ",
      "                "
    ]
  ]
}