{
  "xsize": 16,
  "zsize": 16,
  "palette": {
    "palette": [
      {
        "char": " ",
        "block": "minecraft:air"
      },
      {
        "char": "H",
        "block": "minecraft:oak_stairs[facing=north,half=bottom,shape=straight,waterlogged=false]"
      },
      {
        "char": "b",
        "block": "minecraft:glass"
      },
      {
        "char": "h",
        "block": "minecraft:vine[east=false,north=false,south=false,up=false,west=true]"
      },
      {
        "char": "Q",
        "block": "minecraft:oak_stairs[facing=west,half=bottom,shape=straight,waterlogged=false]"
      },
      {
        "char": "k",
        "block": "minecraft:stone_bricks[weathering=false]"
      },
      {
        "char": "G",
        "block": "minecraft:oak_stairs[facing=east,half=bottom,shape=straight,waterlogged=false]"
      },
      {
        "char": "T",
        "block": "minecraft:jungle_leaves[distance=7,persistent=true,waterlogged=false]"
      },
      {
        "char": "a",
        "block": "minecraft:cobblestone[weathering=false]"
      },
      {
        "char": "E",
        "block": "minecraft:oak_stairs[facing=south,half=bottom,shape=straight,waterlogged=false]"
      },
      {
        "char": "c",
        "block": "minecraft:stone[weathering=false]"
      },
      {
        "char": "F",
        "block": "minecraft:redstone_lamp[lit=false]"
      },
      {
        "char": "d",
        "block": "minecraft:mossy_cobblestone"
      },
      {
        "char": "f",
        "block": "minecraft:vine[east=false,north=true,south=false,up=false,west=false]"
      },
      {
        "char": "U",
        "block": "minecraft:flower_pot"
      },
      {
        "char": "z",
        "block": "minecraft:cracked_stone_bricks"
      },
      {
        "char": "y",
        "block": "minecraft:mossy_stone_bricks"
      },
      {
        "char": "e",
        "block": "minecraft:smooth_stone_slab[type=double,waterlogged=false]"
      },
      {
        "char": "j",
        "block": "minecraft:bookshelf"
      }
    ]
  },
  "slices": [
    [
      " HH    b h      ",
      "QkkG  Ta h      ",
      "QkkG   b        ",
      " EE   Ta        ",
      "       b        ",
      "       c h      ",
      "      Fb h      ",
      "bdbdbcba h      ",
      "        kh      ",
      "ffff ffff       ",
      "                ",
      "                ",
      "                ",
      "                ",
      "                ",
      "                "
    ],
    [
      "       b h      ",
      "      Td h      ",
      "  U    b        ",
      "      Tc        ",
      "       b        ",
      "       c h      ",
      "      Fb h      ",
      "babcbdbd h      ",
      "        zh      ",
      "ffff ffff       ",
      "                ",
      "                ",
      "                ",
      "                ",
      "                ",
      "                "
    ],
    [
      "       b h      ",
      "       c h      ",
      "       b        ",
      "       a        ",
      "       b        ",
      "       a h      ",
      "       b h      ",
      "bdbdbdbd h      ",
      "        yh      ",
      "ffff ffff       ",
      "                ",
      "                ",
      "                ",
      "                ",
      "                ",
      "                "
    ],
    [
      "dcdaaaaaeh      ",
      "acadaaaaeh      ",
      "dcdaaacae       ",
      "cdccdccae       ",
      "dddddcaae       ",
      "dacadcaaeh      ",
      "dcadadaaeh      ",
      "aaaaaaaaeh      ",
      "eeeeeeeeeh      ",
      "ffff ffff       ",
      "                ",
      "                ",
      "                ",
      "                ",
      "                ",
      "                "
    ],
    [
      "       b h      ",
      "  jjj  c h      ",
      "       b        ",
      "  jjj  d        ",
      "G      b        ",
      "G jjj  d        ",
      "      Fb        ",
      "bdbcbdbd h      ",
      "        kh      ",
      "ffff ffff       ",
      "                ",
      "                ",
      "                ",
      "                ",
      "                ",
      "                "
    ],
    [
      "       b h      ",
      "  jjj  c h      ",
      "       b        ",
      "  jjj  d        ",
      "       b        ",
      "  jjj  c        ",
      "      Fb        ",
      "bcbabcba h      ",
      "        kh      ",
      "ffff ffff       ",
      "                ",
      "                ",
      "                ",
      "                ",
      "                ",
      "                "
    ]
  ]
}