{
  "xsize": 16,
  "zsize": 16,
  "palette": {
    "palette": [
      {
        "char": " ",
        "block": "minecraft:air"
      },
      {
        "char": "b",
        "block": "minecraft:glass"
      },
      {
        "char": "h",
        "block": "minecraft:vine[east=false,north=false,south=false,up=false,west=true]"
      },
      {
        "char": "d",
        "block": "minecraft:mossy_cobblestone"
      },
      {
        "char": "c",
        "block": "minecraft:stone[weathering=false]"
      },
      {
        "char": "a",
        "block": "minecraft:cobblestone[weathering=false]"
      },
      {
        "char": "F",
        "block": "minecraft:redstone_lamp[lit=false]"
      },
      {
        "char": "y",
        "block": "minecraft:mossy_stone_bricks"
      },
      {
        "char": "f",
        "block": "minecraft:vine[east=false,north=true,south=false,up=false,west=false]"
      },
      {
        "char": "e",
        "block": "minecraft:smooth_stone_slab[type=double,waterlogged=false]"
      },
      {
        "char": "j",
        "block": "minecraft:bookshelf"
      },
      {
        "char": "z",
        "block": "minecraft:cracked_stone_bricks"
      },
      {
        "char": "k",
        "block": "minecraft:stone_bricks[weathering=false]"
      }
    ]
  },
  "slices": [
    [
      "       b h      ",
      "       d        ",
      "       b        ",
      "       c        ",
      "       b        ",
      "       a        ",
      "      Fb        ",
      "bdbcbabc h      ",
      "        yh      ",
      " fff    f       ",
      "                ",
      "                ",
      "                ",
      "                ",
      "                ",
      "                "
    ],
    [
      "ccdcadaaeh      ",
      "cdcdadcae       ",
      "adaacdcae       ",
      "acadaddae       ",
      "accdcccae       ",
      "dcdcdcaae       ",
      "ccadcdcae       ",
      "aaaaaaaaeh      ",
      "eeeeeeeeeh      ",
      " fff    f       ",
      "                ",
      "                ",
      "                ",
      "                ",
      "                ",
      "                "
    ],
    [
      "       b h      ",
      "       c        ",
      "  jjj  b        ",
      "       d        ",
      "       b        ",
      "  jjj  d        ",
      "      Fb        ",
      "bababcba h      ",
      "        zh      ",
      " fff    f       ",
      "                ",
      "                ",
      "                ",
      "                ",
      "                ",
      "                "
    ],
    [
      "       b h      ",
      "       a        ",
      "  jjj  b        ",
      "       a        ",
      "       b        ",
      "  jjj  c        ",
      "      Fb        ",
      "bdbdbcbd h      ",
      "        kh      ",
      " fff    f       ",
      "                ",
      "                ",
      "                ",
      "                ",
      "                ",
      "                "
    ],
    [
      "       b h      ",
      "       a        ",
      "       b        ",
      "       a        ",
      "       b        ",
      "       c        ",
      "      Fb        ",
      "bdbcbaba h      ",
      "        zh      ",
      " fff    f       ",
      "                ",
      "                ",
      "                ",
      "                ",
      "                ",
      "                "
    ],
    [
      "addadcaaeh      ",
      "daadcccae       ",
      "acdaadcae       ",
      "dacdaacae       ",
      "daccccaae       ",
      "cadcadcae       ",
      "cddadddae       ",
      "aaaaaaaaeh      ",
      "eeeeeeeeeh      ",
      " fff    f       ",
      "                ",
      "                ",
      "                ",
      "                ",
      "                ",
      "                "
    ]
  ]
}