{
  "xsize": 16,
  "zsize": 16,
  "palette": {
    "palette": [
      {
        "char": " ",
        "block": "minecraft:air"
      },
      {
        "char": "n",
        "block": "minecraft:air"
      },
      {
        "char": "t",
        "block": "minecraft:air"
      },
      {
        "char": "m",
        "block": "minecraft:air"
      },
      {
        "char": "q",
        "block": "minecraft:air"
      },
      {
        "char": "o",
        "block": "minecraft:air"
      },
      {
        "char": "s",
        "block": "minecraft:air"
      },
      {
        "char": "r",
        "block": "minecraft:air"
      },
      {
        "char": "p",
        "block": "minecraft:air"
      },
      {
        "char": "Σ",
        "block": "minecraft:air"
      },
      {
        "char": "ʹ",
        "block": "minecraft:air",
        "tag": {
          "SpawnData": {
            "entity": {}
          },
          "MaxNearbyEntities": "6s",
          "MinSpawnDelay": "200s",
          "z": 579,
          "x": 51,
          "MaxSpawnDelay": "800s",
          "RequiredPlayerRange": "16s",
          "SpawnCount": "4s",
          "ForgeCaps": {},
          "id": "minecraft:mob_spawner",
          "SpawnPotentials": [],
          "y": 132,
          "SpawnRange": "4s",
          "Delay": "94s"
        }
      },
      {
        "char": "τ",
        "block": "minecraft:air"
      },
      {
        "char": "a",
        "block": "minecraft:air"
      },
      {
        "char": "e",
        "block": "minecraft:air"
      },
      {
        "char": "l",
        "block": "minecraft:grass"
      },
      {
        "char": "R",
        "block": "minecraft:air"
      },
      {
        "char": "ϥ",
        "block": "minecraft:air"
      },
      {
        "char": "ϡ",
        "block": "minecraft:air"
      },
      {
        "char": "Ά",
        "block": "minecraft:air"
      },
      {
        "char": "Ό",
        "block": "minecraft:air"
      },
      {
        "char": "G",
        "block": "minecraft:air"
      },
      {
        "char": "h",
        "block": "minecraft:air"
      },
      {
        "char": "ψ",
        "block": "minecraft:air"
      },
      {
        "char": "Ц",
        "block": "minecraft:air"
      },
      {
        "char": "T",
        "block": "minecraft:air"
      },
      {
        "char": "Ϝ",
        "block": "minecraft:air"
      },
      {
        "char": "d",
        "block": "minecraft:air"
      },
      {
        "char": "f",
        "block": "minecraft:air"
      },
      {
        "char": "ι",
        "block": "minecraft:air"
      },
      {
        "char": "y",
        "block": "minecraft:air"
      },
      {
        "char": "b",
        "block": "minecraft:air"
      },
      {
        "char": "c",
        "block": "minecraft:air"
      },
      {
        "char": "Ϭ",
        "block": "minecraft:air"
      },
      {
        "char": "z",
        "block": "minecraft:air"
      },
      {
        "char": "k",
        "block": "minecraft:air"
      },
      {
        "char": "ϓ",
        "block": "minecraft:air"
      },
      {
        "char": "F",
        "block": "minecraft:air"
      },
      {
        "char": "ϝ",
        "block": "minecraft:air"
      },
      {
        "char": "κ",
        "block": "minecraft:air"
      },
      {
        "char": "I",
        "block": "minecraft:air"
      },
      {
        "char": "М",
        "block": "minecraft:air"
      }
    ]
  },
  "slices": [
    [
      "nnnnnnnttmmqoqss",
      "nnnnnnnttmmqrops",
      "nnnnnnnttmmpmspo",
      "nnnnnnnttmmsprqq",
      "nnnnnnnttmmrpqoq",
      "nnnnnnnttmmpspqs",
      "nnnnnnnttmmsqoqm",
      "ΣΣΣttttttʹmqqrrq",
      "tttttttttmmmpopq",
      "oroomʹʹtmmmpprqs",
      "pprmssqtmmmqqpoq",
      "sprsmopqmmsporop",
      "pmomprrsprrrmppp",
      "orqoosqpmpoqrpsq",
      "prqpsoppopsmprrr",
      "roqrmrrqroqqqqoq"
    ],
    [
      "    τττaell     ",
      "    Rϥϡaell     ",
      "    Ά lael  l   ",
      " ΌΌ Ά  aell     ",
      " ΌΌ ΆG aell     ",
      "    Ά  aeh      ",
      "ψψЦlΆ Taell   ll",
      "   aaaaaeϜl     ",
      "aadeeeeeelll    ",
      "fffflιιyfll     ",
      "   l   ylll     ",
      "    l   ll      ",
      "ll l       ll   ",
      "        l       ",
      "          ll    ",
      "    l       l   "
    ],
    [
      "       b h      ",
      "    R  c h      ",
      "       b        ",
      "    Ϭ  d        ",
      "       b        ",
      "       a h      ",
      "      Tb h      ",
      "   abcba h      ",
      "ada    yzh      ",
      "ffff ffkf       ",
      "       k        ",
      "                ",
      "                ",
      "                ",
      "                ",
      "                "
    ],
    [
      "       b h      ",
      "    R  c h      ",
      "       b        ",
      "       c        ",
      "       b        ",
      "       c h      ",
      "      Tb h      ",
      "nnncbaba h      ",
      "       ykh      ",
      "ffff ffyf       ",
      "       k        ",
      "                ",
      "                ",
      "                ",
      "                ",
      "                "
    ],
    [
      "       b h      ",
      "    R  a h      ",
      "   ϓFϝ b        ",
      "    κ  a        ",
      "       b        ",
      "       c h      ",
      "       b h      ",
      "bcbdbcbc h      ",
      "       yyh      ",
      "ffff ffkf       ",
      "       y        ",
      "                ",
      "                ",
      "                ",
      "                ",
      "                "
    ],
    [
      "cacaaaaaeh      ",
      "aaaadddaeh      ",
      "dcadccaae       ",
      "dcacaadae       ",
      "caccdadae       ",
      "ccaaaacaeh      ",
      "aaddddcaeh      ",
      "aaaaaaaaeh      ",
      "eeeeeeeeeh      ",
      "ffff ffIf       ",
      "       М        ",
      "                ",
      "                ",
      "                ",
      "                ",
      "                "
    ]
  ]
}