{
  "xsize": 16,
  "zsize": 16,
  "palette": {
    "palette": [
      {
        "char": " ",
        "block": "minecraft:air"
      },
      {
        "char": "b",
        "block": "minecraft:glass"
      },
      {
        "char": "h",
        "block": "minecraft:vine[east=false,north=false,south=false,up=false,west=true]"
      },
      {
        "char": "a",
        "block": "minecraft:cobblestone[weathering=false]"
      },
      {
        "char": "j",
        "block": "minecraft:bookshelf"
      },
      {
        "char": "c",
        "block": "minecraft:stone[weathering=false]"
      },
      {
        "char": "F",
        "block": "minecraft:redstone_lamp[lit=false]"
      },
      {
        "char": "d",
        "block": "minecraft:mossy_cobblestone"
      },
      {
        "char": "ΐ",
        "block": "minecraft:vine[east=true,north=true,south=false,up=false,west=false]"
      },
      {
        "char": "y",
        "block": "minecraft:mossy_stone_bricks"
      },
      {
        "char": "f",
        "block": "minecraft:vine[east=false,north=true,south=false,up=false,west=false]"
      },
      {
        "char": "Ϻ",
        "block": "minecraft:vine[east=true,north=true,south=false,up=true,west=false]"
      },
      {
        "char": "k",
        "block": "minecraft:stone_bricks[weathering=false]"
      },
      {
        "char": "e",
        "block": "minecraft:smooth_stone_slab[type=double,waterlogged=false]"
      },
      {
        "char": "P",
        "block": "minecraft:stone_slab[type=bottom,waterlogged=false,weathering=false]"
      },
      {
        "char": "Α",
        "block": "minecraft:stone_slab[type=double,waterlogged=false,weathering=false]"
      },
      {
        "char": "E",
        "block": "minecraft:oak_stairs[facing=south,half=bottom,shape=straight,waterlogged=false]"
      },
      {
        "char": "z",
        "block": "minecraft:cracked_stone_bricks"
      }
    ]
  },
  "slices": [
    [
      "       b h      ",
      "       a        ",
      "       b        ",
      "jj jjj c        ",
      "       b        ",
      "jj jjj a        ",
      "      Fb        ",
      "bcbcbdbc h      ",
      "       ΐyh      ",
      " fff ffff       ",
      "                ",
      "                ",
      "                ",
      "                ",
      "                ",
      "                "
    ],
    [
      "       b h      ",
      "       c        ",
      "       b        ",
      "jj jjj d        ",
      "       b        ",
      "jj jjj d        ",
      "      Fb        ",
      "bdbdbcbc h      ",
      "       ΐyh      ",
      " fff ffff       ",
      "                ",
      "                ",
      "                ",
      "                ",
      "                ",
      "                "
    ],
    [
      " F     b h      ",
      "       c        ",
      "       b        ",
      "       a        ",
      "       b        ",
      "       d        ",
      "      Fb        ",
      "bdbcbdba h      ",
      "       Ϻkh      ",
      " fff ffff       ",
      "                ",
      "                ",
      "                ",
      "                ",
      "                ",
      "                "
    ],
    [
      "accccddaeh      ",
      "cdcadcaae       ",
      "adcccdaae       ",
      "acddcdcae       ",
      "caaacdaae       ",
      "ddccdcaae       ",
      "adcccacae       ",
      "aaaaaaaaeh      ",
      "eeeeeeeeeh      ",
      " fff ffff       ",
      "                ",
      "                ",
      "                ",
      "                ",
      "                ",
      "                "
    ],
    [
      "PΑP    b h      ",
      "       a        ",
      "P  E   b        ",
      " jPj j d        ",
      " j j j b        ",
      " j j j a        ",
      "      Fb        ",
      "bcbabdbc h      ",
      "        zh      ",
      " fff ffff       ",
      "                ",
      "                ",
      "                ",
      "                ",
      "                ",
      "                "
    ],
    [
      "       b h      ",
      "       c        ",
      "       b        ",
      " j j j d        ",
      " j j j b        ",
      " j j j d        ",
      "      Fb        ",
      "bcbababc h      ",
      "        kh      ",
      " fff ffff       ",
      "                ",
      "                ",
      "                ",
      "                ",
      "                ",
      "                "
    ]
  ]
}