{
  "xsize": 16,
  "zsize": 16,
  "palette": {
    "palette": [
      {
        "char": " ",
        "block": "minecraft:air"
      },
      {
        "char": "i",
        "block": "minecraft:vine[east=false,north=false,south=true,up=false,west=false]"
      },
      {
        "char": "Ε",
        "block": "minecraft:vine[east=true,north=false,south=false,up=true,west=false]"
      },
      {
        "char": "y",
        "block": "minecraft:mossy_stone_bricks"
      },
      {
        "char": "h",
        "block": "minecraft:vine[east=false,north=false,south=false,up=false,west=true]"
      },
      {
        "char": "b",
        "block": "minecraft:glass"
      },
      {
        "char": "c",
        "block": "minecraft:stone[weathering=false]"
      },
      {
        "char": "a",
        "block": "minecraft:cobblestone[weathering=false]"
      },
      {
        "char": "d",
        "block": "minecraft:mossy_cobblestone"
      },
      {
        "char": "j",
        "block": "minecraft:bookshelf"
      },
      {
        "char": "k",
        "block": "minecraft:stone_bricks[weathering=false]"
      },
      {
        "char": "C",
        "block": "minecraft:stone_brick_stairs[facing=north,half=bottom,shape=straight,waterlogged=false,weathering=false]"
      },
      {
        "char": "e",
        "block": "minecraft:smooth_stone_slab[type=double,waterlogged=false]"
      },
      {
        "char": "g",
        "block": "minecraft:vine[east=true,north=false,south=false,up=false,west=false]"
      },
      {
        "char": "K",
        "block": "minecraft:glass_pane[east=false,north=true,south=true,waterlogged=false,west=false]"
      },
      {
        "char": "͵",
        "block": "minecraft:glass_pane[east=true,north=false,south=false,waterlogged=false,west=true]"
      }
    ]
  },
  "slices": [
    [
      "                ",
      "                ",
      "                ",
      "                ",
      "                ",
      "                ",
      "                ",
      "        i       ",
      "       Εyh      ",
      "  bcbabd        ",
      "     jjb        ",
      "     kkc        ",
      "     CCb        ",
      "       a        ",
      "       b h      ",
      "       c        "
    ],
    [
      "                ",
      "                ",
      "                ",
      "                ",
      "                ",
      "                ",
      "                ",
      "        i       ",
      "eeeeeeeeeh      ",
      "aaaaaaaae       ",
      "daddacaae       ",
      "ddccdCCae       ",
      "dddcc  ae       ",
      "cdacd  ae       ",
      "aaaad  aeh      ",
      "adcdaccae       "
    ],
    [
      "                ",
      "                ",
      "                ",
      "                ",
      "                ",
      "                ",
      "                ",
      "        i       ",
      "       gkh      ",
      "babcbcbc        ",
      "       b        ",
      "       c        ",
      "  jjj  b        ",
      "    K  c        ",
      "    K  b h      ",
      "  jjj͵͵a        "
    ],
    [
      "                ",
      "                ",
      "                ",
      "                ",
      "                ",
      "                ",
      "                ",
      "                ",
      "                ",
      "bcbdbd          ",
      "       b        ",
      "       a        ",
      "  jjj  b        ",
      "       d        ",
      "       b h      ",
      "  jjj  d        "
    ],
    [
      "                ",
      "                ",
      "                ",
      "                ",
      "                ",
      "                ",
      "                ",
      "                ",
      "                ",
      "bababa          ",
      "                ",
      "       a        ",
      "       b        ",
      "       a        ",
      "       b h      ",
      "       c        "
    ],
    [
      "                ",
      "                ",
      "                ",
      "                ",
      "                ",
      "                ",
      "                ",
      "                ",
      "eeeeeee         ",
      "aaaaaa          ",
      "addddca e       ",
      "adcaaaaae       ",
      "ccdcaacae       ",
      "ddacacaae       ",
      "aacaaccaeh      ",
      "ccdcaaaae       "
    ]
  ]
}