{
  "xsize": 16,
  "zsize": 16,
  "palette": {
    "palette": [
      {
        "char": " ",
        "block": "minecraft:air"
      },
      {
        "char": "b",
        "block": "minecraft:glass"
      },
      {
        "char": "h",
        "block": "minecraft:vine[east=false,north=false,south=false,up=false,west=true]"
      },
      {
        "char": "d",
        "block": "minecraft:mossy_cobblestone"
      },
      {
        "char": "c",
        "block": "minecraft:stone[weathering=false]"
      },
      {
        "char": "a",
        "block": "minecraft:cobblestone[weathering=false]"
      },
      {
        "char": "z",
        "block": "minecraft:cracked_stone_bricks"
      },
      {
        "char": "f",
        "block": "minecraft:vine[east=false,north=true,south=false,up=false,west=false]"
      },
      {
        "char": "e",
        "block": "minecraft:smooth_stone_slab[type=double,waterlogged=false]"
      },
      {
        "char": "G",
        "block": "minecraft:oak_stairs[facing=east,half=bottom,shape=straight,waterlogged=false]"
      },
      {
        "char": "k",
        "block": "minecraft:stone_bricks[weathering=false]"
      },
      {
        "char": "ύ",
        "block": "minecraft:oak_stairs[facing=west,half=bottom,shape=inner_left,waterlogged=false]"
      },
      {
        "char": "E",
        "block": "minecraft:oak_stairs[facing=south,half=bottom,shape=straight,waterlogged=false]"
      },
      {
        "char": "F",
        "block": "minecraft:redstone_lamp[lit=false]"
      },
      {
        "char": "U",
        "block": "minecraft:flower_pot"
      },
      {
        "char": "y",
        "block": "minecraft:mossy_stone_bricks"
      }
    ]
  },
  "slices": [
    [
      "       b h      ",
      "       d h      ",
      "       b        ",
      "       c        ",
      "       b        ",
      "       a        ",
      "       b        ",
      "bcbcbaba h      ",
      "        zh      ",
      "ffff ffff       ",
      "                ",
      "                ",
      "                ",
      "                ",
      "                ",
      "                "
    ],
    [
      "a   dccaeh      ",
      " addddcaeh      ",
      "cacccddae       ",
      "acccddcae       ",
      "dddcdddae       ",
      "ccdaaddae       ",
      "aaadacaae       ",
      "aaaaaaaaeh      ",
      "eeeeeeeeeh      ",
      "ffff ffff       ",
      "                ",
      "                ",
      "                ",
      "                ",
      "                ",
      "                "
    ],
    [
      "       b h      ",
      "       c h      ",
      "      Gb        ",
      "    k Ga        ",
      "    k Gb        ",
      "      Ga        ",
      "   ύEEFb        ",
      "bcbcbdba h      ",
      "        kh      ",
      "ffff ffff       ",
      "                ",
      "                ",
      "                ",
      "                ",
      "                ",
      "                "
    ],
    [
      "       b h      ",
      "       c h      ",
      "       b        ",
      "    U  d        ",
      "       b        ",
      "       c        ",
      "      Fb        ",
      "bdbababa h      ",
      "        zh      ",
      "ffff ffff       ",
      "                ",
      "                ",
      "                ",
      "                ",
      "                ",
      "                "
    ],
    [
      "       b h      ",
      "       d h      ",
      "       b        ",
      "       d        ",
      "       b        ",
      "       d        ",
      "       b        ",
      "bcbcbabd h      ",
      "        yh      ",
      "ffff ffff       ",
      "                ",
      "                ",
      "                ",
      "                ",
      "                ",
      "                "
    ],
    [
      "ddddddaaeh      ",
      "ccdaaddaeh      ",
      "dcaddadae       ",
      "dddccacae       ",
      "cccdcccae       ",
      "acccaaaae       ",
      "daaaccdae       ",
      "aaaaaaaaeh      ",
      "eeeeeeeeeh      ",
      "ffff ffff       ",
      "                ",
      "                ",
      "                ",
      "                ",
      "                ",
      "                "
    ]
  ]
}