{
  "xsize": 16,
  "zsize": 16,
  "palette": {
    "palette": [
      {
        "char": " ",
        "block": "minecraft:air"
      },
      {
        "char": "i",
        "block": "minecraft:vine[east=false,north=false,south=true,up=false,west=false]"
      },
      {
        "char": "g",
        "block": "minecraft:vine[east=true,north=false,south=false,up=false,west=false]"
      },
      {
        "char": "y",
        "block": "minecraft:mossy_stone_bricks"
      },
      {
        "char": "Ί",
        "block": "minecraft:vine[east=false,north=false,south=true,up=false,west=true]"
      },
      {
        "char": "d",
        "block": "minecraft:mossy_cobblestone"
      },
      {
        "char": "b",
        "block": "minecraft:glass"
      },
      {
        "char": "c",
        "block": "minecraft:stone[weathering=false]"
      },
      {
        "char": "B",
        "block": "minecraft:water[level=8]"
      },
      {
        "char": "j",
        "block": "minecraft:bookshelf"
      },
      {
        "char": "a",
        "block": "minecraft:cobblestone[weathering=false]"
      },
      {
        "char": ";",
        "block": "minecraft:air"
      },
      {
        "char": "w",
        "block": "minecraft:air"
      },
      {
        "char": "A",
        "block": "minecraft:air"
      },
      {
        "char": "v",
        "block": "minecraft:stone_brick_stairs[facing=south,half=bottom,shape=straight,waterlogged=false,weathering=false]"
      },
      {
        "char": "z",
        "block": "minecraft:cracked_stone_bricks"
      },
      {
        "char": "Π",
        "block": "minecraft:vine[east=false,north=false,south=false,up=true,west=true]"
      },
      {
        "char": "Ϲ",
        "block": "minecraft:water[level=0]"
      },
      {
        "char": "e",
        "block": "minecraft:smooth_stone_slab[type=double,waterlogged=false]"
      },
      {
        "char": "k",
        "block": "minecraft:stone_bricks[weathering=false]"
      },
      {
        "char": "u",
        "block": "minecraft:stone_brick_slab[type=top,waterlogged=false,weathering=false]"
      },
      {
        "char": "N",
        "block": "minecraft:iron_bars[east=true,north=false,south=false,waterlogged=false,west=true]"
      },
      {
        "char": "I",
        "block": "minecraft:iron_bars[east=false,north=true,south=true,waterlogged=false,west=false]"
      },
      {
        "char": "E",
        "block": "minecraft:oak_stairs[facing=south,half=bottom,shape=straight,waterlogged=false]"
      },
      {
        "char": "ϫ",
        "block": "minecraft:air"
      },
      {
        "char": "O",
        "block": "minecraft:white_wool"
      },
      {
        "char": "Ͻ",
        "block": "minecraft:chest[facing=east,type=single,waterlogged=false]",
        "loot": "bigbuildingsloot",
        "tag": {
          "z": 589,
          "x": 38,
          "ForgeData": {
            "LockFlag": "1b"
          },
          "ForgeCaps": {},
          "id": "minecraft:chest",
          "y": 190,
          "Items": []
        }
      },
      {
        "char": "ͷ",
        "block": "minecraft:red_wool"
      },
      {
        "char": "G",
        "block": "minecraft:oak_stairs[facing=east,half=bottom,shape=straight,waterlogged=false]"
      }
    ]
  },
  "slices": [
    [
      "                ",
      "                ",
      "                ",
      "                ",
      "                ",
      "                ",
      "                ",
      "        i       ",
      "       gyΊ      ",
      "       g dbcbdbc",
      "         bBbj   ",
      "         abj  jj",
      "     ;wwwbj     ",
      "     A   a      ",
      "     A v b  j jj",
      "     A   d      "
    ],
    [
      "                ",
      "                ",
      "                ",
      "                ",
      "                ",
      "                ",
      "                ",
      "        i       ",
      "       gyΊ      ",
      "       g abcbcbd",
      "         bBbj   ",
      "         dbj  jj",
      "         bj     ",
      "         c      ",
      "         b  j jj",
      "       v a      "
    ],
    [
      "                ",
      "                ",
      "                ",
      "                ",
      "                ",
      "                ",
      "                ",
      "        i       ",
      "       gzΠ      ",
      "       g abababc",
      "         bϹb    ",
      "         cb     ",
      "         b      ",
      "         d      ",
      "         b      ",
      "         a      "
    ],
    [
      "                ",
      "                ",
      "                ",
      "                ",
      "                ",
      "                ",
      "                ",
      "        i       ",
      "       geeeeeeee",
      "       geaaaaaaa",
      "        eackccad",
      "        eakcdcda",
      "        eaccdcda",
      "      uueaaadaac",
      "      u eadacadc",
      "      u eaaacdad"
    ],
    [
      "                ",
      "                ",
      "                ",
      "                ",
      "                ",
      "                ",
      "                ",
      "                ",
      "        ;wwwwNNw",
      "        I       ",
      "        I       ",
      "        A   EE  ",
      "     ;wwϫ OOOOOO",
      "     AϽ   OͷOOͷO",
      "     A    OͷOOͷO",
      "     A   GOͷͷͷͷO"
    ],
    [
      "                ",
      "                ",
      "                ",
      "                ",
      "                ",
      "                ",
      "                ",
      "                ",
      "                ",
      "                ",
      "                ",
      "                ",
      "                ",
      "                ",
      "                ",
      "                "
    ]
  ]
}