{
  "xsize": 16,
  "zsize": 16,
  "palette": {
    "palette": [
      {
        "char": " ",
        "block": "minecraft:air"
      },
      {
        "char": "u",
        "block": "minecraft:air"
      },
      {
        "char": "f",
        "block": "minecraft:air"
      },
      {
        "char": "b",
        "block": "minecraft:air"
      },
      {
        "char": "l",
        "block": "minecraft:air"
      },
      {
        "char": "a",
        "block": "minecraft:air"
      },
      {
        "char": "y",
        "block": "minecraft:air"
      },
      {
        "char": "e",
        "block": "minecraft:air"
      },
      {
        "char": "F",
        "block": "minecraft:air"
      },
      {
        "char": "I",
        "block": "minecraft:air"
      },
      {
        "char": "х",
        "block": "minecraft:air"
      },
      {
        "char": "е",
        "block": "minecraft:air"
      },
      {
        "char": "H",
        "block": "minecraft:air"
      },
      {
        "char": "ф",
        "block": "minecraft:air"
      },
      {
        "char": "E",
        "block": "minecraft:air"
      },
      {
        "char": "z",
        "block": "minecraft:air"
      },
      {
        "char": "m",
        "block": "minecraft:air"
      },
      {
        "char": "好",
        "block": "minecraft:air"
      },
      {
        "char": "R",
        "block": "minecraft:air"
      },
      {
        "char": "切",
        "block": "minecraft:air"
      },
      {
        "char": "B",
        "block": "minecraft:air"
      },
      {
        "char": "A",
        "block": "minecraft:air"
      },
      {
        "char": "ӷ",
        "block": "minecraft:air"
      },
      {
        "char": "p",
        "block": "minecraft:air"
      },
      {
        "char": "下",
        "block": "minecraft:air"
      },
      {
        "char": "Q",
        "block": "minecraft:air"
      },
      {
        "char": "w",
        "block": "minecraft:grass"
      },
      {
        "char": "G",
        "block": "minecraft:tall_grass[half=lower]"
      },
      {
        "char": "л",
        "block": "minecraft:air"
      },
      {
        "char": "N",
        "block": "minecraft:air"
      },
      {
        "char": "i",
        "block": "minecraft:air"
      },
      {
        "char": "o",
        "block": "minecraft:air"
      },
      {
        "char": "Ь",
        "block": "minecraft:air"
      },
      {
        "char": "ѿ",
        "block": "minecraft:air"
      },
      {
        "char": "Ѳ",
        "block": "minecraft:air"
      },
      {
        "char": "P",
        "block": "minecraft:tall_grass[half=upper]"
      },
      {
        "char": "ѱ",
        "block": "minecraft:air"
      },
      {
        "char": "提",
        "block": "minecraft:air"
      },
      {
        "char": "щ",
        "block": "minecraft:air"
      },
      {
        "char": "h",
        "block": "minecraft:air"
      },
      {
        "char": "处",
        "block": "minecraft:air"
      },
      {
        "char": "全",
        "block": "minecraft:air"
      },
      {
        "char": "Ӄ",
        "block": "minecraft:air"
      },
      {
        "char": "开",
        "block": "minecraft:air"
      }
    ]
  },
  "slices": [
    [
      "ufblay          ",
      "aabebF          ",
      "bbfefI          ",
      "fauefх          ",
      "fbaeaе          ",
      "afalbI          ",
      "babeby          ",
      "fabebH          ",
      "fbflbф          ",
      "fbaeaF          ",
      "bbalfy          ",
      "fbaebH          ",
      "uafeaE          ",
      "fbfebF          ",
      "fbalby          ",
      "ffbebH          "
    ],
    [
      "zmme            ",
      "zmme好           ",
      "Rmme切           ",
      "fmfeE           ",
      "BAzeE           ",
      "RRzeӷp          ",
      "AAzeH           ",
      "fAfeE           ",
      "fAze下           ",
      "BAze下           ",
      "zBzeӷ           ",
      "Bffee           ",
      "fzBee           ",
      "Amze切           ",
      "AmmeE           ",
      "mmmeE           "
    ],
    [
      "QwGe            ",
      "лwwe好           ",
      "Nwwe            ",
      "лwie            ",
      "лi e            ",
      "E oeӷ           ",
      "Q ie            ",
      "Q ieӷ           ",
      "   e            ",
      " iie            ",
      "Eioe好           ",
      "E Ьe            ",
      "Qѿ e            ",
      "Qwoe            ",
      "QGwe            ",
      "wGGe            "
    ],
    [
      "Ѳ Pi            ",
      "ѱ  i下           ",
      "   i            ",
      "Ѳ               ",
      "ѱ               ",
      "   i提           ",
      "Ѳ  i            ",
      "ѱ   ӷ           ",
      "                ",
      "                ",
      "    提           ",
      "   i            ",
      "щh i            ",
      "щ  i            ",
      "щ               ",
      "  Pi            "
    ],
    [
      "                ",
      "    下           ",
      "    提           ",
      "    提           ",
      "    提           ",
      "    好           ",
      "                ",
      "                ",
      "    下           ",
      "                ",
      "    提           ",
      " 处ѿ             ",
      "h全h             ",
      " Ӄ              ",
      "                ",
      "                "
    ],
    [
      "                ",
      "    下           ",
      "                ",
      "                ",
      "                ",
      "    开           ",
      "                ",
      "    ӷ           ",
      "                ",
      "                ",
      "    提           ",
      " hh             ",
      "hhh             ",
      " h              ",
      "                ",
      "                "
    ]
  ]
}