{
  "xsize": 16,
  "zsize": 16,
  "palette": {
    "palette": [
      {
        "char": " ",
        "block": "minecraft:air"
      },
      {
        "char": "a",
        "block": "minecraft:stone_bricks[weathering=true]"
      },
      {
        "char": "e",
        "block": "minecraft:polished_andesite"
      },
      {
        "char": "f",
        "block": "minecraft:stone[weathering=false]"
      },
      {
        "char": "o",
        "block": "minecraft:air"
      },
      {
        "char": "b",
        "block": "minecraft:cracked_stone_bricks"
      },
      {
        "char": "u",
        "block": "minecraft:stone_bricks[weathering=false]"
      },
      {
        "char": "m",
        "block": "minecraft:grass_block[snowy=false]"
      },
      {
        "char": "A",
        "block": "minecraft:dead_fire_coral_block"
      },
      {
        "char": "z",
        "block": "minecraft:dead_bubble_coral_block"
      },
      {
        "char": "B",
        "block": "minecraft:dead_brain_coral_block"
      },
      {
        "char": "R",
        "block": "minecraft:cobblestone[weathering=false]"
      },
      {
        "char": "G",
        "block": "minecraft:air"
      },
      {
        "char": "w",
        "block": "minecraft:air"
      },
      {
        "char": "Q",
        "block": "minecraft:air"
      },
      {
        "char": "p",
        "block": "minecraft:air"
      },
      {
        "char": "Ҁ",
        "block": "minecraft:spruce_fence[east=true,north=false,south=false,waterlogged=false,west=false]"
      },
      {
        "char": "Э",
        "block": "minecraft:air"
      },
      {
        "char": "E",
        "block": "minecraft:smooth_stone_slab[type=bottom,waterlogged=false]"
      },
      {
        "char": "i",
        "block": "minecraft:air"
      },
      {
        "char": "л",
        "block": "minecraft:air"
      },
      {
        "char": "N",
        "block": "minecraft:stone_slab[type=bottom,waterlogged=false,weathering=false]"
      },
      {
        "char": "з",
        "block": "minecraft:air"
      },
      {
        "char": "P",
        "block": "minecraft:air"
      },
      {
        "char": "ц",
        "block": "minecraft:air"
      },
      {
        "char": "h",
        "block": "minecraft:oak_leaves[distance=7,persistent=true,waterlogged=false]"
      },
      {
        "char": "Ѱ",
        "block": "minecraft:rail[shape=south_east,waterlogged=false]"
      },
      {
        "char": "Ѯ",
        "block": "minecraft:rail[shape=north_east,waterlogged=false]"
      },
      {
        "char": "ӊ",
        "block": "minecraft:spruce_fence[east=false,north=false,south=true,waterlogged=false,west=false]"
      },
      {
        "char": "全",
        "block": "minecraft:spruce_fence[east=false,north=true,south=true,waterlogged=false,west=false]"
      },
      {
        "char": "组",
        "block": "minecraft:spruce_fence[east=false,north=true,south=false,waterlogged=false,west=true]"
      }
    ]
  },
  "slices": [
    [
      "           aefff",
      "          obebbb",
      "           aeaaa",
      "          oaebba",
      "           bebba",
      "          obeaaa",
      "           aeabb",
      "          obeaaa",
      "          oaeuaa",
      "          oaeaba",
      "           aebbb",
      "          obeaba",
      "          obeaba",
      "          obebba",
      "          oaeaaa",
      "          oaeuab"
    ],
    [
      "           aeeee",
      "          oaemmm",
      "           bemmA",
      "          oaezmA",
      "           aeBzf",
      "          oaeffB",
      "          obezBz",
      "           aezAB",
      "          oaezAf",
      "          oaefAf",
      "           bezAA",
      "          oaezRR",
      "           aezAB",
      "          oaefmf",
      "          oaemmR",
      "           bemmz"
    ],
    [
      "           aeeee",
      "          obeGGw",
      "           bewGQ",
      "           bepwQ",
      "          oae ҀQ",
      "          obeЭ E",
      "          obepiE",
      "           beii ",
      "           ae   ",
      "          oaei Q",
      "           bei Q",
      "          obep E",
      "           ae iл",
      "          oaeiwл",
      "          obewwN",
      "           bewwл"
    ],
    [
      "           ii  i",
      "           зiP  ",
      "           i   ц",
      "           зi  ц",
      "          oзi hц",
      "           ii   ",
      "           з    ",
      "          oз    ",
      "           з    ",
      "           i   Ѱ",
      "           зi  Ѯ",
      "           ii   ",
      "          oз   Ѱ",
      "           i   Ѯ",
      "           ii   ",
      "           зi  Ѱ"
    ],
    [
      "                ",
      "                ",
      "                ",
      "              ӊ ",
      "             h全h",
      "             Ҁ组 ",
      "                ",
      "                ",
      "                ",
      "                ",
      "                ",
      "                ",
      "                ",
      "                ",
      "                ",
      "                "
    ],
    [
      "                ",
      "                ",
      "                ",
      "              h ",
      "             hhh",
      "             hh ",
      "                ",
      "                ",
      "                ",
      "                ",
      "                ",
      "                ",
      "                ",
      "                ",
      "                ",
      "                "
    ]
  ]
}