{
  "xsize": 16,
  "zsize": 16,
  "palette": {
    "palette": [
      {
        "char": " ",
        "block": "minecraft:air"
      },
      {
        "char": "l",
        "block": "minecraft:air"
      },
      {
        "char": "e",
        "block": "minecraft:air"
      },
      {
        "char": "p",
        "block": "minecraft:air"
      },
      {
        "char": "g",
        "block": "minecraft:air"
      },
      {
        "char": "c",
        "block": "minecraft:air"
      },
      {
        "char": "v",
        "block": "minecraft:air"
      },
      {
        "char": "j",
        "block": "minecraft:air"
      },
      {
        "char": "ҽ",
        "block": "minecraft:air"
      },
      {
        "char": "m",
        "block": "minecraft:air"
      },
      {
        "char": "B",
        "block": "minecraft:air"
      },
      {
        "char": "A",
        "block": "minecraft:air"
      },
      {
        "char": "z",
        "block": "minecraft:air"
      },
      {
        "char": "f",
        "block": "minecraft:air"
      },
      {
        "char": "R",
        "block": "minecraft:air"
      },
      {
        "char": "Ҷ",
        "block": "minecraft:air"
      },
      {
        "char": "S",
        "block": "minecraft:air"
      },
      {
        "char": "i",
        "block": "minecraft:air"
      },
      {
        "char": "я",
        "block": "minecraft:air"
      },
      {
        "char": "G",
        "block": "minecraft:tall_grass[half=lower]"
      },
      {
        "char": "w",
        "block": "minecraft:grass"
      },
      {
        "char": "с",
        "block": "minecraft:air"
      },
      {
        "char": "Q",
        "block": "minecraft:air"
      },
      {
        "char": "E",
        "block": "minecraft:air"
      },
      {
        "char": "N",
        "block": "minecraft:air"
      },
      {
        "char": "n",
        "block": "minecraft:air"
      },
      {
        "char": "o",
        "block": "minecraft:air"
      },
      {
        "char": "岛",
        "block": "minecraft:air"
      },
      {
        "char": "q",
        "block": "minecraft:air"
      },
      {
        "char": "р",
        "block": "minecraft:air"
      },
      {
        "char": "P",
        "block": "minecraft:tall_grass[half=upper]"
      },
      {
        "char": "Ӝ",
        "block": "minecraft:air"
      },
      {
        "char": "h",
        "block": "minecraft:air"
      },
      {
        "char": "С",
        "block": "minecraft:air"
      },
      {
        "char": "о",
        "block": "minecraft:air"
      },
      {
        "char": "У",
        "block": "minecraft:air"
      },
      {
        "char": "Ҁ",
        "block": "minecraft:air"
      },
      {
        "char": "行",
        "block": "minecraft:air"
      },
      {
        "char": "ѿ",
        "block": "minecraft:air"
      }
    ]
  },
  "slices": [
    [
      "leleeeeep       ",
      "gcvvcggep       ",
      "gccvjjce        ",
      "ccgcccglp       ",
      "ccjcggglp       ",
      "cvjjjjcl        ",
      "cjjvccgl        ",
      "ccg  ҽ l        ",
      "vcc    e        ",
      "eeelllee        ",
      "cgcccvve        ",
      "gcggccclp       ",
      "ccggcjge        ",
      "gcccjcce        ",
      "cvjcgcje        ",
      "gccccvce        "
    ],
    [
      "cvcgggjl        ",
      "mmmmmmmc        ",
      "BAAzAfRgp       ",
      "BmAmfmBc        ",
      "zARffRzg        ",
      "mmmmmmmj        ",
      "AmzAҶffc        ",
      "zffSҽ  c        ",
      "BBBS   g        ",
      "fmffAfzc        ",
      "mmmmmRmjp       ",
      "zmmmfBmg        ",
      "ffffzBAc        ",
      "AzzBmffg        ",
      "mABmmmAg        ",
      "mAmmmmRg        "
    ],
    [
      "iяяяяiяe        ",
      "GGwwGwGс        ",
      "QEQNQNEi        ",
      "QwQwQwEс        ",
      "QNQEQEEс        ",
      "wwwnwwwс        ",
      "iwcjgccg        ",
      " og    g        ",
      "i岛     cp       ",
      " wggcjjg        ",
      "wGGGq wс        ",
      " www рwс        ",
      "i     iс        ",
      "  i w  i        ",
      "wi wGwii        ",
      "w wGGw i        "
    ],
    [
      "       i        ",
      "PP  P P         ",
      "Ӝ Ӝ Ӝ           ",
      "Ӝ Ӝ Ӝ           ",
      "Ӝ Ӝ Ӝ           ",
      "    n n         ",
      " ogccjgg        ",
      " oc    c        ",
      "       g        ",
      "  cccgcc        ",
      " PPPqqq         ",
      "     h          ",
      "                ",
      "                ",
      "    P           ",
      "   PP           "
    ],
    [
      "                ",
      "                ",
      "                ",
      "                ",
      "                ",
      "  n  n n        ",
      "  cvjggc        ",
      "  c    c        ",
      "  g    g        ",
      " ocgcjgc        ",
      "   q   q        ",
      "    hh          ",
      "     р          ",
      "                ",
      "                ",
      "                "
    ],
    [
      " q              ",
      "                ",
      "                ",
      "                ",
      "                ",
      "                ",
      " СоУССУС        ",
      " УСУССоУ        ",
      " оУСУСУС        ",
      " СУУСоСУ        ",
      "     h          ",
      "    Ҁ行ѿ         ",
      "     h          ",
      "                ",
      "                ",
      "                "
    ]
  ]
}