{
  "xsize": 16,
  "zsize": 16,
  "palette": {
    "palette": [
      {
        "char": " ",
        "block": "minecraft:air"
      },
      {
        "char": "o",
        "block": "minecraft:air"
      },
      {
        "char": "a",
        "block": "minecraft:air"
      },
      {
        "char": "e",
        "block": "minecraft:air"
      },
      {
        "char": "u",
        "block": "minecraft:air"
      },
      {
        "char": "b",
        "block": "minecraft:air"
      },
      {
        "char": "f",
        "block": "minecraft:air"
      },
      {
        "char": "m",
        "block": "minecraft:air"
      },
      {
        "char": "z",
        "block": "minecraft:air"
      },
      {
        "char": "R",
        "block": "minecraft:air"
      },
      {
        "char": "A",
        "block": "minecraft:air"
      },
      {
        "char": "B",
        "block": "minecraft:air"
      },
      {
        "char": "w",
        "block": "minecraft:grass"
      },
      {
        "char": "л",
        "block": "minecraft:air"
      },
      {
        "char": "N",
        "block": "minecraft:air"
      },
      {
        "char": "i",
        "block": "minecraft:air"
      },
      {
        "char": "p",
        "block": "minecraft:air"
      },
      {
        "char": "E",
        "block": "minecraft:air"
      },
      {
        "char": "Q",
        "block": "minecraft:air"
      },
      {
        "char": "Э",
        "block": "minecraft:air"
      },
      {
        "char": "Ҁ",
        "block": "minecraft:air"
      },
      {
        "char": "G",
        "block": "minecraft:tall_grass[half=lower]"
      },
      {
        "char": "з",
        "block": "minecraft:air"
      },
      {
        "char": "Ѯ",
        "block": "minecraft:air"
      },
      {
        "char": "Ѱ",
        "block": "minecraft:air"
      },
      {
        "char": "h",
        "block": "minecraft:air"
      },
      {
        "char": "щ",
        "block": "minecraft:air"
      },
      {
        "char": "P",
        "block": "minecraft:tall_grass[half=upper]"
      },
      {
        "char": "区",
        "block": "minecraft:air"
      },
      {
        "char": "全",
        "block": "minecraft:air"
      },
      {
        "char": "Ӄ",
        "block": "minecraft:air"
      }
    ]
  },
  "slices": [
    [
      "          oaeuab",
      "          oaeaaa",
      "          obebba",
      "          obeaba",
      "          obeaba",
      "           aebbb",
      "          oueaba",
      "          oaeaaa",
      "          obeuaa",
      "           aeabb",
      "          obeaaa",
      "           bebba",
      "          oaebba",
      "           aeaaa",
      "          obebbb",
      "           aefff"
    ],
    [
      "           bemmz",
      "          oaemmR",
      "          oaefmf",
      "           aezAB",
      "          oaezRR",
      "           bezAA",
      "          oaefAf",
      "          oaezAf",
      "           aezAB",
      "          obezBz",
      "          oaeffB",
      "           aeBzf",
      "          oaezmA",
      "           bemmA",
      "          oaemmm",
      "           aeeee"
    ],
    [
      "           bewwл",
      "          obewwN",
      "          oaeiwл",
      "           ae iл",
      "          obep E",
      "           bei Q",
      "          oaei Q",
      "           ae   ",
      "           beii ",
      "          obepiE",
      "          obeЭ E",
      "          oae ҀQ",
      "           bepwQ",
      "           bewGQ",
      "          obeGGw",
      "           aeeee"
    ],
    [
      "           зi  Ѯ",
      "           ii   ",
      "           i   Ѱ",
      "          oз   Ѯ",
      "           ii   ",
      "           зi  Ѱ",
      "           i   Ѯ",
      "           з    ",
      "          oз    ",
      "           з    ",
      "           ii   ",
      "          oзi hщ",
      "           зi  щ",
      "           i   щ",
      "           зiP  ",
      "           ii  i"
    ],
    [
      "                ",
      "                ",
      "                ",
      "                ",
      "                ",
      "                ",
      "                ",
      "                ",
      "                ",
      "                ",
      "             Ҁ区 ",
      "             h全h",
      "              Ӄ ",
      "                ",
      "                ",
      "                "
    ],
    [
      "                ",
      "                ",
      "                ",
      "                ",
      "                ",
      "                ",
      "                ",
      "                ",
      "                ",
      "                ",
      "             hh ",
      "             hhh",
      "              h ",
      "                ",
      "                ",
      "                "
    ]
  ]
}