{
  "xsize": 16,
  "zsize": 16,
  "palette": {
    "palette": [
      {
        "char": " ",
        "block": "minecraft:air"
      },
      {
        "char": "f",
        "block": "minecraft:stone[weathering=false]"
      },
      {
        "char": "a",
        "block": "minecraft:stone_bricks[weathering=true]"
      },
      {
        "char": "b",
        "block": "minecraft:cracked_stone_bricks"
      },
      {
        "char": "u",
        "block": "minecraft:stone_bricks[weathering=false]"
      },
      {
        "char": "e",
        "block": "minecraft:polished_andesite"
      }
    ]
  },
  "slices": [
    [
      "fabfaaabbfbfuuff",
      "fuabaabfbabaafuf",
      "fffabbauaaffbbfa",
      "fbabafffbaaaaaua",
      "fbffabfbabafbbfa",
      "faafababbbbabbaa",
      "fabauafffabbffab",
      "fafbabfabbbabbba",
      "fbafuffuaefbbabb",
      "fbffaaffbbbaffbb",
      "faababfufbfbbbbf",
      "fbbababaabfbaabb",
      "ffabbfbbabafaabb",
      "fffabfffbfbfufbb",
      "fffabbafaaabafbf",
      "fbfbabfffabfafbf"
    ],
    [
      "a               ",
      "b               ",
      "a               ",
      "a               ",
      "b               ",
      "b               ",
      "b               ",
      "b               ",
      "b               ",
      "a               ",
      "b               ",
      "a               ",
      "a               ",
      "b               ",
      "b               ",
      "b               "
    ],
    [
      "b               ",
      "a               ",
      "b               ",
      "a               ",
      "a               ",
      "a               ",
      "b               ",
      "b               ",
      "b               ",
      "a               ",
      "a               ",
      "b               ",
      "a               ",
      "a               ",
      "b               ",
      "a               "
    ],
    [
      "b               ",
      "a               ",
      "a               ",
      "a               ",
      "b               ",
      "b               ",
      "a               ",
      "a               ",
      "b               ",
      "b               ",
      "b               ",
      "b               ",
      "a               ",
      "b               ",
      "a               ",
      "a               "
    ],
    [
      "b               ",
      "a               ",
      "u               ",
      "a               ",
      "b               ",
      "a               ",
      "b               ",
      "a               ",
      "a               ",
      "b               ",
      "b               ",
      "b               ",
      "a               ",
      "b               ",
      "b               ",
      "a               "
    ],
    [
      "b               ",
      "b               ",
      "a               ",
      "b               ",
      "b               ",
      "b               ",
      "a               ",
      "a               ",
      "b               ",
      "b               ",
      "b               ",
      "a               ",
      "b               ",
      "a               ",
      "b               ",
      "b               "
    ]
  ]
}