{
  "xsize": 16,
  "zsize": 16,
  "palette": {
    "palette": [
      {
        "char": " ",
        "block": "minecraft:air"
      },
      {
        "char": "f",
        "block": "minecraft:stone[weathering=false]"
      },
      {
        "char": "e",
        "block": "minecraft:polished_andesite"
      },
      {
        "char": "a",
        "block": "minecraft:stone_bricks[weathering=true]"
      },
      {
        "char": "b",
        "block": "minecraft:cracked_stone_bricks"
      },
      {
        "char": "p",
        "block": "minecraft:air"
      },
      {
        "char": "u",
        "block": "minecraft:stone_bricks[weathering=false]"
      },
      {
        "char": "m",
        "block": "minecraft:grass_block[snowy=false]"
      },
      {
        "char": "A",
        "block": "minecraft:dead_fire_coral_block"
      },
      {
        "char": "z",
        "block": "minecraft:dead_bubble_coral_block"
      },
      {
        "char": "B",
        "block": "minecraft:dead_brain_coral_block"
      },
      {
        "char": "R",
        "block": "minecraft:cobblestone[weathering=false]"
      },
      {
        "char": "w",
        "block": "minecraft:air"
      },
      {
        "char": "G",
        "block": "minecraft:air"
      },
      {
        "char": "Q",
        "block": "minecraft:air"
      },
      {
        "char": "o",
        "block": "minecraft:air"
      },
      {
        "char": "ѿ",
        "block": "minecraft:spruce_fence[east=false,north=false,south=false,waterlogged=false,west=true]"
      },
      {
        "char": "E",
        "block": "minecraft:smooth_stone_slab[type=bottom,waterlogged=false]"
      },
      {
        "char": "Ь",
        "block": "minecraft:air"
      },
      {
        "char": "i",
        "block": "minecraft:air"
      },
      {
        "char": "л",
        "block": "minecraft:air"
      },
      {
        "char": "N",
        "block": "minecraft:stone_slab[type=bottom,waterlogged=false,weathering=false]"
      },
      {
        "char": "P",
        "block": "minecraft:air"
      },
      {
        "char": "с",
        "block": "minecraft:air"
      },
      {
        "char": "ц",
        "block": "minecraft:air"
      },
      {
        "char": "h",
        "block": "minecraft:oak_leaves[distance=7,persistent=true,waterlogged=false]"
      },
      {
        "char": "Ѳ",
        "block": "minecraft:rail[shape=south_west,waterlogged=false]"
      },
      {
        "char": "ѱ",
        "block": "minecraft:rail[shape=north_west,waterlogged=false]"
      },
      {
        "char": "ӊ",
        "block": "minecraft:spruce_fence[east=false,north=false,south=true,waterlogged=false,west=false]"
      },
      {
        "char": "全",
        "block": "minecraft:spruce_fence[east=false,north=true,south=true,waterlogged=false,west=false]"
      },
      {
        "char": "务",
        "block": "minecraft:spruce_fence[east=true,north=true,south=false,waterlogged=false,west=false]"
      }
    ]
  },
  "slices": [
    [
      "fffea           ",
      "bbbebp          ",
      "aaaea           ",
      "abbeap          ",
      "abbeb           ",
      "aaaebp          ",
      "bbaea           ",
      "aauebp          ",
      "uaaeap          ",
      "abaeap          ",
      "bbbea           ",
      "abaebp          ",
      "abaebp          ",
      "abbebp          ",
      "aaaeap          ",
      "baaeap          "
    ],
    [
      "eeeeu           ",
      "mmmeap          ",
      "Ammeb           ",
      "Amzeap          ",
      "fzBea           ",
      "Bffeap          ",
      "zBzebp          ",
      "BAzea           ",
      "fAzeap          ",
      "fAfeap          ",
      "AAzeb           ",
      "RRzeap          ",
      "BAzea           ",
      "fmfeap          ",
      "Rmmeap          ",
      "zmmeb           "
    ],
    [
      "eeeea           ",
      "wGGebp          ",
      "QGweb           ",
      "Qwoeb           ",
      "Qѿ eap          ",
      "E Ьebp          ",
      "Eioebp          ",
      " iieb           ",
      "   ea           ",
      "Q ieap          ",
      "Q ieb           ",
      "E oebp          ",
      "лi ea           ",
      "лwieap          ",
      "Nwwebp          ",
      "лwweb           "
    ],
    [
      "i  ii           ",
      "  Piс           ",
      "ц   i           ",
      "ц  iс           ",
      "цh iсp          ",
      "   ii           ",
      "    с           ",
      "    сp          ",
      "    с           ",
      "Ѳ   i           ",
      "ѱ  iс           ",
      "   ii           ",
      "Ѳ   сp          ",
      "ѱ   i           ",
      "   ii           ",
      "Ѳ  iс           "
    ],
    [
      "                ",
      "                ",
      "                ",
      " ӊ              ",
      "h全h             ",
      " 务ѿ             ",
      "                ",
      "                ",
      "                ",
      "                ",
      "                ",
      "                ",
      "                ",
      "                ",
      "                ",
      "                "
    ],
    [
      "                ",
      "                ",
      "                ",
      " h              ",
      "hhh             ",
      " hh             ",
      "                ",
      "                ",
      "                ",
      "                ",
      "                ",
      "                ",
      "                ",
      "                ",
      "                ",
      "                "
    ]
  ]
}