{
  "xsize": 16,
  "zsize": 16,
  "palette": {
    "palette": [
      {
        "char": " ",
        "block": "minecraft:air"
      },
      {
        "char": "f",
        "block": "minecraft:stone[weathering=false]"
      },
      {
        "char": "b",
        "block": "minecraft:cracked_stone_bricks"
      },
      {
        "char": "a",
        "block": "minecraft:stone_bricks[weathering=true]"
      },
      {
        "char": "u",
        "block": "minecraft:stone_bricks[weathering=false]"
      }
    ]
  },
  "slices": [
    [
      "ffffbafafabababb",
      "fuaffbffffafffba",
      "ffbbbbfbaffuuufa",
      "fbfaabbbaffffufu",
      "fbbauaffafbfaaba",
      "fbubfffabfbafufa",
      "fabbffbffufafuff",
      "fabafabaafbbafuf",
      "fbbfffbfbfbbauaa",
      "ffbbffffaafbaffa",
      "fafabafabbabfbff",
      "fbfbbbbbffbabfuf",
      "faafaaaabfauaffu",
      "ffbbfafaafbafbfu",
      "fbfbabaabfaababa",
      "fbabffbffuuufaff"
    ],
    [
      "a               ",
      "b               ",
      "a               ",
      "a               ",
      "b               ",
      "b               ",
      "b               ",
      "b               ",
      "b               ",
      "a               ",
      "b               ",
      "a               ",
      "a               ",
      "b               ",
      "b               ",
      "b               "
    ],
    [
      "b               ",
      "a               ",
      "b               ",
      "a               ",
      "a               ",
      "a               ",
      "b               ",
      "b               ",
      "b               ",
      "a               ",
      "a               ",
      "b               ",
      "a               ",
      "a               ",
      "b               ",
      "a               "
    ],
    [
      "b               ",
      "a               ",
      "a               ",
      "a               ",
      "b               ",
      "b               ",
      "a               ",
      "a               ",
      "b               ",
      "b               ",
      "b               ",
      "b               ",
      "a               ",
      "b               ",
      "a               ",
      "a               "
    ],
    [
      "b               ",
      "a               ",
      "a               ",
      "a               ",
      "b               ",
      "a               ",
      "b               ",
      "a               ",
      "a               ",
      "b               ",
      "b               ",
      "b               ",
      "a               ",
      "b               ",
      "b               ",
      "a               "
    ],
    [
      "b               ",
      "b               ",
      "a               ",
      "b               ",
      "b               ",
      "b               ",
      "a               ",
      "a               ",
      "b               ",
      "b               ",
      "b               ",
      "a               ",
      "b               ",
      "a               ",
      "b               ",
      "b               "
    ]
  ]
}