{
  "xsize": 16,
  "zsize": 16,
  "palette": {
    "palette": [
      {
        "char": " ",
        "block": "minecraft:air"
      },
      {
        "char": "ф",
        "block": "minecraft:air"
      },
      {
        "char": "b",
        "block": "minecraft:air"
      },
      {
        "char": "e",
        "block": "minecraft:air"
      },
      {
        "char": "c",
        "block": "minecraft:air"
      },
      {
        "char": "g",
        "block": "minecraft:air"
      },
      {
        "char": "F",
        "block": "minecraft:air"
      },
      {
        "char": "f",
        "block": "minecraft:air"
      },
      {
        "char": "I",
        "block": "minecraft:air"
      },
      {
        "char": "v",
        "block": "minecraft:air"
      },
      {
        "char": "е",
        "block": "minecraft:air"
      },
      {
        "char": "ѹ",
        "block": "minecraft:air"
      },
      {
        "char": "E",
        "block": "minecraft:air"
      },
      {
        "char": "Ѻ",
        "block": "minecraft:air"
      },
      {
        "char": "C",
        "block": "minecraft:air"
      },
      {
        "char": "y",
        "block": "minecraft:air"
      },
      {
        "char": "j",
        "block": "minecraft:air"
      },
      {
        "char": "N",
        "block": "minecraft:air"
      },
      {
        "char": "a",
        "block": "minecraft:air"
      },
      {
        "char": "х",
        "block": "minecraft:air"
      },
      {
        "char": "m",
        "block": "minecraft:air"
      },
      {
        "char": "A",
        "block": "minecraft:air"
      },
      {
        "char": "z",
        "block": "minecraft:air"
      },
      {
        "char": "B",
        "block": "minecraft:air"
      },
      {
        "char": "R",
        "block": "minecraft:air"
      },
      {
        "char": "情",
        "block": "minecraft:air"
      },
      {
        "char": "o",
        "block": "minecraft:air"
      },
      {
        "char": "з",
        "block": "minecraft:air"
      },
      {
        "char": "G",
        "block": "minecraft:tall_grass[half=lower]"
      },
      {
        "char": "w",
        "block": "minecraft:grass"
      },
      {
        "char": "Q",
        "block": "minecraft:air"
      },
      {
        "char": "i",
        "block": "minecraft:air"
      },
      {
        "char": "и",
        "block": "minecraft:air"
      },
      {
        "char": "P",
        "block": "minecraft:tall_grass[half=upper]"
      },
      {
        "char": "Ѱ",
        "block": "minecraft:air"
      },
      {
        "char": "Ѳ",
        "block": "minecraft:air"
      },
      {
        "char": "Ѯ",
        "block": "minecraft:air"
      },
      {
        "char": "ѱ",
        "block": "minecraft:air"
      }
    ]
  },
  "slices": [
    [
      "          фbecgc",
      "          Ffeccc",
      "          Ifevvv",
      "          Ieeccc",
      "          еfegcv",
      "          фѹeccc",
      "          EѺegcg",
      "          CѺegcc",
      "          yfegcj",
      "          еfecgg",
      "          фbeccg",
      "          Eeegcg",
      "          Ceecjj",
      "          Cfejgg",
      "          Naejgg",
      "          хbeeee"
    ],
    [
      "            vmmm",
      "           NvmAf",
      "           хjmzm",
      "           NvzBm",
      "            vAAm",
      "            vmzm",
      "            cmAB",
      "           EgmAR",
      "           NgmzB",
      "            gzAR",
      "            cmfm",
      "            cmmm",
      "           хgmmm",
      "           хc情mm",
      "            vmmA",
      "           oezBf"
    ],
    [
      "            зGGw",
      "            зGEE",
      "             GNG",
      "            зQQw",
      "             QQw",
      "            зGNw",
      "            зwE ",
      "             wN ",
      "            зwNi",
      "            з E ",
      "            зw w",
      "             wwG",
      "            зwGG",
      "            зiGw",
      "            зww ",
      "           oeии "
    ],
    [
      "                ",
      "             P  ",
      "             P P",
      "             ѰѲ ",
      "             Ѯѱ ",
      "             P  ",
      "                ",
      "                ",
      "                ",
      "                ",
      "                ",
      "                ",
      "              PP",
      "              P ",
      "                ",
      "            i   "
    ],
    [
      "                ",
      "                ",
      "                ",
      "                ",
      "                ",
      "                ",
      "                ",
      "                ",
      "                ",
      "                ",
      "                ",
      "                ",
      "                ",
      "                ",
      "               o",
      "                "
    ],
    [
      "                ",
      "                ",
      "                ",
      "                ",
      "                ",
      "                ",
      "                ",
      "                ",
      "                ",
      "                ",
      "                ",
      "                ",
      "                ",
      "               o",
      "                ",
      "                "
    ]
  ]
}