{
  "xsize": 16,
  "zsize": 16,
  "palette": {
    "palette": [
      {
        "char": " ",
        "block": "minecraft:air"
      },
      {
        "char": "f",
        "block": "minecraft:air"
      },
      {
        "char": "e",
        "block": "minecraft:air"
      },
      {
        "char": "u",
        "block": "minecraft:air"
      },
      {
        "char": "е",
        "block": "minecraft:air"
      },
      {
        "char": "b",
        "block": "minecraft:air"
      },
      {
        "char": "l",
        "block": "minecraft:air"
      },
      {
        "char": "a",
        "block": "minecraft:air"
      },
      {
        "char": "F",
        "block": "minecraft:air"
      },
      {
        "char": "C",
        "block": "minecraft:air"
      },
      {
        "char": "E",
        "block": "minecraft:air"
      },
      {
        "char": "I",
        "block": "minecraft:air"
      },
      {
        "char": "m",
        "block": "minecraft:air"
      },
      {
        "char": "z",
        "block": "minecraft:air"
      },
      {
        "char": "R",
        "block": "minecraft:air"
      },
      {
        "char": "H",
        "block": "minecraft:air"
      },
      {
        "char": "B",
        "block": "minecraft:air"
      },
      {
        "char": "A",
        "block": "minecraft:air"
      },
      {
        "char": "i",
        "block": "minecraft:air"
      },
      {
        "char": "下",
        "block": "minecraft:air"
      },
      {
        "char": "提",
        "block": "minecraft:air"
      },
      {
        "char": "好",
        "block": "minecraft:air"
      },
      {
        "char": "w",
        "block": "minecraft:grass"
      },
      {
        "char": "G",
        "block": "minecraft:tall_grass[half=lower]"
      },
      {
        "char": "p",
        "block": "minecraft:air"
      },
      {
        "char": "Q",
        "block": "minecraft:air"
      },
      {
        "char": "л",
        "block": "minecraft:air"
      },
      {
        "char": "N",
        "block": "minecraft:air"
      },
      {
        "char": "o",
        "block": "minecraft:air"
      },
      {
        "char": "开",
        "block": "minecraft:air"
      },
      {
        "char": "ӷ",
        "block": "minecraft:air"
      },
      {
        "char": "Ь",
        "block": "minecraft:air"
      },
      {
        "char": "ѿ",
        "block": "minecraft:air"
      },
      {
        "char": "P",
        "block": "minecraft:tall_grass[half=upper]"
      },
      {
        "char": "Ѳ",
        "block": "minecraft:air"
      },
      {
        "char": "ѱ",
        "block": "minecraft:air"
      },
      {
        "char": "щ",
        "block": "minecraft:air"
      },
      {
        "char": "h",
        "block": "minecraft:air"
      },
      {
        "char": "处",
        "block": "minecraft:air"
      },
      {
        "char": "全",
        "block": "minecraft:air"
      },
      {
        "char": "Ӄ",
        "block": "minecraft:air"
      }
    ]
  },
  "slices": [
    [
      "fffeuе          ",
      "bfflaF          ",
      "afblbF          ",
      "fuaefC          ",
      "ffuebE          ",
      "ffalbF          ",
      "ffblbC          ",
      "bfaeaF          ",
      "bfbeuе          ",
      "bffefI          ",
      "faaebI          ",
      "fbbefF          ",
      "ffaeaE          ",
      "bbbebе          ",
      "aafeaF          ",
      "ffflfI          "
    ],
    [
      "mmmeE           ",
      "zmmeE           ",
      "zmmeE           ",
      "RmmeH           ",
      "fmfeE           ",
      "BAzeEi          ",
      "RRze下i          ",
      "AAze            ",
      "fAfeE           ",
      "fAze提i          ",
      "BAzeE           ",
      "zBze提           ",
      "BffeH           ",
      "fzBeE           ",
      "Amze            ",
      "mmme好           "
    ],
    [
      "wwGep           ",
      "QwGe            ",
      "лwwep           ",
      "Nwwe            ",
      "лwie            ",
      "лi ep           ",
      "E oe开           ",
      "Q ie            ",
      "Q ie            ",
      "   e提           ",
      " iie            ",
      "Eioeӷ           ",
      "E Ьe            ",
      "Qѿ e            ",
      "Qwoe            ",
      "wwGe开           "
    ],
    [
      "  Pi            ",
      "Ѳ Pi            ",
      "ѱ  i            ",
      "   i            ",
      "Ѳ               ",
      "ѱ               ",
      "   i            ",
      "Ѳ  i提           ",
      "ѱ               ",
      "    提           ",
      "                ",
      "    好           ",
      "   i            ",
      "щh i            ",
      "щ  i            ",
      "  Pi提           "
    ],
    [
      "                ",
      "                ",
      "                ",
      "                ",
      "                ",
      "                ",
      "                ",
      "                ",
      "    下           ",
      "    ӷ           ",
      "                ",
      "    开           ",
      " 处ѿ ӷ           ",
      "h全h             ",
      " Ӄ              ",
      "    提           "
    ],
    [
      "                ",
      "                ",
      "                ",
      "                ",
      "                ",
      "                ",
      "                ",
      "    下           ",
      "                ",
      "    开           ",
      "                ",
      "    ӷ           ",
      " hh             ",
      "hhh 下           ",
      " h              ",
      "    下           "
    ]
  ]
}