{
  "xsize": 16,
  "zsize": 16,
  "palette": {
    "palette": [
      {
        "char": " ",
        "block": "minecraft:air"
      },
      {
        "char": "f",
        "block": "minecraft:stone[weathering=false]"
      },
      {
        "char": "b",
        "block": "minecraft:cracked_stone_bricks"
      },
      {
        "char": "a",
        "block": "minecraft:stone_bricks[weathering=true]"
      },
      {
        "char": "u",
        "block": "minecraft:stone_bricks[weathering=false]"
      }
    ]
  },
  "slices": [
    [
      "ffffffffffffffff",
      "bafabauabfuffbaf",
      "afbbfffufbfffaaf",
      "aabfabafbfbaffbf",
      "fufuuabfbfbbafbf",
      "bffuufbabbabbaff",
      "fuaffaabfauaafff",
      "babaabfaffuaaaff",
      "ffabbfuauffbbbbf",
      "bbfbaffbaffaafaf",
      "aabbfufbfuffffbf",
      "bbaafabfbafbfbbf",
      "ffabbaafbauabaaf",
      "bfbafffffuaabfbf",
      "bfbfuabbbffbaabf",
      "ffafufabbbfbaaaf"
    ],
    [
      "aabbbbbbbaabaaaf",
      "               a",
      "               a",
      "               b",
      "               b",
      "               b",
      "               a",
      "               b",
      "               a",
      "               b",
      "               a",
      "               b",
      "               b",
      "               a",
      "               u",
      "               a"
    ],
    [
      "aabaabbbbaabbabf",
      "               b",
      "               b",
      "               a",
      "               b",
      "               a",
      "               u",
      "               a",
      "               b",
      "               b",
      "               b",
      "               a",
      "               b",
      "               b",
      "               a",
      "               b"
    ],
    [
      "baabbabbababbabf",
      "               a",
      "               a",
      "               u",
      "               a",
      "               b",
      "               a",
      "               b",
      "               a",
      "               a",
      "               a",
      "               a",
      "               b",
      "               a",
      "               b",
      "               a"
    ],
    [
      "ababababababbabf",
      "               a",
      "               b",
      "               a",
      "               a",
      "               a",
      "               b",
      "               b",
      "               a",
      "               b",
      "               a",
      "               b",
      "               a",
      "               b",
      "               a",
      "               a"
    ],
    [
      "baaaabababaababf",
      "               b",
      "               b",
      "               a",
      "               a",
      "               b",
      "               b",
      "               a",
      "               b",
      "               a",
      "               a",
      "               b",
      "               a",
      "               b",
      "               b",
      "               a"
    ]
  ]
}