{
  "xsize": 16,
  "zsize": 16,
  "palette": {
    "palette": [
      {
        "char": " ",
        "block": "minecraft:air"
      },
      {
        "char": "l",
        "block": "minecraft:andesite"
      },
      {
        "char": "j",
        "block": "minecraft:air"
      },
      {
        "char": "c",
        "block": "minecraft:bricks[weathering=true]"
      },
      {
        "char": "v",
        "block": "minecraft:bricks[weathering=false]"
      },
      {
        "char": "g",
        "block": "minecraft:air"
      },
      {
        "char": "n",
        "block": "minecraft:air"
      },
      {
        "char": "e",
        "block": "minecraft:polished_andesite"
      },
      {
        "char": "q",
        "block": "minecraft:air"
      },
      {
        "char": "m",
        "block": "minecraft:grass_block[snowy=false]"
      },
      {
        "char": "B",
        "block": "minecraft:dead_brain_coral_block"
      },
      {
        "char": "z",
        "block": "minecraft:dead_bubble_coral_block"
      },
      {
        "char": "R",
        "block": "minecraft:cobblestone[weathering=false]"
      },
      {
        "char": "f",
        "block": "minecraft:stone[weathering=false]"
      },
      {
        "char": "o",
        "block": "minecraft:air"
      },
      {
        "char": "Ҷ",
        "block": "minecraft:stone[weathering=true]"
      },
      {
        "char": "A",
        "block": "minecraft:dead_fire_coral_block"
      },
      {
        "char": "情",
        "block": "minecraft:cobblestone[weathering=true]"
      },
      {
        "char": "з",
        "block": "minecraft:air"
      },
      {
        "char": "w",
        "block": "minecraft:air"
      },
      {
        "char": "G",
        "block": "minecraft:air"
      },
      {
        "char": "E",
        "block": "minecraft:smooth_stone_slab[type=bottom,waterlogged=false]"
      },
      {
        "char": "N",
        "block": "minecraft:stone_slab[type=bottom,waterlogged=false,weathering=false]"
      },
      {
        "char": "i",
        "block": "minecraft:air"
      },
      {
        "char": "я",
        "block": "minecraft:air"
      },
      {
        "char": "棒",
        "block": "minecraft:stone_slab[type=bottom,waterlogged=false,weathering=true]"
      },
      {
        "char": "р",
        "block": "minecraft:spruce_fence[east=false,north=false,south=false,waterlogged=false,west=false]"
      },
      {
        "char": "Q",
        "block": "minecraft:air"
      },
      {
        "char": "и",
        "block": "minecraft:air"
      },
      {
        "char": "P",
        "block": "minecraft:air"
      },
      {
        "char": "h",
        "block": "minecraft:oak_leaves[distance=7,persistent=true,waterlogged=false]"
      },
      {
        "char": "Ӝ",
        "block": "minecraft:air"
      },
      {
        "char": "Ӛ",
        "block": "minecraft:air"
      },
      {
        "char": "p",
        "block": "minecraft:air"
      }
    ]
  },
  "slices": [
    [
      "        ljcjvcjj",
      "        lcgccgjc",
      " n nn  necccjccv",
      "eeeeelleegcgggcc",
      "lccgcggceccccgjc",
      "eggcggcclcjgccvj",
      "eccvcjgjlccggcvc",
      "lccjcjcglggccccv",
      "egggcccglccccggc",
      "lccgccvjevccgccv",
      "evvcjgccecgcgccv",
      "eeleeeelellelele",
      "   q   q       q",
      "                ",
      "                ",
      "n    n          "
    ],
    [
      "        cmmBzBmB",
      "        cmmzmRmf",
      "n      ojfmҶmAmA",
      "lcjcvcgglBBzmAzz",
      "jzmmmmfAAB情ABBRf",
      "vmmmzmmfBBzBzRf情",
      "jmmRBzҶҶRfRABAff",
      "gmmAmmmmmfAffBAA",
      "gmmBAmBmfmzzffBm",
      "cmmAzBBzzBAAzABf",
      "gBmmRmzmzmmBAAmm",
      "lgjccggcecggcccg",
      "  q q      q q  ",
      "                ",
      "                ",
      " n  n    n n    "
    ],
    [
      "        зwGEEEwN",
      "        iwGNGEwE",
      " n n   nз wEwEwE",
      "lяiяiiяяei EwN E",
      "з wwww iqi E N E",
      "зwwG ww    EiEi棒",
      "iwGEENNNNNENрE N",
      "iwGEGGwww рi EEE",
      "iwGEQGQGQwi рi w",
      "зwwNQNQEQENNNNEE",
      "з wwQwQwQGw i ww",
      "lиииииииeиииииии",
      "q q q qq qq qq q",
      "                ",
      "                ",
      "  n  n   n   n n"
    ],
    [
      "          P     ",
      "            P   ",
      "                ",
      "i       i       ",
      "                ",
      "   P            ",
      "  P         h   ",
      "  P PP    h n   ",
      "  P ӜPӜPӜ q h   ",
      "    Ӝ Ӝ Ӝ       ",
      "    Ӛ Ӛ ӚP      ",
      "i       i       ",
      "                ",
      "                ",
      "                ",
      "                "
    ],
    [
      "                ",
      "                ",
      "                ",
      "                ",
      "                ",
      "                ",
      "            hp  ",
      "          i n   ",
      "           oh   ",
      "                ",
      "                ",
      "                ",
      "                ",
      "                ",
      "                ",
      "                "
    ],
    [
      "                ",
      "                ",
      "                ",
      "                ",
      "                ",
      "                ",
      "            i   ",
      "                ",
      "           oh   ",
      "                ",
      "                ",
      "                ",
      "                ",
      "                ",
      "                ",
      "                "
    ]
  ]
}