{
  "xsize": 16,
  "zsize": 16,
  "palette": {
    "palette": [
      {
        "char": " ",
        "block": "minecraft:air"
      },
      {
        "char": "f",
        "block": "minecraft:air"
      },
      {
        "char": "b",
        "block": "minecraft:air"
      },
      {
        "char": "u",
        "block": "minecraft:air"
      },
      {
        "char": "a",
        "block": "minecraft:air"
      },
      {
        "char": "m",
        "block": "minecraft:air"
      },
      {
        "char": "z",
        "block": "minecraft:air"
      },
      {
        "char": "B",
        "block": "minecraft:air"
      },
      {
        "char": "A",
        "block": "minecraft:air"
      },
      {
        "char": "e",
        "block": "minecraft:air"
      },
      {
        "char": "R",
        "block": "minecraft:air"
      },
      {
        "char": "S",
        "block": "minecraft:air"
      },
      {
        "char": "买",
        "block": "minecraft:air"
      },
      {
        "char": "o",
        "block": "minecraft:air"
      },
      {
        "char": "w",
        "block": "minecraft:grass"
      },
      {
        "char": "i",
        "block": "minecraft:air"
      },
      {
        "char": "G",
        "block": "minecraft:tall_grass[half=lower]"
      },
      {
        "char": "л",
        "block": "minecraft:air"
      },
      {
        "char": "E",
        "block": "minecraft:air"
      },
      {
        "char": "р",
        "block": "minecraft:air"
      },
      {
        "char": "Q",
        "block": "minecraft:air"
      },
      {
        "char": "N",
        "block": "minecraft:air"
      },
      {
        "char": "Ь",
        "block": "minecraft:air"
      },
      {
        "char": "呢",
        "block": "minecraft:air"
      },
      {
        "char": "Я",
        "block": "minecraft:air"
      },
      {
        "char": "p",
        "block": "minecraft:air"
      },
      {
        "char": "同",
        "block": "minecraft:air"
      },
      {
        "char": "觉",
        "block": "minecraft:air"
      },
      {
        "char": "Ц",
        "block": "minecraft:air"
      },
      {
        "char": "P",
        "block": "minecraft:tall_grass[half=upper]"
      },
      {
        "char": "Ѳ",
        "block": "minecraft:air"
      },
      {
        "char": "h",
        "block": "minecraft:air"
      },
      {
        "char": "ц",
        "block": "minecraft:air"
      },
      {
        "char": "ѱ",
        "block": "minecraft:air"
      },
      {
        "char": "n",
        "block": "minecraft:air"
      },
      {
        "char": "щ",
        "block": "minecraft:air"
      },
      {
        "char": "r",
        "block": "minecraft:air"
      },
      {
        "char": "љ",
        "block": "minecraft:air"
      },
      {
        "char": "ї",
        "block": "minecraft:air"
      },
      {
        "char": "Ҁ",
        "block": "minecraft:air"
      },
      {
        "char": "ѿ",
        "block": "minecraft:air"
      },
      {
        "char": "ы",
        "block": "minecraft:air"
      },
      {
        "char": "Ѷ",
        "block": "minecraft:air"
      }
    ]
  },
  "slices": [
    [
      "ffffffffffffffff",
      "bfuufbafafabfbff",
      "ffffufbaabbafbaf",
      "fbfffffabfbbabbf",
      "fabfbfaabbfbbaff",
      "uuaaffbababaaaff",
      "fufbbfbafbbbfbaf",
      "babbfufbbfbabaff",
      "abaabfabfbbfbbaf",
      "afbffuafabfffbff",
      "ffafuabafabbfabf",
      "bbbbfafauuafafaf",
      "aaffbbabaaffbaaf",
      "aaabfabffbbbbbff",
      "fbaabbafbabfafbf",
      "fbbfafbaffbafbaf"
    ],
    [
      "mzzfBfAAmmmmmmme",
      "ffBRfAzfffzmfmme",
      "mmmfBzfRzmRmBmme",
      "mmfBmRRmfmAmzmBe",
      "mmfRmBmmzmmmfBAe",
      "AABfmmmmBmAmABze",
      "BBAzRfAfBzzzARBe",
      "fzRBzRzRABfAzAAe",
      "ffzfRfBBzARzzAfe",
      "RRRzAfzAffABBzfe",
      "RRzBzBmmRBAfAzRe",
      "zBffzmmmmAzBAAfe",
      "mmfAmmzAAAzS买RAe",
      "mBmfmmRmmza  bae",
      "mAmfmmAmAAa oaae",
      "mzzfBfAAmmmmmmme"
    ],
    [
      "w   ii  wGGGwwGe",
      "лEEEi рiQEQNQGwe",
      "QGwE   iQGQGQGwe",
      "Gw Ew iwQGQGQwoe",
      "лwiEw wGEGwGNi e",
      "лiiEGwGGEw wE Ьe",
      "   EEEEEN   E  e",
      "Q    р   ii   Ьe",
      "Q iр   i i   i e",
      " ii  i     呢   e",
      "i iiр ww iЯ    e",
      "i  iiwGGwoab bpe",
      "ww  wGEENEu同oa e",
      "GQwQwGEGwEup b e",
      "GQwQwGE觉ЦNap b e",
      "w   ii  wGGGwwGe"
    ],
    [
      "         P    P ",
      "Ѳ     h ц ц ц  i",
      "ѱ       ц цPц   ",
      "        ц ц ц  i",
      "Ѳ        P P    ",
      "ѱ   P P        i",
      "                ",
      "Ѳ    h         i",
      "ѱ  h            ",
      "               i",
      "    h        n  ",
      "         oaa b i",
      "     P   oap b i",
      " щ щ   P  a  bpi",
      " щ щ   р  b ob  ",
      "         P      "
    ],
    [
      "      h         ",
      "     hhh        ",
      "                ",
      "                ",
      "                ",
      "                ",
      "                ",
      "     h          ",
      "   h            ",
      "                ",
      "           n    ",
      "         obbaa  ",
      "        n br bp ",
      "       nh aљїb  ",
      "      рhhoar b  ",
      "      h         "
    ],
    [
      "     hh         ",
      "     Ҁѿh        ",
      "      h         ",
      "                ",
      "                ",
      "                ",
      "                ",
      "                ",
      "   h            ",
      "                ",
      "          ыыNы  ",
      "          NNNѶ  ",
      "         rѶNѶѶ  ",
      "      nohnѶNыѶ  ",
      "      hhhhыыыN  ",
      "     hh         "
    ]
  ]
}