{
  "xsize": 16,
  "zsize": 16,
  "palette": {
    "palette": [
      {
        "char": " ",
        "block": "minecraft:air"
      },
      {
        "char": "f",
        "block": "minecraft:stone[weathering=false]"
      },
      {
        "char": "a",
        "block": "minecraft:stone_bricks[weathering=true]"
      },
      {
        "char": "b",
        "block": "minecraft:cracked_stone_bricks"
      },
      {
        "char": "u",
        "block": "minecraft:stone_bricks[weathering=false]"
      }
    ]
  },
  "slices": [
    [
      "ffffffffffffffff",
      "fabffufbaaabufab",
      "faafffbfafffbbfu",
      "fbffabfbfabafbuu",
      "fbfabbfbfbaaufuf",
      "ffabbabbabfuuffb",
      "fffaaaafbaaffauf",
      "ffaaaaffafbaabab",
      "fbbbbffaaufbbaff",
      "fafaaffabffabfbb",
      "fbffffufbfufbbaa",
      "fbbfbfabfbafaabb",
      "faabaaabfaabbaff",
      "fbfbaaafffffabfb",
      "fbaabffbbbaafbfb",
      "fauabfbbbafafaff"
    ],
    [
      "faaabaabbbbbbbaa",
      "a               ",
      "a               ",
      "b               ",
      "b               ",
      "b               ",
      "a               ",
      "b               ",
      "a               ",
      "b               ",
      "a               ",
      "b               ",
      "b               ",
      "a               ",
      "u               ",
      "a               "
    ],
    [
      "fbabbaabbbbaabaa",
      "b               ",
      "b               ",
      "a               ",
      "b               ",
      "a               ",
      "u               ",
      "a               ",
      "b               ",
      "b               ",
      "b               ",
      "a               ",
      "b               ",
      "b               ",
      "a               ",
      "b               "
    ],
    [
      "fbabbababbabbaab",
      "a               ",
      "a               ",
      "a               ",
      "a               ",
      "b               ",
      "a               ",
      "b               ",
      "a               ",
      "a               ",
      "a               ",
      "a               ",
      "b               ",
      "a               ",
      "b               ",
      "a               "
    ],
    [
      "fbabbabababababa",
      "a               ",
      "b               ",
      "a               ",
      "u               ",
      "a               ",
      "b               ",
      "b               ",
      "a               ",
      "b               ",
      "a               ",
      "b               ",
      "a               ",
      "b               ",
      "a               ",
      "a               "
    ],
    [
      "fbabaabababaaaab",
      "b               ",
      "b               ",
      "a               ",
      "a               ",
      "b               ",
      "b               ",
      "a               ",
      "b               ",
      "a               ",
      "a               ",
      "b               ",
      "a               ",
      "b               ",
      "b               ",
      "a               "
    ]
  ]
}