{
  "xsize": 16,
  "zsize": 16,
  "palette": {
    "palette": [
      {
        "char": " ",
        "block": "minecraft:air"
      },
      {
        "char": "g",
        "block": "minecraft:air"
      },
      {
        "char": "j",
        "block": "minecraft:air"
      },
      {
        "char": "e",
        "block": "minecraft:air"
      },
      {
        "char": "f",
        "block": "minecraft:air"
      },
      {
        "char": "ф",
        "block": "minecraft:air"
      },
      {
        "char": "c",
        "block": "minecraft:air"
      },
      {
        "char": "C",
        "block": "minecraft:air"
      },
      {
        "char": "v",
        "block": "minecraft:air"
      },
      {
        "char": "l",
        "block": "minecraft:air"
      },
      {
        "char": "u",
        "block": "minecraft:air"
      },
      {
        "char": "y",
        "block": "minecraft:air"
      },
      {
        "char": "I",
        "block": "minecraft:air"
      },
      {
        "char": "Ы",
        "block": "minecraft:air"
      },
      {
        "char": "Ѻ",
        "block": "minecraft:air"
      },
      {
        "char": "х",
        "block": "minecraft:air"
      },
      {
        "char": "N",
        "block": "minecraft:air"
      },
      {
        "char": "ѹ",
        "block": "minecraft:air"
      },
      {
        "char": "е",
        "block": "minecraft:air"
      },
      {
        "char": "H",
        "block": "minecraft:air"
      },
      {
        "char": "b",
        "block": "minecraft:air"
      },
      {
        "char": "a",
        "block": "minecraft:air"
      },
      {
        "char": "E",
        "block": "minecraft:air"
      },
      {
        "char": "m",
        "block": "minecraft:air"
      },
      {
        "char": "z",
        "block": "minecraft:air"
      },
      {
        "char": "B",
        "block": "minecraft:air"
      },
      {
        "char": "Ҷ",
        "block": "minecraft:air"
      },
      {
        "char": "棒",
        "block": "minecraft:air"
      },
      {
        "char": "i",
        "block": "minecraft:air"
      },
      {
        "char": "R",
        "block": "minecraft:air"
      },
      {
        "char": "p",
        "block": "minecraft:air"
      },
      {
        "char": "A",
        "block": "minecraft:air"
      },
      {
        "char": "G",
        "block": "minecraft:tall_grass[half=lower]"
      },
      {
        "char": "w",
        "block": "minecraft:grass"
      },
      {
        "char": "с",
        "block": "minecraft:air"
      },
      {
        "char": "р",
        "block": "minecraft:air"
      },
      {
        "char": "Q",
        "block": "minecraft:air"
      },
      {
        "char": "и",
        "block": "minecraft:air"
      },
      {
        "char": "P",
        "block": "minecraft:tall_grass[half=upper]"
      },
      {
        "char": "h",
        "block": "minecraft:air"
      },
      {
        "char": "Ѳ",
        "block": "minecraft:air"
      },
      {
        "char": "ѱ",
        "block": "minecraft:air"
      }
    ]
  },
  "slices": [
    [
      "ggjefф          ",
      "ggcefC          ",
      "jcvluy          ",
      "cgjluI          ",
      "ggjlЫC          ",
      "cjgeЫф          ",
      "ccjlѺх          ",
      "cgceЫN          ",
      "ccceѹе          ",
      "gcgefх          ",
      "ccgeЫH          ",
      "cvceby          ",
      "gjglby          ",
      "gcceaE          ",
      "jvvebN          ",
      "lleeaE          "
    ],
    [
      "mzmc            ",
      "mzmgф           ",
      "mBmgе           ",
      "mfҶj棒i          ",
      "RfzgEi          ",
      "fRzcp           ",
      "zfmvi           ",
      "mfml            ",
      "mBmgi           ",
      "AAmc            ",
      "BzAgхi          ",
      "RRBcфi          ",
      "ABAvф           ",
      "Bfmci           ",
      "mmmg            ",
      "ggge            "
    ],
    [
      "GEwi            ",
      "GNwс            ",
      "wEwсp           ",
      "wEiсp           ",
      "рE с            ",
      "iEрсp           ",
      " Nwi            ",
      "wNGl            ",
      "wEGс            ",
      " Ewсp           ",
      "iE i            ",
      " E сp           ",
      "QN i            ",
      "QNwс            ",
      "wwGсp           ",
      "iииep           "
    ],
    [
      "P               ",
      "P               ",
      "                ",
      "                ",
      "h               ",
      "  h             ",
      "                ",
      "   i            ",
      "                ",
      "                ",
      "                ",
      "                ",
      "Ѳ               ",
      "ѱ               ",
      "  P             ",
      "   i            "
    ],
    [
      "                ",
      "                ",
      "                ",
      "                ",
      "h               ",
      "  h             ",
      "                ",
      "                ",
      "                ",
      "                ",
      "                ",
      "                ",
      "                ",
      "                ",
      "                ",
      "                "
    ],
    [
      "                ",
      "                ",
      "                ",
      "                ",
      "h               ",
      "                ",
      "                ",
      "                ",
      "                ",
      "                ",
      "                ",
      "                ",
      "                ",
      "                ",
      "                ",
      "                "
    ]
  ]
}