{
  "xsize": 16,
  "zsize": 16,
  "palette": {
    "palette": [
      {
        "char": " ",
        "block": "minecraft:air"
      },
      {
        "char": "b",
        "block": "minecraft:cracked_stone_bricks"
      },
      {
        "char": "a",
        "block": "minecraft:stone_bricks[weathering=true]"
      },
      {
        "char": "f",
        "block": "minecraft:stone[weathering=false]"
      },
      {
        "char": "u",
        "block": "minecraft:stone_bricks[weathering=false]"
      }
    ]
  },
  "slices": [
    [
      "bbababafafabffff",
      "abfffaffffbffauf",
      "afuuuffabfbbbbff",
      "ufuffffabbbaafbf",
      "abaufbfaffaaabbf",
      "afufabfbafffbabf",
      "ffufafuffbffbbaf",
      "fufabbfaabafubaf",
      "auuabbfbfbfffbbf",
      "affabfaaffffbbff",
      "ffbfbabbafabafaf",
      "fufbabffbbbbbfbf",
      "uffaaafbaaaafaaf",
      "afbfabfaufafbbff",
      "ababaafbaababfbf",
      "ffufuuuffbffbabf"
    ],
    [
      "               a",
      "               b",
      "               a",
      "               a",
      "               b",
      "               b",
      "               b",
      "               b",
      "               b",
      "               a",
      "               b",
      "               a",
      "               a",
      "               b",
      "               b",
      "               b"
    ],
    [
      "               b",
      "               a",
      "               b",
      "               a",
      "               a",
      "               a",
      "               b",
      "               b",
      "               b",
      "               a",
      "               a",
      "               b",
      "               a",
      "               a",
      "               b",
      "               a"
    ],
    [
      "               b",
      "               a",
      "               a",
      "               a",
      "               b",
      "               b",
      "               a",
      "               a",
      "               b",
      "               b",
      "               b",
      "               b",
      "               a",
      "               b",
      "               a",
      "               a"
    ],
    [
      "               b",
      "               a",
      "               a",
      "               a",
      "               b",
      "               a",
      "               b",
      "               a",
      "               a",
      "               b",
      "               b",
      "               b",
      "               a",
      "               b",
      "               b",
      "               a"
    ],
    [
      "               b",
      "               b",
      "               a",
      "               b",
      "               b",
      "               b",
      "               a",
      "               a",
      "               b",
      "               b",
      "               b",
      "               a",
      "               b",
      "               a",
      "               b",
      "               b"
    ]
  ]
}