{
  "xsize": 16,
  "zsize": 16,
  "palette": {
    "palette": [
      {
        "char": " ",
        "block": "minecraft:air"
      },
      {
        "char": "b",
        "block": "minecraft:cracked_stone_bricks"
      },
      {
        "char": "a",
        "block": "minecraft:stone_bricks[weathering=true]"
      },
      {
        "char": "e",
        "block": "minecraft:polished_andesite"
      },
      {
        "char": "p",
        "block": "minecraft:air"
      },
      {
        "char": "u",
        "block": "minecraft:stone_bricks[weathering=false]"
      },
      {
        "char": "f",
        "block": "minecraft:stone[weathering=false]"
      },
      {
        "char": "z",
        "block": "minecraft:dead_bubble_coral_block"
      },
      {
        "char": "m",
        "block": "minecraft:grass_block[snowy=false]"
      },
      {
        "char": "R",
        "block": "minecraft:cobblestone[weathering=false]"
      },
      {
        "char": "B",
        "block": "minecraft:dead_brain_coral_block"
      },
      {
        "char": "A",
        "block": "minecraft:dead_fire_coral_block"
      },
      {
        "char": "л",
        "block": "minecraft:air"
      },
      {
        "char": "w",
        "block": "minecraft:air"
      },
      {
        "char": "N",
        "block": "minecraft:stone_slab[type=bottom,waterlogged=false,weathering=false]"
      },
      {
        "char": "i",
        "block": "minecraft:air"
      },
      {
        "char": "E",
        "block": "minecraft:smooth_stone_slab[type=bottom,waterlogged=false]"
      },
      {
        "char": "o",
        "block": "minecraft:air"
      },
      {
        "char": "Q",
        "block": "minecraft:air"
      },
      {
        "char": "Ь",
        "block": "minecraft:air"
      },
      {
        "char": "ѿ",
        "block": "minecraft:spruce_fence[east=false,north=false,south=false,waterlogged=false,west=true]"
      },
      {
        "char": "G",
        "block": "minecraft:air"
      },
      {
        "char": "ѱ",
        "block": "minecraft:rail[shape=north_west,waterlogged=false]"
      },
      {
        "char": "с",
        "block": "minecraft:air"
      },
      {
        "char": "Ѳ",
        "block": "minecraft:rail[shape=south_west,waterlogged=false]"
      },
      {
        "char": "щ",
        "block": "minecraft:air"
      },
      {
        "char": "h",
        "block": "minecraft:oak_leaves[distance=7,persistent=true,waterlogged=false]"
      },
      {
        "char": "P",
        "block": "minecraft:air"
      },
      {
        "char": "处",
        "block": "minecraft:spruce_fence[east=true,north=false,south=true,waterlogged=false,west=false]"
      },
      {
        "char": "全",
        "block": "minecraft:spruce_fence[east=false,north=true,south=true,waterlogged=false,west=false]"
      },
      {
        "char": "Ӄ",
        "block": "minecraft:spruce_fence[east=false,north=true,south=false,waterlogged=false,west=false]"
      }
    ]
  },
  "slices": [
    [
      "baaeap          ",
      "aaaeap          ",
      "abbebp          ",
      "abaebp          ",
      "abaebp          ",
      "bbbea           ",
      "abaeap          ",
      "aaueap          ",
      "aaaebp          ",
      "bbaea           ",
      "aaaebp          ",
      "abbeb           ",
      "abbeap          ",
      "aaaea           ",
      "bbbebp          ",
      "fffea           "
    ],
    [
      "zmmeb           ",
      "Rmmeap          ",
      "fmfeap          ",
      "BAzea           ",
      "RRzeap          ",
      "AAzeb           ",
      "fAfeap          ",
      "fAzeap          ",
      "BAzea           ",
      "zBzebp          ",
      "Bffeap          ",
      "fzBea           ",
      "Amzeap          ",
      "Ammeb           ",
      "mmmeap          ",
      "eeeea           "
    ],
    [
      "лwweb           ",
      "Nwwebp          ",
      "лwieap          ",
      "лi ea           ",
      "E oebp          ",
      "Q ieb           ",
      "Q ieap          ",
      "   ea           ",
      " iieb           ",
      "Eioebp          ",
      "E Ьebp          ",
      "Qѿ eap          ",
      "Qwoeb           ",
      "QGweb           ",
      "wGGebp          ",
      "eeeea           "
    ],
    [
      "ѱ  iс           ",
      "   ii           ",
      "Ѳ   i           ",
      "ѱ   сp          ",
      "   ii           ",
      "Ѳ  iс           ",
      "ѱ   i           ",
      "    с           ",
      "    сp          ",
      "    с           ",
      "   ii           ",
      "щh iсp          ",
      "щ  iс           ",
      "щ   i           ",
      "  Piс           ",
      "i  ii           "
    ],
    [
      "                ",
      "                ",
      "                ",
      "                ",
      "                ",
      "                ",
      "                ",
      "                ",
      "                ",
      "                ",
      " 处ѿ             ",
      "h全h             ",
      " Ӄ              ",
      "                ",
      "                ",
      "                "
    ],
    [
      "                ",
      "                ",
      "                ",
      "                ",
      "                ",
      "                ",
      "                ",
      "                ",
      "                ",
      "                ",
      " hh             ",
      "hhh             ",
      " h              ",
      "                ",
      "                ",
      "                "
    ]
  ]
}