{
  "xsize": 16,
  "zsize": 16,
  "palette": {
    "palette": [
      {
        "char": " ",
        "block": "minecraft:air"
      },
      {
        "char": "f",
        "block": "minecraft:stone[weathering=false]"
      },
      {
        "char": "l",
        "block": "minecraft:andesite"
      },
      {
        "char": "a",
        "block": "minecraft:stone_bricks[weathering=true]"
      },
      {
        "char": "х",
        "block": "minecraft:air"
      },
      {
        "char": "n",
        "block": "minecraft:air"
      },
      {
        "char": "e",
        "block": "minecraft:polished_andesite"
      },
      {
        "char": "е",
        "block": "minecraft:air"
      },
      {
        "char": "c",
        "block": "minecraft:bricks[weathering=true]"
      },
      {
        "char": "j",
        "block": "minecraft:air"
      },
      {
        "char": "g",
        "block": "minecraft:air"
      },
      {
        "char": "b",
        "block": "minecraft:cracked_stone_bricks"
      },
      {
        "char": "v",
        "block": "minecraft:bricks[weathering=false]"
      },
      {
        "char": "H",
        "block": "minecraft:smooth_stone_slab[type=top,waterlogged=false]"
      },
      {
        "char": "Ы",
        "block": "minecraft:smooth_stone"
      },
      {
        "char": "C",
        "block": "minecraft:air"
      },
      {
        "char": "E",
        "block": "minecraft:smooth_stone_slab[type=bottom,waterlogged=false]"
      },
      {
        "char": "ф",
        "block": "minecraft:polished_andesite_slab[type=bottom,waterlogged=false]"
      },
      {
        "char": "ѹ",
        "block": "minecraft:air"
      },
      {
        "char": "m",
        "block": "minecraft:grass_block[snowy=false]"
      },
      {
        "char": "i",
        "block": "minecraft:air"
      },
      {
        "char": "z",
        "block": "minecraft:dead_bubble_coral_block"
      },
      {
        "char": "A",
        "block": "minecraft:dead_fire_coral_block"
      },
      {
        "char": "B",
        "block": "minecraft:dead_brain_coral_block"
      },
      {
        "char": "p",
        "block": "minecraft:air"
      },
      {
        "char": "я",
        "block": "minecraft:air"
      },
      {
        "char": "G",
        "block": "minecraft:air"
      },
      {
        "char": "с",
        "block": "minecraft:air"
      },
      {
        "char": "л",
        "block": "minecraft:air"
      },
      {
        "char": "Q",
        "block": "minecraft:air"
      },
      {
        "char": "w",
        "block": "minecraft:air"
      },
      {
        "char": "N",
        "block": "minecraft:stone_slab[type=bottom,waterlogged=false,weathering=false]"
      },
      {
        "char": "P",
        "block": "minecraft:air"
      },
      {
        "char": "Ѱ",
        "block": "minecraft:rail[shape=south_east,waterlogged=false]"
      },
      {
        "char": "Ѳ",
        "block": "minecraft:rail[shape=south_west,waterlogged=false]"
      },
      {
        "char": "Ѯ",
        "block": "minecraft:rail[shape=north_east,waterlogged=false]"
      },
      {
        "char": "ѱ",
        "block": "minecraft:rail[shape=north_west,waterlogged=false]"
      }
    ]
  },
  "slices": [
    [
      "ffflaх          ",
      "                ",
      "                ",
      "                ",
      "                ",
      "   n            ",
      "leeefе          ",
      "cjgebе          ",
      "gccleх          ",
      "cvclbH          ",
      "gjgeЫH          ",
      "ccclЫC          ",
      "ccjebE          ",
      "cccefф          ",
      "ggclѹE          ",
      "cccebе          "
    ],
    [
      "eeee            ",
      "                ",
      "                ",
      "                ",
      "                ",
      "   nn           ",
      "gcve            ",
      "mmmji           ",
      "zzmgi           ",
      "zABgф           ",
      "Azfcеi          ",
      "mBmcеi          ",
      "BBmgi           ",
      "mmmji           ",
      "BAmep           ",
      "mfmvi           "
    ],
    [
      "eeee            ",
      "                ",
      "                ",
      "                ",
      "                ",
      "  n             ",
      "iяяep           ",
      "GGGс            ",
      "лQwс            ",
      "лQ сp           ",
      "EEiсp           ",
      "GNwi            ",
      "ENGсp           ",
      "wGGс            ",
      "EEGep           ",
      "GNGс            "
    ],
    [
      "i  i            ",
      "                ",
      "                ",
      "                ",
      "                ",
      "                ",
      "   i            ",
      "PPP             ",
      "ѰѲ              ",
      "Ѯѱ              ",
      "                ",
      "P               ",
      "  P             ",
      " P              ",
      "  Pi            ",
      "P P             "
    ],
    [
      "                ",
      "                ",
      "                ",
      "                ",
      "                ",
      "                ",
      "                ",
      "                ",
      "                ",
      "                ",
      "                ",
      "                ",
      "                ",
      "                ",
      "                ",
      "                "
    ],
    [
      "                ",
      "                ",
      "                ",
      "                ",
      "                ",
      "                ",
      "                ",
      "                ",
      "                ",
      "                ",
      "                ",
      "                ",
      "                ",
      "                ",
      "                ",
      "                "
    ]
  ]
}