{
  "xsize": 16,
  "zsize": 16,
  "palette": {
    "palette": [
      {
        "char": " ",
        "block": "minecraft:air"
      },
      {
        "char": "y",
        "block": "minecraft:air"
      },
      {
        "char": "a",
        "block": "minecraft:air"
      },
      {
        "char": "l",
        "block": "minecraft:air"
      },
      {
        "char": "b",
        "block": "minecraft:air"
      },
      {
        "char": "f",
        "block": "minecraft:air"
      },
      {
        "char": "u",
        "block": "minecraft:air"
      },
      {
        "char": "F",
        "block": "minecraft:air"
      },
      {
        "char": "e",
        "block": "minecraft:air"
      },
      {
        "char": "I",
        "block": "minecraft:air"
      },
      {
        "char": "х",
        "block": "minecraft:air"
      },
      {
        "char": "е",
        "block": "minecraft:air"
      },
      {
        "char": "H",
        "block": "minecraft:air"
      },
      {
        "char": "ф",
        "block": "minecraft:air"
      },
      {
        "char": "E",
        "block": "minecraft:air"
      },
      {
        "char": "m",
        "block": "minecraft:air"
      },
      {
        "char": "z",
        "block": "minecraft:air"
      },
      {
        "char": "R",
        "block": "minecraft:air"
      },
      {
        "char": "A",
        "block": "minecraft:air"
      },
      {
        "char": "B",
        "block": "minecraft:air"
      },
      {
        "char": "G",
        "block": "minecraft:tall_grass[half=lower]"
      },
      {
        "char": "w",
        "block": "minecraft:grass"
      },
      {
        "char": "Q",
        "block": "minecraft:air"
      },
      {
        "char": "л",
        "block": "minecraft:air"
      },
      {
        "char": "N",
        "block": "minecraft:air"
      },
      {
        "char": "i",
        "block": "minecraft:air"
      },
      {
        "char": "p",
        "block": "minecraft:air"
      },
      {
        "char": "Э",
        "block": "minecraft:air"
      },
      {
        "char": "Ҁ",
        "block": "minecraft:air"
      },
      {
        "char": "з",
        "block": "minecraft:air"
      },
      {
        "char": "Ѱ",
        "block": "minecraft:air"
      },
      {
        "char": "Ѯ",
        "block": "minecraft:air"
      },
      {
        "char": "h",
        "block": "minecraft:air"
      },
      {
        "char": "щ",
        "block": "minecraft:air"
      },
      {
        "char": "P",
        "block": "minecraft:tall_grass[half=upper]"
      },
      {
        "char": "区",
        "block": "minecraft:air"
      },
      {
        "char": "全",
        "block": "minecraft:air"
      },
      {
        "char": "Ӄ",
        "block": "minecraft:air"
      }
    ]
  },
  "slices": [
    [
      "          yalbfu",
      "          Fbebaa",
      "          Ifefbb",
      "          хfeaaf",
      "          еaeabf",
      "          Iblafa",
      "          ybebab",
      "          Hbebaf",
      "          фblfbf",
      "          Faeabf",
      "          yflabb",
      "          Hbeabf",
      "          Eaefaa",
      "          Fbefbf",
      "          yblabf",
      "          Hbebff"
    ],
    [
      "           aemmz",
      "           bemmz",
      "           aemmR",
      "           uefmf",
      "           aezAB",
      "           aezRR",
      "           bezAA",
      "           aefAf",
      "           aezAf",
      "           aezAB",
      "           bezBz",
      "           aeffB",
      "           aeBzf",
      "           aezmA",
      "           bemmA",
      "           aemmm"
    ],
    [
      "           aeGwQ",
      "           bewwл",
      "           bewwN",
      "           aeiwл",
      "           ae iл",
      "           bep E",
      "           bei Q",
      "           aei Q",
      "           ae   ",
      "           beii ",
      "           be iE",
      "           beЭ E",
      "           ae ҀQ",
      "           bepwQ",
      "           bewGQ",
      "           beGGw"
    ],
    [
      "           зi  Ѱ",
      "           зi  Ѯ",
      "           ii   ",
      "           i   Ѱ",
      "           з   Ѯ",
      "           i    ",
      "           зi  Ѱ",
      "           i   Ѯ",
      "           з    ",
      "           з    ",
      "           з    ",
      "           ii   ",
      "           зi hщ",
      "           зi  щ",
      "           i   щ",
      "           зiP  "
    ],
    [
      "                ",
      "                ",
      "                ",
      "                ",
      "                ",
      "                ",
      "                ",
      "                ",
      "                ",
      "                ",
      "                ",
      "             Ҁ区 ",
      "             h全h",
      "              Ӄ ",
      "                ",
      "                "
    ],
    [
      "                ",
      "                ",
      "                ",
      "                ",
      "                ",
      "                ",
      "                ",
      "                ",
      "                ",
      "                ",
      "                ",
      "             hh ",
      "             hhh",
      "              h ",
      "                ",
      "                "
    ]
  ]
}