{
  "xsize": 16,
  "zsize": 16,
  "palette": {
    "palette": [
      {
        "char": " ",
        "block": "minecraft:air"
      },
      {
        "char": "a",
        "block": "minecraft:air"
      },
      {
        "char": "e",
        "block": "minecraft:air"
      },
      {
        "char": "f",
        "block": "minecraft:air"
      },
      {
        "char": "o",
        "block": "minecraft:air"
      },
      {
        "char": "b",
        "block": "minecraft:air"
      },
      {
        "char": "u",
        "block": "minecraft:air"
      },
      {
        "char": "m",
        "block": "minecraft:air"
      },
      {
        "char": "A",
        "block": "minecraft:air"
      },
      {
        "char": "z",
        "block": "minecraft:air"
      },
      {
        "char": "B",
        "block": "minecraft:air"
      },
      {
        "char": "R",
        "block": "minecraft:air"
      },
      {
        "char": "G",
        "block": "minecraft:tall_grass[half=lower]"
      },
      {
        "char": "w",
        "block": "minecraft:grass"
      },
      {
        "char": "Q",
        "block": "minecraft:air"
      },
      {
        "char": "p",
        "block": "minecraft:air"
      },
      {
        "char": "Ҁ",
        "block": "minecraft:air"
      },
      {
        "char": "Э",
        "block": "minecraft:air"
      },
      {
        "char": "E",
        "block": "minecraft:air"
      },
      {
        "char": "i",
        "block": "minecraft:air"
      },
      {
        "char": "л",
        "block": "minecraft:air"
      },
      {
        "char": "N",
        "block": "minecraft:air"
      },
      {
        "char": "з",
        "block": "minecraft:air"
      },
      {
        "char": "P",
        "block": "minecraft:tall_grass[half=upper]"
      },
      {
        "char": "ц",
        "block": "minecraft:air"
      },
      {
        "char": "h",
        "block": "minecraft:air"
      },
      {
        "char": "Ѱ",
        "block": "minecraft:air"
      },
      {
        "char": "Ѯ",
        "block": "minecraft:air"
      },
      {
        "char": "ӊ",
        "block": "minecraft:air"
      },
      {
        "char": "全",
        "block": "minecraft:air"
      },
      {
        "char": "组",
        "block": "minecraft:air"
      }
    ]
  },
  "slices": [
    [
      "           aefff",
      "          obebbb",
      "           aeaaa",
      "          oaebba",
      "           bebba",
      "          obeaaa",
      "           aeabb",
      "          obeaaa",
      "          oaeuaa",
      "          oaeaba",
      "           aebbb",
      "          obeaba",
      "          obeaba",
      "          obebba",
      "          oaeaaa",
      "          oaeuab"
    ],
    [
      "           aeeee",
      "          oaemmm",
      "           bemmA",
      "          oaezmA",
      "           aeBzf",
      "          oaeffB",
      "          obezBz",
      "           aezAB",
      "          oaezAf",
      "          oaefAf",
      "           bezAA",
      "          oaezRR",
      "           aezAB",
      "          oaefmf",
      "          oaemmR",
      "           bemmz"
    ],
    [
      "           aeeee",
      "          obeGGw",
      "           bewGQ",
      "           bepwQ",
      "          oae ҀQ",
      "          obeЭ E",
      "          obepiE",
      "           beii ",
      "           ae   ",
      "          oaei Q",
      "           bei Q",
      "          obep E",
      "           ae iл",
      "          oaeiwл",
      "          obewwN",
      "           bewwл"
    ],
    [
      "           ii  i",
      "           зiP  ",
      "           i   ц",
      "           зi  ц",
      "          oзi hц",
      "           ii   ",
      "           з    ",
      "          oз    ",
      "           з    ",
      "           i   Ѱ",
      "           зi  Ѯ",
      "           ii   ",
      "          oз   Ѱ",
      "           i   Ѯ",
      "           ii   ",
      "           зi  Ѱ"
    ],
    [
      "                ",
      "                ",
      "                ",
      "              ӊ ",
      "             h全h",
      "             Ҁ组 ",
      "                ",
      "                ",
      "                ",
      "                ",
      "                ",
      "                ",
      "                ",
      "                ",
      "                ",
      "                "
    ],
    [
      "                ",
      "                ",
      "                ",
      "              h ",
      "             hhh",
      "             hh ",
      "                ",
      "                ",
      "                ",
      "                ",
      "                ",
      "                ",
      "                ",
      "                ",
      "                ",
      "                "
    ]
  ]
}