{
  "xsize": 16,
  "zsize": 16,
  "palette": {
    "palette": [
      {
        "char": " ",
        "block": "minecraft:air"
      },
      {
        "char": "f",
        "block": "minecraft:air"
      },
      {
        "char": "l",
        "block": "minecraft:air"
      },
      {
        "char": "a",
        "block": "minecraft:air"
      },
      {
        "char": "х",
        "block": "minecraft:air"
      },
      {
        "char": "n",
        "block": "minecraft:air"
      },
      {
        "char": "e",
        "block": "minecraft:air"
      },
      {
        "char": "е",
        "block": "minecraft:air"
      },
      {
        "char": "c",
        "block": "minecraft:air"
      },
      {
        "char": "j",
        "block": "minecraft:air"
      },
      {
        "char": "g",
        "block": "minecraft:air"
      },
      {
        "char": "b",
        "block": "minecraft:air"
      },
      {
        "char": "v",
        "block": "minecraft:air"
      },
      {
        "char": "H",
        "block": "minecraft:air"
      },
      {
        "char": "Ы",
        "block": "minecraft:air"
      },
      {
        "char": "C",
        "block": "minecraft:air"
      },
      {
        "char": "E",
        "block": "minecraft:air"
      },
      {
        "char": "ф",
        "block": "minecraft:air"
      },
      {
        "char": "ѹ",
        "block": "minecraft:air"
      },
      {
        "char": "m",
        "block": "minecraft:air"
      },
      {
        "char": "i",
        "block": "minecraft:air"
      },
      {
        "char": "z",
        "block": "minecraft:air"
      },
      {
        "char": "A",
        "block": "minecraft:air"
      },
      {
        "char": "B",
        "block": "minecraft:air"
      },
      {
        "char": "p",
        "block": "minecraft:air"
      },
      {
        "char": "я",
        "block": "minecraft:air"
      },
      {
        "char": "G",
        "block": "minecraft:tall_grass[half=lower]"
      },
      {
        "char": "с",
        "block": "minecraft:air"
      },
      {
        "char": "л",
        "block": "minecraft:air"
      },
      {
        "char": "Q",
        "block": "minecraft:air"
      },
      {
        "char": "w",
        "block": "minecraft:grass"
      },
      {
        "char": "N",
        "block": "minecraft:air"
      },
      {
        "char": "P",
        "block": "minecraft:tall_grass[half=upper]"
      },
      {
        "char": "Ѱ",
        "block": "minecraft:air"
      },
      {
        "char": "Ѳ",
        "block": "minecraft:air"
      },
      {
        "char": "Ѯ",
        "block": "minecraft:air"
      },
      {
        "char": "ѱ",
        "block": "minecraft:air"
      }
    ]
  },
  "slices": [
    [
      "ffflaх          ",
      "                ",
      "                ",
      "                ",
      "                ",
      "   n            ",
      "leeefе          ",
      "cjgebе          ",
      "gccleх          ",
      "cvclbH          ",
      "gjgeЫH          ",
      "ccclЫC          ",
      "ccjebE          ",
      "cccefф          ",
      "ggclѹE          ",
      "cccebе          "
    ],
    [
      "eeee            ",
      "                ",
      "                ",
      "                ",
      "                ",
      "   nn           ",
      "gcve            ",
      "mmmji           ",
      "zzmgi           ",
      "zABgф           ",
      "Azfcеi          ",
      "mBmcеi          ",
      "BBmgi           ",
      "mmmji           ",
      "BAmep           ",
      "mfmvi           "
    ],
    [
      "eeee            ",
      "                ",
      "                ",
      "                ",
      "                ",
      "  n             ",
      "iяяep           ",
      "GGGс            ",
      "лQwс            ",
      "лQ сp           ",
      "EEiсp           ",
      "GNwi            ",
      "ENGсp           ",
      "wGGс            ",
      "EEGep           ",
      "GNGс            "
    ],
    [
      "i  i            ",
      "                ",
      "                ",
      "                ",
      "                ",
      "                ",
      "   i            ",
      "PPP             ",
      "ѰѲ              ",
      "Ѯѱ              ",
      "                ",
      "P               ",
      "  P             ",
      " P              ",
      "  Pi            ",
      "P P             "
    ],
    [
      "                ",
      "                ",
      "                ",
      "                ",
      "                ",
      "                ",
      "                ",
      "                ",
      "                ",
      "                ",
      "                ",
      "                ",
      "                ",
      "                ",
      "                ",
      "                "
    ],
    [
      "                ",
      "                ",
      "                ",
      "                ",
      "                ",
      "                ",
      "                ",
      "                ",
      "                ",
      "                ",
      "                ",
      "                ",
      "                ",
      "                ",
      "                ",
      "                "
    ]
  ]
}