{
  "xsize": 16,
  "zsize": 16,
  "palette": {
    "palette": [
      {
        "char": " ",
        "block": "minecraft:air"
      },
      {
        "char": "ф",
        "block": "minecraft:air"
      },
      {
        "char": "f",
        "block": "minecraft:air"
      },
      {
        "char": "e",
        "block": "minecraft:air"
      },
      {
        "char": "j",
        "block": "minecraft:air"
      },
      {
        "char": "g",
        "block": "minecraft:air"
      },
      {
        "char": "C",
        "block": "minecraft:air"
      },
      {
        "char": "c",
        "block": "minecraft:air"
      },
      {
        "char": "y",
        "block": "minecraft:air"
      },
      {
        "char": "u",
        "block": "minecraft:air"
      },
      {
        "char": "l",
        "block": "minecraft:air"
      },
      {
        "char": "I",
        "block": "minecraft:air"
      },
      {
        "char": "Ы",
        "block": "minecraft:air"
      },
      {
        "char": "х",
        "block": "minecraft:air"
      },
      {
        "char": "Ѻ",
        "block": "minecraft:air"
      },
      {
        "char": "N",
        "block": "minecraft:air"
      },
      {
        "char": "е",
        "block": "minecraft:air"
      },
      {
        "char": "ѹ",
        "block": "minecraft:air"
      },
      {
        "char": "H",
        "block": "minecraft:air"
      },
      {
        "char": "b",
        "block": "minecraft:air"
      },
      {
        "char": "E",
        "block": "minecraft:air"
      },
      {
        "char": "a",
        "block": "minecraft:air"
      },
      {
        "char": "m",
        "block": "minecraft:air"
      },
      {
        "char": "z",
        "block": "minecraft:air"
      },
      {
        "char": "B",
        "block": "minecraft:air"
      },
      {
        "char": "i",
        "block": "minecraft:air"
      },
      {
        "char": "R",
        "block": "minecraft:air"
      },
      {
        "char": "o",
        "block": "minecraft:air"
      },
      {
        "char": "情",
        "block": "minecraft:air"
      },
      {
        "char": "A",
        "block": "minecraft:air"
      },
      {
        "char": "Ҷ",
        "block": "minecraft:air"
      },
      {
        "char": "w",
        "block": "minecraft:grass"
      },
      {
        "char": "G",
        "block": "minecraft:tall_grass[half=lower]"
      },
      {
        "char": "з",
        "block": "minecraft:air"
      },
      {
        "char": "р",
        "block": "minecraft:air"
      },
      {
        "char": "Q",
        "block": "minecraft:air"
      },
      {
        "char": "и",
        "block": "minecraft:air"
      },
      {
        "char": "P",
        "block": "minecraft:tall_grass[half=upper]"
      },
      {
        "char": "h",
        "block": "minecraft:air"
      },
      {
        "char": "Ѱ",
        "block": "minecraft:air"
      },
      {
        "char": "Ѯ",
        "block": "minecraft:air"
      }
    ]
  },
  "slices": [
    [
      "          фfejgg",
      "          Cfecgg",
      "          yulccj",
      "          Iuljgc",
      "          CЫljgg",
      "          фЫegjc",
      "          хѺljcc",
      "          NЫecgc",
      "          еѹeccc",
      "          хfegcg",
      "          HЫegcc",
      "          ybeccc",
      "          yblgjg",
      "          Eaeccg",
      "          Nbeccj",
      "          Eaeell"
    ],
    [
      "            cmzm",
      "           фgmzm",
      "           еgmBm",
      "          iNjffm",
      "          iEgzfR",
      "           ocz情f",
      "           icmfz",
      "            lmfm",
      "           igmBm",
      "            cmAA",
      "          iхgAzB",
      "          iфcBRR",
      "           фcABA",
      "           icmҶB",
      "            gmmm",
      "            eggg"
    ],
    [
      "            iwEG",
      "            зwNG",
      "           oзwEw",
      "           oзiEw",
      "            з Eр",
      "           oзрEi",
      "            iwN ",
      "            lGNw",
      "            зGEw",
      "           oзwE ",
      "            i Ei",
      "           oз E ",
      "            i NQ",
      "            зwNQ",
      "           oзGww",
      "           oeииi"
    ],
    [
      "               P",
      "                ",
      "                ",
      "                ",
      "               h",
      "             h  ",
      "                ",
      "            i   ",
      "                ",
      "                ",
      "                ",
      "                ",
      "               Ѱ",
      "               Ѯ",
      "             P  ",
      "            i   "
    ],
    [
      "                ",
      "                ",
      "                ",
      "                ",
      "               h",
      "             h  ",
      "                ",
      "                ",
      "                ",
      "                ",
      "                ",
      "                ",
      "                ",
      "                ",
      "                ",
      "                "
    ],
    [
      "                ",
      "                ",
      "                ",
      "                ",
      "               h",
      "                ",
      "                ",
      "                ",
      "                ",
      "                ",
      "                ",
      "                ",
      "                ",
      "                ",
      "                ",
      "                "
    ]
  ]
}