{
  "xsize": 16,
  "zsize": 16,
  "palette": {
    "palette": [
      {
        "char": " ",
        "block": "minecraft:air"
      },
      {
        "char": "l",
        "block": "minecraft:air"
      },
      {
        "char": "j",
        "block": "minecraft:air"
      },
      {
        "char": "c",
        "block": "minecraft:air"
      },
      {
        "char": "v",
        "block": "minecraft:air"
      },
      {
        "char": "g",
        "block": "minecraft:air"
      },
      {
        "char": "n",
        "block": "minecraft:air"
      },
      {
        "char": "e",
        "block": "minecraft:air"
      },
      {
        "char": "q",
        "block": "minecraft:air"
      },
      {
        "char": "m",
        "block": "minecraft:air"
      },
      {
        "char": "B",
        "block": "minecraft:air"
      },
      {
        "char": "z",
        "block": "minecraft:air"
      },
      {
        "char": "R",
        "block": "minecraft:air"
      },
      {
        "char": "f",
        "block": "minecraft:air"
      },
      {
        "char": "o",
        "block": "minecraft:air"
      },
      {
        "char": "Ҷ",
        "block": "minecraft:air"
      },
      {
        "char": "A",
        "block": "minecraft:air"
      },
      {
        "char": "情",
        "block": "minecraft:air"
      },
      {
        "char": "з",
        "block": "minecraft:air"
      },
      {
        "char": "w",
        "block": "minecraft:grass"
      },
      {
        "char": "G",
        "block": "minecraft:tall_grass[half=lower]"
      },
      {
        "char": "E",
        "block": "minecraft:air"
      },
      {
        "char": "N",
        "block": "minecraft:air"
      },
      {
        "char": "i",
        "block": "minecraft:air"
      },
      {
        "char": "я",
        "block": "minecraft:air"
      },
      {
        "char": "棒",
        "block": "minecraft:air"
      },
      {
        "char": "р",
        "block": "minecraft:air"
      },
      {
        "char": "Q",
        "block": "minecraft:air"
      },
      {
        "char": "и",
        "block": "minecraft:air"
      },
      {
        "char": "P",
        "block": "minecraft:tall_grass[half=upper]"
      },
      {
        "char": "h",
        "block": "minecraft:air"
      },
      {
        "char": "Ӝ",
        "block": "minecraft:air"
      },
      {
        "char": "Ӛ",
        "block": "minecraft:air"
      },
      {
        "char": "p",
        "block": "minecraft:air"
      }
    ]
  },
  "slices": [
    [
      "        ljcjvcjj",
      "        lcgccgjc",
      " n nn  necccjccv",
      "eeeeelleegcgggcc",
      "lccgcggceccccgjc",
      "eggcggcclcjgccvj",
      "eccvcjgjlccggcvc",
      "lccjcjcglggccccv",
      "egggcccglccccggc",
      "lccgccvjevccgccv",
      "evvcjgccecgcgccv",
      "eeleeeelellelele",
      "   q   q       q",
      "                ",
      "                ",
      "n    n          "
    ],
    [
      "        cmmBzBmB",
      "        cmmzmRmf",
      "n      ojfmҶmAmA",
      "lcjcvcgglBBzmAzz",
      "jzmmmmfAAB情ABBRf",
      "vmmmzmmfBBzBzRf情",
      "jmmRBzҶҶRfRABAff",
      "gmmAmmmmmfAffBAA",
      "gmmBAmBmfmzzffBm",
      "cmmAzBBzzBAAzABf",
      "gBmmRmzmzmmBAAmm",
      "lgjccggcecggcccg",
      "  q q      q q  ",
      "                ",
      "                ",
      " n  n    n n    "
    ],
    [
      "        зwGEEEwN",
      "        iwGNGEwE",
      " n n   nз wEwEwE",
      "lяiяiiяяei EwN E",
      "з wwww iqi E N E",
      "зwwG ww    EiEi棒",
      "iwGEENNNNNENрE N",
      "iwGEGGwww рi EEE",
      "iwGEQGQGQwi рi w",
      "зwwNQNQEQENNNNEE",
      "з wwQwQwQGw i ww",
      "lиииииииeиииииии",
      "q q q qq qq qq q",
      "                ",
      "                ",
      "  n  n   n   n n"
    ],
    [
      "          P     ",
      "            P   ",
      "                ",
      "i       i       ",
      "                ",
      "   P            ",
      "  P         h   ",
      "  P PP    h n   ",
      "  P ӜPӜPӜ q h   ",
      "    Ӝ Ӝ Ӝ       ",
      "    Ӛ Ӛ ӚP      ",
      "i       i       ",
      "                ",
      "                ",
      "                ",
      "                "
    ],
    [
      "                ",
      "                ",
      "                ",
      "                ",
      "                ",
      "                ",
      "            hp  ",
      "          i n   ",
      "           oh   ",
      "                ",
      "                ",
      "                ",
      "                ",
      "                ",
      "                ",
      "                "
    ],
    [
      "                ",
      "                ",
      "                ",
      "                ",
      "                ",
      "                ",
      "            i   ",
      "                ",
      "           oh   ",
      "                ",
      "                ",
      "                ",
      "                ",
      "                ",
      "                ",
      "                "
    ]
  ]
}