{
  "xsize": 16,
  "zsize": 16,
  "palette": {
    "palette": [
      {
        "char": " ",
        "block": "minecraft:air"
      },
      {
        "char": "f",
        "block": "minecraft:stone[weathering=false]"
      },
      {
        "char": "u",
        "block": "minecraft:stone_bricks[weathering=false]"
      },
      {
        "char": "b",
        "block": "minecraft:cracked_stone_bricks"
      },
      {
        "char": "a",
        "block": "minecraft:stone_bricks[weathering=true]"
      },
      {
        "char": "e",
        "block": "minecraft:polished_andesite"
      }
    ]
  },
  "slices": [
    [
      "ffuufbfbbaaufbaf",
      "fufaababfbaabauf",
      "afbbffuaaabbafff",
      "aaaauaabfffababf",
      "afbbfababfbaffbf",
      "aabbabbbbabafaaf",
      "baffbbafffaaabaf",
      "abbbabbbafbabfaf",
      "bbabbfeauffufabf",
      "bbffabbbffaaffbf",
      "fbbbbfbfufbabaaf",
      "bbaabfbaabababbf",
      "bbaafababbfbbaff",
      "bbfufbfbfffbafff",
      "fbfabauafabbafff",
      "fbfufbafffbabfbf"
    ],
    [
      "               a",
      "               b",
      "               a",
      "               a",
      "               b",
      "               b",
      "               b",
      "               b",
      "               b",
      "               a",
      "               b",
      "               a",
      "               a",
      "               b",
      "               b",
      "               b"
    ],
    [
      "               b",
      "               a",
      "               b",
      "               a",
      "               a",
      "               a",
      "               b",
      "               b",
      "               b",
      "               a",
      "               a",
      "               b",
      "               a",
      "               a",
      "               b",
      "               a"
    ],
    [
      "               b",
      "               a",
      "               a",
      "               a",
      "               b",
      "               b",
      "               a",
      "               a",
      "               b",
      "               b",
      "               b",
      "               b",
      "               a",
      "               b",
      "               a",
      "               a"
    ],
    [
      "               b",
      "               a",
      "               a",
      "               a",
      "               b",
      "               a",
      "               b",
      "               a",
      "               a",
      "               b",
      "               b",
      "               b",
      "               a",
      "               b",
      "               b",
      "               a"
    ],
    [
      "               b",
      "               b",
      "               a",
      "               b",
      "               b",
      "               b",
      "               a",
      "               a",
      "               b",
      "               b",
      "               b",
      "               a",
      "               b",
      "               a",
      "               b",
      "               b"
    ]
  ]
}