{
  "xsize": 16,
  "zsize": 16,
  "palette": {
    "palette": [
      {
        "char": " ",
        "block": "minecraft:air"
      },
      {
        "char": "c",
        "block": "minecraft:air"
      },
      {
        "char": "e",
        "block": "minecraft:air"
      },
      {
        "char": "Ѻ",
        "block": "minecraft:air"
      },
      {
        "char": "N",
        "block": "minecraft:air"
      },
      {
        "char": "j",
        "block": "minecraft:air"
      },
      {
        "char": "a",
        "block": "minecraft:air"
      },
      {
        "char": "х",
        "block": "minecraft:air"
      },
      {
        "char": "g",
        "block": "minecraft:air"
      },
      {
        "char": "b",
        "block": "minecraft:air"
      },
      {
        "char": "ф",
        "block": "minecraft:air"
      },
      {
        "char": "е",
        "block": "minecraft:air"
      },
      {
        "char": "Ы",
        "block": "minecraft:air"
      },
      {
        "char": "y",
        "block": "minecraft:air"
      },
      {
        "char": "F",
        "block": "minecraft:air"
      },
      {
        "char": "H",
        "block": "minecraft:air"
      },
      {
        "char": "v",
        "block": "minecraft:air"
      },
      {
        "char": "l",
        "block": "minecraft:air"
      },
      {
        "char": "u",
        "block": "minecraft:air"
      },
      {
        "char": "q",
        "block": "minecraft:air"
      },
      {
        "char": "n",
        "block": "minecraft:air"
      },
      {
        "char": "B",
        "block": "minecraft:air"
      },
      {
        "char": "f",
        "block": "minecraft:air"
      },
      {
        "char": "m",
        "block": "minecraft:air"
      },
      {
        "char": "i",
        "block": "minecraft:air"
      },
      {
        "char": "A",
        "block": "minecraft:air"
      },
      {
        "char": "R",
        "block": "minecraft:air"
      },
      {
        "char": "z",
        "block": "minecraft:air"
      },
      {
        "char": "p",
        "block": "minecraft:air"
      },
      {
        "char": "E",
        "block": "minecraft:air"
      },
      {
        "char": "G",
        "block": "minecraft:tall_grass[half=lower]"
      },
      {
        "char": "с",
        "block": "minecraft:air"
      },
      {
        "char": "w",
        "block": "minecraft:grass"
      },
      {
        "char": "Q",
        "block": "minecraft:air"
      },
      {
        "char": "л",
        "block": "minecraft:air"
      },
      {
        "char": "и",
        "block": "minecraft:air"
      },
      {
        "char": "Ѱ",
        "block": "minecraft:air"
      },
      {
        "char": "Ѳ",
        "block": "minecraft:air"
      },
      {
        "char": "P",
        "block": "minecraft:tall_grass[half=upper]"
      },
      {
        "char": "Ѯ",
        "block": "minecraft:air"
      },
      {
        "char": "ѱ",
        "block": "minecraft:air"
      }
    ]
  },
  "slices": [
    [
      "ccceѺN          ",
      "jcjeaх          ",
      "cggeeх          ",
      "cgcebф          ",
      "gcjeѺе          ",
      "ccgeЫy          ",
      "ggceaF          ",
      "jcgebH          ",
      "vcjeaе          ",
      "cgceeх          ",
      "cggluе          ",
      "eeeeeе          ",
      "   q            ",
      "                ",
      "                ",
      "   n            "
    ],
    [
      "Bfmci           ",
      "mARvi           ",
      "mzRvp           ",
      "mBmv            ",
      "mARvp           ",
      "mBBvф           ",
      "mfmjEi          ",
      "mzBcN           ",
      "mBAgp           ",
      "fzmgi           ",
      "mmmc            ",
      "cjvei           ",
      "  qq            ",
      "                ",
      "                ",
      "   nn           "
    ],
    [
      "EEGс            ",
      "wQлi            ",
      "GлQсp           ",
      "GNGс            ",
      "wллсp           ",
      "wQлсp           ",
      "GEGi            ",
      "wлQсp           ",
      "GQQi            ",
      "ENGсp           ",
      "GGwс            ",
      "иииe            ",
      "q               ",
      "                ",
      "                ",
      "  n             "
    ],
    [
      "                ",
      " ѰѲ             ",
      "PѮѱ             ",
      "P P             ",
      " ѰѲ             ",
      " Ѯѱ             ",
      "P               ",
      " ѰѲ             ",
      "PѮѱ             ",
      "  P             ",
      "PP              ",
      "   i            ",
      "                ",
      "                ",
      "                ",
      "                "
    ],
    [
      "                ",
      "                ",
      "                ",
      "                ",
      "                ",
      "                ",
      "                ",
      "                ",
      "                ",
      "                ",
      "                ",
      "                ",
      "                ",
      "                ",
      "                ",
      "                "
    ],
    [
      "                ",
      "                ",
      "                ",
      "                ",
      "                ",
      "                ",
      "                ",
      "                ",
      "                ",
      "                ",
      "                ",
      "                ",
      "                ",
      "                ",
      "                ",
      "                "
    ]
  ]
}