{
  "xsize": 16,
  "zsize": 16,
  "palette": {
    "palette": [
      {
        "char": " ",
        "block": "minecraft:air"
      },
      {
        "char": "b",
        "block": "minecraft:air"
      },
      {
        "char": "a",
        "block": "minecraft:air"
      },
      {
        "char": "e",
        "block": "minecraft:air"
      },
      {
        "char": "p",
        "block": "minecraft:air"
      },
      {
        "char": "u",
        "block": "minecraft:air"
      },
      {
        "char": "f",
        "block": "minecraft:air"
      },
      {
        "char": "z",
        "block": "minecraft:air"
      },
      {
        "char": "m",
        "block": "minecraft:air"
      },
      {
        "char": "R",
        "block": "minecraft:air"
      },
      {
        "char": "B",
        "block": "minecraft:air"
      },
      {
        "char": "A",
        "block": "minecraft:air"
      },
      {
        "char": "л",
        "block": "minecraft:air"
      },
      {
        "char": "w",
        "block": "minecraft:grass"
      },
      {
        "char": "N",
        "block": "minecraft:air"
      },
      {
        "char": "i",
        "block": "minecraft:air"
      },
      {
        "char": "E",
        "block": "minecraft:air"
      },
      {
        "char": "o",
        "block": "minecraft:air"
      },
      {
        "char": "Q",
        "block": "minecraft:air"
      },
      {
        "char": "Ь",
        "block": "minecraft:air"
      },
      {
        "char": "ѿ",
        "block": "minecraft:air"
      },
      {
        "char": "G",
        "block": "minecraft:tall_grass[half=lower]"
      },
      {
        "char": "ѱ",
        "block": "minecraft:air"
      },
      {
        "char": "с",
        "block": "minecraft:air"
      },
      {
        "char": "Ѳ",
        "block": "minecraft:air"
      },
      {
        "char": "щ",
        "block": "minecraft:air"
      },
      {
        "char": "h",
        "block": "minecraft:air"
      },
      {
        "char": "P",
        "block": "minecraft:tall_grass[half=upper]"
      },
      {
        "char": "处",
        "block": "minecraft:air"
      },
      {
        "char": "全",
        "block": "minecraft:air"
      },
      {
        "char": "Ӄ",
        "block": "minecraft:air"
      }
    ]
  },
  "slices": [
    [
      "baaeap          ",
      "aaaeap          ",
      "abbebp          ",
      "abaebp          ",
      "abaebp          ",
      "bbbea           ",
      "abaeap          ",
      "aaueap          ",
      "aaaebp          ",
      "bbaea           ",
      "aaaebp          ",
      "abbeb           ",
      "abbeap          ",
      "aaaea           ",
      "bbbebp          ",
      "fffea           "
    ],
    [
      "zmmeb           ",
      "Rmmeap          ",
      "fmfeap          ",
      "BAzea           ",
      "RRzeap          ",
      "AAzeb           ",
      "fAfeap          ",
      "fAzeap          ",
      "BAzea           ",
      "zBzebp          ",
      "Bffeap          ",
      "fzBea           ",
      "Amzeap          ",
      "Ammeb           ",
      "mmmeap          ",
      "eeeea           "
    ],
    [
      "лwweb           ",
      "Nwwebp          ",
      "лwieap          ",
      "лi ea           ",
      "E oebp          ",
      "Q ieb           ",
      "Q ieap          ",
      "   ea           ",
      " iieb           ",
      "Eioebp          ",
      "E Ьebp          ",
      "Qѿ eap          ",
      "Qwoeb           ",
      "QGweb           ",
      "wGGebp          ",
      "eeeea           "
    ],
    [
      "ѱ  iс           ",
      "   ii           ",
      "Ѳ   i           ",
      "ѱ   сp          ",
      "   ii           ",
      "Ѳ  iс           ",
      "ѱ   i           ",
      "    с           ",
      "    сp          ",
      "    с           ",
      "   ii           ",
      "щh iсp          ",
      "щ  iс           ",
      "щ   i           ",
      "  Piс           ",
      "i  ii           "
    ],
    [
      "                ",
      "                ",
      "                ",
      "                ",
      "                ",
      "                ",
      "                ",
      "                ",
      "                ",
      "                ",
      " 处ѿ             ",
      "h全h             ",
      " Ӄ              ",
      "                ",
      "                ",
      "                "
    ],
    [
      "                ",
      "                ",
      "                ",
      "                ",
      "                ",
      "                ",
      "                ",
      "                ",
      "                ",
      "                ",
      " hh             ",
      "hhh             ",
      " h              ",
      "                ",
      "                ",
      "                "
    ]
  ]
}