{
  "xsize": 16,
  "zsize": 16,
  "palette": {
    "palette": [
      {
        "char": " ",
        "block": "minecraft:air"
      },
      {
        "char": "e",
        "block": "minecraft:air"
      },
      {
        "char": "a",
        "block": "minecraft:air"
      },
      {
        "char": "ф",
        "block": "minecraft:air"
      },
      {
        "char": "c",
        "block": "minecraft:air"
      },
      {
        "char": "j",
        "block": "minecraft:air"
      },
      {
        "char": "Ѻ",
        "block": "minecraft:air"
      },
      {
        "char": "х",
        "block": "minecraft:air"
      },
      {
        "char": "g",
        "block": "minecraft:air"
      },
      {
        "char": "f",
        "block": "minecraft:air"
      },
      {
        "char": "l",
        "block": "minecraft:air"
      },
      {
        "char": "Ы",
        "block": "minecraft:air"
      },
      {
        "char": "H",
        "block": "minecraft:air"
      },
      {
        "char": "y",
        "block": "minecraft:air"
      },
      {
        "char": "C",
        "block": "minecraft:air"
      },
      {
        "char": "b",
        "block": "minecraft:air"
      },
      {
        "char": "е",
        "block": "minecraft:air"
      },
      {
        "char": "u",
        "block": "minecraft:air"
      },
      {
        "char": "E",
        "block": "minecraft:air"
      },
      {
        "char": "v",
        "block": "minecraft:air"
      },
      {
        "char": "Э",
        "block": "minecraft:air"
      },
      {
        "char": "m",
        "block": "minecraft:air"
      },
      {
        "char": "B",
        "block": "minecraft:air"
      },
      {
        "char": "A",
        "block": "minecraft:air"
      },
      {
        "char": "z",
        "block": "minecraft:air"
      },
      {
        "char": "i",
        "block": "minecraft:air"
      },
      {
        "char": "R",
        "block": "minecraft:air"
      },
      {
        "char": "Ҷ",
        "block": "minecraft:air"
      },
      {
        "char": "p",
        "block": "minecraft:air"
      },
      {
        "char": "я",
        "block": "minecraft:air"
      },
      {
        "char": "G",
        "block": "minecraft:tall_grass[half=lower]"
      },
      {
        "char": "с",
        "block": "minecraft:air"
      },
      {
        "char": "w",
        "block": "minecraft:grass"
      },
      {
        "char": "N",
        "block": "minecraft:air"
      },
      {
        "char": "р",
        "block": "minecraft:air"
      },
      {
        "char": "o",
        "block": "minecraft:air"
      },
      {
        "char": "P",
        "block": "minecraft:tall_grass[half=upper]"
      },
      {
        "char": "h",
        "block": "minecraft:air"
      }
    ]
  },
  "slices": [
    [
      "eeeeaф          ",
      "cjjeѺх          ",
      "ggjefф          ",
      "jcglЫH          ",
      "cggeay          ",
      "cggeaC          ",
      "cjclbC          ",
      "gccefе          ",
      "ccglѺф          ",
      "eleeuE          ",
      "gjclѺф          ",
      "cggeЫх          ",
      "vcgebх          ",
      "cjclaC          ",
      "gggeЫy          ",
      "cggefy          "
    ],
    [
      "cgclЭ           ",
      "mmmv            ",
      "BAmc            ",
      "mfmg            ",
      "zAmjхi          ",
      "mmmcх           ",
      "Rmmg i          ",
      "fBBci           ",
      "Bffv            ",
      "BAfe            ",
      "fҶmvi           ",
      "zmmvЭ           ",
      "mmmcp           ",
      "mmmgеi          ",
      "mmmjф           ",
      "mmmjхi          "
    ],
    [
      "яiяep           ",
      "GGGс            ",
      "EEGс            ",
      "wEwсp           ",
      "NEwс            ",
      "wwwi            ",
      "рwwс            ",
      "  iс            ",
      "  рсp           ",
      "  oep           ",
      " iwс            ",
      " wwi            ",
      "wwGi            ",
      "wGGсp           ",
      "GwGсp           ",
      "wGwсp           "
    ],
    [
      "   i            ",
      "P P             ",
      "  P             ",
      "                ",
      "                ",
      "                ",
      "h               ",
      "                ",
      "  h             ",
      "   i            ",
      "                ",
      "                ",
      "  P             ",
      " PP             ",
      "P P             ",
      " P              "
    ],
    [
      "                ",
      "                ",
      "                ",
      "                ",
      "                ",
      "                ",
      "h               ",
      "                ",
      "  h             ",
      "                ",
      "                ",
      "                ",
      "                ",
      "                ",
      "                ",
      "                "
    ],
    [
      "                ",
      "                ",
      "                ",
      "                ",
      "                ",
      "                ",
      "                ",
      "                ",
      "  h             ",
      "                ",
      "                ",
      "                ",
      "                ",
      "                ",
      "                ",
      "                "
    ]
  ]
}