{
  "xsize": 16,
  "zsize": 16,
  "palette": {
    "palette": [
      {
        "char": " ",
        "block": "minecraft:air"
      },
      {
        "char": "N",
        "block": "minecraft:air"
      },
      {
        "char": "Ѻ",
        "block": "minecraft:air"
      },
      {
        "char": "e",
        "block": "minecraft:air"
      },
      {
        "char": "c",
        "block": "minecraft:air"
      },
      {
        "char": "х",
        "block": "minecraft:air"
      },
      {
        "char": "u",
        "block": "minecraft:air"
      },
      {
        "char": "j",
        "block": "minecraft:air"
      },
      {
        "char": "g",
        "block": "minecraft:air"
      },
      {
        "char": "ф",
        "block": "minecraft:air"
      },
      {
        "char": "b",
        "block": "minecraft:air"
      },
      {
        "char": "е",
        "block": "minecraft:air"
      },
      {
        "char": "y",
        "block": "minecraft:air"
      },
      {
        "char": "Ы",
        "block": "minecraft:air"
      },
      {
        "char": "F",
        "block": "minecraft:air"
      },
      {
        "char": "a",
        "block": "minecraft:air"
      },
      {
        "char": "H",
        "block": "minecraft:air"
      },
      {
        "char": "v",
        "block": "minecraft:air"
      },
      {
        "char": "l",
        "block": "minecraft:air"
      },
      {
        "char": "q",
        "block": "minecraft:air"
      },
      {
        "char": "n",
        "block": "minecraft:air"
      },
      {
        "char": "i",
        "block": "minecraft:air"
      },
      {
        "char": "m",
        "block": "minecraft:air"
      },
      {
        "char": "f",
        "block": "minecraft:air"
      },
      {
        "char": "B",
        "block": "minecraft:air"
      },
      {
        "char": "R",
        "block": "minecraft:air"
      },
      {
        "char": "A",
        "block": "minecraft:air"
      },
      {
        "char": "o",
        "block": "minecraft:air"
      },
      {
        "char": "z",
        "block": "minecraft:air"
      },
      {
        "char": "E",
        "block": "minecraft:air"
      },
      {
        "char": "з",
        "block": "minecraft:air"
      },
      {
        "char": "G",
        "block": "minecraft:tall_grass[half=lower]"
      },
      {
        "char": "л",
        "block": "minecraft:air"
      },
      {
        "char": "Q",
        "block": "minecraft:air"
      },
      {
        "char": "w",
        "block": "minecraft:grass"
      },
      {
        "char": "и",
        "block": "minecraft:air"
      },
      {
        "char": "P",
        "block": "minecraft:tall_grass[half=upper]"
      },
      {
        "char": "Ѱ",
        "block": "minecraft:air"
      },
      {
        "char": "Ѳ",
        "block": "minecraft:air"
      },
      {
        "char": "Ѯ",
        "block": "minecraft:air"
      },
      {
        "char": "ѱ",
        "block": "minecraft:air"
      }
    ]
  },
  "slices": [
    [
      "          NѺeccc",
      "          хuejcj",
      "          хeeggc",
      "          фbecgc",
      "          еѺejcg",
      "          yЫegcc",
      "          Faecgg",
      "          Hbegcj",
      "          еaejcv",
      "          хeecgc",
      "          еulggc",
      "          еeeeee",
      "            q   ",
      "                ",
      "                ",
      "            n   "
    ],
    [
      "           icmfB",
      "           icRAm",
      "           ovRzm",
      "            vmBm",
      "           ovRAm",
      "           фcBBm",
      "          iEjmfm",
      "           NcBzm",
      "           ogABm",
      "           igmzf",
      "            cmmm",
      "           ievjc",
      "            qq  ",
      "                ",
      "                ",
      "           nn   "
    ],
    [
      "            зGEE",
      "            iлQw",
      "           oзQлG",
      "            зGNG",
      "           oзллw",
      "           oзлQw",
      "            iGEG",
      "           oзQлw",
      "            iQQG",
      "           oзGNE",
      "            зwGG",
      "            eиии",
      "               q",
      "                ",
      "                ",
      "           n n  "
    ],
    [
      "             P  ",
      "             ѰѲ ",
      "             Ѯѱ ",
      "             P P",
      "             ѰѲ ",
      "             Ѯѱ ",
      "             P P",
      "             ѰѲ ",
      "             Ѯѱ ",
      "             P  ",
      "              PP",
      "            i   ",
      "                ",
      "                ",
      "                ",
      "                "
    ],
    [
      "                ",
      "                ",
      "                ",
      "                ",
      "                ",
      "                ",
      "                ",
      "                ",
      "                ",
      "                ",
      "                ",
      "                ",
      "                ",
      "                ",
      "                ",
      "                "
    ],
    [
      "                ",
      "                ",
      "                ",
      "                ",
      "                ",
      "                ",
      "                ",
      "                ",
      "                ",
      "                ",
      "                ",
      "                ",
      "                ",
      "                ",
      "                ",
      "                "
    ]
  ]
}