{
  "xsize": 16,
  "zsize": 16,
  "palette": {
    "palette": [
      {
        "char": " ",
        "block": "minecraft:air"
      },
      {
        "char": "c",
        "block": "minecraft:air"
      },
      {
        "char": "g",
        "block": "minecraft:air"
      },
      {
        "char": "e",
        "block": "minecraft:air"
      },
      {
        "char": "b",
        "block": "minecraft:air"
      },
      {
        "char": "ф",
        "block": "minecraft:air"
      },
      {
        "char": "v",
        "block": "minecraft:air"
      },
      {
        "char": "f",
        "block": "minecraft:air"
      },
      {
        "char": "F",
        "block": "minecraft:air"
      },
      {
        "char": "I",
        "block": "minecraft:air"
      },
      {
        "char": "е",
        "block": "minecraft:air"
      },
      {
        "char": "ѹ",
        "block": "minecraft:air"
      },
      {
        "char": "Ѻ",
        "block": "minecraft:air"
      },
      {
        "char": "E",
        "block": "minecraft:air"
      },
      {
        "char": "C",
        "block": "minecraft:air"
      },
      {
        "char": "j",
        "block": "minecraft:air"
      },
      {
        "char": "y",
        "block": "minecraft:air"
      },
      {
        "char": "a",
        "block": "minecraft:air"
      },
      {
        "char": "N",
        "block": "minecraft:air"
      },
      {
        "char": "х",
        "block": "minecraft:air"
      },
      {
        "char": "m",
        "block": "minecraft:air"
      },
      {
        "char": "A",
        "block": "minecraft:air"
      },
      {
        "char": "z",
        "block": "minecraft:air"
      },
      {
        "char": "B",
        "block": "minecraft:air"
      },
      {
        "char": "情",
        "block": "minecraft:air"
      },
      {
        "char": "R",
        "block": "minecraft:air"
      },
      {
        "char": "p",
        "block": "minecraft:air"
      },
      {
        "char": "w",
        "block": "minecraft:grass"
      },
      {
        "char": "G",
        "block": "minecraft:tall_grass[half=lower]"
      },
      {
        "char": "с",
        "block": "minecraft:air"
      },
      {
        "char": "Q",
        "block": "minecraft:air"
      },
      {
        "char": "i",
        "block": "minecraft:air"
      },
      {
        "char": "и",
        "block": "minecraft:air"
      },
      {
        "char": "P",
        "block": "minecraft:tall_grass[half=upper]"
      },
      {
        "char": "Ѱ",
        "block": "minecraft:air"
      },
      {
        "char": "Ѳ",
        "block": "minecraft:air"
      },
      {
        "char": "Ѯ",
        "block": "minecraft:air"
      },
      {
        "char": "ѱ",
        "block": "minecraft:air"
      }
    ]
  },
  "slices": [
    [
      "cgcebф          ",
      "vcvefF          ",
      "vvvefI          ",
      "ccceeI          ",
      "ccgefе          ",
      "ccceѹф          ",
      "gcgeѺE          ",
      "ccgeѺC          ",
      "jcgefy          ",
      "ggcefе          ",
      "gccebф          ",
      "gcgeeE          ",
      "jjceeC          ",
      "ggjefC          ",
      "ggjeaN          ",
      "eeeebх          "
    ],
    [
      "mmmv            ",
      "fAmvN           ",
      "mzmjх           ",
      "mBzvN           ",
      "mAAv            ",
      "mzmv            ",
      "BAmc            ",
      "情AmgE           ",
      "BzmgN           ",
      "RAzg            ",
      "mfmc            ",
      "mmmc            ",
      "mmmgх           ",
      "mmRcх           ",
      "Ammc            ",
      "fBzep           "
    ],
    [
      "wGGс            ",
      "EEGс            ",
      "GNG             ",
      "wQQс            ",
      "wQQ             ",
      "wNGс            ",
      " Ewс            ",
      " Nw             ",
      "iNwс            ",
      " E с            ",
      "w wс            ",
      "Gww             ",
      "GGwс            ",
      "wGiс            ",
      " wwс            ",
      " ииep           "
    ],
    [
      " PP             ",
      "  P             ",
      "P P             ",
      " ѰѲ             ",
      " Ѯѱ             ",
      "  P             ",
      "                ",
      "                ",
      "                ",
      "                ",
      "                ",
      "P               ",
      "PP              ",
      " P              ",
      "                ",
      "   i            "
    ],
    [
      "                ",
      "                ",
      "                ",
      "                ",
      "                ",
      "                ",
      "                ",
      "                ",
      "                ",
      "                ",
      "                ",
      "                ",
      "                ",
      "                ",
      "p               ",
      "                "
    ],
    [
      "                ",
      "                ",
      "                ",
      "                ",
      "                ",
      "                ",
      "                ",
      "                ",
      "                ",
      "                ",
      "                ",
      "                ",
      "                ",
      "p               ",
      "                ",
      "                "
    ]
  ]
}