{
  "xsize": 16,
  "zsize": 16,
  "palette": {
    "palette": [
      {
        "char": " ",
        "block": "minecraft:air"
      },
      {
        "char": "j",
        "block": "minecraft:air"
      },
      {
        "char": "c",
        "block": "minecraft:bricks[weathering=true]"
      },
      {
        "char": "l",
        "block": "minecraft:andesite"
      },
      {
        "char": "v",
        "block": "minecraft:bricks[weathering=false]"
      },
      {
        "char": "g",
        "block": "minecraft:air"
      },
      {
        "char": "e",
        "block": "minecraft:polished_andesite"
      },
      {
        "char": "n",
        "block": "minecraft:air"
      },
      {
        "char": "q",
        "block": "minecraft:air"
      },
      {
        "char": "B",
        "block": "minecraft:dead_brain_coral_block"
      },
      {
        "char": "m",
        "block": "minecraft:grass_block[snowy=false]"
      },
      {
        "char": "z",
        "block": "minecraft:dead_bubble_coral_block"
      },
      {
        "char": "f",
        "block": "minecraft:stone[weathering=false]"
      },
      {
        "char": "R",
        "block": "minecraft:cobblestone[weathering=false]"
      },
      {
        "char": "A",
        "block": "minecraft:dead_fire_coral_block"
      },
      {
        "char": "Ҷ",
        "block": "minecraft:stone[weathering=true]"
      },
      {
        "char": "p",
        "block": "minecraft:air"
      },
      {
        "char": "情",
        "block": "minecraft:cobblestone[weathering=true]"
      },
      {
        "char": "N",
        "block": "minecraft:stone_slab[type=bottom,waterlogged=false,weathering=false]"
      },
      {
        "char": "w",
        "block": "minecraft:air"
      },
      {
        "char": "E",
        "block": "minecraft:smooth_stone_slab[type=bottom,waterlogged=false]"
      },
      {
        "char": "G",
        "block": "minecraft:air"
      },
      {
        "char": "с",
        "block": "minecraft:air"
      },
      {
        "char": "i",
        "block": "minecraft:air"
      },
      {
        "char": "я",
        "block": "minecraft:air"
      },
      {
        "char": "р",
        "block": "minecraft:spruce_fence[east=false,north=false,south=false,waterlogged=false,west=false]"
      },
      {
        "char": "Q",
        "block": "minecraft:air"
      },
      {
        "char": "и",
        "block": "minecraft:air"
      },
      {
        "char": "P",
        "block": "minecraft:air"
      },
      {
        "char": "h",
        "block": "minecraft:oak_leaves[distance=7,persistent=true,waterlogged=false]"
      },
      {
        "char": "Ӛ",
        "block": "minecraft:air"
      },
      {
        "char": "Ӝ",
        "block": "minecraft:air"
      },
      {
        "char": "o",
        "block": "minecraft:air"
      }
    ]
  },
  "slices": [
    [
      "jjccjcjl        ",
      "vjgccgcl        ",
      "vccjcccen  nn n ",
      "ccgggcgeelleeeee",
      "cjgccvcecggcgccl",
      "jcccgjclvcggcgge",
      "cccggccljgjcvcce",
      "cccccgglgcjcjccl",
      "cggcccclgcccggge",
      "cccgccvejcccgccl",
      "vvcgcgcevcgjccve",
      "elelelleleeeelee",
      "q       q   q   ",
      "                ",
      "                ",
      "          n    n"
    ],
    [
      "BmBzBmmc        ",
      "fmRmzmmc        ",
      "AmAmfmҶjp      n",
      "zzAmzBBlggcvvjcl",
      "fRBBARBAAfmmmmzj",
      "RfRzBzBBfmmzmmmc",
      "ҶfABARf情ҶҶzBRmmj",
      "AABffAfmmmmmAmmg",
      "mBffzzmfmBmABmmg",
      "fBAzAABzzBBzAmmc",
      "mmAABmmzmzmRmmBg",
      "gcvcggcecggccjgl",
      "  q q      q q  ",
      "                ",
      "                ",
      "    n n    n  n "
    ],
    [
      "NwEEEGwс        ",
      "EwEGNGwi        ",
      "EwEwEw сn   n n ",
      "E NwE ieяяiiяiяl",
      "E N E iqi wwww с",
      "NiEiE    ww Gwwс",
      "N EрNENNNNNEEGwi",
      "EEE iр wwwGGEGwi",
      "w iр iwQGQGQEGwi",
      "EENNNNEQEQNQNwwс",
      "ww i wGQwQwQww с",
      "иииииииeиииииииl",
      "q qq qq qq q q q",
      "                ",
      "                ",
      "n n   n   n  n  "
    ],
    [
      "     P          ",
      "   P P          ",
      "                ",
      "       i       i",
      "                ",
      "            P   ",
      "   h         P  ",
      "   n h    P  P  ",
      "   h q ӚPӚPӚ P  ",
      "       Ӛ Ӛ Ӛ    ",
      "      PӜ Ӝ Ӝ    ",
      "       i       i",
      "                ",
      "                ",
      "                ",
      "                "
    ],
    [
      "                ",
      "                ",
      "                ",
      "                ",
      "                ",
      "                ",
      "  oh            ",
      "   n i          ",
      "   hp           ",
      "                ",
      "                ",
      "                ",
      "                ",
      "                ",
      "                ",
      "                "
    ],
    [
      "                ",
      "                ",
      "                ",
      "                ",
      "                ",
      "                ",
      "   i            ",
      "                ",
      "   hp           ",
      "                ",
      "                ",
      "                ",
      "                ",
      "                ",
      "                ",
      "                "
    ]
  ]
}