{
  "xsize": 16,
  "zsize": 16,
  "palette": {
    "palette": [
      {
        "char": " ",
        "block": "minecraft:air"
      },
      {
        "char": "f",
        "block": "minecraft:stone[weathering=false]"
      },
      {
        "char": "a",
        "block": "minecraft:stone_bricks[weathering=true]"
      },
      {
        "char": "b",
        "block": "minecraft:cracked_stone_bricks"
      },
      {
        "char": "u",
        "block": "minecraft:stone_bricks[weathering=false]"
      },
      {
        "char": "e",
        "block": "minecraft:polished_andesite"
      }
    ]
  },
  "slices": [
    [
      "ffffffffffffffff",
      "abbafabbabbffuff",
      "bfbbffbfafabffff",
      "bababbfbabffabaf",
      "bafbbufufbabafbf",
      "fbbbffufuababbbf",
      "bfabbuufabaaaaaf",
      "afbafbfbaffbabff",
      "ffauaaefbaffbauf",
      "fuuffaaaaabffbaf",
      "fffffabbfbbbffbf",
      "aaffafbfafabbbaf",
      "abbfabbfafaaffuf",
      "bbabffbabfaffuuf",
      "fbbaabfaabbabaaf",
      "bbfuuaffbabfabbf"
    ],
    [
      "aabbbbbbbaabaaaf",
      "               a",
      "               a",
      "               b",
      "               b",
      "               b",
      "               a",
      "               b",
      "               a",
      "               b",
      "               a",
      "               b",
      "               b",
      "               a",
      "               a",
      "               a"
    ],
    [
      "aabaabbbbaabbabf",
      "               b",
      "               b",
      "               a",
      "               b",
      "               a",
      "               a",
      "               a",
      "               b",
      "               b",
      "               b",
      "               a",
      "               b",
      "               b",
      "               a",
      "               b"
    ],
    [
      "baabbabbababbabf",
      "               a",
      "               a",
      "               a",
      "               a",
      "               b",
      "               a",
      "               b",
      "               a",
      "               a",
      "               a",
      "               a",
      "               b",
      "               a",
      "               b",
      "               a"
    ],
    [
      "ababababababbabf",
      "               a",
      "               b",
      "               a",
      "               a",
      "               a",
      "               b",
      "               b",
      "               a",
      "               b",
      "               a",
      "               b",
      "               a",
      "               b",
      "               a",
      "               a"
    ],
    [
      "baaaabababaababf",
      "               b",
      "               b",
      "               a",
      "               a",
      "               b",
      "               b",
      "               a",
      "               b",
      "               a",
      "               a",
      "               b",
      "               a",
      "               b",
      "               b",
      "               a"
    ]
  ]
}