{
  "xsize": 16,
  "zsize": 16,
  "palette": {
    "palette": [
      {
        "char": " ",
        "block": "minecraft:air"
      },
      {
        "char": "f",
        "block": "minecraft:stone[weathering=false]"
      },
      {
        "char": "b",
        "block": "minecraft:cracked_stone_bricks"
      },
      {
        "char": "a",
        "block": "minecraft:stone_bricks[weathering=true]"
      },
      {
        "char": "u",
        "block": "minecraft:stone_bricks[weathering=false]"
      },
      {
        "char": "e",
        "block": "minecraft:polished_andesite"
      },
      {
        "char": "q",
        "block": "minecraft:air"
      },
      {
        "char": "ж",
        "block": "minecraft:air"
      },
      {
        "char": "m",
        "block": "minecraft:grass_block[snowy=false]"
      },
      {
        "char": "z",
        "block": "minecraft:dead_bubble_coral_block"
      },
      {
        "char": "A",
        "block": "minecraft:dead_fire_coral_block"
      },
      {
        "char": "R",
        "block": "minecraft:cobblestone[weathering=false]"
      },
      {
        "char": "B",
        "block": "minecraft:dead_brain_coral_block"
      },
      {
        "char": "w",
        "block": "minecraft:air"
      },
      {
        "char": "G",
        "block": "minecraft:air"
      },
      {
        "char": "Q",
        "block": "minecraft:air"
      },
      {
        "char": "N",
        "block": "minecraft:stone_slab[type=bottom,waterlogged=false,weathering=false]"
      },
      {
        "char": "E",
        "block": "minecraft:smooth_stone_slab[type=bottom,waterlogged=false]"
      },
      {
        "char": "i",
        "block": "minecraft:air"
      },
      {
        "char": "р",
        "block": "minecraft:spruce_fence[east=false,north=false,south=false,waterlogged=false,west=false]"
      },
      {
        "char": "л",
        "block": "minecraft:air"
      },
      {
        "char": "n",
        "block": "minecraft:air"
      },
      {
        "char": "P",
        "block": "minecraft:air"
      },
      {
        "char": "щ",
        "block": "minecraft:air"
      },
      {
        "char": "h",
        "block": "minecraft:oak_leaves[distance=7,persistent=true,waterlogged=false]"
      },
      {
        "char": "Ѯ",
        "block": "minecraft:rail[shape=north_east,waterlogged=false]"
      },
      {
        "char": "и",
        "block": "minecraft:air"
      },
      {
        "char": "Ҁ",
        "block": "minecraft:spruce_fence[east=true,north=false,south=false,waterlogged=false,west=false]"
      },
      {
        "char": "ѿ",
        "block": "minecraft:spruce_fence[east=false,north=false,south=false,waterlogged=false,west=true]"
      }
    ]
  },
  "slices": [
    [
      "fbbaaaaabbbaabau",
      "fbbabbaaabbaabaa",
      "fabaaauuabaaaabb",
      "eeeeeeeeeeeeeeee",
      "babbaaabaabaabab",
      "q ж  qq q q    q",
      "                ",
      "                ",
      "                ",
      "                ",
      "                ",
      "                ",
      "                ",
      "                ",
      "                ",
      "                "
    ],
    [
      "emmfmzfffzAfRBff",
      "emmmmmmmAAfBfzzm",
      "emmmmmmmmRzfmmmm",
      "eeeeeeeeeeeeeeee",
      "baababbaabaabbab",
      "  q   q q q q  q",
      "                ",
      "                ",
      "                ",
      "                ",
      "                ",
      "                ",
      "                ",
      "                ",
      "                ",
      "                "
    ],
    [
      "ewGQNQEQiр iEEEл",
      "eGwwGGGw  ii   w",
      "eGGwGGwGwnn wwww",
      "eeeeeeeeeeeeeeee",
      "aabbbababbbbaabb",
      " q    qq   q q  ",
      "                ",
      "                ",
      "                ",
      "                ",
      "                ",
      "                ",
      "                ",
      "                ",
      "                ",
      "                "
    ],
    [
      "i Pщ щ щ h     Ѯ",
      " P  P           ",
      " PP PP P        ",
      " iii    ii   ii ",
      "iiииииiiииiииииi",
      "  q q    q   q  ",
      "                ",
      "                ",
      "                ",
      "                ",
      "                ",
      "                ",
      "                ",
      "                ",
      "                ",
      "                "
    ],
    [
      "        hhh     ",
      "         h      ",
      "                ",
      "                ",
      "                ",
      "                ",
      "                ",
      "                ",
      "                ",
      "                ",
      "                ",
      "                ",
      "                ",
      "                ",
      "                ",
      "                "
    ],
    [
      "        hҀѿ     ",
      "         hh     ",
      "                ",
      "                ",
      "                ",
      "                ",
      "                ",
      "                ",
      "                ",
      "                ",
      "                ",
      "                ",
      "                ",
      "                ",
      "                ",
      "                "
    ]
  ]
}