{
  "xsize": 16,
  "zsize": 16,
  "palette": {
    "palette": [
      {
        "char": " ",
        "block": "minecraft:air"
      },
      {
        "char": "ф",
        "block": "minecraft:polished_andesite_slab[type=bottom,waterlogged=false]"
      },
      {
        "char": "a",
        "block": "minecraft:stone_bricks[weathering=true]"
      },
      {
        "char": "e",
        "block": "minecraft:polished_andesite"
      },
      {
        "char": "х",
        "block": "minecraft:air"
      },
      {
        "char": "Ѻ",
        "block": "minecraft:air"
      },
      {
        "char": "j",
        "block": "minecraft:air"
      },
      {
        "char": "c",
        "block": "minecraft:bricks[weathering=true]"
      },
      {
        "char": "f",
        "block": "minecraft:stone[weathering=false]"
      },
      {
        "char": "g",
        "block": "minecraft:air"
      },
      {
        "char": "H",
        "block": "minecraft:smooth_stone_slab[type=top,waterlogged=false]"
      },
      {
        "char": "Ы",
        "block": "minecraft:smooth_stone"
      },
      {
        "char": "l",
        "block": "minecraft:andesite"
      },
      {
        "char": "y",
        "block": "minecraft:polished_andesite_slab[type=top,waterlogged=false]"
      },
      {
        "char": "u",
        "block": "minecraft:stone_bricks[weathering=false]"
      },
      {
        "char": "C",
        "block": "minecraft:air"
      },
      {
        "char": "b",
        "block": "minecraft:cracked_stone_bricks"
      },
      {
        "char": "е",
        "block": "minecraft:air"
      },
      {
        "char": "E",
        "block": "minecraft:smooth_stone_slab[type=bottom,waterlogged=false]"
      },
      {
        "char": "v",
        "block": "minecraft:bricks[weathering=false]"
      },
      {
        "char": "Ь",
        "block": "minecraft:air"
      },
      {
        "char": "m",
        "block": "minecraft:grass_block[snowy=false]"
      },
      {
        "char": "A",
        "block": "minecraft:dead_fire_coral_block"
      },
      {
        "char": "B",
        "block": "minecraft:dead_brain_coral_block"
      },
      {
        "char": "i",
        "block": "minecraft:air"
      },
      {
        "char": "z",
        "block": "minecraft:dead_bubble_coral_block"
      },
      {
        "char": "R",
        "block": "minecraft:cobblestone[weathering=false]"
      },
      {
        "char": "Ҷ",
        "block": "minecraft:stone[weathering=true]"
      },
      {
        "char": "o",
        "block": "minecraft:air"
      },
      {
        "char": "я",
        "block": "minecraft:air"
      },
      {
        "char": "з",
        "block": "minecraft:air"
      },
      {
        "char": "G",
        "block": "minecraft:air"
      },
      {
        "char": "w",
        "block": "minecraft:air"
      },
      {
        "char": "N",
        "block": "minecraft:stone_slab[type=bottom,waterlogged=false,weathering=false]"
      },
      {
        "char": "р",
        "block": "minecraft:spruce_fence[east=false,north=false,south=false,waterlogged=false,west=false]"
      },
      {
        "char": "p",
        "block": "minecraft:air"
      },
      {
        "char": "P",
        "block": "minecraft:air"
      },
      {
        "char": "h",
        "block": "minecraft:oak_leaves[distance=7,persistent=true,waterlogged=false]"
      }
    ]
  },
  "slices": [
    [
      "          фaeeee",
      "          хѺejjc",
      "          фfejgg",
      "          HЫlgcj",
      "          yueggc",
      "          Caeggc",
      "          Cblcjc",
      "          еfeccg",
      "          фѺlgcc",
      "          Eueele",
      "          фѺlcjg",
      "          хЫeggc",
      "          хbegcv",
      "          Calcjc",
      "          yЫeggg",
      "          yfeggc"
    ],
    [
      "           Ьlcgc",
      "            vmmm",
      "            cmAB",
      "            gmfm",
      "          iхjmAz",
      "           хcmmm",
      "          i gmmR",
      "           icBBf",
      "            cffB",
      "            efAB",
      "           ivmҶҶ",
      "           Ьvmmz",
      "           ocmmm",
      "          iеgmmm",
      "           фjmmm",
      "          iхjmmm"
    ],
    [
      "           oeяiя",
      "            зGGG",
      "            зGEE",
      "           oзwEw",
      "            зwEN",
      "            iwww",
      "            зwwр",
      "            зi  ",
      "           oзр  ",
      "           oep  ",
      "            зwi ",
      "            iww ",
      "            iGww",
      "           oзGGw",
      "           oзGwG",
      "           oзwGw"
    ],
    [
      "            i   ",
      "             PP ",
      "             P  ",
      "                ",
      "                ",
      "                ",
      "               h",
      "                ",
      "             h  ",
      "            i   ",
      "                ",
      "                ",
      "             P  ",
      "             PP ",
      "             P P",
      "              P "
    ],
    [
      "                ",
      "                ",
      "                ",
      "                ",
      "                ",
      "                ",
      "               h",
      "                ",
      "             h  ",
      "                ",
      "                ",
      "                ",
      "                ",
      "                ",
      "                ",
      "                "
    ],
    [
      "                ",
      "                ",
      "                ",
      "                ",
      "                ",
      "                ",
      "                ",
      "                ",
      "             h  ",
      "                ",
      "                ",
      "                ",
      "                ",
      "                ",
      "                ",
      "                "
    ]
  ]
}