{
  "xsize": 16,
  "zsize": 16,
  "palette": {
    "palette": [
      {
        "char": " ",
        "block": "minecraft:air"
      },
      {
        "char": "ф",
        "block": "minecraft:air"
      },
      {
        "char": "a",
        "block": "minecraft:air"
      },
      {
        "char": "e",
        "block": "minecraft:air"
      },
      {
        "char": "х",
        "block": "minecraft:air"
      },
      {
        "char": "Ѻ",
        "block": "minecraft:air"
      },
      {
        "char": "j",
        "block": "minecraft:air"
      },
      {
        "char": "c",
        "block": "minecraft:air"
      },
      {
        "char": "f",
        "block": "minecraft:air"
      },
      {
        "char": "g",
        "block": "minecraft:air"
      },
      {
        "char": "H",
        "block": "minecraft:air"
      },
      {
        "char": "Ы",
        "block": "minecraft:air"
      },
      {
        "char": "l",
        "block": "minecraft:air"
      },
      {
        "char": "y",
        "block": "minecraft:air"
      },
      {
        "char": "u",
        "block": "minecraft:air"
      },
      {
        "char": "C",
        "block": "minecraft:air"
      },
      {
        "char": "b",
        "block": "minecraft:air"
      },
      {
        "char": "е",
        "block": "minecraft:air"
      },
      {
        "char": "E",
        "block": "minecraft:air"
      },
      {
        "char": "v",
        "block": "minecraft:air"
      },
      {
        "char": "Ь",
        "block": "minecraft:air"
      },
      {
        "char": "m",
        "block": "minecraft:air"
      },
      {
        "char": "A",
        "block": "minecraft:air"
      },
      {
        "char": "B",
        "block": "minecraft:air"
      },
      {
        "char": "i",
        "block": "minecraft:air"
      },
      {
        "char": "z",
        "block": "minecraft:air"
      },
      {
        "char": "R",
        "block": "minecraft:air"
      },
      {
        "char": "Ҷ",
        "block": "minecraft:air"
      },
      {
        "char": "o",
        "block": "minecraft:air"
      },
      {
        "char": "я",
        "block": "minecraft:air"
      },
      {
        "char": "з",
        "block": "minecraft:air"
      },
      {
        "char": "G",
        "block": "minecraft:tall_grass[half=lower]"
      },
      {
        "char": "w",
        "block": "minecraft:grass"
      },
      {
        "char": "N",
        "block": "minecraft:air"
      },
      {
        "char": "р",
        "block": "minecraft:air"
      },
      {
        "char": "p",
        "block": "minecraft:air"
      },
      {
        "char": "P",
        "block": "minecraft:tall_grass[half=upper]"
      },
      {
        "char": "h",
        "block": "minecraft:air"
      }
    ]
  },
  "slices": [
    [
      "          фaeeee",
      "          хѺejjc",
      "          фfejgg",
      "          HЫlgcj",
      "          yueggc",
      "          Caeggc",
      "          Cblcjc",
      "          еfeccg",
      "          фѺlgcc",
      "          Eueele",
      "          фѺlcjg",
      "          хЫeggc",
      "          хbegcv",
      "          Calcjc",
      "          yЫeggg",
      "          yfeggc"
    ],
    [
      "           Ьlcgc",
      "            vmmm",
      "            cmAB",
      "            gmfm",
      "          iхjmAz",
      "           хcmmm",
      "          i gmmR",
      "           icBBf",
      "            cffB",
      "            efAB",
      "           ivmҶҶ",
      "           Ьvmmz",
      "           ocmmm",
      "          iеgmmm",
      "           фjmmm",
      "          iхjmmm"
    ],
    [
      "           oeяiя",
      "            зGGG",
      "            зGEE",
      "           oзwEw",
      "            зwEN",
      "            iwww",
      "            зwwр",
      "            зi  ",
      "           oзр  ",
      "           oep  ",
      "            зwi ",
      "            iww ",
      "            iGww",
      "           oзGGw",
      "           oзGwG",
      "           oзwGw"
    ],
    [
      "            i   ",
      "             PP ",
      "             P  ",
      "                ",
      "                ",
      "                ",
      "               h",
      "                ",
      "             h  ",
      "            i   ",
      "                ",
      "                ",
      "             P  ",
      "             PP ",
      "             P P",
      "              P "
    ],
    [
      "                ",
      "                ",
      "                ",
      "                ",
      "                ",
      "                ",
      "               h",
      "                ",
      "             h  ",
      "                ",
      "                ",
      "                ",
      "                ",
      "                ",
      "                ",
      "                "
    ],
    [
      "                ",
      "                ",
      "                ",
      "                ",
      "                ",
      "                ",
      "                ",
      "                ",
      "             h  ",
      "                ",
      "                ",
      "                ",
      "                ",
      "                ",
      "                ",
      "                "
    ]
  ]
}