{
  "xsize": 16,
  "zsize": 16,
  "palette": {
    "palette": [
      {
        "char": " ",
        "block": "minecraft:air"
      },
      {
        "char": "е",
        "block": "minecraft:air"
      },
      {
        "char": "u",
        "block": "minecraft:stone_bricks[weathering=false]"
      },
      {
        "char": "e",
        "block": "minecraft:polished_andesite"
      },
      {
        "char": "f",
        "block": "minecraft:stone[weathering=false]"
      },
      {
        "char": "F",
        "block": "minecraft:stone_slab[type=top,waterlogged=false,weathering=false]"
      },
      {
        "char": "a",
        "block": "minecraft:stone_bricks[weathering=true]"
      },
      {
        "char": "l",
        "block": "minecraft:andesite"
      },
      {
        "char": "b",
        "block": "minecraft:cracked_stone_bricks"
      },
      {
        "char": "C",
        "block": "minecraft:air"
      },
      {
        "char": "E",
        "block": "minecraft:smooth_stone_slab[type=bottom,waterlogged=false]"
      },
      {
        "char": "I",
        "block": "minecraft:air"
      },
      {
        "char": "m",
        "block": "minecraft:grass_block[snowy=false]"
      },
      {
        "char": "z",
        "block": "minecraft:dead_bubble_coral_block"
      },
      {
        "char": "R",
        "block": "minecraft:cobblestone[weathering=false]"
      },
      {
        "char": "A",
        "block": "minecraft:dead_fire_coral_block"
      },
      {
        "char": "B",
        "block": "minecraft:dead_brain_coral_block"
      },
      {
        "char": "G",
        "block": "minecraft:air"
      },
      {
        "char": "w",
        "block": "minecraft:air"
      },
      {
        "char": "Q",
        "block": "minecraft:air"
      },
      {
        "char": "л",
        "block": "minecraft:air"
      },
      {
        "char": "N",
        "block": "minecraft:stone_slab[type=bottom,waterlogged=false,weathering=false]"
      },
      {
        "char": "i",
        "block": "minecraft:air"
      },
      {
        "char": "Э",
        "block": "minecraft:air"
      },
      {
        "char": "Ҁ",
        "block": "minecraft:spruce_fence[east=true,north=false,south=false,waterlogged=false,west=false]"
      },
      {
        "char": "p",
        "block": "minecraft:air"
      },
      {
        "char": "з",
        "block": "minecraft:air"
      },
      {
        "char": "Ѱ",
        "block": "minecraft:rail[shape=south_east,waterlogged=false]"
      },
      {
        "char": "Ѯ",
        "block": "minecraft:rail[shape=north_east,waterlogged=false]"
      },
      {
        "char": "h",
        "block": "minecraft:oak_leaves[distance=7,persistent=true,waterlogged=false]"
      },
      {
        "char": "щ",
        "block": "minecraft:air"
      },
      {
        "char": "区",
        "block": "minecraft:spruce_fence[east=false,north=false,south=true,waterlogged=false,west=true]"
      },
      {
        "char": "全",
        "block": "minecraft:spruce_fence[east=false,north=true,south=true,waterlogged=false,west=false]"
      },
      {
        "char": "Ӄ",
        "block": "minecraft:spruce_fence[east=false,north=true,south=false,waterlogged=false,west=false]"
      }
    ]
  },
  "slices": [
    [
      "          еuefff",
      "          Falffb",
      "          Fblbfa",
      "          Cfeauf",
      "          Ebeuff",
      "          Fblaff",
      "          Cblbff",
      "          Faeafb",
      "          еaebfb",
      "          Ifeffb",
      "          Ibeaaf",
      "          Ffebbf",
      "          Eaeaff",
      "          еbebbb",
      "          Faefaa",
      "          Iflfff"
    ],
    [
      "           aemmm",
      "           aemmz",
      "           bemmz",
      "           aemmR",
      "           aefmf",
      "           aezAB",
      "           aezRR",
      "           bezAA",
      "           aefAf",
      "           aezAf",
      "           aezAB",
      "           bezBz",
      "           aeffB",
      "           aeBzf",
      "           aezmA",
      "           aemmm"
    ],
    [
      "           beGww",
      "           aeGwQ",
      "           bewwл",
      "           bewwN",
      "           aeiwл",
      "           ae iл",
      "           be  E",
      "           bei Q",
      "           aei Q",
      "           ae   ",
      "           beii ",
      "           be iE",
      "           beЭ E",
      "           ae ҀQ",
      "           bepwQ",
      "           beGww"
    ],
    [
      "           ii   ",
      "           зi  Ѱ",
      "           зi  Ѯ",
      "           ii   ",
      "           i   Ѱ",
      "           з   Ѯ",
      "           i    ",
      "           зi  Ѱ",
      "           i   Ѯ",
      "           з    ",
      "           з    ",
      "           з    ",
      "           ii   ",
      "           зi hщ",
      "           зi  щ",
      "           ii   "
    ],
    [
      "                ",
      "                ",
      "                ",
      "                ",
      "                ",
      "                ",
      "                ",
      "                ",
      "                ",
      "                ",
      "                ",
      "                ",
      "             Ҁ区 ",
      "             h全h",
      "              Ӄ ",
      "                "
    ],
    [
      "                ",
      "                ",
      "                ",
      "                ",
      "                ",
      "                ",
      "                ",
      "                ",
      "                ",
      "                ",
      "                ",
      "                ",
      "             hh ",
      "             hhh",
      "              h ",
      "                "
    ]
  ]
}