{
  "xsize": 16,
  "zsize": 16,
  "palette": {
    "palette": [
      {
        "char": " ",
        "block": "minecraft:air"
      },
      {
        "char": "p",
        "block": "minecraft:vine[east=false,north=false,south=true,up=false,west=false]"
      },
      {
        "char": "u",
        "block": "minecraft:vine[east=true,north=false,south=true,up=false,west=false]"
      },
      {
        "char": "h",
        "block": "minecraft:mossy_stone_bricks"
      },
      {
        "char": "d",
        "block": "minecraft:glass"
      },
      {
        "char": "j",
        "block": "minecraft:stone_bricks[weathering=false]"
      },
      {
        "char": "O",
        "block": "minecraft:stone_brick_stairs[facing=south,half=top,shape=straight,waterlogged=false,weathering=false]"
      },
      {
        "char": "΅",
        "block": "minecraft:stone_brick_stairs[facing=east,half=top,shape=straight,waterlogged=false,weathering=false]"
      },
      {
        "char": "b",
        "block": "minecraft:quartz_pillar[axis=y]"
      },
      {
        "char": "i",
        "block": "minecraft:cracked_stone_bricks"
      },
      {
        "char": "·",
        "block": "minecraft:spruce_fence[east=true,north=false,south=true,waterlogged=false,west=false]"
      },
      {
        "char": "s",
        "block": "minecraft:vine[east=true,north=false,south=false,up=false,west=false]"
      },
      {
        "char": "Ί",
        "block": "minecraft:quartz_stairs[facing=south,half=bottom,shape=straight,waterlogged=false]"
      },
      {
        "char": "o",
        "block": "minecraft:mossy_cobblestone"
      },
      {
        "char": "g",
        "block": "minecraft:smooth_stone_slab[type=double,waterlogged=false]"
      },
      {
        "char": "c",
        "block": "minecraft:cobblestone[weathering=false]"
      },
      {
        "char": "z",
        "block": "minecraft:smooth_stone_slab[type=top,waterlogged=false]"
      },
      {
        "char": "D",
        "block": "minecraft:stone_brick_slab[type=bottom,waterlogged=false,weathering=false]"
      },
      {
        "char": "P",
        "block": "minecraft:air"
      },
      {
        "char": "ʹ",
        "block": "minecraft:air"
      },
      {
        "char": "7",
        "block": "minecraft:dark_oak_fence[east=false,north=false,south=false,waterlogged=false,west=false]"
      },
      {
        "char": "5",
        "block": "minecraft:air"
      },
      {
        "char": "T",
        "block": "minecraft:air"
      },
      {
        "char": "Z",
        "block": "minecraft:air"
      },
      {
        "char": "F",
        "block": "minecraft:air"
      },
      {
        "char": "E",
        "block": "minecraft:redstone_lamp[lit=false]"
      },
      {
        "char": "ρ",
        "block": "minecraft:chest[facing=east,type=single,waterlogged=false]",
        "loot": "bigbuildingsloot",
        "tag": {
          "z": 620,
          "x": 142,
          "ForgeData": {
            "LockFlag": "1b"
          },
          "ForgeCaps": {},
          "id": "minecraft:chest",
          "y": 140,
          "Items": []
        }
      },
      {
        "char": "J",
        "block": "minecraft:air"
      },
      {
        "char": "σ",
        "block": "minecraft:stone_brick_slab[type=double,waterlogged=false,weathering=false]"
      },
      {
        "char": "r",
        "block": "minecraft:smooth_stone_slab[type=bottom,waterlogged=false]"
      }
    ]
  },
  "slices": [
    [
      "                ",
      "                ",
      "              p ",
      "          p puhd",
      "         u ddj  ",
      "        ud      ",
      "        j       ",
      "       d     O  ",
      "      d     ΅j  ",
      "      d         ",
      "      d   O    b",
      "     uj  ΅i  ·b ",
      "    sj       b  ",
      "    sd      bb  ",
      "     d      bb b",
      "     d      bbΊb"
    ],
    [
      "                ",
      "                ",
      "              pO",
      "          p puoj",
      "         ujjhogg",
      "        ujgggggg",
      "        cggggggg",
      "       jgggggggg",
      "      hggggggg z",
      "      iggggg   z",
      "      hgggg    b",
      "     uogggg  ·bz",
      "    scgggg   bzz",
      "    siggggzzbb z",
      "     jgggg zbb b",
      "     hggggzzbb b"
    ],
    [
      "                ",
      "                ",
      "              p ",
      "          p puid",
      "         udddh  ",
      "        pd      ",
      "        h       ",
      "       d  D  Pʹ7",
      "      d    P5T Z",
      "      dD  PT   F",
      "      d  DF    b",
      "     ui  PT  Eb ",
      "    sj   F   bρ ",
      "    sd   F  bbgb",
      "     d   F  bb b",
      "     dJ  F  bb b"
    ],
    [
      "                ",
      "                ",
      "              p ",
      "          p puid",
      "         udddj  ",
      "         d      ",
      "        i       ",
      "       d       7",
      "      d         ",
      "      d         ",
      "      d        b",
      "     uj       b ",
      "    sh       b  ",
      "    sd      bbgb",
      "     d      bb b",
      "     dʹ     bb b"
    ],
    [
      "                ",
      "                ",
      "              pO",
      "          p puch",
      "         uhhic  ",
      "         j      ",
      "                ",
      "       hD      7",
      "      D         ",
      "      σ         ",
      "      i        b",
      "     uo       bb",
      "    so       bbb",
      "    sh      bbbb",
      "     h      bb b",
      "     hʹ     bb b"
    ],
    [
      "                ",
      "                ",
      "              p ",
      "            puid",
      "          dddi  ",
      "         d      ",
      "                ",
      "               r",
      "               r",
      "               r",
      "               r",
      "     uj       rb",
      "    si       rbb",
      "    sd      rbbb",
      "     d      rb b",
      "     dʹ     rb b"
    ]
  ]
}