{
  "xsize": 16,
  "zsize": 16,
  "palette": {
    "palette": [
      {
        "char": " ",
        "block": "minecraft:air"
      },
      {
        "char": "a",
        "block": "minecraft:air"
      },
      {
        "char": "v",
        "block": "minecraft:air"
      },
      {
        "char": "q",
        "block": "minecraft:air"
      },
      {
        "char": "w",
        "block": "minecraft:air"
      },
      {
        "char": "e",
        "block": "minecraft:air"
      },
      {
        "char": "y",
        "block": "minecraft:air"
      },
      {
        "char": "x",
        "block": "minecraft:air"
      },
      {
        "char": "c",
        "block": "minecraft:air"
      },
      {
        "char": "o",
        "block": "minecraft:air"
      },
      {
        "char": "t",
        "block": "minecraft:air"
      },
      {
        "char": "i",
        "block": "minecraft:air"
      },
      {
        "char": "h",
        "block": "minecraft:air"
      },
      {
        "char": "f",
        "block": "minecraft:grass"
      },
      {
        "char": "j",
        "block": "minecraft:air"
      },
      {
        "char": "b",
        "block": "minecraft:air"
      },
      {
        "char": "l",
        "block": "minecraft:air"
      },
      {
        "char": "9",
        "block": "minecraft:air"
      },
      {
        "char": "K",
        "block": "minecraft:air"
      },
      {
        "char": "E",
        "block": "minecraft:air"
      },
      {
        "char": "8",
        "block": "minecraft:air"
      },
      {
        "char": "6",
        "block": "minecraft:air"
      },
      {
        "char": "Ε",
        "block": "minecraft:air"
      },
      {
        "char": "3",
        "block": "minecraft:air"
      },
      {
        "char": "Ή",
        "block": "minecraft:air"
      },
      {
        "char": "d",
        "block": "minecraft:air"
      },
      {
        "char": "0",
        "block": "minecraft:air"
      },
      {
        "char": "Δ",
        "block": "minecraft:air"
      },
      {
        "char": "n",
        "block": "minecraft:air"
      },
      {
        "char": "A",
        "block": "minecraft:air"
      },
      {
        "char": "δ",
        "block": "minecraft:air"
      },
      {
        "char": "Γ",
        "block": "minecraft:air"
      },
      {
        "char": "Ϋ",
        "block": "minecraft:air"
      },
      {
        "char": "m",
        "block": "minecraft:air"
      },
      {
        "char": "Κ",
        "block": "minecraft:air"
      },
      {
        "char": "υ",
        "block": "minecraft:air"
      },
      {
        "char": "ν",
        "block": "minecraft:air"
      },
      {
        "char": "͵",
        "block": "minecraft:air"
      },
      {
        "char": "θ",
        "block": "minecraft:air"
      },
      {
        "char": "Ϗ",
        "block": "minecraft:air"
      },
      {
        "char": "μ",
        "block": "minecraft:air"
      }
    ]
  },
  "slices": [
    [
      "aaaaaaaaaaaaavqv",
      "aaaaaaaaaaaaawvv",
      "aaaaaaaaaaaaeywv",
      "aaaaaaaaaaaaeyyw",
      "aaaaaaaaaaaaeywe",
      "aaaaaaaaaaaeewvq",
      "aaaaaaaaaaaeeywq",
      "aaaaaaaaaaeeeqxq",
      "aaaaaaaaaeeeexxv",
      "aaaaaaaeeeeeexee",
      "aaaeeeeeeeeeevvx",
      "eeeeeeeeeeeeeyxx",
      "eeeeeeeeeeeeeqqx",
      "eeeeeeeeeeeeevvx",
      "eeeeeeeeeeeeeeqv",
      "eeeeeeeeeeeeeyex"
    ],
    [
      "cccooccccccti   ",
      "ccccoccccciih   ",
      "coccocccccoif   ",
      "oocccccccctif   ",
      "occcccccccohf  f",
      "cccccccccthff   ",
      "ccccccccctjf    ",
      "ccccccccoifff   ",
      "cccjocciiffff   ",
      "oooihhif ffff ff",
      "hhifffffffff    ",
      "fffffffffffff   ",
      "ff fffffffff    ",
      "fffffffffffff   ",
      "ffffffffffff f  ",
      "fff ffffffff  f "
    ],
    [
      "bb bll9l  Kh    ",
      "bbbE 8j6lΕi     ",
      "bb  l 3l Ήd     ",
      "0 l9 l l Ήd     ",
      "l 8i6 l lΔd     ",
      " l 3l ll dn     ",
      "l ll l  iA      ",
      " l δΓΓΫdA       ",
      "l Khdddm        ",
      "ddhA            ",
      " mm             ",
      "                ",
      "                ",
      "                ",
      "                ",
      "                "
    ],
    [
      "Κυbb      Kh    ",
      "Κνb͵  i   h     ",
      "bb        d     ",
      "0         d     ",
      "   h      d     ",
      "         dn     ",
      "        jA      ",
      "       dA       ",
      "  Kidddm        ",
      "ddhn            ",
      " mm             ",
      "                ",
      "                ",
      "                ",
      "                ",
      "                "
    ],
    [
      "θ Ϗb      Kc    ",
      "μ b͵  j   t     ",
      "bb        j     ",
      "0         i     ",
      "   h      i     ",
      "         jn     ",
      "        cA      ",
      "       jA       ",
      "  Kcihim        ",
      "ihon            ",
      " mm             ",
      "                ",
      "                ",
      "                ",
      "                ",
      "                "
    ],
    [
      "   b      Eh    ",
      "  bE  j   i     ",
      "bb        d     ",
      "0         d     ",
      "   j      d     ",
      "         dn     ",
      "        jA      ",
      "       dA       ",
      "  Ehdddm        ",
      "ddjn            ",
      " mm             ",
      "                ",
      "                ",
      "                ",
      "                ",
      "                "
    ]
  ]
}