{
  "xsize": 16,
  "zsize": 16,
  "palette": {
    "palette": [
      {
        "char": " ",
        "block": "minecraft:air"
      },
      {
        "char": "b",
        "block": "minecraft:quartz_pillar[axis=y]"
      },
      {
        "char": "h",
        "block": "minecraft:mossy_stone_bricks"
      },
      {
        "char": "͵",
        "block": "minecraft:spruce_fence[east=false,north=true,south=false,waterlogged=false,west=true]"
      },
      {
        "char": "i",
        "block": "minecraft:cracked_stone_bricks"
      },
      {
        "char": "ͷ",
        "block": "minecraft:stone_brick_stairs[facing=west,half=top,shape=straight,waterlogged=false,weathering=false]"
      },
      {
        "char": "ͼ",
        "block": "minecraft:stone_brick_stairs[facing=north,half=top,shape=straight,waterlogged=false,weathering=false]"
      },
      {
        "char": "d",
        "block": "minecraft:glass"
      },
      {
        "char": "0",
        "block": "minecraft:ladder[facing=south,waterlogged=false]"
      },
      {
        "char": "j",
        "block": "minecraft:stone_bricks[weathering=false]"
      },
      {
        "char": "n",
        "block": "minecraft:vine[east=false,north=false,south=false,up=false,west=true]"
      },
      {
        "char": "A",
        "block": "minecraft:vine[east=false,north=true,south=false,up=false,west=true]"
      },
      {
        "char": "m",
        "block": "minecraft:vine[east=false,north=true,south=false,up=false,west=false]"
      },
      {
        "char": "g",
        "block": "minecraft:smooth_stone_slab[type=double,waterlogged=false]"
      },
      {
        "char": "o",
        "block": "minecraft:mossy_cobblestone"
      },
      {
        "char": "c",
        "block": "minecraft:cobblestone[weathering=false]"
      },
      {
        "char": "z",
        "block": "minecraft:smooth_stone_slab[type=top,waterlogged=false]"
      },
      {
        "char": "t",
        "block": "minecraft:stone[weathering=false]"
      },
      {
        "char": "F",
        "block": "minecraft:air"
      },
      {
        "char": "E",
        "block": "minecraft:redstone_lamp[lit=false]"
      },
      {
        "char": "P",
        "block": "minecraft:air"
      },
      {
        "char": "T",
        "block": "minecraft:air"
      },
      {
        "char": "5",
        "block": "minecraft:air"
      },
      {
        "char": "N",
        "block": "minecraft:air"
      },
      {
        "char": "J",
        "block": "minecraft:air"
      },
      {
        "char": "4",
        "block": "minecraft:air"
      },
      {
        "char": "ΐ",
        "block": "minecraft:quartz_stairs[facing=east,half=bottom,shape=straight,waterlogged=false]"
      },
      {
        "char": "Z",
        "block": "minecraft:air"
      },
      {
        "char": "Ͱ",
        "block": "minecraft:stone_button[face=wall,facing=north,powered=false]"
      },
      {
        "char": "r",
        "block": "minecraft:smooth_stone_slab[type=bottom,waterlogged=false]"
      }
    ]
  },
  "slices": [
    [
      "   b       h    ",
      "  b͵  iͷ  i     ",
      "bb    ͼ   d     ",
      "0         d     ",
      "   jͷ     d     ",
      "   ͼ     dn     ",
      "        jA      ",
      "       dA       ",
      "   idddm        ",
      "ddin            ",
      " mm             ",
      "                ",
      "                ",
      "                ",
      "                ",
      "                "
    ],
    [
      "b bb   ggggo    ",
      "  b͵  ggggc     ",
      "bb    ggggh     ",
      "0z   gggggi     ",
      "zz gggggggh     ",
      "ggggggggghn     ",
      "ggggggggtA      ",
      "gggggggjA       ",
      "gggcjjhm        ",
      "hion            ",
      " mm             ",
      "                ",
      "                ",
      "                ",
      "                ",
      "                "
    ],
    [
      "   b   F   i    ",
      "  bE  PT  h     ",
      "bb    F   d     ",
      "0F   PT   d     ",
      " F P5T    d     ",
      " N5T     d      ",
      "        hA      ",
      "  PJ   dA       ",
      "  4idddm        ",
      "ddhn            ",
      " mm             ",
      "                ",
      "                ",
      "                ",
      "                ",
      "                "
    ],
    [
      "ΐb b       h    ",
      "bbb       h     ",
      "bb        d     ",
      "          d     ",
      "          d     ",
      "         d      ",
      "        jA      ",
      "   Z   dA       ",
      "   hdddm        ",
      "ddin            ",
      " mm             ",
      "                ",
      "                ",
      "                ",
      "                ",
      "                "
    ],
    [
      " Ͱbb       o    ",
      "bbb       t     ",
      "bb        i     ",
      "          j     ",
      "          i     ",
      "         i      ",
      "        oA      ",
      "   Z   hA       ",
      "   cjjjm        ",
      "jjon            ",
      " mm             ",
      "                ",
      "                ",
      "                ",
      "                ",
      "                "
    ],
    [
      " Ͱbr      4j    ",
      "bbr       h     ",
      "rr        d     ",
      "          d     ",
      "          d     ",
      "         d      ",
      "        iA      ",
      "   Z   dA       ",
      "   hdddm        ",
      "ddin            ",
      " mm             ",
      "                ",
      "                ",
      "                ",
      "                ",
      "                "
    ]
  ]
}