{
  "xsize": 16,
  "zsize": 16,
  "palette": {
    "palette": [
      {
        "char": " ",
        "block": "minecraft:air"
      },
      {
        "char": "e",
        "block": "minecraft:air"
      },
      {
        "char": "y",
        "block": "minecraft:air"
      },
      {
        "char": "q",
        "block": "minecraft:air"
      },
      {
        "char": "a",
        "block": "minecraft:air"
      },
      {
        "char": "x",
        "block": "minecraft:air"
      },
      {
        "char": "w",
        "block": "minecraft:air"
      },
      {
        "char": "v",
        "block": "minecraft:air"
      },
      {
        "char": "j",
        "block": "minecraft:air"
      },
      {
        "char": "f",
        "block": "minecraft:grass"
      },
      {
        "char": "i",
        "block": "minecraft:air"
      },
      {
        "char": "t",
        "block": "minecraft:air"
      },
      {
        "char": "c",
        "block": "minecraft:air"
      },
      {
        "char": "o",
        "block": "minecraft:air"
      },
      {
        "char": "h",
        "block": "minecraft:air"
      },
      {
        "char": "ͻ",
        "block": "minecraft:air"
      },
      {
        "char": "Ͳ",
        "block": "minecraft:air"
      },
      {
        "char": "D",
        "block": "minecraft:air"
      },
      {
        "char": "K",
        "block": "minecraft:air"
      },
      {
        "char": "l",
        "block": "minecraft:air"
      },
      {
        "char": "9",
        "block": "minecraft:air"
      },
      {
        "char": "b",
        "block": "minecraft:air"
      },
      {
        "char": "Φ",
        "block": "minecraft:air"
      },
      {
        "char": "8",
        "block": "minecraft:air"
      },
      {
        "char": "6",
        "block": "minecraft:air"
      },
      {
        "char": "E",
        "block": "minecraft:air"
      },
      {
        "char": "d",
        "block": "minecraft:air"
      },
      {
        "char": "ͽ",
        "block": "minecraft:air"
      },
      {
        "char": "3",
        "block": "minecraft:air"
      },
      {
        "char": "s",
        "block": "minecraft:air"
      },
      {
        "char": "Λ",
        "block": "minecraft:air"
      },
      {
        "char": "m",
        "block": "minecraft:air"
      },
      {
        "char": "R",
        "block": "minecraft:air"
      },
      {
        "char": "n",
        "block": "minecraft:air"
      },
      {
        "char": "Ά",
        "block": "minecraft:air"
      },
      {
        "char": "γ",
        "block": "minecraft:air"
      },
      {
        "char": "ύ",
        "block": "minecraft:air"
      },
      {
        "char": "C",
        "block": "minecraft:air"
      }
    ]
  },
  "slices": [
    [
      "eyqeaaaaaaaaaaaa",
      "xeqeeaaaaaaaaaaa",
      "xyweeaaaaaaaaaaa",
      "wwveeaaaaaaaaaaa",
      "xqweeaaaaaaaaaaa",
      "wwweeeaaaaaaaaaa",
      "xwqeeeaaaaaaaaaa",
      "yqyeeeeaaaaaaaaa",
      "qyqeeeeeaaaaaaaa",
      "qyweeaeeeeaaaaaa",
      "xqxeeeeeeeeeeeee",
      "yqveeeeaeeeeeeee",
      "vxxeeeeeeaeeaeee",
      "yyeeeeaeeeeeeeee",
      "vqxeeeeeeeeeeeea",
      "wyyjeeeeeeaeeeee"
    ],
    [
      "f  fitcccccccocc",
      " ffffijccccccccc",
      "   ffitccccccccc",
      "  fffhtcccccccco",
      "   ffhocccccccco",
      "   fffitcccccccc",
      "   fffhtcccccccc",
      "   ffffiooccccoc",
      "   fffffjhocccoo",
      "   ffiffffioccoͻ",
      "  ffffffffffffff",
      "    fffhffffffff",
      " f  f fffͲffhfff",
      "  ff fDfffff fff",
      "    fffffffffffD",
      "   D fffffhfffff"
    ],
    [
      "     hK l 9l bbb",
      "      iΦ 8h6 Ebb",
      "      dͽll3 l  b",
      "     sdͽ llll9 l",
      "     sdΛlll 8 6 ",
      "      md  i l3 l",
      "       RinDll l ",
      "        m l D i ",
      "        Ͳ      l",
      "          mDmͲ d",
      "                ",
      "                ",
      "                ",
      "                ",
      "                ",
      "                "
    ],
    [
      "     jK      b b",
      "      j   h  Άbb",
      "      d        b",
      "     sd         ",
      "     sd      h  ",
      "      md        ",
      "       Rin      ",
      "        m       ",
      "                ",
      "          mmm  d",
      "                ",
      "                ",
      "                ",
      "                ",
      "                ",
      "                "
    ],
    [
      "     tK      b γ",
      "      o   j  Άbύ",
      "      i        b",
      "     sh         ",
      "     sj      i  ",
      "      mh        ",
      "       Rc       ",
      "        mh      ",
      "             i  ",
      "          mmm  h",
      "                ",
      "                ",
      "                ",
      "                ",
      "                ",
      "                "
    ],
    [
      "    ChE      bb ",
      "     Ci   h  Eb ",
      "      d        b",
      "     sd         ",
      "     sd      j  ",
      "      md        ",
      "       Rh       ",
      "        md      ",
      "             jE ",
      "          mmm id",
      "                ",
      "                ",
      "                ",
      "                ",
      "                ",
      "                "
    ]
  ]
}