{
  "xsize": 16,
  "zsize": 16,
  "palette": {
    "palette": [
      {
        "char": " ",
        "block": "minecraft:air"
      },
      {
        "char": "p",
        "block": "minecraft:vine[east=false,north=false,south=true,up=false,west=false]"
      },
      {
        "char": "d",
        "block": "minecraft:glass"
      },
      {
        "char": "h",
        "block": "minecraft:mossy_stone_bricks"
      },
      {
        "char": "B",
        "block": "minecraft:vine[east=false,north=false,south=true,up=false,west=true]"
      },
      {
        "char": "i",
        "block": "minecraft:cracked_stone_bricks"
      },
      {
        "char": "n",
        "block": "minecraft:vine[east=false,north=false,south=false,up=false,west=true]"
      },
      {
        "char": "r",
        "block": "minecraft:smooth_stone_slab[type=bottom,waterlogged=false]"
      },
      {
        "char": "j",
        "block": "minecraft:stone_bricks[weathering=false]"
      },
      {
        "char": "b",
        "block": "minecraft:quartz_pillar[axis=y]"
      },
      {
        "char": "ͳ",
        "block": "minecraft:air"
      },
      {
        "char": "c",
        "block": "minecraft:cobblestone[weathering=false]"
      },
      {
        "char": "ͱ",
        "block": "minecraft:air"
      },
      {
        "char": "t",
        "block": "minecraft:stone[weathering=false]"
      },
      {
        "char": "S",
        "block": "minecraft:black_concrete"
      },
      {
        "char": "g",
        "block": "minecraft:smooth_stone_slab[type=double,waterlogged=false]"
      },
      {
        "char": "D",
        "block": "minecraft:stone_brick_slab[type=bottom,waterlogged=false,weathering=false]"
      },
      {
        "char": "Ύ",
        "block": "minecraft:stone_brick_slab[type=top,waterlogged=false,weathering=false]"
      },
      {
        "char": "k",
        "block": "minecraft:gray_stained_glass"
      },
      {
        "char": "G",
        "block": "minecraft:air"
      },
      {
        "char": "ώ",
        "block": "minecraft:air"
      },
      {
        "char": "η",
        "block": "minecraft:air"
      },
      {
        "char": "ͺ",
        "block": "minecraft:air"
      },
      {
        "char": "Ͷ",
        "block": "minecraft:air"
      },
      {
        "char": "I",
        "block": "minecraft:air"
      },
      {
        "char": "έ",
        "block": "minecraft:air"
      }
    ]
  },
  "slices": [
    [
      "                ",
      "                ",
      "  p             ",
      "ddhBp           ",
      "   hddd         ",
      "       d        ",
      "        i       ",
      "         d      ",
      "          d     ",
      "          dn    ",
      "          dn    ",
      "rr        j     ",
      "bbr        i    ",
      "b br      ͳdn   ",
      "dbbr       d    ",
      "bbbr       d    "
    ],
    [
      "                ",
      "                ",
      "  p             ",
      "iicBp           ",
      "ͱͱͱchih         ",
      "       h        ",
      "        t       ",
      "         i      ",
      "          h     ",
      "          in    ",
      "          jn    ",
      "          c     ",
      "b          t    ",
      "Sb        ͳhn   ",
      "dSb        h    ",
      "Sb         i    "
    ],
    [
      "                ",
      "                ",
      "                ",
      "                ",
      "hjj             ",
      "                ",
      "        i       ",
      "         h      ",
      "          h     ",
      "          hn    ",
      "          hn    ",
      "          g     ",
      "          i     ",
      "b         i     ",
      "db        h     ",
      "b         i     "
    ],
    [
      "                ",
      "                ",
      "                ",
      "                ",
      "                ",
      "jhD             ",
      "      Dh        ",
      "        j       ",
      "         h      ",
      "         h      ",
      "         j      ",
      "         g      ",
      "         h      ",
      "S        i      ",
      "dS       j      ",
      "S        h      "
    ],
    [
      "                ",
      "                ",
      "                ",
      "                ",
      "                ",
      "                ",
      "ggg Ύ           ",
      "ijhhgjii        ",
      "kkkkjgijj       ",
      "    kjgih       ",
      "     kjgh       ",
      "      kig       ",
      "      kjg       ",
      "      kjg       ",
      "      khg       ",
      "      khg       "
    ],
    [
      "                ",
      "                ",
      "                ",
      "                ",
      "                ",
      "                ",
      "GGώ             ",
      "      ηͺ        ",
      "       Ͷͺ       ",
      "kkkk    I       ",
      "  kkk   I       ",
      "    kk  I       ",
      "     k  I       ",
      "     k  I       ",
      "     k  I       ",
      "     k  έ       "
    ]
  ]
}