{
  "xsize": 16,
  "zsize": 16,
  "palette": {
    "palette": [
      {
        "char": " ",
        "block": "minecraft:air"
      },
      {
        "char": "p",
        "block": "minecraft:vine[east=false,north=true,south=false,up=false,west=false]"
      },
      {
        "char": "΅",
        "block": "minecraft:vine[east=true,north=true,south=false,up=false,west=false]"
      },
      {
        "char": "h",
        "block": "minecraft:cracked_stone_bricks"
      },
      {
        "char": "i",
        "block": "minecraft:mossy_stone_bricks"
      },
      {
        "char": "a",
        "block": "minecraft:stone_bricks[weathering=false]"
      },
      {
        "char": "r",
        "block": "minecraft:vine[east=true,north=false,south=false,up=false,west=false]"
      },
      {
        "char": "l",
        "block": "minecraft:vine[east=false,north=false,south=true,up=false,west=false]"
      },
      {
        "char": "Έ",
        "block": "minecraft:vine[east=false,north=false,south=true,up=false,west=true]"
      },
      {
        "char": "Α",
        "block": "minecraft:vine[east=true,north=false,south=true,up=false,west=false]"
      },
      {
        "char": "t",
        "block": "minecraft:smooth_stone_slab[type=top,waterlogged=false]"
      },
      {
        "char": "g",
        "block": "minecraft:basalt[axis=x]"
      },
      {
        "char": "b",
        "block": "minecraft:cyan_terracotta"
      },
      {
        "char": "c",
        "block": "minecraft:deepslate[axis=y]"
      },
      {
        "char": "e",
        "block": "minecraft:cobbled_deepslate"
      },
      {
        "char": "ͳ",
        "block": "minecraft:daylight_detector[inverted=false,power=0]",
        "tag": {
          "z": 337,
          "x": 75,
          "ForgeCaps": {},
          "id": "minecraft:daylight_detector",
          "y": 145
        }
      },
      {
        "char": "q",
        "block": "minecraft:smooth_stone_slab[type=bottom,waterlogged=false]"
      },
      {
        "char": "k",
        "block": "minecraft:mossy_cobblestone"
      },
      {
        "char": "n",
        "block": "minecraft:cobblestone[weathering=false]"
      },
      {
        "char": "f",
        "block": "minecraft:blackstone"
      },
      {
        "char": "m",
        "block": "minecraft:grass_block[snowy=false]"
      },
      {
        "char": "s",
        "block": "minecraft:air"
      }
    ]
  },
  "slices": [
    [
      "p΅hhihahihahi   ",
      "  ΅iaiihhaiii   ",
      "   ΅haaiahiia   ",
      "   rahaahhihi   ",
      "ll rihahahiia   ",
      "hhΈΑhhhhaiiii   ",
      "hhiihaahiiiih   ",
      "hiahaiahahiai   ",
      "ahiiiaihhhhhi   ",
      "hhaahihahihii   ",
      "haihhahaiiiha   ",
      "aiiihiiahhhhh   ",
      "hihiihhhhahha   ",
      "ttttttttttgbt   ",
      "tttttttttciie   ",
      "tttttttttbiag   "
    ],
    [
      "           ͳq   ",
      "           ͳq   ",
      "           ͳq   ",
      "           ͳq   ",
      "     q     ͳq   ",
      "           ͳq   ",
      "           ͳq   ",
      "   q       ͳq   ",
      "     q     ͳq   ",
      "           ͳq   ",
      "q          ͳq   ",
      "           ͳq   ",
      "qqqqqqqqqqqqq   ",
      "knknnngkkkbgb   ",
      "kkkkkbkkkkkek   ",
      "enfngkgnkgcnn   "
    ],
    [
      "                ",
      "                ",
      "                ",
      "                ",
      "                ",
      "                ",
      "                ",
      "                ",
      "                ",
      "                ",
      "                ",
      "                ",
      "                ",
      "    l  lΑ       ",
      "hiihhiiaihhhi   ",
      "aaahhhii  iia   "
    ],
    [
      "                ",
      "                ",
      "                ",
      "                ",
      "                ",
      "                ",
      "                ",
      "                ",
      "                ",
      "                ",
      "                ",
      "                ",
      "                ",
      "    l  lΑ   e   ",
      "ahaiiih iihhn   ",
      "hahhhhh  hhan   "
    ],
    [
      "                ",
      "                ",
      "                ",
      "                ",
      "                ",
      "                ",
      "                ",
      "                ",
      "                ",
      "                ",
      "                ",
      "                ",
      "                ",
      "    l  lΑ  n    ",
      "hiahiih hahk    ",
      "hhiiahi  iam    "
    ],
    [
      "                ",
      "                ",
      "                ",
      "                ",
      "                ",
      "                ",
      "                ",
      "                ",
      "                ",
      "                ",
      "                ",
      "                ",
      "                ",
      "    l  lΑ n     ",
      "iihihiiiiin     ",
      "haiiihhihhms    "
    ]
  ]
}