{
  "xsize": 16,
  "zsize": 16,
  "palette": {
    "palette": [
      {
        "char": " ",
        "block": "minecraft:air"
      },
      {
        "char": "d",
        "block": "minecraft:air"
      },
      {
        "char": "f",
        "block": "minecraft:air"
      },
      {
        "char": "e",
        "block": "minecraft:air"
      },
      {
        "char": "m",
        "block": "minecraft:air"
      },
      {
        "char": "g",
        "block": "minecraft:air"
      },
      {
        "char": "b",
        "block": "minecraft:air"
      },
      {
        "char": "c",
        "block": "minecraft:air"
      },
      {
        "char": "ή",
        "block": "minecraft:air",
        "tag": {
          "SpawnData": {
            "entity": {}
          },
          "MaxNearbyEntities": "6s",
          "MinSpawnDelay": "200s",
          "z": 349,
          "x": 54,
          "MaxSpawnDelay": "800s",
          "RequiredPlayerRange": "16s",
          "SpawnCount": "4s",
          "ForgeCaps": {},
          "id": "minecraft:mob_spawner",
          "SpawnPotentials": [],
          "y": 136,
          "SpawnRange": "4s",
          "Delay": "181s"
        }
      },
      {
        "char": "Ά",
        "block": "minecraft:air"
      },
      {
        "char": "y",
        "block": "minecraft:air"
      },
      {
        "char": ";",
        "block": "minecraft:air"
      },
      {
        "char": "a",
        "block": "minecraft:air"
      },
      {
        "char": "Β",
        "block": "minecraft:air"
      },
      {
        "char": "h",
        "block": "minecraft:air"
      },
      {
        "char": "s",
        "block": "minecraft:grass"
      },
      {
        "char": "р",
        "block": "minecraft:air"
      },
      {
        "char": "Ї",
        "block": "minecraft:air"
      },
      {
        "char": "i",
        "block": "minecraft:air"
      },
      {
        "char": "Ё",
        "block": "minecraft:air"
      },
      {
        "char": "ΐ",
        "block": "minecraft:air"
      },
      {
        "char": "v",
        "block": "minecraft:air"
      },
      {
        "char": "w",
        "block": "minecraft:air"
      },
      {
        "char": "x",
        "block": "minecraft:air"
      },
      {
        "char": "k",
        "block": "minecraft:air"
      },
      {
        "char": "ϐ",
        "block": "minecraft:air"
      },
      {
        "char": "ύ",
        "block": "minecraft:air"
      },
      {
        "char": "Н",
        "block": "minecraft:air"
      },
      {
        "char": "ο",
        "block": "minecraft:air"
      },
      {
        "char": "Њ",
        "block": "minecraft:air"
      },
      {
        "char": "ϒ",
        "block": "minecraft:air"
      },
      {
        "char": "Ε",
        "block": "minecraft:air"
      },
      {
        "char": "p",
        "block": "minecraft:air"
      },
      {
        "char": "Ο",
        "block": "minecraft:air"
      },
      {
        "char": "Π",
        "block": "minecraft:air"
      },
      {
        "char": "Τ",
        "block": "minecraft:air"
      }
    ]
  },
  "slices": [
    [
      "dffddddddddddddd",
      "dfeddddddddddddd",
      "dmgddddddddddddd",
      "dbgdmmmmmmmmmmmm",
      "demdmmmmmmmmmmmm",
      "dcbdmdmmmmmmmmmm",
      "dfbddmmmdmmmmmmm",
      "dήmddddddddddddd",
      "dcgddddddddddddd",
      "ebmddddddddddddd",
      "Άmy;Άyyyyym;;Ά;;",
      ";;yy;Άy;yy;Ά;Άy;",
      "ΆmΆym;yΆΆ;;yyyyy",
      "beffcmmffccbbbmf",
      "mbfcbgccgcbeeggb",
      "efcgffcecbefbmgb"
    ],
    [
      "a  cffbcgcecgcef",
      "a  fgcebgfefcgbe",
      "a Βegedbbfcbebeg",
      "a Βh   s     ss ",
      "a shss р s    s ",
      "aЇ is s   sss   ",
      "aЁ i s      ss  ",
      "aΐsibgeebffcffdb",
      "a  eegcfcbeffcmf",
      "v swwwwwwxwxxwxx",
      "ks        s ϐ   ",
      "   ϐ ύ          ",
      "ΐs ύs        Н  ",
      "     ss         ",
      "s               ",
      "             s  "
    ],
    [
      "a  ebccdcfbfcccd",
      "a  edcdedbgccbff",
      "a οbbfefegbffgbc",
      "a οi            ",
      "a  h            ",
      "a  ibcebccccgc c",
      "Њϒ fbeegmgebeceb",
      "v  xwwxwwwwxwxxw",
      "Ε               ",
      "                ",
      "                ",
      "                ",
      "                ",
      "                ",
      "                ",
      "                "
    ],
    [
      "a  eecbcgcdedgge",
      "a  efeebebcgbgdg",
      "a  ecbbefeefccee",
      "a  gbcccbggdcfbb",
      "a  ggbbbcbfefbmg",
      "Ε  wwwxwwxxxwwxx",
      "        s       ",
      "                ",
      "                ",
      "                ",
      "                ",
      "                ",
      "                ",
      "                ",
      "                ",
      "                "
    ],
    [
      "a  ebdmbfgfcfbcc",
      "a  ggeeecggegmmf",
      "a  mmbbbfbmecceg",
      "Ε  xxwxwxwwxxwxx",
      "              s ",
      "                ",
      "                ",
      "                ",
      "                ",
      "                ",
      "                ",
      "                ",
      "                ",
      "                ",
      "                ",
      "                "
    ],
    [
      "v   ecs         ",
      "v    ppp   ppss ",
      "Ε  ssΟΠΤ ΟΠΤ ΟΠΤ",
      "                ",
      "                ",
      "                ",
      "                ",
      "                ",
      "                ",
      "                ",
      "                ",
      "                ",
      "                ",
      "                ",
      "                ",
      "                "
    ]
  ]
}