{
  "xsize": 16,
  "zsize": 16,
  "palette": {
    "palette": [
      {
        "char": " ",
        "block": "minecraft:air"
      },
      {
        "char": "p",
        "block": "minecraft:air"
      },
      {
        "char": "΅",
        "block": "minecraft:air"
      },
      {
        "char": "h",
        "block": "minecraft:air"
      },
      {
        "char": "i",
        "block": "minecraft:air"
      },
      {
        "char": "a",
        "block": "minecraft:air"
      },
      {
        "char": "r",
        "block": "minecraft:air"
      },
      {
        "char": "l",
        "block": "minecraft:air"
      },
      {
        "char": "Έ",
        "block": "minecraft:air"
      },
      {
        "char": "Α",
        "block": "minecraft:air"
      },
      {
        "char": "t",
        "block": "minecraft:air"
      },
      {
        "char": "g",
        "block": "minecraft:air"
      },
      {
        "char": "b",
        "block": "minecraft:air"
      },
      {
        "char": "c",
        "block": "minecraft:air"
      },
      {
        "char": "e",
        "block": "minecraft:air"
      },
      {
        "char": "ͳ",
        "block": "minecraft:air",
        "tag": {
          "z": 337,
          "x": 75,
          "ForgeCaps": {},
          "id": "minecraft:daylight_detector",
          "y": 145
        }
      },
      {
        "char": "q",
        "block": "minecraft:air"
      },
      {
        "char": "k",
        "block": "minecraft:air"
      },
      {
        "char": "n",
        "block": "minecraft:air"
      },
      {
        "char": "f",
        "block": "minecraft:air"
      },
      {
        "char": "m",
        "block": "minecraft:air"
      },
      {
        "char": "s",
        "block": "minecraft:grass"
      }
    ]
  },
  "slices": [
    [
      "p΅hhihahihahi   ",
      "  ΅iaiihhaiii   ",
      "   ΅haaiahiia   ",
      "   rahaahhihi   ",
      "ll rihahahiia   ",
      "hhΈΑhhhhaiiii   ",
      "hhiihaahiiiih   ",
      "hiahaiahahiai   ",
      "ahiiiaihhhhhi   ",
      "hhaahihahihii   ",
      "haihhahaiiiha   ",
      "aiiihiiahhhhh   ",
      "hihiihhhhahha   ",
      "ttttttttttgbt   ",
      "tttttttttciie   ",
      "tttttttttbiag   "
    ],
    [
      "           ͳq   ",
      "           ͳq   ",
      "           ͳq   ",
      "           ͳq   ",
      "     q     ͳq   ",
      "           ͳq   ",
      "           ͳq   ",
      "   q       ͳq   ",
      "     q     ͳq   ",
      "           ͳq   ",
      "q          ͳq   ",
      "           ͳq   ",
      "qqqqqqqqqqqqq   ",
      "knknnngkkkbgb   ",
      "kkkkkbkkkkkek   ",
      "enfngkgnkgcnn   "
    ],
    [
      "                ",
      "                ",
      "                ",
      "                ",
      "                ",
      "                ",
      "                ",
      "                ",
      "                ",
      "                ",
      "                ",
      "                ",
      "                ",
      "    l  lΑ       ",
      "hiihhiiaihhhi   ",
      "aaahhhii  iia   "
    ],
    [
      "                ",
      "                ",
      "                ",
      "                ",
      "                ",
      "                ",
      "                ",
      "                ",
      "                ",
      "                ",
      "                ",
      "                ",
      "                ",
      "    l  lΑ   e   ",
      "ahaiiih iihhn   ",
      "hahhhhh  hhan   "
    ],
    [
      "                ",
      "                ",
      "                ",
      "                ",
      "                ",
      "                ",
      "                ",
      "                ",
      "                ",
      "                ",
      "                ",
      "                ",
      "                ",
      "    l  lΑ  n    ",
      "hiahiih hahk    ",
      "hhiiahi  iam    "
    ],
    [
      "                ",
      "                ",
      "                ",
      "                ",
      "                ",
      "                ",
      "                ",
      "                ",
      "                ",
      "                ",
      "                ",
      "                ",
      "                ",
      "    l  lΑ n     ",
      "iihihiiiiin     ",
      "haiiihhihhms    "
    ]
  ]
}