{
  "xsize": 16,
  "zsize": 16,
  "palette": {
    "palette": [
      {
        "char": " ",
        "block": "minecraft:structure_void"
      },
      {
        "char": "c",
        "block": "minecraft:dirt"
      },
      {
        "char": "F",
        "block": "minecraft:stone_brick_stairs[facing=north,half=bottom,shape=straight,waterlogged=false,weathering=true]"
      },
      {
        "char": "h",
        "block": "minecraft:stone_brick_stairs[facing=north,half=bottom,shape=straight,waterlogged=false,weathering=false]"
      },
      {
        "char": "o",
        "block": "minecraft:stone[weathering=false]"
      },
      {
        "char": "B",
        "block": "minecraft:mossy_stone_brick_stairs[facing=north,half=bottom,shape=straight,waterlogged=false]"
      },
      {
        "char": "l",
        "block": "minecraft:stone_brick_slab[type=bottom,waterlogged=false,weathering=false]"
      },
      {
        "char": "n",
        "block": "minecraft:smooth_stone_slab[type=bottom,waterlogged=false]"
      },
      {
        "char": "u",
        "block": "minecraft:polished_andesite_stairs[facing=south,half=bottom,shape=straight,waterlogged=false]"
      },
      {
        "char": "i",
        "block": "minecraft:stone_brick_stairs[facing=south,half=bottom,shape=straight,waterlogged=false,weathering=false]"
      },
      {
        "char": "z",
        "block": "minecraft:redstone_block"
      },
      {
        "char": "q",
        "block": "minecraft:quartz_pillar[axis=x]"
      },
      {
        "char": "v",
        "block": "minecraft:polished_andesite_stairs[facing=north,half=bottom,shape=straight,waterlogged=false]"
      },
      {
        "char": "C",
        "block": "minecraft:stone_brick_slab[type=bottom,waterlogged=false,weathering=true]"
      },
      {
        "char": "y",
        "block": "minecraft:mossy_stone_brick_stairs[facing=south,half=bottom,shape=straight,waterlogged=false]"
      },
      {
        "char": "E",
        "block": "minecraft:air"
      },
      {
        "char": "a",
        "block": "minecraft:quartz_pillar[axis=y]"
      },
      {
        "char": "j",
        "block": "minecraft:mossy_stone_bricks"
      },
      {
        "char": "b",
        "block": "minecraft:stone_bricks[weathering=false]"
      },
      {
        "char": "f",
        "block": "minecraft:vine[east=false,north=true,south=false,up=false,west=false]"
      },
      {
        "char": "k",
        "block": "minecraft:rail[shape=east_west,waterlogged=false]"
      },
      {
        "char": "g",
        "block": "minecraft:vine[east=false,north=false,south=true,up=false,west=false]"
      },
      {
        "char": "d",
        "block": "minecraft:stone_brick_stairs[facing=north,half=top,shape=straight,waterlogged=false,weathering=false]"
      },
      {
        "char": "e",
        "block": "minecraft:stone_brick_stairs[facing=south,half=top,shape=straight,waterlogged=false,weathering=false]"
      },
      {
        "char": "t",
        "block": "minecraft:smooth_quartz_stairs[facing=north,half=top,shape=straight,waterlogged=false]"
      },
      {
        "char": "w",
        "block": "minecraft:mossy_stone_brick_stairs[facing=north,half=top,shape=straight,waterlogged=false]"
      },
      {
        "char": "m",
        "block": "minecraft:vine[east=false,north=false,south=false,up=true,west=false]"
      },
      {
        "char": "r",
        "block": "minecraft:smooth_quartz_stairs[facing=south,half=top,shape=straight,waterlogged=false]"
      },
      {
        "char": "x",
        "block": "minecraft:mossy_stone_brick_stairs[facing=south,half=top,shape=straight,waterlogged=false]"
      },
      {
        "char": "D",
        "block": "minecraft:stone_bricks[weathering=true]"
      },
      {
        "char": "s",
        "block": "minecraft:quartz_pillar[axis=z]"
      },
      {
        "char": "A",
        "block": "minecraft:smooth_quartz_slab[type=top,waterlogged=false]"
      },
      {
        "char": "p",
        "block": "minecraft:stone_brick_slab[type=top,waterlogged=false,weathering=false]"
      }
    ]
  },
  "slices": [
    [
      "                ",
      "                ",
      "                ",
      "                ",
      "cccccccccccccccc",
      "FhoBohoBoBohoBoh",
      "llnlnlnlnlnlnlnl",
      "uuiuiuiuiuiuiuiu",
      "zqqzqqqzqqqzqqqz",
      "vvhvhvhvhvhvhvhv",
      "CCnlnlnlnlnlnlnl",
      "yyoioyoyEioyoyoi",
      "cccccccccccccccc",
      "                ",
      "                ",
      "                "
    ],
    [
      "                ",
      "                ",
      "                ",
      "                ",
      "ahhahjhahbBahjha",
      "f  f f f f f f f",
      "                ",
      "                ",
      "kkkkkkkkkkkkkkkk",
      "                ",
      "                ",
      "g  g g g g g g g",
      "aiiaibiaijiaibia",
      "                ",
      "                ",
      "                "
    ],
    [
      "                ",
      "                ",
      "                ",
      "                ",
      "addadjdadjdadjda",
      "f  f f f f f f f",
      "                ",
      "                ",
      "                ",
      "                ",
      "                ",
      "g  g g g   g g g",
      "aeeaejeaebeaejea",
      "                ",
      "                ",
      "                "
    ],
    [
      "                ",
      "                ",
      "                ",
      "                ",
      "ahhahbhahjhahbha",
      "f  f f f f f   f",
      "                ",
      "                ",
      "                ",
      "                ",
      "                ",
      "g  g g g   g   g",
      "aiiaijiaibiaibia",
      "                ",
      "                ",
      "                "
    ],
    [
      "                ",
      "                ",
      "                ",
      "                ",
      "addadbdadbdadbda",
      "f  f f f   f   f",
      "                ",
      "                ",
      "                ",
      "                ",
      "                ",
      "g  g g g   g   g",
      "aeeaebeaebeaebea",
      "                ",
      "                ",
      "                "
    ],
    [
      "                ",
      "                ",
      "                ",
      "                ",
      "abbabbbabbbabbba",
      "twwtdwwtwddtdwdt",
      " m  m m m  m m  ",
      "                ",
      "                ",
      "                ",
      "mm  mm m m  m mm",
      "rxerxxxrxxerexer",
      "aDDabbbabbbabbba",
      "                ",
      "                ",
      "                "
    ],
    [
      "                ",
      "                ",
      "                ",
      "                ",
      "                ",
      "                ",
      "sjbsjbjsjjbsbbbs",
      "tddtdddtwwdtdddt",
      "AppApppApppApppA",
      "reerxeereeereeer",
      "sjbsbjbsbbbsbbjs",
      "                ",
      "                ",
      "                ",
      "                ",
      "                "
    ]
  ]
}