{
  "xsize": 16,
  "zsize": 16,
  "palette": {
    "palette": [
      {
        "char": " ",
        "block": "minecraft:structure_void"
      },
      {
        "char": "g",
        "block": "minecraft:stone_brick_stairs[facing=north,half=bottom,shape=straight,waterlogged=false,weathering=false]"
      },
      {
        "char": "t",
        "block": "minecraft:stone[weathering=false]"
      },
      {
        "char": "u",
        "block": "minecraft:mossy_stone_brick_stairs[facing=north,half=bottom,shape=straight,waterlogged=false]"
      },
      {
        "char": "v",
        "block": "minecraft:stone[weathering=true]"
      },
      {
        "char": "C",
        "block": "minecraft:air"
      },
      {
        "char": "j",
        "block": "minecraft:stone_brick_slab[type=bottom,waterlogged=false,weathering=false]"
      },
      {
        "char": "i",
        "block": "minecraft:smooth_stone_slab[type=bottom,waterlogged=false]"
      },
      {
        "char": "y",
        "block": "minecraft:stone_brick_slab[type=bottom,waterlogged=false,weathering=true]"
      },
      {
        "char": "q",
        "block": "minecraft:polished_andesite_stairs[facing=south,half=bottom,shape=straight,waterlogged=false]"
      },
      {
        "char": "e",
        "block": "minecraft:stone_brick_stairs[facing=south,half=bottom,shape=straight,waterlogged=false,weathering=false]"
      },
      {
        "char": "z",
        "block": "minecraft:redstone_block"
      },
      {
        "char": "l",
        "block": "minecraft:quartz_pillar[axis=x]"
      },
      {
        "char": "p",
        "block": "minecraft:polished_andesite_stairs[facing=north,half=bottom,shape=straight,waterlogged=false]"
      },
      {
        "char": "w",
        "block": "minecraft:mossy_stone_brick_stairs[facing=south,half=bottom,shape=straight,waterlogged=false]"
      },
      {
        "char": "b",
        "block": "minecraft:quartz_pillar[axis=y]"
      },
      {
        "char": "c",
        "block": "minecraft:stone_bricks[weathering=false]"
      },
      {
        "char": "n",
        "block": "minecraft:mossy_stone_bricks"
      },
      {
        "char": "k",
        "block": "minecraft:stone_bricks[weathering=true]"
      },
      {
        "char": "D",
        "block": "minecraft:stone_brick_stairs[facing=north,half=bottom,shape=straight,waterlogged=false,weathering=true]"
      },
      {
        "char": "h",
        "block": "minecraft:rail[shape=east_west,waterlogged=false]"
      },
      {
        "char": "B",
        "block": "minecraft:stone_brick_stairs[facing=south,half=bottom,shape=straight,waterlogged=false,weathering=true]"
      },
      {
        "char": "a",
        "block": "minecraft:white_stained_glass"
      },
      {
        "char": "f",
        "block": "minecraft:stone_brick_stairs[facing=north,half=top,shape=straight,waterlogged=false,weathering=false]"
      },
      {
        "char": "x",
        "block": "minecraft:stone_brick_stairs[facing=north,half=top,shape=straight,waterlogged=false,weathering=true]"
      },
      {
        "char": "d",
        "block": "minecraft:stone_brick_stairs[facing=south,half=top,shape=straight,waterlogged=false,weathering=false]"
      },
      {
        "char": "m",
        "block": "minecraft:smooth_quartz_stairs[facing=north,half=top,shape=straight,waterlogged=false]"
      },
      {
        "char": "r",
        "block": "minecraft:mossy_stone_brick_stairs[facing=north,half=top,shape=straight,waterlogged=false]"
      },
      {
        "char": "o",
        "block": "minecraft:smooth_quartz_stairs[facing=south,half=top,shape=straight,waterlogged=false]"
      },
      {
        "char": "A",
        "block": "minecraft:stone_brick_stairs[facing=south,half=top,shape=straight,waterlogged=false,weathering=true]"
      },
      {
        "char": "s",
        "block": "minecraft:mossy_stone_brick_stairs[facing=south,half=top,shape=straight,waterlogged=false]"
      }
    ]
  },
  "slices": [
    [
      "                ",
      "                ",
      "                ",
      "                ",
      "                ",
      "gtuvutgCututgtuu",
      "jijiyijijijijijy",
      "qeqeqeqeqeqeqeqq",
      "zlllzlllzlllzllz",
      "pgpgpgpgpgpgpgpp",
      "yijiyijijijijiyj",
      "evwtevwvwvevwtee",
      "                ",
      "                ",
      "                ",
      "                "
    ],
    [
      "                ",
      "                ",
      "                ",
      "                ",
      "bgcgbgngbgkgbgDb",
      "                ",
      "                ",
      "                ",
      "hhhhhhhhhhhhhhhh",
      "                ",
      "                ",
      "                ",
      "bBnBbwcebenebeeb",
      "                ",
      "                ",
      "                "
    ],
    [
      "                ",
      "                ",
      "                ",
      "                ",
      "banabacabanabaab",
      "                ",
      "                ",
      "                ",
      "                ",
      "                ",
      "                ",
      "                ",
      "banabanabanabaab",
      "                ",
      "                ",
      "                "
    ],
    [
      "                ",
      "                ",
      "                ",
      "                ",
      "bacabakabanabaab",
      "                ",
      "                ",
      "                ",
      "                ",
      "                ",
      "                ",
      "                ",
      "bakabanabakabaab",
      "                ",
      "                ",
      "                "
    ],
    [
      "                ",
      "                ",
      "                ",
      "                ",
      "bfcxbfcfbxcxbffb",
      "                ",
      "                ",
      "                ",
      "                ",
      "                ",
      "                ",
      "                ",
      "bdcdbdkdbdcdbddb",
      "                ",
      "                ",
      "                "
    ],
    [
      "                ",
      "                ",
      "                ",
      "                ",
      "bcccbkckbkkcbccb",
      "mfrxmxrrmrrrmfrm",
      "                ",
      "                ",
      "                ",
      "                ",
      "                ",
      "oAsdoAdsossdosso",
      "bcckbcccbkccbckb",
      "                ",
      "                ",
      "                "
    ],
    [
      "                ",
      "                ",
      "                ",
      "                ",
      "                ",
      "                ",
      "aaaaaaaaaaaaaaaa",
      "mfffmfffmffrmffm",
      "aaaaaaaaaaaaaaaa",
      "odddodssodddoddo",
      "aaaaaaaaaaaaaaaa",
      "                ",
      "                ",
      "                ",
      "                ",
      "                "
    ]
  ]
}