{
  "xsize": 16,
  "zsize": 16,
  "palette": {
    "palette": [
      {
        "char": " ",
        "block": "minecraft:air"
      },
      {
        "char": "a",
        "block": "minecraft:air"
      },
      {
        "char": "x",
        "block": "minecraft:air"
      },
      {
        "char": "b",
        "block": "minecraft:grass"
      },
      {
        "char": "p",
        "block": "minecraft:tall_grass[half=lower]"
      },
      {
        "char": "e",
        "block": "minecraft:air"
      },
      {
        "char": "d",
        "block": "minecraft:air"
      },
      {
        "char": "A",
        "block": "minecraft:air"
      },
      {
        "char": "h",
        "block": "minecraft:air"
      },
      {
        "char": "Y",
        "block": "minecraft:air"
      },
      {
        "char": "L",
        "block": "minecraft:air"
      },
      {
        "char": "y",
        "block": "minecraft:air"
      },
      {
        "char": "i",
        "block": "minecraft:air"
      },
      {
        "char": "m",
        "block": "minecraft:air"
      },
      {
        "char": "c",
        "block": "minecraft:air"
      },
      {
        "char": "k",
        "block": "minecraft:air"
      },
      {
        "char": "0",
        "block": "minecraft:air"
      },
      {
        "char": "ρ",
        "block": "minecraft:air"
      },
      {
        "char": "o",
        "block": "minecraft:air"
      },
      {
        "char": "w",
        "block": "minecraft:air"
      },
      {
        "char": "ή",
        "block": "minecraft:air"
      },
      {
        "char": "ͱ",
        "block": "minecraft:air"
      },
      {
        "char": "G",
        "block": "minecraft:air"
      },
      {
        "char": "E",
        "block": "minecraft:air"
      },
      {
        "char": "n",
        "block": "minecraft:air"
      },
      {
        "char": "q",
        "block": "minecraft:air"
      },
      {
        "char": "z",
        "block": "minecraft:air"
      },
      {
        "char": "ͳ",
        "block": "minecraft:air"
      },
      {
        "char": "t",
        "block": "minecraft:air"
      },
      {
        "char": "f",
        "block": "minecraft:air"
      },
      {
        "char": "Ͱ",
        "block": "minecraft:air"
      }
    ]
  },
  "slices": [
    [
      "aaaaaaaaaaaaaaaa",
      "aaaaaaaaaaaaaaaa",
      "aaaaaaaxaaaaaaaa",
      "aaaaaaaxaaaaaaaa",
      "aaaaaaaaxaaaaaaa",
      "aaaaaaaaaaaaaaaa",
      "aaaaaaaaaaaaaaaa",
      "aaaaaaaaaaaaaaaa",
      "aaaaaaaaaaaaaaaa",
      "aaaaaaaaaaaaaaaa",
      "aaaaaaaaaaaaaaaa",
      "aaaaaaaaaaaaaaaa",
      "aaaaaaaaaaaaaaaa",
      "aaaaaaaaaaaaaaaa",
      "aaaaaaaaaaaaaaaa",
      "aaaaaaaaaaaaaaaa"
    ],
    [
      "bpbbbb  eddddddd",
      "bbbbbbbAeddddddd",
      "ppbb   hdddddddd",
      "bbbp   hdddddddd",
      "bbpbbbbYLeeeeeee",
      "bbbbbbb bbb bbyb",
      "bbbbb b   bbbbbb",
      "pbbp bb bbb  b  ",
      "bbbbbbb bbb  b b",
      "bbbbbbbbbbbbbbbb",
      "bbbbb bbbb  bbb ",
      "pbbpbbbbbbbb  bb",
      "ppbbbb b  bbbbbb",
      "bbpbbbbbbbbb b b",
      "bbbb bbbbb bbbbb",
      "bbpbbbbbbbbbbb b"
    ],
    [
      "        i mck   ",
      "        0 mck   ",
      "          mck  ρ",
      "          mccccc",
      "        Yowwwwww",
      "              y ",
      "                ",
      "                ",
      "                ",
      "                ",
      "                ",
      "                ",
      "                ",
      "                ",
      "                ",
      "                "
    ],
    [
      "          mck   ",
      "        A mck   ",
      "          mck  ή",
      "          mccͱͱͱ",
      "        A GwE   ",
      "              y ",
      "                ",
      "                ",
      "                ",
      "                ",
      "                ",
      "                ",
      "                ",
      "                ",
      "                ",
      "                "
    ],
    [
      "        nhkcq   ",
      "        nhkck   ",
      "        nhkck   ",
      "        nhkccccc",
      "        nzkwwͳͳͳ",
      "              y ",
      "                ",
      "                ",
      "                ",
      "                ",
      "                ",
      "                ",
      "                ",
      "                ",
      "                ",
      "                "
    ],
    [
      "        t hc fff",
      "        t hcqfff",
      "          hkffff",
      "          hccccc",
      "          zͰGwww",
      "              y ",
      "                ",
      "                ",
      "                ",
      "                ",
      "                ",
      "                ",
      "                ",
      "                ",
      "                ",
      "                "
    ]
  ]
}