{
  "xsize": 16,
  "zsize": 16,
  "palette": {
    "palette": [
      {
        "char": " ",
        "block": "minecraft:air"
      },
      {
        "char": "a",
        "block": "minecraft:air"
      },
      {
        "char": "x",
        "block": "minecraft:air"
      },
      {
        "char": "d",
        "block": "minecraft:air"
      },
      {
        "char": "e",
        "block": "minecraft:air"
      },
      {
        "char": "b",
        "block": "minecraft:grass"
      },
      {
        "char": "i",
        "block": "minecraft:air"
      },
      {
        "char": "c",
        "block": "minecraft:air"
      },
      {
        "char": "G",
        "block": "minecraft:air"
      },
      {
        "char": "o",
        "block": "minecraft:air"
      },
      {
        "char": "E",
        "block": "minecraft:air"
      },
      {
        "char": "ͼ",
        "block": "minecraft:air",
        "tag": {
          "z": 544,
          "x": 48,
          "CookTimeTotal": 0,
          "ForgeData": {
            "LockFlag": "1b"
          },
          "CookTime": 0,
          "ForgeCaps": {
            "polymorph:block_entity_recipe_data": {}
          },
          "id": "minecraft:furnace",
          "y": 134,
          "Items": [],
          "BurnTime": 0,
          "RecipesUsed": {}
        }
      },
      {
        "char": "g",
        "block": "minecraft:air"
      },
      {
        "char": "ω",
        "block": "minecraft:air"
      },
      {
        "char": "Ξ",
        "block": "minecraft:air"
      },
      {
        "char": "ΰ",
        "block": "minecraft:air",
        "tag": {
          "z": 546,
          "x": 48,
          "ForgeData": {
            "LockFlag": "1b"
          },
          "ForgeCaps": {},
          "id": "minecraft:dropper",
          "y": 134,
          "Items": []
        }
      },
      {
        "char": "l",
        "block": "minecraft:air"
      },
      {
        "char": "y",
        "block": "minecraft:air"
      },
      {
        "char": "w",
        "block": "minecraft:air"
      },
      {
        "char": "Ν",
        "block": "minecraft:air"
      },
      {
        "char": "J",
        "block": "minecraft:air"
      },
      {
        "char": "3",
        "block": "minecraft:air",
        "loot": "bigbuildingsloot",
        "tag": {
          "z": 545,
          "x": 48,
          "ForgeData": {
            "LockFlag": "1b"
          },
          "ForgeCaps": {},
          "id": "minecraft:chest",
          "y": 136,
          "Items": []
        }
      },
      {
        "char": "6",
        "block": "minecraft:air",
        "loot": "bigbuildingsloot",
        "tag": {
          "z": 546,
          "x": 48,
          "ForgeData": {
            "LockFlag": "1b"
          },
          "ForgeCaps": {},
          "id": "minecraft:chest",
          "y": 136,
          "Items": []
        }
      },
      {
        "char": "k",
        "block": "minecraft:air"
      },
      {
        "char": "v",
        "block": "minecraft:air"
      },
      {
        "char": "j",
        "block": "minecraft:air"
      },
      {
        "char": "h",
        "block": "minecraft:air"
      },
      {
        "char": "͵",
        "block": "minecraft:air"
      }
    ]
  },
  "slices": [
    [
      "aaaaaaaaaaaaaaaa",
      "aaaaaaaaaaaaaaaa",
      "aaaaaaaaaaaaaaaa",
      "aaaaaaaaaaaaaaaa",
      "aaxaaaaaaaaaaaaa",
      "aaaaaaaaaaaaaaaa",
      "aaaaaaaaaaaaaaaa",
      "aaaaaaaaaaaaaaaa",
      "aaaaaaaaaaaaaaaa",
      "aaaaaaaaaaaaaaaa",
      "aaaaaaaaaaaaaaaa",
      "aaaaaaaaaaaaaaaa",
      "aaaaaaaaaaaaaaaa",
      "aaaaaaaaaaaaaaaa",
      "aaaaaaaaaaaaaaaa",
      "aaaaaaaaaaaaaaaa"
    ],
    [
      "ddebbbb   bbibbb",
      "dde  bbbbbbbibbb",
      "ddebb   b bbibbb",
      "ddebbbbbbb bibbb",
      "eecbbbbb bbbib  ",
      " bi   bbbb  ibb ",
      "b ib b b bb i  b",
      "bbibbbbbbb bibbb",
      "bbibbbb bbbbib b",
      "b ib  b     ibbb",
      " bGoooooooooEbbb",
      "bb bb bbbbbbb bb",
      "  b  b b    b bb",
      "bbb b bbbb bbbbb",
      "b b b  b b  bb b",
      "b bb b bbbbbbbbb"
    ],
    [
      "ͼcg             ",
      "ωcΞ             ",
      "ΰcg l           ",
      "ccgy            ",
      "wwE             ",
      "                ",
      "                ",
      "                ",
      "                ",
      "                ",
      "                ",
      "                ",
      "                ",
      "                ",
      "                ",
      "                "
    ],
    [
      " cg             ",
      " cg             ",
      "Νcg l           ",
      "ccgy            ",
      "GwE             ",
      "                ",
      "                ",
      "                ",
      "                ",
      "                ",
      "                ",
      "                ",
      "                ",
      "                ",
      "                ",
      "                "
    ],
    [
      "Jcg             ",
      "3cg             ",
      "6cg l           ",
      "ccgy            ",
      "wwE             ",
      "                ",
      "                ",
      "                ",
      "                ",
      "                ",
      "                ",
      "                ",
      "                ",
      "                ",
      "                ",
      "                "
    ],
    [
      " kvj            ",
      "hkv             ",
      "hkv l           ",
      "ccvy            ",
      "E͵v             ",
      "                ",
      "                ",
      "                ",
      "                ",
      "                ",
      "                ",
      "                ",
      "                ",
      "                ",
      "                ",
      "                "
    ]
  ]
}