{
  "xsize": 16,
  "zsize": 16,
  "palette": {
    "palette": [
      {
        "char": " ",
        "block": "minecraft:air"
      },
      {
        "char": "a",
        "block": "minecraft:air"
      },
      {
        "char": "N",
        "block": "minecraft:air"
      },
      {
        "char": "I",
        "block": "minecraft:air"
      },
      {
        "char": "x",
        "block": "minecraft:air"
      },
      {
        "char": "b",
        "block": "minecraft:grass"
      },
      {
        "char": "p",
        "block": "minecraft:tall_grass[half=lower]"
      },
      {
        "char": "L",
        "block": "minecraft:air"
      },
      {
        "char": "e",
        "block": "minecraft:air"
      },
      {
        "char": "d",
        "block": "minecraft:air"
      },
      {
        "char": "z",
        "block": "minecraft:air"
      },
      {
        "char": "j",
        "block": "minecraft:air"
      },
      {
        "char": "F",
        "block": "minecraft:air"
      },
      {
        "char": "o",
        "block": "minecraft:air"
      },
      {
        "char": "i",
        "block": "minecraft:air"
      },
      {
        "char": "ε",
        "block": "minecraft:air"
      },
      {
        "char": "Α",
        "block": "minecraft:air"
      },
      {
        "char": "E",
        "block": "minecraft:air"
      },
      {
        "char": "A",
        "block": "minecraft:air"
      },
      {
        "char": "8",
        "block": "minecraft:air"
      },
      {
        "char": "r",
        "block": "minecraft:air"
      },
      {
        "char": "m",
        "block": "minecraft:air"
      },
      {
        "char": "c",
        "block": "minecraft:air"
      },
      {
        "char": "t",
        "block": "minecraft:air"
      },
      {
        "char": "π",
        "block": "minecraft:air"
      },
      {
        "char": "G",
        "block": "minecraft:air"
      },
      {
        "char": "T",
        "block": "minecraft:air"
      },
      {
        "char": "ώ",
        "block": "minecraft:air"
      },
      {
        "char": "y",
        "block": "minecraft:air"
      },
      {
        "char": "ζ",
        "block": "minecraft:air"
      },
      {
        "char": "q",
        "block": "minecraft:air"
      },
      {
        "char": "k",
        "block": "minecraft:air"
      },
      {
        "char": "7",
        "block": "minecraft:air"
      },
      {
        "char": "ι",
        "block": "minecraft:air"
      },
      {
        "char": "Υ",
        "block": "minecraft:air"
      },
      {
        "char": "n",
        "block": "minecraft:air"
      },
      {
        "char": "H",
        "block": "minecraft:air"
      },
      {
        "char": "h",
        "block": "minecraft:air"
      },
      {
        "char": "Ϋ",
        "block": "minecraft:air"
      },
      {
        "char": "s",
        "block": "minecraft:air"
      },
      {
        "char": "f",
        "block": "minecraft:air"
      },
      {
        "char": "J",
        "block": "minecraft:air"
      },
      {
        "char": "μ",
        "block": "minecraft:air"
      }
    ]
  },
  "slices": [
    [
      "aaNIaaINaaaaaaaa",
      "aaIaNINIaaaaaaaa",
      "aaaNaaaaaaaaaaaa",
      "aaaaaaaaaaxaaaaa",
      "aaaaaaaaaaaaaaaa",
      "aaaaaaaxxxaaaaaa",
      "aaaaaaaxaaaaaaaa",
      "aaaaaaaxaaaaaaaa",
      "aaaaaaaxaaaaaaaa",
      "aaaaaaaaaaaaaaaa",
      "aaaaaaaaaaaaaaaa",
      "aaaaaaaaaaaaaaaa",
      "aaaaaaaaaaaaaaaa",
      "aaaaaaaaaaaaaaaa",
      "aaaaaaaaaaaaaaaa",
      "aaaaaaaaaaaaaaaa"
    ],
    [
      "bp   b  bb  bb b",
      "bb b    bbbbbbbb",
      "bbb  bb  bbbb bb",
      "bbb  bbbbbLeeeee",
      "bbpb      eddddd",
      "bbbp bbzLLeddddd",
      "pbbb   zdddddddd",
      "bbbb   zdddddddd",
      "pbbbbbbzeddddddd",
      "bbppbbbbeddddddd",
      "bbbbbbbbeddddddd",
      "bbpbbbbbeddddddd",
      "bbbb bbjeddddddd",
      "bbbbbbbbeddddddd",
      "bbbb bbbeddddddd",
      "bbbbbbbbeddddddd"
    ],
    [
      "                ",
      "                ",
      "                ",
      "          Fooooo",
      "          i     ",
      "        εΑE A   ",
      "                ",
      "                ",
      "        8 Frrrrr",
      "        i mccccc",
      "      tπi Gc   T",
      "      tji  ώ    ",
      "       yi  ζ    ",
      "        i Fc    ",
      "        i mcq   ",
      "        i mck   "
    ],
    [
      "                ",
      "                ",
      "                ",
      "          A   A ",
      "                ",
      "          A A   ",
      "                ",
      "                ",
      "        A Frrrrr",
      "          mccccc",
      "      tj  Gc    ",
      "       7A  ι    ",
      "           Υ    ",
      "          Fc    ",
      "        A mc    ",
      "          mcq   "
    ],
    [
      "                ",
      "                ",
      "                ",
      "          ne  A ",
      "          nd    ",
      "          ndA   ",
      "          nd    ",
      "          nd    ",
      "        nzLedFrH",
      "        nhkccccc",
      "        nhkc   d",
      "       jnhkc    ",
      "        nhkc    ",
      "        nhkc    ",
      "        nhkc    ",
      "        nhkc    "
    ],
    [
      "       Ϋ        ",
      "                ",
      "                ",
      "            neAe",
      "            sd d",
      "            sd d",
      "            sd d",
      "            sd d",
      "          zHneke",
      "          hcfcfc",
      "          h Jfff",
      "       tj hkffff",
      "        μjhkffff",
      "          hccfff",
      "        t hc fff",
      "         yhc fff"
    ]
  ]
}