{
  "xsize": 16,
  "zsize": 16,
  "palette": {
    "palette": [
      {
        "char": " ",
        "block": "minecraft:air"
      },
      {
        "char": "a",
        "block": "minecraft:polished_andesite_slab[type=top,waterlogged=false]"
      },
      {
        "char": "Ύ",
        "block": "minecraft:note_block[instrument=harp,note=0,powered=false]"
      },
      {
        "char": "Ά",
        "block": "minecraft:polished_andesite_slab[type=double,waterlogged=false]"
      },
      {
        "char": "з",
        "block": "minecraft:note_block[instrument=harp,note=1,powered=false]"
      },
      {
        "char": "h",
        "block": "minecraft:bricks[weathering=false]"
      },
      {
        "char": "q",
        "block": "minecraft:granite"
      },
      {
        "char": "w",
        "block": "minecraft:terracotta"
      },
      {
        "char": "Ν",
        "block": "minecraft:vine[east=false,north=true,south=false,up=true,west=false]"
      },
      {
        "char": "v",
        "block": "minecraft:quartz_stairs[facing=east,half=bottom,shape=straight,waterlogged=false]"
      },
      {
        "char": "b",
        "block": "minecraft:polished_andesite"
      },
      {
        "char": "e",
        "block": "minecraft:andesite"
      },
      {
        "char": "S",
        "block": "minecraft:polished_andesite_slab[type=bottom,waterlogged=false]"
      },
      {
        "char": "f",
        "block": "minecraft:grass_block[snowy=false]"
      },
      {
        "char": "Τ",
        "block": "minecraft:quartz_stairs[facing=north,half=bottom,shape=outer_right,waterlogged=false]"
      },
      {
        "char": "r",
        "block": "minecraft:quartz_stairs[facing=north,half=bottom,shape=straight,waterlogged=false]"
      },
      {
        "char": "n",
        "block": "minecraft:air"
      },
      {
        "char": "Ͷ",
        "block": "minecraft:quartz_stairs[facing=east,half=bottom,shape=outer_left,waterlogged=false]"
      }
    ]
  },
  "slices": [
    [
      "aaaaaaaaaaaaaaaa",
      "aaaaaaaaaaaaa aa",
      "Ύaaaaaaaaaaa   a",
      "aaaaaaaaaaa  aaa",
      "aaaaaaaaaaaaaaaa",
      "aaaaaaaaaaaaaaaa",
      "aaaaaaaaaaaaaaaa",
      "aaaaaaaaaaΆaΆaaΆ",
      "aaaaaaaaaaaaaaaa",
      "aaaaaaaaaaaaaaaa",
      "aaaaaaaaaaaaaaaa",
      "aaaaaaaaaaaaaaaa",
      "aaaaaaaaaaaaaaaa",
      "Ύaaaaaaaaaaaзaaa",
      "hhqhhhqhhhhqwhhh",
      "  Ν             "
    ],
    [
      "vbbbeeeeebbbeeeb",
      "vbeeeebbbebbeebb",
      "vbebbbebbebebSee",
      "vbbebfbbbeeebeeb",
      "vbbbffbbbbeeeebe",
      "vbbbeeebebbeebeb",
      "vbefbebbebeebbee",
      "vbfeebeeeebebbeb",
      "vbbbbbbeeebbbbeb",
      "vbbebbebbbeebeef",
      "vbeebebbeeeebbeb",
      "vbbbbebebeeeebeb",
      "vbbbeeebebebbbee",
      "vbebeebbebeebebe",
      "vhqwqhqhhwqhqhhw",
      "Τrrrrrrrrrrrrrrr"
    ],
    [
      " v              ",
      " v              ",
      " v              ",
      " v              ",
      " v  nn        b ",
      " v              ",
      " v              ",
      " vn             ",
      " v              ",
      " v             n",
      " v              ",
      " v              ",
      " v              ",
      " v              ",
      " Ͷrrrrrrrrrrrrrr",
      "                "
    ],
    [
      "                ",
      "                ",
      "                ",
      "                ",
      "                ",
      "                ",
      "                ",
      "                ",
      "                ",
      "                ",
      "                ",
      "                ",
      "                ",
      "                ",
      "                ",
      "                "
    ],
    [
      "                ",
      "                ",
      "                ",
      "                ",
      "                ",
      "                ",
      "                ",
      "                ",
      "                ",
      "                ",
      "                ",
      "                ",
      "                ",
      "                ",
      "                ",
      "                "
    ],
    [
      "                ",
      "                ",
      "                ",
      "                ",
      "                ",
      "                ",
      "                ",
      "                ",
      "                ",
      "                ",
      "                ",
      "                ",
      "                ",
      "                ",
      "                ",
      "                "
    ]
  ]
}