{
  "xsize": 16,
  "zsize": 16,
  "palette": {
    "palette": [
      {
        "char": " ",
        "block": "minecraft:air"
      },
      {
        "char": "a",
        "block": "minecraft:air"
      },
      {
        "char": "b",
        "block": "minecraft:air"
      },
      {
        "char": "T",
        "block": "minecraft:air"
      },
      {
        "char": "S",
        "block": "minecraft:air"
      },
      {
        "char": "i",
        "block": "minecraft:air"
      },
      {
        "char": "Σ",
        "block": "minecraft:air"
      },
      {
        "char": "U",
        "block": "minecraft:air"
      },
      {
        "char": "Ω",
        "block": "minecraft:air"
      },
      {
        "char": "Γ",
        "block": "minecraft:air"
      },
      {
        "char": "϶",
        "block": "minecraft:air"
      },
      {
        "char": "t",
        "block": "minecraft:air"
      },
      {
        "char": "Ђ",
        "block": "minecraft:air"
      },
      {
        "char": "P",
        "block": "minecraft:air"
      },
      {
        "char": "ϭ",
        "block": "minecraft:air"
      },
      {
        "char": "E",
        "block": "minecraft:air"
      },
      {
        "char": "d",
        "block": "minecraft:grass"
      },
      {
        "char": "r",
        "block": "minecraft:air"
      },
      {
        "char": "W",
        "block": "minecraft:tall_grass[half=lower]"
      },
      {
        "char": "G",
        "block": "minecraft:air"
      },
      {
        "char": "X",
        "block": "minecraft:air"
      },
      {
        "char": "l",
        "block": "minecraft:air"
      },
      {
        "char": "ε",
        "block": "minecraft:air"
      },
      {
        "char": "Ϗ",
        "block": "minecraft:air"
      },
      {
        "char": "V",
        "block": "minecraft:tall_grass[half=upper]"
      },
      {
        "char": "ό",
        "block": "minecraft:air"
      },
      {
        "char": "π",
        "block": "minecraft:air"
      }
    ]
  },
  "slices": [
    [
      "aaaaaaaaaaaaaabT",
      "aaaaaaaaaaaaabbS",
      "aaaaaaaaaaaaaabi",
      "aaaaaaaaaaaaaaai",
      "aaaaaaaaaaaaaabi",
      "ΣΣΣaaaaaaaaaaaaU",
      "aaaaaaaaaaaaaaaT",
      "aaaaaaaaaaaaaaai",
      "iiiiiiiiiiiiiiiS",
      "ΩΓ϶tttttΩΓЂPttPϭ",
      "                ",
      "                ",
      "                ",
      "                ",
      "                ",
      "                "
    ],
    [
      "           EEEdr",
      "             WdG",
      "            EEWr",
      "            EE r",
      "XXXX          dr",
      "   X        EE G",
      "XXXX        EE G",
      "               r",
      "rrrrrrrrrrrrGGGr",
      "llllllllllllllll",
      "                ",
      "                ",
      "                ",
      "                ",
      "                ",
      "                "
    ],
    [
      "           εϏ   ",
      "             V  ",
      "            όπV ",
      "            εϏ  ",
      "                ",
      "            όπ  ",
      "            εϏ  ",
      "                ",
      "                ",
      "                ",
      "                ",
      "                ",
      "                ",
      "                ",
      "                ",
      "                "
    ],
    [
      "                ",
      "                ",
      "                ",
      "                ",
      "                ",
      "                ",
      "                ",
      "                ",
      "                ",
      "                ",
      "                ",
      "                ",
      "                ",
      "                ",
      "                ",
      "                "
    ],
    [
      "                ",
      "                ",
      "                ",
      "                ",
      "                ",
      "                ",
      "                ",
      "                ",
      "                ",
      "                ",
      "                ",
      "                ",
      "                ",
      "                ",
      "                ",
      "                "
    ],
    [
      "                ",
      "                ",
      "                ",
      "                ",
      "                ",
      "                ",
      "                ",
      "                ",
      "                ",
      "                ",
      "                ",
      "                ",
      "                ",
      "                ",
      "                ",
      "                "
    ]
  ]
}