{
  "xsize": 16,
  "zsize": 16,
  "palette": {
    "palette": [
      {
        "char": " ",
        "block": "minecraft:air"
      },
      {
        "char": "x",
        "block": "minecraft:air"
      },
      {
        "char": "m",
        "block": "minecraft:air"
      },
      {
        "char": "u",
        "block": "minecraft:air"
      },
      {
        "char": "k",
        "block": "minecraft:air"
      },
      {
        "char": "f",
        "block": "minecraft:air"
      },
      {
        "char": "g",
        "block": "minecraft:air"
      },
      {
        "char": "c",
        "block": "minecraft:air"
      },
      {
        "char": "h",
        "block": "minecraft:air"
      },
      {
        "char": "b",
        "block": "minecraft:air"
      },
      {
        "char": "p",
        "block": "minecraft:air"
      },
      {
        "char": "j",
        "block": "minecraft:air"
      },
      {
        "char": "ͼ",
        "block": "minecraft:air"
      },
      {
        "char": "n",
        "block": "minecraft:air"
      },
      {
        "char": "s",
        "block": "minecraft:air"
      },
      {
        "char": "d",
        "block": "minecraft:grass"
      },
      {
        "char": "e",
        "block": "minecraft:air"
      },
      {
        "char": "3",
        "block": "minecraft:air"
      },
      {
        "char": "φ",
        "block": "minecraft:air"
      },
      {
        "char": "М",
        "block": "minecraft:air",
        "tag": {
          "z": 530,
          "x": 139,
          "ForgeCaps": {},
          "id": "minecraft:skull",
          "y": 133
        }
      },
      {
        "char": "Ϫ",
        "block": "minecraft:air",
        "tag": {
          "z": 531,
          "x": 128,
          "ForgeCaps": {},
          "id": "minecraft:skull",
          "y": 133
        }
      },
      {
        "char": "ϼ",
        "block": "minecraft:air"
      },
      {
        "char": "N",
        "block": "minecraft:air"
      },
      {
        "char": "0",
        "block": "minecraft:air"
      },
      {
        "char": "ў",
        "block": "minecraft:air",
        "tag": {
          "z": 536,
          "x": 131,
          "ForgeCaps": {},
          "id": "minecraft:skull",
          "y": 133
        }
      },
      {
        "char": "И",
        "block": "minecraft:air"
      },
      {
        "char": "Л",
        "block": "minecraft:air",
        "tag": {
          "z": 541,
          "x": 143,
          "ForgeCaps": {},
          "id": "minecraft:skull",
          "y": 133
        }
      },
      {
        "char": "v",
        "block": "minecraft:air"
      },
      {
        "char": "ϓ",
        "block": "minecraft:air",
        "tag": {
          "z": 543,
          "x": 132,
          "ForgeCaps": {},
          "id": "minecraft:skull",
          "y": 133
        }
      },
      {
        "char": "F",
        "block": "minecraft:air"
      },
      {
        "char": "1",
        "block": "minecraft:air"
      },
      {
        "char": "D",
        "block": "minecraft:air"
      },
      {
        "char": "y",
        "block": "minecraft:air"
      },
      {
        "char": "K",
        "block": "minecraft:air"
      },
      {
        "char": "Ρ",
        "block": "minecraft:air"
      },
      {
        "char": "B",
        "block": "minecraft:air"
      }
    ]
  },
  "slices": [
    [
      "xmuuumuuumuuumuu",
      "xmkkfmgchmkbbmkb",
      "bmggfmggfmfccmgk",
      "pmhcgmcbgmgfgmbb",
      "xmccfmhfbmghkmcb",
      "xfkcbkggbjjfcbhk",
      "pghfcbbbͼbffhckh",
      "bnbnchfbbffcbhfg",
      "xfgbcgbgnhccgbkg",
      "sfbfbfbbbhchhcgh",
      "xbknhbcchbngfhcb",
      "pcbbhbbcccbgfbhb",
      "xbcghfgffbffbcgk",
      "snchkcfgkhcghbfh",
      "phkgfbkbcbcfhgff",
      "phkbgbgckccfbchf"
    ],
    [
      "  dee3ee ee e3e ",
      "    ee e   φee d",
      "dd      e dМ    ",
      "Ϫ      ϼ      d ",
      "      N dN      ",
      "    d N dN   d  ",
      "      dd0dN     ",
      "d d   NddN  d   ",
      "   ў  dN     d  ",
      "  d   d d       ",
      " d   d   dd     ",
      "  d  dd   d  d И",
      " d       d  d   ",
      "            dd Л",
      "       d d      ",
      " vvdϓd d    d   "
    ],
    [
      "     F      eF  ",
      "                ",
      "                ",
      "                ",
      "      1DyD1     ",
      "      DyKyD     ",
      "      yK0Ky     ",
      "      DyKyD     ",
      "       DyD      ",
      "                ",
      "                ",
      "                ",
      "                ",
      "                ",
      "                ",
      " vv             "
    ],
    [
      "     F       F  ",
      "                ",
      "                ",
      "                ",
      "       DyD1     ",
      "      DyKyD     ",
      "      yK0Ky     ",
      "      DyKyD     ",
      "       DyD1     ",
      "                ",
      "                ",
      "                ",
      "                ",
      "                ",
      "                ",
      " vv             "
    ],
    [
      "     F       F  ",
      "                ",
      "                ",
      "                ",
      "                ",
      "        Ky      ",
      "       K0K      ",
      "       yK       ",
      "                ",
      "                ",
      "                ",
      "                ",
      "                ",
      "                ",
      "                ",
      "                "
    ],
    [
      "     Ρ       Ρ  ",
      "     B       B  ",
      "                ",
      "                ",
      "                ",
      "        y       ",
      "       yKy      ",
      "        y       ",
      "                ",
      "                ",
      "                ",
      "                ",
      "                ",
      "                ",
      "                ",
      "                "
    ]
  ]
}