{
  "xsize": 16,
  "zsize": 16,
  "palette": {
    "palette": [
      {
        "char": " ",
        "block": "minecraft:air"
      },
      {
        "char": "j",
        "block": "minecraft:air"
      },
      {
        "char": "l",
        "block": "minecraft:air"
      },
      {
        "char": "i",
        "block": "minecraft:air"
      },
      {
        "char": "k",
        "block": "minecraft:air"
      },
      {
        "char": "m",
        "block": "minecraft:air"
      },
      {
        "char": "f",
        "block": "minecraft:air"
      },
      {
        "char": "H",
        "block": "minecraft:air"
      },
      {
        "char": "0",
        "block": "minecraft:air"
      },
      {
        "char": "d",
        "block": "minecraft:air"
      },
      {
        "char": "g",
        "block": "minecraft:air"
      },
      {
        "char": "F",
        "block": "minecraft:air"
      },
      {
        "char": "c",
        "block": "minecraft:air"
      },
      {
        "char": "O",
        "block": "minecraft:air"
      },
      {
        "char": "y",
        "block": "minecraft:air"
      },
      {
        "char": "B",
        "block": "minecraft:air"
      },
      {
        "char": "n",
        "block": "minecraft:grass"
      },
      {
        "char": "ϻ",
        "block": "minecraft:air"
      },
      {
        "char": "ͼ",
        "block": "minecraft:air"
      },
      {
        "char": "Ϧ",
        "block": "minecraft:air",
        "tag": {
          "z": 539,
          "x": 74,
          "ForgeCaps": {},
          "id": "minecraft:skull",
          "y": 133
        }
      },
      {
        "char": "Y",
        "block": "minecraft:tall_grass[half=lower]"
      },
      {
        "char": "О",
        "block": "minecraft:air",
        "tag": {
          "z": 511,
          "x": 78,
          "ForgeCaps": {},
          "id": "minecraft:skull",
          "y": 133
        }
      },
      {
        "char": "Ώ",
        "block": "minecraft:air"
      },
      {
        "char": "ʹ",
        "block": "minecraft:air"
      },
      {
        "char": "X",
        "block": "minecraft:tall_grass[half=upper]"
      },
      {
        "char": "W",
        "block": "minecraft:air"
      }
    ]
  },
  "slices": [
    [
      "jlillkmijlfjflji",
      "mmjklmljmklmkjkk",
      "ilkikfjkmjmlikll",
      "klflllijmjiffjjm",
      "klHmHfH0HkdgFlmm",
      "kiHjHmHjHidgFljf",
      "jlHlHfHlHjcdFkml",
      "ijkkmmmkjmijkfij",
      "jllmmlfjlfcdjfmm",
      "mlkjfilmljfmmfkk",
      "mfjifjkfffgcjimk",
      "mjmkilikfjjOmjm0",
      "kkkiilkklfgcFmfl",
      "jjmkikllfkgdFgjO",
      "imklkiikmkdcFcyy",
      "lmilmk0jmiccFgBi"
    ],
    [
      "          n n   ",
      "                ",
      "    nn          ",
      "  n        ϻn   ",
      "  n  n      F   ",
      "    n       ͼϦ n",
      "     n      F   ",
      "             n  ",
      "   n  n  n   n  ",
      "    n     n  n  ",
      " n  n  nnY      ",
      "        Y       ",
      "  n      n n0   ",
      "        n   ͼ   ",
      "            F   ",
      "            ͼ О "
    ],
    [
      "                ",
      "                ",
      "                ",
      "                ",
      "            Ώ   ",
      "            ʹ   ",
      "            0   ",
      "                ",
      "                ",
      "                ",
      "         X      ",
      "        X       ",
      "            Ώ   ",
      "            ʹ   ",
      "            Ώ   ",
      "            ʹ   "
    ],
    [
      "                ",
      "                ",
      "                ",
      "                ",
      "            W   ",
      "                ",
      "            W   ",
      "                ",
      "                ",
      "                ",
      "                ",
      "                ",
      "            W   ",
      "                ",
      "            W   ",
      "                "
    ],
    [
      "                ",
      "                ",
      "                ",
      "                ",
      "                ",
      "                ",
      "                ",
      "                ",
      "                ",
      "                ",
      "                ",
      "                ",
      "                ",
      "                ",
      "                ",
      "                "
    ],
    [
      "                ",
      "                ",
      "                ",
      "                ",
      "                ",
      "                ",
      "                ",
      "                ",
      "                ",
      "                ",
      "                ",
      "                ",
      "                ",
      "                ",
      "                ",
      "                "
    ]
  ]
}