{
  "xsize": 16,
  "zsize": 16,
  "palette": {
    "palette": [
      {
        "char": " ",
        "block": "minecraft:air"
      },
      {
        "char": "p",
        "block": "minecraft:air"
      },
      {
        "char": "a",
        "block": "minecraft:air"
      },
      {
        "char": "Ύ",
        "block": "minecraft:air"
      },
      {
        "char": "q",
        "block": "minecraft:air"
      },
      {
        "char": "h",
        "block": "minecraft:air"
      },
      {
        "char": "Ά",
        "block": "minecraft:air"
      },
      {
        "char": "J",
        "block": "minecraft:air"
      },
      {
        "char": "ΰ",
        "block": "minecraft:air"
      },
      {
        "char": "Ζ",
        "block": "minecraft:air"
      },
      {
        "char": "΄",
        "block": "minecraft:air"
      },
      {
        "char": "b",
        "block": "minecraft:air"
      },
      {
        "char": "x",
        "block": "minecraft:air"
      },
      {
        "char": "e",
        "block": "minecraft:air"
      },
      {
        "char": "f",
        "block": "minecraft:air"
      },
      {
        "char": "w",
        "block": "minecraft:air"
      },
      {
        "char": "n",
        "block": "minecraft:grass"
      },
      {
        "char": "A",
        "block": "minecraft:air"
      },
      {
        "char": "Υ",
        "block": "minecraft:air"
      },
      {
        "char": "Φ",
        "block": "minecraft:air"
      },
      {
        "char": "Χ",
        "block": "minecraft:air"
      },
      {
        "char": "Ο",
        "block": "minecraft:air"
      }
    ]
  },
  "slices": [
    [
      "ppppppppppppppp ",
      "aΎaaaaaaaaaaΎq  ",
      "aaaaaaaaaaaaah  ",
      "aaaaaaaaaaaaaq  ",
      "aaaaaaaaaaaaah  ",
      "Άaaaaaaaaaaaah  ",
      "aaaaaaaaaaaaah  ",
      "ΆaaaaaaaaaaaaJΰ ",
      "aaaaaaaaaaaaah  ",
      "aaaaaaaaΆaΆaah  ",
      "Άaaaaaaaaaaaah  ",
      "aaaaaaaaaaaaah  ",
      "Άaaaaaaaaaaaah  ",
      "aaaaaaaaaaaaah  ",
      "aaaaaaaaaaaaaq  ",
      "aaaaaΖ aaaaaah  "
    ],
    [
      "                ",
      "pppppppppppppp΄ ",
      "bbbbbbbbbbbbbhx ",
      "ebeebebfeebbehx ",
      "eeebbbebbbebehx ",
      "bbebbebbeebbbqx ",
      "bbbebeeebeebbqx ",
      "beebbebebebebwx ",
      "eeebbbeebbbfeqx ",
      "bbebeeeebbbbbhx ",
      "bbebbbeebbbebhx ",
      "eebbbbbeeebbbhx ",
      "bbbebbeebebbehx ",
      "eebbbbeebebeehx ",
      "bbe eb bebeeehx ",
      "bebbeΖeebbbebhx "
    ],
    [
      "                ",
      "                ",
      "ppppppppppppp΄  ",
      "       n     x  ",
      "             x  ",
      "             x  ",
      "A AA AA      x  ",
      "A AA AA      x  ",
      "             x  ",
      "A AA AA      x  ",
      "A AA AA      x  ",
      "             x  ",
      "             x  ",
      "    b        x  ",
      "             x  ",
      "       b     x  "
    ],
    [
      "                ",
      "                ",
      "                ",
      "                ",
      "                ",
      "                ",
      "Υ ΦΥ ΦΥ         ",
      "Χ ΟΧ ΟΧ         ",
      "                ",
      "Υ ΦΥ ΦΥ         ",
      "Χ ΟΧ ΟΧ         ",
      "                ",
      "                ",
      "                ",
      "                ",
      "                "
    ],
    [
      "                ",
      "                ",
      "                ",
      "                ",
      "                ",
      "                ",
      "                ",
      "                ",
      "                ",
      "                ",
      "                ",
      "                ",
      "                ",
      "                ",
      "                ",
      "                "
    ],
    [
      "                ",
      "                ",
      "                ",
      "                ",
      "                ",
      "                ",
      "                ",
      "                ",
      "                ",
      "                ",
      "                ",
      "                ",
      "                ",
      "                ",
      "                ",
      "                "
    ]
  ]
}