{
  "xsize": 16,
  "zsize": 16,
  "palette": {
    "palette": [
      {
        "char": " ",
        "block": "minecraft:air"
      },
      {
        "char": "h",
        "block": "minecraft:air"
      },
      {
        "char": "w",
        "block": "minecraft:air"
      },
      {
        "char": "p",
        "block": "minecraft:air"
      },
      {
        "char": "a",
        "block": "minecraft:air"
      },
      {
        "char": "Ύ",
        "block": "minecraft:air"
      },
      {
        "char": "q",
        "block": "minecraft:air"
      },
      {
        "char": "A",
        "block": "minecraft:air"
      },
      {
        "char": "t",
        "block": "minecraft:air"
      },
      {
        "char": "b",
        "block": "minecraft:air"
      },
      {
        "char": "e",
        "block": "minecraft:air"
      },
      {
        "char": "v",
        "block": "minecraft:air"
      },
      {
        "char": "f",
        "block": "minecraft:air"
      },
      {
        "char": "N",
        "block": "minecraft:air"
      },
      {
        "char": "P",
        "block": "minecraft:air"
      },
      {
        "char": "n",
        "block": "minecraft:grass"
      },
      {
        "char": "Φ",
        "block": "minecraft:air"
      },
      {
        "char": "Ο",
        "block": "minecraft:air"
      },
      {
        "char": "H",
        "block": "minecraft:air"
      },
      {
        "char": "D",
        "block": "minecraft:air"
      },
      {
        "char": "C",
        "block": "minecraft:air"
      },
      {
        "char": "x",
        "block": "minecraft:air"
      },
      {
        "char": "r",
        "block": "minecraft:air"
      },
      {
        "char": "ͽ",
        "block": "minecraft:air"
      }
    ]
  },
  "slices": [
    [
      "hhhwpppppppppppp",
      " aaahΎaaaaaaaaaa",
      "   hhaaaaaaaaaaa",
      "   whaaaaaaaaaaa",
      "hhhqhaaaaaaaaaaa",
      "qqqhAaaaaaaaaaaa",
      "Ύaaaaaaaaaaaaaaa",
      "aaaaaaaaaaaaaaaa",
      "aaaaaaaaaaaaaaaa",
      "aaaaaaaaaaaaaaaa",
      "aaaaaaaaaaaaaaaa",
      "aaaaaaaaaaaaaaaa",
      "aaaaaaaaaaaaaaaa",
      "aaaaaaaaaaaaaaaa",
      "aaaaaaaaaaaaaaaa",
      "aaaaaaaaaaaaaaaa"
    ],
    [
      "hhwht           ",
      "bbbhpppppppppppp",
      "bbbhbbbbbbbbbbbb",
      "bbbqbbbbebeeeeeb",
      "qhwqbebbbeeeeebb",
      "vbbbAbeebbebbebb",
      "vbbebbeebebbebeb",
      "vbbebbeeeebeefbe",
      "vbbebbbebebefbbb",
      "vbfbebeebbebebbb",
      "vbebbbbbbeeeebee",
      "vbebbbbbbbeeebbb",
      "vbbbbbeebebbebbe",
      "vbeebebeebebbeee",
      "vbebebbebbbeebeb",
      "vbebebbeebebbbeb"
    ],
    [
      "NPNht           ",
      "   q            ",
      "   wpppppppppppp",
      "   q            ",
      "qqwh            ",
      " v  A           ",
      " v             A",
      " v           n A",
      " v          n   ",
      " vn            A",
      " v             A",
      " v              ",
      " v              ",
      " v              ",
      " v              ",
      " v              "
    ],
    [
      "whwq            ",
      "   q            ",
      "   q            ",
      "   h            ",
      "wqhh            ",
      "    A           ",
      "               Φ",
      "               Ο",
      "                ",
      "               Φ",
      "               Ο",
      "                ",
      "                ",
      "                ",
      "                ",
      "                "
    ],
    [
      "HHHHD           ",
      "   HD           ",
      "   HD           ",
      "   HD           ",
      "HHHHD           ",
      "DCDCA           ",
      "                ",
      "                ",
      "                ",
      "                ",
      "                ",
      "                ",
      "                ",
      "                ",
      "                ",
      "                "
    ],
    [
      "bbbbCx          ",
      "bbbbCx          ",
      "bbbbCx          ",
      "bbbbDx          ",
      "bbbbDx          ",
      "CDCDCx          ",
      "rrrrrͽ          ",
      "                ",
      "                ",
      "                ",
      "                ",
      "                ",
      "                ",
      "                ",
      "                ",
      "                "
    ]
  ]
}