{
  "xsize": 16,
  "zsize": 16,
  "palette": {
    "palette": [
      {
        "char": " ",
        "block": "minecraft:air"
      },
      {
        "char": "h",
        "block": "minecraft:bricks[weathering=false]"
      },
      {
        "char": "w",
        "block": "minecraft:terracotta"
      },
      {
        "char": "p",
        "block": "minecraft:quartz_stairs[facing=south,half=bottom,shape=straight,waterlogged=false]"
      },
      {
        "char": "a",
        "block": "minecraft:polished_andesite_slab[type=top,waterlogged=false]"
      },
      {
        "char": "Ύ",
        "block": "minecraft:note_block[instrument=harp,note=0,powered=false]"
      },
      {
        "char": "q",
        "block": "minecraft:granite"
      },
      {
        "char": "A",
        "block": "minecraft:quartz_pillar[axis=y]"
      },
      {
        "char": "t",
        "block": "minecraft:vine[east=false,north=true,south=false,up=false,west=false]"
      },
      {
        "char": "b",
        "block": "minecraft:polished_andesite"
      },
      {
        "char": "e",
        "block": "minecraft:andesite"
      },
      {
        "char": "v",
        "block": "minecraft:quartz_stairs[facing=east,half=bottom,shape=straight,waterlogged=false]"
      },
      {
        "char": "f",
        "block": "minecraft:grass_block[snowy=false]"
      },
      {
        "char": "N",
        "block": "minecraft:green_concrete"
      },
      {
        "char": "P",
        "block": "minecraft:lime_concrete"
      },
      {
        "char": "n",
        "block": "minecraft:air"
      },
      {
        "char": "Φ",
        "block": "minecraft:rail[shape=south_east,waterlogged=false]"
      },
      {
        "char": "Ο",
        "block": "minecraft:rail[shape=north_east,waterlogged=false]"
      },
      {
        "char": "H",
        "block": "minecraft:white_concrete"
      },
      {
        "char": "D",
        "block": "minecraft:diorite_slab[type=bottom,waterlogged=false]"
      },
      {
        "char": "C",
        "block": "minecraft:smooth_quartz_slab[type=bottom,waterlogged=false]"
      },
      {
        "char": "x",
        "block": "minecraft:quartz_stairs[facing=west,half=bottom,shape=straight,waterlogged=false]"
      },
      {
        "char": "r",
        "block": "minecraft:quartz_stairs[facing=north,half=bottom,shape=straight,waterlogged=false]"
      },
      {
        "char": "ͽ",
        "block": "minecraft:quartz_stairs[facing=west,half=bottom,shape=outer_right,waterlogged=false]"
      }
    ]
  },
  "slices": [
    [
      "hhhwpppppppppppp",
      " aaahΎaaaaaaaaaa",
      "   hhaaaaaaaaaaa",
      "   whaaaaaaaaaaa",
      "hhhqhaaaaaaaaaaa",
      "qqqhAaaaaaaaaaaa",
      "Ύaaaaaaaaaaaaaaa",
      "aaaaaaaaaaaaaaaa",
      "aaaaaaaaaaaaaaaa",
      "aaaaaaaaaaaaaaaa",
      "aaaaaaaaaaaaaaaa",
      "aaaaaaaaaaaaaaaa",
      "aaaaaaaaaaaaaaaa",
      "aaaaaaaaaaaaaaaa",
      "aaaaaaaaaaaaaaaa",
      "aaaaaaaaaaaaaaaa"
    ],
    [
      "hhwht           ",
      "bbbhpppppppppppp",
      "bbbhbbbbbbbbbbbb",
      "bbbqbbbbebeeeeeb",
      "qhwqbebbbeeeeebb",
      "vbbbAbeebbebbebb",
      "vbbebbeebebbebeb",
      "vbbebbeeeebeefbe",
      "vbbebbbebebefbbb",
      "vbfbebeebbebebbb",
      "vbebbbbbbeeeebee",
      "vbebbbbbbbeeebbb",
      "vbbbbbeebebbebbe",
      "vbeebebeebebbeee",
      "vbebebbebbbeebeb",
      "vbebebbeebebbbeb"
    ],
    [
      "NPNht           ",
      "   q            ",
      "   wpppppppppppp",
      "   q            ",
      "qqwh            ",
      " v  A           ",
      " v             A",
      " v           n A",
      " v          n   ",
      " vn            A",
      " v             A",
      " v              ",
      " v              ",
      " v              ",
      " v              ",
      " v              "
    ],
    [
      "whwq            ",
      "   q            ",
      "   q            ",
      "   h            ",
      "wqhh            ",
      "    A           ",
      "               Φ",
      "               Ο",
      "                ",
      "               Φ",
      "               Ο",
      "                ",
      "                ",
      "                ",
      "                ",
      "                "
    ],
    [
      "HHHHD           ",
      "   HD           ",
      "   HD           ",
      "   HD           ",
      "HHHHD           ",
      "DCDCA           ",
      "                ",
      "                ",
      "                ",
      "                ",
      "                ",
      "                ",
      "                ",
      "                ",
      "                ",
      "                "
    ],
    [
      "bbbbCx          ",
      "bbbbCx          ",
      "bbbbCx          ",
      "bbbbDx          ",
      "bbbbDx          ",
      "CDCDCx          ",
      "rrrrrͽ          ",
      "                ",
      "                ",
      "                ",
      "                ",
      "                ",
      "                ",
      "                ",
      "                ",
      "                "
    ]
  ]
}