{
  "xsize": 16,
  "zsize": 16,
  "palette": {
    "palette": [
      {
        "char": " ",
        "block": "minecraft:air"
      },
      {
        "char": "i",
        "block": "minecraft:air"
      },
      {
        "char": "k",
        "block": "minecraft:air"
      },
      {
        "char": "m",
        "block": "minecraft:air"
      },
      {
        "char": "j",
        "block": "minecraft:air"
      },
      {
        "char": "f",
        "block": "minecraft:air"
      },
      {
        "char": "0",
        "block": "minecraft:air"
      },
      {
        "char": "O",
        "block": "minecraft:air"
      },
      {
        "char": "c",
        "block": "minecraft:air"
      },
      {
        "char": "F",
        "block": "minecraft:air"
      },
      {
        "char": "g",
        "block": "minecraft:air"
      },
      {
        "char": "B",
        "block": "minecraft:air"
      },
      {
        "char": "l",
        "block": "minecraft:air"
      },
      {
        "char": "d",
        "block": "minecraft:air"
      },
      {
        "char": "y",
        "block": "minecraft:air"
      },
      {
        "char": "n",
        "block": "minecraft:grass"
      },
      {
        "char": "Y",
        "block": "minecraft:tall_grass[half=lower]"
      },
      {
        "char": "ͼ",
        "block": "minecraft:air"
      },
      {
        "char": "L",
        "block": "minecraft:air"
      },
      {
        "char": "ϡ",
        "block": "minecraft:air"
      },
      {
        "char": "Ϳ",
        "block": "minecraft:air"
      },
      {
        "char": "Ϲ",
        "block": "minecraft:air",
        "tag": {
          "z": 533,
          "x": 82,
          "ForgeCaps": {},
          "id": "minecraft:skull",
          "y": 133
        }
      },
      {
        "char": "϶",
        "block": "minecraft:air"
      },
      {
        "char": "П",
        "block": "minecraft:air",
        "tag": {
          "z": 518,
          "x": 71,
          "ForgeCaps": {},
          "id": "minecraft:skull",
          "y": 133
        }
      },
      {
        "char": "Е",
        "block": "minecraft:air",
        "tag": {
          "z": 526,
          "x": 71,
          "ForgeCaps": {},
          "id": "minecraft:skull",
          "y": 133
        }
      },
      {
        "char": "Ώ",
        "block": "minecraft:air"
      },
      {
        "char": "X",
        "block": "minecraft:tall_grass[half=upper]"
      },
      {
        "char": "ʹ",
        "block": "minecraft:air"
      },
      {
        "char": "K",
        "block": "minecraft:air"
      },
      {
        "char": "κ",
        "block": "minecraft:air"
      },
      {
        "char": "ϙ",
        "block": "minecraft:air"
      },
      {
        "char": "W",
        "block": "minecraft:air"
      },
      {
        "char": "ϑ",
        "block": "minecraft:air"
      },
      {
        "char": "9",
        "block": "minecraft:air"
      }
    ]
  },
  "slices": [
    [
      "ikmjfif0OkccFgBl",
      "ijlffilkiiggFgBi",
      "mkdgdccdddcdFdyy",
      "jldgf dcdgdcFdkm",
      "mlyyyyFFFFFFFfli",
      "jilijBFdggfgdckl",
      "jflijBFgyyyyyOim",
      "iikjjBFgBmfiflfi",
      "fkyyyyFcBlifikii",
      "mklijBFdBiiijOmf",
      "fjljjfFdyyyyyfOl",
      "kmlilBFcBfjmliim",
      "kkfyyyFdBkmlifii",
      "lmimjBFdBmkimllm",
      "mlkliBFgyyyyyffm",
      "jjmfkBFgBilifimf"
    ],
    [
      "    n n     0   ",
      "   nY       ͼ   ",
      "            F L ",
      "    n       ͼ   ",
      "      0ϡͿϡOϡͿY Ϲ",
      "      ϶   n     ",
      " n   nͿП        ",
      "      ͼ   n n n ",
      "n     F    nn   ",
      "n  n  ͼ        n",
      "n     Ϳ L    n n",
      "      ͼ         ",
      "  n   Ϳ      n  ",
      "      ͼ         ",
      "      OЕ      n ",
      "   n  ͼ     n  n"
    ],
    [
      "            Ώ   ",
      "    X       ʹ   ",
      "            Ϳ K ",
      "            ʹ   ",
      "      ͿκFκFκFX  ",
      "      ϙ         ",
      "      Ώ         ",
      "      ϙ         ",
      "      O         ",
      "      ϙ         ",
      "      Ϳ K       ",
      "      ʹ         ",
      "      0         ",
      "      ʹ         ",
      "      F         ",
      "      ʹ         "
    ],
    [
      "            W   ",
      "                ",
      "            L K ",
      "                ",
      "      W L L L   ",
      "                ",
      "      W         ",
      "                ",
      "      L         ",
      "                ",
      "      W K       ",
      "                ",
      "      L         ",
      "                ",
      "      W         ",
      "                "
    ],
    [
      "                ",
      "                ",
      "              K ",
      "                ",
      "      W         ",
      "                ",
      "      W         ",
      "                ",
      "      W         ",
      "                ",
      "        K       ",
      "                ",
      "                ",
      "                ",
      "                ",
      "                "
    ],
    [
      "                ",
      "                ",
      "              ϑ9",
      "                ",
      "      L         ",
      "                ",
      "      W         ",
      "                ",
      "      L         ",
      "                ",
      "        ϑ9      ",
      "                ",
      "                ",
      "                ",
      "                ",
      "                "
    ]
  ]
}