{
  "xsize": 16,
  "zsize": 16,
  "palette": {
    "palette": [
      {
        "char": " ",
        "block": "minecraft:air"
      },
      {
        "char": "a",
        "block": "minecraft:air"
      },
      {
        "char": "Ύ",
        "block": "minecraft:air"
      },
      {
        "char": "Ά",
        "block": "minecraft:air"
      },
      {
        "char": "з",
        "block": "minecraft:air"
      },
      {
        "char": "h",
        "block": "minecraft:air"
      },
      {
        "char": "q",
        "block": "minecraft:air"
      },
      {
        "char": "w",
        "block": "minecraft:air"
      },
      {
        "char": "Ν",
        "block": "minecraft:air"
      },
      {
        "char": "v",
        "block": "minecraft:air"
      },
      {
        "char": "b",
        "block": "minecraft:air"
      },
      {
        "char": "e",
        "block": "minecraft:air"
      },
      {
        "char": "S",
        "block": "minecraft:air"
      },
      {
        "char": "f",
        "block": "minecraft:air"
      },
      {
        "char": "Τ",
        "block": "minecraft:air"
      },
      {
        "char": "r",
        "block": "minecraft:air"
      },
      {
        "char": "n",
        "block": "minecraft:grass"
      },
      {
        "char": "Ͷ",
        "block": "minecraft:air"
      }
    ]
  },
  "slices": [
    [
      "aaaaaaaaaaaaaaaa",
      "aaaaaaaaaaaaa aa",
      "Ύaaaaaaaaaaa   a",
      "aaaaaaaaaaa  aaa",
      "aaaaaaaaaaaaaaaa",
      "aaaaaaaaaaaaaaaa",
      "aaaaaaaaaaaaaaaa",
      "aaaaaaaaaaΆaΆaaΆ",
      "aaaaaaaaaaaaaaaa",
      "aaaaaaaaaaaaaaaa",
      "aaaaaaaaaaaaaaaa",
      "aaaaaaaaaaaaaaaa",
      "aaaaaaaaaaaaaaaa",
      "Ύaaaaaaaaaaaзaaa",
      "hhqhhhqhhhhqwhhh",
      "  Ν             "
    ],
    [
      "vbbbeeeeebbbeeeb",
      "vbeeeebbbebbeebb",
      "vbebbbebbebebSee",
      "vbbebfbbbeeebeeb",
      "vbbbffbbbbeeeebe",
      "vbbbeeebebbeebeb",
      "vbefbebbebeebbee",
      "vbfeebeeeebebbeb",
      "vbbbbbbeeebbbbeb",
      "vbbebbebbbeebeef",
      "vbeebebbeeeebbeb",
      "vbbbbebebeeeebeb",
      "vbbbeeebebebbbee",
      "vbebeebbebeebebe",
      "vhqwqhqhhwqhqhhw",
      "Τrrrrrrrrrrrrrrr"
    ],
    [
      " v              ",
      " v              ",
      " v              ",
      " v              ",
      " v  nn        b ",
      " v              ",
      " v              ",
      " vn             ",
      " v              ",
      " v             n",
      " v              ",
      " v              ",
      " v              ",
      " v              ",
      " Ͷrrrrrrrrrrrrrr",
      "                "
    ],
    [
      "                ",
      "                ",
      "                ",
      "                ",
      "                ",
      "                ",
      "                ",
      "                ",
      "                ",
      "                ",
      "                ",
      "                ",
      "                ",
      "                ",
      "                ",
      "                "
    ],
    [
      "                ",
      "                ",
      "                ",
      "                ",
      "                ",
      "                ",
      "                ",
      "                ",
      "                ",
      "                ",
      "                ",
      "                ",
      "                ",
      "                ",
      "                ",
      "                "
    ],
    [
      "                ",
      "                ",
      "                ",
      "                ",
      "                ",
      "                ",
      "                ",
      "                ",
      "                ",
      "                ",
      "                ",
      "                ",
      "                ",
      "                ",
      "                ",
      "                "
    ]
  ]
}