{
  "xsize": 16,
  "zsize": 16,
  "palette": {
    "palette": [
      {
        "char": " ",
        "block": "minecraft:air"
      },
      {
        "char": "c",
        "block": "minecraft:vine[east=false,north=false,south=true,up=false,west=false]"
      },
      {
        "char": "e",
        "block": "minecraft:stone_bricks[weathering=false]"
      },
      {
        "char": "g",
        "block": "minecraft:glass_pane[east=true,north=false,south=false,waterlogged=false,west=true]"
      },
      {
        "char": "i",
        "block": "minecraft:mossy_stone_bricks"
      },
      {
        "char": "f",
        "block": "minecraft:glass_pane[east=false,north=true,south=true,waterlogged=false,west=false]"
      },
      {
        "char": "C",
        "block": "minecraft:redstone_lamp[lit=false]"
      },
      {
        "char": "h",
        "block": "minecraft:cracked_stone_bricks"
      },
      {
        "char": "a",
        "block": "minecraft:cobblestone[weathering=false]"
      },
      {
        "char": "d",
        "block": "minecraft:mossy_cobblestone"
      },
      {
        "char": "b",
        "block": "minecraft:stone[weathering=false]"
      },
      {
        "char": "j",
        "block": "minecraft:light_gray_carpet"
      },
      {
        "char": "y",
        "block": "minecraft:redstone_wire[east=side,north=side,power=0,south=side,west=side]"
      },
      {
        "char": "ҁ",
        "block": "minecraft:furnace[facing=south,lit=false]",
        "tag": {
          "z": 617,
          "x": 81,
          "CookTimeTotal": 0,
          "ForgeData": {
            "LockFlag": "1b"
          },
          "CookTime": 0,
          "ForgeCaps": {
            "polymorph:block_entity_recipe_data": {}
          },
          "id": "minecraft:furnace",
          "y": 200,
          "Items": [],
          "BurnTime": 0,
          "RecipesUsed": {}
        }
      },
      {
        "char": "҃",
        "block": "minecraft:skeleton_skull[rotation=4]",
        "tag": {
          "z": 618,
          "x": 72,
          "ForgeCaps": {},
          "id": "minecraft:skull",
          "y": 200
        }
      },
      {
        "char": "Ҹ",
        "block": "minecraft:skeleton_skull[rotation=2]",
        "tag": {
          "z": 630,
          "x": 78,
          "ForgeCaps": {},
          "id": "minecraft:skull",
          "y": 194
        }
      },
      {
        "char": "Е",
        "block": "minecraft:dark_oak_stairs[facing=north,half=bottom,shape=straight,waterlogged=false]"
      },
      {
        "char": "ϟ",
        "block": "minecraft:oak_wall_sign[facing=south,waterlogged=false]",
        "tag": {
          "z": 617,
          "x": 85,
          "is_waxed": "0b",
          "ForgeCaps": {
            "supplementaries:antique_ink": {
              "ink": "0b"
            }
          },
          "id": "minecraft:sign",
          "y": 153,
          "front_text": {
            "color": "black",
            "has_glowing_text": "0b",
            "messages": [
              "{\"extra\":[{\"text\":\"Floor 3\"}],\"text\":\"\"}",
              "{\"extra\":[{\"text\":\"Complaints\"}],\"text\":\"\"}",
              "{\"text\":\"\"}",
              "{\"text\":\"\"}"
            ]
          },
          "back_text": {
            "color": "black",
            "has_glowing_text": "0b",
            "messages": [
              "{\"text\":\"\"}",
              "{\"text\":\"\"}",
              "{\"text\":\"\"}",
              "{\"text\":\"\"}"
            ]
          }
        }
      }
    ]
  },
  "slices": [
    [
      "                ",
      "                ",
      "                ",
      "                ",
      "                ",
      "                ",
      "                ",
      "        ccc c cc",
      "       egigigege",
      "       f        ",
      "       eC    C C",
      "       f        ",
      "       e        ",
      "        C    C C",
      "       h        ",
      "                "
    ],
    [
      "                ",
      "                ",
      "                ",
      "                ",
      "                ",
      "                ",
      "                ",
      "        ccc c cc",
      "       adadddaad",
      "       adbabbaba",
      "       ababbaabb",
      "       dadaaabab",
      "       ddbaabbab",
      "       aabbabbba",
      "       aaaabbbba",
      "        babababa"
    ],
    [
      "                ",
      "                ",
      "                ",
      "                ",
      "                ",
      "                ",
      "                ",
      "        ccc c cc",
      "       agighgigi",
      "       jjy j ҁ ҁ",
      "        ҃j j   j",
      "       yjyjjyj  ",
      "       e j  jyjy",
      "        jj jjҸj ",
      "        j j jy  ",
      "         j j   Е"
    ],
    [
      "                ",
      "                ",
      "                ",
      "                ",
      "                ",
      "                ",
      "                ",
      "        ccc c cc",
      "         e   ege",
      "             ϟ ϟ",
      "                ",
      "                ",
      "       e        ",
      "                ",
      "                ",
      "                "
    ],
    [
      "                ",
      "                ",
      "                ",
      "                ",
      "                ",
      "                ",
      "                ",
      "        ccc c cc",
      "             daa",
      "                ",
      "                ",
      "                ",
      "                ",
      "                ",
      "                ",
      "                "
    ],
    [
      "                ",
      "                ",
      "                ",
      "                ",
      "                ",
      "                ",
      "                ",
      "        ccc c cc",
      "             ege",
      "                ",
      "                ",
      "         C      ",
      "                ",
      "                ",
      "                ",
      "         C      "
    ]
  ]
}