{
  "xsize": 16,
  "zsize": 16,
  "palette": {
    "palette": [
      {
        "char": " ",
        "block": "minecraft:air"
      },
      {
        "char": "t",
        "block": "minecraft:deepslate[axis=y]"
      },
      {
        "char": "x",
        "block": "minecraft:grass_block[snowy=false]"
      },
      {
        "char": "o",
        "block": "minecraft:basalt[axis=x]"
      },
      {
        "char": "s",
        "block": "minecraft:cyan_terracotta"
      },
      {
        "char": "u",
        "block": "minecraft:cobbled_deepslate"
      },
      {
        "char": "l",
        "block": "minecraft:dirt"
      },
      {
        "char": "Κ",
        "block": "minecraft:cobblestone_slab[type=double,waterlogged=false,weathering=false]"
      },
      {
        "char": "r",
        "block": "minecraft:blackstone"
      },
      {
        "char": "O",
        "block": "minecraft:air"
      },
      {
        "char": "ώ",
        "block": "minecraft:deepslate[axis=x]"
      },
      {
        "char": "q",
        "block": "minecraft:air"
      },
      {
        "char": "d",
        "block": "minecraft:vine[east=true,north=false,south=false,up=false,west=false]"
      },
      {
        "char": "n",
        "block": "minecraft:cracked_stone_bricks"
      },
      {
        "char": "c",
        "block": "minecraft:mossy_cobblestone"
      },
      {
        "char": "b",
        "block": "minecraft:cobblestone[weathering=false]"
      },
      {
        "char": "m",
        "block": "minecraft:mossy_stone_bricks"
      },
      {
        "char": "k",
        "block": "minecraft:stone_bricks[weathering=false]"
      },
      {
        "char": "ϐ",
        "block": "minecraft:air"
      },
      {
        "char": "e",
        "block": "minecraft:stone[weathering=false]"
      },
      {
        "char": "g",
        "block": "minecraft:vine[east=false,north=true,south=false,up=false,west=false]"
      },
      {
        "char": "y",
        "block": "minecraft:vine[east=true,north=true,south=true,up=false,west=false]"
      },
      {
        "char": "v",
        "block": "minecraft:bookshelf"
      },
      {
        "char": "a",
        "block": "minecraft:smooth_stone_slab[type=double,waterlogged=false]"
      },
      {
        "char": "j",
        "block": "minecraft:glass_pane[east=false,north=true,south=true,waterlogged=false,west=false]"
      },
      {
        "char": "ϒ",
        "block": "minecraft:air"
      },
      {
        "char": "i",
        "block": "minecraft:glass_pane[east=true,north=false,south=false,waterlogged=false,west=true]"
      },
      {
        "char": "p",
        "block": "minecraft:vine[east=true,north=false,south=false,up=false,west=true]"
      },
      {
        "char": "Ϥ",
        "block": "minecraft:polished_diorite_slab[type=bottom,waterlogged=false]"
      }
    ]
  },
  "slices": [
    [
      "txosxuoxollΚllll",
      "ttotoxssulllllll",
      "xttrostoslllllll",
      "sotorootulllllll",
      "tottrstotllxllll",
      "suroooosullxxlll",
      "ruusxtouulllllll",
      "stouxrstrlllllll",
      "tsttoxxstroOOOOo",
      "tssuuxrtrstsstox",
      "otossxsurxorosru",
      "srusoxorxsorussu",
      "oώuoroxtsxtotrtu",
      "srurtsurorttosst",
      "ώusoouttotsuouts",
      "srώurxostortorxo"
    ],
    [
      " qq q  qdncbbbbb",
      "     q  dncbbbbb",
      "qq       mcbbbbb",
      "    q   dmbbbbbb",
      "        dkcϐbbbb",
      "q        meϐϐbbb",
      "    q    nbebccb",
      " q  q  qdknmmmmm",
      "     qq  gq gg  ",
      "     q      q qq",
      "     q   q      ",
      "     q qq       ",
      "      q  qq     ",
      "    q          q",
      "                ",
      "    qq        q "
    ],
    [
      "        dyevbbbb",
      "        dab bbbb",
      "         yj bbbb",
      "        dac  bbb",
      "        daeϒ  bb",
      "          jϒϒ  b",
      "          miceic",
      "        da daapa",
      "         g  gg  ",
      "                ",
      "                ",
      "                ",
      "                ",
      "                ",
      "                ",
      "                "
    ],
    [
      "        dybvvϤbb",
      "        dac  bbb",
      "         yj   bb",
      "        dac     ",
      "        dab     ",
      "          j     ",
      "          kiecic",
      "        da daapa",
      "         g  gg  ",
      "                ",
      "                ",
      "                ",
      "                ",
      "                ",
      "                ",
      "                "
    ],
    [
      "        dyc   bb",
      "        dae   bb",
      "         yj    b",
      "        dab     ",
      "        dac     ",
      "          j     ",
      "          miccie",
      "        da daapa",
      "         g  gg  ",
      "                ",
      "                ",
      "                ",
      "                ",
      "                ",
      "                ",
      "                "
    ],
    [
      "        dye    b",
      "        dab   Ϥb",
      "         yj     ",
      "        dae     ",
      "        dae     ",
      "          j     ",
      "          kicbic",
      "        da daapa",
      "         g  gg  ",
      "                ",
      "                ",
      "                ",
      "                ",
      "                ",
      "                ",
      "                "
    ]
  ]
}