{
  "xsize": 16,
  "zsize": 16,
  "palette": {
    "palette": [
      {
        "char": " ",
        "block": "minecraft:air"
      },
      {
        "char": "c",
        "block": "minecraft:vine[east=false,north=false,south=true,up=false,west=false]"
      },
      {
        "char": "i",
        "block": "minecraft:mossy_stone_bricks"
      },
      {
        "char": "g",
        "block": "minecraft:glass_pane[east=true,north=false,south=false,waterlogged=false,west=true]"
      },
      {
        "char": "a",
        "block": "minecraft:cobblestone[weathering=false]"
      },
      {
        "char": "Л",
        "block": "minecraft:dark_oak_fence[east=false,north=false,south=false,waterlogged=false,west=false]"
      },
      {
        "char": "d",
        "block": "minecraft:mossy_cobblestone"
      },
      {
        "char": "b",
        "block": "minecraft:stone[weathering=false]"
      },
      {
        "char": "h",
        "block": "minecraft:cracked_stone_bricks"
      },
      {
        "char": "Б",
        "block": "minecraft:glass_pane[east=false,north=false,south=true,waterlogged=false,west=false]"
      },
      {
        "char": "Q",
        "block": "minecraft:crafting_table"
      },
      {
        "char": "T",
        "block": "minecraft:flower_pot"
      },
      {
        "char": "e",
        "block": "minecraft:stone_bricks[weathering=false]"
      },
      {
        "char": "C",
        "block": "minecraft:redstone_lamp[lit=false]"
      },
      {
        "char": "j",
        "block": "minecraft:light_gray_carpet"
      },
      {
        "char": "I",
        "block": "minecraft:glass_pane[east=true,north=true,south=true,waterlogged=false,west=false]"
      },
      {
        "char": "f",
        "block": "minecraft:glass_pane[east=false,north=true,south=true,waterlogged=false,west=false]"
      },
      {
        "char": "你",
        "block": "minecraft:sea_pickle[pickles=4,waterlogged=false]"
      },
      {
        "char": "У",
        "block": "minecraft:stone_button[face=floor,facing=north,powered=false]"
      },
      {
        "char": "σ",
        "block": "minecraft:cobblestone_slab[type=bottom,waterlogged=false,weathering=false]"
      },
      {
        "char": "б",
        "block": "minecraft:sea_pickle[pickles=2,waterlogged=false]"
      },
      {
        "char": "л",
        "block": "minecraft:stone_button[face=floor,facing=south,powered=false]"
      },
      {
        "char": "Ғ",
        "block": "minecraft:stone_button[face=floor,facing=west,powered=false]"
      },
      {
        "char": "Я",
        "block": "minecraft:stone_button[face=floor,facing=east,powered=false]"
      }
    ]
  },
  "slices": [
    [
      "                ",
      "                ",
      "                ",
      "                ",
      "                ",
      "                ",
      "                ",
      "        ccc c cc",
      "             igi",
      "                ",
      "       a        ",
      "         Л      ",
      "                ",
      "                ",
      "                ",
      "         Л      "
    ],
    [
      "                ",
      "                ",
      "                ",
      "                ",
      "                ",
      "                ",
      "                ",
      "        ccc c cc",
      "            ddaa",
      "          ababaa",
      "       ab  abbbb",
      "        abaababb",
      "        abaaabab",
      "       ababbbbab",
      "        bbaaabbb",
      "       aabaaabba"
    ],
    [
      "                ",
      "                ",
      "                ",
      "                ",
      "                ",
      "                ",
      "                ",
      "        ccc c cc",
      "           ighgh",
      "       Б   Q QT ",
      "       e    QC j",
      "       IQT QQ bQ",
      "       e aa jTbb",
      "       fjaj aa你a",
      "       iQjbQ Уba",
      "       fjaTУQQσj"
    ],
    [
      "                ",
      "                ",
      "                ",
      "                ",
      "                ",
      "                ",
      "                ",
      "        ccc c cc",
      "       egighghge",
      "       f     T  ",
      "       e        ",
      "       IQ  Q    ",
      "       i aб   bT",
      "       f σ  a  л",
      "       h  Ғ    a",
      "       f a      "
    ],
    [
      "                ",
      "                ",
      "                ",
      "                ",
      "                ",
      "                ",
      "                ",
      "        ccc c cc",
      "       daadaadad",
      "       a        ",
      "       a        ",
      "       dT       ",
      "       d      Я ",
      "       d        ",
      "       d        ",
      "       a        "
    ],
    [
      "                ",
      "                ",
      "                ",
      "                ",
      "                ",
      "                ",
      "                ",
      "        ccc c cc",
      "       egigeghge",
      "       f        ",
      "       i  C     ",
      "       f        ",
      "       i        ",
      "       f        ",
      "       h        ",
      "       f        "
    ]
  ]
}