{
  "xsize": 16,
  "zsize": 16,
  "palette": {
    "palette": [
      {
        "char": " ",
        "block": "minecraft:air"
      },
      {
        "char": "c",
        "block": "minecraft:vine[east=false,north=false,south=true,up=false,west=false]"
      },
      {
        "char": "g",
        "block": "minecraft:glass_pane[east=true,north=false,south=false,waterlogged=false,west=true]"
      },
      {
        "char": "h",
        "block": "minecraft:cracked_stone_bricks"
      },
      {
        "char": "e",
        "block": "minecraft:stone_bricks[weathering=false]"
      },
      {
        "char": "f",
        "block": "minecraft:glass_pane[east=false,north=true,south=true,waterlogged=false,west=false]"
      },
      {
        "char": "i",
        "block": "minecraft:mossy_stone_bricks"
      },
      {
        "char": "a",
        "block": "minecraft:cobblestone[weathering=false]"
      },
      {
        "char": "d",
        "block": "minecraft:mossy_cobblestone"
      },
      {
        "char": "b",
        "block": "minecraft:stone[weathering=false]"
      },
      {
        "char": "Q",
        "block": "minecraft:crafting_table"
      },
      {
        "char": "C",
        "block": "minecraft:redstone_lamp[lit=false]"
      },
      {
        "char": "Ғ",
        "block": "minecraft:stone_button[face=floor,facing=west,powered=false]"
      },
      {
        "char": "j",
        "block": "minecraft:light_gray_carpet"
      },
      {
        "char": "σ",
        "block": "minecraft:cobblestone_slab[type=bottom,waterlogged=false,weathering=false]"
      },
      {
        "char": "л",
        "block": "minecraft:stone_button[face=floor,facing=south,powered=false]"
      },
      {
        "char": "x",
        "block": "minecraft:cobblestone_stairs[facing=north,half=bottom,shape=straight,waterlogged=false,weathering=false]"
      },
      {
        "char": "д",
        "block": "minecraft:sea_pickle[pickles=3,waterlogged=false]"
      },
      {
        "char": "Ѩ",
        "block": "minecraft:sea_pickle[pickles=1,waterlogged=false]"
      },
      {
        "char": "l",
        "block": "minecraft:bookshelf"
      },
      {
        "char": "T",
        "block": "minecraft:flower_pot"
      },
      {
        "char": "Я",
        "block": "minecraft:stone_button[face=floor,facing=east,powered=false]"
      }
    ]
  },
  "slices": [
    [
      "                ",
      "                ",
      "                ",
      "                ",
      "                ",
      "                ",
      "                ",
      "ccc cccc        ",
      "ghghgege        ",
      "       f        ",
      "       i        ",
      "       f        ",
      "       e        ",
      "       f        ",
      "       i        ",
      "       f        "
    ],
    [
      "                ",
      "                ",
      "                ",
      "                ",
      "                ",
      "                ",
      "                ",
      "ccc cccc        ",
      "adaadada        ",
      "bbbbbbba        ",
      "aaaabaaa        ",
      "bbababba        ",
      "aabbabad        ",
      "abbbbbbd        ",
      "bbababaa        ",
      "abbbaaba        "
    ],
    [
      "                ",
      "                ",
      "                ",
      "                ",
      "                ",
      "                ",
      "                ",
      "ccc cccc        ",
      "gigegigi        ",
      " Q     f        ",
      "Q QCaaai        ",
      "ҒQ ja  f        ",
      "jQjQa  h        ",
      " jσ a  f        ",
      "jjjja  e        ",
      " Q лxxxf        "
    ],
    [
      "                ",
      "                ",
      "                ",
      "                ",
      "                ",
      "                ",
      "                ",
      "ccc cccc        ",
      "gigighgi        ",
      " Q     f        ",
      "д QѨaaae        ",
      "     l f        ",
      " T  дl h        ",
      "    a  f        ",
      "    xxxh        ",
      " Q     f        "
    ],
    [
      "                ",
      "                ",
      "                ",
      "                ",
      "                ",
      "                ",
      "                ",
      "ccc cccc        ",
      "adaadadd        ",
      "       a        ",
      "    aaaa        ",
      "     l a        ",
      "     l a        ",
      "    xxxa        ",
      "       d        ",
      " Я     d        "
    ],
    [
      "                ",
      "                ",
      "                ",
      "                ",
      "                ",
      "                ",
      "                ",
      "ccc cc          ",
      "ghgighge        ",
      "       f        ",
      " C  aaai        ",
      "    a  f        ",
      "    xxxi        ",
      "       f        ",
      "       e        ",
      "       f        "
    ]
  ]
}