{
  "xsize": 16,
  "zsize": 16,
  "palette": {
    "palette": [
      {
        "char": " ",
        "block": "minecraft:air"
      },
      {
        "char": "c",
        "block": "minecraft:vine[east=false,north=false,south=true,up=false,west=false]"
      },
      {
        "char": "F",
        "block": "minecraft:oak_leaves[distance=7,persistent=true,waterlogged=false]"
      },
      {
        "char": "i",
        "block": "minecraft:mossy_stone_bricks"
      },
      {
        "char": "g",
        "block": "minecraft:glass_pane[east=true,north=false,south=false,waterlogged=false,west=true]"
      },
      {
        "char": "h",
        "block": "minecraft:cracked_stone_bricks"
      },
      {
        "char": "e",
        "block": "minecraft:stone_bricks[weathering=false]"
      },
      {
        "char": "f",
        "block": "minecraft:glass_pane[east=false,north=true,south=true,waterlogged=false,west=false]"
      },
      {
        "char": "я",
        "block": "minecraft:glass_pane[east=false,north=true,south=false,waterlogged=false,west=false]"
      },
      {
        "char": "H",
        "block": "minecraft:air"
      },
      {
        "char": "υ",
        "block": "minecraft:vine[east=false,north=false,south=true,up=true,west=false]"
      },
      {
        "char": "a",
        "block": "minecraft:cobblestone[weathering=false]"
      },
      {
        "char": "d",
        "block": "minecraft:mossy_cobblestone"
      },
      {
        "char": "b",
        "block": "minecraft:stone[weathering=false]"
      },
      {
        "char": "в",
        "block": "minecraft:glass_pane[east=true,north=false,south=false,waterlogged=false,west=false]"
      },
      {
        "char": "y",
        "block": "minecraft:redstone_wire[east=side,north=side,power=0,south=side,west=side]"
      },
      {
        "char": "k",
        "block": "minecraft:red_carpet"
      },
      {
        "char": "ѱ",
        "block": "minecraft:skeleton_skull[rotation=7]",
        "tag": {
          "z": 618,
          "x": 72,
          "ForgeCaps": {},
          "id": "minecraft:skull",
          "y": 164
        }
      },
      {
        "char": "l",
        "block": "minecraft:bookshelf"
      },
      {
        "char": "҃",
        "block": "minecraft:skeleton_skull[rotation=4]",
        "tag": {
          "z": 618,
          "x": 72,
          "ForgeCaps": {},
          "id": "minecraft:skull",
          "y": 200
        }
      }
    ]
  },
  "slices": [
    [
      "                ",
      "                ",
      "                ",
      "                ",
      "                ",
      "                ",
      "                ",
      "        cccc Fcc",
      "       ighgegigh",
      "       f        ",
      "       h        ",
      "       я        ",
      "                ",
      "           H  H ",
      "                ",
      "                "
    ],
    [
      "                ",
      "                ",
      "                ",
      "                ",
      "                ",
      "                ",
      "                ",
      "        cccυF cc",
      "        addddaad",
      "        adaaabbb",
      "       dbdaaabab",
      "       abbabbbbb",
      "        bbbabbbb",
      "        abaabaaa",
      "        bbabaaaa",
      "        baaaaaaa"
    ],
    [
      "                ",
      "                ",
      "                ",
      "                ",
      "                ",
      "                ",
      "                ",
      "        cccF  cc",
      "        вhghgigi",
      "          yk  k ",
      "        ѱ kk kk ",
      "         ky k   ",
      "         y k  k ",
      "         k      ",
      "        k  lllyl",
      "         kk ҃   "
    ],
    [
      "                ",
      "                ",
      "                ",
      "                ",
      "                ",
      "                ",
      "                ",
      "        ccccF cc",
      "        вighgegh",
      "                ",
      "                ",
      "                ",
      "       i        ",
      "                ",
      "       i   lll l",
      "                "
    ],
    [
      "                ",
      "                ",
      "                ",
      "                ",
      "                ",
      "                ",
      "                ",
      "        cccυυFcc",
      "        aaaaddda",
      "                ",
      "       a        ",
      "       d        ",
      "       a        ",
      "       d        ",
      "       d   lll l",
      "       a        "
    ],
    [
      "                ",
      "                ",
      "                ",
      "                ",
      "                ",
      "                ",
      "                ",
      "        cc FF cc",
      "       hghgigige",
      "       f        ",
      "       i        ",
      "       f        ",
      "       h        ",
      "       f        ",
      "       h        ",
      "       f        "
    ]
  ]
}