{
  "xsize": 16,
  "zsize": 16,
  "palette": {
    "palette": [
      {
        "char": " ",
        "block": "minecraft:air"
      },
      {
        "char": "e",
        "block": "minecraft:air"
      },
      {
        "char": "ϯ",
        "block": "minecraft:air"
      },
      {
        "char": "I",
        "block": "minecraft:air"
      },
      {
        "char": "i",
        "block": "minecraft:air"
      },
      {
        "char": "h",
        "block": "minecraft:air"
      },
      {
        "char": "a",
        "block": "minecraft:air"
      },
      {
        "char": "b",
        "block": "minecraft:air"
      },
      {
        "char": "d",
        "block": "minecraft:air"
      },
      {
        "char": "E",
        "block": "minecraft:air"
      },
      {
        "char": "φ",
        "block": "minecraft:air"
      },
      {
        "char": "Ϛ",
        "block": "minecraft:air"
      },
      {
        "char": "τ",
        "block": "minecraft:air"
      },
      {
        "char": "ϵ",
        "block": "minecraft:air"
      },
      {
        "char": "Ή",
        "block": "minecraft:air"
      },
      {
        "char": "k",
        "block": "minecraft:air"
      },
      {
        "char": "q",
        "block": "minecraft:air"
      },
      {
        "char": "Ϻ",
        "block": "minecraft:air"
      },
      {
        "char": "ј",
        "block": "minecraft:air"
      },
      {
        "char": "Ѹ",
        "block": "minecraft:air"
      },
      {
        "char": "є",
        "block": "minecraft:air",
        "loot": "bigbuildingsloot",
        "tag": {
          "z": 617,
          "x": 72,
          "ForgeData": {
            "LockFlag": "1b"
          },
          "ForgeCaps": {},
          "id": "minecraft:chest",
          "y": 133,
          "Items": []
        }
      },
      {
        "char": "Ѓ",
        "block": "minecraft:air"
      },
      {
        "char": "ы",
        "block": "minecraft:air"
      },
      {
        "char": "r",
        "block": "minecraft:air"
      },
      {
        "char": "п",
        "block": "minecraft:air"
      },
      {
        "char": "Р",
        "block": "minecraft:tall_grass[half=lower]"
      },
      {
        "char": "Ϸ",
        "block": "minecraft:air"
      },
      {
        "char": "К",
        "block": "minecraft:air"
      },
      {
        "char": "Т",
        "block": "minecraft:air"
      },
      {
        "char": "Џ",
        "block": "minecraft:air"
      },
      {
        "char": "ӑ",
        "block": "minecraft:air",
        "tag": {
          "z": 628,
          "x": 80,
          "ForgeCaps": {},
          "id": "minecraft:skull",
          "y": 225
        }
      },
      {
        "char": "м",
        "block": "minecraft:air"
      },
      {
        "char": "С",
        "block": "minecraft:tall_grass[half=upper]"
      },
      {
        "char": "Ў",
        "block": "minecraft:air"
      },
      {
        "char": "m",
        "block": "minecraft:air"
      },
      {
        "char": "C",
        "block": "minecraft:air"
      },
      {
        "char": "Ѕ",
        "block": "minecraft:air"
      },
      {
        "char": "Л",
        "block": "minecraft:air"
      }
    ]
  },
  "slices": [
    [
      "        e       ",
      "        e       ",
      "       ee       ",
      "       ee       ",
      "ϯ      ee       ",
      "       Ie       ",
      "       ie       ",
      "       ee       ",
      "eheeeieee       ",
      "eeeeeeee        ",
      "                ",
      "                ",
      "                ",
      "                ",
      "                ",
      "                "
    ],
    [
      "ababbabdEφ      ",
      "babaabbaEφ      ",
      "aaabbbbdϚ       ",
      "bbababaa        ",
      "abababbdτ       ",
      "aaabbbadEφ      ",
      "aabbaaaaEφ      ",
      "bbabaabdϚ       ",
      "aaaaaddd        ",
      "Eφ ϵEEφ         ",
      "Ϛ   ϚϚ          ",
      "                ",
      "                ",
      "                ",
      "                ",
      "                "
    ],
    [
      " Ήk k kqϺ       ",
      "Ήk Ήkk q        ",
      "   k Ήkq        ",
      "ΉΉ Ήk Ήq        ",
      "јјѸk Ήkq        ",
      "ΉєѸk kΉqϺ       ",
      " kЃΉ ыrпР       ",
      " ϷEКkqТq        ",
      "rrЏrrЏre        ",
      "Р   ϺϺ          ",
      "                ",
      "                ",
      "                ",
      "                ",
      "                ",
      "                "
    ],
    [
      "       q        ",
      "       q        ",
      "       q        ",
      "       q        ",
      "ӑ м    q        ",
      "       q        ",
      "     ыrпС       ",
      "  Ў  qТq        ",
      "rrrrrЏre        ",
      "С   mm          ",
      "                ",
      "                ",
      "                ",
      "                ",
      "                ",
      "                "
    ],
    [
      "  Ѓ    q        ",
      " ϷCК   q        ",
      "  Ѕ    q        ",
      "       q        ",
      "       q        ",
      "       q        ",
      "     ыrп        ",
      "  Ў  qТq        ",
      "rrrrrЏre        ",
      "    mm          ",
      "                ",
      "                ",
      "                ",
      "                ",
      "                ",
      "                "
    ],
    [
      "       q        ",
      "  Л    q        ",
      "       q        ",
      "       q        ",
      "       q        ",
      "       q        ",
      "     ыrп        ",
      "  Ў  qТq        ",
      "rrrrrЏre        ",
      "    mm          ",
      "                ",
      "                ",
      "                ",
      "                ",
      "                ",
      "                "
    ]
  ]
}