{
  "xsize": 16,
  "zsize": 16,
  "palette": {
    "palette": [
      {
        "char": " ",
        "block": "minecraft:air"
      },
      {
        "char": "c",
        "block": "minecraft:vine[east=false,north=false,south=true,up=false,west=false]"
      },
      {
        "char": "F",
        "block": "minecraft:oak_leaves[distance=7,persistent=true,waterlogged=false]"
      },
      {
        "char": "υ",
        "block": "minecraft:vine[east=false,north=false,south=true,up=true,west=false]"
      },
      {
        "char": "g",
        "block": "minecraft:glass_pane[east=true,north=false,south=false,waterlogged=false,west=true]"
      },
      {
        "char": "e",
        "block": "minecraft:stone_bricks[weathering=false]"
      },
      {
        "char": "h",
        "block": "minecraft:cracked_stone_bricks"
      },
      {
        "char": "i",
        "block": "minecraft:mossy_stone_bricks"
      },
      {
        "char": "o",
        "block": "minecraft:vine[east=false,north=false,south=false,up=false,west=true]"
      },
      {
        "char": "f",
        "block": "minecraft:glass_pane[east=false,north=true,south=true,waterlogged=false,west=false]"
      },
      {
        "char": "d",
        "block": "minecraft:mossy_cobblestone"
      },
      {
        "char": "a",
        "block": "minecraft:cobblestone[weathering=false]"
      },
      {
        "char": "b",
        "block": "minecraft:stone[weathering=false]"
      },
      {
        "char": "ϯ",
        "block": "minecraft:cobblestone_slab[type=double,waterlogged=false,weathering=false]"
      },
      {
        "char": "J",
        "block": "minecraft:glass_pane[east=true,north=false,south=true,waterlogged=false,west=true]"
      },
      {
        "char": "l",
        "block": "minecraft:bookshelf"
      },
      {
        "char": "ѱ",
        "block": "minecraft:skeleton_skull[rotation=7]",
        "tag": {
          "z": 618,
          "x": 72,
          "ForgeCaps": {},
          "id": "minecraft:skull",
          "y": 164
        }
      },
      {
        "char": "Ί",
        "block": "minecraft:glass_pane[east=false,north=true,south=true,waterlogged=false,west=true]"
      },
      {
        "char": "Ё",
        "block": "minecraft:redstone_wire[east=none,north=side,power=0,south=side,west=none]"
      },
      {
        "char": "y",
        "block": "minecraft:redstone_wire[east=side,north=side,power=0,south=side,west=side]"
      },
      {
        "char": "x",
        "block": "minecraft:cobblestone_stairs[facing=north,half=bottom,shape=straight,waterlogged=false,weathering=false]"
      },
      {
        "char": "ѹ",
        "block": "minecraft:dark_oak_fence[east=false,north=false,south=true,waterlogged=false,west=false]"
      },
      {
        "char": "ғ",
        "block": "minecraft:dark_oak_fence[east=false,north=true,south=false,waterlogged=false,west=false]"
      },
      {
        "char": "и",
        "block": "minecraft:dark_oak_fence[east=false,north=false,south=true,waterlogged=false,west=true]"
      },
      {
        "char": "Ϲ",
        "block": "minecraft:dark_oak_fence[east=false,north=true,south=true,waterlogged=false,west=false]"
      }
    ]
  },
  "slices": [
    [
      "                ",
      "                ",
      "                ",
      "                ",
      "                ",
      "                ",
      "                ",
      "ccFυcccc        ",
      "geghgigho       ",
      "       f        ",
      "       e        ",
      "       f        ",
      "       i        ",
      "       f        ",
      "       h        ",
      "       f        "
    ],
    [
      "                ",
      "                ",
      "                ",
      "                ",
      "                ",
      "                ",
      "                ",
      "cccFυccc        ",
      "daaaadado       ",
      "bbabbaba        ",
      "abϯababa        ",
      "aaababbd        ",
      "bbbbaaad        ",
      "baaaabba        ",
      "abbbbaaa        ",
      "baabaabd        "
    ],
    [
      "                ",
      "                ",
      "                ",
      "                ",
      "                ",
      "                ",
      "                ",
      "ccccFυcc        ",
      "JhgeJhJio       ",
      "lѱ laaaΊ        ",
      "lЁ laaah        ",
      " Ё la  f        ",
      "l yla  e        ",
      "ly la  f        ",
      "l  la  h        ",
      "l   xxxf        "
    ],
    [
      "                ",
      "                ",
      "                ",
      "                ",
      "                ",
      "                ",
      "                ",
      "cccccFcc        ",
      "JigeJeJho       ",
      "l  laaaΊ        ",
      "l  laaae        ",
      "   la  f        ",
      "l  la  h        ",
      "l  la  f        ",
      "l   xxxi        ",
      "l      f        "
    ],
    [
      "                ",
      "                ",
      "                ",
      "                ",
      "                ",
      "                ",
      "                ",
      "cccccccc        ",
      "aaadadddo       ",
      "l  laaaa        ",
      "l  laaaa        ",
      "   la  a        ",
      "l  la  d        ",
      "l   xxxa        ",
      "l      d        ",
      "l      a        "
    ],
    [
      "                ",
      "                ",
      "                ",
      "                ",
      "                ",
      "                ",
      "                ",
      "cccccccc        ",
      "gh hJe io       ",
      "ѹ  laaaΊ        ",
      "ғ  laaai        ",
      "   la  f        ",
      "и   xxxi        ",
      "Ϲ      f        ",
      "Ϲ      i        ",
      "Ϲ      f        "
    ]
  ]
}