{
  "xsize": 16,
  "zsize": 16,
  "palette": {
    "palette": [
      {
        "char": " ",
        "block": "minecraft:air"
      },
      {
        "char": "i",
        "block": "minecraft:mossy_stone_bricks"
      },
      {
        "char": "ъ",
        "block": "minecraft:dark_oak_fence[east=true,north=false,south=true,waterlogged=false,west=false]"
      },
      {
        "char": "f",
        "block": "minecraft:glass_pane[east=false,north=true,south=true,waterlogged=false,west=false]"
      },
      {
        "char": "Ф",
        "block": "minecraft:dark_oak_fence[east=true,north=true,south=false,waterlogged=false,west=false]"
      },
      {
        "char": "h",
        "block": "minecraft:cracked_stone_bricks"
      },
      {
        "char": "u",
        "block": "minecraft:cobblestone_stairs[facing=south,half=bottom,shape=straight,waterlogged=false,weathering=false]"
      },
      {
        "char": "a",
        "block": "minecraft:cobblestone[weathering=false]"
      },
      {
        "char": "g",
        "block": "minecraft:glass_pane[east=true,north=false,south=false,waterlogged=false,west=true]"
      },
      {
        "char": "d",
        "block": "minecraft:mossy_cobblestone"
      },
      {
        "char": "b",
        "block": "minecraft:stone[weathering=false]"
      },
      {
        "char": "j",
        "block": "minecraft:light_gray_carpet"
      },
      {
        "char": "C",
        "block": "minecraft:redstone_lamp[lit=false]"
      },
      {
        "char": "I",
        "block": "minecraft:glass_pane[east=true,north=true,south=true,waterlogged=false,west=false]"
      },
      {
        "char": "σ",
        "block": "minecraft:cobblestone_slab[type=bottom,waterlogged=false,weathering=false]"
      },
      {
        "char": "T",
        "block": "minecraft:flower_pot"
      },
      {
        "char": "e",
        "block": "minecraft:stone_bricks[weathering=false]"
      },
      {
        "char": "о",
        "block": "minecraft:air"
      },
      {
        "char": "Ј",
        "block": "minecraft:air"
      },
      {
        "char": "Љ",
        "block": "minecraft:air"
      },
      {
        "char": "ҋ",
        "block": "minecraft:air"
      },
      {
        "char": "Я",
        "block": "minecraft:stone_button[face=floor,facing=east,powered=false]"
      },
      {
        "char": "Q",
        "block": "minecraft:crafting_table"
      },
      {
        "char": "χ",
        "block": "minecraft:air"
      },
      {
        "char": "Ͽ",
        "block": "minecraft:air"
      },
      {
        "char": "Ғ",
        "block": "minecraft:stone_button[face=floor,facing=west,powered=false]"
      },
      {
        "char": "个",
        "block": "minecraft:stone_button[face=wall,facing=east,powered=false]"
      },
      {
        "char": "Є",
        "block": "minecraft:air"
      },
      {
        "char": "б",
        "block": "minecraft:sea_pickle[pickles=2,waterlogged=false]"
      },
      {
        "char": "л",
        "block": "minecraft:stone_button[face=floor,facing=south,powered=false]"
      },
      {
        "char": "У",
        "block": "minecraft:stone_button[face=floor,facing=north,powered=false]"
      }
    ]
  },
  "slices": [
    [
      "       i       ъ",
      "       f       Ф",
      "       h        ",
      "       f        ",
      "       h        ",
      "       fuuu    ъ",
      "       haaa    Ф",
      "       f        ",
      "       igi      ",
      "                ",
      "                ",
      "                ",
      "                ",
      "                ",
      "                ",
      "                "
    ],
    [
      "       daabbbbba",
      "       ababbabab",
      "       dbbaababb",
      "       d   aabab",
      "       d   ababb",
      "       d   aabba",
      "       duuubbaab",
      "       dbabb aab",
      "       aaad     ",
      "                ",
      "                ",
      "                ",
      "                ",
      "                ",
      "                ",
      "                "
    ],
    [
      "       iabaj jCb",
      "       IbjσjbbT ",
      "       eоЈЉҋЯQba",
      "       f   χjCσa",
      "       h   Ͽ Ғba",
      "       f   χQj a",
      "       i个  ЄбjT ",
      "       f jлj  Qj",
      "       ege      ",
      "                ",
      "                ",
      "                ",
      "                ",
      "                ",
      "                ",
      "                "
    ],
    [
      "       eQ T    У",
      "       f     Q  ",
      "       iT  T бb ",
      "       f       a",
      "       h       Q",
      "       f    T   ",
      "       h        ",
      "       f        ",
      "       ege      ",
      "                ",
      "                ",
      "                ",
      "                ",
      "                ",
      "                ",
      "                "
    ],
    [
      "       a        ",
      "       d        ",
      "       a      Я ",
      "       d       У",
      "       d        ",
      "       a        ",
      "       d        ",
      "       d        ",
      "       ada      ",
      "                ",
      "                ",
      "                ",
      "                ",
      "                ",
      "                ",
      "                "
    ],
    [
      "       h        ",
      "       f        ",
      "       i        ",
      "       f        ",
      "       i  C     ",
      "       f        ",
      "       e        ",
      "       f        ",
      "       egh      ",
      "                ",
      "                ",
      "                ",
      "                ",
      "                ",
      "                ",
      "                "
    ]
  ]
}