{
  "xsize": 16,
  "zsize": 16,
  "palette": {
    "palette": [
      {
        "char": " ",
        "block": "minecraft:air"
      },
      {
        "char": "e",
        "block": "minecraft:stone_bricks[weathering=false]"
      },
      {
        "char": "f",
        "block": "minecraft:glass_pane[east=false,north=true,south=true,waterlogged=false,west=false]"
      },
      {
        "char": "h",
        "block": "minecraft:cracked_stone_bricks"
      },
      {
        "char": "g",
        "block": "minecraft:glass_pane[east=true,north=false,south=false,waterlogged=false,west=true]"
      },
      {
        "char": "i",
        "block": "minecraft:mossy_stone_bricks"
      },
      {
        "char": "a",
        "block": "minecraft:cobblestone[weathering=false]"
      },
      {
        "char": "b",
        "block": "minecraft:stone[weathering=false]"
      },
      {
        "char": "d",
        "block": "minecraft:mossy_cobblestone"
      },
      {
        "char": "k",
        "block": "minecraft:red_carpet"
      },
      {
        "char": "y",
        "block": "minecraft:redstone_wire[east=side,north=side,power=0,south=side,west=side]"
      },
      {
        "char": "u",
        "block": "minecraft:cobblestone_stairs[facing=south,half=bottom,shape=straight,waterlogged=false,weathering=false]"
      },
      {
        "char": "l",
        "block": "minecraft:bookshelf"
      },
      {
        "char": "P",
        "block": "minecraft:glass_pane[east=true,north=true,south=false,waterlogged=false,west=true]"
      },
      {
        "char": "I",
        "block": "minecraft:glass_pane[east=true,north=true,south=true,waterlogged=false,west=false]"
      },
      {
        "char": "ϯ",
        "block": "minecraft:cobblestone_slab[type=double,waterlogged=false,weathering=false]"
      }
    ]
  },
  "slices": [
    [
      "                ",
      "                ",
      "       e        ",
      "       f        ",
      "       e        ",
      "       f        ",
      "       h        ",
      "       f        ",
      "       egighgegh",
      "                ",
      "                ",
      "                ",
      "                ",
      "                ",
      "                ",
      "                "
    ],
    [
      "        abababab",
      "       dabbbaaba",
      "       dbabbabab",
      "       dababbaab",
      "       dbaabbaba",
      "       aabbaabbb",
      "       aaababbba",
      "       dabbabbab",
      "       dadaadada",
      "                ",
      "                ",
      "                ",
      "                ",
      "                ",
      "                ",
      "                "
    ],
    [
      "        k   y y ",
      "        uuulll l",
      "       e  al    ",
      "       f  al    ",
      "       e  al  l ",
      "       f aal  l ",
      "       eaaal  l ",
      "       f   l  l ",
      "       hgigegiPi",
      "                ",
      "                ",
      "                ",
      "                ",
      "                ",
      "                ",
      "                "
    ],
    [
      "       h        ",
      "           lll l",
      "       iuuul    ",
      "       f  al    ",
      "       h  al  l ",
      "       Iaaal  l ",
      "       eaaal  l ",
      "       f   l  l ",
      "       hgigeghPh",
      "                ",
      "                ",
      "                ",
      "                ",
      "                ",
      "                ",
      "                "
    ],
    [
      "       d        ",
      "       d   lll l",
      "       d   l    ",
      "       duuul    ",
      "       d  al  l ",
      "       aaaal  l ",
      "       aaaal  l ",
      "       d   l  l ",
      "       daadaaaad",
      "                ",
      "                ",
      "                ",
      "                ",
      "                ",
      "                ",
      "                "
    ],
    [
      "       i        ",
      "       f        ",
      "       e        ",
      "       f        ",
      "       huuu     ",
      "       Iaaa     ",
      "       haaa     ",
      "       f  ϯ     ",
      "       igePegige",
      "                ",
      "                ",
      "                ",
      "                ",
      "                ",
      "                ",
      "                "
    ]
  ]
}