{
  "xsize": 16,
  "zsize": 16,
  "palette": {
    "palette": [
      {
        "char": " ",
        "block": "minecraft:air"
      },
      {
        "char": "h",
        "block": "minecraft:cracked_stone_bricks"
      },
      {
        "char": "f",
        "block": "minecraft:glass_pane[east=false,north=true,south=true,waterlogged=false,west=false]"
      },
      {
        "char": "i",
        "block": "minecraft:mossy_stone_bricks"
      },
      {
        "char": "g",
        "block": "minecraft:glass_pane[east=true,north=false,south=false,waterlogged=false,west=true]"
      },
      {
        "char": "a",
        "block": "minecraft:cobblestone[weathering=false]"
      },
      {
        "char": "b",
        "block": "minecraft:stone[weathering=false]"
      },
      {
        "char": "d",
        "block": "minecraft:mossy_cobblestone"
      },
      {
        "char": "k",
        "block": "minecraft:red_carpet"
      },
      {
        "char": "u",
        "block": "minecraft:cobblestone_stairs[facing=south,half=bottom,shape=straight,waterlogged=false,weathering=false]"
      },
      {
        "char": "e",
        "block": "minecraft:stone_bricks[weathering=false]"
      },
      {
        "char": "l",
        "block": "minecraft:bookshelf"
      },
      {
        "char": "S",
        "block": "minecraft:oak_slab[type=double,waterlogged=false]"
      },
      {
        "char": "Ѻ",
        "block": "minecraft:oak_slab[type=top,waterlogged=false]"
      },
      {
        "char": "Ϊ",
        "block": "minecraft:oak_wall_sign[facing=west,waterlogged=false]",
        "tag": {
          "z": 621,
          "x": 75,
          "is_waxed": "0b",
          "ForgeCaps": {
            "supplementaries:antique_ink": {
              "ink": "0b"
            }
          },
          "id": "minecraft:sign",
          "y": 219,
          "front_text": {
            "color": "black",
            "has_glowing_text": "0b",
            "messages": [
              "{\"extra\":[{\"text\":\"D. Herron\"}],\"text\":\"\"}",
              "{\"text\":\"\"}",
              "{\"text\":\"\"}",
              "{\"text\":\"\"}"
            ]
          },
          "back_text": {
            "color": "black",
            "has_glowing_text": "0b",
            "messages": [
              "{\"text\":\"\"}",
              "{\"text\":\"\"}",
              "{\"text\":\"\"}",
              "{\"text\":\"\"}"
            ]
          }
        }
      },
      {
        "char": "τ",
        "block": "minecraft:dark_oak_trapdoor[facing=north,half=bottom,open=true,powered=false,waterlogged=false]"
      },
      {
        "char": "ϴ",
        "block": "minecraft:spruce_log[axis=y]"
      },
      {
        "char": "φ",
        "block": "minecraft:dark_oak_trapdoor[facing=east,half=bottom,open=true,powered=false,waterlogged=false]"
      },
      {
        "char": "д",
        "block": "minecraft:sea_pickle[pickles=3,waterlogged=false]"
      },
      {
        "char": "϶",
        "block": "minecraft:dark_oak_leaves[distance=1,persistent=true,waterlogged=false]"
      },
      {
        "char": "ϸ",
        "block": "minecraft:dark_oak_leaves[distance=2,persistent=true,waterlogged=false]"
      },
      {
        "char": "ҙ",
        "block": "minecraft:spruce_fence[east=true,north=false,south=false,waterlogged=false,west=false]"
      }
    ]
  },
  "slices": [
    [
      "       h        ",
      "       f        ",
      "       h        ",
      "       f        ",
      "       i        ",
      "       f        ",
      "       h        ",
      "       f        ",
      "       hgigighgi",
      "                ",
      "                ",
      "                ",
      "                ",
      "                ",
      "                ",
      "                "
    ],
    [
      "       aabbbaaab",
      "       abbabbaaa",
      "       aaaabbbbb",
      "       dbbaabbaa",
      "       aabbbaaba",
      "       daabaaaaa",
      "       aaabababa",
      "       aabbabbaa",
      "       ddddddadd",
      "                ",
      "                ",
      "                ",
      "                ",
      "                ",
      "                ",
      "                "
    ],
    [
      "       i k     k",
      "       fuuu   kk",
      "       e  l     ",
      "       f  l   SѺ",
      "       e  l     ",
      "       f  l    Ϊ",
      "       eaalτ    ",
      "       f   ϴφ   ",
      "       egigigige",
      "                ",
      "                ",
      "                ",
      "                ",
      "                ",
      "                ",
      "                "
    ],
    [
      "       h        ",
      "       f        ",
      "       iuuu     ",
      "       f  l    д",
      "       h  l     ",
      "       f  l     ",
      "       iaal     ",
      "       f   ϶    ",
      "       igegigigh",
      "                ",
      "                ",
      "                ",
      "                ",
      "                ",
      "                ",
      "                "
    ],
    [
      "       a        ",
      "       d        ",
      "       d        ",
      "       duuu     ",
      "       a  l     ",
      "       d  l     ",
      "       aaal     ",
      "       d   ϸ    ",
      "       dddaaddda",
      "                ",
      "                ",
      "                ",
      "                ",
      "                ",
      "                ",
      "                "
    ],
    [
      "       h        ",
      "       f       ҙ",
      "       i        ",
      "       f        ",
      "       huuu     ",
      "       f  l     ",
      "       haal     ",
      "       f        ",
      "       ighgegegh",
      "                ",
      "                ",
      "                ",
      "                ",
      "                ",
      "                ",
      "                "
    ]
  ]
}