{
  "xsize": 16,
  "zsize": 16,
  "palette": {
    "palette": [
      {
        "char": " ",
        "block": "minecraft:air"
      },
      {
        "char": "Ѝ",
        "block": "minecraft:redstone_torch[lit=true]"
      },
      {
        "char": "h",
        "block": "minecraft:cracked_stone_bricks"
      },
      {
        "char": "ї",
        "block": "minecraft:spruce_fence[east=false,north=false,south=false,waterlogged=false,west=false]"
      },
      {
        "char": "f",
        "block": "minecraft:glass_pane[east=false,north=true,south=true,waterlogged=false,west=false]"
      },
      {
        "char": "i",
        "block": "minecraft:mossy_stone_bricks"
      },
      {
        "char": "g",
        "block": "minecraft:glass_pane[east=true,north=false,south=false,waterlogged=false,west=true]"
      },
      {
        "char": "m",
        "block": "minecraft:vine[east=false,north=true,south=false,up=false,west=false]"
      },
      {
        "char": "a",
        "block": "minecraft:cobblestone[weathering=false]"
      },
      {
        "char": "b",
        "block": "minecraft:stone[weathering=false]"
      },
      {
        "char": "d",
        "block": "minecraft:mossy_cobblestone"
      },
      {
        "char": "L",
        "block": "minecraft:black_carpet"
      },
      {
        "char": "j",
        "block": "minecraft:light_gray_carpet"
      },
      {
        "char": "k",
        "block": "minecraft:red_carpet"
      },
      {
        "char": "e",
        "block": "minecraft:stone_bricks[weathering=false]"
      },
      {
        "char": "Н",
        "block": "minecraft:cauldron"
      },
      {
        "char": "y",
        "block": "minecraft:redstone_wire[east=side,north=side,power=0,south=side,west=side]"
      },
      {
        "char": "Ѓ",
        "block": "minecraft:dark_oak_trapdoor[facing=north,half=top,open=true,powered=false,waterlogged=false]"
      },
      {
        "char": "Ϸ",
        "block": "minecraft:dark_oak_trapdoor[facing=west,half=top,open=true,powered=false,waterlogged=false]"
      },
      {
        "char": "ϴ",
        "block": "minecraft:spruce_log[axis=y]"
      },
      {
        "char": "К",
        "block": "minecraft:dark_oak_trapdoor[facing=east,half=top,open=true,powered=false,waterlogged=false]"
      },
      {
        "char": "ѳ",
        "block": "minecraft:skeleton_skull[rotation=13]",
        "tag": {
          "z": 629,
          "x": 84,
          "ForgeCaps": {},
          "id": "minecraft:skull",
          "y": 219
        }
      },
      {
        "char": "Ί",
        "block": "minecraft:glass_pane[east=false,north=true,south=true,waterlogged=false,west=true]"
      },
      {
        "char": "P",
        "block": "minecraft:glass_pane[east=true,north=true,south=false,waterlogged=false,west=true]"
      },
      {
        "char": "϶",
        "block": "minecraft:dark_oak_leaves[distance=1,persistent=true,waterlogged=false]"
      },
      {
        "char": "ϸ",
        "block": "minecraft:dark_oak_leaves[distance=2,persistent=true,waterlogged=false]"
      },
      {
        "char": "Г",
        "block": "minecraft:dark_oak_leaves[distance=3,persistent=true,waterlogged=false]"
      }
    ]
  },
  "slices": [
    [
      "Ѝ      h        ",
      "їЍ     f        ",
      "Ѝ      i        ",
      "       f        ",
      "       h        ",
      "       f        ",
      "       h        ",
      "       f        ",
      "ghghghgi        ",
      "   mmm          ",
      "                ",
      "                ",
      "                ",
      "                ",
      "                ",
      "                "
    ],
    [
      "abbbbabd        ",
      "aaabbaba        ",
      "babaabaa        ",
      "abaababa        ",
      "bbababaa        ",
      "abbabaaa        ",
      "aaaaaaba        ",
      "aabbbbbd        ",
      "ddddddda        ",
      "   mmm          ",
      "                ",
      "                ",
      "                ",
      "                ",
      "                ",
      "                "
    ],
    [
      " L j k e        ",
      "j   k kf        ",
      " jjj  ki        ",
      "   kkjНf        ",
      "k k   Нh        ",
      " kkykkНf        ",
      "kЃy  yЃi        ",
      "ϷϴКyѳϷϴΊ        ",
      "geghghPi        ",
      "   mmm          ",
      "                ",
      "                ",
      "                ",
      "                ",
      "                ",
      "                "
    ],
    [
      "       h        ",
      "       f        ",
      "       h        ",
      "       f        ",
      "       i        ",
      "       f        ",
      "       h        ",
      " ϶    ϶f        ",
      "gighghgi        ",
      "   mmm          ",
      "                ",
      "                ",
      "                ",
      "                ",
      "                ",
      "                "
    ],
    [
      "       d        ",
      "       d        ",
      "       a        ",
      "       a        ",
      "       a        ",
      "       d        ",
      "       d        ",
      " ϸ    ϸd        ",
      "adadadad        ",
      "   mmm          ",
      "                ",
      "                ",
      "                ",
      "                ",
      "                ",
      "                "
    ],
    [
      "       i        ",
      "       f        ",
      "       h        ",
      "       f        ",
      "       i        ",
      "       f        ",
      "       i        ",
      " Г    Гf        ",
      "gegighgi        ",
      "   mmm          ",
      "                ",
      "                ",
      "                ",
      "                ",
      "                ",
      "                "
    ]
  ]
}