{
  "xsize": 16,
  "zsize": 16,
  "palette": {
    "palette": [
      {
        "char": " ",
        "block": "minecraft:air"
      },
      {
        "char": "c",
        "block": "minecraft:vine[east=false,north=false,south=true,up=false,west=false]"
      },
      {
        "char": "e",
        "block": "minecraft:stone_bricks[weathering=false]"
      },
      {
        "char": "g",
        "block": "minecraft:glass_pane[east=true,north=false,south=false,waterlogged=false,west=true]"
      },
      {
        "char": "h",
        "block": "minecraft:cracked_stone_bricks"
      },
      {
        "char": "f",
        "block": "minecraft:glass_pane[east=false,north=true,south=true,waterlogged=false,west=false]"
      },
      {
        "char": "я",
        "block": "minecraft:glass_pane[east=false,north=true,south=false,waterlogged=false,west=false]"
      },
      {
        "char": "Б",
        "block": "minecraft:glass_pane[east=false,north=false,south=true,waterlogged=false,west=false]"
      },
      {
        "char": "a",
        "block": "minecraft:cobblestone[weathering=false]"
      },
      {
        "char": "d",
        "block": "minecraft:mossy_cobblestone"
      },
      {
        "char": "b",
        "block": "minecraft:stone[weathering=false]"
      },
      {
        "char": "J",
        "block": "minecraft:glass_pane[east=true,north=false,south=true,waterlogged=false,west=true]"
      },
      {
        "char": "I",
        "block": "minecraft:glass_pane[east=true,north=true,south=true,waterlogged=false,west=false]"
      },
      {
        "char": "ϴ",
        "block": "minecraft:spruce_log[axis=y]"
      },
      {
        "char": "φ",
        "block": "minecraft:dark_oak_trapdoor[facing=east,half=bottom,open=true,powered=false,waterlogged=false]"
      },
      {
        "char": "k",
        "block": "minecraft:red_carpet"
      },
      {
        "char": "Ϛ",
        "block": "minecraft:dark_oak_trapdoor[facing=south,half=bottom,open=true,powered=false,waterlogged=false]"
      },
      {
        "char": "i",
        "block": "minecraft:mossy_stone_bricks"
      },
      {
        "char": "϶",
        "block": "minecraft:dark_oak_leaves[distance=1,persistent=true,waterlogged=false]"
      },
      {
        "char": "ϸ",
        "block": "minecraft:dark_oak_leaves[distance=2,persistent=true,waterlogged=false]"
      }
    ]
  },
  "slices": [
    [
      "                ",
      "                ",
      "                ",
      "                ",
      "                ",
      "                ",
      "                ",
      "       cccccc cc",
      "       eghghghge",
      "       f        ",
      "       e        ",
      "       f        ",
      "       h        ",
      "       я        ",
      "                ",
      "       Б        "
    ],
    [
      "                ",
      "                ",
      "                ",
      "                ",
      "                ",
      "                ",
      "                ",
      "       cccccc cc",
      "       adddaadad",
      "       aaaabaaba",
      "       dabaaaabb",
      "       aabaaabbb",
      "       dbbbabaaa",
      "       aaaababaa",
      "       aababaaaa",
      "       aabbaabba"
    ],
    [
      "                ",
      "                ",
      "                ",
      "                ",
      "                ",
      "                ",
      "                ",
      "       cccccc cc",
      "       hJeghghge",
      "       Iϴφkk kk ",
      "       hϚ  kk  k",
      "       f k k k k",
      "       ik k     ",
      "       f kk   kk",
      "       hkk      ",
      "       fk k   k "
    ],
    [
      "                ",
      "                ",
      "                ",
      "                ",
      "                ",
      "                ",
      "                ",
      "       cccccc cc",
      "       egeghgegi",
      "       f϶       ",
      "       e        ",
      "       f        ",
      "       i        ",
      "       f        ",
      "       h        ",
      "       f        "
    ],
    [
      "                ",
      "                ",
      "                ",
      "                ",
      "                ",
      "                ",
      "                ",
      "       cccccc cc",
      "       daaadaada",
      "       aϸ       ",
      "       a        ",
      "       a        ",
      "       d        ",
      "       a        ",
      "       a        ",
      "       a        "
    ],
    [
      "                ",
      "                ",
      "                ",
      "                ",
      "                ",
      "                ",
      "                ",
      "       cccccc cc",
      "       eghgegigh",
      "       f        ",
      "       e        ",
      "       f        ",
      "       i        ",
      "       f        ",
      "       e        ",
      "       f        "
    ]
  ]
}