{
  "xsize": 16,
  "zsize": 16,
  "palette": {
    "palette": [
      {
        "char": " ",
        "block": "minecraft:air"
      },
      {
        "char": "t",
        "block": "minecraft:air"
      },
      {
        "char": "x",
        "block": "minecraft:air"
      },
      {
        "char": "o",
        "block": "minecraft:air"
      },
      {
        "char": "s",
        "block": "minecraft:air"
      },
      {
        "char": "u",
        "block": "minecraft:air"
      },
      {
        "char": "l",
        "block": "minecraft:air"
      },
      {
        "char": "Κ",
        "block": "minecraft:air"
      },
      {
        "char": "r",
        "block": "minecraft:air"
      },
      {
        "char": "O",
        "block": "minecraft:air"
      },
      {
        "char": "ώ",
        "block": "minecraft:air"
      },
      {
        "char": "q",
        "block": "minecraft:grass"
      },
      {
        "char": "d",
        "block": "minecraft:air"
      },
      {
        "char": "n",
        "block": "minecraft:air"
      },
      {
        "char": "c",
        "block": "minecraft:air"
      },
      {
        "char": "b",
        "block": "minecraft:air"
      },
      {
        "char": "m",
        "block": "minecraft:air"
      },
      {
        "char": "k",
        "block": "minecraft:air"
      },
      {
        "char": "ϐ",
        "block": "minecraft:tall_grass[half=lower]"
      },
      {
        "char": "e",
        "block": "minecraft:air"
      },
      {
        "char": "g",
        "block": "minecraft:air"
      },
      {
        "char": "y",
        "block": "minecraft:air"
      },
      {
        "char": "v",
        "block": "minecraft:air"
      },
      {
        "char": "a",
        "block": "minecraft:air"
      },
      {
        "char": "j",
        "block": "minecraft:air"
      },
      {
        "char": "ϒ",
        "block": "minecraft:tall_grass[half=upper]"
      },
      {
        "char": "i",
        "block": "minecraft:air"
      },
      {
        "char": "p",
        "block": "minecraft:air"
      },
      {
        "char": "Ϥ",
        "block": "minecraft:air"
      }
    ]
  },
  "slices": [
    [
      "txosxuoxollΚllll",
      "ttotoxssulllllll",
      "xttrostoslllllll",
      "sotorootulllllll",
      "tottrstotllxllll",
      "suroooosullxxlll",
      "ruusxtouulllllll",
      "stouxrstrlllllll",
      "tsttoxxstroOOOOo",
      "tssuuxrtrstsstox",
      "otossxsurxorosru",
      "srusoxorxsorussu",
      "oώuoroxtsxtotrtu",
      "srurtsurorttosst",
      "ώusoouttotsuouts",
      "srώurxostortorxo"
    ],
    [
      " qq q  qdncbbbbb",
      "     q  dncbbbbb",
      "qq       mcbbbbb",
      "    q   dmbbbbbb",
      "        dkcϐbbbb",
      "q        meϐϐbbb",
      "    q    nbebccb",
      " q  q  qdknmmmmm",
      "     qq  gq gg  ",
      "     q      q qq",
      "     q   q      ",
      "     q qq       ",
      "      q  qq     ",
      "    q          q",
      "                ",
      "    qq        q "
    ],
    [
      "        dyevbbbb",
      "        dab bbbb",
      "         yj bbbb",
      "        dac  bbb",
      "        daeϒ  bb",
      "          jϒϒ  b",
      "          miceic",
      "        da daapa",
      "         g  gg  ",
      "                ",
      "                ",
      "                ",
      "                ",
      "                ",
      "                ",
      "                "
    ],
    [
      "        dybvvϤbb",
      "        dac  bbb",
      "         yj   bb",
      "        dac     ",
      "        dab     ",
      "          j     ",
      "          kiecic",
      "        da daapa",
      "         g  gg  ",
      "                ",
      "                ",
      "                ",
      "                ",
      "                ",
      "                ",
      "                "
    ],
    [
      "        dyc   bb",
      "        dae   bb",
      "         yj    b",
      "        dab     ",
      "        dac     ",
      "          j     ",
      "          miccie",
      "        da daapa",
      "         g  gg  ",
      "                ",
      "                ",
      "                ",
      "                ",
      "                ",
      "                ",
      "                "
    ],
    [
      "        dye    b",
      "        dab   Ϥb",
      "         yj     ",
      "        dae     ",
      "        dae     ",
      "          j     ",
      "          kicbic",
      "        da daapa",
      "         g  gg  ",
      "                ",
      "                ",
      "                ",
      "                ",
      "                ",
      "                ",
      "                "
    ]
  ]
}