{
  "xsize": 16,
  "zsize": 16,
  "palette": {
    "palette": [
      {
        "char": " ",
        "block": "minecraft:air"
      },
      {
        "char": "h",
        "block": "minecraft:cracked_stone_bricks"
      },
      {
        "char": "f",
        "block": "minecraft:glass_pane[east=false,north=true,south=true,waterlogged=false,west=false]"
      },
      {
        "char": "i",
        "block": "minecraft:mossy_stone_bricks"
      },
      {
        "char": "e",
        "block": "minecraft:stone_bricks[weathering=false]"
      },
      {
        "char": "g",
        "block": "minecraft:glass_pane[east=true,north=false,south=false,waterlogged=false,west=true]"
      },
      {
        "char": "m",
        "block": "minecraft:vine[east=false,north=true,south=false,up=false,west=false]"
      },
      {
        "char": "b",
        "block": "minecraft:stone[weathering=false]"
      },
      {
        "char": "a",
        "block": "minecraft:cobblestone[weathering=false]"
      },
      {
        "char": "d",
        "block": "minecraft:mossy_cobblestone"
      },
      {
        "char": "n",
        "block": "minecraft:quartz_slab[type=double,waterlogged=false]"
      },
      {
        "char": "j",
        "block": "minecraft:light_gray_carpet"
      },
      {
        "char": "k",
        "block": "minecraft:red_carpet"
      },
      {
        "char": "Έ",
        "block": "minecraft:oak_wall_sign[facing=east,waterlogged=false]",
        "tag": {
          "z": 618,
          "x": 74,
          "is_waxed": "0b",
          "ForgeCaps": {
            "supplementaries:antique_ink": {
              "ink": "0b"
            }
          },
          "id": "minecraft:sign",
          "y": 219,
          "front_text": {
            "color": "black",
            "has_glowing_text": "0b",
            "messages": [
              "{\"extra\":[{\"text\":\"T. Cabel\"}],\"text\":\"\"}",
              "{\"text\":\"\"}",
              "{\"text\":\"\"}",
              "{\"text\":\"\"}"
            ]
          },
          "back_text": {
            "color": "black",
            "has_glowing_text": "0b",
            "messages": [
              "{\"text\":\"\"}",
              "{\"text\":\"\"}",
              "{\"text\":\"\"}",
              "{\"text\":\"\"}"
            ]
          }
        }
      },
      {
        "char": "в",
        "block": "minecraft:glass_pane[east=true,north=false,south=false,waterlogged=false,west=false]"
      }
    ]
  },
  "slices": [
    [
      "       h        ",
      "       f        ",
      "       i        ",
      "       f        ",
      "       i        ",
      "       f        ",
      "       e        ",
      "       f        ",
      "ghghgegi        ",
      "   mmm          ",
      "                ",
      "                ",
      "                ",
      "                ",
      "                ",
      "                "
    ],
    [
      "babaaaba        ",
      "babbbbaa        ",
      "babababa        ",
      "baabaaaa        ",
      "babaabaa        ",
      "aabababa        ",
      "bbbbbabd        ",
      "abbbbaba        ",
      "adaaadda        ",
      "   mmm          ",
      "                ",
      "                ",
      "                ",
      "                ",
      "                ",
      "                "
    ],
    [
      "n jj kki        ",
      "n     kf        ",
      "  jjkk e        ",
      " j  k  f        ",
      "  k   ke        ",
      "  k k kf        ",
      "kk k a h        ",
      "    k kf        ",
      "ghgegigh        ",
      "   mmm          ",
      "                ",
      "                ",
      "                ",
      "                ",
      "                ",
      "                "
    ],
    [
      "nΈ     h        ",
      "n      f        ",
      "       i        ",
      "       f        ",
      "       h        ",
      "       f        ",
      "     a e        ",
      "       f        ",
      "geghgege        ",
      "   mmm          ",
      "                ",
      "                ",
      "                ",
      "                ",
      "                ",
      "                "
    ],
    [
      "       d        ",
      "       d        ",
      "       a        ",
      "       a        ",
      "       d        ",
      "       a        ",
      "     a d        ",
      "       d        ",
      "addaaddd        ",
      "   mmm          ",
      "                ",
      "                ",
      "                ",
      "                ",
      "                ",
      "                "
    ],
    [
      "       i        ",
      "       f        ",
      "       e        ",
      "       f        ",
      "       e        ",
      "       f        ",
      "     a e        ",
      "       f        ",
      "вhgeghge        ",
      "   mmm          ",
      "                ",
      "                ",
      "                ",
      "                ",
      "                ",
      "                "
    ]
  ]
}