{
  "xsize": 16,
  "zsize": 16,
  "palette": {
    "palette": [
      {
        "char": " ",
        "block": "minecraft:air"
      },
      {
        "char": "c",
        "block": "minecraft:vine[east=false,north=false,south=true,up=false,west=false]"
      },
      {
        "char": "g",
        "block": "minecraft:glass_pane[east=true,north=false,south=false,waterlogged=false,west=true]"
      },
      {
        "char": "e",
        "block": "minecraft:stone_bricks[weathering=false]"
      },
      {
        "char": "h",
        "block": "minecraft:cracked_stone_bricks"
      },
      {
        "char": "a",
        "block": "minecraft:cobblestone[weathering=false]"
      },
      {
        "char": "x",
        "block": "minecraft:cobblestone_stairs[facing=north,half=bottom,shape=straight,waterlogged=false,weathering=false]"
      },
      {
        "char": "f",
        "block": "minecraft:glass_pane[east=false,north=true,south=true,waterlogged=false,west=false]"
      },
      {
        "char": "i",
        "block": "minecraft:mossy_stone_bricks"
      },
      {
        "char": "d",
        "block": "minecraft:mossy_cobblestone"
      },
      {
        "char": "b",
        "block": "minecraft:stone[weathering=false]"
      },
      {
        "char": "j",
        "block": "minecraft:light_gray_carpet"
      },
      {
        "char": "ҁ",
        "block": "minecraft:furnace[facing=south,lit=false]",
        "tag": {
          "z": 617,
          "x": 81,
          "CookTimeTotal": 0,
          "ForgeData": {
            "LockFlag": "1b"
          },
          "CookTime": 0,
          "ForgeCaps": {
            "polymorph:block_entity_recipe_data": {}
          },
          "id": "minecraft:furnace",
          "y": 200,
          "Items": [],
          "BurnTime": 0,
          "RecipesUsed": {}
        }
      },
      {
        "char": "н",
        "block": "minecraft:air"
      },
      {
        "char": "χ",
        "block": "minecraft:air"
      },
      {
        "char": "ҫ",
        "block": "minecraft:air"
      },
      {
        "char": "Ј",
        "block": "minecraft:air"
      },
      {
        "char": "Љ",
        "block": "minecraft:air"
      },
      {
        "char": "Ж",
        "block": "minecraft:air"
      },
      {
        "char": "Е",
        "block": "minecraft:dark_oak_stairs[facing=north,half=bottom,shape=straight,waterlogged=false]"
      },
      {
        "char": "ϟ",
        "block": "minecraft:oak_wall_sign[facing=south,waterlogged=false]",
        "tag": {
          "z": 617,
          "x": 85,
          "is_waxed": "0b",
          "ForgeCaps": {
            "supplementaries:antique_ink": {
              "ink": "0b"
            }
          },
          "id": "minecraft:sign",
          "y": 153,
          "front_text": {
            "color": "black",
            "has_glowing_text": "0b",
            "messages": [
              "{\"extra\":[{\"text\":\"Floor 3\"}],\"text\":\"\"}",
              "{\"extra\":[{\"text\":\"Complaints\"}],\"text\":\"\"}",
              "{\"text\":\"\"}",
              "{\"text\":\"\"}"
            ]
          },
          "back_text": {
            "color": "black",
            "has_glowing_text": "0b",
            "messages": [
              "{\"text\":\"\"}",
              "{\"text\":\"\"}",
              "{\"text\":\"\"}",
              "{\"text\":\"\"}"
            ]
          }
        }
      }
    ]
  },
  "slices": [
    [
      "                ",
      "                ",
      "                ",
      "                ",
      "                ",
      "                ",
      "                ",
      "cccccccc        ",
      "ge h h          ",
      "                ",
      "    aaae        ",
      "    xxx         ",
      "       h        ",
      "       f        ",
      "       i        ",
      "       f        "
    ],
    [
      "                ",
      "                ",
      "                ",
      "                ",
      "                ",
      "                ",
      "                ",
      "cccccccc        ",
      "addddad         ",
      "aaabbaaa        ",
      "babaxxx         ",
      "baab            ",
      "abaa   a        ",
      "aaab   a        ",
      "abaaabba        ",
      "bbbbaaad        "
    ],
    [
      "                ",
      "                ",
      "                ",
      "                ",
      "                ",
      "                ",
      "                ",
      "cccccccc        ",
      "gighghgh        ",
      "jҁ  jj f        ",
      "  jн   i        ",
      "jjjχ   f        ",
      "   χ   i        ",
      "jjjχ   f        ",
      " j ҫЈЉЖh        ",
      "Е j ЕЕ f        "
    ],
    [
      "                ",
      "                ",
      "                ",
      "                ",
      "                ",
      "                ",
      "                ",
      "cccccccc        ",
      "gigeghge        ",
      " ϟ     f        ",
      "       h        ",
      "       f        ",
      "       h        ",
      "       f        ",
      "       h        ",
      "       f        "
    ],
    [
      "                ",
      "                ",
      "                ",
      "                ",
      "                ",
      "                ",
      "                ",
      "ccc cccc        ",
      "daaddaaa        ",
      "       a        ",
      "       a        ",
      "       a        ",
      "       d        ",
      "       d        ",
      "       d        ",
      "       a        "
    ],
    [
      "                ",
      "                ",
      "                ",
      "                ",
      "                ",
      "                ",
      "                ",
      "ccc cccc        ",
      "gegegige        ",
      "       f        ",
      "       e        ",
      "       f        ",
      "       e        ",
      "       f        ",
      "       i        ",
      "       f        "
    ]
  ]
}