{
  "xsize": 16,
  "zsize": 16,
  "palette": {
    "palette": [
      {
        "char": " ",
        "block": "minecraft:air"
      },
      {
        "char": "h",
        "block": "minecraft:cracked_stone_bricks"
      },
      {
        "char": "f",
        "block": "minecraft:glass_pane[east=false,north=true,south=true,waterlogged=false,west=false]"
      },
      {
        "char": "i",
        "block": "minecraft:mossy_stone_bricks"
      },
      {
        "char": "g",
        "block": "minecraft:glass_pane[east=true,north=false,south=false,waterlogged=false,west=true]"
      },
      {
        "char": "e",
        "block": "minecraft:stone_bricks[weathering=false]"
      },
      {
        "char": "m",
        "block": "minecraft:vine[east=false,north=true,south=false,up=false,west=false]"
      },
      {
        "char": "b",
        "block": "minecraft:stone[weathering=false]"
      },
      {
        "char": "a",
        "block": "minecraft:cobblestone[weathering=false]"
      },
      {
        "char": "d",
        "block": "minecraft:mossy_cobblestone"
      },
      {
        "char": "l",
        "block": "minecraft:bookshelf"
      },
      {
        "char": "y",
        "block": "minecraft:redstone_wire[east=side,north=side,power=0,south=side,west=side]"
      },
      {
        "char": "Ί",
        "block": "minecraft:glass_pane[east=false,north=true,south=true,waterlogged=false,west=true]"
      },
      {
        "char": "Ӄ",
        "block": "minecraft:skeleton_skull[rotation=0]",
        "tag": {
          "z": 626,
          "x": 83,
          "ForgeCaps": {},
          "id": "minecraft:skull",
          "y": 164
        }
      },
      {
        "char": "P",
        "block": "minecraft:glass_pane[east=true,north=true,south=false,waterlogged=false,west=true]"
      }
    ]
  },
  "slices": [
    [
      "       h        ",
      "       f        ",
      "       i        ",
      "       f        ",
      "       i        ",
      "       f        ",
      "       i        ",
      "       f        ",
      "gigegigh        ",
      "   mmm          ",
      "                ",
      "                ",
      "                ",
      "                ",
      "                ",
      "                "
    ],
    [
      "bbbabbad        ",
      "bbabbbbd        ",
      "abababbd        ",
      "bbabaaba        ",
      "bbbababd        ",
      "abbaaaad        ",
      "aabbaaad        ",
      "bbbabbbd        ",
      "aaadddad        ",
      "   mmm          ",
      "                ",
      "                ",
      "                ",
      "                ",
      "                ",
      "                "
    ],
    [
      "       e        ",
      "ll ylllΊ        ",
      "  yӃ   h        ",
      "     y f        ",
      " ly l  h        ",
      " l  l  f        ",
      " l  l  h        ",
      " l  l  f        ",
      "geghPege        ",
      "   mmm          ",
      "                ",
      "                ",
      "                ",
      "                ",
      "                ",
      "                "
    ],
    [
      "       i        ",
      "ll  lllΊ        ",
      "       e        ",
      "       f        ",
      " l  l  i        ",
      " l  l  f        ",
      " l  l  i        ",
      " l  l  f        ",
      "ghghPhgh        ",
      "   mmm          ",
      "                ",
      "                ",
      "                ",
      "                ",
      "                ",
      "                "
    ],
    [
      "       a        ",
      "ll  llld        ",
      "       a        ",
      "       d        ",
      " l  l  d        ",
      " l  l  a        ",
      " l  l  a        ",
      " l  l  d        ",
      "aaaaaadd        ",
      "   mmm          ",
      "                ",
      "                ",
      "                ",
      "                ",
      "                ",
      "                "
    ],
    [
      "       e        ",
      "       f        ",
      "       i        ",
      "       f        ",
      "       i        ",
      "       f        ",
      "       h        ",
      "       f        ",
      "geghgigi        ",
      "   mmm          ",
      "                ",
      "                ",
      "                ",
      "                ",
      "                ",
      "                "
    ]
  ]
}