{
  "xsize": 16,
  "zsize": 16,
  "palette": {
    "palette": [
      {
        "char": " ",
        "block": "minecraft:air"
      },
      {
        "char": "i",
        "block": "minecraft:mossy_stone_bricks"
      },
      {
        "char": "f",
        "block": "minecraft:glass_pane[east=false,north=true,south=true,waterlogged=false,west=false]"
      },
      {
        "char": "h",
        "block": "minecraft:cracked_stone_bricks"
      },
      {
        "char": "e",
        "block": "minecraft:stone_bricks[weathering=false]"
      },
      {
        "char": "g",
        "block": "minecraft:glass_pane[east=true,north=false,south=false,waterlogged=false,west=true]"
      },
      {
        "char": "m",
        "block": "minecraft:vine[east=false,north=true,south=false,up=false,west=false]"
      },
      {
        "char": "b",
        "block": "minecraft:stone[weathering=false]"
      },
      {
        "char": "a",
        "block": "minecraft:cobblestone[weathering=false]"
      },
      {
        "char": "d",
        "block": "minecraft:mossy_cobblestone"
      },
      {
        "char": "l",
        "block": "minecraft:bookshelf"
      },
      {
        "char": "k",
        "block": "minecraft:red_carpet"
      },
      {
        "char": "y",
        "block": "minecraft:redstone_wire[east=side,north=side,power=0,south=side,west=side]"
      },
      {
        "char": "ц",
        "block": "minecraft:skeleton_skull[rotation=3]",
        "tag": {
          "z": 631,
          "x": 81,
          "ForgeCaps": {},
          "id": "minecraft:skull",
          "y": 133
        }
      },
      {
        "char": "ϯ",
        "block": "minecraft:cobblestone_slab[type=double,waterlogged=false,weathering=false]"
      },
      {
        "char": "Ϲ",
        "block": "minecraft:dark_oak_fence[east=false,north=true,south=true,waterlogged=false,west=false]"
      },
      {
        "char": "Ф",
        "block": "minecraft:dark_oak_fence[east=true,north=true,south=false,waterlogged=false,west=false]"
      },
      {
        "char": "Ѥ",
        "block": "minecraft:dark_oak_fence[east=true,north=false,south=false,waterlogged=false,west=true]"
      },
      {
        "char": "的",
        "block": "minecraft:dark_oak_fence[east=false,north=false,south=false,waterlogged=false,west=true]"
      }
    ]
  },
  "slices": [
    [
      "       i        ",
      "       f        ",
      "       h        ",
      "       f        ",
      "       e        ",
      "       f        ",
      "       e        ",
      "       f        ",
      "geghgegh        ",
      "   mmm          ",
      "                ",
      "                ",
      "                ",
      "                ",
      "                ",
      "                "
    ],
    [
      "bbbbaaaa        ",
      "babbbaad        ",
      "aaaaaaba        ",
      "bbbbabaa        ",
      "abbbabaa        ",
      "babbbbbd        ",
      "abbaaaad        ",
      "aaaabbaa        ",
      "aaadadad        ",
      "   mmm          ",
      "                ",
      "                ",
      "                ",
      "                ",
      "                ",
      "                "
    ],
    [
      "l   k  i        ",
      "l   k kf        ",
      "l    k i        ",
      "lllk  kf        ",
      "  k  k h        ",
      "yk kk  f        ",
      "k yk kki        ",
      "цyk  k f        ",
      "ghghghgh        ",
      "   mmm          ",
      "                ",
      "                ",
      "                ",
      "                ",
      "                ",
      "                "
    ],
    [
      "l      ϯ        ",
      "l      f        ",
      "l      e        ",
      "lll    f        ",
      "       e        ",
      "       f        ",
      "       i        ",
      "       f        ",
      "gigegigh        ",
      "   mmm          ",
      "                ",
      "                ",
      "                ",
      "                ",
      "                ",
      "                "
    ],
    [
      "l      a        ",
      "l      d        ",
      "l      a        ",
      "lll    a        ",
      "       d        ",
      "       d        ",
      "       a        ",
      "       d        ",
      "dddddaad        ",
      "   mmm          ",
      "                ",
      "                ",
      "                ",
      "                ",
      "                ",
      "                "
    ],
    [
      "Ϲ      h        ",
      "Ϲ      f        ",
      "Ϲ      h        ",
      "ФѤ的    f        ",
      "       e        ",
      "       f        ",
      "       e        ",
      "       f        ",
      "ghghgige        ",
      "   mmm          ",
      "                ",
      "                ",
      "                ",
      "                ",
      "                ",
      "                "
    ]
  ]
}