{
  "xsize": 16,
  "zsize": 16,
  "palette": {
    "palette": [
      {
        "char": " ",
        "block": "minecraft:air"
      },
      {
        "char": "b",
        "block": "minecraft:cobblestone[weathering=false]"
      },
      {
        "char": "G",
        "block": "minecraft:redstone_lamp[lit=false]"
      },
      {
        "char": "c",
        "block": "minecraft:mossy_cobblestone"
      },
      {
        "char": "a",
        "block": "minecraft:smooth_stone_slab[type=double,waterlogged=false]"
      },
      {
        "char": "R",
        "block": "minecraft:oak_stairs[facing=south,half=bottom,shape=straight,waterlogged=false]"
      },
      {
        "char": "e",
        "block": "minecraft:stone[weathering=false]"
      },
      {
        "char": "f",
        "block": "minecraft:vine[east=false,north=false,south=false,up=false,west=true]"
      },
      {
        "char": "g",
        "block": "minecraft:vine[east=false,north=true,south=false,up=false,west=false]"
      },
      {
        "char": "k",
        "block": "minecraft:stone_bricks[weathering=false]"
      },
      {
        "char": "m",
        "block": "minecraft:mossy_stone_bricks"
      },
      {
        "char": "v",
        "block": "minecraft:bookshelf"
      },
      {
        "char": "p",
        "block": "minecraft:vine[east=true,north=false,south=false,up=false,west=true]"
      },
      {
        "char": "n",
        "block": "minecraft:cracked_stone_bricks"
      },
      {
        "char": "Λ",
        "block": "minecraft:air"
      },
      {
        "char": "K",
        "block": "minecraft:iron_bars[east=false,north=true,south=true,waterlogged=false,west=false]"
      },
      {
        "char": "j",
        "block": "minecraft:glass_pane[east=false,north=true,south=true,waterlogged=false,west=false]"
      },
      {
        "char": "i",
        "block": "minecraft:glass_pane[east=true,north=false,south=false,waterlogged=false,west=true]"
      },
      {
        "char": "J",
        "block": "minecraft:iron_bars[east=true,north=false,south=false,waterlogged=false,west=true]"
      },
      {
        "char": "Й",
        "block": "minecraft:iron_bars[east=false,north=true,south=false,waterlogged=false,west=true]"
      }
    ]
  },
  "slices": [
    [
      " bbbbGc         ",
      " bbbbbca        ",
      " bbbbbc         ",
      "Rbbbbbca        ",
      "bbbbbbea        ",
      "Gbbbbbb         ",
      "beebebb         ",
      " a aa  af       ",
      "       g        ",
      "                ",
      "                ",
      "                ",
      "                ",
      "                ",
      "                ",
      "                "
    ],
    [
      "    ek m        ",
      "   vek m        ",
      "    empn        ",
      "  vvekpk        ",
      "keeecnfn        ",
      "knnmnnfm        ",
      "g gg g k        ",
      "nnknnnkn        ",
      "                ",
      "                ",
      "                ",
      "                ",
      "                ",
      "                ",
      "                ",
      "                "
    ],
    [
      "    ea Λ        ",
      "   v   Λ        ",
      "    eafK        ",
      "   veafK        ",
      "e ec jfK        ",
      "aiaaiafK        ",
      "g gg g K        ",
      "JJJJJJJЙ        ",
      "                ",
      "                ",
      "                ",
      "                ",
      "                ",
      "                ",
      "                ",
      "                "
    ],
    [
      "    ca          ",
      "                ",
      "    eaf         ",
      "    eaf         ",
      "c cb jf         ",
      "aiaaiaf         ",
      "g gg g          ",
      "                ",
      "                ",
      "                ",
      "                ",
      "                ",
      "                ",
      "                ",
      "                ",
      "                "
    ],
    [
      "    ba          ",
      "     j          ",
      "    eaf         ",
      "    ba          ",
      "e cb jf         ",
      "aiaaiaf         ",
      "g gg g          ",
      "                ",
      "                ",
      "                ",
      "                ",
      "                ",
      "                ",
      "                ",
      "                ",
      "                "
    ],
    [
      "    ea          ",
      "     j          ",
      "    eaf         ",
      "    ca          ",
      "c be jf         ",
      "aiaaiaf         ",
      "g gg g          ",
      "                ",
      "                ",
      "                ",
      "                ",
      "                ",
      "                ",
      "                ",
      "                ",
      "                "
    ]
  ]
}