{
  "xsize": 16,
  "zsize": 16,
  "palette": {
    "palette": [
      {
        "char": " ",
        "block": "minecraft:air"
      },
      {
        "char": "e",
        "block": "minecraft:stone_bricks[weathering=false]"
      },
      {
        "char": "f",
        "block": "minecraft:glass_pane[east=false,north=true,south=true,waterlogged=false,west=false]"
      },
      {
        "char": "a",
        "block": "minecraft:cobblestone[weathering=false]"
      },
      {
        "char": "i",
        "block": "minecraft:mossy_stone_bricks"
      },
      {
        "char": "в",
        "block": "minecraft:glass_pane[east=true,north=false,south=false,waterlogged=false,west=false]"
      },
      {
        "char": "h",
        "block": "minecraft:cracked_stone_bricks"
      },
      {
        "char": "g",
        "block": "minecraft:glass_pane[east=true,north=false,south=false,waterlogged=false,west=true]"
      },
      {
        "char": "m",
        "block": "minecraft:vine[east=false,north=true,south=false,up=false,west=false]"
      },
      {
        "char": "b",
        "block": "minecraft:stone[weathering=false]"
      },
      {
        "char": "d",
        "block": "minecraft:mossy_cobblestone"
      },
      {
        "char": "ϼ",
        "block": "minecraft:dark_oak_planks"
      },
      {
        "char": "а",
        "block": "minecraft:dark_oak_stairs[facing=east,half=bottom,shape=straight,waterlogged=false]"
      },
      {
        "char": "В",
        "block": "minecraft:dark_oak_stairs[facing=west,half=bottom,shape=straight,waterlogged=false]"
      },
      {
        "char": "j",
        "block": "minecraft:light_gray_carpet"
      },
      {
        "char": "Ί",
        "block": "minecraft:glass_pane[east=false,north=true,south=true,waterlogged=false,west=true]"
      },
      {
        "char": "О",
        "block": "minecraft:dark_oak_stairs[facing=south,half=bottom,shape=straight,waterlogged=false]"
      },
      {
        "char": "y",
        "block": "minecraft:redstone_wire[east=side,north=side,power=0,south=side,west=side]"
      },
      {
        "char": "Е",
        "block": "minecraft:dark_oak_stairs[facing=north,half=bottom,shape=straight,waterlogged=false]"
      },
      {
        "char": "Ҙ",
        "block": "minecraft:skeleton_skull[rotation=14]",
        "tag": {
          "z": 623,
          "x": 74,
          "ForgeCaps": {},
          "id": "minecraft:skull",
          "y": 170
        }
      },
      {
        "char": "Ӡ",
        "block": "minecraft:glass_pane[east=true,north=true,south=false,waterlogged=false,west=false]"
      },
      {
        "char": "P",
        "block": "minecraft:glass_pane[east=true,north=true,south=false,waterlogged=false,west=true]"
      },
      {
        "char": "T",
        "block": "minecraft:flower_pot"
      },
      {
        "char": "C",
        "block": "minecraft:redstone_lamp[lit=false]"
      }
    ]
  },
  "slices": [
    [
      "       e        ",
      "       f        ",
      "       e        ",
      "       f        ",
      "       e        ",
      "       f        ",
      "     a i        ",
      "       f        ",
      "вhgegige        ",
      "   mmm          ",
      "                ",
      "                ",
      "                ",
      "                ",
      "                ",
      "                "
    ],
    [
      "ababbabd        ",
      "babaabba        ",
      "aaabbbbd        ",
      "bbababaa        ",
      "abababbd        ",
      "aaabbbad        ",
      "aabbaaaa        ",
      "bbabaabd        ",
      " aaaaddd        ",
      "   mmm          ",
      "                ",
      "                ",
      "                ",
      "                ",
      "                ",
      "                "
    ],
    [
      "ϼа Вϼϼаh        ",
      "ϼаjВϼϼаΊ        ",
      "Оyj ОО h        ",
      " jyjj jf        ",
      "ЕyҘjЕЕ e        ",
      "ϼаjВϼϼаΊ        ",
      "ϼа Вϼϼаi        ",
      "О j ОО f        ",
      "ӠegePege        ",
      "   mmm          ",
      "                ",
      "                ",
      "                ",
      "                ",
      "                ",
      "                "
    ],
    [
      "T   T  i        ",
      "       f        ",
      "       h        ",
      "       f        ",
      "       h        ",
      "T      f        ",
      "     T i        ",
      "       f        ",
      "geghghge        ",
      "   mmm          ",
      "                ",
      "                ",
      "                ",
      "                ",
      "                ",
      "                "
    ],
    [
      "       d        ",
      "       d        ",
      "       d        ",
      "       a        ",
      "       d        ",
      "       a        ",
      "       a        ",
      "       d        ",
      "d ddddaa        ",
      "   mmm          ",
      "                ",
      "                ",
      "                ",
      "                ",
      "                ",
      "                "
    ],
    [
      "C   CC h        ",
      "C   CC f        ",
      "       i        ",
      "       f        ",
      "       i        ",
      "C   CC f        ",
      "C   CC i        ",
      "       f        ",
      " igeghgh        ",
      "   mmm          ",
      "                ",
      "                ",
      "                ",
      "                ",
      "                ",
      "                "
    ]
  ]
}