{
  "xsize": 16,
  "zsize": 16,
  "palette": {
    "palette": [
      {
        "char": " ",
        "block": "minecraft:air"
      },
      {
        "char": "c",
        "block": "minecraft:vine[east=false,north=false,south=true,up=false,west=false]"
      },
      {
        "char": "i",
        "block": "minecraft:mossy_stone_bricks"
      },
      {
        "char": "g",
        "block": "minecraft:glass_pane[east=true,north=false,south=false,waterlogged=false,west=true]"
      },
      {
        "char": "h",
        "block": "minecraft:cracked_stone_bricks"
      },
      {
        "char": "e",
        "block": "minecraft:stone_bricks[weathering=false]"
      },
      {
        "char": "f",
        "block": "minecraft:glass_pane[east=false,north=true,south=true,waterlogged=false,west=false]"
      },
      {
        "char": "d",
        "block": "minecraft:mossy_cobblestone"
      },
      {
        "char": "a",
        "block": "minecraft:cobblestone[weathering=false]"
      },
      {
        "char": "b",
        "block": "minecraft:stone[weathering=false]"
      },
      {
        "char": "J",
        "block": "minecraft:glass_pane[east=true,north=false,south=true,waterlogged=false,west=true]"
      },
      {
        "char": "I",
        "block": "minecraft:glass_pane[east=true,north=true,south=true,waterlogged=false,west=false]"
      },
      {
        "char": "ϴ",
        "block": "minecraft:spruce_log[axis=y]"
      },
      {
        "char": "К",
        "block": "minecraft:dark_oak_trapdoor[facing=east,half=top,open=true,powered=false,waterlogged=false]"
      },
      {
        "char": "k",
        "block": "minecraft:red_carpet"
      },
      {
        "char": "Ѕ",
        "block": "minecraft:dark_oak_trapdoor[facing=south,half=top,open=true,powered=false,waterlogged=false]"
      },
      {
        "char": "y",
        "block": "minecraft:redstone_wire[east=side,north=side,power=0,south=side,west=side]"
      },
      {
        "char": "ө",
        "block": "minecraft:skeleton_skull[rotation=15]",
        "tag": {
          "z": 622,
          "x": 78,
          "ForgeCaps": {},
          "id": "minecraft:skull",
          "y": 188
        }
      },
      {
        "char": "L",
        "block": "minecraft:black_carpet"
      },
      {
        "char": "϶",
        "block": "minecraft:dark_oak_leaves[distance=1,persistent=true,waterlogged=false]"
      },
      {
        "char": "ϸ",
        "block": "minecraft:dark_oak_leaves[distance=2,persistent=true,waterlogged=false]"
      },
      {
        "char": "Г",
        "block": "minecraft:dark_oak_leaves[distance=3,persistent=true,waterlogged=false]"
      }
    ]
  },
  "slices": [
    [
      "                ",
      "                ",
      "                ",
      "                ",
      "                ",
      "                ",
      "                ",
      "        ccc c cc",
      "       ighghgi e",
      "       f        ",
      "       i        ",
      "       f        ",
      "       e        ",
      "                ",
      "                ",
      "                "
    ],
    [
      "                ",
      "                ",
      "                ",
      "                ",
      "                ",
      "                ",
      "                ",
      "        ccc c cc",
      "       ddaaaaadd",
      "       daababbbb",
      "       daababbba",
      "       abaabbbba",
      "       aababbaaa",
      "       daaaabbaa",
      "        aabbbabb",
      "        bbbbaaab"
    ],
    [
      "                ",
      "                ",
      "                ",
      "                ",
      "                ",
      "                ",
      "                ",
      "        ccc c cc",
      "       iJigigegh",
      "       IϴК k k  ",
      "       hЅ k k  k",
      "       f kk  kk ",
      "       ek  k    ",
      "         k    y ",
      "         k k yөy",
      "          kk  L "
    ],
    [
      "                ",
      "                ",
      "                ",
      "                ",
      "                ",
      "                ",
      "                ",
      "        ccc c cc",
      "       igegegige",
      "       f϶       ",
      "       h        ",
      "       f        ",
      "       h        ",
      "                ",
      "                ",
      "                "
    ],
    [
      "                ",
      "                ",
      "                ",
      "                ",
      "                ",
      "                ",
      "                ",
      "        ccc c cc",
      "       aaaddaaad",
      "       dϸ       ",
      "       a        ",
      "       a        ",
      "       a        ",
      "       d        ",
      "       a        ",
      "       d        "
    ],
    [
      "                ",
      "                ",
      "                ",
      "                ",
      "                ",
      "                ",
      "                ",
      "        ccc c cc",
      "       hghghgigi",
      "       fГ       ",
      "       h        ",
      "       f        ",
      "       e        ",
      "       f        ",
      "       i        ",
      "       f        "
    ]
  ]
}