{
  "xsize": 16,
  "zsize": 16,
  "palette": {
    "palette": [
      {
        "char": " ",
        "block": "minecraft:air"
      },
      {
        "char": "l",
        "block": "minecraft:dirt"
      },
      {
        "char": "b",
        "block": "minecraft:cobblestone[weathering=false]"
      },
      {
        "char": "u",
        "block": "minecraft:cobbled_deepslate"
      },
      {
        "char": "r",
        "block": "minecraft:blackstone"
      },
      {
        "char": "o",
        "block": "minecraft:basalt[axis=x]"
      },
      {
        "char": "s",
        "block": "minecraft:cyan_terracotta"
      },
      {
        "char": "x",
        "block": "minecraft:grass_block[snowy=false]"
      },
      {
        "char": "O",
        "block": "minecraft:air"
      },
      {
        "char": "t",
        "block": "minecraft:deepslate[axis=y]"
      },
      {
        "char": "m",
        "block": "minecraft:mossy_stone_bricks"
      },
      {
        "char": "q",
        "block": "minecraft:air"
      },
      {
        "char": "e",
        "block": "minecraft:stone[weathering=false]"
      },
      {
        "char": "k",
        "block": "minecraft:stone_bricks[weathering=false]"
      },
      {
        "char": "f",
        "block": "minecraft:vine[east=false,north=false,south=false,up=false,west=true]"
      },
      {
        "char": "c",
        "block": "minecraft:mossy_cobblestone"
      },
      {
        "char": "n",
        "block": "minecraft:cracked_stone_bricks"
      },
      {
        "char": "d",
        "block": "minecraft:vine[east=true,north=false,south=false,up=false,west=false]"
      },
      {
        "char": "g",
        "block": "minecraft:vine[east=false,north=true,south=false,up=false,west=false]"
      },
      {
        "char": "E",
        "block": "minecraft:cobblestone_slab[type=bottom,waterlogged=false,weathering=false]"
      },
      {
        "char": "a",
        "block": "minecraft:smooth_stone_slab[type=double,waterlogged=false]"
      },
      {
        "char": "A",
        "block": "minecraft:vine[east=false,north=true,south=true,up=false,west=true]"
      },
      {
        "char": "F",
        "block": "minecraft:glass_pane[east=false,north=true,south=true,waterlogged=false,west=true]"
      },
      {
        "char": "j",
        "block": "minecraft:glass_pane[east=false,north=true,south=true,waterlogged=false,west=false]"
      },
      {
        "char": "L",
        "block": "minecraft:glass_pane[east=true,north=true,south=false,waterlogged=false,west=true]"
      },
      {
        "char": "i",
        "block": "minecraft:glass_pane[east=true,north=false,south=false,waterlogged=false,west=true]"
      },
      {
        "char": "p",
        "block": "minecraft:vine[east=true,north=false,south=false,up=false,west=true]"
      }
    ]
  },
  "slices": [
    [
      "llllbbllurooosxr",
      "llllllllOrsoooxo",
      "lllllllluurorros",
      "llllllllOxtuoruo",
      "llllllllOorxoxto",
      "lllllxllrtsuoruo",
      "llllllllsOssooxo",
      "llllllllrrruoots",
      "tOxOosOOorxoossu",
      "oxrusuttssrusrro",
      "rtsutuooxtuxuusu",
      "srturrutuoroxssu",
      "srtuorurrotxuoox",
      "rstrtrrtsosuosxo",
      "xruuutsstxuosxtt",
      "rttoxuuuoororsss"
    ],
    [
      "bbbbbbbm      q ",
      "bbbqbbekf     q ",
      "bbbbbbcn    q   ",
      "bbbbbbbkfq      ",
      "bbbbcbemf  q q  ",
      "bbbbcqem        ",
      "bcbcceem d    q ",
      "mkmnmmkmfq      ",
      " gqgg  g  q     ",
      " qEq            ",
      " q      q  q    ",
      "      q   q qq  ",
      "    q      q   q",
      "              q ",
      "q        q   q  ",
      "    q     q     "
    ],
    [
      "bbbakkeA        ",
      "bbba  caf       ",
      "bbbbbbFA        ",
      "bbbbb eaf       ",
      "bbbb  caf       ",
      "bbbb  jg        ",
      "ceLebin  d      ",
      " apaaf af       ",
      " g gg  g        ",
      "                ",
      "                ",
      "                ",
      "                ",
      "                ",
      "                ",
      "                "
    ],
    [
      "bbba  cA        ",
      "bbb   baf       ",
      "bbb   jA        ",
      "bbb   caf       ",
      "      baf       ",
      "      jg        ",
      "ecicbim  d      ",
      " apaaf af       ",
      " g gg  g        ",
      "                ",
      "                ",
      "                ",
      "                ",
      "                ",
      "                ",
      "                "
    ],
    [
      "bb    cA        ",
      "bbb   caf       ",
      "bb    jA        ",
      "      baf       ",
      "      eaf       ",
      "      jg        ",
      "bbicbik  d      ",
      " apaaf af       ",
      " g gg  g        ",
      "                ",
      "                ",
      "                ",
      "                ",
      "                ",
      "                ",
      "                "
    ],
    [
      "b     cA        ",
      "      caf       ",
      "      jA        ",
      "      caf       ",
      "      eaf       ",
      "      jg        ",
      "eeicein  d      ",
      " apaaf af       ",
      " g gg  g        ",
      "                ",
      "                ",
      "                ",
      "                ",
      "                ",
      "                ",
      "                "
    ]
  ]
}