{
  "xsize": 16,
  "zsize": 16,
  "palette": {
    "palette": [
      {
        "char": " ",
        "block": "minecraft:air"
      },
      {
        "char": "c",
        "block": "minecraft:vine[east=false,north=false,south=true,up=false,west=false]"
      },
      {
        "char": "g",
        "block": "minecraft:glass_pane[east=true,north=false,south=false,waterlogged=false,west=true]"
      },
      {
        "char": "e",
        "block": "minecraft:stone_bricks[weathering=false]"
      },
      {
        "char": "h",
        "block": "minecraft:cracked_stone_bricks"
      },
      {
        "char": "i",
        "block": "minecraft:mossy_stone_bricks"
      },
      {
        "char": "o",
        "block": "minecraft:vine[east=false,north=false,south=false,up=false,west=true]"
      },
      {
        "char": "f",
        "block": "minecraft:glass_pane[east=false,north=true,south=true,waterlogged=false,west=false]"
      },
      {
        "char": "a",
        "block": "minecraft:cobblestone[weathering=false]"
      },
      {
        "char": "d",
        "block": "minecraft:mossy_cobblestone"
      },
      {
        "char": "b",
        "block": "minecraft:stone[weathering=false]"
      },
      {
        "char": "J",
        "block": "minecraft:glass_pane[east=true,north=false,south=true,waterlogged=false,west=true]"
      },
      {
        "char": "Θ",
        "block": "minecraft:white_wool"
      },
      {
        "char": "к",
        "block": "minecraft:spruce_stairs[facing=west,half=bottom,shape=straight,waterlogged=false]"
      },
      {
        "char": "l",
        "block": "minecraft:bookshelf"
      },
      {
        "char": "Ί",
        "block": "minecraft:glass_pane[east=false,north=true,south=true,waterlogged=false,west=true]"
      },
      {
        "char": "k",
        "block": "minecraft:red_carpet"
      },
      {
        "char": "ҡ",
        "block": "minecraft:skeleton_skull[rotation=5]",
        "tag": {
          "z": 622,
          "x": 80,
          "ForgeCaps": {},
          "id": "minecraft:skull",
          "y": 176
        }
      },
      {
        "char": "y",
        "block": "minecraft:redstone_wire[east=side,north=side,power=0,south=side,west=side]"
      },
      {
        "char": "ϻ",
        "block": "minecraft:oak_stairs[facing=south,half=bottom,shape=straight,waterlogged=false]"
      },
      {
        "char": "ҍ",
        "block": "minecraft:spruce_stairs[facing=west,half=top,shape=straight,waterlogged=false]"
      },
      {
        "char": "ϟ",
        "block": "minecraft:oak_wall_sign[facing=south,waterlogged=false]",
        "tag": {
          "z": 617,
          "x": 85,
          "is_waxed": "0b",
          "ForgeCaps": {
            "supplementaries:antique_ink": {
              "ink": "0b"
            }
          },
          "id": "minecraft:sign",
          "y": 153,
          "front_text": {
            "color": "black",
            "has_glowing_text": "0b",
            "messages": [
              "{\"extra\":[{\"text\":\"Floor 3\"}],\"text\":\"\"}",
              "{\"extra\":[{\"text\":\"Complaints\"}],\"text\":\"\"}",
              "{\"text\":\"\"}",
              "{\"text\":\"\"}"
            ]
          },
          "back_text": {
            "color": "black",
            "has_glowing_text": "0b",
            "messages": [
              "{\"text\":\"\"}",
              "{\"text\":\"\"}",
              "{\"text\":\"\"}",
              "{\"text\":\"\"}"
            ]
          }
        }
      }
    ]
  },
  "slices": [
    [
      "                ",
      "                ",
      "                ",
      "                ",
      "                ",
      "                ",
      "                ",
      "cccccccc        ",
      "geghgegio       ",
      "       f        ",
      "       i        ",
      "       f        ",
      "       ho       ",
      "       fo       ",
      "       io       ",
      "       fo       "
    ],
    [
      "                ",
      "                ",
      "                ",
      "                ",
      "                ",
      "                ",
      "                ",
      "cccccccc        ",
      "aadaaaddo       ",
      "ababbbad        ",
      "baabbbba        ",
      "baabbaad        ",
      "abbbbbbdo       ",
      "bbbbaaaao       ",
      "bbaabbbao       ",
      "abbbabbao       "
    ],
    [
      "                ",
      "                ",
      "                ",
      "                ",
      "                ",
      "                ",
      "                ",
      "cccccccc        ",
      "JighgeJeo       ",
      "ΘΘк  llΊ        ",
      "k k   lh        ",
      " kk k  f        ",
      "   k k ho       ",
      " ҡy k  fo       ",
      "y    k io       ",
      "ϻ ϻ   kfo       "
    ],
    [
      "                ",
      "                ",
      "                ",
      "                ",
      "                ",
      "                ",
      "                ",
      "cccccccc        ",
      "JighgeJeo       ",
      "ΘΘҍ   lΊ        ",
      "       e        ",
      "       f        ",
      "       ho       ",
      "       fo       ",
      "       eo       ",
      "       fo       "
    ],
    [
      "                ",
      "                ",
      "                ",
      "                ",
      "                ",
      "                ",
      "                ",
      "cccccccc        ",
      "dddadaddo       ",
      "ΘΘк    a        ",
      "ϟ      d        ",
      "       a        ",
      "       ao       ",
      "       do       ",
      "       ao       ",
      "       ao       "
    ],
    [
      "                ",
      "                ",
      "                ",
      "                ",
      "                ",
      "                ",
      "                ",
      "cccccccc        ",
      "Jhgeghgho       ",
      "ΘΘҍ    f        ",
      "       h        ",
      "       f        ",
      "       ho       ",
      "       f        ",
      "       eo       ",
      "       f        "
    ]
  ]
}