{
  "xsize": 16,
  "zsize": 16,
  "palette": {
    "palette": [
      {
        "char": " ",
        "block": "minecraft:air"
      },
      {
        "char": "l",
        "block": "minecraft:air"
      },
      {
        "char": "b",
        "block": "minecraft:air"
      },
      {
        "char": "u",
        "block": "minecraft:air"
      },
      {
        "char": "r",
        "block": "minecraft:air"
      },
      {
        "char": "o",
        "block": "minecraft:air"
      },
      {
        "char": "s",
        "block": "minecraft:air"
      },
      {
        "char": "x",
        "block": "minecraft:air"
      },
      {
        "char": "O",
        "block": "minecraft:air"
      },
      {
        "char": "t",
        "block": "minecraft:air"
      },
      {
        "char": "m",
        "block": "minecraft:air"
      },
      {
        "char": "q",
        "block": "minecraft:grass"
      },
      {
        "char": "e",
        "block": "minecraft:air"
      },
      {
        "char": "k",
        "block": "minecraft:air"
      },
      {
        "char": "f",
        "block": "minecraft:air"
      },
      {
        "char": "c",
        "block": "minecraft:air"
      },
      {
        "char": "n",
        "block": "minecraft:air"
      },
      {
        "char": "d",
        "block": "minecraft:air"
      },
      {
        "char": "g",
        "block": "minecraft:air"
      },
      {
        "char": "E",
        "block": "minecraft:air"
      },
      {
        "char": "a",
        "block": "minecraft:air"
      },
      {
        "char": "A",
        "block": "minecraft:air"
      },
      {
        "char": "F",
        "block": "minecraft:air"
      },
      {
        "char": "j",
        "block": "minecraft:air"
      },
      {
        "char": "L",
        "block": "minecraft:air"
      },
      {
        "char": "i",
        "block": "minecraft:air"
      },
      {
        "char": "p",
        "block": "minecraft:air"
      }
    ]
  },
  "slices": [
    [
      "llllbbllurooosxr",
      "llllllllOrsoooxo",
      "lllllllluurorros",
      "llllllllOxtuoruo",
      "llllllllOorxoxto",
      "lllllxllrtsuoruo",
      "llllllllsOssooxo",
      "llllllllrrruoots",
      "tOxOosOOorxoossu",
      "oxrusuttssrusrro",
      "rtsutuooxtuxuusu",
      "srturrutuoroxssu",
      "srtuorurrotxuoox",
      "rstrtrrtsosuosxo",
      "xruuutsstxuosxtt",
      "rttoxuuuoororsss"
    ],
    [
      "bbbbbbbm      q ",
      "bbbqbbekf     q ",
      "bbbbbbcn    q   ",
      "bbbbbbbkfq      ",
      "bbbbcbemf  q q  ",
      "bbbbcqem        ",
      "bcbcceem d    q ",
      "mkmnmmkmfq      ",
      " gqgg  g  q     ",
      " qEq            ",
      " q      q  q    ",
      "      q   q qq  ",
      "    q      q   q",
      "              q ",
      "q        q   q  ",
      "    q     q     "
    ],
    [
      "bbbakkeA        ",
      "bbba  caf       ",
      "bbbbbbFA        ",
      "bbbbb eaf       ",
      "bbbb  caf       ",
      "bbbb  jg        ",
      "ceLebin  d      ",
      " apaaf af       ",
      " g gg  g        ",
      "                ",
      "                ",
      "                ",
      "                ",
      "                ",
      "                ",
      "                "
    ],
    [
      "bbba  cA        ",
      "bbb   baf       ",
      "bbb   jA        ",
      "bbb   caf       ",
      "      baf       ",
      "      jg        ",
      "ecicbim  d      ",
      " apaaf af       ",
      " g gg  g        ",
      "                ",
      "                ",
      "                ",
      "                ",
      "                ",
      "                ",
      "                "
    ],
    [
      "bb    cA        ",
      "bbb   caf       ",
      "bb    jA        ",
      "      baf       ",
      "      eaf       ",
      "      jg        ",
      "bbicbik  d      ",
      " apaaf af       ",
      " g gg  g        ",
      "                ",
      "                ",
      "                ",
      "                ",
      "                ",
      "                ",
      "                "
    ],
    [
      "b     cA        ",
      "      caf       ",
      "      jA        ",
      "      caf       ",
      "      eaf       ",
      "      jg        ",
      "eeicein  d      ",
      " apaaf af       ",
      " g gg  g        ",
      "                ",
      "                ",
      "                ",
      "                ",
      "                ",
      "                ",
      "                "
    ]
  ]
}