{
  "xsize": 16,
  "zsize": 16,
  "palette": {
    "palette": [
      {
        "char": " ",
        "block": "minecraft:air"
      },
      {
        "char": "m",
        "block": "minecraft:quartz_pillar[axis=y]"
      },
      {
        "char": "b",
        "block": "minecraft:smooth_stone_slab[type=top,waterlogged=false]"
      },
      {
        "char": "j",
        "block": "minecraft:vine[east=true,north=false,south=false,up=false,west=false]"
      },
      {
        "char": "X",
        "block": "minecraft:redstone_lamp[lit=false]"
      },
      {
        "char": "i",
        "block": "minecraft:vine[east=false,north=true,south=false,up=false,west=false]"
      },
      {
        "char": "U",
        "block": "minecraft:quartz_stairs[facing=east,half=top,shape=straight,waterlogged=false]"
      },
      {
        "char": "c",
        "block": "minecraft:polished_andesite"
      },
      {
        "char": "a",
        "block": "minecraft:andesite"
      },
      {
        "char": "o",
        "block": "minecraft:grass_block[snowy=false]"
      },
      {
        "char": "Ϣ",
        "block": "minecraft:quartz_stairs[facing=east,half=top,shape=outer_left,waterlogged=false]"
      },
      {
        "char": "H",
        "block": "minecraft:quartz_stairs[facing=north,half=top,shape=straight,waterlogged=false]"
      },
      {
        "char": "v",
        "block": "minecraft:air"
      },
      {
        "char": "F",
        "block": "minecraft:stone_brick_wall[east=none,north=none,south=none,up=true,waterlogged=false,weathering=false,west=none]"
      },
      {
        "char": "γ",
        "block": "minecraft:air"
      },
      {
        "char": "R",
        "block": "minecraft:light_blue_wool"
      },
      {
        "char": "J",
        "block": "minecraft:air"
      },
      {
        "char": "ϋ",
        "block": "minecraft:air"
      },
      {
        "char": "Ε",
        "block": "minecraft:air"
      }
    ]
  },
  "slices": [
    [
      "       mmmmmmmmm",
      "       mbbbbbbbb",
      "      jmbbbbbbbb",
      "       mbbbbbbbb",
      "       mbbbXbbbX",
      "       mbbbbbbbb",
      "      jmmmmmmmmm",
      "      jmbbbbbmbb",
      "       mbbbXbmbX",
      "       mbbbbbmbb",
      "       mbbbbbmbb",
      "       mbbbbbmbb",
      "       mmmmmmmmm",
      "       iiii   i ",
      "                ",
      "                "
    ],
    [
      "      Ucccccccaa",
      "      Uaccccacca",
      "      Uacocacaaa",
      "      Uaaccccacc",
      "      Uaacccaoca",
      "      Uccacaacca",
      "      Ucccaacaac",
      "      Uaacacacac",
      "      Ucaaccaccc",
      "      Uaaaccccca",
      "      Uaoccaacaa",
      "      Uccaacacac",
      "      Uaccaooacc",
      "      ϢHHHHHHHHH",
      "                ",
      "                "
    ],
    [
      "                ",
      "                ",
      "         v      ",
      "                ",
      "             v  ",
      "                ",
      "                ",
      "                ",
      "                ",
      "       F        ",
      "        v       ",
      "                ",
      "          Fvv   ",
      "                ",
      "                ",
      "                "
    ],
    [
      "                ",
      "                ",
      "                ",
      "                ",
      "                ",
      "                ",
      "                ",
      "                ",
      "                ",
      "       F        ",
      "                ",
      "                ",
      "          F     ",
      "                ",
      "                ",
      "                "
    ],
    [
      "                ",
      "                ",
      "                ",
      "                ",
      "                ",
      "                ",
      "                ",
      "                ",
      "                ",
      "       F        ",
      "       γ        ",
      "                ",
      "         γF     ",
      "                ",
      "                ",
      "                "
    ],
    [
      "                ",
      "                ",
      "                ",
      "                ",
      "                ",
      "                ",
      "                ",
      "                ",
      "      RJ        ",
      "       RJ       ",
      "        Rϋ      ",
      "         RJ     ",
      "          RJ    ",
      "           Ε    ",
      "                ",
      "                "
    ]
  ]
}