{
  "xsize": 16,
  "zsize": 16,
  "palette": {
    "palette": [
      {
        "char": " ",
        "block": "minecraft:air"
      },
      {
        "char": "m",
        "block": "minecraft:quartz_pillar[axis=y]"
      },
      {
        "char": "b",
        "block": "minecraft:smooth_stone_slab[type=top,waterlogged=false]"
      },
      {
        "char": "g",
        "block": "minecraft:vine[east=false,north=false,south=false,up=false,west=true]"
      },
      {
        "char": "X",
        "block": "minecraft:redstone_lamp[lit=false]"
      },
      {
        "char": "i",
        "block": "minecraft:vine[east=false,north=true,south=false,up=false,west=false]"
      },
      {
        "char": "a",
        "block": "minecraft:andesite"
      },
      {
        "char": "c",
        "block": "minecraft:polished_andesite"
      },
      {
        "char": "o",
        "block": "minecraft:grass_block[snowy=false]"
      },
      {
        "char": "T",
        "block": "minecraft:quartz_stairs[facing=west,half=top,shape=straight,waterlogged=false]"
      },
      {
        "char": "H",
        "block": "minecraft:quartz_stairs[facing=north,half=top,shape=straight,waterlogged=false]"
      },
      {
        "char": "Ϡ",
        "block": "minecraft:quartz_stairs[facing=north,half=top,shape=outer_left,waterlogged=false]"
      },
      {
        "char": "v",
        "block": "minecraft:air"
      },
      {
        "char": "ϐ",
        "block": "minecraft:azure_bluet"
      }
    ]
  },
  "slices": [
    [
      "mmmmmmmmmmmm    ",
      "bbbmbbbbbbbmg   ",
      "bbbmbbbbbbbm    ",
      "bbbmbbbbbbbmg   ",
      "bbbmbbbXbbbmg   ",
      "bbbmbbbbbbbmg   ",
      "mmmmbbbbbbbm    ",
      "bbbmbbbbbbbm    ",
      "bbbmbbbXbbbm    ",
      "bbbmbbbbbbbmg   ",
      "bbbmbbbbbbbm    ",
      "bbbmbbbbbbbmg   ",
      "mmmmmmmmmmmm    ",
      "i      i  i     ",
      "                ",
      "                "
    ],
    [
      "acaaacacaocaT   ",
      "ccccaacccaocT   ",
      "accaaccaccacT   ",
      "caaaccaaccaaT   ",
      "accccaccccaaT   ",
      "aaacaaacaacaT   ",
      "aaaccaccaaaaT   ",
      "ccaaccacaaccT   ",
      "ccaccccaoccaT   ",
      "ccacaaaaccacT   ",
      "accacccccoaaT   ",
      "caccccccoccaT   ",
      "acaacaccaacaT   ",
      "HHHHHHHHHHHHϠ   ",
      "                ",
      "                "
    ],
    [
      "         v      ",
      "          v     ",
      "                ",
      "                ",
      "                ",
      "                ",
      "                ",
      "                ",
      "        v       ",
      "                ",
      "         ϐ      ",
      "        v       ",
      "                ",
      "                ",
      "                ",
      "                "
    ],
    [
      "                ",
      "                ",
      "                ",
      "                ",
      "                ",
      "                ",
      "                ",
      "                ",
      "                ",
      "                ",
      "                ",
      "                ",
      "                ",
      "                ",
      "                ",
      "                "
    ],
    [
      "                ",
      "                ",
      "                ",
      "                ",
      "                ",
      "                ",
      "                ",
      "                ",
      "                ",
      "                ",
      "                ",
      "                ",
      "                ",
      "                ",
      "                ",
      "                "
    ],
    [
      "                ",
      "                ",
      "                ",
      "                ",
      "                ",
      "                ",
      "                ",
      "                ",
      "                ",
      "                ",
      "                ",
      "                ",
      "                ",
      "                ",
      "                ",
      "                "
    ]
  ]
}