{
  "xsize": 16,
  "zsize": 16,
  "palette": {
    "palette": [
      {
        "char": " ",
        "block": "minecraft:air"
      },
      {
        "char": "w",
        "block": "minecraft:deepslate[axis=y]"
      },
      {
        "char": "u",
        "block": "minecraft:basalt[axis=x]"
      },
      {
        "char": "z",
        "block": "minecraft:cobbled_deepslate"
      },
      {
        "char": "A",
        "block": "minecraft:cyan_terracotta"
      },
      {
        "char": "t",
        "block": "minecraft:blackstone"
      },
      {
        "char": "B",
        "block": "minecraft:yellow_concrete"
      },
      {
        "char": "a",
        "block": "minecraft:andesite"
      },
      {
        "char": "e",
        "block": "minecraft:stone[weathering=false]"
      },
      {
        "char": "o",
        "block": "minecraft:grass_block[snowy=false]"
      },
      {
        "char": "N",
        "block": "minecraft:quartz_block"
      },
      {
        "char": "4",
        "block": "minecraft:polished_diorite"
      },
      {
        "char": "L",
        "block": "minecraft:diorite"
      },
      {
        "char": "v",
        "block": "minecraft:air"
      },
      {
        "char": "p",
        "block": "minecraft:air"
      },
      {
        "char": "g",
        "block": "minecraft:vine[east=false,north=false,south=false,up=false,west=true]"
      },
      {
        "char": "P",
        "block": "minecraft:air"
      },
      {
        "char": "α",
        "block": "minecraft:stone_button[face=wall,facing=east,powered=false]"
      },
      {
        "char": "ε",
        "block": "minecraft:air"
      },
      {
        "char": "π",
        "block": "minecraft:lily_of_the_valley"
      },
      {
        "char": "ά",
        "block": "minecraft:air"
      },
      {
        "char": "V",
        "block": "minecraft:air"
      },
      {
        "char": "8",
        "block": "minecraft:glass_pane[east=false,north=false,south=true,waterlogged=false,west=false]"
      },
      {
        "char": "d",
        "block": "minecraft:vine[east=false,north=false,south=true,up=false,west=false]"
      },
      {
        "char": "Q",
        "block": "minecraft:air"
      },
      {
        "char": "ϵ",
        "block": "minecraft:oak_fence[east=false,north=true,south=false,waterlogged=false,west=true]"
      },
      {
        "char": "Ό",
        "block": "minecraft:air"
      },
      {
        "char": ";",
        "block": "minecraft:air"
      }
    ]
  },
  "slices": [
    [
      "wuzwAzwuAzwAwwwt",
      "utwttzwAtuzuztwt",
      "ztAAzAutzwtwuAuw",
      "ttwAwwzAtuAuAuzt",
      "BaeeBeoaBeaaBaae",
      "BeoeBooeBaeeBeea",
      "BeaeBeoeBeeaBooa",
      "BeaooeeaBaaooeee",
      "BoaaBaeeBeaaBeea",
      "eaoeoeeaeeoeeaee",
      "eeoeeeooeeeeeaee",
      "eeeoaaeeeeeeaoae",
      "aeeeeeeooeeeoeoe",
      "eeeeeoaoeeeeeeee",
      "N44NNL4LNNLLoeae",
      "4NN4NLLLo4Noeoee"
    ],
    [
      "                ",
      "                ",
      "                ",
      "                ",
      "      v     p   ",
      "g v  Pv p     p ",
      "α     P      Pv ",
      "g  vv      vP   ",
      " v    p       p ",
      "α v v     v     ",
      "  v   vv       p",
      "   vp      p v  ",
      " p     Pv   ε π ",
      "     v v  p ά   ",
      "p           V p ",
      "8d8dddddvdddVv  "
    ],
    [
      "                ",
      "                ",
      "                ",
      "                ",
      "                ",
      "g    Q          ",
      "      Q      Q  ",
      "g           Q   ",
      "                ",
      "g               ",
      "                ",
      "                ",
      "       Q    ϵ   ",
      "            ε   ",
      "            V   ",
      "8d8dddddddddV   "
    ],
    [
      "                ",
      "                ",
      "                ",
      "                ",
      "                ",
      "                ",
      "                ",
      "                ",
      "                ",
      "g               ",
      "                ",
      "                ",
      "            Ό   ",
      "            ά   ",
      "            V   ",
      "8d8dddddddddV   "
    ],
    [
      "                ",
      "                ",
      "                ",
      "                ",
      "                ",
      "                ",
      "                ",
      "                ",
      "                ",
      "                ",
      "                ",
      "                ",
      "            Ό   ",
      "            ά   ",
      "            V   ",
      "8d8dddddddddV   "
    ],
    [
      "                ",
      "                ",
      "                ",
      "                ",
      "                ",
      "                ",
      "                ",
      "                ",
      "                ",
      "                ",
      "                ",
      "                ",
      "            ;   ",
      "            ;   ",
      "            ;   ",
      "dddddddddddd;   "
    ]
  ]
}