{
  "xsize": 16,
  "zsize": 16,
  "palette": {
    "palette": [
      {
        "char": " ",
        "block": "minecraft:structure_void"
      },
      {
        "char": "e",
        "block": "minecraft:cyan_terracotta"
      },
      {
        "char": "c",
        "block": "minecraft:basalt[axis=z]"
      },
      {
        "char": "a",
        "block": "minecraft:blackstone"
      },
      {
        "char": "b",
        "block": "minecraft:deepslate[axis=y]"
      },
      {
        "char": "d",
        "block": "minecraft:cobbled_deepslate"
      },
      {
        "char": "i",
        "block": "minecraft:air"
      },
      {
        "char": "k",
        "block": "minecraft:vine[east=false,north=true,south=false,up=false,west=false]"
      },
      {
        "char": "z",
        "block": "minecraft:vine[east=true,north=true,south=false,up=false,west=false]"
      },
      {
        "char": "v",
        "block": "minecraft:quartz_block"
      },
      {
        "char": "x",
        "block": "minecraft:calcite"
      },
      {
        "char": "w",
        "block": "minecraft:vine[east=false,north=false,south=true,up=false,west=false]"
      },
      {
        "char": "l",
        "block": "minecraft:vine[east=true,north=false,south=false,up=false,west=false]"
      },
      {
        "char": "n",
        "block": "minecraft:polished_diorite"
      },
      {
        "char": "s",
        "block": "minecraft:diorite"
      },
      {
        "char": "h",
        "block": "minecraft:grass_block[snowy=false]"
      },
      {
        "char": "A",
        "block": "minecraft:dirt"
      },
      {
        "char": "p",
        "block": "minecraft:air"
      },
      {
        "char": "f",
        "block": "minecraft:air"
      },
      {
        "char": "q",
        "block": "minecraft:vine[east=false,north=false,south=false,up=false,west=true]"
      },
      {
        "char": "j",
        "block": "minecraft:air"
      },
      {
        "char": "y",
        "block": "minecraft:stone[weathering=false]"
      },
      {
        "char": "u",
        "block": "minecraft:cracked_stone_bricks"
      },
      {
        "char": "o",
        "block": "minecraft:vine[east=false,north=false,south=false,up=true,west=false]"
      },
      {
        "char": "r",
        "block": "minecraft:smooth_stone_slab[type=bottom,waterlogged=false]"
      },
      {
        "char": "g",
        "block": "minecraft:mossy_cobblestone_slab[type=bottom,waterlogged=false]"
      },
      {
        "char": "m",
        "block": "minecraft:moss_block"
      },
      {
        "char": "t",
        "block": "minecraft:cobblestone_slab[type=bottom,waterlogged=false,weathering=false]"
      }
    ]
  },
  "slices": [
    [
      "ecabbaddabdedbaa",
      "dbacikk  zvxcaea",
      "baeai  wwlnsabha",
      "ddcdnsnxnvsvbcce",
      "bhbennvssnxnddaa",
      "dccAbhdadbdbehea",
      "cddadadhabcbbhhe",
      "dbehdedbcdaaahee",
      "ddccbdabbcbaacee",
      "cbbbdbceeceaaeae",
      "echhccedbcacabhe",
      "aeeeebcedcddbeca",
      "bebcbdadcdchcchh",
      "daaaabdbheaecabc",
      "baahccdhacababec",
      "aabdededcachhcba"
    ],
    [
      "  lpffffffffpq  ",
      "   k        j   ",
      "            j   ",
      "            j   ",
      "   w        j   ",
      "  lpq      lpq  ",
      "   k        k   ",
      "                ",
      "                ",
      "                ",
      "                ",
      "                ",
      "                ",
      "                ",
      "                ",
      "                "
    ],
    [
      "  lyffffffffpq  ",
      "   k        j   ",
      "            j   ",
      "            j   ",
      "   w        j   ",
      "  luq      luq  ",
      "            k   ",
      "                ",
      "                ",
      "                ",
      "                ",
      "                ",
      "                ",
      "                ",
      "                ",
      "                "
    ],
    [
      "  luffffffffu   ",
      "   k  oo    j   ",
      "      oo    j   ",
      "           oj   ",
      "    o   o   j   ",
      "   pq      lp   ",
      "            k   ",
      "                ",
      "                ",
      "                ",
      "                ",
      "                ",
      "                ",
      "                ",
      "                ",
      "                "
    ],
    [
      "   irgimgiigi   ",
      "   giimmigggg   ",
      "   gggmmrggti   ",
      "   iiggiggimr   ",
      "   rmrttmtggt   ",
      "   ggiggiiigr   ",
      "                ",
      "                ",
      "                ",
      "                ",
      "                ",
      "                ",
      "                ",
      "                ",
      "                ",
      "                "
    ]
  ]
}