{
  "xsize": 16,
  "zsize": 16,
  "palette": {
    "palette": [
      {
        "char": " ",
        "block": "minecraft:structure_void"
      },
      {
        "char": "a",
        "block": "minecraft:cyan_terracotta"
      },
      {
        "char": "i",
        "block": "minecraft:diorite"
      },
      {
        "char": "h",
        "block": "minecraft:polished_diorite"
      },
      {
        "char": "m",
        "block": "minecraft:quartz_block"
      },
      {
        "char": "p",
        "block": "minecraft:calcite"
      },
      {
        "char": "e",
        "block": "minecraft:blackstone"
      },
      {
        "char": "k",
        "block": "minecraft:grass_block[snowy=false]"
      },
      {
        "char": "d",
        "block": "minecraft:cobbled_deepslate"
      },
      {
        "char": "o",
        "block": "minecraft:smooth_quartz_stairs[facing=west,half=bottom,shape=straight,waterlogged=false]"
      },
      {
        "char": "j",
        "block": "minecraft:vine[east=false,north=true,south=false,up=false,west=false]"
      },
      {
        "char": "n",
        "block": "minecraft:smooth_quartz_stairs[facing=east,half=top,shape=straight,waterlogged=false]"
      },
      {
        "char": "c",
        "block": "minecraft:basalt[axis=z]"
      },
      {
        "char": "b",
        "block": "minecraft:deepslate[axis=y]"
      },
      {
        "char": "s",
        "block": "minecraft:vine[east=false,north=false,south=true,up=false,west=false]"
      },
      {
        "char": "q",
        "block": "minecraft:air"
      },
      {
        "char": "t",
        "block": "minecraft:vine[east=false,north=false,south=false,up=false,west=true]"
      },
      {
        "char": "l",
        "block": "minecraft:air"
      },
      {
        "char": "g",
        "block": "minecraft:air"
      },
      {
        "char": "r",
        "block": "minecraft:air"
      },
      {
        "char": "u",
        "block": "minecraft:air"
      },
      {
        "char": "v",
        "block": "minecraft:air"
      },
      {
        "char": "w",
        "block": "minecraft:air"
      },
      {
        "char": "f",
        "block": "minecraft:vine[east=false,north=false,south=false,up=true,west=false]"
      }
    ]
  },
  "slices": [
    [
      "aaaihmiphihhmaea",
      "kedio jj  nhicab",
      "cbamos ss niibba",
      "ekbihmiphihhhake",
      "kbbbeeabkceaacdb",
      "cdaadbekcakdckee",
      "dabbcebcecaadedb",
      "abebaccbaccbkaea",
      "kekbccbddecddkad",
      "dbdabaccdacdbbcb",
      "cbdaakcekaedkbdd",
      "beddkaeecbackkba",
      "edakbacdedcadebc",
      "cbedbaabacecabdd",
      "bacdddkbckbaaedb",
      "bebbeeckcabcaaba"
    ],
    [
      "   qhimimihhpt  ",
      "l   jj   nojj   ",
      "         no     ",
      " l qggggggggr l ",
      "l       l       ",
      "       l  l  l  ",
      "                ",
      "            l   ",
      "l l          l  ",
      "               u",
      "     l      l vu",
      "    l       ll v",
      "   l            ",
      "                ",
      "      l  l      ",
      "       l        "
    ],
    [
      "   qhimphihmpt  ",
      "     jj nojjj   ",
      "        no      ",
      "   qggggggggr   ",
      "                ",
      "                ",
      "                ",
      "                ",
      "                ",
      "                ",
      "                ",
      "                ",
      "                ",
      "                ",
      "                ",
      "                "
    ],
    [
      "   qhmiphihhmt  ",
      "       nojjjj   ",
      "       no       ",
      "   qggggggggr   ",
      "                ",
      "                ",
      "                ",
      "                ",
      "                ",
      "                ",
      "                ",
      "                ",
      "                ",
      "                ",
      "                ",
      "                "
    ],
    [
      "   qmhhphipph   ",
      "    j nojjjjj   ",
      "      no        ",
      "   qggggggggr   ",
      "                ",
      "                ",
      "                ",
      "                ",
      "                ",
      "                ",
      "               w",
      "                ",
      "                ",
      "                ",
      "                ",
      "                "
    ],
    [
      "   qpimmhhmmp  f",
      " f   nojjjjj f  ",
      "     no    f  f ",
      " f qggggggggr   ",
      " ff    f  f f   ",
      "    f    f   f  ",
      " f     f f      ",
      "    f        f  ",
      "          f    f",
      "     f f    f   ",
      "  f           f ",
      " f  ff    f     ",
      "      f  f  f f ",
      "   f            ",
      " f    f f f f   ",
      "          f  f  "
    ],
    [
      "aaaihmiphihhmaea",
      "aedio     nhicab",
      "cbamo     niibba",
      "eabihmiphihhhaae",
      "abbbeeabaceaacdb",
      "cdaadbeacaadcaee",
      "dabbcebcecaadedb",
      "abebaccbaccbaaea",
      "aeabccbddecddaad",
      "dbdabaccdacdbbcb",
      "cbdaaaceaaedabdd",
      "beddaaeecbacaaba",
      "edaabacdedcadebc",
      "cbedbaabacecabdd",
      "bacdddabcabaaedb",
      "bebbeecacabcaaba"
    ]
  ]
}