{
  "xsize": 16,
  "zsize": 16,
  "palette": {
    "palette": [
      {
        "char": " ",
        "block": "minecraft:air"
      },
      {
        "char": "a",
        "block": "minecraft:air"
      },
      {
        "char": "i",
        "block": "minecraft:air"
      },
      {
        "char": "h",
        "block": "minecraft:air"
      },
      {
        "char": "m",
        "block": "minecraft:air"
      },
      {
        "char": "p",
        "block": "minecraft:air"
      },
      {
        "char": "e",
        "block": "minecraft:air"
      },
      {
        "char": "k",
        "block": "minecraft:air"
      },
      {
        "char": "d",
        "block": "minecraft:air"
      },
      {
        "char": "o",
        "block": "minecraft:air"
      },
      {
        "char": "j",
        "block": "minecraft:air"
      },
      {
        "char": "n",
        "block": "minecraft:air"
      },
      {
        "char": "c",
        "block": "minecraft:air"
      },
      {
        "char": "b",
        "block": "minecraft:air"
      },
      {
        "char": "s",
        "block": "minecraft:air"
      },
      {
        "char": "q",
        "block": "minecraft:air"
      },
      {
        "char": "t",
        "block": "minecraft:air"
      },
      {
        "char": "l",
        "block": "minecraft:tall_grass[half=lower]"
      },
      {
        "char": "g",
        "block": "minecraft:air"
      },
      {
        "char": "r",
        "block": "minecraft:air"
      },
      {
        "char": "u",
        "block": "minecraft:air"
      },
      {
        "char": "v",
        "block": "minecraft:air"
      },
      {
        "char": "w",
        "block": "minecraft:air"
      },
      {
        "char": "f",
        "block": "minecraft:air"
      }
    ]
  },
  "slices": [
    [
      "aaaihmiphihhmaea",
      "kedio jj  nhicab",
      "cbamos ss niibba",
      "ekbihmiphihhhake",
      "kbbbeeabkceaacdb",
      "cdaadbekcakdckee",
      "dabbcebcecaadedb",
      "abebaccbaccbkaea",
      "kekbccbddecddkad",
      "dbdabaccdacdbbcb",
      "cbdaakcekaedkbdd",
      "beddkaeecbackkba",
      "edakbacdedcadebc",
      "cbedbaabacecabdd",
      "bacdddkbckbaaedb",
      "bebbeeckcabcaaba"
    ],
    [
      "   qhimimihhpt  ",
      "l   jj   nojj   ",
      "         no     ",
      " l qggggggggr l ",
      "l       l       ",
      "       l  l  l  ",
      "                ",
      "            l   ",
      "l l          l  ",
      "               u",
      "     l      l vu",
      "    l       ll v",
      "   l            ",
      "                ",
      "      l  l      ",
      "       l        "
    ],
    [
      "   qhimphihmpt  ",
      "     jj nojjj   ",
      "        no      ",
      "   qggggggggr   ",
      "                ",
      "                ",
      "                ",
      "                ",
      "                ",
      "                ",
      "                ",
      "                ",
      "                ",
      "                ",
      "                ",
      "                "
    ],
    [
      "   qhmiphihhmt  ",
      "       nojjjj   ",
      "       no       ",
      "   qggggggggr   ",
      "                ",
      "                ",
      "                ",
      "                ",
      "                ",
      "                ",
      "                ",
      "                ",
      "                ",
      "                ",
      "                ",
      "                "
    ],
    [
      "   qmhhphipph   ",
      "    j nojjjjj   ",
      "      no        ",
      "   qggggggggr   ",
      "                ",
      "                ",
      "                ",
      "                ",
      "                ",
      "                ",
      "               w",
      "                ",
      "                ",
      "                ",
      "                ",
      "                "
    ],
    [
      "   qpimmhhmmp  f",
      " f   nojjjjj f  ",
      "     no    f  f ",
      " f qggggggggr   ",
      " ff    f  f f   ",
      "    f    f   f  ",
      " f     f f      ",
      "    f        f  ",
      "          f    f",
      "     f f    f   ",
      "  f           f ",
      " f  ff    f     ",
      "      f  f  f f ",
      "   f            ",
      " f    f f f f   ",
      "          f  f  "
    ],
    [
      "aaaihmiphihhmaea",
      "aedio     nhicab",
      "cbamo     niibba",
      "eabihmiphihhhaae",
      "abbbeeabaceaacdb",
      "cdaadbeacaadcaee",
      "dabbcebcecaadedb",
      "abebaccbaccbaaea",
      "aeabccbddecddaad",
      "dbdabaccdacdbbcb",
      "cbdaaaceaaedabdd",
      "beddaaeecbacaaba",
      "edaabacdedcadebc",
      "cbedbaabacecabdd",
      "bacdddabcabaaedb",
      "bebbeecacabcaaba"
    ]
  ]
}