{
  "xsize": 16,
  "zsize": 16,
  "palette": {
    "palette": [
      {
        "char": " ",
        "block": "minecraft:air"
      },
      {
        "char": "b",
        "block": "minecraft:air"
      },
      {
        "char": "q",
        "block": "minecraft:air"
      },
      {
        "char": "k",
        "block": "minecraft:air"
      },
      {
        "char": "c",
        "block": "minecraft:air"
      },
      {
        "char": "a",
        "block": "minecraft:air"
      },
      {
        "char": "d",
        "block": "minecraft:air"
      },
      {
        "char": "p",
        "block": "minecraft:air"
      },
      {
        "char": "x",
        "block": "minecraft:air"
      },
      {
        "char": "i",
        "block": "minecraft:air"
      },
      {
        "char": "v",
        "block": "minecraft:air"
      },
      {
        "char": "j",
        "block": "minecraft:air"
      },
      {
        "char": "A",
        "block": "minecraft:air"
      },
      {
        "char": "f",
        "block": "minecraft:air"
      },
      {
        "char": "u",
        "block": "minecraft:air"
      },
      {
        "char": "D",
        "block": "minecraft:air"
      },
      {
        "char": "z",
        "block": "minecraft:air"
      },
      {
        "char": "G",
        "block": "minecraft:air"
      },
      {
        "char": "B",
        "block": "minecraft:air"
      },
      {
        "char": "O",
        "block": "minecraft:air"
      },
      {
        "char": "S",
        "block": "minecraft:air"
      },
      {
        "char": "r",
        "block": "minecraft:air"
      },
      {
        "char": "o",
        "block": "minecraft:air"
      },
      {
        "char": "g",
        "block": "minecraft:tall_grass[half=lower]"
      },
      {
        "char": "C",
        "block": "minecraft:air"
      },
      {
        "char": "I",
        "block": "minecraft:air"
      },
      {
        "char": "e",
        "block": "minecraft:air"
      },
      {
        "char": "s",
        "block": "minecraft:air"
      },
      {
        "char": "m",
        "block": "minecraft:air"
      },
      {
        "char": "w",
        "block": "minecraft:air"
      },
      {
        "char": "U",
        "block": "minecraft:air"
      },
      {
        "char": "l",
        "block": "minecraft:air"
      },
      {
        "char": "T",
        "block": "minecraft:air"
      },
      {
        "char": "M",
        "block": "minecraft:air"
      },
      {
        "char": "J",
        "block": "minecraft:air"
      },
      {
        "char": "L",
        "block": "minecraft:air"
      },
      {
        "char": "Q",
        "block": "minecraft:air"
      },
      {
        "char": "P",
        "block": "minecraft:air"
      },
      {
        "char": "E",
        "block": "minecraft:air"
      },
      {
        "char": "y",
        "block": "minecraft:air"
      },
      {
        "char": "N",
        "block": "minecraft:air"
      },
      {
        "char": "t",
        "block": "minecraft:air"
      },
      {
        "char": "H",
        "block": "minecraft:grass"
      },
      {
        "char": "h",
        "block": "minecraft:tall_grass[half=upper]"
      },
      {
        "char": "n",
        "block": "minecraft:air"
      },
      {
        "char": "R",
        "block": "minecraft:air"
      },
      {
        "char": "K",
        "block": "minecraft:air"
      },
      {
        "char": "F",
        "block": "minecraft:air"
      }
    ]
  },
  "slices": [
    [
      "bqkbcaacdaacbpxb",
      "bivbadjaaccabApb",
      "piibddcaaafdbiki",
      "ivibcadaadccbxkp",
      "fjaddfdcdcaafaca",
      "fdjdaafaffaacfcc",
      "jfadfccddcccaaac",
      "adcjufddacdjcjaf",
      "accdcdddccjcfccc",
      "ddaafcdfaaaaacad",
      "djdacfafddjacdca",
      "acddfdfdaadcaddc",
      "bbbbbbbbbbbbbbbb",
      "bkiAkbivikiipiki",
      "pDibzikDkqzkuqqu",
      "bbbbbbbbbbbbbbbb"
    ],
    [
      "     GBOBS ro  g",
      "g  gr CICe  gr g",
      "  rs m mee  sm  ",
      "   g  wew   g  U",
      "ee              ",
      "oee        o l l",
      " eee o T  M le  ",
      "l e m       eee ",
      "  m          ee ",
      "J  L m m  Q  Pe ",
      "               E",
      "       lo       ",
      " glsggm glg sg g",
      "g o gE        y ",
      "   ge  Nt     e ",
      "ollet ety oggg H"
    ],
    [
      "               h",
      "h  h        h  h",
      "   n    e   n   ",
      "   h        h   ",
      "                ",
      " e              ",
      "  e             ",
      "             e  ",
      "             e  ",
      "                ",
      "                ",
      "                ",
      " h nhh  h h nh h",
      "h   h           ",
      "   h            ",
      "    e      hhh  "
    ],
    [
      "                ",
      "                ",
      "   n        n   ",
      "                ",
      "                ",
      "                ",
      "                ",
      "                ",
      "                ",
      "                ",
      "                ",
      "                ",
      "   n        n   ",
      "                ",
      "                ",
      "                "
    ],
    [
      "                ",
      "                ",
      "   R        K   ",
      "                ",
      "                ",
      "                ",
      "                ",
      "                ",
      "                ",
      "                ",
      "                ",
      "                ",
      "   F        F   ",
      "                ",
      "                ",
      "                "
    ],
    [
      "                ",
      "                ",
      "                ",
      "                ",
      "                ",
      "                ",
      "                ",
      "                ",
      "                ",
      "                ",
      "                ",
      "                ",
      "                ",
      "                ",
      "                ",
      "                "
    ]
  ]
}