{
  "xsize": 16,
  "zsize": 16,
  "palette": {
    "palette": [
      {
        "char": " ",
        "block": "minecraft:air"
      },
      {
        "char": "b",
        "block": "minecraft:cobbled_deepslate"
      },
      {
        "char": "f",
        "block": "minecraft:basalt[axis=x]"
      },
      {
        "char": "c",
        "block": "minecraft:cyan_terracotta"
      },
      {
        "char": "d",
        "block": "minecraft:blackstone"
      },
      {
        "char": "e",
        "block": "minecraft:deepslate[axis=y]"
      },
      {
        "char": "g",
        "block": "minecraft:grass_block[snowy=false]"
      },
      {
        "char": "a",
        "block": "minecraft:oak_leaves[distance=7,persistent=true,waterlogged=false]"
      },
      {
        "char": "r",
        "block": "minecraft:air"
      },
      {
        "char": "o",
        "block": "minecraft:air"
      },
      {
        "char": "p",
        "block": "minecraft:air"
      },
      {
        "char": "n",
        "block": "minecraft:large_fern[half=lower]"
      },
      {
        "char": "v",
        "block": "minecraft:air"
      },
      {
        "char": "l",
        "block": "minecraft:air"
      },
      {
        "char": "j",
        "block": "minecraft:air"
      },
      {
        "char": "i",
        "block": "minecraft:air"
      },
      {
        "char": "h",
        "block": "minecraft:air"
      },
      {
        "char": "u",
        "block": "minecraft:structure_void"
      },
      {
        "char": "q",
        "block": "minecraft:structure_void"
      },
      {
        "char": "t",
        "block": "minecraft:structure_void"
      },
      {
        "char": "s",
        "block": "minecraft:structure_void"
      },
      {
        "char": "w",
        "block": "minecraft:fern"
      },
      {
        "char": "m",
        "block": "minecraft:large_fern[half=upper]"
      },
      {
        "char": "k",
        "block": "minecraft:air"
      }
    ]
  },
  "slices": [
    [
      "bfcdcbecbeebbdgc",
      "bfcdcbecdfbddfcg",
      "cfddggbefbecfbcc",
      "dfbfgededebcbdcc",
      "edbfebbcffdegccb",
      "cbbdcebcbcddegcc",
      "cecfcffdfddbbdfe",
      "cbcebbddebbcbece",
      "ccbbbcbbdcbbbcbb",
      "cbeebbdbcbeebbdb",
      "bdfbddfccdfbddfc",
      "bfgecfbccfbecfbc",
      "cdebcbdggdebcbdc",
      "dffdecccbffdeccc",
      "ebcddecccbcgdecc",
      "dfddbbdfefddbbdf"
    ],
    [
      " aro    paa   n ",
      "aaaa  v aaaaaa l",
      "aaa nl  aaaaaa  ",
      " aj l    aaaa   ",
      "    ij h aaal   ",
      "       u  aa l j",
      "aaa h i hi  j   ",
      "aaaah h j i     ",
      "haaa   q ht  s  ",
      " iaa i  j ih    ",
      "   h        j   ",
      " jl          hh ",
      "aaa i  wl   aa i",
      "aaaa  aaa   aaa ",
      " aa  aaaa  l aaa",
      "      aa   j   a"
    ],
    [
      "              m ",
      " a       aa    k",
      " a  mk   aaa    ",
      "    k    aaa    ",
      "          a k   ",
      "             k  ",
      "                ",
      "  a             ",
      "  a             ",
      "                ",
      "                ",
      "  k             ",
      "        k       ",
      " aa          a  ",
      "      aa   k  a ",
      "                "
    ],
    [
      "                ",
      "                ",
      "          a     ",
      "          a     ",
      "                ",
      "                ",
      "                ",
      "                ",
      "                ",
      "                ",
      "                ",
      "                ",
      "                ",
      "                ",
      "                ",
      "                "
    ],
    [
      "                ",
      "                ",
      "                ",
      "                ",
      "                ",
      "                ",
      "                ",
      "                ",
      "                ",
      "                ",
      "                ",
      "                ",
      "                ",
      "                ",
      "                ",
      "                "
    ],
    [
      "                ",
      "                ",
      "                ",
      "                ",
      "                ",
      "                ",
      "                ",
      "                ",
      "                ",
      "                ",
      "                ",
      "                ",
      "                ",
      "                ",
      "                ",
      "                "
    ]
  ]
}