{
  "xsize": 16,
  "zsize": 16,
  "palette": {
    "palette": [
      {
        "char": " ",
        "block": "minecraft:air"
      },
      {
        "char": "a",
        "block": "minecraft:air"
      },
      {
        "char": "j",
        "block": "minecraft:air"
      },
      {
        "char": "m",
        "block": "minecraft:air"
      },
      {
        "char": "e",
        "block": "minecraft:air"
      },
      {
        "char": "b",
        "block": "minecraft:air"
      },
      {
        "char": "d",
        "block": "minecraft:air"
      },
      {
        "char": "q",
        "block": "minecraft:air"
      },
      {
        "char": "u",
        "block": "minecraft:air"
      },
      {
        "char": "o",
        "block": "minecraft:air"
      },
      {
        "char": "l",
        "block": "minecraft:air"
      },
      {
        "char": "h",
        "block": "minecraft:air"
      },
      {
        "char": "t",
        "block": "minecraft:air"
      },
      {
        "char": "C",
        "block": "minecraft:air"
      },
      {
        "char": "F",
        "block": "minecraft:air"
      },
      {
        "char": "z",
        "block": "minecraft:air"
      },
      {
        "char": "x",
        "block": "minecraft:air"
      },
      {
        "char": "f",
        "block": "minecraft:tall_grass[half=lower]"
      },
      {
        "char": "i",
        "block": "minecraft:air"
      },
      {
        "char": "k",
        "block": "minecraft:air"
      },
      {
        "char": "p",
        "block": "minecraft:grass"
      },
      {
        "char": "c",
        "block": "minecraft:air"
      },
      {
        "char": "r",
        "block": "minecraft:air"
      },
      {
        "char": "v",
        "block": "minecraft:air"
      },
      {
        "char": "G",
        "block": "minecraft:air"
      },
      {
        "char": "y",
        "block": "minecraft:air"
      },
      {
        "char": "D",
        "block": "minecraft:air"
      },
      {
        "char": "s",
        "block": "minecraft:air"
      },
      {
        "char": "g",
        "block": "minecraft:tall_grass[half=upper]"
      },
      {
        "char": "n",
        "block": "minecraft:air"
      },
      {
        "char": "w",
        "block": "minecraft:air"
      },
      {
        "char": "E",
        "block": "minecraft:air"
      },
      {
        "char": "B",
        "block": "minecraft:air"
      },
      {
        "char": "A",
        "block": "minecraft:air"
      }
    ]
  },
  "slices": [
    [
      "ajmaebbedbbeaqua",
      "ajoabdlbbeebauqa",
      "qjjaddebbbhdajmj",
      "jojaebdbbdeeaumq",
      "hlbddhdedebbhbeb",
      "hdldbbhbhhbbehee",
      "lhbdheeddeeebbbe",
      "bdelthddbadlelbh",
      "beededddealaheee",
      "ddbbhedhabbbbebd",
      "dldbehbhddlbedeb",
      "beddhdhdbbdebdde",
      "aaaaaaaaaaaaaaaa",
      "amjCmajojmjjqomF",
      "qzoaxomzmoxmtjjt",
      "aaaaaaaaaaaaaaaa"
    ],
    [
      "f ii  k  i  f  f",
      "p  f    cci f  k",
      "i  r   ccc ir   ",
      "cc v    c  if f ",
      " cc      i      ",
      " cc     i       ",
      "Gi     c k  i  k",
      "    y cccf      ",
      "      cc p vi   ",
      " ccc k  p   cck ",
      " cccc    icccc  ",
      "  cc  kk k cc   ",
      "kffrifff fffrfff",
      "ff   f          ",
      "    c  Dsk f  ci",
      "pyp s cs ffpff v"
    ],
    [
      "g           g  g",
      "   g        g   ",
      "   n    c   n   ",
      "            g g ",
      " c              ",
      "                ",
      "                ",
      "    w  c g      ",
      "                ",
      "                ",
      "   c        c   ",
      "                ",
      " ggn ggg gggnggg",
      "gg   g          ",
      "           g    ",
      " w       gg gg  "
    ],
    [
      "                ",
      "                ",
      "   n        n   ",
      "                ",
      "                ",
      "                ",
      "                ",
      "                ",
      "                ",
      "                ",
      "                ",
      "                ",
      "   n        n   ",
      "                ",
      "                ",
      "                "
    ],
    [
      "                ",
      "                ",
      "   E        B   ",
      "                ",
      "                ",
      "                ",
      "                ",
      "                ",
      "                ",
      "                ",
      "                ",
      "                ",
      "   A        A   ",
      "                ",
      "                ",
      "                "
    ],
    [
      "                ",
      "                ",
      "                ",
      "                ",
      "                ",
      "                ",
      "                ",
      "                ",
      "                ",
      "                ",
      "                ",
      "                ",
      "                ",
      "                ",
      "                ",
      "                "
    ]
  ]
}