{
  "xsize": 16,
  "zsize": 16,
  "palette": {
    "palette": [
      {
        "char": " ",
        "block": "minecraft:air"
      },
      {
        "char": "a",
        "block": "minecraft:air"
      },
      {
        "char": "s",
        "block": "minecraft:air"
      },
      {
        "char": "k",
        "block": "minecraft:air"
      },
      {
        "char": "h",
        "block": "minecraft:air"
      },
      {
        "char": "g",
        "block": "minecraft:air"
      },
      {
        "char": "d",
        "block": "minecraft:air"
      },
      {
        "char": "n",
        "block": "minecraft:air"
      },
      {
        "char": "c",
        "block": "minecraft:air"
      },
      {
        "char": "i",
        "block": "minecraft:air"
      },
      {
        "char": "u",
        "block": "minecraft:air"
      },
      {
        "char": "r",
        "block": "minecraft:air"
      },
      {
        "char": "y",
        "block": "minecraft:air"
      },
      {
        "char": "E",
        "block": "minecraft:air"
      },
      {
        "char": "D",
        "block": "minecraft:air"
      },
      {
        "char": "K",
        "block": "minecraft:air"
      },
      {
        "char": "Q",
        "block": "minecraft:air"
      },
      {
        "char": "B",
        "block": "minecraft:air"
      },
      {
        "char": "F",
        "block": "minecraft:air"
      },
      {
        "char": "C",
        "block": "minecraft:air"
      },
      {
        "char": "j",
        "block": "minecraft:air"
      },
      {
        "char": "b",
        "block": "minecraft:air"
      },
      {
        "char": "m",
        "block": "minecraft:air"
      },
      {
        "char": "l",
        "block": "minecraft:air"
      },
      {
        "char": "x",
        "block": "minecraft:air"
      },
      {
        "char": "O",
        "block": "minecraft:air"
      },
      {
        "char": "e",
        "block": "minecraft:tall_grass[half=lower]"
      },
      {
        "char": "q",
        "block": "minecraft:air"
      },
      {
        "char": "I",
        "block": "minecraft:air"
      },
      {
        "char": "L",
        "block": "minecraft:air"
      },
      {
        "char": "z",
        "block": "minecraft:air"
      },
      {
        "char": "v",
        "block": "minecraft:air"
      },
      {
        "char": "P",
        "block": "minecraft:air"
      },
      {
        "char": "t",
        "block": "minecraft:grass"
      },
      {
        "char": "H",
        "block": "minecraft:air"
      },
      {
        "char": "N",
        "block": "minecraft:air"
      },
      {
        "char": "M",
        "block": "minecraft:air"
      },
      {
        "char": "T",
        "block": "minecraft:air"
      },
      {
        "char": "w",
        "block": "minecraft:air"
      },
      {
        "char": "f",
        "block": "minecraft:tall_grass[half=upper]"
      },
      {
        "char": "o",
        "block": "minecraft:air"
      },
      {
        "char": "p",
        "block": "minecraft:air"
      },
      {
        "char": "J",
        "block": "minecraft:air"
      },
      {
        "char": "S",
        "block": "minecraft:air"
      },
      {
        "char": "R",
        "block": "minecraft:air"
      },
      {
        "char": "A",
        "block": "minecraft:air"
      },
      {
        "char": "G",
        "block": "minecraft:air"
      }
    ]
  },
  "slices": [
    [
      "askahgdnchhcaiaa",
      "uryahchcdhcdaEra",
      "DsKancddghhgasia",
      "aaaacdghcdhhakra",
      "guhngccggnhnakua",
      "dhdddhggdccdaQra",
      "dgcdadhgnnddaiia",
      "gcddgcdchgdhaika",
      "cddacnuhcngcaska",
      "daddnggcngddaiia",
      "addcgcchhcchaBsa",
      "ccgccdcccdguaika",
      "aaaaaaaaaaaaaiia",
      "BkFkaikriisikyra",
      "DkErrrCisyFkksCa",
      "aaaaaaaaaaaaaaaa"
    ],
    [
      " j bb mlx  j bOe",
      "e  qx     xmm be",
      "  lq  lI  bbL qz",
      " v ejP z bbbv  e",
      " e l     bbjj et",
      " j  l     b e  l",
      "          j tmHz",
      "m   m m   N vl e",
      " bbt    j M q  l",
      " bbbj   ll me b ",
      "tmbbb m     ejbq",
      "mbbbbb     eteb ",
      "qvbbbbevjleTqeeq",
      " l bb j  t w j m",
      " w   jwm b   bqe",
      "l qee eeeeeeete "
    ],
    [
      "               f",
      "f  o           f",
      "   o          o ",
      " p f       bp  f",
      " f        b   f ",
      "       J    f   ",
      "                ",
      "       S    p  f",
      "            o   ",
      "  b         f   ",
      "   b        f  o",
      "   b       f f  ",
      "op b  fp  f offo",
      "                ",
      "              of",
      "  off fffffff f "
    ],
    [
      "                ",
      "                ",
      "                ",
      " p          p   ",
      "                ",
      "                ",
      "                ",
      "            p   ",
      "                ",
      "                ",
      "                ",
      "                ",
      " p     p        ",
      "                ",
      "                ",
      "                "
    ],
    [
      "                ",
      "                ",
      "                ",
      " R          A   ",
      "                ",
      "                ",
      "                ",
      "            A   ",
      "                ",
      "                ",
      "                ",
      "                ",
      " G     G        ",
      "                ",
      "                ",
      "                "
    ],
    [
      "                ",
      "                ",
      "                ",
      "                ",
      "                ",
      "                ",
      "                ",
      "                ",
      "                ",
      "                ",
      "                ",
      "                ",
      "                ",
      "                ",
      "                ",
      "                "
    ]
  ]
}