{
  "xsize": 16,
  "zsize": 16,
  "palette": {
    "palette": [
      {
        "char": " ",
        "block": "minecraft:air"
      },
      {
        "char": "b",
        "block": "minecraft:grass_block[snowy=false]"
      },
      {
        "char": "p",
        "block": "minecraft:stone[weathering=false]"
      },
      {
        "char": "n",
        "block": "minecraft:cracked_stone_bricks"
      },
      {
        "char": "c",
        "block": "minecraft:cyan_terracotta"
      },
      {
        "char": "a",
        "block": "minecraft:deepslate[axis=y]"
      },
      {
        "char": "d",
        "block": "minecraft:cobbled_deepslate"
      },
      {
        "char": "q",
        "block": "minecraft:air"
      },
      {
        "char": "r",
        "block": "minecraft:cobblestone_stairs[facing=north,half=bottom,shape=straight,waterlogged=false,weathering=false]"
      },
      {
        "char": "j",
        "block": "minecraft:air"
      },
      {
        "char": "m",
        "block": "minecraft:basalt[axis=z]"
      },
      {
        "char": "f",
        "block": "minecraft:blackstone"
      },
      {
        "char": "u",
        "block": "minecraft:moss_block"
      },
      {
        "char": "w",
        "block": "minecraft:mossy_stone_bricks"
      },
      {
        "char": "v",
        "block": "minecraft:mossy_cobblestone"
      },
      {
        "char": "l",
        "block": "minecraft:air"
      },
      {
        "char": "i",
        "block": "minecraft:air"
      },
      {
        "char": "g",
        "block": "minecraft:air"
      },
      {
        "char": "k",
        "block": "minecraft:air"
      },
      {
        "char": "e",
        "block": "minecraft:oak_leaves[distance=7,persistent=true,waterlogged=false]"
      },
      {
        "char": "E",
        "block": "minecraft:structure_void"
      },
      {
        "char": "s",
        "block": "minecraft:structure_void"
      },
      {
        "char": "G",
        "block": "minecraft:structure_void"
      },
      {
        "char": "B",
        "block": "minecraft:structure_void"
      },
      {
        "char": "F",
        "block": "minecraft:structure_void"
      },
      {
        "char": "z",
        "block": "minecraft:structure_void"
      },
      {
        "char": "K",
        "block": "minecraft:structure_void"
      },
      {
        "char": "C",
        "block": "minecraft:spruce_leaves[distance=7,persistent=true,waterlogged=false]"
      },
      {
        "char": "t",
        "block": "minecraft:jungle_leaves[distance=7,persistent=true,waterlogged=false]"
      },
      {
        "char": "D",
        "block": "minecraft:air"
      },
      {
        "char": "y",
        "block": "minecraft:air"
      },
      {
        "char": "J",
        "block": "minecraft:fern"
      },
      {
        "char": "h",
        "block": "minecraft:air"
      },
      {
        "char": "o",
        "block": "minecraft:structure_void"
      },
      {
        "char": "I",
        "block": "minecraft:structure_void"
      },
      {
        "char": "H",
        "block": "minecraft:structure_void"
      },
      {
        "char": "A",
        "block": "minecraft:structure_void"
      },
      {
        "char": "x",
        "block": "minecraft:structure_void"
      }
    ]
  },
  "slices": [
    [
      "bpnbcaacdaacbqrb",
      "bjjbadmaaccabrqb",
      "qjjbddcaaafdbjnj",
      "jpjbcadaadccbrnq",
      "fmaddfdcdcaafaca",
      "fdmdaafaffaacfcc",
      "mfadfccddcccaaac",
      "adcmufddacdmcmaf",
      "accdcdddccmcfccc",
      "ddaafcdfaaaaacad",
      "dmdacfafddmacdca",
      "acddfdfdaadcaddc",
      "bbbbbbbbbbbbbbbb",
      "bnjrnbjpjnjjqjnj",
      "qwpbvpnwnpvnujpu",
      "bbbbbbbbbbbbbbbb"
    ],
    [
      "l ig    kk ek   ",
      "ge g   Ei eee kg",
      " e s i    ees   ",
      "eeeg     li g  i",
      " ee    Gl     i ",
      "                ",
      " i    l    B  F ",
      "   i           i",
      "    z  K lii   l",
      "     ki   l  e  ",
      " kik   ii  eeee ",
      "        k k ee  ",
      " kgslg kggggsggg",
      "kee  l     l   l",
      "  eeek Ctk  giek",
      "D g tlet  gigyJg"
    ],
    [
      "   h            ",
      "h  h       e   h",
      "   o        o   ",
      " e h        h   ",
      "       I        ",
      "                ",
      "                ",
      "                ",
      "                ",
      "                ",
      "            ee  ",
      "                ",
      "  ho h  hhhhohhh",
      "                ",
      "  ee        h   ",
      "  h       h h  h"
    ],
    [
      "                ",
      "                ",
      "   o        o   ",
      "                ",
      "                ",
      "                ",
      "                ",
      "                ",
      "                ",
      "                ",
      "                ",
      "                ",
      "   o        o   ",
      "                ",
      "                ",
      "                "
    ],
    [
      "                ",
      "                ",
      "   H        A   ",
      "                ",
      "                ",
      "                ",
      "                ",
      "                ",
      "                ",
      "                ",
      "                ",
      "                ",
      "   x        x   ",
      "                ",
      "                ",
      "                "
    ],
    [
      "                ",
      "                ",
      "                ",
      "                ",
      "                ",
      "                ",
      "                ",
      "                ",
      "                ",
      "                ",
      "                ",
      "                ",
      "                ",
      "                ",
      "                ",
      "                "
    ]
  ]
}