{
  "xsize": 16,
  "zsize": 16,
  "palette": {
    "palette": [
      {
        "char": " ",
        "block": "minecraft:air"
      },
      {
        "char": "a",
        "block": "minecraft:air"
      },
      {
        "char": "h",
        "block": "minecraft:air"
      },
      {
        "char": "e",
        "block": "minecraft:air"
      },
      {
        "char": "n",
        "block": "minecraft:air"
      },
      {
        "char": "r",
        "block": "minecraft:air"
      },
      {
        "char": "p",
        "block": "minecraft:air"
      },
      {
        "char": "x",
        "block": "minecraft:air"
      },
      {
        "char": "m",
        "block": "minecraft:air"
      },
      {
        "char": "y",
        "block": "minecraft:air"
      },
      {
        "char": "o",
        "block": "minecraft:air"
      },
      {
        "char": "A",
        "block": "minecraft:air"
      },
      {
        "char": "w",
        "block": "minecraft:air"
      },
      {
        "char": "j",
        "block": "minecraft:air"
      },
      {
        "char": "i",
        "block": "minecraft:air"
      },
      {
        "char": "f",
        "block": "minecraft:air"
      },
      {
        "char": "l",
        "block": "minecraft:air"
      },
      {
        "char": "C",
        "block": "minecraft:air"
      },
      {
        "char": "t",
        "block": "minecraft:air"
      },
      {
        "char": "B",
        "block": "minecraft:air"
      },
      {
        "char": "v",
        "block": "minecraft:air"
      },
      {
        "char": "c",
        "block": "minecraft:tall_grass[half=lower]"
      },
      {
        "char": "k",
        "block": "minecraft:air"
      },
      {
        "char": "q",
        "block": "minecraft:air"
      },
      {
        "char": "g",
        "block": "minecraft:grass"
      },
      {
        "char": "b",
        "block": "minecraft:air"
      },
      {
        "char": "H",
        "block": "minecraft:air"
      },
      {
        "char": "I",
        "block": "minecraft:air"
      },
      {
        "char": "K",
        "block": "minecraft:air"
      },
      {
        "char": "z",
        "block": "minecraft:air"
      },
      {
        "char": "L",
        "block": "minecraft:air"
      },
      {
        "char": "D",
        "block": "minecraft:air"
      },
      {
        "char": "s",
        "block": "minecraft:air"
      },
      {
        "char": "G",
        "block": "minecraft:air"
      },
      {
        "char": "E",
        "block": "minecraft:air"
      },
      {
        "char": "F",
        "block": "minecraft:air"
      },
      {
        "char": "J",
        "block": "minecraft:air"
      },
      {
        "char": "u",
        "block": "minecraft:air"
      },
      {
        "char": "d",
        "block": "minecraft:tall_grass[half=upper]"
      }
    ]
  },
  "slices": [
    [
      "aaaaaaaaaaaaaaaa",
      "ahhenrpnxeerhpma",
      "ahxnyoeenxnnhAma",
      "awhaaaaaaaaaahea",
      "arhajiffliijaeea",
      "aChajltfitfiaBea",
      "aehafiiilfjfaopa",
      "aneajfltflllaooa",
      "aematjjfilfjaoea",
      "amnafljijifiaopa",
      "aneafltfjfliaewa",
      "aepaifjijlffamea",
      "aewaaaaaaaaaahoa",
      "armewBhweeherpAa",
      "amhmeomhepryrpma",
      "aaaaaaaaaaaaaaaa"
    ],
    [
      "vcckccqcccggbbb ",
      "vk    bbc  bbbbb",
      "g c  bbb c  bkHk",
      "cb cccb cccc c g",
      "cbbc    IK  g qc",
      "cbbbzkL  Dbbc  k",
      "cbbv  s   kbbg c",
      "vb v bk qG bbcc ",
      "gs kbbb    bb  g",
      "cb gbb k  q bg c",
      "bbbc E  kF  s  c",
      "qb c   Js z k  g",
      "gb ccc g bscccc ",
      "c         bbb bg",
      "c   qg   bbbbb g",
      "kccgbcccc bbqsbg"
    ],
    [
      "udd dd ddd      ",
      "u       d   b   ",
      "  d   b  d      ",
      "d  ddd  dddd d  ",
      "d  d           d",
      "d b         d   ",
      "d  u       b   d",
      "u  u         dd ",
      "     b          ",
      "d              d",
      " b d           d",
      "   d            ",
      "   ddd     dddd ",
      "d               ",
      "d         bb    ",
      " dd  dddd       "
    ],
    [
      "                ",
      "                ",
      "                ",
      "                ",
      "                ",
      "                ",
      "                ",
      "                ",
      "                ",
      "                ",
      "                ",
      "                ",
      "                ",
      "                ",
      "                ",
      "                "
    ],
    [
      "                ",
      "                ",
      "                ",
      "                ",
      "                ",
      "                ",
      "                ",
      "                ",
      "                ",
      "                ",
      "                ",
      "                ",
      "                ",
      "                ",
      "                ",
      "                "
    ],
    [
      "                ",
      "                ",
      "                ",
      "                ",
      "                ",
      "                ",
      "                ",
      "                ",
      "                ",
      "                ",
      "                ",
      "                ",
      "                ",
      "                ",
      "                ",
      "                "
    ]
  ]
}