{
  "xsize": 16,
  "zsize": 16,
  "palette": {
    "palette": [
      {
        "char": " ",
        "block": "minecraft:air"
      },
      {
        "char": "b",
        "block": "minecraft:grass_block[snowy=false]"
      },
      {
        "char": "i",
        "block": "minecraft:air"
      },
      {
        "char": "l",
        "block": "minecraft:cracked_stone_bricks"
      },
      {
        "char": "d",
        "block": "minecraft:cyan_terracotta"
      },
      {
        "char": "c",
        "block": "minecraft:deepslate[axis=y]"
      },
      {
        "char": "f",
        "block": "minecraft:cobbled_deepslate"
      },
      {
        "char": "m",
        "block": "minecraft:air"
      },
      {
        "char": "x",
        "block": "minecraft:cobblestone_stairs[facing=north,half=bottom,shape=straight,waterlogged=false,weathering=true]"
      },
      {
        "char": "r",
        "block": "minecraft:stone[weathering=false]"
      },
      {
        "char": "k",
        "block": "minecraft:basalt[axis=z]"
      },
      {
        "char": "h",
        "block": "minecraft:blackstone"
      },
      {
        "char": "t",
        "block": "minecraft:stone[weathering=true]"
      },
      {
        "char": "I",
        "block": "minecraft:mossy_cobblestone_stairs[facing=north,half=bottom,shape=straight,waterlogged=false]"
      },
      {
        "char": "G",
        "block": "minecraft:deepslate[axis=z]"
      },
      {
        "char": "F",
        "block": "minecraft:cobblestone_stairs[facing=north,half=bottom,shape=straight,waterlogged=false,weathering=false]"
      },
      {
        "char": "C",
        "block": "minecraft:mossy_stone_bricks"
      },
      {
        "char": "A",
        "block": "minecraft:mossy_cobblestone"
      },
      {
        "char": "w",
        "block": "minecraft:moss_block"
      },
      {
        "char": "e",
        "block": "minecraft:air"
      },
      {
        "char": "a",
        "block": "minecraft:oak_leaves[distance=7,persistent=true,waterlogged=false]"
      },
      {
        "char": "j",
        "block": "minecraft:structure_void"
      },
      {
        "char": "o",
        "block": "minecraft:air"
      },
      {
        "char": "s",
        "block": "minecraft:air"
      },
      {
        "char": "B",
        "block": "minecraft:air"
      },
      {
        "char": "n",
        "block": "minecraft:air"
      },
      {
        "char": "p",
        "block": "minecraft:air"
      },
      {
        "char": "q",
        "block": "minecraft:structure_void"
      },
      {
        "char": "v",
        "block": "minecraft:air"
      },
      {
        "char": "y",
        "block": "minecraft:air"
      },
      {
        "char": "K",
        "block": "minecraft:air"
      },
      {
        "char": "H",
        "block": "minecraft:spruce_leaves[distance=7,persistent=true,waterlogged=false]"
      },
      {
        "char": "u",
        "block": "minecraft:jungle_leaves[distance=7,persistent=true,waterlogged=false]"
      },
      {
        "char": "g",
        "block": "minecraft:air"
      },
      {
        "char": "z",
        "block": "minecraft:structure_void"
      },
      {
        "char": "J",
        "block": "minecraft:structure_void"
      },
      {
        "char": "E",
        "block": "minecraft:structure_void"
      },
      {
        "char": "D",
        "block": "minecraft:structure_void"
      }
    ]
  },
  "slices": [
    [
      "bilbdccdfccdbmxb",
      "birbcfkccddcbxmb",
      "miibffdccchfbili",
      "itibdcbccfddbIlm",
      "hkcffbfdfdcchcdc",
      "hfkfcchchhccdbdd",
      "khcfhGdffdddcccd",
      "cfdkdhffcdfkdkch",
      "cddfdfffddkdhddd",
      "ffcchdfbcccccdcf",
      "fkfcdhchffkcdfdc",
      "cdffhfhfccfdcffd",
      "bbbbbbbbbbbbbbbb",
      "bliFlbitiliimrli",
      "mCrbArlCltAlwiiw",
      "bbbbbbbbbbbbbbbb"
    ],
    [
      "eaee        eaae",
      "aaae        eaae",
      "aaaj       ojaa ",
      " aae  s     eae ",
      "B  nps          ",
      "  qnp   o    s  ",
      "            a   ",
      "          aaaa  ",
      "         aaaaaa ",
      "     v e aaaaa  ",
      "  qnp   aaaaaa B",
      "   np    v a    ",
      "eeejoeeeee ejeee",
      "eeaa eaaa y     ",
      "K aaa aHaa  y ao",
      "eeeeu aueeeeeeee"
    ],
    [
      "g gg        g  g",
      "   g        ga g",
      " aaj        ja  ",
      "   g        g g ",
      "                ",
      "  q             ",
      "                ",
      "            a   ",
      "          aaa   ",
      "       g  aaa   ",
      "  q        a    ",
      "                ",
      "gggj ggggg gjggg",
      "gg   g          ",
      "       aa       ",
      "gggg    gggggggg"
    ],
    [
      "                ",
      "                ",
      "   j        j   ",
      "                ",
      "                ",
      "  z             ",
      "                ",
      "                ",
      "                ",
      "           a    ",
      "  z             ",
      "                ",
      "   j        j   ",
      "                ",
      "                ",
      "                "
    ],
    [
      "                ",
      "                ",
      "   J        E   ",
      "                ",
      "                ",
      "                ",
      "                ",
      "                ",
      "                ",
      "                ",
      "                ",
      "                ",
      "   D        D   ",
      "                ",
      "                ",
      "                "
    ],
    [
      "                ",
      "                ",
      "                ",
      "                ",
      "                ",
      "                ",
      "                ",
      "                ",
      "                ",
      "                ",
      "                ",
      "                ",
      "                ",
      "                ",
      "                ",
      "                "
    ]
  ]
}