{
  "xsize": 16,
  "zsize": 16,
  "palette": {
    "palette": [
      {
        "char": " ",
        "block": "minecraft:air"
      },
      {
        "char": "a",
        "block": "minecraft:grass_block[snowy=false]"
      },
      {
        "char": "i",
        "block": "minecraft:air"
      },
      {
        "char": "k",
        "block": "minecraft:cracked_stone_bricks"
      },
      {
        "char": "r",
        "block": "minecraft:moss_block"
      },
      {
        "char": "u",
        "block": "minecraft:air"
      },
      {
        "char": "l",
        "block": "minecraft:stone[weathering=false]"
      },
      {
        "char": "z",
        "block": "minecraft:mossy_stone_bricks"
      },
      {
        "char": "v",
        "block": "minecraft:air"
      },
      {
        "char": "F",
        "block": "minecraft:cobblestone_stairs[facing=south,half=bottom,shape=straight,waterlogged=false,weathering=true]"
      },
      {
        "char": "w",
        "block": "minecraft:cobblestone_stairs[facing=south,half=bottom,shape=straight,waterlogged=false,weathering=false]"
      },
      {
        "char": "e",
        "block": "minecraft:blackstone"
      },
      {
        "char": "f",
        "block": "minecraft:deepslate[axis=y]"
      },
      {
        "char": "c",
        "block": "minecraft:cobbled_deepslate"
      },
      {
        "char": "d",
        "block": "minecraft:cyan_terracotta"
      },
      {
        "char": "j",
        "block": "minecraft:basalt[axis=x]"
      },
      {
        "char": "s",
        "block": "minecraft:mossy_cobblestone_stairs[facing=south,half=bottom,shape=straight,waterlogged=false]"
      },
      {
        "char": "g",
        "block": "minecraft:air"
      },
      {
        "char": "q",
        "block": "minecraft:air"
      },
      {
        "char": "o",
        "block": "minecraft:air"
      },
      {
        "char": "b",
        "block": "minecraft:oak_leaves[distance=7,persistent=true,waterlogged=false]"
      },
      {
        "char": "t",
        "block": "minecraft:structure_void"
      },
      {
        "char": "x",
        "block": "minecraft:air"
      },
      {
        "char": "H",
        "block": "minecraft:spruce_leaves[distance=7,persistent=true,waterlogged=false]"
      },
      {
        "char": "n",
        "block": "minecraft:large_fern[half=lower]"
      },
      {
        "char": "C",
        "block": "minecraft:structure_void"
      },
      {
        "char": "E",
        "block": "minecraft:structure_void"
      },
      {
        "char": "I",
        "block": "minecraft:structure_void"
      },
      {
        "char": "D",
        "block": "minecraft:structure_void"
      },
      {
        "char": "G",
        "block": "minecraft:structure_void"
      },
      {
        "char": "J",
        "block": "minecraft:structure_void"
      },
      {
        "char": "A",
        "block": "minecraft:air"
      },
      {
        "char": "h",
        "block": "minecraft:air"
      },
      {
        "char": "p",
        "block": "minecraft:structure_void"
      },
      {
        "char": "m",
        "block": "minecraft:large_fern[half=upper]"
      },
      {
        "char": "y",
        "block": "minecraft:structure_void"
      },
      {
        "char": "B",
        "block": "minecraft:structure_void"
      }
    ]
  },
  "slices": [
    [
      "aaaaaaaaaaaaaaaa",
      "ikkkirullzilikll",
      "uiilkkikvFkirauw",
      "aaaaefecddecaaaa",
      "dedfecfefcjcjcff",
      "fdfddjfjdfejdfdj",
      "jfccjeeeedcjdffc",
      "fjccffeecddccfde",
      "rfedcccdfjdcdcjf",
      "eedcccjccdcfdfed",
      "decdecffdjfejede",
      "efccdcrdeccdcrjd",
      "aaaaeedeffeeaaaa",
      "llklvilazswviiii",
      "lilikrskiiiskiks",
      "aaaaaaaaaaaaaaaa"
    ],
    [
      "ggggqgggg  gg og",
      "  bt    xb t   b",
      "   b  b bbb  g H",
      "gqgg    bb  ggnn",
      "   bb      x  o ",
      " obbbb C  Eo    ",
      "   bb       o   ",
      "   b            ",
      "      q         ",
      "  oI oD   G  J  ",
      "    q o   q o   ",
      "    b       bb  ",
      "nqgbbb     bbb A",
      "   qb  g    bbbb",
      "   t b n   t bb ",
      "ngggnngnggngnggA"
    ],
    [
      "hhhh hhhh  hh  h",
      "   p       p    ",
      "        bb   h  ",
      "h hh        hhmm",
      "                ",
      "   bb           ",
      "                ",
      "                ",
      "                ",
      "                ",
      "                ",
      "                ",
      "m h b       b   ",
      "       h     b  ",
      "   p   m   p    ",
      "mhhhmmhmhhmhmhh "
    ],
    [
      "                ",
      "   p       p    ",
      "                ",
      "                ",
      "                ",
      "                ",
      "                ",
      "                ",
      "                ",
      "                ",
      "                ",
      "                ",
      "                ",
      "                ",
      "   p       p    ",
      "                "
    ],
    [
      "                ",
      "   y       y    ",
      "                ",
      "                ",
      "                ",
      "                ",
      "                ",
      "                ",
      "                ",
      "                ",
      "                ",
      "                ",
      "                ",
      "                ",
      "   B       B    ",
      "                "
    ],
    [
      "                ",
      "                ",
      "                ",
      "                ",
      "                ",
      "                ",
      "                ",
      "                ",
      "                ",
      "                ",
      "                ",
      "                ",
      "                ",
      "                ",
      "                ",
      "                "
    ]
  ]
}