{
  "xsize": 16,
  "zsize": 16,
  "palette": {
    "palette": [
      {
        "char": " ",
        "block": "minecraft:air"
      },
      {
        "char": "a",
        "block": "minecraft:air"
      },
      {
        "char": "g",
        "block": "minecraft:air"
      },
      {
        "char": "e",
        "block": "minecraft:air"
      },
      {
        "char": "o",
        "block": "minecraft:air"
      },
      {
        "char": "q",
        "block": "minecraft:air"
      },
      {
        "char": "y",
        "block": "minecraft:air"
      },
      {
        "char": "j",
        "block": "minecraft:air"
      },
      {
        "char": "H",
        "block": "minecraft:air"
      },
      {
        "char": "p",
        "block": "minecraft:air"
      },
      {
        "char": "x",
        "block": "minecraft:air"
      },
      {
        "char": "u",
        "block": "minecraft:air"
      },
      {
        "char": "i",
        "block": "minecraft:air"
      },
      {
        "char": "h",
        "block": "minecraft:air"
      },
      {
        "char": "f",
        "block": "minecraft:air"
      },
      {
        "char": "k",
        "block": "minecraft:air"
      },
      {
        "char": "t",
        "block": "minecraft:air"
      },
      {
        "char": "A",
        "block": "minecraft:air"
      },
      {
        "char": "w",
        "block": "minecraft:air"
      },
      {
        "char": "M",
        "block": "minecraft:air"
      },
      {
        "char": "n",
        "block": "minecraft:grass"
      },
      {
        "char": "c",
        "block": "minecraft:tall_grass[half=lower]"
      },
      {
        "char": "b",
        "block": "minecraft:air"
      },
      {
        "char": "s",
        "block": "minecraft:air"
      },
      {
        "char": "r",
        "block": "minecraft:air"
      },
      {
        "char": "J",
        "block": "minecraft:air"
      },
      {
        "char": "m",
        "block": "minecraft:air"
      },
      {
        "char": "O",
        "block": "minecraft:air"
      },
      {
        "char": "z",
        "block": "minecraft:air"
      },
      {
        "char": "K",
        "block": "minecraft:air"
      },
      {
        "char": "C",
        "block": "minecraft:air"
      },
      {
        "char": "N",
        "block": "minecraft:air"
      },
      {
        "char": "G",
        "block": "minecraft:air"
      },
      {
        "char": "D",
        "block": "minecraft:air"
      },
      {
        "char": "I",
        "block": "minecraft:air"
      },
      {
        "char": "v",
        "block": "minecraft:air"
      },
      {
        "char": "L",
        "block": "minecraft:air"
      },
      {
        "char": "F",
        "block": "minecraft:air"
      },
      {
        "char": "E",
        "block": "minecraft:air"
      },
      {
        "char": "B",
        "block": "minecraft:air"
      },
      {
        "char": "d",
        "block": "minecraft:tall_grass[half=upper]"
      },
      {
        "char": "l",
        "block": "minecraft:air"
      }
    ]
  },
  "slices": [
    [
      "aaaaaaaaaaaaaaaa",
      "aggeoeqoyeejgqja",
      "agyoHpeeoyoogxja",
      "augaaaaaaaaaagea",
      "ajgaihffkhhiajea",
      "axgaiktfhtfhaAea",
      "aegafhhhkfifapqa",
      "aoeaifktfkkkappa",
      "aejatiifhkfiapea",
      "ajoafkihihfhapqa",
      "aoeafktfifkhaeua",
      "aeqahfihikffaeea",
      "ajuaaaaaaaaaagpa",
      "ajjeuAguwwgewqMa",
      "ajgeepegeqwxjqja",
      "aaaaaaaaaaaaaaaa"
    ],
    [
      " n cbbbbnb ccccc",
      "ccbbbbbbbbbbcbbb",
      "sbbbbcbbbcbbcrJc",
      "cbbbcmccccmccc c",
      "cbccs       r sc",
      "c cm  O bb  c   ",
      "c m    bbbb sc m",
      "c  z   Kbb rC c ",
      " N     GDIs cc m",
      "cz n    r v  c c",
      "bbLn F  E   cC m",
      "mbb  v    r    c",
      "bbbcc cn c scnnc",
      "cbbbv c   Bbb bn",
      "m bbbB c bbbbb  ",
      "cccbbbvcmcnrcmb "
    ],
    [
      "   d b     ddddd",
      "dd   bbb  b d b ",
      "  bb d bbd  d  d",
      "db  dlddddlddd d",
      "d dd           d",
      "d dl        d   ",
      "d l     bb   d l",
      "d             d ",
      "            dd l",
      "d            d d",
      "            d  l",
      "lb             d",
      " b dd d  d  d  d",
      "d b   d         ",
      "l  b   d   b    ",
      "ddd    dld  dl  "
    ],
    [
      "                ",
      "                ",
      "                ",
      "                ",
      "                ",
      "                ",
      "                ",
      "                ",
      "                ",
      "                ",
      "                ",
      "                ",
      "                ",
      "                ",
      "                ",
      "                "
    ],
    [
      "                ",
      "                ",
      "                ",
      "                ",
      "                ",
      "                ",
      "                ",
      "                ",
      "                ",
      "                ",
      "                ",
      "                ",
      "                ",
      "                ",
      "                ",
      "                "
    ],
    [
      "                ",
      "                ",
      "                ",
      "                ",
      "                ",
      "                ",
      "                ",
      "                ",
      "                ",
      "                ",
      "                ",
      "                ",
      "                ",
      "                ",
      "                ",
      "                "
    ]
  ]
}