{
  "xsize": 16,
  "zsize": 16,
  "palette": {
    "palette": [
      {
        "char": " ",
        "block": "minecraft:air"
      },
      {
        "char": "e",
        "block": "minecraft:grass_block[snowy=false]"
      },
      {
        "char": "n",
        "block": "minecraft:cracked_stone_bricks"
      },
      {
        "char": "l",
        "block": "minecraft:air"
      },
      {
        "char": "f",
        "block": "minecraft:blackstone"
      },
      {
        "char": "b",
        "block": "minecraft:deepslate[axis=y]"
      },
      {
        "char": "c",
        "block": "minecraft:cobbled_deepslate"
      },
      {
        "char": "i",
        "block": "minecraft:basalt[axis=x]"
      },
      {
        "char": "a",
        "block": "minecraft:cyan_terracotta"
      },
      {
        "char": "I",
        "block": "minecraft:mossy_cobblestone"
      },
      {
        "char": "x",
        "block": "minecraft:air"
      },
      {
        "char": "t",
        "block": "minecraft:mossy_stone_bricks"
      },
      {
        "char": "k",
        "block": "minecraft:moss_block"
      },
      {
        "char": "z",
        "block": "minecraft:stone[weathering=false]"
      },
      {
        "char": "q",
        "block": "minecraft:stone[weathering=true]"
      },
      {
        "char": "D",
        "block": "minecraft:cobblestone_stairs[facing=north,half=bottom,shape=straight,waterlogged=false,weathering=false]"
      },
      {
        "char": "g",
        "block": "minecraft:air"
      },
      {
        "char": "d",
        "block": "minecraft:oak_leaves[distance=7,persistent=true,waterlogged=false]"
      },
      {
        "char": "y",
        "block": "minecraft:air"
      },
      {
        "char": "j",
        "block": "minecraft:air"
      },
      {
        "char": "o",
        "block": "minecraft:air"
      },
      {
        "char": "w",
        "block": "minecraft:air"
      },
      {
        "char": "v",
        "block": "minecraft:air"
      },
      {
        "char": "s",
        "block": "minecraft:air"
      },
      {
        "char": "r",
        "block": "minecraft:air"
      },
      {
        "char": "H",
        "block": "minecraft:air"
      },
      {
        "char": "u",
        "block": "minecraft:air"
      },
      {
        "char": "G",
        "block": "minecraft:air"
      },
      {
        "char": "C",
        "block": "minecraft:air"
      },
      {
        "char": "F",
        "block": "minecraft:structure_void"
      },
      {
        "char": "J",
        "block": "minecraft:structure_void"
      },
      {
        "char": "A",
        "block": "minecraft:air"
      },
      {
        "char": "E",
        "block": "minecraft:air"
      },
      {
        "char": "p",
        "block": "minecraft:large_fern[half=lower]"
      },
      {
        "char": "B",
        "block": "minecraft:air"
      },
      {
        "char": "h",
        "block": "minecraft:air"
      },
      {
        "char": "m",
        "block": "minecraft:large_fern[half=upper]"
      }
    ]
  },
  "slices": [
    [
      "enlefbfciacieIne",
      "xntekacccbbfexln",
      "zqlebifcabaaeqtz",
      "eeeecbbaabafeeee",
      "aaiabafacacfffcb",
      "aaafffbfffcffbfb",
      "aaccfbibfiibaabb",
      "caccibacbbfibcca",
      "ccbccffcaabbbaaf",
      "kiabcbbkcfibbiib",
      "caabccfbacbkbaac",
      "caaacbaacbaibccf",
      "eeeebcabcabaeeee",
      "ellefackbibbenqk",
      "ttkebiiacfccelqq",
      "eDqeacaaccbfetne"
    ],
    [
      "gddg      yjg dd",
      "dddgg y     dddd",
      "dd g j o j  gddd",
      "ggwg   jj   gvdg",
      "s   r     s s   ",
      "    r        H s",
      "  ur    o     o ",
      " G CoF  J       ",
      "   rAu       A  ",
      "gw  r  g u      ",
      "           g   v",
      "     jjjjjjE   u",
      "ggggo       pvpp",
      "oddg   g    gpdp",
      "ddgg w      Bddd",
      "gd g s   B  gddp"
    ],
    [
      "h  h        h   ",
      " d hh         d ",
      "   h        h d ",
      "hh h        h  h",
      "                ",
      "                ",
      "                ",
      "                ",
      "                ",
      "h      h        ",
      "           h    ",
      "                ",
      "hhhh        m mm",
      "   h   h    hm m",
      " dhh          dd",
      "h  h        h  m"
    ],
    [
      "                ",
      "                ",
      "                ",
      "                ",
      "                ",
      "                ",
      "                ",
      "                ",
      "                ",
      "                ",
      "                ",
      "                ",
      "                ",
      "                ",
      "                ",
      "                "
    ],
    [
      "                ",
      "                ",
      "                ",
      "                ",
      "                ",
      "                ",
      "                ",
      "                ",
      "                ",
      "                ",
      "                ",
      "                ",
      "                ",
      "                ",
      "                ",
      "                "
    ],
    [
      "                ",
      "                ",
      "                ",
      "                ",
      "                ",
      "                ",
      "                ",
      "                ",
      "                ",
      "                ",
      "                ",
      "                ",
      "                ",
      "                ",
      "                ",
      "                "
    ]
  ]
}