{
  "xsize": 16,
  "zsize": 16,
  "palette": {
    "palette": [
      {
        "char": " ",
        "block": "minecraft:air"
      },
      {
        "char": "a",
        "block": "minecraft:grass_block[snowy=false]"
      },
      {
        "char": "h",
        "block": "minecraft:cracked_stone_bricks"
      },
      {
        "char": "e",
        "block": "minecraft:air"
      },
      {
        "char": "n",
        "block": "minecraft:air"
      },
      {
        "char": "r",
        "block": "minecraft:stone[weathering=true]"
      },
      {
        "char": "p",
        "block": "minecraft:air"
      },
      {
        "char": "x",
        "block": "minecraft:air"
      },
      {
        "char": "m",
        "block": "minecraft:stone[weathering=false]"
      },
      {
        "char": "y",
        "block": "minecraft:cobblestone_stairs[facing=south,half=bottom,shape=straight,waterlogged=false,weathering=true]"
      },
      {
        "char": "o",
        "block": "minecraft:moss_block"
      },
      {
        "char": "A",
        "block": "minecraft:mossy_cobblestone_stairs[facing=south,half=bottom,shape=straight,waterlogged=false]"
      },
      {
        "char": "w",
        "block": "minecraft:mossy_stone_bricks"
      },
      {
        "char": "j",
        "block": "minecraft:blackstone"
      },
      {
        "char": "i",
        "block": "minecraft:deepslate[axis=y]"
      },
      {
        "char": "f",
        "block": "minecraft:cobbled_deepslate"
      },
      {
        "char": "l",
        "block": "minecraft:cyan_terracotta"
      },
      {
        "char": "C",
        "block": "minecraft:cobblestone_stairs[facing=south,half=bottom,shape=straight,waterlogged=false,weathering=false]"
      },
      {
        "char": "t",
        "block": "minecraft:basalt[axis=x]"
      },
      {
        "char": "B",
        "block": "minecraft:mossy_cobblestone"
      },
      {
        "char": "v",
        "block": "minecraft:large_fern[half=lower]"
      },
      {
        "char": "c",
        "block": "minecraft:air"
      },
      {
        "char": "k",
        "block": "minecraft:air"
      },
      {
        "char": "q",
        "block": "minecraft:air"
      },
      {
        "char": "g",
        "block": "minecraft:air"
      },
      {
        "char": "b",
        "block": "minecraft:oak_leaves[distance=7,persistent=true,waterlogged=false]"
      },
      {
        "char": "H",
        "block": "minecraft:spruce_leaves[distance=7,persistent=true,waterlogged=false]"
      },
      {
        "char": "I",
        "block": "minecraft:air"
      },
      {
        "char": "K",
        "block": "minecraft:air"
      },
      {
        "char": "z",
        "block": "minecraft:air"
      },
      {
        "char": "L",
        "block": "minecraft:air"
      },
      {
        "char": "D",
        "block": "minecraft:air"
      },
      {
        "char": "s",
        "block": "minecraft:air"
      },
      {
        "char": "G",
        "block": "minecraft:structure_void"
      },
      {
        "char": "E",
        "block": "minecraft:air"
      },
      {
        "char": "F",
        "block": "minecraft:structure_void"
      },
      {
        "char": "J",
        "block": "minecraft:air"
      },
      {
        "char": "u",
        "block": "minecraft:large_fern[half=upper]"
      },
      {
        "char": "d",
        "block": "minecraft:air"
      }
    ]
  },
  "slices": [
    [
      "aaaaaaaaaaaaaaaa",
      "ahhenrpnxeerhpma",
      "ahxnyoeenxnnhAma",
      "awhaaaaaaaaaahea",
      "arhajiffliijaeea",
      "aChajltfitfiaBea",
      "aehafiiilfjfaopa",
      "aneajfltflllaooa",
      "aematjjfilfjaoea",
      "amnafljijifiaopa",
      "aneafltfjfliaewa",
      "aepaifjijlffamea",
      "aewaaaaaaaaaahoa",
      "armewBhweeherpAa",
      "amhmeomhepryrpma",
      "aaaaaaaaaaaaaaaa"
    ],
    [
      "vcckccqcccggbbb ",
      "vk    bbc  bbbbb",
      "g c  bbb c  bkHk",
      "cb cccb cccc c g",
      "cbbc    IK  g qc",
      "cbbbzkL  Dbbc  k",
      "cbbv  s   kbbg c",
      "vb v bk qG bbcc ",
      "gs kbbb    bb  g",
      "cb gbb k  q bg c",
      "bbbc E  kF  s  c",
      "qb c   Js z k  g",
      "gb ccc g bscccc ",
      "c         bbb bg",
      "c   qg   bbbbb g",
      "kccgbcccc bbqsbg"
    ],
    [
      "udd dd ddd      ",
      "u       d   b   ",
      "  d   b  d      ",
      "d  ddd  dddd d  ",
      "d  d           d",
      "d b         d   ",
      "d  u       b   d",
      "u  u         dd ",
      "     b          ",
      "d              d",
      " b d           d",
      "   d            ",
      "   ddd     dddd ",
      "d               ",
      "d         bb    ",
      " dd  dddd       "
    ],
    [
      "                ",
      "                ",
      "                ",
      "                ",
      "                ",
      "                ",
      "                ",
      "                ",
      "                ",
      "                ",
      "                ",
      "                ",
      "                ",
      "                ",
      "                ",
      "                "
    ],
    [
      "                ",
      "                ",
      "                ",
      "                ",
      "                ",
      "                ",
      "                ",
      "                ",
      "                ",
      "                ",
      "                ",
      "                ",
      "                ",
      "                ",
      "                ",
      "                "
    ],
    [
      "                ",
      "                ",
      "                ",
      "                ",
      "                ",
      "                ",
      "                ",
      "                ",
      "                ",
      "                ",
      "                ",
      "                ",
      "                ",
      "                ",
      "                ",
      "                "
    ]
  ]
}