{
  "xsize": 16,
  "zsize": 16,
  "palette": {
    "palette": [
      {
        "char": " ",
        "block": "minecraft:air"
      },
      {
        "char": "a",
        "block": "minecraft:grass_block[snowy=false]"
      },
      {
        "char": "i",
        "block": "minecraft:air"
      },
      {
        "char": "l",
        "block": "minecraft:cracked_stone_bricks"
      },
      {
        "char": "p",
        "block": "minecraft:moss_block"
      },
      {
        "char": "u",
        "block": "minecraft:air"
      },
      {
        "char": "k",
        "block": "minecraft:stone[weathering=false]"
      },
      {
        "char": "y",
        "block": "minecraft:mossy_stone_bricks"
      },
      {
        "char": "G",
        "block": "minecraft:stone[weathering=true]"
      },
      {
        "char": "v",
        "block": "minecraft:air"
      },
      {
        "char": "B",
        "block": "minecraft:cobblestone_stairs[facing=south,half=bottom,shape=straight,waterlogged=false,weathering=true]"
      },
      {
        "char": "s",
        "block": "minecraft:cobblestone_stairs[facing=south,half=bottom,shape=straight,waterlogged=false,weathering=false]"
      },
      {
        "char": "g",
        "block": "minecraft:deepslate[axis=y]"
      },
      {
        "char": "e",
        "block": "minecraft:cobbled_deepslate"
      },
      {
        "char": "f",
        "block": "minecraft:cyan_terracotta"
      },
      {
        "char": "h",
        "block": "minecraft:blackstone"
      },
      {
        "char": "j",
        "block": "minecraft:basalt[axis=x]"
      },
      {
        "char": "w",
        "block": "minecraft:mossy_cobblestone_stairs[facing=south,half=bottom,shape=straight,waterlogged=false]"
      },
      {
        "char": "m",
        "block": "minecraft:air"
      },
      {
        "char": "c",
        "block": "minecraft:air"
      },
      {
        "char": "n",
        "block": "minecraft:air"
      },
      {
        "char": "r",
        "block": "minecraft:large_fern[half=lower]"
      },
      {
        "char": "b",
        "block": "minecraft:oak_leaves[distance=7,persistent=true,waterlogged=false]"
      },
      {
        "char": "t",
        "block": "minecraft:structure_void"
      },
      {
        "char": "D",
        "block": "minecraft:spruce_leaves[distance=7,persistent=true,waterlogged=false]"
      },
      {
        "char": "C",
        "block": "minecraft:air"
      },
      {
        "char": "E",
        "block": "minecraft:structure_void"
      },
      {
        "char": "H",
        "block": "minecraft:structure_void"
      },
      {
        "char": "A",
        "block": "minecraft:air"
      },
      {
        "char": "F",
        "block": "minecraft:air"
      },
      {
        "char": "d",
        "block": "minecraft:air"
      },
      {
        "char": "q",
        "block": "minecraft:large_fern[half=upper]"
      },
      {
        "char": "o",
        "block": "minecraft:structure_void"
      },
      {
        "char": "x",
        "block": "minecraft:structure_void"
      },
      {
        "char": "z",
        "block": "minecraft:structure_void"
      }
    ]
  },
  "slices": [
    [
      "aaaaaaaaaaaaaaaa",
      "illlipukkyiGilkk",
      "ukikllilvBlipaus",
      "aaaageegffeeaaaa",
      "fhfgheghgejejegg",
      "gfgfgfjhgeeefgfj",
      "jgeehfjfjehgfgge",
      "gjeegghheffeegfh",
      "pgafeeefgjfefejg",
      "hefaggfgfgfefghf",
      "fheffhhejehejhfh",
      "hgeefepfheefepjf",
      "aaaaghfhejhjaaaa",
      "kklkvkkaywsvkiki",
      "kiiilpwliiislkls",
      "aaaaaaaaaaaaaaaa"
    ],
    [
      "mc mcmcnrmccccc ",
      " cbt c     t rmb",
      "   bn b   b cc D",
      "crccm       rccr",
      "m     n   m     ",
      "  C bbb       b ",
      " n bbb       bbb",
      "n  bb   E  Hmbbb",
      "  Ab   n      b ",
      "  bbb           ",
      "bbbbb   bb   n  ",
      "  bb  c bbb  c  ",
      "ncmcn   bbb c cc",
      "  c    c b      ",
      "n  tcbmcF  tc c ",
      "cc c  c cccccc c"
    ],
    [
      " d  d d q ddddd ",
      " d o d     o q  ",
      "            dd  ",
      "dqdd        qddq",
      "                ",
      "                ",
      "    b         b ",
      "              b ",
      "                ",
      "   b            ",
      "  bb            ",
      "      d  b   d  ",
      " d d     b  d dd",
      "  d    d        ",
      "   od  d   od d ",
      "dd d  d dddddd d"
    ],
    [
      "                ",
      "   o       o    ",
      "                ",
      "                ",
      "                ",
      "                ",
      "                ",
      "                ",
      "                ",
      "                ",
      "                ",
      "                ",
      "                ",
      "                ",
      "   o       o    ",
      "                "
    ],
    [
      "                ",
      "   x       x    ",
      "                ",
      "                ",
      "                ",
      "                ",
      "                ",
      "                ",
      "                ",
      "                ",
      "                ",
      "                ",
      "                ",
      "                ",
      "   z       z    ",
      "                "
    ],
    [
      "                ",
      "                ",
      "                ",
      "                ",
      "                ",
      "                ",
      "                ",
      "                ",
      "                ",
      "                ",
      "                ",
      "                ",
      "                ",
      "                ",
      "                ",
      "                "
    ]
  ]
}