{
  "xsize": 16,
  "zsize": 16,
  "palette": {
    "palette": [
      {
        "char": " ",
        "block": "minecraft:air"
      },
      {
        "char": "a",
        "block": "minecraft:air"
      },
      {
        "char": "g",
        "block": "minecraft:air"
      },
      {
        "char": "k",
        "block": "minecraft:air"
      },
      {
        "char": "t",
        "block": "minecraft:air"
      },
      {
        "char": "y",
        "block": "minecraft:air"
      },
      {
        "char": "u",
        "block": "minecraft:air"
      },
      {
        "char": "H",
        "block": "minecraft:air"
      },
      {
        "char": "r",
        "block": "minecraft:air"
      },
      {
        "char": "z",
        "block": "minecraft:air"
      },
      {
        "char": "v",
        "block": "minecraft:air"
      },
      {
        "char": "o",
        "block": "minecraft:air"
      },
      {
        "char": "m",
        "block": "minecraft:air"
      },
      {
        "char": "n",
        "block": "minecraft:air"
      },
      {
        "char": "j",
        "block": "minecraft:air"
      },
      {
        "char": "e",
        "block": "minecraft:air"
      },
      {
        "char": "i",
        "block": "minecraft:air"
      },
      {
        "char": "f",
        "block": "minecraft:air"
      },
      {
        "char": "d",
        "block": "minecraft:air"
      },
      {
        "char": "q",
        "block": "minecraft:air"
      },
      {
        "char": "E",
        "block": "minecraft:air"
      },
      {
        "char": "M",
        "block": "minecraft:air"
      },
      {
        "char": "b",
        "block": "minecraft:tall_grass[half=lower]"
      },
      {
        "char": "l",
        "block": "minecraft:air"
      },
      {
        "char": "x",
        "block": "minecraft:air"
      },
      {
        "char": "p",
        "block": "minecraft:air"
      },
      {
        "char": "h",
        "block": "minecraft:air"
      },
      {
        "char": "A",
        "block": "minecraft:air"
      },
      {
        "char": "w",
        "block": "minecraft:air"
      },
      {
        "char": "N",
        "block": "minecraft:air"
      },
      {
        "char": "F",
        "block": "minecraft:air"
      },
      {
        "char": "C",
        "block": "minecraft:air"
      },
      {
        "char": "I",
        "block": "minecraft:air"
      },
      {
        "char": "L",
        "block": "minecraft:air"
      },
      {
        "char": "Q",
        "block": "minecraft:air"
      },
      {
        "char": "K",
        "block": "minecraft:air"
      },
      {
        "char": "P",
        "block": "minecraft:air"
      },
      {
        "char": "O",
        "block": "minecraft:air"
      },
      {
        "char": "R",
        "block": "minecraft:air"
      },
      {
        "char": "B",
        "block": "minecraft:air"
      },
      {
        "char": "D",
        "block": "minecraft:air"
      },
      {
        "char": "c",
        "block": "minecraft:tall_grass[half=upper]"
      },
      {
        "char": "s",
        "block": "minecraft:air"
      },
      {
        "char": "G",
        "block": "minecraft:air"
      },
      {
        "char": "J",
        "block": "minecraft:air"
      }
    ]
  },
  "slices": [
    [
      "aaaaaaaaaaaaaaaa",
      "gkkkgtyuuHgrgkgr",
      "ygggkkgkzvkgtayv",
      "aaaaommmnjjoaaaa",
      "eiefidfifdqdqdff",
      "fefeonnojjonefeq",
      "qfddojmommomeffd",
      "fqddffiideeddfei",
      "tfqeddfefqededqf",
      "idedmmjnjmjnefie",
      "eidejononjnnqiei",
      "ifddedteiddedtqe",
      "aaaamjnmjjomaaaa",
      "rrkrzugaHvvzugrg",
      "rgggktEkgguMkrkE",
      "aaaaaaaaaaaaaaaa"
    ],
    [
      "  b bbbbb bb bbb",
      " l x     lpxpb  ",
      " hAw  wp  wlb  N",
      "b b   h     p   ",
      "l  h   h        ",
      "  F  hF   l l h ",
      "         C    l ",
      "I   L   l       ",
      " hl    Q     p  ",
      "  K  Pp  pC   p ",
      "  OA   h hR     ",
      "I  l    l h  l  ",
      "b B  hD  B  bpbb",
      " hhp B b        ",
      "D  x wp   hx  bl",
      "bbb  bbbb Abbbbb"
    ],
    [
      "  c ccccc cc ccc",
      "   s       s c  ",
      "            c   ",
      "c c             ",
      "                ",
      "                ",
      "                ",
      "                ",
      "                ",
      "                ",
      "                ",
      "                ",
      "c           c cc",
      "       c        ",
      "   s       s  c ",
      "ccc  cccc  ccccc"
    ],
    [
      "                ",
      "   s       s    ",
      "                ",
      "                ",
      "                ",
      "                ",
      "                ",
      "                ",
      "                ",
      "                ",
      "                ",
      "                ",
      "                ",
      "                ",
      "   s       s    ",
      "                "
    ],
    [
      "                ",
      "   G       G    ",
      "                ",
      "                ",
      "                ",
      "                ",
      "                ",
      "                ",
      "                ",
      "                ",
      "                ",
      "                ",
      "                ",
      "                ",
      "   J       J    ",
      "a               "
    ],
    [
      "                ",
      "                ",
      "                ",
      "                ",
      "                ",
      "                ",
      "                ",
      "                ",
      "                ",
      "                ",
      "                ",
      "                ",
      "                ",
      "                ",
      "                ",
      "                "
    ]
  ]
}