{
  "xsize": 16,
  "zsize": 16,
  "palette": {
    "palette": [
      {
        "char": " ",
        "block": "minecraft:air"
      },
      {
        "char": "a",
        "block": "minecraft:air"
      },
      {
        "char": "i",
        "block": "minecraft:air"
      },
      {
        "char": "k",
        "block": "minecraft:air"
      },
      {
        "char": "r",
        "block": "minecraft:air"
      },
      {
        "char": "u",
        "block": "minecraft:air"
      },
      {
        "char": "l",
        "block": "minecraft:air"
      },
      {
        "char": "z",
        "block": "minecraft:air"
      },
      {
        "char": "v",
        "block": "minecraft:air"
      },
      {
        "char": "F",
        "block": "minecraft:air"
      },
      {
        "char": "w",
        "block": "minecraft:air"
      },
      {
        "char": "e",
        "block": "minecraft:air"
      },
      {
        "char": "f",
        "block": "minecraft:air"
      },
      {
        "char": "c",
        "block": "minecraft:air"
      },
      {
        "char": "d",
        "block": "minecraft:air"
      },
      {
        "char": "j",
        "block": "minecraft:air"
      },
      {
        "char": "s",
        "block": "minecraft:air"
      },
      {
        "char": "g",
        "block": "minecraft:tall_grass[half=lower]"
      },
      {
        "char": "q",
        "block": "minecraft:air"
      },
      {
        "char": "o",
        "block": "minecraft:air"
      },
      {
        "char": "b",
        "block": "minecraft:air"
      },
      {
        "char": "t",
        "block": "minecraft:air"
      },
      {
        "char": "x",
        "block": "minecraft:air"
      },
      {
        "char": "H",
        "block": "minecraft:air"
      },
      {
        "char": "n",
        "block": "minecraft:air"
      },
      {
        "char": "C",
        "block": "minecraft:air"
      },
      {
        "char": "E",
        "block": "minecraft:air"
      },
      {
        "char": "I",
        "block": "minecraft:air"
      },
      {
        "char": "D",
        "block": "minecraft:air"
      },
      {
        "char": "G",
        "block": "minecraft:air"
      },
      {
        "char": "J",
        "block": "minecraft:air"
      },
      {
        "char": "A",
        "block": "minecraft:air"
      },
      {
        "char": "h",
        "block": "minecraft:tall_grass[half=upper]"
      },
      {
        "char": "p",
        "block": "minecraft:air"
      },
      {
        "char": "m",
        "block": "minecraft:air"
      },
      {
        "char": "y",
        "block": "minecraft:air"
      },
      {
        "char": "B",
        "block": "minecraft:air"
      }
    ]
  },
  "slices": [
    [
      "aaaaaaaaaaaaaaaa",
      "ikkkirullzilikll",
      "uiilkkikvFkirauw",
      "aaaaefecddecaaaa",
      "dedfecfefcjcjcff",
      "fdfddjfjdfejdfdj",
      "jfccjeeeedcjdffc",
      "fjccffeecddccfde",
      "rfedcccdfjdcdcjf",
      "eedcccjccdcfdfed",
      "decdecffdjfejede",
      "efccdcrdeccdcrjd",
      "aaaaeedeffeeaaaa",
      "llklvilazswviiii",
      "lilikrskiiiskiks",
      "aaaaaaaaaaaaaaaa"
    ],
    [
      "ggggqgggg  gg og",
      "  bt    xb t   b",
      "   b  b bbb  g H",
      "gqgg    bb  ggnn",
      "   bb      x  o ",
      " obbbb C  Eo    ",
      "   bb       o   ",
      "   b            ",
      "      q         ",
      "  oI oD   G  J  ",
      "    q o   q o   ",
      "    b       bb  ",
      "nqgbbb     bbb A",
      "   qb  g    bbbb",
      "   t b n   t bb ",
      "ngggnngnggngnggA"
    ],
    [
      "hhhh hhhh  hh  h",
      "   p       p    ",
      "        bb   h  ",
      "h hh        hhmm",
      "                ",
      "   bb           ",
      "                ",
      "                ",
      "                ",
      "                ",
      "                ",
      "                ",
      "m h b       b   ",
      "       h     b  ",
      "   p   m   p    ",
      "mhhhmmhmhhmhmhh "
    ],
    [
      "                ",
      "   p       p    ",
      "                ",
      "                ",
      "                ",
      "                ",
      "                ",
      "                ",
      "                ",
      "                ",
      "                ",
      "                ",
      "                ",
      "                ",
      "   p       p    ",
      "                "
    ],
    [
      "                ",
      "   y       y    ",
      "                ",
      "                ",
      "                ",
      "                ",
      "                ",
      "                ",
      "                ",
      "                ",
      "                ",
      "                ",
      "                ",
      "                ",
      "   B       B    ",
      "                "
    ],
    [
      "                ",
      "                ",
      "                ",
      "                ",
      "                ",
      "                ",
      "                ",
      "                ",
      "                ",
      "                ",
      "                ",
      "                ",
      "                ",
      "                ",
      "                ",
      "                "
    ]
  ]
}