{
  "xsize": 16,
  "zsize": 16,
  "palette": {
    "palette": [
      {
        "char": " ",
        "block": "minecraft:air"
      },
      {
        "char": "a",
        "block": "minecraft:air"
      },
      {
        "char": "i",
        "block": "minecraft:air"
      },
      {
        "char": "l",
        "block": "minecraft:air"
      },
      {
        "char": "p",
        "block": "minecraft:air"
      },
      {
        "char": "s",
        "block": "minecraft:air"
      },
      {
        "char": "m",
        "block": "minecraft:air"
      },
      {
        "char": "x",
        "block": "minecraft:air"
      },
      {
        "char": "t",
        "block": "minecraft:air"
      },
      {
        "char": "q",
        "block": "minecraft:air"
      },
      {
        "char": "f",
        "block": "minecraft:air"
      },
      {
        "char": "e",
        "block": "minecraft:air"
      },
      {
        "char": "d",
        "block": "minecraft:air"
      },
      {
        "char": "c",
        "block": "minecraft:air"
      },
      {
        "char": "h",
        "block": "minecraft:air"
      },
      {
        "char": "u",
        "block": "minecraft:air"
      },
      {
        "char": "H",
        "block": "minecraft:air"
      },
      {
        "char": "j",
        "block": "minecraft:tall_grass[half=lower]"
      },
      {
        "char": "n",
        "block": "minecraft:air"
      },
      {
        "char": "g",
        "block": "minecraft:air"
      },
      {
        "char": "b",
        "block": "minecraft:air"
      },
      {
        "char": "r",
        "block": "minecraft:air"
      },
      {
        "char": "C",
        "block": "minecraft:air"
      },
      {
        "char": "B",
        "block": "minecraft:air"
      },
      {
        "char": "E",
        "block": "minecraft:air"
      },
      {
        "char": "D",
        "block": "minecraft:air"
      },
      {
        "char": "G",
        "block": "minecraft:air"
      },
      {
        "char": "F",
        "block": "minecraft:air"
      },
      {
        "char": "A",
        "block": "minecraft:air"
      },
      {
        "char": "v",
        "block": "minecraft:air"
      },
      {
        "char": "I",
        "block": "minecraft:air"
      },
      {
        "char": "z",
        "block": "minecraft:grass"
      },
      {
        "char": "k",
        "block": "minecraft:tall_grass[half=upper]"
      },
      {
        "char": "o",
        "block": "minecraft:air"
      },
      {
        "char": "w",
        "block": "minecraft:air"
      },
      {
        "char": "y",
        "block": "minecraft:air"
      }
    ]
  },
  "slices": [
    [
      "aaaaaaaaaaaaaaaa",
      "illlipsmixiiilmm",
      "smimlliltqlipasq",
      "aaaafedffdchaaaa",
      "ehedhcdhdcfcfcdd",
      "dedefddcdfddedef",
      "fdccfcfhdehdeddc",
      "dfccddhhceeccdeh",
      "pdfecccedfececfd",
      "hcecfccffcceedhe",
      "ehcehefcedddfheh",
      "hdccehpehccecpfe",
      "aaaahfccccddaaaa",
      "milmtimaxqutHiii",
      "mimilpqliimulmlq",
      "aaaaaaaaaaaaaaaa"
    ],
    [
      "j nj j g     j j",
      " jbr      gr n b",
      "   bg b   b gg C",
      " gg  gn     j  j",
      "           g    ",
      " gB  E  bbb     ",
      "       bbbbb g  ",
      "        bbb     ",
      "j  gbb    b ngD ",
      "g  bbbn   g     ",
      "   bb   gg      ",
      "      gG  Fg  A ",
      "vjIz   nn     j ",
      "     n      bb  ",
      "   r b jg  rbbb ",
      " jv j jggj j bb "
    ],
    [
      "k  k k       k k",
      " k o       o    ",
      "                ",
      "            k  k",
      "                ",
      "         b      ",
      "        bbb     ",
      "                ",
      "k               ",
      "    b           ",
      "                ",
      "                ",
      " k            k ",
      "                ",
      "   o   k   o b  ",
      " k  k k  k k    "
    ],
    [
      "                ",
      "   o       o    ",
      "                ",
      "                ",
      "                ",
      "                ",
      "                ",
      "                ",
      "                ",
      "                ",
      "                ",
      "                ",
      "                ",
      "                ",
      "   o       o    ",
      "                "
    ],
    [
      "                ",
      "   w       w    ",
      "                ",
      "                ",
      "                ",
      "                ",
      "                ",
      "                ",
      "                ",
      "                ",
      "                ",
      "                ",
      "                ",
      "                ",
      "   y       y    ",
      "                "
    ],
    [
      "                ",
      "                ",
      "                ",
      "                ",
      "                ",
      "                ",
      "                ",
      "                ",
      "                ",
      "                ",
      "                ",
      "                ",
      "                ",
      "                ",
      "                ",
      "                "
    ]
  ]
}