{
  "xsize": 16,
  "zsize": 16,
  "palette": {
    "palette": [
      {
        "char": " ",
        "block": "minecraft:air"
      },
      {
        "char": "a",
        "block": "minecraft:air"
      },
      {
        "char": "j",
        "block": "minecraft:air"
      },
      {
        "char": "h",
        "block": "minecraft:air"
      },
      {
        "char": "g",
        "block": "minecraft:air"
      },
      {
        "char": "c",
        "block": "minecraft:air"
      },
      {
        "char": "k",
        "block": "minecraft:air"
      },
      {
        "char": "d",
        "block": "minecraft:air"
      },
      {
        "char": "i",
        "block": "minecraft:air"
      },
      {
        "char": "u",
        "block": "minecraft:air"
      },
      {
        "char": "r",
        "block": "minecraft:air"
      },
      {
        "char": "z",
        "block": "minecraft:air"
      },
      {
        "char": "v",
        "block": "minecraft:air"
      },
      {
        "char": "E",
        "block": "minecraft:air"
      },
      {
        "char": "w",
        "block": "minecraft:air"
      },
      {
        "char": "t",
        "block": "minecraft:air"
      },
      {
        "char": "F",
        "block": "minecraft:air"
      },
      {
        "char": "D",
        "block": "minecraft:air"
      },
      {
        "char": "e",
        "block": "minecraft:tall_grass[half=lower]"
      },
      {
        "char": "q",
        "block": "minecraft:air"
      },
      {
        "char": "b",
        "block": "minecraft:air"
      },
      {
        "char": "p",
        "block": "minecraft:air"
      },
      {
        "char": "L",
        "block": "minecraft:air"
      },
      {
        "char": "A",
        "block": "minecraft:grass"
      },
      {
        "char": "N",
        "block": "minecraft:air"
      },
      {
        "char": "m",
        "block": "minecraft:air"
      },
      {
        "char": "S",
        "block": "minecraft:air"
      },
      {
        "char": "M",
        "block": "minecraft:air"
      },
      {
        "char": "x",
        "block": "minecraft:air"
      },
      {
        "char": "T",
        "block": "minecraft:air"
      },
      {
        "char": "O",
        "block": "minecraft:air"
      },
      {
        "char": "s",
        "block": "minecraft:air"
      },
      {
        "char": "K",
        "block": "minecraft:air"
      },
      {
        "char": "P",
        "block": "minecraft:air"
      },
      {
        "char": "l",
        "block": "minecraft:air"
      },
      {
        "char": "B",
        "block": "minecraft:air"
      },
      {
        "char": "J",
        "block": "minecraft:air"
      },
      {
        "char": "H",
        "block": "minecraft:air"
      },
      {
        "char": "I",
        "block": "minecraft:air"
      },
      {
        "char": "Q",
        "block": "minecraft:air"
      },
      {
        "char": "y",
        "block": "minecraft:air"
      },
      {
        "char": "f",
        "block": "minecraft:tall_grass[half=upper]"
      },
      {
        "char": "n",
        "block": "minecraft:air"
      },
      {
        "char": "o",
        "block": "minecraft:air"
      },
      {
        "char": "R",
        "block": "minecraft:air"
      },
      {
        "char": "C",
        "block": "minecraft:air"
      },
      {
        "char": "G",
        "block": "minecraft:air"
      }
    ]
  },
  "slices": [
    [
      "ajjahgckdhhdaiah",
      "urzahdhdchdcavrc",
      "Ewvakdccgchgatid",
      "aaaadcghdchhajrc",
      "guhkgddggkhkatuc",
      "chccchggcddcawrc",
      "cgdcachgkkccaiic",
      "gdccgdcdhgchaitg",
      "dccadkuhdkgdatja",
      "cacckggdkgccaiia",
      "accdgddhhddhavwa",
      "ddgddcdddcguaija",
      "aaaaaaaaaaaaaiia",
      "vjFjiijriiwitzra",
      "EjvrrrDiwzFjjtDa",
      "aaaaaaaaaaaaaaaa"
    ],
    [
      "eq b      q pbL ",
      "q qA b   N  e b ",
      "   m  b SM  e  m",
      "AxTe  bb O mx   ",
      " pb  ssssss m e ",
      "  bbb  bbKPme   ",
      " lbbp l     m B ",
      "   b     Jl x  l",
      "l bH  I    m    ",
      "qb bb  m  l elbe",
      "e bbb   lQl e be",
      "   q q   m bbbbq",
      "expbbeexepeppbbp",
      "  bbbb  m  ybbbb",
      " y bBby  b m bee",
      "elqbppl e eeeeqe"
    ],
    [
      "f           n   ",
      "            f   ",
      "            f   ",
      " o f        o   ",
      " n     b      f ",
      "            f   ",
      "   bn           ",
      "   b        o   ",
      "   bb           ",
      "  bb        f  f",
      "f b         f  f",
      "                ",
      "fon  ffofnfnnb n",
      "    b        b  ",
      "   b          ff",
      "f   nn  f ffff f"
    ],
    [
      "                ",
      "                ",
      "                ",
      " o          o   ",
      "                ",
      "                ",
      "                ",
      "            o   ",
      "                ",
      "                ",
      "                ",
      "                ",
      " o     o        ",
      "                ",
      "                ",
      "                "
    ],
    [
      "                ",
      "                ",
      "                ",
      " R          C   ",
      "                ",
      "                ",
      "                ",
      "            C   ",
      "                ",
      "                ",
      "                ",
      "                ",
      " G     G        ",
      "                ",
      "                ",
      "                "
    ],
    [
      "                ",
      "                ",
      "                ",
      "                ",
      "                ",
      "                ",
      "                ",
      "                ",
      "                ",
      "                ",
      "                ",
      "                ",
      "                ",
      "                ",
      "                ",
      "                "
    ]
  ]
}