{
  "xsize": 16,
  "zsize": 16,
  "palette": {
    "palette": [
      {
        "char": " ",
        "block": "minecraft:air"
      },
      {
        "char": "a",
        "block": "minecraft:air"
      },
      {
        "char": "j",
        "block": "minecraft:air"
      },
      {
        "char": "h",
        "block": "minecraft:air"
      },
      {
        "char": "g",
        "block": "minecraft:air"
      },
      {
        "char": "e",
        "block": "minecraft:air"
      },
      {
        "char": "m",
        "block": "minecraft:air"
      },
      {
        "char": "f",
        "block": "minecraft:air"
      },
      {
        "char": "i",
        "block": "minecraft:air"
      },
      {
        "char": "t",
        "block": "minecraft:air"
      },
      {
        "char": "o",
        "block": "minecraft:air"
      },
      {
        "char": "x",
        "block": "minecraft:air"
      },
      {
        "char": "A",
        "block": "minecraft:air"
      },
      {
        "char": "D",
        "block": "minecraft:air"
      },
      {
        "char": "r",
        "block": "minecraft:air"
      },
      {
        "char": "S",
        "block": "minecraft:air"
      },
      {
        "char": "B",
        "block": "minecraft:air"
      },
      {
        "char": "O",
        "block": "minecraft:air"
      },
      {
        "char": "E",
        "block": "minecraft:air"
      },
      {
        "char": "C",
        "block": "minecraft:air"
      },
      {
        "char": "c",
        "block": "minecraft:tall_grass[half=lower]"
      },
      {
        "char": "b",
        "block": "minecraft:air"
      },
      {
        "char": "p",
        "block": "minecraft:air"
      },
      {
        "char": "s",
        "block": "minecraft:air"
      },
      {
        "char": "L",
        "block": "minecraft:air"
      },
      {
        "char": "q",
        "block": "minecraft:air"
      },
      {
        "char": "l",
        "block": "minecraft:air"
      },
      {
        "char": "P",
        "block": "minecraft:air"
      },
      {
        "char": "u",
        "block": "minecraft:air"
      },
      {
        "char": "R",
        "block": "minecraft:air"
      },
      {
        "char": "v",
        "block": "minecraft:air"
      },
      {
        "char": "U",
        "block": "minecraft:air"
      },
      {
        "char": "K",
        "block": "minecraft:air"
      },
      {
        "char": "y",
        "block": "minecraft:air"
      },
      {
        "char": "N",
        "block": "minecraft:air"
      },
      {
        "char": "G",
        "block": "minecraft:air"
      },
      {
        "char": "J",
        "block": "minecraft:air"
      },
      {
        "char": "M",
        "block": "minecraft:air"
      },
      {
        "char": "Q",
        "block": "minecraft:air"
      },
      {
        "char": "I",
        "block": "minecraft:grass"
      },
      {
        "char": "w",
        "block": "minecraft:air"
      },
      {
        "char": "H",
        "block": "minecraft:air"
      },
      {
        "char": "d",
        "block": "minecraft:tall_grass[half=upper]"
      },
      {
        "char": "k",
        "block": "minecraft:air"
      },
      {
        "char": "n",
        "block": "minecraft:air"
      },
      {
        "char": "T",
        "block": "minecraft:air"
      },
      {
        "char": "z",
        "block": "minecraft:air"
      },
      {
        "char": "F",
        "block": "minecraft:air"
      }
    ]
  },
  "slices": [
    [
      "aajahgemfhhfaiaa",
      "toxahfhfehfeaAoa",
      "DrAamfeegehgajia",
      "aaaafeghfehhajoa",
      "gthmgffggmhmaSta",
      "eheeehggeffeajoa",
      "egfeaehgmmeeaiia",
      "gfeegfefhgehaira",
      "feeafmthfmgfarja",
      "eaeemggfmgeeaiia",
      "aeefgffhhffhaBra",
      "ffgffefffegtaija",
      "aaaaaaaaaaaaaiia",
      "OrEjiijoiirijxoa",
      "DjBoooCirxErjjCa",
      "aaaaaaaaaaaaaaaa"
    ],
    [
      "cb bp  s bbbcb c",
      "bbb   p   bbc b ",
      " bb      LbqlPcc",
      " u q R      u   ",
      "   s  q    sc cc",
      " v       U  cp p",
      "sv ppK p    lcyc",
      " v   s  bbb up  ",
      "      Nbbbb c Gc",
      " J  M  bbb  l b ",
      "bb      b   l bc",
      " bb   Q    lccb ",
      "Iulccpluclc cccc",
      "s      qqc wq  c",
      "qw qy w  b   bcH",
      "  cll clc clcccc"
    ],
    [
      "d           d  d",
      " bb       bbd   ",
      "            k dd",
      " n          n   ",
      "            d dd",
      "            d   ",
      "            kd d",
      "            n   ",
      "        bb  d  d",
      "        b   k   ",
      " b          k  d",
      " b         kdd  ",
      " nkdd kndkd dddd",
      "         d     d",
      "              d ",
      "  dkk dkd dkdddd"
    ],
    [
      "                ",
      "                ",
      "                ",
      " n          n   ",
      "                ",
      "                ",
      "                ",
      "            n   ",
      "                ",
      "                ",
      "                ",
      "                ",
      " n     n        ",
      "                ",
      "                ",
      "                "
    ],
    [
      "                ",
      "                ",
      "                ",
      " T          z   ",
      "                ",
      "                ",
      "                ",
      "            z   ",
      "                ",
      "                ",
      "                ",
      "                ",
      " F     F        ",
      "                ",
      "                ",
      "                "
    ],
    [
      "                ",
      "                ",
      "                ",
      "                ",
      "                ",
      "                ",
      "                ",
      "                ",
      "                ",
      "                ",
      "                ",
      "                ",
      "                ",
      "                ",
      "                ",
      "                "
    ]
  ]
}