{
  "xsize": 16,
  "zsize": 16,
  "palette": {
    "palette": [
      {
        "char": " ",
        "block": "minecraft:air"
      },
      {
        "char": "e",
        "block": "minecraft:grass_block[snowy=false]"
      },
      {
        "char": "n",
        "block": "minecraft:cracked_stone_bricks"
      },
      {
        "char": "o",
        "block": "minecraft:air"
      },
      {
        "char": "h",
        "block": "minecraft:blackstone"
      },
      {
        "char": "c",
        "block": "minecraft:deepslate[axis=y]"
      },
      {
        "char": "d",
        "block": "minecraft:cobbled_deepslate"
      },
      {
        "char": "i",
        "block": "minecraft:basalt[axis=x]"
      },
      {
        "char": "a",
        "block": "minecraft:cyan_terracotta"
      },
      {
        "char": "z",
        "block": "minecraft:mossy_cobblestone"
      },
      {
        "char": "v",
        "block": "minecraft:air"
      },
      {
        "char": "q",
        "block": "minecraft:mossy_stone_bricks"
      },
      {
        "char": "k",
        "block": "minecraft:moss_block"
      },
      {
        "char": "r",
        "block": "minecraft:stone[weathering=false]"
      },
      {
        "char": "u",
        "block": "minecraft:stone[weathering=true]"
      },
      {
        "char": "y",
        "block": "minecraft:cobblestone_stairs[facing=north,half=bottom,shape=straight,waterlogged=false,weathering=false]"
      },
      {
        "char": "f",
        "block": "minecraft:air"
      },
      {
        "char": "m",
        "block": "minecraft:large_fern[half=lower]"
      },
      {
        "char": "t",
        "block": "minecraft:air"
      },
      {
        "char": "j",
        "block": "minecraft:air"
      },
      {
        "char": "b",
        "block": "minecraft:oak_leaves[distance=7,persistent=true,waterlogged=false]"
      },
      {
        "char": "p",
        "block": "minecraft:air"
      },
      {
        "char": "w",
        "block": "minecraft:structure_void"
      },
      {
        "char": "x",
        "block": "minecraft:air"
      },
      {
        "char": "A",
        "block": "minecraft:air"
      },
      {
        "char": "C",
        "block": "minecraft:air"
      },
      {
        "char": "g",
        "block": "minecraft:air"
      },
      {
        "char": "l",
        "block": "minecraft:large_fern[half=upper]"
      },
      {
        "char": "s",
        "block": "minecraft:structure_void"
      },
      {
        "char": "B",
        "block": "minecraft:structure_void"
      },
      {
        "char": "D",
        "block": "minecraft:structure_void"
      }
    ]
  },
  "slices": [
    [
      "enoehchdiadiezne",
      "vnqekadddccheven",
      "rroecihdacaaerqu",
      "eeeedccaacaheeee",
      "aaiacahadadhhhdc",
      "aaahhhchehdhhchc",
      "aaddhcichiicaacc",
      "deedicadcehicdda",
      "decddhhdaacccaah",
      "kiacdcckdhicciic",
      "daacddhcadckcaad",
      "daaadcaadcaicddh",
      "eeeecdacdacaeeee",
      "eooehadkciccenuk",
      "qqkeciiadhddeoru",
      "eyueadaaddcheqne"
    ],
    [
      "fm t     t   jff",
      " f ff  bb   f ff",
      "  pf  bbbb  f  j",
      "fffm  bbbb  ffwf",
      "j     pb  j     ",
      "   b    f   p   ",
      "  tbbb     bb p ",
      " mbbbb   f bbb  ",
      " xbbbb      bb  ",
      "f  b   m t   j  ",
      "      bbb  f    ",
      "      bbbb      ",
      "ffmfp  bb   mfwf",
      "f  f   f    ff f",
      "  ff       Af  j",
      "fC m j      f jf"
    ],
    [
      "gl            gg",
      " g gg       g gg",
      "   g   bb   g   ",
      "gggl    b   ggsg",
      "                ",
      "        g       ",
      "                ",
      " l  b    g  b   ",
      "   b            ",
      "g      l        ",
      "           g    ",
      "        b       ",
      "gglg        lgsg",
      "g  g   g    gg g",
      "  gg        g   ",
      "g  l        g  g"
    ],
    [
      "                ",
      "                ",
      "                ",
      "              s ",
      "                ",
      "                ",
      "                ",
      "                ",
      "                ",
      "                ",
      "                ",
      "                ",
      "              s ",
      "                ",
      "                ",
      "                "
    ],
    [
      "                ",
      "                ",
      "                ",
      "              B ",
      "                ",
      "                ",
      "                ",
      "                ",
      "                ",
      "                ",
      "                ",
      "                ",
      "              D ",
      "                ",
      "                ",
      "                "
    ],
    [
      "                ",
      "                ",
      "                ",
      "                ",
      "                ",
      "                ",
      "                ",
      "                ",
      "                ",
      "                ",
      "                ",
      "                ",
      "                ",
      "                ",
      "                ",
      "                "
    ]
  ]
}