{
  "xsize": 16,
  "zsize": 16,
  "palette": {
    "palette": [
      {
        "char": " ",
        "block": "minecraft:air"
      },
      {
        "char": "b",
        "block": "minecraft:air"
      },
      {
        "char": "p",
        "block": "minecraft:air"
      },
      {
        "char": "n",
        "block": "minecraft:air"
      },
      {
        "char": "c",
        "block": "minecraft:air"
      },
      {
        "char": "a",
        "block": "minecraft:air"
      },
      {
        "char": "d",
        "block": "minecraft:air"
      },
      {
        "char": "q",
        "block": "minecraft:air"
      },
      {
        "char": "r",
        "block": "minecraft:air"
      },
      {
        "char": "j",
        "block": "minecraft:air"
      },
      {
        "char": "m",
        "block": "minecraft:air"
      },
      {
        "char": "f",
        "block": "minecraft:air"
      },
      {
        "char": "u",
        "block": "minecraft:air"
      },
      {
        "char": "w",
        "block": "minecraft:air"
      },
      {
        "char": "v",
        "block": "minecraft:air"
      },
      {
        "char": "l",
        "block": "minecraft:air"
      },
      {
        "char": "i",
        "block": "minecraft:air"
      },
      {
        "char": "g",
        "block": "minecraft:tall_grass[half=lower]"
      },
      {
        "char": "k",
        "block": "minecraft:air"
      },
      {
        "char": "e",
        "block": "minecraft:air"
      },
      {
        "char": "E",
        "block": "minecraft:air"
      },
      {
        "char": "s",
        "block": "minecraft:air"
      },
      {
        "char": "G",
        "block": "minecraft:air"
      },
      {
        "char": "B",
        "block": "minecraft:air"
      },
      {
        "char": "F",
        "block": "minecraft:air"
      },
      {
        "char": "z",
        "block": "minecraft:air"
      },
      {
        "char": "K",
        "block": "minecraft:air"
      },
      {
        "char": "C",
        "block": "minecraft:air"
      },
      {
        "char": "t",
        "block": "minecraft:air"
      },
      {
        "char": "D",
        "block": "minecraft:air"
      },
      {
        "char": "y",
        "block": "minecraft:grass"
      },
      {
        "char": "J",
        "block": "minecraft:air"
      },
      {
        "char": "h",
        "block": "minecraft:tall_grass[half=upper]"
      },
      {
        "char": "o",
        "block": "minecraft:air"
      },
      {
        "char": "I",
        "block": "minecraft:air"
      },
      {
        "char": "H",
        "block": "minecraft:air"
      },
      {
        "char": "A",
        "block": "minecraft:air"
      },
      {
        "char": "x",
        "block": "minecraft:air"
      }
    ]
  },
  "slices": [
    [
      "bpnbcaacdaacbqrb",
      "bjjbadmaaccabrqb",
      "qjjbddcaaafdbjnj",
      "jpjbcadaadccbrnq",
      "fmaddfdcdcaafaca",
      "fdmdaafaffaacfcc",
      "mfadfccddcccaaac",
      "adcmufddacdmcmaf",
      "accdcdddccmcfccc",
      "ddaafcdfaaaaacad",
      "dmdacfafddmacdca",
      "acddfdfdaadcaddc",
      "bbbbbbbbbbbbbbbb",
      "bnjrnbjpjnjjqjnj",
      "qwpbvpnwnpvnujpu",
      "bbbbbbbbbbbbbbbb"
    ],
    [
      "l ig    kk ek   ",
      "ge g   Ei eee kg",
      " e s i    ees   ",
      "eeeg     li g  i",
      " ee    Gl     i ",
      "                ",
      " i    l    B  F ",
      "   i           i",
      "    z  K lii   l",
      "     ki   l  e  ",
      " kik   ii  eeee ",
      "        k k ee  ",
      " kgslg kggggsggg",
      "kee  l     l   l",
      "  eeek Ctk  giek",
      "D g tlet  gigyJg"
    ],
    [
      "   h            ",
      "h  h       e   h",
      "   o        o   ",
      " e h        h   ",
      "       I        ",
      "                ",
      "                ",
      "                ",
      "                ",
      "                ",
      "            ee  ",
      "                ",
      "  ho h  hhhhohhh",
      "                ",
      "  ee        h   ",
      "  h       h h  h"
    ],
    [
      "                ",
      "                ",
      "   o        o   ",
      "                ",
      "                ",
      "                ",
      "                ",
      "                ",
      "                ",
      "                ",
      "                ",
      "                ",
      "   o        o   ",
      "                ",
      "                ",
      "                "
    ],
    [
      "                ",
      "                ",
      "   H        A   ",
      "                ",
      "                ",
      "                ",
      "                ",
      "                ",
      "                ",
      "                ",
      "                ",
      "                ",
      "   x        x   ",
      "                ",
      "                ",
      "                "
    ],
    [
      "                ",
      "                ",
      "                ",
      "                ",
      "                ",
      "                ",
      "                ",
      "                ",
      "                ",
      "                ",
      "                ",
      "                ",
      "                ",
      "                ",
      "                ",
      "                "
    ]
  ]
}