{
  "xsize": 16,
  "zsize": 16,
  "palette": {
    "palette": [
      {
        "char": " ",
        "block": "minecraft:air"
      },
      {
        "char": "a",
        "block": "minecraft:air"
      },
      {
        "char": "j",
        "block": "minecraft:air"
      },
      {
        "char": "g",
        "block": "minecraft:air"
      },
      {
        "char": "h",
        "block": "minecraft:air"
      },
      {
        "char": "e",
        "block": "minecraft:air"
      },
      {
        "char": "l",
        "block": "minecraft:air"
      },
      {
        "char": "d",
        "block": "minecraft:air"
      },
      {
        "char": "i",
        "block": "minecraft:air"
      },
      {
        "char": "s",
        "block": "minecraft:air"
      },
      {
        "char": "p",
        "block": "minecraft:air"
      },
      {
        "char": "y",
        "block": "minecraft:air"
      },
      {
        "char": "w",
        "block": "minecraft:air"
      },
      {
        "char": "D",
        "block": "minecraft:air"
      },
      {
        "char": "H",
        "block": "minecraft:air"
      },
      {
        "char": "m",
        "block": "minecraft:air"
      },
      {
        "char": "E",
        "block": "minecraft:air"
      },
      {
        "char": "C",
        "block": "minecraft:air"
      },
      {
        "char": "b",
        "block": "minecraft:tall_grass[half=lower]"
      },
      {
        "char": "f",
        "block": "minecraft:air"
      },
      {
        "char": "k",
        "block": "minecraft:air"
      },
      {
        "char": "u",
        "block": "minecraft:air"
      },
      {
        "char": "z",
        "block": "minecraft:air"
      },
      {
        "char": "v",
        "block": "minecraft:grass"
      },
      {
        "char": "t",
        "block": "minecraft:air"
      },
      {
        "char": "o",
        "block": "minecraft:air"
      },
      {
        "char": "r",
        "block": "minecraft:air"
      },
      {
        "char": "A",
        "block": "minecraft:air"
      },
      {
        "char": "x",
        "block": "minecraft:air"
      },
      {
        "char": "F",
        "block": "minecraft:air"
      },
      {
        "char": "c",
        "block": "minecraft:tall_grass[half=upper]"
      },
      {
        "char": "n",
        "block": "minecraft:air"
      },
      {
        "char": "q",
        "block": "minecraft:air"
      },
      {
        "char": "I",
        "block": "minecraft:air"
      },
      {
        "char": "B",
        "block": "minecraft:air"
      },
      {
        "char": "G",
        "block": "minecraft:air"
      }
    ]
  },
  "slices": [
    [
      "ajjagheldggdaiaa",
      "spyagdgdegdeawpa",
      "DjHaldeeheghamia",
      "aaaadehgdeggajpa",
      "hsglhddhhaglajsa",
      "egeeeghaeddeajpa",
      "ehdeaeghlleeaiia",
      "hdeehdedghegaima",
      "deeadlsgdladamja",
      "eaeelhhdlaaeaiia",
      "aeedhddggddgawma",
      "ddhddedddehsaija",
      "aaaaaaaaaaaaaiia",
      "wmEjiijpiimimypa",
      "DjwpppCimyEmjmCa",
      "aaaaaaaaaaaaaaaa"
    ],
    [
      "b  f      k uf b",
      "bz b   f    u fb",
      "   bzfffff  v  b",
      "btbk  ff   ot  b",
      " b    f  f  r bb",
      "       b ff b   ",
      " k  b   ff  b Ab",
      "            tbkb",
      "k  v ou   b r  z",
      " u  of   uv rbf ",
      "v    ff   okb fb",
      "       k   bb fb",
      " tbbbrbtboobbbb ",
      "k   o k  o x F b",
      "ox  A x  f  kfbb",
      "b bb F bbrbrbkbo"
    ],
    [
      "c              c",
      "c  c           c",
      "   c   f       c",
      "cnc    f    n  c",
      " c          q cc",
      "       c f  c   ",
      "    c       c  c",
      "            nc c",
      "          c q   ",
      "            qc  ",
      "            c  c",
      "           cc  c",
      " ncccqcnc  cccc ",
      "               c",
      "              cc",
      "c cc   ccqcqc c "
    ],
    [
      "                ",
      "                ",
      "                ",
      " n          n   ",
      "                ",
      "                ",
      "                ",
      "            n   ",
      "                ",
      "                ",
      "                ",
      "                ",
      " n     n        ",
      "                ",
      "                ",
      "                "
    ],
    [
      "                ",
      "                ",
      "                ",
      " I          B   ",
      "                ",
      "                ",
      "                ",
      "            B   ",
      "                ",
      "                ",
      "                ",
      "                ",
      " G     G        ",
      "                ",
      "                ",
      "                "
    ],
    [
      "                ",
      "                ",
      "                ",
      "                ",
      "                ",
      "                ",
      "                ",
      "                ",
      "                ",
      "                ",
      "                ",
      "                ",
      "                ",
      "                ",
      "                ",
      "                "
    ]
  ]
}