{
  "xsize": 16,
  "zsize": 16,
  "palette": {
    "palette": [
      {
        "char": " ",
        "block": "minecraft:air"
      },
      {
        "char": "a",
        "block": "minecraft:air"
      },
      {
        "char": "i",
        "block": "minecraft:air"
      },
      {
        "char": "k",
        "block": "minecraft:air"
      },
      {
        "char": "n",
        "block": "minecraft:air"
      },
      {
        "char": "p",
        "block": "minecraft:air"
      },
      {
        "char": "w",
        "block": "minecraft:air"
      },
      {
        "char": "A",
        "block": "minecraft:air"
      },
      {
        "char": "u",
        "block": "minecraft:air"
      },
      {
        "char": "x",
        "block": "minecraft:air"
      },
      {
        "char": "I",
        "block": "minecraft:air"
      },
      {
        "char": "q",
        "block": "minecraft:air"
      },
      {
        "char": "j",
        "block": "minecraft:air"
      },
      {
        "char": "e",
        "block": "minecraft:air"
      },
      {
        "char": "h",
        "block": "minecraft:air"
      },
      {
        "char": "d",
        "block": "minecraft:air"
      },
      {
        "char": "g",
        "block": "minecraft:air"
      },
      {
        "char": "D",
        "block": "minecraft:air"
      },
      {
        "char": "s",
        "block": "minecraft:air"
      },
      {
        "char": "b",
        "block": "minecraft:tall_grass[half=lower]"
      },
      {
        "char": "m",
        "block": "minecraft:air"
      },
      {
        "char": "f",
        "block": "minecraft:air"
      },
      {
        "char": "v",
        "block": "minecraft:air"
      },
      {
        "char": "l",
        "block": "minecraft:air"
      },
      {
        "char": "F",
        "block": "minecraft:air"
      },
      {
        "char": "C",
        "block": "minecraft:air"
      },
      {
        "char": "t",
        "block": "minecraft:air"
      },
      {
        "char": "E",
        "block": "minecraft:air"
      },
      {
        "char": "L",
        "block": "minecraft:air"
      },
      {
        "char": "K",
        "block": "minecraft:air"
      },
      {
        "char": "G",
        "block": "minecraft:air"
      },
      {
        "char": "H",
        "block": "minecraft:air"
      },
      {
        "char": "y",
        "block": "minecraft:air"
      },
      {
        "char": "J",
        "block": "minecraft:air"
      },
      {
        "char": "M",
        "block": "minecraft:air"
      },
      {
        "char": "r",
        "block": "minecraft:air"
      },
      {
        "char": "c",
        "block": "minecraft:tall_grass[half=upper]"
      },
      {
        "char": "o",
        "block": "minecraft:air"
      },
      {
        "char": "z",
        "block": "minecraft:air"
      },
      {
        "char": "B",
        "block": "minecraft:air"
      }
    ]
  },
  "slices": [
    [
      "aaaaaaaaaaaaaaaa",
      "ikkknpwiiAiuikin",
      "wiinkkikxIkipawq",
      "aaaajehjdgghaaaa",
      "eheghdghgdjdjdgg",
      "gegegjeddhhhegej",
      "jgddhjgdjhdheggd",
      "gjddgghhdeeddgeh",
      "pgjedddegjededjg",
      "hdedehdehgedeghe",
      "ehdeejddeeedjheh",
      "hgddedpehddedpje",
      "aaaajegeghhjaaaa",
      "uiknxnnaAqqxiini",
      "uiiikpDkiinqkukq",
      "aaaaaaaaaaaaaaaa"
    ],
    [
      "sbbbbbb sbmsbbbb",
      " bfv b     v slf",
      "   f mfb  fm   F",
      "bbbs        C bb",
      "   l    f      m",
      "t E  L fff    l ",
      "     m fff  K ff",
      "        f   tfff",
      "b     l f    fff",
      "     f     G  f ",
      "l  mffft   l    ",
      "    ffbHyyJ  b m",
      "bmbb    t  M bbb",
      "  b  l b mm  l  ",
      " t vbf b   vb bl",
      "bbbbb bbbblbbbbb"
    ],
    [
      "rcccccc rc rcccc",
      " c o c     o r  ",
      "       c        ",
      "cccr          cc",
      "                ",
      "        f       ",
      "        f       ",
      "              f ",
      "c             f ",
      "                ",
      "     f          ",
      "      c      c  ",
      "c cc         ccc",
      "  c    c        ",
      "   oc  c   oc c ",
      "ccccc cccc ccccc"
    ],
    [
      "                ",
      "   o       o    ",
      "                ",
      "                ",
      "                ",
      "                ",
      "                ",
      "                ",
      "                ",
      "                ",
      "                ",
      "                ",
      "                ",
      "                ",
      "   o       o    ",
      "                "
    ],
    [
      "                ",
      "   z       z    ",
      "                ",
      "                ",
      "                ",
      "                ",
      "                ",
      "                ",
      "                ",
      "                ",
      "                ",
      "                ",
      "                ",
      "                ",
      "   B       B    ",
      "                "
    ],
    [
      "                ",
      "                ",
      "                ",
      "                ",
      "                ",
      "                ",
      "                ",
      "                ",
      "                ",
      "                ",
      "                ",
      "                ",
      "                ",
      "                ",
      "                ",
      "                "
    ]
  ]
}