{
  "xsize": 16,
  "zsize": 16,
  "palette": {
    "palette": [
      {
        "char": " ",
        "block": "minecraft:air"
      },
      {
        "char": "b",
        "block": "minecraft:grass_block[snowy=false]"
      },
      {
        "char": "o",
        "block": "minecraft:stone[weathering=false]"
      },
      {
        "char": "k",
        "block": "minecraft:cracked_stone_bricks"
      },
      {
        "char": "c",
        "block": "minecraft:cyan_terracotta"
      },
      {
        "char": "a",
        "block": "minecraft:deepslate[axis=y]"
      },
      {
        "char": "d",
        "block": "minecraft:cobbled_deepslate"
      },
      {
        "char": "q",
        "block": "minecraft:air"
      },
      {
        "char": "t",
        "block": "minecraft:cobblestone_stairs[facing=north,half=bottom,shape=straight,waterlogged=false,weathering=false]"
      },
      {
        "char": "g",
        "block": "minecraft:air"
      },
      {
        "char": "l",
        "block": "minecraft:basalt[axis=z]"
      },
      {
        "char": "e",
        "block": "minecraft:blackstone"
      },
      {
        "char": "w",
        "block": "minecraft:moss_block"
      },
      {
        "char": "A",
        "block": "minecraft:mossy_stone_bricks"
      },
      {
        "char": "y",
        "block": "minecraft:mossy_cobblestone"
      },
      {
        "char": "i",
        "block": "minecraft:air"
      },
      {
        "char": "f",
        "block": "minecraft:air"
      },
      {
        "char": "h",
        "block": "minecraft:air"
      },
      {
        "char": "B",
        "block": "minecraft:air"
      },
      {
        "char": "r",
        "block": "minecraft:air"
      },
      {
        "char": "m",
        "block": "minecraft:air"
      },
      {
        "char": "p",
        "block": "minecraft:air"
      },
      {
        "char": "E",
        "block": "minecraft:structure_void"
      },
      {
        "char": "j",
        "block": "minecraft:structure_void"
      },
      {
        "char": "s",
        "block": "minecraft:air"
      },
      {
        "char": "z",
        "block": "minecraft:air"
      },
      {
        "char": "n",
        "block": "minecraft:air"
      },
      {
        "char": "D",
        "block": "minecraft:structure_void"
      },
      {
        "char": "K",
        "block": "minecraft:structure_void"
      },
      {
        "char": "G",
        "block": "minecraft:structure_void"
      },
      {
        "char": "J",
        "block": "minecraft:structure_void"
      },
      {
        "char": "F",
        "block": "minecraft:structure_void"
      },
      {
        "char": "u",
        "block": "minecraft:oak_leaves[distance=7,persistent=true,waterlogged=false]"
      },
      {
        "char": "C",
        "block": "minecraft:spruce_leaves[distance=7,persistent=true,waterlogged=false]"
      },
      {
        "char": "v",
        "block": "minecraft:jungle_leaves[distance=7,persistent=true,waterlogged=false]"
      },
      {
        "char": "H",
        "block": "minecraft:air"
      },
      {
        "char": "L",
        "block": "minecraft:structure_void"
      },
      {
        "char": "I",
        "block": "minecraft:structure_void"
      },
      {
        "char": "x",
        "block": "minecraft:structure_void"
      }
    ]
  },
  "slices": [
    [
      "bokbcaacdaacbqtb",
      "bggbadlaaccabtqb",
      "qggbddcaaaedbgkg",
      "gogbcadaadccbtkq",
      "eladdedcdcaaeaca",
      "edldaaeaeeaacecc",
      "leadeccddcccaaac",
      "adclweddacdlclae",
      "accdcdddcclceccc",
      "ddaaecdeaaaaacad",
      "dldaceaeddlacdca",
      "acddededaadcaddc",
      "bbbbbbbbbbbbbbbb",
      "bkgtkbgogkggqgkg",
      "qAobyokAkoykwgow",
      "bbbbbbbbbbbbbbbb"
    ],
    [
      "i f     hhB h   ",
      " r m  pEf h   h ",
      "   j fs  zf j   ",
      "    s n nifrn  f",
      " n   n Dii p  f ",
      "    z s Bp      ",
      " fm   i  r K  G ",
      "m  f           f",
      "m   J  F iff rpi",
      " nm  hf   i     ",
      " hfh   ff   s   ",
      "        h h     ",
      " h ji  h  m j  m",
      "h    i n mni p i",
      "    uh Cvhp ifuh",
      "p   viuvr  f    "
    ],
    [
      "                ",
      "                ",
      "   j        j   ",
      "                ",
      "       H        ",
      "                ",
      "                ",
      "                ",
      "                ",
      "                ",
      "                ",
      "                ",
      "   j        j   ",
      "                ",
      "                ",
      "                "
    ],
    [
      "                ",
      "                ",
      "   j        j   ",
      "                ",
      "                ",
      "                ",
      "                ",
      "                ",
      "                ",
      "                ",
      "                ",
      "                ",
      "   j        j   ",
      "                ",
      "                ",
      "                "
    ],
    [
      "                ",
      "                ",
      "   L        I   ",
      "                ",
      "                ",
      "                ",
      "                ",
      "                ",
      "                ",
      "                ",
      "                ",
      "                ",
      "   x        x   ",
      "                ",
      "                ",
      "                "
    ],
    [
      "                ",
      "                ",
      "                ",
      "                ",
      "                ",
      "                ",
      "                ",
      "                ",
      "                ",
      "                ",
      "                ",
      "                ",
      "                ",
      "                ",
      "                ",
      "                "
    ]
  ]
}