{
  "xsize": 16,
  "zsize": 16,
  "palette": {
    "palette": [
      {
        "char": " ",
        "block": "minecraft:air"
      },
      {
        "char": "e",
        "block": "minecraft:air"
      },
      {
        "char": "n",
        "block": "minecraft:air"
      },
      {
        "char": "o",
        "block": "minecraft:air"
      },
      {
        "char": "h",
        "block": "minecraft:air"
      },
      {
        "char": "c",
        "block": "minecraft:air"
      },
      {
        "char": "d",
        "block": "minecraft:air"
      },
      {
        "char": "i",
        "block": "minecraft:air"
      },
      {
        "char": "a",
        "block": "minecraft:air"
      },
      {
        "char": "z",
        "block": "minecraft:air"
      },
      {
        "char": "v",
        "block": "minecraft:air"
      },
      {
        "char": "q",
        "block": "minecraft:air"
      },
      {
        "char": "k",
        "block": "minecraft:air"
      },
      {
        "char": "r",
        "block": "minecraft:air"
      },
      {
        "char": "u",
        "block": "minecraft:air"
      },
      {
        "char": "y",
        "block": "minecraft:air"
      },
      {
        "char": "f",
        "block": "minecraft:tall_grass[half=lower]"
      },
      {
        "char": "m",
        "block": "minecraft:air"
      },
      {
        "char": "t",
        "block": "minecraft:air"
      },
      {
        "char": "j",
        "block": "minecraft:air"
      },
      {
        "char": "b",
        "block": "minecraft:air"
      },
      {
        "char": "p",
        "block": "minecraft:air"
      },
      {
        "char": "w",
        "block": "minecraft:air"
      },
      {
        "char": "x",
        "block": "minecraft:grass"
      },
      {
        "char": "A",
        "block": "minecraft:air"
      },
      {
        "char": "C",
        "block": "minecraft:air"
      },
      {
        "char": "g",
        "block": "minecraft:tall_grass[half=upper]"
      },
      {
        "char": "l",
        "block": "minecraft:air"
      },
      {
        "char": "s",
        "block": "minecraft:air"
      },
      {
        "char": "B",
        "block": "minecraft:air"
      },
      {
        "char": "D",
        "block": "minecraft:air"
      }
    ]
  },
  "slices": [
    [
      "enoehchdiadiezne",
      "vnqekadddccheven",
      "rroecihdacaaerqu",
      "eeeedccaacaheeee",
      "aaiacahadadhhhdc",
      "aaahhhchehdhhchc",
      "aaddhcichiicaacc",
      "deedicadcehicdda",
      "decddhhdaacccaah",
      "kiacdcckdhicciic",
      "daacddhcadckcaad",
      "daaadcaadcaicddh",
      "eeeecdacdacaeeee",
      "eooehadkciccenuk",
      "qqkeciiadhddeoru",
      "eyueadaaddcheqne"
    ],
    [
      "fm t     t   jff",
      " f ff  bb   f ff",
      "  pf  bbbb  f  j",
      "fffm  bbbb  ffwf",
      "j     pb  j     ",
      "   b    f   p   ",
      "  tbbb     bb p ",
      " mbbbb   f bbb  ",
      " xbbbb      bb  ",
      "f  b   m t   j  ",
      "      bbb  f    ",
      "      bbbb      ",
      "ffmfp  bb   mfwf",
      "f  f   f    ff f",
      "  ff       Af  j",
      "fC m j      f jf"
    ],
    [
      "gl            gg",
      " g gg       g gg",
      "   g   bb   g   ",
      "gggl    b   ggsg",
      "                ",
      "        g       ",
      "                ",
      " l  b    g  b   ",
      "   b            ",
      "g      l        ",
      "           g    ",
      "        b       ",
      "gglg        lgsg",
      "g  g   g    gg g",
      "  gg        g   ",
      "g  l        g  g"
    ],
    [
      "                ",
      "                ",
      "                ",
      "              s ",
      "                ",
      "                ",
      "                ",
      "                ",
      "                ",
      "                ",
      "                ",
      "                ",
      "              s ",
      "                ",
      "                ",
      "                "
    ],
    [
      "                ",
      "                ",
      "                ",
      "              B ",
      "                ",
      "                ",
      "                ",
      "                ",
      "                ",
      "                ",
      "                ",
      "                ",
      "              D ",
      "                ",
      "                ",
      "                "
    ],
    [
      "                ",
      "                ",
      "                ",
      "                ",
      "                ",
      "                ",
      "                ",
      "                ",
      "                ",
      "                ",
      "                ",
      "                ",
      "                ",
      "                ",
      "                ",
      "                "
    ]
  ]
}