{
  "xsize": 16,
  "zsize": 16,
  "palette": {
    "palette": [
      {
        "char": " ",
        "block": "minecraft:air"
      },
      {
        "char": "a",
        "block": "minecraft:air"
      },
      {
        "char": "i",
        "block": "minecraft:air"
      },
      {
        "char": "l",
        "block": "minecraft:air"
      },
      {
        "char": "p",
        "block": "minecraft:air"
      },
      {
        "char": "u",
        "block": "minecraft:air"
      },
      {
        "char": "k",
        "block": "minecraft:air"
      },
      {
        "char": "y",
        "block": "minecraft:air"
      },
      {
        "char": "G",
        "block": "minecraft:air"
      },
      {
        "char": "v",
        "block": "minecraft:air"
      },
      {
        "char": "B",
        "block": "minecraft:air"
      },
      {
        "char": "s",
        "block": "minecraft:air"
      },
      {
        "char": "g",
        "block": "minecraft:air"
      },
      {
        "char": "e",
        "block": "minecraft:air"
      },
      {
        "char": "f",
        "block": "minecraft:air"
      },
      {
        "char": "h",
        "block": "minecraft:air"
      },
      {
        "char": "j",
        "block": "minecraft:air"
      },
      {
        "char": "w",
        "block": "minecraft:air"
      },
      {
        "char": "m",
        "block": "minecraft:air"
      },
      {
        "char": "c",
        "block": "minecraft:tall_grass[half=lower]"
      },
      {
        "char": "n",
        "block": "minecraft:air"
      },
      {
        "char": "r",
        "block": "minecraft:air"
      },
      {
        "char": "b",
        "block": "minecraft:air"
      },
      {
        "char": "t",
        "block": "minecraft:air"
      },
      {
        "char": "D",
        "block": "minecraft:air"
      },
      {
        "char": "C",
        "block": "minecraft:air"
      },
      {
        "char": "E",
        "block": "minecraft:air"
      },
      {
        "char": "H",
        "block": "minecraft:air"
      },
      {
        "char": "A",
        "block": "minecraft:grass"
      },
      {
        "char": "F",
        "block": "minecraft:air"
      },
      {
        "char": "d",
        "block": "minecraft:tall_grass[half=upper]"
      },
      {
        "char": "q",
        "block": "minecraft:air"
      },
      {
        "char": "o",
        "block": "minecraft:air"
      },
      {
        "char": "x",
        "block": "minecraft:air"
      },
      {
        "char": "z",
        "block": "minecraft:air"
      }
    ]
  },
  "slices": [
    [
      "aaaaaaaaaaaaaaaa",
      "illlipukkyiGilkk",
      "ukikllilvBlipaus",
      "aaaageegffeeaaaa",
      "fhfgheghgejejegg",
      "gfgfgfjhgeeefgfj",
      "jgeehfjfjehgfgge",
      "gjeegghheffeegfh",
      "pgafeeefgjfefejg",
      "hefaggfgfgfefghf",
      "fheffhhejehejhfh",
      "hgeefepfheefepjf",
      "aaaaghfhejhjaaaa",
      "kklkvkkaywsvkiki",
      "kiiilpwliiislkls",
      "aaaaaaaaaaaaaaaa"
    ],
    [
      "mc mcmcnrmccccc ",
      " cbt c     t rmb",
      "   bn b   b cc D",
      "crccm       rccr",
      "m     n   m     ",
      "  C bbb       b ",
      " n bbb       bbb",
      "n  bb   E  Hmbbb",
      "  Ab   n      b ",
      "  bbb           ",
      "bbbbb   bb   n  ",
      "  bb  c bbb  c  ",
      "ncmcn   bbb c cc",
      "  c    c b      ",
      "n  tcbmcF  tc c ",
      "cc c  c cccccc c"
    ],
    [
      " d  d d q ddddd ",
      " d o d     o q  ",
      "            dd  ",
      "dqdd        qddq",
      "                ",
      "                ",
      "    b         b ",
      "              b ",
      "                ",
      "   b            ",
      "  bb            ",
      "      d  b   d  ",
      " d d     b  d dd",
      "  d    d        ",
      "   od  d   od d ",
      "dd d  d dddddd d"
    ],
    [
      "                ",
      "   o       o    ",
      "                ",
      "                ",
      "                ",
      "                ",
      "                ",
      "                ",
      "                ",
      "                ",
      "                ",
      "                ",
      "                ",
      "                ",
      "   o       o    ",
      "                "
    ],
    [
      "                ",
      "   x       x    ",
      "                ",
      "                ",
      "                ",
      "                ",
      "                ",
      "                ",
      "                ",
      "                ",
      "                ",
      "                ",
      "                ",
      "                ",
      "   z       z    ",
      "                "
    ],
    [
      "                ",
      "                ",
      "                ",
      "                ",
      "                ",
      "                ",
      "                ",
      "                ",
      "                ",
      "                ",
      "                ",
      "                ",
      "                ",
      "                ",
      "                ",
      "                "
    ]
  ]
}