{
  "xsize": 16,
  "zsize": 16,
  "palette": {
    "palette": [
      {
        "char": " ",
        "block": "minecraft:air"
      },
      {
        "char": "c",
        "block": "minecraft:cobbled_deepslate"
      },
      {
        "char": "f",
        "block": "minecraft:basalt[axis=x]"
      },
      {
        "char": "b",
        "block": "minecraft:cyan_terracotta"
      },
      {
        "char": "d",
        "block": "minecraft:blackstone"
      },
      {
        "char": "e",
        "block": "minecraft:deepslate[axis=y]"
      },
      {
        "char": "j",
        "block": "minecraft:grass_block[snowy=false]"
      },
      {
        "char": "o",
        "block": "minecraft:cobbled_deepslate_stairs[facing=north,half=bottom,shape=inner_left,waterlogged=false]"
      },
      {
        "char": "r",
        "block": "minecraft:blackstone_stairs[facing=south,half=bottom,shape=inner_left,waterlogged=false]"
      },
      {
        "char": "h",
        "block": "minecraft:air"
      },
      {
        "char": "a",
        "block": "minecraft:oak_leaves[distance=7,persistent=true,waterlogged=false]"
      },
      {
        "char": "i",
        "block": "minecraft:air"
      },
      {
        "char": "g",
        "block": "minecraft:air"
      },
      {
        "char": "m",
        "block": "minecraft:air"
      },
      {
        "char": "p",
        "block": "minecraft:fern"
      },
      {
        "char": "k",
        "block": "minecraft:air"
      },
      {
        "char": "s",
        "block": "minecraft:air"
      },
      {
        "char": "t",
        "block": "minecraft:air"
      },
      {
        "char": "l",
        "block": "minecraft:structure_void"
      },
      {
        "char": "q",
        "block": "minecraft:structure_void"
      },
      {
        "char": "n",
        "block": "minecraft:air"
      }
    ]
  },
  "slices": [
    [
      "cfbdbcebceeccdcb",
      "cfbdbcebdfcddfbb",
      "bfddddcefcebfcbb",
      "dfcfbejedecbcdbb",
      "edcfejcbffdebbbc",
      "bcorbccbcbddebbb",
      "bebfbffdfddccdfe",
      "bcbeccddeccbceje",
      "bbcccbccdbcccbcc",
      "bceeccdcbceeccdc",
      "cdfcddfbbdfcddfb",
      "cfcebfcbbfcebfcb",
      "bdecbcdbbdecbcdb",
      "dffdebbbcffdebbb",
      "ecbddebbbcbddebb",
      "dfddccdfefddccdf"
    ],
    [
      "h aa      iaa   ",
      " aaaaa  h  aaa  ",
      " aaaahg    aaaa ",
      "miaa  p   hhaai ",
      "  a  k a  g h   ",
      "g     aaaa    hg",
      "    a aaa       ",
      "h  aa    si g t ",
      " gaaa l  q  gh  ",
      "  aahi   g    ig",
      " g aa     gg    ",
      "      g   aa    ",
      "  aaa h iaaaa h ",
      " aaaa     aaaa  ",
      "aaaa      haaag ",
      "         g  i   "
    ],
    [
      "                ",
      "  aaa       a   ",
      "  aa        a   ",
      "                ",
      "                ",
      "       a        ",
      "                ",
      "   a          n ",
      "   a            ",
      "                ",
      "                ",
      "                ",
      "          aa    ",
      "  aa       aa   ",
      "                ",
      "                "
    ],
    [
      "                ",
      "                ",
      "                ",
      "                ",
      "                ",
      "                ",
      "                ",
      "                ",
      "                ",
      "                ",
      "                ",
      "                ",
      "                ",
      "                ",
      "                ",
      "                "
    ],
    [
      "                ",
      "                ",
      "                ",
      "                ",
      "                ",
      "                ",
      "                ",
      "                ",
      "                ",
      "                ",
      "                ",
      "                ",
      "                ",
      "                ",
      "                ",
      "                "
    ],
    [
      "                ",
      "                ",
      "                ",
      "                ",
      "                ",
      "                ",
      "                ",
      "                ",
      "                ",
      "                ",
      "                ",
      "                ",
      "                ",
      "                ",
      "                ",
      "                "
    ]
  ]
}