{
  "xsize": 16,
  "zsize": 16,
  "palette": {
    "palette": [
      {
        "char": " ",
        "block": "minecraft:air"
      },
      {
        "char": "a",
        "block": "minecraft:grass_block[snowy=false]"
      },
      {
        "char": "i",
        "block": "minecraft:air"
      },
      {
        "char": "l",
        "block": "minecraft:cracked_stone_bricks"
      },
      {
        "char": "p",
        "block": "minecraft:moss_block"
      },
      {
        "char": "s",
        "block": "minecraft:air"
      },
      {
        "char": "m",
        "block": "minecraft:stone[weathering=false]"
      },
      {
        "char": "x",
        "block": "minecraft:mossy_stone_bricks"
      },
      {
        "char": "t",
        "block": "minecraft:air"
      },
      {
        "char": "q",
        "block": "minecraft:cobblestone_stairs[facing=south,half=bottom,shape=straight,waterlogged=false,weathering=false]"
      },
      {
        "char": "f",
        "block": "minecraft:basalt[axis=x]"
      },
      {
        "char": "e",
        "block": "minecraft:cyan_terracotta"
      },
      {
        "char": "d",
        "block": "minecraft:deepslate[axis=y]"
      },
      {
        "char": "c",
        "block": "minecraft:cobbled_deepslate"
      },
      {
        "char": "h",
        "block": "minecraft:blackstone"
      },
      {
        "char": "u",
        "block": "minecraft:mossy_cobblestone_stairs[facing=south,half=bottom,shape=straight,waterlogged=false]"
      },
      {
        "char": "H",
        "block": "minecraft:stone[weathering=true]"
      },
      {
        "char": "j",
        "block": "minecraft:air"
      },
      {
        "char": "n",
        "block": "minecraft:air"
      },
      {
        "char": "g",
        "block": "minecraft:air"
      },
      {
        "char": "b",
        "block": "minecraft:oak_leaves[distance=7,persistent=true,waterlogged=false]"
      },
      {
        "char": "r",
        "block": "minecraft:structure_void"
      },
      {
        "char": "C",
        "block": "minecraft:spruce_leaves[distance=7,persistent=true,waterlogged=false]"
      },
      {
        "char": "B",
        "block": "minecraft:structure_void"
      },
      {
        "char": "E",
        "block": "minecraft:structure_void"
      },
      {
        "char": "D",
        "block": "minecraft:structure_void"
      },
      {
        "char": "G",
        "block": "minecraft:structure_void"
      },
      {
        "char": "F",
        "block": "minecraft:structure_void"
      },
      {
        "char": "A",
        "block": "minecraft:structure_void"
      },
      {
        "char": "v",
        "block": "minecraft:air"
      },
      {
        "char": "I",
        "block": "minecraft:fern"
      },
      {
        "char": "z",
        "block": "minecraft:air"
      },
      {
        "char": "k",
        "block": "minecraft:air"
      },
      {
        "char": "o",
        "block": "minecraft:structure_void"
      },
      {
        "char": "w",
        "block": "minecraft:structure_void"
      },
      {
        "char": "y",
        "block": "minecraft:structure_void"
      }
    ]
  },
  "slices": [
    [
      "aaaaaaaaaaaaaaaa",
      "illlipsmixiiilmm",
      "smimlliltqlipasq",
      "aaaafedffdchaaaa",
      "ehedhcdhdcfcfcdd",
      "dedefddcdfddedef",
      "fdccfcfhdehdeddc",
      "dfccddhhceeccdeh",
      "pdfecccedfececfd",
      "hcecfccffcceedhe",
      "ehcehefcedddfheh",
      "hdccehpehccecpfe",
      "aaaahfccccddaaaa",
      "milmtimaxqutHiii",
      "mimilpqliimulmlq",
      "aaaaaaaaaaaaaaaa"
    ],
    [
      "j nj j g     j j",
      " jbr      gr n b",
      "   bg b   b gg C",
      " gg  gn     j  j",
      "           g    ",
      " gB  E  bbb     ",
      "       bbbbb g  ",
      "        bbb     ",
      "j  gbb    b ngD ",
      "g  bbbn   g     ",
      "   bb   gg      ",
      "      gG  Fg  A ",
      "vjIz   nn     j ",
      "     n      bb  ",
      "   r b jg  rbbb ",
      " jv j jggj j bb "
    ],
    [
      "k  k k       k k",
      " k o       o    ",
      "                ",
      "            k  k",
      "                ",
      "         b      ",
      "        bbb     ",
      "                ",
      "k               ",
      "    b           ",
      "                ",
      "                ",
      " k            k ",
      "                ",
      "   o   k   o b  ",
      " k  k k  k k    "
    ],
    [
      "                ",
      "   o       o    ",
      "                ",
      "                ",
      "                ",
      "                ",
      "                ",
      "                ",
      "                ",
      "                ",
      "                ",
      "                ",
      "                ",
      "                ",
      "   o       o    ",
      "                "
    ],
    [
      "                ",
      "   w       w    ",
      "                ",
      "                ",
      "                ",
      "                ",
      "                ",
      "                ",
      "                ",
      "                ",
      "                ",
      "                ",
      "                ",
      "                ",
      "   y       y    ",
      "                "
    ],
    [
      "                ",
      "                ",
      "                ",
      "                ",
      "                ",
      "                ",
      "                ",
      "                ",
      "                ",
      "                ",
      "                ",
      "                ",
      "                ",
      "                ",
      "                ",
      "                "
    ]
  ]
}