{
  "xsize": 16,
  "zsize": 16,
  "palette": {
    "palette": [
      {
        "char": " ",
        "block": "minecraft:air"
      },
      {
        "char": "a",
        "block": "minecraft:air"
      },
      {
        "char": "h",
        "block": "minecraft:air"
      },
      {
        "char": "j",
        "block": "minecraft:air"
      },
      {
        "char": "r",
        "block": "minecraft:air"
      },
      {
        "char": "v",
        "block": "minecraft:air"
      },
      {
        "char": "o",
        "block": "minecraft:air"
      },
      {
        "char": "t",
        "block": "minecraft:air"
      },
      {
        "char": "O",
        "block": "minecraft:air"
      },
      {
        "char": "I",
        "block": "minecraft:air"
      },
      {
        "char": "Q",
        "block": "minecraft:air"
      },
      {
        "char": "i",
        "block": "minecraft:air"
      },
      {
        "char": "m",
        "block": "minecraft:air"
      },
      {
        "char": "e",
        "block": "minecraft:air"
      },
      {
        "char": "f",
        "block": "minecraft:air"
      },
      {
        "char": "g",
        "block": "minecraft:air"
      },
      {
        "char": "K",
        "block": "minecraft:air"
      },
      {
        "char": "A",
        "block": "minecraft:air"
      },
      {
        "char": "y",
        "block": "minecraft:air"
      },
      {
        "char": "c",
        "block": "minecraft:tall_grass[half=lower]"
      },
      {
        "char": "p",
        "block": "minecraft:air"
      },
      {
        "char": "l",
        "block": "minecraft:air"
      },
      {
        "char": "q",
        "block": "minecraft:grass"
      },
      {
        "char": "F",
        "block": "minecraft:air"
      },
      {
        "char": "s",
        "block": "minecraft:air"
      },
      {
        "char": "C",
        "block": "minecraft:air"
      },
      {
        "char": "b",
        "block": "minecraft:air"
      },
      {
        "char": "P",
        "block": "minecraft:air"
      },
      {
        "char": "S",
        "block": "minecraft:air"
      },
      {
        "char": "E",
        "block": "minecraft:air"
      },
      {
        "char": "R",
        "block": "minecraft:air"
      },
      {
        "char": "z",
        "block": "minecraft:air"
      },
      {
        "char": "M",
        "block": "minecraft:air"
      },
      {
        "char": "G",
        "block": "minecraft:air"
      },
      {
        "char": "H",
        "block": "minecraft:air"
      },
      {
        "char": "J",
        "block": "minecraft:air"
      },
      {
        "char": "T",
        "block": "minecraft:air"
      },
      {
        "char": "w",
        "block": "minecraft:air"
      },
      {
        "char": "x",
        "block": "minecraft:air"
      },
      {
        "char": "N",
        "block": "minecraft:air"
      },
      {
        "char": "u",
        "block": "minecraft:air"
      },
      {
        "char": "d",
        "block": "minecraft:tall_grass[half=upper]"
      },
      {
        "char": "k",
        "block": "minecraft:air"
      },
      {
        "char": "n",
        "block": "minecraft:air"
      },
      {
        "char": "L",
        "block": "minecraft:air"
      },
      {
        "char": "B",
        "block": "minecraft:air"
      },
      {
        "char": "D",
        "block": "minecraft:air"
      }
    ]
  },
  "slices": [
    [
      "ahjaaaaaaaaaarva",
      "ahoaaaaaaaaaavra",
      "rhhathOthIjhahjh",
      "hohaaaaaaaaaaQjr",
      "imeffafgfgeeiege",
      "ifmfeeieiieegagg",
      "miefaKgffgggeeeg",
      "efgmgiffegfmgmei",
      "eggfgfffggmgiggg",
      "ffeeigfaeeeeegef",
      "fmfegieiffmegfge",
      "egffififeefgeffg",
      "aaaaaaaaaaaaaaaa",
      "ajhvjahohjhhrojh",
      "rtoaAojtjoAjyhhy",
      "aaaaaaaaaaaaaaaa"
    ],
    [
      "c plcccclcllc  c",
      "c  qqcccccc c  l",
      " F s        s   ",
      " p cqqcccc lc c ",
      "C  bb b         ",
      "  bbbb  p   bc  ",
      " bbbbb  bbb pb  ",
      "bbbbb   bbbb    ",
      " bbbb PbbbbbbS  ",
      "  bb E qbbbb Rz ",
      "         bb MG C",
      "           HJzT ",
      "w cspllcc bxsxcc",
      "cc   q   bbb    ",
      "    b  Nuwb l bp",
      " clcucbuccccccc "
    ],
    [
      "d  kddddkdkkd  d",
      "d    dddddd d  k",
      "   n        n   ",
      "   d  dddd kd d ",
      "                ",
      "    b        d  ",
      "  bb            ",
      " bbbb     b     ",
      "  b      bbb    ",
      "          b     ",
      "                ",
      "                ",
      "  dn kkdd   n dd",
      "dd        b     ",
      "            k   ",
      " dkd d  ddddddd "
    ],
    [
      "                ",
      "                ",
      "   n        n   ",
      "                ",
      "                ",
      "                ",
      "   b            ",
      "   b            ",
      "          b     ",
      "                ",
      "                ",
      "            L   ",
      "   n        n   ",
      "                ",
      "                ",
      "                "
    ],
    [
      "                ",
      "                ",
      "   B        B   ",
      "                ",
      "                ",
      "                ",
      "                ",
      "                ",
      "                ",
      "                ",
      "                ",
      "                ",
      "   D        D   ",
      "                ",
      "                ",
      "                "
    ],
    [
      "                ",
      "                ",
      "                ",
      "                ",
      "                ",
      "                ",
      "                ",
      "                ",
      "                ",
      "                ",
      "                ",
      "                ",
      "                ",
      "                ",
      "                ",
      "                "
    ]
  ]
}