{
  "xsize": 16,
  "zsize": 16,
  "palette": {
    "palette": [
      {
        "char": " ",
        "block": "minecraft:air"
      },
      {
        "char": "a",
        "block": "minecraft:air"
      },
      {
        "char": "q",
        "block": "minecraft:air"
      },
      {
        "char": "l",
        "block": "minecraft:air"
      },
      {
        "char": "h",
        "block": "minecraft:air"
      },
      {
        "char": "g",
        "block": "minecraft:air"
      },
      {
        "char": "b",
        "block": "minecraft:air"
      },
      {
        "char": "m",
        "block": "minecraft:air"
      },
      {
        "char": "c",
        "block": "minecraft:air"
      },
      {
        "char": "i",
        "block": "minecraft:air"
      },
      {
        "char": "s",
        "block": "minecraft:air"
      },
      {
        "char": "o",
        "block": "minecraft:air"
      },
      {
        "char": "v",
        "block": "minecraft:air"
      },
      {
        "char": "I",
        "block": "minecraft:air"
      },
      {
        "char": "B",
        "block": "minecraft:air"
      },
      {
        "char": "C",
        "block": "minecraft:air"
      },
      {
        "char": "P",
        "block": "minecraft:air"
      },
      {
        "char": "y",
        "block": "minecraft:air"
      },
      {
        "char": "D",
        "block": "minecraft:air"
      },
      {
        "char": "z",
        "block": "minecraft:air"
      },
      {
        "char": "f",
        "block": "minecraft:air"
      },
      {
        "char": "j",
        "block": "minecraft:air"
      },
      {
        "char": "k",
        "block": "minecraft:air"
      },
      {
        "char": "d",
        "block": "minecraft:tall_grass[half=lower]"
      },
      {
        "char": "r",
        "block": "minecraft:grass"
      },
      {
        "char": "K",
        "block": "minecraft:air"
      },
      {
        "char": "G",
        "block": "minecraft:air"
      },
      {
        "char": "p",
        "block": "minecraft:air"
      },
      {
        "char": "t",
        "block": "minecraft:air"
      },
      {
        "char": "J",
        "block": "minecraft:air"
      },
      {
        "char": "w",
        "block": "minecraft:air"
      },
      {
        "char": "O",
        "block": "minecraft:air"
      },
      {
        "char": "R",
        "block": "minecraft:air"
      },
      {
        "char": "H",
        "block": "minecraft:air"
      },
      {
        "char": "L",
        "block": "minecraft:air"
      },
      {
        "char": "M",
        "block": "minecraft:air"
      },
      {
        "char": "u",
        "block": "minecraft:air"
      },
      {
        "char": "N",
        "block": "minecraft:air"
      },
      {
        "char": "E",
        "block": "minecraft:air"
      },
      {
        "char": "e",
        "block": "minecraft:tall_grass[half=upper]"
      },
      {
        "char": "n",
        "block": "minecraft:air"
      },
      {
        "char": "A",
        "block": "minecraft:air"
      },
      {
        "char": "Q",
        "block": "minecraft:air"
      },
      {
        "char": "x",
        "block": "minecraft:air"
      },
      {
        "char": "F",
        "block": "minecraft:air"
      }
    ]
  },
  "slices": [
    [
      "aqlahgbmchhcaiaa",
      "sovahchcbhcbaIoa",
      "BqCamcbbgbhgaPia",
      "aaaacbghcbhhaloa",
      "gshmgccggmhmalsa",
      "bhbbbhggbccbaqoa",
      "bgcbabhgmmbbaiia",
      "gcbbgcbchgbhaiqa",
      "cbbacmshcmgcalla",
      "babbmggcmgbbaiia",
      "abbcgcchhcchayqa",
      "ccgccbcccbgsaila",
      "aaaaaaaaaaaaaiia",
      "yqDliiloiiqilvoa",
      "BlCoooziqvDlllza",
      "aaaaaaaaaaaaaaaa"
    ],
    [
      "   f  j  k  df r",
      "   fj K G j   f ",
      "  fffp kk   d  r",
      " t fj       t  d",
      "        J  jj dd",
      "jk  p  kj   k  r",
      "            dkwd",
      "    O  R fHLtp d",
      "       j f kd  r",
      "fff     fpM   f ",
      "pff    jj   dkfk",
      " fp k        jfr",
      "dtkd dktddddk  d",
      "          pu   N",
      " u  w u  f   fdj",
      "j d d dddjEEdpdd"
    ],
    [
      "            e   ",
      "                ",
      "   f        e   ",
      " n          n  e",
      "              ee",
      "                ",
      "            e  e",
      "            n  e",
      "         f  e   ",
      "                ",
      " f          e   ",
      "                ",
      "en e e neeee   e",
      "                ",
      "              e ",
      "  e e eee AAe ee"
    ],
    [
      "                ",
      "                ",
      "                ",
      " n          n   ",
      "                ",
      "                ",
      "                ",
      "            n   ",
      "                ",
      "                ",
      "                ",
      "                ",
      " n     n        ",
      "                ",
      "                ",
      "                "
    ],
    [
      "                ",
      "                ",
      "                ",
      " Q          x   ",
      "                ",
      "                ",
      "                ",
      "            x   ",
      "                ",
      "                ",
      "                ",
      "                ",
      " F     F        ",
      "                ",
      "                ",
      "                "
    ],
    [
      "                ",
      "                ",
      "                ",
      "                ",
      "                ",
      "                ",
      "                ",
      "                ",
      "                ",
      "                ",
      "                ",
      "                ",
      "                ",
      "                ",
      "                ",
      "                "
    ]
  ]
}