{
  "xsize": 16,
  "zsize": 16,
  "palette": {
    "palette": [
      {
        "char": " ",
        "block": "minecraft:air"
      },
      {
        "char": "a",
        "block": "minecraft:grass_block[snowy=false]"
      },
      {
        "char": "k",
        "block": "minecraft:air"
      },
      {
        "char": "n",
        "block": "minecraft:cracked_stone_bricks"
      },
      {
        "char": "x",
        "block": "minecraft:stone[weathering=true]"
      },
      {
        "char": "r",
        "block": "minecraft:moss_block"
      },
      {
        "char": "u",
        "block": "minecraft:air"
      },
      {
        "char": "p",
        "block": "minecraft:stone[weathering=false]"
      },
      {
        "char": "z",
        "block": "minecraft:mossy_stone_bricks"
      },
      {
        "char": "v",
        "block": "minecraft:air"
      },
      {
        "char": "s",
        "block": "minecraft:cobblestone_stairs[facing=south,half=bottom,shape=straight,waterlogged=false,weathering=false]"
      },
      {
        "char": "c",
        "block": "minecraft:cyan_terracotta"
      },
      {
        "char": "h",
        "block": "minecraft:blackstone"
      },
      {
        "char": "b",
        "block": "minecraft:cobbled_deepslate"
      },
      {
        "char": "i",
        "block": "minecraft:basalt[axis=x]"
      },
      {
        "char": "g",
        "block": "minecraft:deepslate[axis=y]"
      },
      {
        "char": "w",
        "block": "minecraft:mossy_cobblestone_stairs[facing=south,half=bottom,shape=straight,waterlogged=false]"
      },
      {
        "char": "e",
        "block": "minecraft:air"
      },
      {
        "char": "m",
        "block": "minecraft:large_fern[half=lower]"
      },
      {
        "char": "K",
        "block": "minecraft:air"
      },
      {
        "char": "j",
        "block": "minecraft:air"
      },
      {
        "char": "d",
        "block": "minecraft:oak_leaves[distance=7,persistent=true,waterlogged=false]"
      },
      {
        "char": "t",
        "block": "minecraft:structure_void"
      },
      {
        "char": "G",
        "block": "minecraft:air"
      },
      {
        "char": "o",
        "block": "minecraft:air"
      },
      {
        "char": "H",
        "block": "minecraft:spruce_leaves[distance=7,persistent=true,waterlogged=false]"
      },
      {
        "char": "C",
        "block": "minecraft:structure_void"
      },
      {
        "char": "J",
        "block": "minecraft:structure_void"
      },
      {
        "char": "F",
        "block": "minecraft:structure_void"
      },
      {
        "char": "D",
        "block": "minecraft:structure_void"
      },
      {
        "char": "B",
        "block": "minecraft:structure_void"
      },
      {
        "char": "E",
        "block": "minecraft:structure_void"
      },
      {
        "char": "I",
        "block": "minecraft:air"
      },
      {
        "char": "f",
        "block": "minecraft:air"
      },
      {
        "char": "l",
        "block": "minecraft:large_fern[half=upper]"
      },
      {
        "char": "q",
        "block": "minecraft:structure_void"
      },
      {
        "char": "y",
        "block": "minecraft:structure_void"
      },
      {
        "char": "A",
        "block": "minecraft:structure_void"
      }
    ]
  },
  "slices": [
    [
      "aaaaaaaaaaaaaaaa",
      "knnnxruppzkxknpp",
      "upkknnknvsnkraus",
      "aaaachbigchbaaaa",
      "chcghbghgbibibgg",
      "gcgcibcbcigccgci",
      "igbbchbbgiiicggb",
      "gibbgghhbccbbgch",
      "rgicbbbcgicbcbig",
      "hbcbhbhcbbhbcghc",
      "chbcggbcbcgbihch",
      "hgbbcbrchbbcbric",
      "aaaaicgbigggaaaa",
      "ppnkvkpazwwvpkpk",
      "pkkknrsnkkpsnkns",
      "aaaaaaaaaaaaaaaa"
    ],
    [
      "ememmmeeeeeeKmme",
      " jdt mj    t G d",
      " o de de  d e  H",
      "ejme        eoee",
      "        j  j    ",
      "  o  j    dd    ",
      "o C  J   dddd  j",
      "j  oo  o ddd  j ",
      "mdjo    j       ",
      " dd       F  Dj ",
      "dd B  E         ",
      "dj   j     oje  ",
      "ejem   j    demo",
      "    o  m   dddd ",
      " o t dje  Itdddd",
      "eee meemeemeee e"
    ],
    [
      "flflllffffff llf",
      "   q l     q    ",
      "    f  f    f   ",
      "f lf        f ff",
      "                ",
      "                ",
      "           d    ",
      "                ",
      "l               ",
      " d              ",
      "                ",
      "             f  ",
      "f fl         fl ",
      "       l    dd  ",
      "   q   f   q    ",
      "fff lfflfflfff f"
    ],
    [
      "                ",
      "   q       q    ",
      "                ",
      "                ",
      "                ",
      "                ",
      "                ",
      "                ",
      "                ",
      "                ",
      "                ",
      "                ",
      "                ",
      "                ",
      "   q       q    ",
      "                "
    ],
    [
      "                ",
      "   y       y    ",
      "                ",
      "                ",
      "                ",
      "                ",
      "                ",
      "                ",
      "                ",
      "                ",
      "                ",
      "                ",
      "                ",
      "                ",
      "   A       A    ",
      "                "
    ],
    [
      "                ",
      "                ",
      "                ",
      "                ",
      "                ",
      "                ",
      "                ",
      "                ",
      "                ",
      "                ",
      "                ",
      "                ",
      "                ",
      "                ",
      "                ",
      "                "
    ]
  ]
}