{
  "xsize": 16,
  "zsize": 16,
  "palette": {
    "palette": [
      {
        "char": " ",
        "block": "minecraft:air"
      },
      {
        "char": "b",
        "block": "minecraft:air"
      },
      {
        "char": "i",
        "block": "minecraft:air"
      },
      {
        "char": "k",
        "block": "minecraft:air"
      },
      {
        "char": "m",
        "block": "minecraft:air"
      },
      {
        "char": "p",
        "block": "minecraft:air"
      },
      {
        "char": "u",
        "block": "minecraft:air"
      },
      {
        "char": "s",
        "block": "minecraft:air"
      },
      {
        "char": "B",
        "block": "minecraft:air"
      },
      {
        "char": "x",
        "block": "minecraft:air"
      },
      {
        "char": "v",
        "block": "minecraft:air"
      },
      {
        "char": "y",
        "block": "minecraft:air"
      },
      {
        "char": "c",
        "block": "minecraft:air"
      },
      {
        "char": "g",
        "block": "minecraft:air"
      },
      {
        "char": "h",
        "block": "minecraft:air"
      },
      {
        "char": "j",
        "block": "minecraft:air"
      },
      {
        "char": "f",
        "block": "minecraft:air"
      },
      {
        "char": "z",
        "block": "minecraft:air"
      },
      {
        "char": "d",
        "block": "minecraft:tall_grass[half=lower]"
      },
      {
        "char": "w",
        "block": "minecraft:air"
      },
      {
        "char": "a",
        "block": "minecraft:air"
      },
      {
        "char": "t",
        "block": "minecraft:air"
      },
      {
        "char": "r",
        "block": "minecraft:air"
      },
      {
        "char": "G",
        "block": "minecraft:air"
      },
      {
        "char": "n",
        "block": "minecraft:air"
      },
      {
        "char": "l",
        "block": "minecraft:air"
      },
      {
        "char": "L",
        "block": "minecraft:air"
      },
      {
        "char": "M",
        "block": "minecraft:air"
      },
      {
        "char": "D",
        "block": "minecraft:air"
      },
      {
        "char": "E",
        "block": "minecraft:air"
      },
      {
        "char": "J",
        "block": "minecraft:air"
      },
      {
        "char": "F",
        "block": "minecraft:air"
      },
      {
        "char": "H",
        "block": "minecraft:air"
      },
      {
        "char": "e",
        "block": "minecraft:tall_grass[half=upper]"
      },
      {
        "char": "o",
        "block": "minecraft:air"
      },
      {
        "char": "q",
        "block": "minecraft:air"
      },
      {
        "char": "I",
        "block": "minecraft:air"
      },
      {
        "char": "K",
        "block": "minecraft:air"
      },
      {
        "char": "A",
        "block": "minecraft:air"
      },
      {
        "char": "C",
        "block": "minecraft:air"
      }
    ]
  },
  "slices": [
    [
      "bbbbbbbbbbbbbbbb",
      "ikkkmpussBimiksm",
      "umimkkikxvkipbuy",
      "bbbbcgchcjfhbbbb",
      "chcghfghgfjfjfgg",
      "gcgccghchgcccgcj",
      "jgffjccfccfccggf",
      "gjffgghhfccffgch",
      "pgjcfffcgjcfcfjg",
      "hfcfccgfcjfhcghc",
      "chfchghgchhfjhch",
      "hgffcfpchffcfpjc",
      "bbbbffjccjchbbbb",
      "mmksximbBzyxiiii",
      "miiikpzkiisvkmkv",
      "bbbbbbbbbbbbbbbb"
    ],
    [
      "dddddddddd d  dw",
      "adat r  aa taaaa",
      "aaaad aaaaa daaG",
      "rddd   aa   dard",
      "       na   n  l",
      "    L  M   D  El",
      "             n  ",
      "            l   ",
      "nlJ    l        ",
      "  n       n Fn  ",
      "    l   l l     ",
      "  H a  l     d  ",
      "   aaa   aaaddad",
      "  d aaaraaaa aa ",
      "   twa d aatd r ",
      "lrldddnnddwdnddd"
    ],
    [
      "eeeeeeeeee e  e ",
      "ae o q     o    ",
      "aa  e   aa  ea  ",
      "qeee        e qe",
      "                ",
      "                ",
      "                ",
      "                ",
      "                ",
      "       I K      ",
      "                ",
      "             e  ",
      "    a       ee e",
      "  e  a q  a     ",
      "   o   e   oe q ",
      " q eee  ee e eee"
    ],
    [
      "                ",
      "   o       o    ",
      "                ",
      "                ",
      "                ",
      "                ",
      "                ",
      "                ",
      "                ",
      "                ",
      "                ",
      "                ",
      "                ",
      "                ",
      "   o       o    ",
      "                "
    ],
    [
      "                ",
      "   A       A    ",
      "                ",
      "                ",
      "                ",
      "                ",
      "                ",
      "                ",
      "                ",
      "                ",
      "                ",
      "                ",
      "                ",
      "                ",
      "   C       C    ",
      "                "
    ],
    [
      "                ",
      "                ",
      "                ",
      "                ",
      "                ",
      "                ",
      "                ",
      "                ",
      "                ",
      "                ",
      "                ",
      "                ",
      "                ",
      "                ",
      "                ",
      "                "
    ]
  ]
}