{
  "xsize": 16,
  "zsize": 16,
  "palette": {
    "palette": [
      {
        "char": " ",
        "block": "minecraft:air"
      },
      {
        "char": "a",
        "block": "minecraft:grass_block[snowy=false]"
      },
      {
        "char": "j",
        "block": "minecraft:air"
      },
      {
        "char": "g",
        "block": "minecraft:deepslate[axis=y]"
      },
      {
        "char": "h",
        "block": "minecraft:blackstone"
      },
      {
        "char": "e",
        "block": "minecraft:cyan_terracotta"
      },
      {
        "char": "l",
        "block": "minecraft:basalt[axis=x]"
      },
      {
        "char": "d",
        "block": "minecraft:cobbled_deepslate"
      },
      {
        "char": "i",
        "block": "minecraft:cracked_stone_bricks"
      },
      {
        "char": "s",
        "block": "minecraft:moss_block"
      },
      {
        "char": "p",
        "block": "minecraft:mossy_stone_bricks"
      },
      {
        "char": "y",
        "block": "minecraft:air"
      },
      {
        "char": "w",
        "block": "minecraft:cobblestone_stairs[facing=north,half=bottom,shape=straight,waterlogged=false,weathering=false]"
      },
      {
        "char": "D",
        "block": "minecraft:mossy_cobblestone"
      },
      {
        "char": "H",
        "block": "minecraft:cobblestone_stairs[facing=north,half=bottom,shape=straight,waterlogged=false,weathering=true]"
      },
      {
        "char": "m",
        "block": "minecraft:stone[weathering=false]"
      },
      {
        "char": "E",
        "block": "minecraft:air"
      },
      {
        "char": "C",
        "block": "minecraft:air"
      },
      {
        "char": "b",
        "block": "minecraft:air"
      },
      {
        "char": "f",
        "block": "minecraft:oak_leaves[distance=7,persistent=true,waterlogged=false]"
      },
      {
        "char": "k",
        "block": "minecraft:air"
      },
      {
        "char": "u",
        "block": "minecraft:fern"
      },
      {
        "char": "z",
        "block": "minecraft:air"
      },
      {
        "char": "v",
        "block": "minecraft:air"
      },
      {
        "char": "t",
        "block": "minecraft:structure_void"
      },
      {
        "char": "o",
        "block": "minecraft:air"
      },
      {
        "char": "r",
        "block": "minecraft:large_fern[half=lower]"
      },
      {
        "char": "A",
        "block": "minecraft:jungle_leaves[distance=7,persistent=true,waterlogged=false]"
      },
      {
        "char": "x",
        "block": "minecraft:spruce_leaves[distance=7,persistent=true,waterlogged=false]"
      },
      {
        "char": "F",
        "block": "minecraft:air"
      },
      {
        "char": "c",
        "block": "minecraft:air"
      },
      {
        "char": "n",
        "block": "minecraft:structure_void"
      },
      {
        "char": "q",
        "block": "minecraft:large_fern[half=upper]"
      },
      {
        "char": "I",
        "block": "minecraft:structure_void"
      },
      {
        "char": "B",
        "block": "minecraft:structure_void"
      },
      {
        "char": "G",
        "block": "minecraft:structure_void"
      }
    ]
  },
  "slices": [
    [
      "ajjagheldggdaiaa",
      "spyagdgdegdeawpa",
      "DjHaldeeheghamia",
      "aaaadehgdeggajpa",
      "hsglhddhhaglajsa",
      "egeeeghaeddeajpa",
      "ehdeaeghlleeaiia",
      "hdeehdedghegaima",
      "deeadlsgdladamja",
      "eaeelhhdlaaeaiia",
      "aeedhddggddgawma",
      "ddhddedddehsaija",
      "aaaaaaaaaaaaaiia",
      "wmEjiijpiimimypa",
      "DjwpppCimyEmjmCa",
      "aaaaaaaaaaaaaaaa"
    ],
    [
      "b  f      k uf b",
      "bz b   f    u fb",
      "   bzfffff  v  b",
      "btbk  ff   ot  b",
      " b    f  f  r bb",
      "       b ff b   ",
      " k  b   ff  b Ab",
      "            tbkb",
      "k  v ou   b r  z",
      " u  of   uv rbf ",
      "v    ff   okb fb",
      "       k   bb fb",
      " tbbbrbtboobbbb ",
      "k   o k  o x F b",
      "ox  A x  f  kfbb",
      "b bb F bbrbrbkbo"
    ],
    [
      "c              c",
      "c  c           c",
      "   c   f       c",
      "cnc    f    n  c",
      " c          q cc",
      "       c f  c   ",
      "    c       c  c",
      "            nc c",
      "          c q   ",
      "            qc  ",
      "            c  c",
      "           cc  c",
      " ncccqcnc  cccc ",
      "               c",
      "              cc",
      "c cc   ccqcqc c "
    ],
    [
      "                ",
      "                ",
      "                ",
      " n          n   ",
      "                ",
      "                ",
      "                ",
      "            n   ",
      "                ",
      "                ",
      "                ",
      "                ",
      " n     n        ",
      "                ",
      "                ",
      "                "
    ],
    [
      "                ",
      "                ",
      "                ",
      " I          B   ",
      "                ",
      "                ",
      "                ",
      "            B   ",
      "                ",
      "                ",
      "                ",
      "                ",
      " G     G        ",
      "                ",
      "                ",
      "                "
    ],
    [
      "                ",
      "                ",
      "                ",
      "                ",
      "                ",
      "                ",
      "                ",
      "                ",
      "                ",
      "                ",
      "                ",
      "                ",
      "                ",
      "                ",
      "                ",
      "                "
    ]
  ]
}