{
  "xsize": 16,
  "zsize": 16,
  "palette": {
    "palette": [
      {
        "char": " ",
        "block": "minecraft:air"
      },
      {
        "char": "c",
        "block": "minecraft:air"
      },
      {
        "char": "f",
        "block": "minecraft:air"
      },
      {
        "char": "b",
        "block": "minecraft:air"
      },
      {
        "char": "d",
        "block": "minecraft:air"
      },
      {
        "char": "e",
        "block": "minecraft:air"
      },
      {
        "char": "j",
        "block": "minecraft:air"
      },
      {
        "char": "o",
        "block": "minecraft:air"
      },
      {
        "char": "r",
        "block": "minecraft:air"
      },
      {
        "char": "h",
        "block": "minecraft:air"
      },
      {
        "char": "a",
        "block": "minecraft:air"
      },
      {
        "char": "i",
        "block": "minecraft:air"
      },
      {
        "char": "g",
        "block": "minecraft:air"
      },
      {
        "char": "m",
        "block": "minecraft:air"
      },
      {
        "char": "p",
        "block": "minecraft:air"
      },
      {
        "char": "k",
        "block": "minecraft:grass"
      },
      {
        "char": "s",
        "block": "minecraft:air"
      },
      {
        "char": "t",
        "block": "minecraft:tall_grass[half=lower]"
      },
      {
        "char": "l",
        "block": "minecraft:air"
      },
      {
        "char": "q",
        "block": "minecraft:air"
      },
      {
        "char": "n",
        "block": "minecraft:tall_grass[half=upper]"
      }
    ]
  },
  "slices": [
    [
      "cfbdbcebceeccdcb",
      "cfbdbcebdfcddfbb",
      "bfddddcefcebfcbb",
      "dfcfbejedecbcdbb",
      "edcfejcbffdebbbc",
      "bcorbccbcbddebbb",
      "bebfbffdfddccdfe",
      "bcbeccddeccbceje",
      "bbcccbccdbcccbcc",
      "bceeccdcbceeccdc",
      "cdfcddfbbdfcddfb",
      "cfcebfcbbfcebfcb",
      "bdecbcdbbdecbcdb",
      "dffdebbbcffdebbb",
      "ecbddebbbcbddebb",
      "dfddccdfefddccdf"
    ],
    [
      "h aa      iaa   ",
      " aaaaa  h  aaa  ",
      " aaaahg    aaaa ",
      "miaa  p   hhaai ",
      "  a  k a  g h   ",
      "g     aaaa    hg",
      "    a aaa       ",
      "h  aa    si g t ",
      " gaaa l  q  gh  ",
      "  aahi   g    ig",
      " g aa     gg    ",
      "      g   aa    ",
      "  aaa h iaaaa h ",
      " aaaa     aaaa  ",
      "aaaa      haaag ",
      "         g  i   "
    ],
    [
      "                ",
      "  aaa       a   ",
      "  aa        a   ",
      "                ",
      "                ",
      "       a        ",
      "                ",
      "   a          n ",
      "   a            ",
      "                ",
      "                ",
      "                ",
      "          aa    ",
      "  aa       aa   ",
      "                ",
      "                "
    ],
    [
      "                ",
      "                ",
      "                ",
      "                ",
      "                ",
      "                ",
      "                ",
      "                ",
      "                ",
      "                ",
      "                ",
      "                ",
      "                ",
      "                ",
      "                ",
      "                "
    ],
    [
      "                ",
      "                ",
      "                ",
      "                ",
      "                ",
      "                ",
      "                ",
      "                ",
      "                ",
      "                ",
      "                ",
      "                ",
      "                ",
      "                ",
      "                ",
      "                "
    ],
    [
      "                ",
      "                ",
      "                ",
      "                ",
      "                ",
      "                ",
      "                ",
      "                ",
      "                ",
      "                ",
      "                ",
      "                ",
      "                ",
      "                ",
      "                ",
      "                "
    ]
  ]
}