{
  "xsize": 16,
  "zsize": 16,
  "palette": {
    "palette": [
      {
        "char": " ",
        "block": "minecraft:air"
      },
      {
        "char": "a",
        "block": "minecraft:grass_block[snowy=false]"
      },
      {
        "char": "j",
        "block": "minecraft:air"
      },
      {
        "char": "m",
        "block": "minecraft:cracked_stone_bricks"
      },
      {
        "char": "e",
        "block": "minecraft:cyan_terracotta"
      },
      {
        "char": "b",
        "block": "minecraft:deepslate[axis=y]"
      },
      {
        "char": "d",
        "block": "minecraft:cobbled_deepslate"
      },
      {
        "char": "q",
        "block": "minecraft:air"
      },
      {
        "char": "u",
        "block": "minecraft:cobblestone_stairs[facing=north,half=bottom,shape=straight,waterlogged=false,weathering=false]"
      },
      {
        "char": "o",
        "block": "minecraft:stone[weathering=false]"
      },
      {
        "char": "l",
        "block": "minecraft:basalt[axis=z]"
      },
      {
        "char": "h",
        "block": "minecraft:blackstone"
      },
      {
        "char": "t",
        "block": "minecraft:moss_block"
      },
      {
        "char": "C",
        "block": "minecraft:cobblestone_stairs[facing=north,half=bottom,shape=straight,waterlogged=false,weathering=true]"
      },
      {
        "char": "F",
        "block": "minecraft:stone[weathering=true]"
      },
      {
        "char": "z",
        "block": "minecraft:mossy_stone_bricks"
      },
      {
        "char": "x",
        "block": "minecraft:mossy_cobblestone"
      },
      {
        "char": "f",
        "block": "minecraft:air"
      },
      {
        "char": "i",
        "block": "minecraft:air"
      },
      {
        "char": "k",
        "block": "minecraft:air"
      },
      {
        "char": "p",
        "block": "minecraft:air"
      },
      {
        "char": "c",
        "block": "minecraft:oak_leaves[distance=7,persistent=true,waterlogged=false]"
      },
      {
        "char": "r",
        "block": "minecraft:structure_void"
      },
      {
        "char": "v",
        "block": "minecraft:fern"
      },
      {
        "char": "G",
        "block": "minecraft:air"
      },
      {
        "char": "y",
        "block": "minecraft:large_fern[half=lower]"
      },
      {
        "char": "D",
        "block": "minecraft:spruce_leaves[distance=7,persistent=true,waterlogged=false]"
      },
      {
        "char": "s",
        "block": "minecraft:jungle_leaves[distance=7,persistent=true,waterlogged=false]"
      },
      {
        "char": "g",
        "block": "minecraft:air"
      },
      {
        "char": "n",
        "block": "minecraft:structure_void"
      },
      {
        "char": "w",
        "block": "minecraft:large_fern[half=upper]"
      },
      {
        "char": "E",
        "block": "minecraft:structure_void"
      },
      {
        "char": "B",
        "block": "minecraft:structure_void"
      },
      {
        "char": "A",
        "block": "minecraft:structure_void"
      }
    ]
  },
  "slices": [
    [
      "ajmaebbedbbeaqua",
      "ajoabdlbbeebauqa",
      "qjjaddebbbhdajmj",
      "jojaebdbbdeeaumq",
      "hlbddhdedebbhbeb",
      "hdldbbhbhhbbehee",
      "lhbdheeddeeebbbe",
      "bdelthddbadlelbh",
      "beededddealaheee",
      "ddbbhedhabbbbebd",
      "dldbehbhddlbedeb",
      "beddhdhdbbdebdde",
      "aaaaaaaaaaaaaaaa",
      "amjCmajojmjjqomF",
      "qzoaxomzmoxmtjjt",
      "aaaaaaaaaaaaaaaa"
    ],
    [
      "f ii  k  i  f  f",
      "p  f    cci f  k",
      "i  r   ccc ir   ",
      "cc v    c  if f ",
      " cc      i      ",
      " cc     i       ",
      "Gi     c k  i  k",
      "    y cccf      ",
      "      cc p vi   ",
      " ccc k  p   cck ",
      " cccc    icccc  ",
      "  cc  kk k cc   ",
      "kffrifff fffrfff",
      "ff   f          ",
      "    c  Dsk f  ci",
      "pyp s cs ffpff v"
    ],
    [
      "g           g  g",
      "   g        g   ",
      "   n    c   n   ",
      "            g g ",
      " c              ",
      "                ",
      "                ",
      "    w  c g      ",
      "                ",
      "                ",
      "   c        c   ",
      "                ",
      " ggn ggg gggnggg",
      "gg   g          ",
      "           g    ",
      " w       gg gg  "
    ],
    [
      "                ",
      "                ",
      "   n        n   ",
      "                ",
      "                ",
      "                ",
      "                ",
      "                ",
      "                ",
      "                ",
      "                ",
      "                ",
      "   n        n   ",
      "                ",
      "                ",
      "                "
    ],
    [
      "                ",
      "                ",
      "   E        B   ",
      "                ",
      "                ",
      "                ",
      "                ",
      "                ",
      "                ",
      "                ",
      "                ",
      "                ",
      "   A        A   ",
      "                ",
      "                ",
      "                "
    ],
    [
      "                ",
      "                ",
      "                ",
      "                ",
      "                ",
      "                ",
      "                ",
      "                ",
      "                ",
      "                ",
      "                ",
      "                ",
      "                ",
      "                ",
      "                ",
      "                "
    ]
  ]
}