{
  "xsize": 16,
  "zsize": 16,
  "palette": {
    "palette": [
      {
        "char": " ",
        "block": "minecraft:air"
      },
      {
        "char": "b",
        "block": "minecraft:air"
      },
      {
        "char": "i",
        "block": "minecraft:air"
      },
      {
        "char": "l",
        "block": "minecraft:air"
      },
      {
        "char": "d",
        "block": "minecraft:air"
      },
      {
        "char": "c",
        "block": "minecraft:air"
      },
      {
        "char": "e",
        "block": "minecraft:air"
      },
      {
        "char": "m",
        "block": "minecraft:air"
      },
      {
        "char": "s",
        "block": "minecraft:air"
      },
      {
        "char": "n",
        "block": "minecraft:air"
      },
      {
        "char": "k",
        "block": "minecraft:air"
      },
      {
        "char": "C",
        "block": "minecraft:air"
      },
      {
        "char": "h",
        "block": "minecraft:air"
      },
      {
        "char": "J",
        "block": "minecraft:air"
      },
      {
        "char": "O",
        "block": "minecraft:air"
      },
      {
        "char": "v",
        "block": "minecraft:air"
      },
      {
        "char": "D",
        "block": "minecraft:air"
      },
      {
        "char": "t",
        "block": "minecraft:air"
      },
      {
        "char": "r",
        "block": "minecraft:air"
      },
      {
        "char": "f",
        "block": "minecraft:tall_grass[half=lower]"
      },
      {
        "char": "a",
        "block": "minecraft:air"
      },
      {
        "char": "p",
        "block": "minecraft:air"
      },
      {
        "char": "x",
        "block": "minecraft:grass"
      },
      {
        "char": "j",
        "block": "minecraft:air"
      },
      {
        "char": "H",
        "block": "minecraft:air"
      },
      {
        "char": "T",
        "block": "minecraft:air"
      },
      {
        "char": "y",
        "block": "minecraft:air"
      },
      {
        "char": "P",
        "block": "minecraft:air"
      },
      {
        "char": "Q",
        "block": "minecraft:air"
      },
      {
        "char": "o",
        "block": "minecraft:air"
      },
      {
        "char": "z",
        "block": "minecraft:air"
      },
      {
        "char": "L",
        "block": "minecraft:air"
      },
      {
        "char": "u",
        "block": "minecraft:air"
      },
      {
        "char": "E",
        "block": "minecraft:air"
      },
      {
        "char": "A",
        "block": "minecraft:air"
      },
      {
        "char": "F",
        "block": "minecraft:air"
      },
      {
        "char": "I",
        "block": "minecraft:air"
      },
      {
        "char": "R",
        "block": "minecraft:air"
      },
      {
        "char": "S",
        "block": "minecraft:air"
      },
      {
        "char": "K",
        "block": "minecraft:air"
      },
      {
        "char": "G",
        "block": "minecraft:air"
      },
      {
        "char": "q",
        "block": "minecraft:air"
      },
      {
        "char": "N",
        "block": "minecraft:air"
      },
      {
        "char": "g",
        "block": "minecraft:tall_grass[half=upper]"
      },
      {
        "char": "M",
        "block": "minecraft:air"
      },
      {
        "char": "B",
        "block": "minecraft:air"
      },
      {
        "char": "w",
        "block": "minecraft:air"
      }
    ]
  },
  "slices": [
    [
      "bilbdccdeccdbmsb",
      "binbcekccddcbCmb",
      "miibeedccchebili",
      "inibdcebceddbJlm",
      "hkceehedbdcchcdc",
      "hekecchchhccdbdd",
      "khcehddeedddcccd",
      "cedkbheecdekdkch",
      "cddedeeeddkdhddd",
      "eecchdehcecccdce",
      "ekecdhcheekcdedc",
      "cdeeheheccedceed",
      "bbbbbbbbbbbbbbbb",
      "blislbiniliimOli",
      "mvnDtnlvlntlriir",
      "bbbbbbbbbbbbbbbb"
    ],
    [
      "fapf         aaa",
      "faaf      a xaaa",
      "aaaj     aaajaaa",
      "aaaa   f aaafaaa",
      " aaH    f a  aaa",
      "  Ty         fa ",
      " p PQ          o",
      "  z f           ",
      "   aa    L  p   ",
      "  aaaa   u      ",
      "  aaaaa  u      ",
      "   aa oo EA     ",
      "offjpf F  I jfff",
      "ff  ff      aaaR",
      "S  Ka  Gqo ffaa ",
      "ffNfqfaqffffffff"
    ],
    [
      "g  g            ",
      "g  g          aa",
      " aaj      a j a ",
      " aa    g  a g a ",
      "        g       ",
      "             g  ",
      "                ",
      "    g           ",
      "                ",
      "    a           ",
      "    a           ",
      "                ",
      " ggj g      jggg",
      "gg  gg       a  ",
      "           gg a ",
      "gg g g  gggggggg"
    ],
    [
      "                ",
      "                ",
      "   j        j   ",
      "                ",
      "                ",
      "                ",
      "                ",
      "                ",
      "                ",
      "                ",
      "                ",
      "                ",
      "   j        j   ",
      "                ",
      "                ",
      "                "
    ],
    [
      "                ",
      "                ",
      "   M        B   ",
      "                ",
      "                ",
      "                ",
      "                ",
      "                ",
      "                ",
      "                ",
      "                ",
      "                ",
      "   w        w   ",
      "                ",
      "                ",
      "                "
    ],
    [
      "                ",
      "                ",
      "                ",
      "                ",
      "                ",
      "                ",
      "                ",
      "                ",
      "                ",
      "                ",
      "                ",
      "                ",
      "                ",
      "                ",
      "                ",
      "                "
    ]
  ]
}