{
  "xsize": 16,
  "zsize": 16,
  "palette": {
    "palette": [
      {
        "char": " ",
        "block": "minecraft:air"
      },
      {
        "char": "m",
        "block": "minecraft:air"
      },
      {
        "char": "k",
        "block": "minecraft:air"
      },
      {
        "char": "i",
        "block": "minecraft:air"
      },
      {
        "char": "a",
        "block": "minecraft:air"
      },
      {
        "char": "P",
        "block": "minecraft:air"
      },
      {
        "char": "v",
        "block": "minecraft:air"
      },
      {
        "char": "o",
        "block": "minecraft:air"
      },
      {
        "char": "n",
        "block": "minecraft:tall_grass[half=lower]"
      },
      {
        "char": "e",
        "block": "minecraft:grass"
      },
      {
        "char": "J",
        "block": "minecraft:air"
      },
      {
        "char": "ω",
        "block": "minecraft:air"
      },
      {
        "char": "ί",
        "block": "minecraft:air"
      },
      {
        "char": "b",
        "block": "minecraft:air"
      },
      {
        "char": "Њ",
        "block": "minecraft:air"
      },
      {
        "char": "j",
        "block": "minecraft:air"
      },
      {
        "char": "t",
        "block": "minecraft:air"
      },
      {
        "char": "方",
        "block": "minecraft:air"
      },
      {
        "char": "论",
        "block": "minecraft:air"
      },
      {
        "char": "V",
        "block": "minecraft:air"
      },
      {
        "char": "r",
        "block": "minecraft:tall_grass[half=upper]"
      },
      {
        "char": "q",
        "block": "minecraft:air"
      }
    ]
  },
  "slices": [
    [
      "mkmmkiimaaaaaaaP",
      "kiikkmiiaaaaaaaa",
      "aaaaaaaaaaaaaaaa",
      "aaaaaaaaaaaaaaaa",
      "aaaaaaaaaaaaaaaa",
      "kaikivkiimoikoao",
      "iiioikmoiakvkiim",
      "mmmviimoivmvioak",
      "mikkookomomikvki",
      "omkovaoiivkkviio",
      "mvaiokookikokvai",
      "vkikmvkkkkamkmiv",
      "vkvovkoivkmkkkmm",
      "kiiovimiikkmiivv",
      "kmikvikmomiimvao",
      "okvmooovimvoiaom"
    ],
    [
      "        neeJnnωί",
      "        beeee en",
      "beenneJneeЊeeeee",
      "bbJeeeebeeebeeeJ",
      "nbjbnbbnbbnbbbnb",
      " j     jjjjjjtj ",
      "j   tj  tj tj   ",
      " t jj   j     t ",
      "   t   t j  tjj ",
      "     t  方  论 jj ",
      " tj j j jj   jt ",
      "   jVV t jj t   ",
      "j  jt        jj ",
      "  t V t j t jjVt",
      "j      tVjj jVjj",
      "        jtjt j  "
    ],
    [
      "        r  Jrr  ",
      "               r",
      "      Jr        ",
      " bJ            b",
      "r   rJbr  r b r ",
      "                ",
      "                ",
      "                ",
      "                ",
      "                ",
      "                ",
      "                ",
      "                ",
      "                ",
      "                ",
      "                "
    ],
    [
      "           b    ",
      "                ",
      "      b         ",
      "  J            b",
      "     J          ",
      "                ",
      "                ",
      "                ",
      "                ",
      "                ",
      "                ",
      "                ",
      "                ",
      "                ",
      "                ",
      "                "
    ],
    [
      "                ",
      "                ",
      "      b         ",
      "  b             ",
      "     b          ",
      "                ",
      "                ",
      "                ",
      "                ",
      "                ",
      "                ",
      "                ",
      "                ",
      "                ",
      "                ",
      "                "
    ],
    [
      "              qq",
      "                ",
      "                ",
      "  b             ",
      "     b          ",
      "                ",
      "                ",
      "                ",
      "                ",
      "                ",
      "                ",
      "                ",
      "                ",
      "                ",
      "                ",
      "                "
    ]
  ]
}