{
  "xsize": 16,
  "zsize": 16,
  "palette": {
    "palette": [
      {
        "char": " ",
        "block": "minecraft:air"
      },
      {
        "char": "l",
        "block": "minecraft:air"
      },
      {
        "char": "i",
        "block": "minecraft:air"
      },
      {
        "char": "d",
        "block": "minecraft:air"
      },
      {
        "char": "o",
        "block": "minecraft:air"
      },
      {
        "char": "j",
        "block": "minecraft:air"
      },
      {
        "char": "a",
        "block": "minecraft:air"
      },
      {
        "char": "A",
        "block": "minecraft:air"
      },
      {
        "char": "F",
        "block": "minecraft:air"
      },
      {
        "char": "y",
        "block": "minecraft:air"
      },
      {
        "char": "z",
        "block": "minecraft:air"
      },
      {
        "char": "E",
        "block": "minecraft:air"
      },
      {
        "char": "g",
        "block": "minecraft:grass"
      },
      {
        "char": "c",
        "block": "minecraft:air"
      },
      {
        "char": "Ό",
        "block": "minecraft:air"
      },
      {
        "char": "ʹ",
        "block": "minecraft:air"
      },
      {
        "char": "m",
        "block": "minecraft:air"
      },
      {
        "char": "Τ",
        "block": "minecraft:air"
      },
      {
        "char": "t",
        "block": "minecraft:grass"
      },
      {
        "char": "v",
        "block": "minecraft:air"
      },
      {
        "char": "Ͷ",
        "block": "minecraft:air"
      },
      {
        "char": "Ϧ",
        "block": "minecraft:air"
      },
      {
        "char": "θ",
        "block": "minecraft:air"
      },
      {
        "char": "1",
        "block": "minecraft:air"
      },
      {
        "char": "͵",
        "block": "minecraft:air"
      },
      {
        "char": "u",
        "block": "minecraft:tall_grass[half=upper]"
      },
      {
        "char": "Ϡ",
        "block": "minecraft:air"
      },
      {
        "char": "ζ",
        "block": "minecraft:air"
      },
      {
        "char": "Ύ",
        "block": "minecraft:air"
      },
      {
        "char": "Μ",
        "block": "minecraft:air"
      },
      {
        "char": "C",
        "block": "minecraft:air"
      },
      {
        "char": "0",
        "block": "minecraft:air",
        "tag": {
          "x": -565,
          "y": -55,
          "Items": [],
          "z": -1,
          "CookingTimes": [
            "I",
            0,
            0,
            0,
            0
          ],
          "CookingTotalTimes": [
            "I",
            0,
            0,
            0,
            0
          ],
          "id": "minecraft:campfire"
        }
      },
      {
        "char": "κ",
        "block": "minecraft:air"
      }
    ]
  },
  "slices": [
    [
      "llidlolldooodjdi",
      "ojilljdliiojlijd",
      "oljollddjjjjdjid",
      "dojliiijlojjjooo",
      "jdidlaaaiodjlioa",
      "djjllialliooojjj",
      "iidliilaijjlilji",
      "ldddjdilojdlldld",
      "jioiiljdjlddddll",
      "aaaaaaaaloolaljj",
      "aaaaaaaajjjljdjj",
      "aaaaaaaadiiiidij",
      "AFAAFFyAdjlddddo",
      "zAFyEAEyladljidl",
      "EyyyyEAzdjdjloij",
      "yFzyEyAyliaijlod"
    ],
    [
      "                ",
      "                ",
      "                ",
      "                ",
      "     ggg       g",
      "      g         ",
      "       g        ",
      "                ",
      "                ",
      "cccccccΌ    g   ",
      "gg  cggʹ        ",
      "cmgcgΤtc        ",
      "  vvͶͶ          ",
      " vv      g      ",
      "  Ϧ  θ          ",
      "          g     "
    ],
    [
      "                ",
      "                ",
      "                ",
      "                ",
      "                ",
      "                ",
      "                ",
      "                ",
      "                ",
      "1ccc11cc        ",
      "       c        ",
      " ͵   Τu         ",
      "                ",
      "                ",
      "                ",
      "                "
    ],
    [
      "                ",
      "                ",
      "                ",
      "                ",
      "                ",
      "                ",
      "                ",
      "                ",
      "                ",
      "                ",
      "                ",
      " ͵   c          ",
      "                ",
      "                ",
      "                ",
      "                "
    ],
    [
      "                ",
      "                ",
      "                ",
      "                ",
      "                ",
      "                ",
      "                ",
      "                ",
      "                ",
      "                ",
      "                ",
      " ͵  Ϡζc         ",
      "Ύc   c          ",
      "Μ               ",
      "                ",
      " c              "
    ],
    [
      "                ",
      "                ",
      "                ",
      "                ",
      "                ",
      "                ",
      "                ",
      "                ",
      "                ",
      "                ",
      "     c          ",
      "Cc  cΌc         ",
      " 0   κζ         ",
      " c              ",
      "c0              ",
      "Cc              "
    ]
  ]
}