{
  "xsize": 16,
  "zsize": 16,
  "palette": {
    "palette": [
      {
        "char": " ",
        "block": "minecraft:air"
      },
      {
        "char": "R",
        "block": "minecraft:rooted_dirt"
      },
      {
        "char": "P",
        "block": "minecraft:coarse_dirt"
      },
      {
        "char": "2",
        "block": "minecraft:podzol[snowy=false]"
      },
      {
        "char": "a",
        "block": "minecraft:grass_block[snowy=false]"
      },
      {
        "char": "i",
        "block": "minecraft:deepslate[axis=y]"
      },
      {
        "char": "k",
        "block": "minecraft:cobbled_deepslate"
      },
      {
        "char": "m",
        "block": "minecraft:cyan_terracotta"
      },
      {
        "char": "v",
        "block": "minecraft:blackstone"
      },
      {
        "char": "o",
        "block": "minecraft:basalt[axis=x]"
      },
      {
        "char": "b",
        "block": "minecraft:oak_leaves[distance=7,persistent=true,waterlogged=false]"
      },
      {
        "char": "ί",
        "block": "minecraft:air"
      },
      {
        "char": "Ϧ",
        "block": "minecraft:air"
      },
      {
        "char": "n",
        "block": "minecraft:air"
      },
      {
        "char": "j",
        "block": "minecraft:air"
      },
      {
        "char": "e",
        "block": "minecraft:air"
      },
      {
        "char": "J",
        "block": "minecraft:air"
      },
      {
        "char": "V",
        "block": "minecraft:air"
      },
      {
        "char": "Њ",
        "block": "minecraft:air"
      },
      {
        "char": "Ͱ",
        "block": "minecraft:air"
      },
      {
        "char": "t",
        "block": "minecraft:air"
      },
      {
        "char": "心",
        "block": "minecraft:air"
      },
      {
        "char": "十",
        "block": "minecraft:air"
      },
      {
        "char": "r",
        "block": "minecraft:air"
      },
      {
        "char": "ͳ",
        "block": "minecraft:oak_trapdoor[facing=south,half=top,open=false,powered=false,waterlogged=false]"
      },
      {
        "char": "q",
        "block": "minecraft:brick_slab[type=top,waterlogged=false,weathering=false]"
      }
    ]
  },
  "slices": [
    [
      "RP2PRaaaiikmmmki",
      "aaaaaaaakmmiiimi",
      "aaaaaaaavikkamoi",
      "aaaaaaaaakamvvoi",
      "aaaaaaaaakmkoiii",
      "iomokioioikmmami",
      "okavvoiiiiooiiii",
      "miimkomikvkkmvma",
      "ooaiokkvaimkmkoi",
      "immimokviikaavvi",
      "koiiiiomaioaivim",
      "avokiioaivmiviim",
      "iokvaoiikvkimoka",
      "vimkomkkivoakkoa",
      "mkkviookvmkmkami",
      "kkommmmvaoaimako"
    ],
    [
      "bbίbίϦnb    j   ",
      "nenJneeb   jjV  ",
      "eeeeЊͰnb    jtj ",
      "nbbnbnbbj t    j",
      "bnnbnnbnV     j ",
      "            tjtj",
      "  j      t     j",
      "   t   t j    jj",
      "  j     jjj  j  ",
      "t     tjjj tjjj ",
      "  jt   jt jj t  ",
      "jjj    jj     j ",
      " Vj j心  十  t  jj",
      " t   t t  jjjjjj",
      " jjj       t jt ",
      "  jjj   j j  j  "
    ],
    [
      "      r         ",
      "r rJr           ",
      "     Jr         ",
      "r  r rb         ",
      "     r r        ",
      "                ",
      "                ",
      "                ",
      "                ",
      "                ",
      "                ",
      "                ",
      "                ",
      "                ",
      "                ",
      "                "
    ],
    [
      "                ",
      "   b            ",
      "     J          ",
      "                ",
      "                ",
      "                ",
      "                ",
      "                ",
      "                ",
      "                ",
      "                ",
      "                ",
      "                ",
      "                ",
      "                ",
      "                "
    ],
    [
      " ͳͳ             ",
      "   b            ",
      "     b          ",
      "                ",
      "                ",
      "                ",
      "                ",
      "                ",
      "                ",
      "                ",
      "                ",
      "                ",
      "                ",
      "                ",
      "                ",
      "                "
    ],
    [
      "ͳͳͳͳqq          ",
      "                ",
      "     b          ",
      "                ",
      "                ",
      "                ",
      "                ",
      "                ",
      "                ",
      "                ",
      "                ",
      "                ",
      "                ",
      "                ",
      "                ",
      "                "
    ]
  ]
}