{
  "xsize": 16,
  "zsize": 16,
  "palette": {
    "palette": [
      {
        "char": " ",
        "block": "minecraft:air"
      },
      {
        "char": "e",
        "block": "minecraft:grass"
      },
      {
        "char": "C",
        "block": "minecraft:air"
      },
      {
        "char": "p",
        "block": "minecraft:air"
      },
      {
        "char": "u",
        "block": "minecraft:air"
      },
      {
        "char": "q",
        "block": "minecraft:air"
      },
      {
        "char": "μ",
        "block": "minecraft:air"
      },
      {
        "char": "f",
        "block": "minecraft:air"
      },
      {
        "char": "8",
        "block": "minecraft:air"
      },
      {
        "char": "M",
        "block": "minecraft:air"
      },
      {
        "char": "ή",
        "block": "minecraft:air"
      },
      {
        "char": "Ϗ",
        "block": "minecraft:air"
      },
      {
        "char": "Ψ",
        "block": "minecraft:air"
      },
      {
        "char": "B",
        "block": "minecraft:air"
      },
      {
        "char": "y",
        "block": "minecraft:air"
      },
      {
        "char": "1",
        "block": "minecraft:air"
      },
      {
        "char": "͵",
        "block": "minecraft:air"
      },
      {
        "char": "К",
        "block": "minecraft:air"
      },
      {
        "char": "δ",
        "block": "minecraft:air"
      },
      {
        "char": "ϙ",
        "block": "minecraft:air"
      },
      {
        "char": "ζ",
        "block": "minecraft:air"
      },
      {
        "char": ";",
        "block": "minecraft:air"
      },
      {
        "char": "Σ",
        "block": "minecraft:air"
      },
      {
        "char": "Π",
        "block": "minecraft:air"
      },
      {
        "char": "ʹ",
        "block": "minecraft:air"
      },
      {
        "char": "4",
        "block": "minecraft:air"
      },
      {
        "char": "J",
        "block": "minecraft:air"
      },
      {
        "char": "ͱ",
        "block": "minecraft:air"
      }
    ]
  },
  "slices": [
    [
      "    eC          ",
      "   eC       puq ",
      "     μpppppppuff",
      "    8Muuuuuuuuuu",
      "e ήM eqqfqqqqqqq",
      " ϏΨ   eB        ",
      "e   y qfqqqqqqqq",
      "    e uuuuuuuuuu",
      "   yC pppppppqq ",
      "          1͵pqq ",
      "          1͵pqq ",
      "          1͵pqq ",
      "          1͵puff",
      "          1͵puqp",
      "          1ККК1p",
      "               p"
    ],
    [
      "     eC         ",
      "              pu",
      "  yC δM       pq",
      " yy  ϙζy      pq",
      "    ; pppppppppu",
      "y δMμΨuuuuuuuuuu",
      "  ϙζ  pppppppppu",
      "    Cy        pu",
      "   eyC        pu",
      "              pu",
      "              pu",
      "              pu",
      "              pu",
      "              pu",
      "                ",
      "                "
    ],
    [
      "     C          ",
      "    Σ C         ",
      "  C ΠΣ          ",
      "  y ʹ C         ",
      " y  4 C C       ",
      "eC              ",
      "  Jey C         ",
      "  yyyy          ",
      "                ",
      "  ey            ",
      "                ",
      "                ",
      "                ",
      "                ",
      "                ",
      "                "
    ],
    [
      "                ",
      "   C            ",
      "                ",
      " C ͱΠ  y        ",
      "  yy C y        ",
      " y eCy          ",
      "y CCey          ",
      "CyC             ",
      "  y             ",
      "   y            ",
      "                ",
      "                ",
      "                ",
      "                ",
      "                ",
      "                "
    ],
    [
      "                ",
      "                ",
      "    yCC         ",
      "     e          ",
      "    y           ",
      "C  CC           ",
      " C y  e         ",
      " eC             ",
      " Ce e           ",
      "    y           ",
      "                ",
      "                ",
      "                ",
      "                ",
      "                ",
      "                "
    ],
    [
      "                ",
      "                ",
      "                ",
      "                ",
      "     y          ",
      " eyCe           ",
      "  y y           ",
      "   e e          ",
      "   yy           ",
      "                ",
      "                ",
      "                ",
      "                ",
      "                ",
      "                ",
      "                "
    ]
  ]
}