{
  "xsize": 16,
  "zsize": 16,
  "palette": {
    "palette": [
      {
        "char": " ",
        "block": "minecraft:air"
      },
      {
        "char": "c",
        "block": "minecraft:light_blue_terracotta"
      },
      {
        "char": "b",
        "block": "minecraft:oak_leaves[distance=7,persistent=true,waterlogged=false]"
      },
      {
        "char": "Щ",
        "block": "minecraft:air",
        "loot": "suburbanloot",
        "tag": {
          "ForgeData": {
            "LockFlag": "1b"
          },
          "x": -402,
          "y": -59,
          "Items": [],
          "z": -157,
          "id": "refurbished_furniture:drawer"
        }
      },
      {
        "char": "B",
        "block": "minecraft:stripped_oak_wood[axis=y]"
      },
      {
        "char": "G",
        "block": "minecraft:air"
      },
      {
        "char": "有",
        "block": "minecraft:air"
      },
      {
        "char": "ͺ",
        "block": "minecraft:spruce_button[face=floor,facing=west,powered=false]"
      },
      {
        "char": "к",
        "block": "minecraft:air",
        "loot": "suburbanloot",
        "tag": {
          "ForgeData": {
            "LockFlag": "1b"
          },
          "x": -400,
          "y": -55,
          "Items": [],
          "z": -185,
          "id": "refurbished_furniture:drawer"
        }
      },
      {
        "char": "ϟ",
        "block": "minecraft:spruce_trapdoor[facing=north,half=bottom,open=false,powered=false,waterlogged=false]"
      },
      {
        "char": "Ά",
        "block": "minecraft:spruce_button[face=floor,facing=south,powered=false]"
      },
      {
        "char": "Ҍ",
        "block": "minecraft:air"
      },
      {
        "char": "Ҷ",
        "block": "minecraft:air"
      },
      {
        "char": "只",
        "block": "minecraft:air"
      },
      {
        "char": "ә",
        "block": "minecraft:air"
      },
      {
        "char": "用",
        "block": "minecraft:air"
      },
      {
        "char": "D",
        "block": "minecraft:air"
      },
      {
        "char": "意",
        "block": "minecraft:air"
      },
      {
        "char": "ӈ",
        "block": "minecraft:air"
      },
      {
        "char": "工",
        "block": "minecraft:dark_oak_trapdoor[facing=west,half=top,open=true,powered=false,waterlogged=false]"
      },
      {
        "char": "Ґ",
        "block": "minecraft:dark_oak_trapdoor[facing=south,half=top,open=true,powered=false,waterlogged=false]"
      },
      {
        "char": "ͽ",
        "block": "minecraft:air"
      },
      {
        "char": "ύ",
        "block": "minecraft:oak_trapdoor[facing=south,half=top,open=true,powered=false,waterlogged=false]"
      },
      {
        "char": "d",
        "block": "minecraft:spruce_slab[type=top,waterlogged=false]"
      },
      {
        "char": "q",
        "block": "minecraft:brick_slab[type=top,waterlogged=false,weathering=false]"
      },
      {
        "char": "ͳ",
        "block": "minecraft:oak_trapdoor[facing=south,half=top,open=false,powered=false,waterlogged=false]"
      },
      {
        "char": "u",
        "block": "minecraft:brick_slab[type=double,waterlogged=false,weathering=false]"
      },
      {
        "char": "p",
        "block": "minecraft:brick_slab[type=bottom,waterlogged=false,weathering=false]"
      },
      {
        "char": "t",
        "block": "minecraft:air"
      }
    ]
  },
  "slices": [
    [
      "cb ЩBG          ",
      "有ͺ кc           ",
      "cϟΆbc           ",
      "ccҌcc           ",
      "cҶΆ只cG          ",
      "cә 用cG          ",
      "ccccB           ",
      " DD             ",
      "      b         ",
      "                ",
      "                ",
      "                ",
      "                ",
      "                ",
      "                ",
      "                "
    ],
    [
      "c   BG          ",
      "意   c           ",
      "c   cG          ",
      "ccӈccG          ",
      "c   c           ",
      "c   c           ",
      "ccccBG          ",
      "  D D           ",
      "                ",
      "                ",
      "                ",
      "                ",
      "                ",
      "                ",
      "                ",
      "                "
    ],
    [
      "c   B           ",
      "工   c           ",
      "c   cG          ",
      "ccҐcc           ",
      "c   c           ",
      "c   c           ",
      "ccͽcB           ",
      " ύ D            ",
      "                ",
      "                ",
      "                ",
      "                ",
      "                ",
      "                ",
      "                ",
      "                "
    ],
    [
      "cdddBq          ",
      "cdddcq          ",
      "cdddcq          ",
      "cccccq          ",
      "cdddcq          ",
      "cdddcq          ",
      "ccccBq          ",
      "ͳͳͳͳqq          ",
      "                ",
      "                ",
      "                ",
      "                ",
      "                ",
      "                ",
      "                ",
      "                "
    ],
    [
      "  qupt          ",
      "  qppt          ",
      "  qup           ",
      "  qppt          ",
      "  qpp           ",
      "  qup           ",
      "cccup           ",
      "  qup           ",
      "                ",
      "                ",
      "                ",
      "                ",
      "                ",
      "                ",
      "                ",
      "                "
    ],
    [
      "qu              ",
      "qup             ",
      "qupt            ",
      "qpp             ",
      "qp              ",
      "qp t            ",
      "cupt            ",
      "qup             ",
      "                ",
      "                ",
      "                ",
      "                ",
      "                ",
      "                ",
      "                ",
      "                "
    ]
  ]
}