{
  "xsize": 16,
  "zsize": 16,
  "palette": {
    "palette": [
      {
        "char": " ",
        "block": "minecraft:air"
      },
      {
        "char": "Ο",
        "block": "minecraft:air"
      },
      {
        "char": "g",
        "block": "minecraft:air"
      },
      {
        "char": "O",
        "block": "minecraft:air"
      },
      {
        "char": "b",
        "block": "minecraft:air"
      },
      {
        "char": "Ώ",
        "block": "minecraft:air"
      },
      {
        "char": "Ҹ",
        "block": "minecraft:air"
      },
      {
        "char": "J",
        "block": "minecraft:air"
      },
      {
        "char": "ψ",
        "block": "minecraft:air"
      },
      {
        "char": "ό",
        "block": "minecraft:air"
      },
      {
        "char": "Ϝ",
        "block": "minecraft:air"
      },
      {
        "char": "3",
        "block": "minecraft:air"
      },
      {
        "char": "Π",
        "block": "minecraft:air"
      },
      {
        "char": "4",
        "block": "minecraft:air"
      },
      {
        "char": "ʹ",
        "block": "minecraft:air"
      },
      {
        "char": "Ψ",
        "block": "minecraft:air"
      },
      {
        "char": ";",
        "block": "minecraft:air"
      },
      {
        "char": "C",
        "block": "minecraft:air"
      },
      {
        "char": "μ",
        "block": "minecraft:air"
      },
      {
        "char": "M",
        "block": "minecraft:air"
      },
      {
        "char": "ή",
        "block": "minecraft:air"
      },
      {
        "char": "y",
        "block": "minecraft:air"
      },
      {
        "char": "Χ",
        "block": "minecraft:air"
      },
      {
        "char": "в",
        "block": "minecraft:air"
      },
      {
        "char": "б",
        "block": "minecraft:air"
      },
      {
        "char": "ͱ",
        "block": "minecraft:air"
      },
      {
        "char": "δ",
        "block": "minecraft:air"
      },
      {
        "char": "Ђ",
        "block": "minecraft:air"
      },
      {
        "char": "ζ",
        "block": "minecraft:air"
      },
      {
        "char": "e",
        "block": "minecraft:grass"
      },
      {
        "char": "Ϲ",
        "block": "minecraft:air"
      },
      {
        "char": "z",
        "block": "minecraft:air"
      },
      {
        "char": "x",
        "block": "minecraft:air"
      },
      {
        "char": "ͷ",
        "block": "minecraft:air"
      },
      {
        "char": "s",
        "block": "minecraft:air"
      },
      {
        "char": "I",
        "block": "minecraft:air"
      },
      {
        "char": "w",
        "block": "minecraft:air"
      },
      {
        "char": "U",
        "block": "minecraft:air"
      }
    ]
  },
  "slices": [
    [
      "                ",
      "    Ο           ",
      "gO bΏb          ",
      "Ҹg  bJ          ",
      "bg              ",
      "ψg              ",
      "bg              ",
      "όg              ",
      "Ϝg              ",
      " g              ",
      "gO              ",
      "                ",
      "     3Π         ",
      "  43ʹ4ʹ         ",
      "  Ψ Ο; C        ",
      " ;μμMή y        "
    ],
    [
      "                ",
      "    b           ",
      "gO bJ           ",
      " g              ",
      " Χ              ",
      " g              ",
      "вб              ",
      " g              ",
      "вб              ",
      " g              ",
      "gO              ",
      "    yCC         ",
      "      ͱ         ",
      "    δЂ y        ",
      "  ΨήMζCe        ",
      "   Ψμe          "
    ],
    [
      "                ",
      "                ",
      "gO  b           ",
      " g              ",
      "вбϹ             ",
      " g              ",
      " ΧϹ             ",
      " g              ",
      "вбϹ             ",
      " g              ",
      "gO              ",
      "   y e          ",
      "  e  y y        ",
      "   C   y        ",
      "e 4 Jeyy        ",
      "  3  C          "
    ],
    [
      "                ",
      "zzz             ",
      "gOz             ",
      "xg              ",
      "xg              ",
      "xg              ",
      "xg              ",
      "xg              ",
      "xg              ",
      "xg              ",
      "gOz             ",
      "zzz y           ",
      "  yCy C         ",
      " ey C e         ",
      "     Cye        ",
      "y ͷ yC          "
    ],
    [
      "                ",
      "                ",
      "ssI             ",
      "wwU             ",
      " gz             ",
      " g              ",
      " g              ",
      " g              ",
      " gz             ",
      "wwU             ",
      "ssI             ",
      "                ",
      "                ",
      "     C          ",
      "   CyC          ",
      "    CCC         "
    ],
    [
      "                ",
      "                ",
      "                ",
      "                ",
      "ssI             ",
      "wwU             ",
      " gz             ",
      "wwU             ",
      "ssI             ",
      "                ",
      "                ",
      "                ",
      "                ",
      "                ",
      "    ye          ",
      "   e            "
    ]
  ]
}