{
  "xsize": 16,
  "zsize": 16,
  "palette": {
    "palette": [
      {
        "char": " ",
        "block": "minecraft:air"
      },
      {
        "char": "e",
        "block": "minecraft:air"
      },
      {
        "char": "C",
        "block": "minecraft:dark_oak_leaves[distance=7,persistent=false,waterlogged=false]"
      },
      {
        "char": "p",
        "block": "minecraft:brick_slab[type=bottom,waterlogged=false,weathering=false]"
      },
      {
        "char": "u",
        "block": "minecraft:brick_slab[type=double,waterlogged=false,weathering=false]"
      },
      {
        "char": "q",
        "block": "minecraft:brick_slab[type=top,waterlogged=false,weathering=false]"
      },
      {
        "char": "μ",
        "block": "minecraft:dark_oak_leaves[distance=1,persistent=false,waterlogged=false]"
      },
      {
        "char": "f",
        "block": "minecraft:pink_terracotta"
      },
      {
        "char": "8",
        "block": "minecraft:air"
      },
      {
        "char": "M",
        "block": "minecraft:oak_wood[axis=y]"
      },
      {
        "char": "ή",
        "block": "minecraft:oak_leaves[distance=1,persistent=false,waterlogged=false]"
      },
      {
        "char": "Ϗ",
        "block": "minecraft:dark_oak_leaves[distance=3,persistent=false,waterlogged=false]"
      },
      {
        "char": "Ψ",
        "block": "minecraft:oak_leaves[distance=2,persistent=false,waterlogged=false]"
      },
      {
        "char": "B",
        "block": "minecraft:stripped_oak_wood[axis=y]"
      },
      {
        "char": "y",
        "block": "minecraft:oak_leaves[distance=7,persistent=false,waterlogged=false]"
      },
      {
        "char": "1",
        "block": "minecraft:spruce_trapdoor[facing=west,half=bottom,open=false,powered=false,waterlogged=false]"
      },
      {
        "char": "͵",
        "block": "minecraft:spruce_slab[type=bottom,waterlogged=false]"
      },
      {
        "char": "К",
        "block": "minecraft:spruce_trapdoor[facing=south,half=bottom,open=false,powered=false,waterlogged=false]"
      },
      {
        "char": "δ",
        "block": "minecraft:air"
      },
      {
        "char": "ϙ",
        "block": "minecraft:air"
      },
      {
        "char": "ζ",
        "block": "minecraft:air"
      },
      {
        "char": ";",
        "block": "minecraft:dark_oak_leaves[distance=2,persistent=false,waterlogged=false]"
      },
      {
        "char": "Σ",
        "block": "minecraft:dark_oak_leaves[distance=6,persistent=false,waterlogged=false]"
      },
      {
        "char": "Π",
        "block": "minecraft:dark_oak_leaves[distance=5,persistent=false,waterlogged=false]"
      },
      {
        "char": "ʹ",
        "block": "minecraft:dark_oak_leaves[distance=4,persistent=false,waterlogged=false]"
      },
      {
        "char": "4",
        "block": "minecraft:oak_leaves[distance=3,persistent=false,waterlogged=false]"
      },
      {
        "char": "J",
        "block": "minecraft:air"
      },
      {
        "char": "ͱ",
        "block": "minecraft:oak_leaves[distance=6,persistent=false,waterlogged=false]"
      }
    ]
  },
  "slices": [
    [
      "    eC          ",
      "   eC       puq ",
      "     μpppppppuff",
      "    8Muuuuuuuuuu",
      "e ήM eqqfqqqqqqq",
      " ϏΨ   eB        ",
      "e   y qfqqqqqqqq",
      "    e uuuuuuuuuu",
      "   yC pppppppqq ",
      "          1͵pqq ",
      "          1͵pqq ",
      "          1͵pqq ",
      "          1͵puff",
      "          1͵puqp",
      "          1ККК1p",
      "               p"
    ],
    [
      "     eC         ",
      "              pu",
      "  yC δM       pq",
      " yy  ϙζy      pq",
      "    ; pppppppppu",
      "y δMμΨuuuuuuuuuu",
      "  ϙζ  pppppppppu",
      "    Cy        pu",
      "   eyC        pu",
      "              pu",
      "              pu",
      "              pu",
      "              pu",
      "              pu",
      "                ",
      "                "
    ],
    [
      "     C          ",
      "    Σ C         ",
      "  C ΠΣ          ",
      "  y ʹ C         ",
      " y  4 C C       ",
      "eC              ",
      "  Jey C         ",
      "  yyyy          ",
      "                ",
      "  ey            ",
      "                ",
      "                ",
      "                ",
      "                ",
      "                ",
      "                "
    ],
    [
      "                ",
      "   C            ",
      "                ",
      " C ͱΠ  y        ",
      "  yy C y        ",
      " y eCy          ",
      "y CCey          ",
      "CyC             ",
      "  y             ",
      "   y            ",
      "                ",
      "                ",
      "                ",
      "                ",
      "                ",
      "                "
    ],
    [
      "                ",
      "                ",
      "    yCC         ",
      "     e          ",
      "    y           ",
      "C  CC           ",
      " C y  e         ",
      " eC             ",
      " Ce e           ",
      "    y           ",
      "                ",
      "                ",
      "                ",
      "                ",
      "                ",
      "                "
    ],
    [
      "                ",
      "                ",
      "                ",
      "                ",
      "     y          ",
      " eyCe           ",
      "  y y           ",
      "   e e          ",
      "   yy           ",
      "                ",
      "                ",
      "                ",
      "                ",
      "                ",
      "                ",
      "                "
    ]
  ]
}