{
  "xsize": 16,
  "zsize": 16,
  "palette": {
    "palette": [
      {
        "char": " ",
        "block": "minecraft:structure_void"
      },
      {
        "char": "l",
        "block": "minecraft:cobbled_deepslate"
      },
      {
        "char": "i",
        "block": "minecraft:deepslate[axis=y]"
      },
      {
        "char": "d",
        "block": "minecraft:cyan_terracotta"
      },
      {
        "char": "o",
        "block": "minecraft:blackstone"
      },
      {
        "char": "j",
        "block": "minecraft:basalt[axis=x]"
      },
      {
        "char": "a",
        "block": "minecraft:grass_block[snowy=false]"
      },
      {
        "char": "A",
        "block": "minecraft:dead_bubble_coral_block"
      },
      {
        "char": "F",
        "block": "minecraft:cobblestone[weathering=false]"
      },
      {
        "char": "y",
        "block": "minecraft:stone[weathering=false]"
      },
      {
        "char": "z",
        "block": "minecraft:dead_fire_coral_block"
      },
      {
        "char": "E",
        "block": "minecraft:dead_brain_coral_block"
      },
      {
        "char": "g",
        "block": "minecraft:air"
      },
      {
        "char": "c",
        "block": "minecraft:oak_leaves[distance=7,persistent=true,waterlogged=false]"
      },
      {
        "char": "Ό",
        "block": "minecraft:air"
      },
      {
        "char": "ʹ",
        "block": "minecraft:air"
      },
      {
        "char": "m",
        "block": "minecraft:stone_bricks[weathering=false]"
      },
      {
        "char": "Τ",
        "block": "minecraft:air"
      },
      {
        "char": "t",
        "block": "minecraft:air"
      },
      {
        "char": "v",
        "block": "minecraft:air"
      },
      {
        "char": "Ͷ",
        "block": "minecraft:air"
      },
      {
        "char": "Ϧ",
        "block": "minecraft:air"
      },
      {
        "char": "θ",
        "block": "minecraft:air"
      },
      {
        "char": "1",
        "block": "minecraft:air"
      },
      {
        "char": "͵",
        "block": "minecraft:stone_brick_wall[east=none,north=none,south=none,up=true,waterlogged=false,weathering=false,west=none]"
      },
      {
        "char": "u",
        "block": "minecraft:air"
      },
      {
        "char": "Ϡ",
        "block": "minecraft:air"
      },
      {
        "char": "ζ",
        "block": "minecraft:air"
      },
      {
        "char": "Ύ",
        "block": "minecraft:spruce_trapdoor[facing=east,half=top,open=false,powered=false,waterlogged=false]"
      },
      {
        "char": "Μ",
        "block": "minecraft:spruce_trapdoor[facing=east,half=top,open=true,powered=false,waterlogged=false]"
      },
      {
        "char": "C",
        "block": "minecraft:spruce_trapdoor[facing=west,half=bottom,open=false,powered=false,waterlogged=false]"
      },
      {
        "char": "0",
        "block": "minecraft:campfire[facing=west,lit=false,signal_fire=false,waterlogged=false]",
        "tag": {
          "x": -565,
          "y": -55,
          "Items": [],
          "z": -1,
          "CookingTimes": [
            "I",
            0,
            0,
            0,
            0
          ],
          "CookingTotalTimes": [
            "I",
            0,
            0,
            0,
            0
          ],
          "id": "minecraft:campfire"
        }
      },
      {
        "char": "κ",
        "block": "minecraft:air"
      }
    ]
  },
  "slices": [
    [
      "llidlolldooodjdi",
      "ojilljdliiojlijd",
      "oljollddjjjjdjid",
      "dojliiijlojjjooo",
      "jdidlaaaiodjlioa",
      "djjllialliooojjj",
      "iidliilaijjlilji",
      "ldddjdilojdlldld",
      "jioiiljdjlddddll",
      "aaaaaaaaloolaljj",
      "aaaaaaaajjjljdjj",
      "aaaaaaaadiiiidij",
      "AFAAFFyAdjlddddo",
      "zAFyEAEyladljidl",
      "EyyyyEAzdjdjloij",
      "yFzyEyAyliaijlod"
    ],
    [
      "                ",
      "                ",
      "                ",
      "                ",
      "     ggg       g",
      "      g         ",
      "       g        ",
      "                ",
      "                ",
      "cccccccΌ    g   ",
      "gg  cggʹ        ",
      "cmgcgΤtc        ",
      "  vvͶͶ          ",
      " vv      g      ",
      "  Ϧ  θ          ",
      "          g     "
    ],
    [
      "                ",
      "                ",
      "                ",
      "                ",
      "                ",
      "                ",
      "                ",
      "                ",
      "                ",
      "1ccc11cc        ",
      "       c        ",
      " ͵   Τu         ",
      "                ",
      "                ",
      "                ",
      "                "
    ],
    [
      "                ",
      "                ",
      "                ",
      "                ",
      "                ",
      "                ",
      "                ",
      "                ",
      "                ",
      "                ",
      "                ",
      " ͵   c          ",
      "                ",
      "                ",
      "                ",
      "                "
    ],
    [
      "                ",
      "                ",
      "                ",
      "                ",
      "                ",
      "                ",
      "                ",
      "                ",
      "                ",
      "                ",
      "                ",
      " ͵  Ϡζc         ",
      "Ύc   c          ",
      "Μ               ",
      "                ",
      " c              "
    ],
    [
      "                ",
      "                ",
      "                ",
      "                ",
      "                ",
      "                ",
      "                ",
      "                ",
      "                ",
      "                ",
      "     c          ",
      "Cc  cΌc         ",
      " 0   κζ         ",
      " c              ",
      "c0              ",
      "Cc              "
    ]
  ]
}