{
  "xsize": 16,
  "zsize": 16,
  "palette": {
    "palette": [
      {
        "char": " ",
        "block": "minecraft:air"
      },
      {
        "char": "m",
        "block": "minecraft:cyan_terracotta"
      },
      {
        "char": "k",
        "block": "minecraft:cobbled_deepslate"
      },
      {
        "char": "i",
        "block": "minecraft:deepslate[axis=y]"
      },
      {
        "char": "a",
        "block": "minecraft:grass_block[snowy=false]"
      },
      {
        "char": "P",
        "block": "minecraft:coarse_dirt"
      },
      {
        "char": "v",
        "block": "minecraft:blackstone"
      },
      {
        "char": "o",
        "block": "minecraft:basalt[axis=x]"
      },
      {
        "char": "n",
        "block": "minecraft:air"
      },
      {
        "char": "e",
        "block": "minecraft:air"
      },
      {
        "char": "J",
        "block": "minecraft:air"
      },
      {
        "char": "ω",
        "block": "minecraft:air"
      },
      {
        "char": "ί",
        "block": "minecraft:air"
      },
      {
        "char": "b",
        "block": "minecraft:oak_leaves[distance=7,persistent=true,waterlogged=false]"
      },
      {
        "char": "Њ",
        "block": "minecraft:air"
      },
      {
        "char": "j",
        "block": "minecraft:air"
      },
      {
        "char": "t",
        "block": "minecraft:air"
      },
      {
        "char": "方",
        "block": "minecraft:air"
      },
      {
        "char": "论",
        "block": "minecraft:air"
      },
      {
        "char": "V",
        "block": "minecraft:air"
      },
      {
        "char": "r",
        "block": "minecraft:air"
      },
      {
        "char": "q",
        "block": "minecraft:brick_slab[type=top,waterlogged=false,weathering=false]"
      }
    ]
  },
  "slices": [
    [
      "mkmmkiimaaaaaaaP",
      "kiikkmiiaaaaaaaa",
      "aaaaaaaaaaaaaaaa",
      "aaaaaaaaaaaaaaaa",
      "aaaaaaaaaaaaaaaa",
      "kaikivkiimoikoao",
      "iiioikmoiakvkiim",
      "mmmviimoivmvioak",
      "mikkookomomikvki",
      "omkovaoiivkkviio",
      "mvaiokookikokvai",
      "vkikmvkkkkamkmiv",
      "vkvovkoivkmkkkmm",
      "kiiovimiikkmiivv",
      "kmikvikmomiimvao",
      "okvmooovimvoiaom"
    ],
    [
      "        neeJnnωί",
      "        beeee en",
      "beenneJneeЊeeeee",
      "bbJeeeebeeebeeeJ",
      "nbjbnbbnbbnbbbnb",
      " j     jjjjjjtj ",
      "j   tj  tj tj   ",
      " t jj   j     t ",
      "   t   t j  tjj ",
      "     t  方  论 jj ",
      " tj j j jj   jt ",
      "   jVV t jj t   ",
      "j  jt        jj ",
      "  t V t j t jjVt",
      "j      tVjj jVjj",
      "        jtjt j  "
    ],
    [
      "        r  Jrr  ",
      "               r",
      "      Jr        ",
      " bJ            b",
      "r   rJbr  r b r ",
      "                ",
      "                ",
      "                ",
      "                ",
      "                ",
      "                ",
      "                ",
      "                ",
      "                ",
      "                ",
      "                "
    ],
    [
      "           b    ",
      "                ",
      "      b         ",
      "  J            b",
      "     J          ",
      "                ",
      "                ",
      "                ",
      "                ",
      "                ",
      "                ",
      "                ",
      "                ",
      "                ",
      "                ",
      "                "
    ],
    [
      "                ",
      "                ",
      "      b         ",
      "  b             ",
      "     b          ",
      "                ",
      "                ",
      "                ",
      "                ",
      "                ",
      "                ",
      "                ",
      "                ",
      "                ",
      "                ",
      "                "
    ],
    [
      "              qq",
      "                ",
      "                ",
      "  b             ",
      "     b          ",
      "                ",
      "                ",
      "                ",
      "                ",
      "                ",
      "                ",
      "                ",
      "                ",
      "                ",
      "                ",
      "                "
    ]
  ]
}