{
  "xsize": 16,
  "zsize": 16,
  "palette": {
    "palette": [
      {
        "char": " ",
        "block": "minecraft:air"
      },
      {
        "char": "R",
        "block": "minecraft:air"
      },
      {
        "char": "P",
        "block": "minecraft:air"
      },
      {
        "char": "2",
        "block": "minecraft:air"
      },
      {
        "char": "a",
        "block": "minecraft:air"
      },
      {
        "char": "i",
        "block": "minecraft:air"
      },
      {
        "char": "k",
        "block": "minecraft:air"
      },
      {
        "char": "m",
        "block": "minecraft:air"
      },
      {
        "char": "v",
        "block": "minecraft:air"
      },
      {
        "char": "o",
        "block": "minecraft:air"
      },
      {
        "char": "b",
        "block": "minecraft:air"
      },
      {
        "char": "ί",
        "block": "minecraft:air"
      },
      {
        "char": "Ϧ",
        "block": "minecraft:air"
      },
      {
        "char": "n",
        "block": "minecraft:tall_grass[half=lower]"
      },
      {
        "char": "j",
        "block": "minecraft:air"
      },
      {
        "char": "e",
        "block": "minecraft:grass"
      },
      {
        "char": "J",
        "block": "minecraft:air"
      },
      {
        "char": "V",
        "block": "minecraft:air"
      },
      {
        "char": "Њ",
        "block": "minecraft:air"
      },
      {
        "char": "Ͱ",
        "block": "minecraft:air"
      },
      {
        "char": "t",
        "block": "minecraft:air"
      },
      {
        "char": "心",
        "block": "minecraft:air"
      },
      {
        "char": "十",
        "block": "minecraft:air"
      },
      {
        "char": "r",
        "block": "minecraft:tall_grass[half=upper]"
      },
      {
        "char": "ͳ",
        "block": "minecraft:air"
      },
      {
        "char": "q",
        "block": "minecraft:air"
      }
    ]
  },
  "slices": [
    [
      "RP2PRaaaiikmmmki",
      "aaaaaaaakmmiiimi",
      "aaaaaaaavikkamoi",
      "aaaaaaaaakamvvoi",
      "aaaaaaaaakmkoiii",
      "iomokioioikmmami",
      "okavvoiiiiooiiii",
      "miimkomikvkkmvma",
      "ooaiokkvaimkmkoi",
      "immimokviikaavvi",
      "koiiiiomaioaivim",
      "avokiioaivmiviim",
      "iokvaoiikvkimoka",
      "vimkomkkivoakkoa",
      "mkkviookvmkmkami",
      "kkommmmvaoaimako"
    ],
    [
      "bbίbίϦnb    j   ",
      "nenJneeb   jjV  ",
      "eeeeЊͰnb    jtj ",
      "nbbnbnbbj t    j",
      "bnnbnnbnV     j ",
      "            tjtj",
      "  j      t     j",
      "   t   t j    jj",
      "  j     jjj  j  ",
      "t     tjjj tjjj ",
      "  jt   jt jj t  ",
      "jjj    jj     j ",
      " Vj j心  十  t  jj",
      " t   t t  jjjjjj",
      " jjj       t jt ",
      "  jjj   j j  j  "
    ],
    [
      "      r         ",
      "r rJr           ",
      "     Jr         ",
      "r  r rb         ",
      "     r r        ",
      "                ",
      "                ",
      "                ",
      "                ",
      "                ",
      "                ",
      "                ",
      "                ",
      "                ",
      "                ",
      "                "
    ],
    [
      "                ",
      "   b            ",
      "     J          ",
      "                ",
      "                ",
      "                ",
      "                ",
      "                ",
      "                ",
      "                ",
      "                ",
      "                ",
      "                ",
      "                ",
      "                ",
      "                "
    ],
    [
      " ͳͳ             ",
      "   b            ",
      "     b          ",
      "                ",
      "                ",
      "                ",
      "                ",
      "                ",
      "                ",
      "                ",
      "                ",
      "                ",
      "                ",
      "                ",
      "                ",
      "                "
    ],
    [
      "ͳͳͳͳqq          ",
      "                ",
      "     b          ",
      "                ",
      "                ",
      "                ",
      "                ",
      "                ",
      "                ",
      "                ",
      "                ",
      "                ",
      "                ",
      "                ",
      "                ",
      "                "
    ]
  ]
}