{
  "xsize": 16,
  "zsize": 16,
  "palette": {
    "palette": [
      {
        "char": " ",
        "block": "minecraft:air"
      },
      {
        "char": "y",
        "block": "minecraft:air"
      },
      {
        "char": "s",
        "block": "minecraft:air"
      },
      {
        "char": "w",
        "block": "minecraft:air"
      },
      {
        "char": "H",
        "block": "minecraft:air"
      },
      {
        "char": "C",
        "block": "minecraft:air"
      },
      {
        "char": "3",
        "block": "minecraft:air"
      },
      {
        "char": "e",
        "block": "minecraft:grass"
      },
      {
        "char": "ʹ",
        "block": "minecraft:air"
      },
      {
        "char": "X",
        "block": "minecraft:air"
      },
      {
        "char": "M",
        "block": "minecraft:air"
      },
      {
        "char": "Е",
        "block": "minecraft:air"
      },
      {
        "char": "ή",
        "block": "minecraft:air"
      },
      {
        "char": "Ψ",
        "block": "minecraft:air"
      },
      {
        "char": "对",
        "block": "minecraft:air"
      },
      {
        "char": "҄",
        "block": "minecraft:air"
      },
      {
        "char": "4",
        "block": "minecraft:air"
      },
      {
        "char": "ͷ",
        "block": "minecraft:air"
      },
      {
        "char": "f",
        "block": "minecraft:air"
      },
      {
        "char": "I",
        "block": "minecraft:air"
      },
      {
        "char": "U",
        "block": "minecraft:air"
      },
      {
        "char": "z",
        "block": "minecraft:air"
      },
      {
        "char": "D",
        "block": "minecraft:air"
      },
      {
        "char": ";",
        "block": "minecraft:air"
      },
      {
        "char": "я",
        "block": "minecraft:air"
      },
      {
        "char": "μ",
        "block": "minecraft:air"
      },
      {
        "char": "Ϗ",
        "block": "minecraft:air"
      },
      {
        "char": "ͱ",
        "block": "minecraft:air"
      },
      {
        "char": "ϧ",
        "block": "minecraft:air"
      },
      {
        "char": "Σ",
        "block": "minecraft:air"
      },
      {
        "char": "Ѧ",
        "block": "minecraft:air"
      },
      {
        "char": "Π",
        "block": "minecraft:air"
      },
      {
        "char": "л",
        "block": "minecraft:air"
      }
    ]
  },
  "slices": [
    [
      "   yy swH      H",
      "  Cy  swH      H",
      "   yC swH      H",
      "y 3 eyswH      H",
      " ʹ XM swH      H",
      "  ЕMήΨswH      H",
      "  对҄Ψ4swH      H",
      "  ͷ3  swH      H",
      "    yyswH      H",
      "    C swffffffff",
      "    C IUz  DD  z",
      "                ",
      "                ",
      "                ",
      "                ",
      "                "
    ],
    [
      "   y yy swH  Hws",
      "     e yswH  Hws",
      "e 3  y  swH  Hws",
      " 34;яy  swH  Hws",
      " 4;ήM ʹ swH  Hws",
      " ;μμμΨ4 swH  Hws",
      " ήM  Ϗʹ swH  Hww",
      "y  4    swH  Hws",
      "      C swH  Hws",
      "    y e swffffws",
      "   Cy   IUzD zUI",
      "                ",
      "                ",
      "                ",
      "                ",
      "                "
    ],
    [
      "    C y   swws  ",
      "y 3 yyy   swws  ",
      "  4Ψ    C swws  ",
      "ͷ ;ήM ͱy  swws  ",
      "  4;ϧΣͷͱy swws  ",
      "y       e swws  ",
      " ѦMή 3ͷ   swws  ",
      " yϧ;  ͱ C swws  ",
      " yΣ ͱy    swws  ",
      "     y    swws  ",
      "   C      IUUI  ",
      "                ",
      "                ",
      "                ",
      "                ",
      "                "
    ],
    [
      "  y  y          ",
      " y  e Cy        ",
      "Π    y  y       ",
      "34;ήM yy        ",
      "      ͱ         ",
      " yΣ   y         ",
      "  лΨ   Cy       ",
      "yy 43ͷ yC       ",
      " Σͷ3Π CC        ",
      " C ͷΣ e         ",
      "   ͱ y          ",
      "                ",
      "                ",
      "                ",
      "                ",
      "                "
    ],
    [
      "   Πͱy          ",
      "  ͷ3  yy        ",
      " ͷ3Ϗ y C        ",
      "   Ψ Cyy        ",
      " C   yy         ",
      " ͱΠ ͷ yC        ",
      "  343 y         ",
      " y              ",
      "     y          ",
      "    yy          ",
      "                ",
      "                ",
      "                ",
      "                ",
      "                ",
      "                "
    ],
    [
      "   ͱ            ",
      "    ye          ",
      "   3  e         ",
      " Π3Ϗʹ ye        ",
      "  Π3ͷ C         ",
      "  ͱͷΣ           ",
      "   3ͷ y         ",
      "    ͱ  C        ",
      "  y  e          ",
      "                ",
      "                ",
      "                ",
      "                ",
      "                ",
      "                ",
      "                "
    ]
  ]
}