{
  "xsize": 16,
  "zsize": 16,
  "palette": {
    "palette": [
      {
        "char": " ",
        "block": "minecraft:air"
      },
      {
        "char": "r",
        "block": "minecraft:air"
      },
      {
        "char": "t",
        "block": "minecraft:air"
      },
      {
        "char": "q",
        "block": "minecraft:air"
      },
      {
        "char": "u",
        "block": "minecraft:air"
      },
      {
        "char": "s",
        "block": "minecraft:air"
      },
      {
        "char": "o",
        "block": "minecraft:air"
      },
      {
        "char": "m",
        "block": "minecraft:air"
      },
      {
        "char": "j",
        "block": "minecraft:air"
      },
      {
        "char": "w",
        "block": "minecraft:air"
      },
      {
        "char": "b",
        "block": "minecraft:air"
      },
      {
        "char": "a",
        "block": "minecraft:air"
      },
      {
        "char": "c",
        "block": "minecraft:air"
      },
      {
        "char": "i",
        "block": "minecraft:air"
      },
      {
        "char": "L",
        "block": "minecraft:air"
      },
      {
        "char": "p",
        "block": "minecraft:grass"
      },
      {
        "char": "f",
        "block": "minecraft:air"
      },
      {
        "char": "k",
        "block": "minecraft:air"
      },
      {
        "char": "Ш",
        "block": "minecraft:air"
      },
      {
        "char": "ϻ",
        "block": "minecraft:air"
      },
      {
        "char": "M",
        "block": "minecraft:air"
      },
      {
        "char": "ͽ",
        "block": "minecraft:air"
      },
      {
        "char": "D",
        "block": "minecraft:air"
      },
      {
        "char": "ϣ",
        "block": "minecraft:air"
      },
      {
        "char": "K",
        "block": "minecraft:air"
      },
      {
        "char": "Ϸ",
        "block": "minecraft:air"
      },
      {
        "char": "g",
        "block": "minecraft:air"
      },
      {
        "char": "Δ",
        "block": "minecraft:air"
      },
      {
        "char": "d",
        "block": "minecraft:air"
      },
      {
        "char": "μ",
        "block": "minecraft:air"
      },
      {
        "char": "h",
        "block": "minecraft:air"
      },
      {
        "char": "z",
        "block": "minecraft:air"
      },
      {
        "char": "n",
        "block": "minecraft:air"
      }
    ]
  },
  "slices": [
    [
      "rrttqtursttuturu",
      "urrssuuqqstursus",
      "rsquuqtqqtrqrqtr",
      "tsstsuqqtrqrtrqs",
      "rqqqrsustsrttrtu",
      "oooooooooooousus",
      "oooooooooooorqst",
      "ooooooooooooqtqr",
      "mjwwwwwwwoooqqqs",
      "bacaccbiwooostur",
      "cmjccbbcwooosurq",
      "ccmbabbawoooqrsr",
      "bjaacacmwoootssq",
      "LLLjcaacwoooqqsu",
      "iLjLibbbwoooqrqu",
      "iiccmmjbwoooqurt"
    ],
    [
      "                ",
      "                ",
      "                ",
      "                ",
      "                ",
      " pp pppp pp     ",
      "fpkkpppppppp    ",
      "ppppppШkpppp    ",
      "iϻacicaaiMpp    ",
      "       ͽaM p    ",
      "D   ͽ   cMϣp    ",
      "  ͽ   ͽ cMp     ",
      "K     ͽDcMp     ",
      "bDmKͽ ͽ aMp     ",
      "ajcmD   bMp     ",
      "cacm Dͽ cMpp    "
    ],
    [
      "                ",
      "                ",
      "                ",
      "                ",
      "                ",
      "                ",
      "fkkk            ",
      "k     kkk       ",
      "aϷagcgcΔbd      ",
      "       ͽμd      ",
      "        bd      ",
      "      ͽ hd      ",
      "        cdd     ",
      "z       hdd     ",
      "iDm     a       ",
      "biD   ͽ h       "
    ],
    [
      "                ",
      "                ",
      "                ",
      "                ",
      "                ",
      "                ",
      "fkkk            ",
      "k     kkk       ",
      "ncbgmgjgad      ",
      "        hd      ",
      "        jd      ",
      "        hd      ",
      "        add     ",
      "        hdd     ",
      "        a       ",
      "        h       "
    ],
    [
      "                ",
      "                ",
      "                ",
      "                ",
      "                ",
      "                ",
      "fkkk            ",
      "k     kkk       ",
      "bacajanjjd      ",
      "        ad      ",
      "        cd      ",
      "        ad      ",
      "        ndd     ",
      "        ndd     ",
      "        i       ",
      "        m       "
    ],
    [
      "                ",
      "                ",
      "                ",
      "                ",
      "                ",
      "                ",
      "fkkk            ",
      "k     kkk       ",
      "cgigcgmgad      ",
      "        hd      ",
      "        bd      ",
      "        hd      ",
      "        add     ",
      "        hdd     ",
      "        m       ",
      "        h       "
    ]
  ]
}