{
  "xsize": 16,
  "zsize": 16,
  "palette": {
    "palette": [
      {
        "char": " ",
        "block": "minecraft:air"
      },
      {
        "char": "a",
        "block": "minecraft:mossy_cobblestone"
      },
      {
        "char": "h",
        "block": "minecraft:glass_pane[east=false,north=true,south=true,waterlogged=false,west=false]"
      },
      {
        "char": "i",
        "block": "minecraft:cobblestone[weathering=false]"
      },
      {
        "char": "n",
        "block": "minecraft:air"
      },
      {
        "char": "d",
        "block": "minecraft:vine[east=false,north=false,south=false,up=false,west=true]"
      },
      {
        "char": "b",
        "block": "minecraft:mossy_stone_bricks"
      },
      {
        "char": "g",
        "block": "minecraft:glass_pane[east=true,north=false,south=false,waterlogged=false,west=true]"
      },
      {
        "char": "m",
        "block": "minecraft:stone_bricks[weathering=false]"
      },
      {
        "char": "e",
        "block": "minecraft:vine[east=false,north=true,south=false,up=false,west=false]"
      },
      {
        "char": "j",
        "block": "minecraft:stone[weathering=false]"
      },
      {
        "char": "c",
        "block": "minecraft:cracked_stone_bricks"
      },
      {
        "char": "Θ",
        "block": "minecraft:air"
      },
      {
        "char": "Γ",
        "block": "minecraft:air"
      },
      {
        "char": "v",
        "block": "minecraft:light_gray_concrete"
      },
      {
        "char": "Ϳ",
        "block": "minecraft:birch_slab[type=top,waterlogged=false]"
      },
      {
        "char": "Ϛ",
        "block": "minecraft:spruce_stairs[facing=north,half=top,shape=straight,waterlogged=false]"
      },
      {
        "char": "C",
        "block": "minecraft:spruce_slab[type=top,waterlogged=false]"
      },
      {
        "char": "ϔ",
        "block": "minecraft:oak_stairs[facing=east,half=bottom,shape=straight,waterlogged=false]"
      },
      {
        "char": "Ѓ",
        "block": "minecraft:spruce_stairs[facing=south,half=bottom,shape=outer_right,waterlogged=false]"
      },
      {
        "char": "ϙ",
        "block": "minecraft:spruce_stairs[facing=south,half=top,shape=straight,waterlogged=false]"
      },
      {
        "char": "Ϯ",
        "block": "minecraft:spruce_stairs[facing=west,half=bottom,shape=straight,waterlogged=false]"
      },
      {
        "char": "Г",
        "block": "minecraft:spruce_stairs[facing=south,half=bottom,shape=inner_right,waterlogged=false]"
      },
      {
        "char": "ϛ",
        "block": "minecraft:spruce_stairs[facing=south,half=bottom,shape=straight,waterlogged=false]"
      },
      {
        "char": "Ђ",
        "block": "minecraft:spruce_stairs[facing=west,half=bottom,shape=outer_left,waterlogged=false]"
      },
      {
        "char": "Φ",
        "block": "minecraft:glass_pane[east=true,north=true,south=false,waterlogged=false,west=true]"
      },
      {
        "char": "ϫ",
        "block": "minecraft:flower_pot"
      },
      {
        "char": "Ψ",
        "block": "minecraft:heavy_weighted_pressure_plate[power=0]"
      }
    ]
  },
  "slices": [
    [
      "        a       ",
      "        h       ",
      "        i       ",
      "        h       ",
      "        nd      ",
      "        hd      ",
      "        bd      ",
      "        hd      ",
      "ngagigmgbd      ",
      "ee     ee       ",
      "                ",
      "                ",
      "                ",
      "                ",
      "                ",
      "                "
    ],
    [
      "   bjcabc       ",
      "   bjcbcj       ",
      "  Θccbjba       ",
      " Γbiabajj       ",
      "jcajinbabd      ",
      "bbijbaicbd      ",
      "aaniabjbad      ",
      "jccaibaaad      ",
      "ncbaciabad      ",
      "ee     ee       ",
      "                ",
      "                ",
      "                ",
      "                ",
      "                ",
      "                "
    ],
    [
      "   vvvvvc       ",
      "    ͿͿ  h       ",
      "        b       ",
      "     Ϛ  h       ",
      "v    Cϔ bd      ",
      "vЃ   ϙ  hd      ",
      "vϮ      md      ",
      "vГϛЂ    hd      ",
      "aΦbgcgagad      ",
      "ee     ee       ",
      "                ",
      "                ",
      "                ",
      "                ",
      "                ",
      "                "
    ],
    [
      "    vvvvb       ",
      "    ϫ   h       ",
      "        b       ",
      "        h       ",
      "     Ψ  b       ",
      "v       hd      ",
      "v       cd      ",
      "v       hd      ",
      "mgmgagbgcd      ",
      "ee     ee       ",
      "                ",
      "                ",
      "                ",
      "                ",
      "                ",
      "                "
    ],
    [
      "        a       ",
      "        b       ",
      "        c       ",
      "        a       ",
      "        n       ",
      "        bd      ",
      "        ad      ",
      "        cd      ",
      "jcbbbjibjd      ",
      "ee     ee       ",
      "                ",
      "                ",
      "                ",
      "                ",
      "                ",
      "                "
    ],
    [
      "        c       ",
      "        h       ",
      "        m       ",
      "        h       ",
      "        i       ",
      "        hd      ",
      "        id      ",
      "        hd      ",
      "jgjgagjgad      ",
      "ee     ee       ",
      "                ",
      "                ",
      "                ",
      "                ",
      "                ",
      "                "
    ]
  ]
}