{
  "xsize": 16,
  "zsize": 16,
  "palette": {
    "palette": [
      {
        "char": " ",
        "block": "minecraft:air"
      },
      {
        "char": "b",
        "block": "minecraft:mossy_stone_bricks"
      },
      {
        "char": "h",
        "block": "minecraft:glass_pane[east=false,north=true,south=true,waterlogged=false,west=false]"
      },
      {
        "char": "c",
        "block": "minecraft:cracked_stone_bricks"
      },
      {
        "char": "j",
        "block": "minecraft:stone[weathering=false]"
      },
      {
        "char": "d",
        "block": "minecraft:vine[east=false,north=false,south=false,up=false,west=true]"
      },
      {
        "char": "l",
        "block": "minecraft:oak_leaves[distance=7,persistent=true,waterlogged=false]"
      },
      {
        "char": "i",
        "block": "minecraft:cobblestone[weathering=false]"
      },
      {
        "char": "g",
        "block": "minecraft:glass_pane[east=true,north=false,south=false,waterlogged=false,west=true]"
      },
      {
        "char": "m",
        "block": "minecraft:stone_bricks[weathering=false]"
      },
      {
        "char": "a",
        "block": "minecraft:mossy_cobblestone"
      },
      {
        "char": "e",
        "block": "minecraft:vine[east=false,north=true,south=false,up=false,west=false]"
      },
      {
        "char": "n",
        "block": "minecraft:air"
      },
      {
        "char": "y",
        "block": "minecraft:stone_slab[type=top,waterlogged=false,weathering=false]"
      },
      {
        "char": "v",
        "block": "minecraft:light_gray_concrete"
      },
      {
        "char": "Ϳ",
        "block": "minecraft:birch_slab[type=top,waterlogged=false]"
      },
      {
        "char": "Ϛ",
        "block": "minecraft:spruce_stairs[facing=north,half=top,shape=straight,waterlogged=false]"
      },
      {
        "char": "C",
        "block": "minecraft:spruce_slab[type=top,waterlogged=false]"
      },
      {
        "char": "ϔ",
        "block": "minecraft:oak_stairs[facing=east,half=bottom,shape=straight,waterlogged=false]"
      },
      {
        "char": "Ѓ",
        "block": "minecraft:spruce_stairs[facing=south,half=bottom,shape=outer_right,waterlogged=false]"
      },
      {
        "char": "ϙ",
        "block": "minecraft:spruce_stairs[facing=south,half=top,shape=straight,waterlogged=false]"
      },
      {
        "char": "Ϯ",
        "block": "minecraft:spruce_stairs[facing=west,half=bottom,shape=straight,waterlogged=false]"
      },
      {
        "char": "Г",
        "block": "minecraft:spruce_stairs[facing=south,half=bottom,shape=inner_right,waterlogged=false]"
      },
      {
        "char": "ϛ",
        "block": "minecraft:spruce_stairs[facing=south,half=bottom,shape=straight,waterlogged=false]"
      },
      {
        "char": "Ђ",
        "block": "minecraft:spruce_stairs[facing=west,half=bottom,shape=outer_left,waterlogged=false]"
      },
      {
        "char": "Φ",
        "block": "minecraft:glass_pane[east=true,north=true,south=false,waterlogged=false,west=true]"
      },
      {
        "char": "ϳ",
        "block": "minecraft:potted_wither_rose"
      },
      {
        "char": "Ψ",
        "block": "minecraft:heavy_weighted_pressure_plate[power=0]"
      },
      {
        "char": "ϫ",
        "block": "minecraft:flower_pot"
      }
    ]
  },
  "slices": [
    [
      "        b       ",
      "        h       ",
      "        c       ",
      "        h       ",
      "        j       ",
      "        hd      ",
      "     ll id      ",
      "    lll hd      ",
      "cgjgmgagbd      ",
      "ee     ee       ",
      "                ",
      "                ",
      "                ",
      "                ",
      "                ",
      "                "
    ],
    [
      "    iamnn       ",
      "  yycibbb       ",
      "    aambm       ",
      " yijbbbbm       ",
      "iiiabbajc       ",
      "mabbnbiibd      ",
      "jbaccllcad      ",
      "ijaccllind      ",
      "ccnanbbibd      ",
      "ee     ee       ",
      "                ",
      "                ",
      "                ",
      "                ",
      "                ",
      "                "
    ],
    [
      "    vvvva       ",
      "    ͿͿ  h       ",
      "        a       ",
      "     Ϛ  h       ",
      "v    Cϔ i       ",
      "vЃ   ϙ  hd      ",
      "vϮ    llbd      ",
      "vГϛЂ lllhd      ",
      "iΦbgbgcgmd      ",
      "ee     ee       ",
      "                ",
      "                ",
      "                ",
      "                ",
      "                ",
      "                "
    ],
    [
      "     vvvc       ",
      "    ϳ   h       ",
      "        m       ",
      "        h       ",
      "     Ψ  c       ",
      "v    ϫ  hd      ",
      "v      lcd      ",
      "v       hd      ",
      "bgigjgagbd      ",
      "ee     ee       ",
      "                ",
      "                ",
      "                ",
      "                ",
      "                ",
      "                "
    ],
    [
      "        j       ",
      "        i       ",
      "        b       ",
      "        i       ",
      "        b       ",
      "        bd      ",
      "       lad      ",
      "       lcd      ",
      "cnbicbjjbd      ",
      "ee     ee       ",
      "                ",
      "                ",
      "                ",
      "                ",
      "                ",
      "                "
    ],
    [
      "        j       ",
      "       lh       ",
      "      llb       ",
      "      llh       ",
      "       lc       ",
      "      llhd      ",
      "      llad      ",
      "       lhd      ",
      "bgmgcgbgcd      ",
      "ee     ee       ",
      "                ",
      "                ",
      "                ",
      "                ",
      "                ",
      "                "
    ]
  ]
}