{
  "xsize": 16,
  "zsize": 16,
  "palette": {
    "palette": [
      {
        "char": " ",
        "block": "minecraft:air"
      },
      {
        "char": "k",
        "block": "minecraft:vine[east=false,north=false,south=true,up=false,west=false]"
      },
      {
        "char": "f",
        "block": "minecraft:vine[east=true,north=false,south=false,up=false,west=false]"
      },
      {
        "char": "b",
        "block": "minecraft:mossy_stone_bricks"
      },
      {
        "char": "g",
        "block": "minecraft:glass_pane[east=true,north=false,south=false,waterlogged=false,west=true]"
      },
      {
        "char": "a",
        "block": "minecraft:mossy_cobblestone"
      },
      {
        "char": "h",
        "block": "minecraft:glass_pane[east=false,north=true,south=true,waterlogged=false,west=false]"
      },
      {
        "char": "j",
        "block": "minecraft:stone[weathering=false]"
      },
      {
        "char": "m",
        "block": "minecraft:stone_bricks[weathering=false]"
      },
      {
        "char": "c",
        "block": "minecraft:cracked_stone_bricks"
      },
      {
        "char": "n",
        "block": "minecraft:air"
      },
      {
        "char": "i",
        "block": "minecraft:cobblestone[weathering=false]"
      },
      {
        "char": "Γ",
        "block": "minecraft:air"
      },
      {
        "char": "Δ",
        "block": "minecraft:glass_pane[east=true,north=false,south=true,waterlogged=false,west=true]"
      },
      {
        "char": "Я",
        "block": "minecraft:spruce_stairs[facing=east,half=bottom,shape=outer_left,waterlogged=false]"
      },
      {
        "char": "Ϡ",
        "block": "minecraft:spruce_stairs[facing=north,half=bottom,shape=inner_right,waterlogged=false]"
      },
      {
        "char": "Ј",
        "block": "minecraft:spruce_stairs[facing=east,half=bottom,shape=straight,waterlogged=false]"
      },
      {
        "char": "Ϛ",
        "block": "minecraft:spruce_stairs[facing=north,half=top,shape=straight,waterlogged=false]"
      },
      {
        "char": "в",
        "block": "minecraft:spruce_stairs[facing=north,half=bottom,shape=outer_right,waterlogged=false]"
      },
      {
        "char": "Χ",
        "block": "minecraft:oak_stairs[facing=west,half=bottom,shape=straight,waterlogged=false]"
      },
      {
        "char": "C",
        "block": "minecraft:spruce_slab[type=top,waterlogged=false]"
      },
      {
        "char": "ϙ",
        "block": "minecraft:spruce_stairs[facing=south,half=top,shape=straight,waterlogged=false]"
      },
      {
        "char": "Ϳ",
        "block": "minecraft:birch_slab[type=top,waterlogged=false]"
      },
      {
        "char": "Ψ",
        "block": "minecraft:heavy_weighted_pressure_plate[power=0]"
      },
      {
        "char": "ϳ",
        "block": "minecraft:potted_wither_rose"
      }
    ]
  },
  "slices": [
    [
      "                ",
      "                ",
      "                ",
      "                ",
      "                ",
      "                ",
      "              k ",
      "          kkkkk ",
      "       fbgagbgag",
      "       fh       ",
      "       fa       ",
      "        h       ",
      "        j       ",
      "        h       ",
      "        a       ",
      "        h       "
    ],
    [
      "                ",
      "                ",
      "                ",
      "                ",
      "                ",
      "                ",
      "              k ",
      "          kkkkk ",
      "       faaamccaa",
      "       fnjibmaii",
      "       fcnabbbci",
      "        ncbabiic",
      "        ajmjbijm",
      "        bccjcc j",
      "        iccicaΓ ",
      "        majaic  "
    ],
    [
      "                ",
      "                ",
      "                ",
      "                ",
      "                ",
      "                ",
      "              k ",
      "          kkkkk ",
      "       fagbgbgaΔ",
      "       fh     ЯϠ",
      "       fc      Ј",
      "        h  Ϛ   в",
      "        b ΧC    ",
      "        h  ϙ    ",
      "        m       ",
      "        h   Ϳ   "
    ],
    [
      "                ",
      "                ",
      "                ",
      "                ",
      "                ",
      "                ",
      "              k ",
      "          kkkkk ",
      "       fagmgcgag",
      "       fh       ",
      "       fa       ",
      "        h       ",
      "        i  Ψ    ",
      "        h       ",
      "        i       ",
      "        h   ϳ   "
    ],
    [
      "                ",
      "                ",
      "                ",
      "                ",
      "                ",
      "                ",
      "              k ",
      "          kkkkk ",
      "       fbmjccnjj",
      "       fm       ",
      "       fc       ",
      "        i       ",
      "        c       ",
      "        i       ",
      "        i       ",
      "        c       "
    ],
    [
      "                ",
      "                ",
      "                ",
      "                ",
      "                ",
      "                ",
      "              k ",
      "          kkkkk ",
      "       fjgigngcg",
      "       fh       ",
      "       fa       ",
      "        h       ",
      "        b       ",
      "        h       ",
      "        c       ",
      "        h       "
    ]
  ]
}