{
  "xsize": 16,
  "zsize": 16,
  "palette": {
    "palette": [
      {
        "char": " ",
        "block": "minecraft:air"
      },
      {
        "char": "c",
        "block": "minecraft:cracked_stone_bricks"
      },
      {
        "char": "h",
        "block": "minecraft:glass_pane[east=false,north=true,south=true,waterlogged=false,west=false]"
      },
      {
        "char": "a",
        "block": "minecraft:mossy_cobblestone"
      },
      {
        "char": "d",
        "block": "minecraft:vine[east=false,north=false,south=false,up=false,west=true]"
      },
      {
        "char": "n",
        "block": "minecraft:air"
      },
      {
        "char": "m",
        "block": "minecraft:stone_bricks[weathering=false]"
      },
      {
        "char": "b",
        "block": "minecraft:mossy_stone_bricks"
      },
      {
        "char": "g",
        "block": "minecraft:glass_pane[east=true,north=false,south=false,waterlogged=false,west=true]"
      },
      {
        "char": "e",
        "block": "minecraft:vine[east=false,north=true,south=false,up=false,west=false]"
      },
      {
        "char": "z",
        "block": "minecraft:stone_slab[type=bottom,waterlogged=false,weathering=false]"
      },
      {
        "char": "i",
        "block": "minecraft:cobblestone[weathering=false]"
      },
      {
        "char": "j",
        "block": "minecraft:stone[weathering=false]"
      },
      {
        "char": "y",
        "block": "minecraft:stone_slab[type=top,waterlogged=false,weathering=false]"
      },
      {
        "char": "ϒ",
        "block": "minecraft:hopper[enabled=true,facing=down]",
        "tag": {
          "z": 583,
          "x": 246,
          "TransferCooldown": 0,
          "ForgeCaps": {},
          "id": "minecraft:hopper",
          "y": 142,
          "Items": []
        }
      },
      {
        "char": "υ",
        "block": "minecraft:activator_rail[powered=false,shape=east_west,waterlogged=false]"
      },
      {
        "char": "ϓ",
        "block": "minecraft:cobweb"
      }
    ]
  },
  "slices": [
    [
      "        c       ",
      "        h       ",
      "        ad      ",
      "        hd      ",
      "        nd      ",
      "        hd      ",
      "        md      ",
      "        hd      ",
      "bgagagbgad      ",
      "ee  eeeee       ",
      "                ",
      "                ",
      "                ",
      "                ",
      "                ",
      "                "
    ],
    [
      "  zaiiaca       ",
      "   ajcibb       ",
      "    c baid      ",
      " y imbacad      ",
      " c  aaaaad      ",
      " jimjanccd      ",
      "bciacbcjcd      ",
      "bcbaimmmad      ",
      "nabmnanccd      ",
      "ee  eeeee       ",
      "                ",
      "                ",
      "                ",
      "                ",
      "                ",
      "                "
    ],
    [
      "        b       ",
      "        h       ",
      "        m       ",
      "        hd      ",
      "        jd      ",
      "        hd      ",
      "        md      ",
      "ϒϒϒ ϒϒϒ hd      ",
      "agbgcgagad      ",
      "ee  eeeee       ",
      "                ",
      "                ",
      "                ",
      "                ",
      "                ",
      "                "
    ],
    [
      "        i       ",
      "        h       ",
      "        a       ",
      "        hd      ",
      "        ad      ",
      "        hd      ",
      "        nd      ",
      "υυυ υυυ hd      ",
      "ngmgbgjgid      ",
      "ee  eeeee       ",
      "                ",
      "                ",
      "                ",
      "                ",
      "                ",
      "                "
    ],
    [
      "        b       ",
      "        m       ",
      "        a       ",
      "        nd      ",
      "        jd      ",
      "        bd      ",
      "        bd      ",
      "        jd      ",
      "iamicbbbbd      ",
      "ee  eeeee       ",
      "                ",
      "                ",
      "                ",
      "                ",
      "                ",
      "                "
    ],
    [
      "        i       ",
      "        h       ",
      "        m       ",
      "        hd      ",
      "        bd      ",
      "        hd      ",
      "        bd      ",
      "       ϓhd      ",
      "mgmgcgbgcd      ",
      "ee  eeeee       ",
      "                ",
      "                ",
      "                ",
      "                ",
      "                ",
      "                "
    ]
  ]
}