{
  "xsize": 16,
  "zsize": 16,
  "palette": {
    "palette": [
      {
        "char": " ",
        "block": "minecraft:air"
      },
      {
        "char": "j",
        "block": "minecraft:air"
      },
      {
        "char": "L",
        "block": "minecraft:air"
      },
      {
        "char": "i",
        "block": "minecraft:air"
      },
      {
        "char": "c",
        "block": "minecraft:air"
      },
      {
        "char": "w",
        "block": "minecraft:air"
      },
      {
        "char": "o",
        "block": "minecraft:air"
      },
      {
        "char": "s",
        "block": "minecraft:air"
      },
      {
        "char": "q",
        "block": "minecraft:air"
      },
      {
        "char": "u",
        "block": "minecraft:air"
      },
      {
        "char": "r",
        "block": "minecraft:air"
      },
      {
        "char": "b",
        "block": "minecraft:air"
      },
      {
        "char": "a",
        "block": "minecraft:air"
      },
      {
        "char": "t",
        "block": "minecraft:air"
      },
      {
        "char": "m",
        "block": "minecraft:air"
      },
      {
        "char": "n",
        "block": "minecraft:air"
      },
      {
        "char": "ͽ",
        "block": "minecraft:air"
      },
      {
        "char": "D",
        "block": "minecraft:air"
      },
      {
        "char": "M",
        "block": "minecraft:air"
      },
      {
        "char": "p",
        "block": "minecraft:grass"
      },
      {
        "char": "K",
        "block": "minecraft:air"
      },
      {
        "char": "΄",
        "block": "minecraft:air"
      },
      {
        "char": "Д",
        "block": "minecraft:air"
      },
      {
        "char": "d",
        "block": "minecraft:air"
      },
      {
        "char": "Ю",
        "block": "minecraft:air"
      },
      {
        "char": "e",
        "block": "minecraft:air"
      },
      {
        "char": "ϣ",
        "block": "minecraft:air"
      },
      {
        "char": "н",
        "block": "minecraft:air"
      },
      {
        "char": "а",
        "block": "minecraft:air"
      },
      {
        "char": "h",
        "block": "minecraft:air"
      },
      {
        "char": "ϝ",
        "block": "minecraft:air"
      },
      {
        "char": "g",
        "block": "minecraft:air"
      },
      {
        "char": "Ͼ",
        "block": "minecraft:air"
      },
      {
        "char": "z",
        "block": "minecraft:air"
      },
      {
        "char": "е",
        "block": "minecraft:air"
      },
      {
        "char": "Κ",
        "block": "minecraft:air"
      }
    ]
  },
  "slices": [
    [
      "jLicijjjwooosqur",
      "bccaacaawooorstt",
      "cciicbmmwooorrur",
      "LccLccbjwooourut",
      "aLLaacbbowootsqs",
      "niLLcjnmwooossts",
      "mmiibabcoooourtr",
      "baaanjcoowoouruq",
      "wwwwiioooooortuu",
      "ooooooooooootsuq",
      "oooooooooooorstt",
      "sttttstqttqsssuu",
      "rutusrqrsrrtuqru",
      "rtquuquruqrstsuq",
      "qqsqrusqtsqutusu",
      "uutuqtsqtqstququ"
    ],
    [
      "bbibͽ DbcMpp    ",
      "caaDK ͽ cMp     ",
      "cjjaD  DcM p    ",
      "iabcD ΄DbMpp    ",
      "cibbm   pД      ",
      " bjm j  KdЮp    ",
      "DD  D    dp     ",
      "     K p ΄p     ",
      "amai     dpp    ",
      "pepppepppppϣ    ",
      "pppнpp аϣ       ",
      "                ",
      "                ",
      "                ",
      "                ",
      "                "
    ],
    [
      "DDc     c       ",
      "bicK    h       ",
      "icDD    nd      ",
      "mjaj    hd      ",
      "jjcj    cd      ",
      "        ϝd      ",
      "         d      ",
      "         d      ",
      "bgiϾ     d      ",
      "eeeeeeeee       ",
      "                ",
      "                ",
      "                ",
      "                ",
      "                ",
      "                "
    ],
    [
      "K       i       ",
      "am      h       ",
      "mi      bd      ",
      "Dz      hd      ",
      "        ad      ",
      "        ϝd      ",
      "         d      ",
      "         d      ",
      "igbϾ   е d      ",
      "ee eeeeee       ",
      "                ",
      "                ",
      "                ",
      "                ",
      "                ",
      "                "
    ],
    [
      "        j       ",
      "        j       ",
      "        ad      ",
      "Κ       id      ",
      "        cd      ",
      "        cd      ",
      "        bd      ",
      "        id      ",
      "cajb jcand      ",
      "ee eeeeee       ",
      "                ",
      "                ",
      "                ",
      "                ",
      "                ",
      "                "
    ],
    [
      "        j       ",
      "        h       ",
      "        bd      ",
      "        hd      ",
      "        jd      ",
      "        hd      ",
      "        id      ",
      "        hd      ",
      "bgcgmgmgad      ",
      "ee  eeeee       ",
      "                ",
      "                ",
      "                ",
      "                ",
      "                ",
      "                "
    ]
  ]
}