{
  "xsize": 16,
  "zsize": 16,
  "palette": {
    "palette": [
      {
        "char": " ",
        "block": "minecraft:air"
      },
      {
        "char": "f",
        "block": "minecraft:vine[east=true,north=false,south=false,up=false,west=false]"
      },
      {
        "char": "k",
        "block": "minecraft:vine[east=false,north=false,south=true,up=false,west=false]"
      },
      {
        "char": "a",
        "block": "minecraft:mossy_cobblestone"
      },
      {
        "char": "g",
        "block": "minecraft:glass_pane[east=true,north=false,south=false,waterlogged=false,west=true]"
      },
      {
        "char": "i",
        "block": "minecraft:cobblestone[weathering=false]"
      },
      {
        "char": "c",
        "block": "minecraft:cracked_stone_bricks"
      },
      {
        "char": "d",
        "block": "minecraft:vine[east=false,north=false,south=false,up=false,west=true]"
      },
      {
        "char": "h",
        "block": "minecraft:glass_pane[east=false,north=true,south=true,waterlogged=false,west=false]"
      },
      {
        "char": "b",
        "block": "minecraft:mossy_stone_bricks"
      },
      {
        "char": "m",
        "block": "minecraft:stone_bricks[weathering=false]"
      },
      {
        "char": "n",
        "block": "minecraft:air"
      },
      {
        "char": "j",
        "block": "minecraft:stone[weathering=false]"
      },
      {
        "char": "y",
        "block": "minecraft:stone_slab[type=top,waterlogged=false,weathering=false]"
      },
      {
        "char": "z",
        "block": "minecraft:stone_slab[type=bottom,waterlogged=false,weathering=false]"
      },
      {
        "char": "v",
        "block": "minecraft:light_gray_concrete"
      },
      {
        "char": "Ω",
        "block": "minecraft:oak_stairs[facing=north,half=bottom,shape=straight,waterlogged=false]"
      },
      {
        "char": "Ϳ",
        "block": "minecraft:birch_slab[type=top,waterlogged=false]"
      },
      {
        "char": ";",
        "block": "minecraft:spruce_stairs[facing=west,half=top,shape=straight,waterlogged=false]"
      },
      {
        "char": "C",
        "block": "minecraft:spruce_slab[type=top,waterlogged=false]"
      },
      {
        "char": "ͼ",
        "block": "minecraft:spruce_stairs[facing=east,half=top,shape=straight,waterlogged=false]"
      },
      {
        "char": "Ψ",
        "block": "minecraft:heavy_weighted_pressure_plate[power=0]"
      }
    ]
  },
  "slices": [
    [
      "                ",
      "                ",
      "                ",
      "                ",
      "                ",
      "                ",
      "fkkk            ",
      "k       k       ",
      "agigcgagad      ",
      "        hd      ",
      "        bd      ",
      "        hd      ",
      "        add     ",
      "        hdd     ",
      "        c       ",
      "        h       "
    ],
    [
      "                ",
      "                ",
      "                ",
      "                ",
      "                ",
      "                ",
      "fkkk            ",
      "k       k       ",
      "bbaamaimnd      ",
      "aijbnciicd      ",
      "acccbcbbnd      ",
      "bbajccibbd      ",
      "ainbbannmdd     ",
      " yiimccabdd     ",
      "   cjbajc       ",
      " zcbamicc       "
    ],
    [
      "                ",
      "                ",
      "                ",
      "                ",
      "                ",
      "                ",
      "fkkk            ",
      "k       k       ",
      "cgmgjgmgnd      ",
      "v       hd      ",
      "v   Ω   bd      ",
      "vͿ ;Cͼ  hd      ",
      "        add     ",
      "        hdd     ",
      "        a       ",
      "        h       "
    ],
    [
      "                ",
      "                ",
      "                ",
      "                ",
      "                ",
      "                ",
      "fkkk            ",
      "k               ",
      "bgbgcgagbd      ",
      "v       hd      ",
      "v       cd      ",
      "v   Ψ   hd      ",
      "        idd     ",
      "        hdd     ",
      "        a       ",
      "        h       "
    ],
    [
      "                ",
      "                ",
      "                ",
      "                ",
      "                ",
      "                ",
      "fkkk            ",
      "k               ",
      "mccmbjcjbd      ",
      "        nd      ",
      "        bd      ",
      "        cd      ",
      "        idd     ",
      "        ndd     ",
      "        c       ",
      "        i       "
    ],
    [
      "                ",
      "                ",
      "                ",
      "                ",
      "                ",
      "                ",
      "fkkk            ",
      "k               ",
      "cgcgcgcgid      ",
      "        hd      ",
      "        cd      ",
      "        hd      ",
      "        cdd     ",
      "        hdd     ",
      "        j       ",
      "        h       "
    ]
  ]
}