{
  "xsize": 16,
  "zsize": 16,
  "palette": {
    "palette": [
      {
        "char": " ",
        "block": "minecraft:air"
      },
      {
        "char": "a",
        "block": "minecraft:mossy_cobblestone"
      },
      {
        "char": "f",
        "block": "minecraft:vine[east=true,north=false,south=false,up=false,west=false]"
      },
      {
        "char": "h",
        "block": "minecraft:glass_pane[east=false,north=true,south=true,waterlogged=false,west=false]"
      },
      {
        "char": "Q",
        "block": "minecraft:oak_fence[east=false,north=false,south=false,waterlogged=false,west=false]"
      },
      {
        "char": "i",
        "block": "minecraft:cobblestone[weathering=false]"
      },
      {
        "char": "c",
        "block": "minecraft:cracked_stone_bricks"
      },
      {
        "char": "m",
        "block": "minecraft:stone_bricks[weathering=false]"
      },
      {
        "char": "g",
        "block": "minecraft:glass_pane[east=true,north=false,south=false,waterlogged=false,west=true]"
      },
      {
        "char": "b",
        "block": "minecraft:mossy_stone_bricks"
      },
      {
        "char": "e",
        "block": "minecraft:vine[east=false,north=true,south=false,up=false,west=false]"
      },
      {
        "char": "j",
        "block": "minecraft:stone[weathering=false]"
      },
      {
        "char": "y",
        "block": "minecraft:stone_slab[type=top,waterlogged=false,weathering=false]"
      },
      {
        "char": "n",
        "block": "minecraft:air"
      },
      {
        "char": "A",
        "block": "minecraft:terracotta"
      },
      {
        "char": "σ",
        "block": "minecraft:oak_wall_sign[facing=west,waterlogged=false]",
        "tag": {
          "z": 581,
          "x": 242,
          "is_waxed": "0b",
          "ForgeCaps": {
            "supplementaries:antique_ink": {
              "ink": "0b"
            }
          },
          "id": "minecraft:sign",
          "y": 184,
          "front_text": {
            "color": "black",
            "has_glowing_text": "0b",
            "messages": [
              "{\"text\":\"\"}",
              "{\"text\":\"\"}",
              "{\"text\":\"\"}",
              "{\"text\":\"\"}"
            ]
          },
          "back_text": {
            "color": "black",
            "has_glowing_text": "0b",
            "messages": [
              "{\"text\":\"\"}",
              "{\"text\":\"\"}",
              "{\"text\":\"\"}",
              "{\"text\":\"\"}"
            ]
          }
        }
      },
      {
        "char": "Ζ",
        "block": "minecraft:smooth_stone_slab[type=bottom,waterlogged=false]"
      },
      {
        "char": "x",
        "block": "minecraft:light_gray_carpet"
      },
      {
        "char": "ϝ",
        "block": "minecraft:glass_pane[east=false,north=true,south=false,waterlogged=false,west=false]"
      },
      {
        "char": "λ",
        "block": "minecraft:glass_pane[east=true,north=false,south=false,waterlogged=false,west=false]"
      }
    ]
  },
  "slices": [
    [
      "        a       ",
      "       fh  Q    ",
      "       fi       ",
      "       fh       ",
      "       fa       ",
      "       fh  Q    ",
      "       fc       ",
      "                ",
      "        mgagbgbg",
      "        eeeeeeee",
      "                ",
      "                ",
      "                ",
      "                ",
      "                ",
      "                "
    ],
    [
      "        jccaayy ",
      "       fnbacb   ",
      "       fcibcby  ",
      "       fnnbaccyy",
      "       fbbabbacc",
      "       faaciaban",
      "       f  biicaj",
      "          njbcjc",
      "         jbmiccc",
      "        eeeeeeee",
      "                ",
      "                ",
      "                ",
      "                ",
      "                ",
      "                "
    ],
    [
      "        m   A   ",
      "       fh σΖA   ",
      "       fa   A   ",
      "       fhx      ",
      "       fn  xAx  ",
      "       f  σΖA σΖ",
      "       f    A   ",
      "             x  ",
      "          cgngbg",
      "        eeeeee  ",
      "                ",
      "                ",
      "                ",
      "                ",
      "                ",
      "                "
    ],
    [
      "        b       ",
      "       fh       ",
      "       fc       ",
      "       fh       ",
      "       fc       ",
      "       f        ",
      "       f        ",
      "                ",
      "          agbgig",
      "        eeeeee  ",
      "                ",
      "                ",
      "                ",
      "                ",
      "                ",
      "                "
    ],
    [
      "        i       ",
      "       fa       ",
      "       fi       ",
      "       fb       ",
      "       f        ",
      "       f        ",
      "       f        ",
      "                ",
      "          biacib",
      "        eeeeee  ",
      "                ",
      "                ",
      "                ",
      "                ",
      "                ",
      "                "
    ],
    [
      "        m       ",
      "       fh       ",
      "       fc       ",
      "       fϝ       ",
      "       f        ",
      "       f        ",
      "       f        ",
      "                ",
      "           λcgcg",
      "        eeeeee  ",
      "                ",
      "                ",
      "                ",
      "                ",
      "                ",
      "                "
    ]
  ]
}