{
  "xsize": 16,
  "zsize": 16,
  "palette": {
    "palette": [
      {
        "char": " ",
        "block": "minecraft:air"
      },
      {
        "char": "c",
        "block": "minecraft:cracked_stone_bricks"
      },
      {
        "char": "f",
        "block": "minecraft:vine[east=true,north=false,south=false,up=false,west=false]"
      },
      {
        "char": "h",
        "block": "minecraft:glass_pane[east=false,north=true,south=true,waterlogged=false,west=false]"
      },
      {
        "char": "a",
        "block": "minecraft:mossy_cobblestone"
      },
      {
        "char": "m",
        "block": "minecraft:stone_bricks[weathering=false]"
      },
      {
        "char": "g",
        "block": "minecraft:glass_pane[east=true,north=false,south=false,waterlogged=false,west=true]"
      },
      {
        "char": "j",
        "block": "minecraft:stone[weathering=false]"
      },
      {
        "char": "e",
        "block": "minecraft:vine[east=false,north=true,south=false,up=false,west=false]"
      },
      {
        "char": "i",
        "block": "minecraft:cobblestone[weathering=false]"
      },
      {
        "char": "b",
        "block": "minecraft:mossy_stone_bricks"
      },
      {
        "char": "Γ",
        "block": "minecraft:air"
      },
      {
        "char": "n",
        "block": "minecraft:air"
      },
      {
        "char": "Θ",
        "block": "minecraft:air"
      },
      {
        "char": "l",
        "block": "minecraft:oak_leaves[distance=7,persistent=true,waterlogged=false]"
      },
      {
        "char": "χ",
        "block": "minecraft:oak_stairs[facing=south,half=bottom,shape=straight,waterlogged=false]"
      },
      {
        "char": "Ω",
        "block": "minecraft:oak_stairs[facing=north,half=bottom,shape=straight,waterlogged=false]"
      },
      {
        "char": ";",
        "block": "minecraft:spruce_stairs[facing=west,half=top,shape=straight,waterlogged=false]"
      },
      {
        "char": "C",
        "block": "minecraft:spruce_slab[type=top,waterlogged=false]"
      },
      {
        "char": "ͼ",
        "block": "minecraft:spruce_stairs[facing=east,half=top,shape=straight,waterlogged=false]"
      },
      {
        "char": "Κ",
        "block": "minecraft:spruce_slab[type=bottom,waterlogged=false]"
      }
    ]
  },
  "slices": [
    [
      "        c       ",
      "       fh       ",
      "       fc       ",
      "       fh       ",
      "       fa       ",
      "       fh       ",
      "       fm       ",
      "       fh       ",
      "       fagjgcgjg",
      "        eeeeeeee",
      "                ",
      "                ",
      "                ",
      "                ",
      "                ",
      "                "
    ],
    [
      "        cicabj  ",
      "       faajbibΓ ",
      "       fbacnai Θ",
      "       fbbcacnjn",
      "       fncjcaaja",
      "       facjcacaa",
      "       fbbncbabj",
      "       fbcnabcnj",
      "       fbcacbbba",
      "        eeeeeeee",
      "                ",
      "                ",
      "                ",
      "                ",
      "                ",
      "                "
    ],
    [
      "       lb  χ    ",
      "       fh       ",
      "       fc  Ω    ",
      "       fh ;Cͼ ;Κ",
      "       fc CCC CC",
      "       fh ;Cͼ ;C",
      "       fa  χ   χ",
      "       fh       ",
      "       fmgngjgbg",
      "        eeeeeeee",
      "                ",
      "                ",
      "                ",
      "                ",
      "                ",
      "                "
    ],
    [
      "       lb       ",
      "       fh       ",
      "       fa       ",
      "       fh       ",
      "       fb       ",
      "       fh       ",
      "       fb       ",
      "       fh       ",
      "       fagjgagmg",
      "        eeeeeeee",
      "                ",
      "                ",
      "                ",
      "                ",
      "                ",
      "                "
    ],
    [
      "      llb       ",
      "       fi       ",
      "       fb       ",
      "       fb       ",
      "       fb       ",
      "       fb       ",
      "       fc       ",
      "       fa       ",
      "       faccannic",
      "        eeeeeeee",
      "                ",
      "                ",
      "                ",
      "                ",
      "                ",
      "                "
    ],
    [
      "       lm       ",
      "        h       ",
      "       fn       ",
      "       fh       ",
      "       fi       ",
      "       fh       ",
      "       fn       ",
      "       fh       ",
      "       fmgagbgag",
      "        eeeeeeee",
      "                ",
      "                ",
      "                ",
      "                ",
      "                ",
      "                "
    ]
  ]
}