{
  "xsize": 16,
  "zsize": 16,
  "palette": {
    "palette": [
      {
        "char": " ",
        "block": "minecraft:air"
      },
      {
        "char": "r",
        "block": "minecraft:basalt[axis=x]"
      },
      {
        "char": "t",
        "block": "minecraft:deepslate[axis=y]"
      },
      {
        "char": "q",
        "block": "minecraft:blackstone"
      },
      {
        "char": "u",
        "block": "minecraft:cyan_terracotta"
      },
      {
        "char": "s",
        "block": "minecraft:cobbled_deepslate"
      },
      {
        "char": "o",
        "block": "minecraft:grass_block[snowy=false]"
      },
      {
        "char": "m",
        "block": "minecraft:stone_bricks[weathering=false]"
      },
      {
        "char": "j",
        "block": "minecraft:stone[weathering=false]"
      },
      {
        "char": "w",
        "block": "minecraft:dirt"
      },
      {
        "char": "b",
        "block": "minecraft:mossy_stone_bricks"
      },
      {
        "char": "a",
        "block": "minecraft:mossy_cobblestone"
      },
      {
        "char": "c",
        "block": "minecraft:cracked_stone_bricks"
      },
      {
        "char": "i",
        "block": "minecraft:cobblestone[weathering=false]"
      },
      {
        "char": "L",
        "block": "minecraft:andesite"
      },
      {
        "char": "p",
        "block": "minecraft:air"
      },
      {
        "char": "f",
        "block": "minecraft:vine[east=true,north=false,south=false,up=false,west=false]"
      },
      {
        "char": "k",
        "block": "minecraft:vine[east=false,north=false,south=true,up=false,west=false]"
      },
      {
        "char": "Ш",
        "block": "minecraft:stone_button[face=floor,facing=east,powered=false]"
      },
      {
        "char": "ϻ",
        "block": "minecraft:oak_door[facing=south,half=lower,hinge=left,open=false,powered=false]"
      },
      {
        "char": "M",
        "block": "minecraft:acacia_leaves[distance=7,persistent=true,waterlogged=false]"
      },
      {
        "char": "ͽ",
        "block": "minecraft:crafting_table"
      },
      {
        "char": "D",
        "block": "minecraft:gravel"
      },
      {
        "char": "ϣ",
        "block": "minecraft:dandelion"
      },
      {
        "char": "K",
        "block": "minecraft:cobblestone_slab[type=bottom,waterlogged=false,weathering=false]"
      },
      {
        "char": "Ϸ",
        "block": "minecraft:oak_door[facing=south,half=upper,hinge=left,open=false,powered=false]"
      },
      {
        "char": "g",
        "block": "minecraft:glass_pane[east=true,north=false,south=false,waterlogged=false,west=true]"
      },
      {
        "char": "Δ",
        "block": "minecraft:glass_pane[east=true,north=false,south=true,waterlogged=false,west=true]"
      },
      {
        "char": "d",
        "block": "minecraft:vine[east=false,north=false,south=false,up=false,west=true]"
      },
      {
        "char": "μ",
        "block": "minecraft:glass_pane[east=false,north=true,south=true,waterlogged=false,west=true]"
      },
      {
        "char": "h",
        "block": "minecraft:glass_pane[east=false,north=true,south=true,waterlogged=false,west=false]"
      },
      {
        "char": "z",
        "block": "minecraft:stone_slab[type=bottom,waterlogged=false,weathering=false]"
      },
      {
        "char": "n",
        "block": "minecraft:air"
      }
    ]
  },
  "slices": [
    [
      "rrttqtursttuturu",
      "urrssuuqqstursus",
      "rsquuqtqqtrqrqtr",
      "tsstsuqqtrqrtrqs",
      "rqqqrsustsrttrtu",
      "oooooooooooousus",
      "oooooooooooorqst",
      "ooooooooooooqtqr",
      "mjwwwwwwwoooqqqs",
      "bacaccbiwooostur",
      "cmjccbbcwooosurq",
      "ccmbabbawoooqrsr",
      "bjaacacmwoootssq",
      "LLLjcaacwoooqqsu",
      "iLjLibbbwoooqrqu",
      "iiccmmjbwoooqurt"
    ],
    [
      "                ",
      "                ",
      "                ",
      "                ",
      "                ",
      " pp pppp pp     ",
      "fpkkpppppppp    ",
      "ppppppШkpppp    ",
      "iϻacicaaiMpp    ",
      "       ͽaM p    ",
      "D   ͽ   cMϣp    ",
      "  ͽ   ͽ cMp     ",
      "K     ͽDcMp     ",
      "bDmKͽ ͽ aMp     ",
      "ajcmD   bMp     ",
      "cacm Dͽ cMpp    "
    ],
    [
      "                ",
      "                ",
      "                ",
      "                ",
      "                ",
      "                ",
      "fkkk            ",
      "k     kkk       ",
      "aϷagcgcΔbd      ",
      "       ͽμd      ",
      "        bd      ",
      "      ͽ hd      ",
      "        cdd     ",
      "z       hdd     ",
      "iDm     a       ",
      "biD   ͽ h       "
    ],
    [
      "                ",
      "                ",
      "                ",
      "                ",
      "                ",
      "                ",
      "fkkk            ",
      "k     kkk       ",
      "ncbgmgjgad      ",
      "        hd      ",
      "        jd      ",
      "        hd      ",
      "        add     ",
      "        hdd     ",
      "        a       ",
      "        h       "
    ],
    [
      "                ",
      "                ",
      "                ",
      "                ",
      "                ",
      "                ",
      "fkkk            ",
      "k     kkk       ",
      "bacajanjjd      ",
      "        ad      ",
      "        cd      ",
      "        ad      ",
      "        ndd     ",
      "        ndd     ",
      "        i       ",
      "        m       "
    ],
    [
      "                ",
      "                ",
      "                ",
      "                ",
      "                ",
      "                ",
      "fkkk            ",
      "k     kkk       ",
      "cgigcgmgad      ",
      "        hd      ",
      "        bd      ",
      "        hd      ",
      "        add     ",
      "        hdd     ",
      "        m       ",
      "        h       "
    ]
  ]
}