{
  "xsize": 16,
  "zsize": 16,
  "palette": {
    "palette": [
      {
        "char": " ",
        "block": "minecraft:air"
      },
      {
        "char": "f",
        "block": "minecraft:vine[east=true,north=false,south=false,up=false,west=false]"
      },
      {
        "char": "k",
        "block": "minecraft:vine[east=false,north=false,south=true,up=false,west=false]"
      },
      {
        "char": "c",
        "block": "minecraft:cracked_stone_bricks"
      },
      {
        "char": "g",
        "block": "minecraft:glass_pane[east=true,north=false,south=false,waterlogged=false,west=true]"
      },
      {
        "char": "i",
        "block": "minecraft:cobblestone[weathering=false]"
      },
      {
        "char": "a",
        "block": "minecraft:mossy_cobblestone"
      },
      {
        "char": "m",
        "block": "minecraft:stone_bricks[weathering=false]"
      },
      {
        "char": "d",
        "block": "minecraft:vine[east=false,north=false,south=false,up=false,west=true]"
      },
      {
        "char": "h",
        "block": "minecraft:glass_pane[east=false,north=true,south=true,waterlogged=false,west=false]"
      },
      {
        "char": "j",
        "block": "minecraft:stone[weathering=false]"
      },
      {
        "char": "b",
        "block": "minecraft:mossy_stone_bricks"
      },
      {
        "char": "n",
        "block": "minecraft:air"
      },
      {
        "char": "z",
        "block": "minecraft:stone_slab[type=bottom,waterlogged=false,weathering=false]"
      },
      {
        "char": "E",
        "block": "minecraft:redstone_lamp[lit=false]"
      },
      {
        "char": "Ζ",
        "block": "minecraft:smooth_stone_slab[type=bottom,waterlogged=false]"
      },
      {
        "char": "ϭ",
        "block": "minecraft:air"
      },
      {
        "char": "Ϣ",
        "block": "minecraft:air"
      },
      {
        "char": "Ε",
        "block": "minecraft:quartz_pillar[axis=y]"
      },
      {
        "char": "ϋ",
        "block": "minecraft:air"
      },
      {
        "char": "ω",
        "block": "minecraft:red_wool"
      },
      {
        "char": "Ϧ",
        "block": "minecraft:stone_pressure_plate[powered=false]"
      },
      {
        "char": "Q",
        "block": "minecraft:oak_fence[east=false,north=false,south=false,waterlogged=false,west=false]"
      }
    ]
  },
  "slices": [
    [
      "                ",
      "                ",
      "                ",
      "                ",
      "                ",
      "                ",
      "fkkk            ",
      "k               ",
      "cgcgigagmd      ",
      "        hd      ",
      "        ad      ",
      "        hd      ",
      "        cdd     ",
      "        hdd     ",
      "        j       ",
      "        h       "
    ],
    [
      "                ",
      "                ",
      "                ",
      "                ",
      "                ",
      "                ",
      "fkkk            ",
      "k               ",
      "cjccibncbd      ",
      "jiicbjmcbd      ",
      "mabacjiijd      ",
      "cjcjcijabd      ",
      "cjjcjmibadd     ",
      " c mabijjdd     ",
      "   zcabma       ",
      "    iibii       "
    ],
    [
      "                ",
      "                ",
      "                ",
      "                ",
      "                ",
      "                ",
      "fkkk            ",
      "k               ",
      "agcgbgbgcd      ",
      "        hd      ",
      "   E    bd      ",
      "   E    hd      ",
      "   E    jdd     ",
      "   Ζ    hdd     ",
      "        b       ",
      "        h       "
    ],
    [
      "                ",
      "                ",
      "                ",
      "                ",
      "                ",
      "                ",
      "fkkk            ",
      "k               ",
      "mgcgigagad      ",
      "        hd      ",
      "ϭ ϢΕϭ   bd      ",
      "ϋ ϋ ϋ   hd      ",
      "        ndd     ",
      "      ω hdd     ",
      "        a       ",
      "      ω h       "
    ],
    [
      "                ",
      "                ",
      "                ",
      "                ",
      "                ",
      "                ",
      "fkkk            ",
      "k               ",
      "nmaamacimd      ",
      "        ad      ",
      "   Ϧ    cd      ",
      "        bd      ",
      "        idd     ",
      "      ω add     ",
      "        b       ",
      "      ω a       "
    ],
    [
      "                ",
      "                ",
      "                ",
      "                ",
      "                ",
      "                ",
      "fkkk            ",
      "k               ",
      "agjgigcgjd      ",
      "        hd      ",
      "        id      ",
      "        hd      ",
      "        ndd     ",
      "      Q hdd     ",
      "        a       ",
      "      Q h       "
    ]
  ]
}