{
  "xsize": 16,
  "zsize": 16,
  "palette": {
    "palette": [
      {
        "char": " ",
        "block": "minecraft:air"
      },
      {
        "char": "f",
        "block": "minecraft:vine[east=true,north=false,south=false,up=false,west=false]"
      },
      {
        "char": "k",
        "block": "minecraft:vine[east=false,north=false,south=true,up=false,west=false]"
      },
      {
        "char": "a",
        "block": "minecraft:mossy_cobblestone"
      },
      {
        "char": "g",
        "block": "minecraft:glass_pane[east=true,north=false,south=false,waterlogged=false,west=true]"
      },
      {
        "char": "b",
        "block": "minecraft:mossy_stone_bricks"
      },
      {
        "char": "c",
        "block": "minecraft:cracked_stone_bricks"
      },
      {
        "char": "d",
        "block": "minecraft:vine[east=false,north=false,south=false,up=false,west=true]"
      },
      {
        "char": "h",
        "block": "minecraft:glass_pane[east=false,north=true,south=true,waterlogged=false,west=false]"
      },
      {
        "char": "Q",
        "block": "minecraft:oak_fence[east=false,north=false,south=false,waterlogged=false,west=false]"
      },
      {
        "char": "m",
        "block": "minecraft:stone_bricks[weathering=false]"
      },
      {
        "char": "n",
        "block": "minecraft:air"
      },
      {
        "char": "j",
        "block": "minecraft:stone[weathering=false]"
      },
      {
        "char": "i",
        "block": "minecraft:cobblestone[weathering=false]"
      },
      {
        "char": "z",
        "block": "minecraft:stone_slab[type=bottom,waterlogged=false,weathering=false]"
      },
      {
        "char": "y",
        "block": "minecraft:stone_slab[type=top,waterlogged=false,weathering=false]"
      },
      {
        "char": "H",
        "block": "minecraft:spruce_trapdoor[facing=west,half=bottom,open=true,powered=false,waterlogged=false]"
      },
      {
        "char": "ͺ",
        "block": "minecraft:chest[facing=south,type=right,waterlogged=false]",
        "loot": "bigbuildingsloot",
        "tag": {
          "z": 578,
          "x": 245,
          "ForgeCaps": {},
          "id": "minecraft:chest",
          "y": 166,
          "Items": []
        }
      },
      {
        "char": "4",
        "block": "minecraft:chest[facing=south,type=left,waterlogged=false]",
        "loot": "bigbuildingsloot",
        "tag": {
          "z": 582,
          "x": 246,
          "ForgeCaps": {},
          "id": "minecraft:chest",
          "y": 167,
          "Items": []
        }
      },
      {
        "char": "F",
        "block": "minecraft:spruce_trapdoor[facing=east,half=bottom,open=true,powered=false,waterlogged=false]"
      },
      {
        "char": "ͻ",
        "block": "minecraft:spruce_trapdoor[facing=south,half=bottom,open=false,powered=false,waterlogged=false]"
      }
    ]
  },
  "slices": [
    [
      "                ",
      "                ",
      "                ",
      "                ",
      "                ",
      "                ",
      "fkkk            ",
      "k               ",
      "agagbgagcd      ",
      "        hd      ",
      "        bd      ",
      "        hd      ",
      "        bdd     ",
      "      Q hdd     ",
      "        m       ",
      "      Q h       "
    ],
    [
      "                ",
      "                ",
      "                ",
      "                ",
      "                ",
      "                ",
      "fkkk            ",
      "                ",
      "ccbcmbnjnd      ",
      "niaijbabad      ",
      "bbacjabmbd      ",
      "jncjcbccid      ",
      "cbiicabccdd     ",
      "  zbmcamadd     ",
      "    cciii       ",
      "   yjcbcc       "
    ],
    [
      "                ",
      "                ",
      "                ",
      "                ",
      "                ",
      "                ",
      "fkkk            ",
      "                ",
      "igagcgagmd      ",
      "        hd      ",
      "    Hͺ4Fid      ",
      "        hd      ",
      "    Hͺ4Fbdd     ",
      "        hdd     ",
      "    Hͺ4Fi       ",
      "        h       "
    ],
    [
      "                ",
      "                ",
      "                ",
      "                ",
      "                ",
      "                ",
      "fkkk            ",
      "                ",
      "igagagagad      ",
      "        hd      ",
      "    Hͺ4Fbd      ",
      "        hd      ",
      "    Hͺ4Fndd     ",
      "        hdd     ",
      "    Hͺ4Fb       ",
      "        h       "
    ],
    [
      "                ",
      "                ",
      "                ",
      "                ",
      "                ",
      "                ",
      "fkkk            ",
      "                ",
      "amjammjjid      ",
      "        cd      ",
      "     ͻͻ nd      ",
      "        bd      ",
      "     ͻͻ idd     ",
      "        bdd     ",
      "     ͻͻ n       ",
      "        i       "
    ],
    [
      "                ",
      "                ",
      "                ",
      "                ",
      "                ",
      "                ",
      "fkkk            ",
      "                ",
      "jgbgbgigbd      ",
      "        hd      ",
      "        bd      ",
      "        hd      ",
      "        bdd     ",
      "        hdd     ",
      "        i       ",
      "        h       "
    ]
  ]
}