{
  "xsize": 16,
  "zsize": 16,
  "palette": {
    "palette": [
      {
        "char": " ",
        "block": "minecraft:air"
      },
      {
        "char": "k",
        "block": "minecraft:vine[east=false,north=false,south=true,up=false,west=false]"
      },
      {
        "char": "f",
        "block": "minecraft:vine[east=true,north=false,south=false,up=false,west=false]"
      },
      {
        "char": "m",
        "block": "minecraft:stone_bricks[weathering=false]"
      },
      {
        "char": "g",
        "block": "minecraft:glass_pane[east=true,north=false,south=false,waterlogged=false,west=true]"
      },
      {
        "char": "j",
        "block": "minecraft:stone[weathering=false]"
      },
      {
        "char": "a",
        "block": "minecraft:mossy_cobblestone"
      },
      {
        "char": "h",
        "block": "minecraft:glass_pane[east=false,north=true,south=true,waterlogged=false,west=false]"
      },
      {
        "char": "l",
        "block": "minecraft:oak_leaves[distance=7,persistent=true,waterlogged=false]"
      },
      {
        "char": "b",
        "block": "minecraft:mossy_stone_bricks"
      },
      {
        "char": "c",
        "block": "minecraft:cracked_stone_bricks"
      },
      {
        "char": "i",
        "block": "minecraft:cobblestone[weathering=false]"
      },
      {
        "char": "n",
        "block": "minecraft:air"
      },
      {
        "char": "y",
        "block": "minecraft:stone_slab[type=top,waterlogged=false,weathering=false]"
      },
      {
        "char": "E",
        "block": "minecraft:redstone_lamp[lit=false]"
      },
      {
        "char": "Ζ",
        "block": "minecraft:smooth_stone_slab[type=bottom,waterlogged=false]"
      },
      {
        "char": "x",
        "block": "minecraft:light_gray_carpet"
      },
      {
        "char": "Ϣ",
        "block": "minecraft:air"
      },
      {
        "char": "Ε",
        "block": "minecraft:quartz_pillar[axis=y]"
      },
      {
        "char": "ϭ",
        "block": "minecraft:air"
      },
      {
        "char": "ϋ",
        "block": "minecraft:air"
      },
      {
        "char": "Ж",
        "block": "minecraft:wither_skeleton_wall_skull[facing=north]",
        "tag": {
          "z": 574,
          "x": 233,
          "ForgeCaps": {},
          "id": "minecraft:skull",
          "y": 161
        }
      },
      {
        "char": "х",
        "block": "minecraft:end_rod[facing=south]"
      },
      {
        "char": "Ϧ",
        "block": "minecraft:stone_pressure_plate[powered=false]"
      }
    ]
  },
  "slices": [
    [
      "                ",
      "                ",
      "                ",
      "                ",
      "                ",
      "                ",
      "              k ",
      "          kkkkkk",
      "       fmgmgjgag",
      "       fhllllll ",
      "       fb   l   ",
      "       fh       ",
      "       fc       ",
      "                ",
      "        c       ",
      "        h       "
    ],
    [
      "                ",
      "                ",
      "                ",
      "                ",
      "                ",
      "                ",
      "              k ",
      "          kkkkkk",
      "       fbbaaaaic",
      "       fccccmicb",
      "       fcbajjjca",
      "       fccibbcbm",
      "       fmbbabccb",
      "        naccib y",
      "        nccibb  ",
      "       lbinbia  "
    ],
    [
      "                ",
      "                ",
      "                ",
      "                ",
      "                ",
      "                ",
      "              k ",
      "          kkkkkk",
      "       fbgagagng",
      "       fh       ",
      "       fa  E   E",
      "       fh  E   E",
      "       fn  E   E",
      "        h  Ζ   Ζ",
      "        c       ",
      "        ax      "
    ],
    [
      "                ",
      "                ",
      "                ",
      "                ",
      "                ",
      "                ",
      "              k ",
      "          kkkkkk",
      "       fagagbgig",
      "       fh       ",
      "       fa ϢΕϭ ϢΕ",
      "       fh ϋ ϋ ϋ ",
      "        c       ",
      "        h       ",
      "        bЖ      ",
      "        aх      "
    ],
    [
      "                ",
      "                ",
      "                ",
      "                ",
      "                ",
      "                ",
      "              k ",
      "          kkkkkk",
      "       faanacbab",
      "       fb       ",
      "       fc  Ϧ   Ϧ",
      "       fa       ",
      "        i       ",
      "        j       ",
      "        m       ",
      "        b       "
    ],
    [
      "                ",
      "                ",
      "                ",
      "                ",
      "                ",
      "                ",
      "              k ",
      "          kkkkkk",
      "       fagagbgbg",
      "       fh       ",
      "       fa       ",
      "        h       ",
      "        b       ",
      "                ",
      "                ",
      "                "
    ]
  ]
}