{
  "xsize": 16,
  "zsize": 16,
  "palette": {
    "palette": [
      {
        "char": " ",
        "block": "minecraft:air"
      },
      {
        "char": "l",
        "block": "minecraft:oak_leaves[distance=7,persistent=true,waterlogged=false]"
      },
      {
        "char": "m",
        "block": "minecraft:stone_bricks[weathering=false]"
      },
      {
        "char": "Q",
        "block": "minecraft:oak_fence[east=false,north=false,south=false,waterlogged=false,west=false]"
      },
      {
        "char": "h",
        "block": "minecraft:glass_pane[east=false,north=true,south=true,waterlogged=false,west=false]"
      },
      {
        "char": "b",
        "block": "minecraft:mossy_stone_bricks"
      },
      {
        "char": "i",
        "block": "minecraft:cobblestone[weathering=false]"
      },
      {
        "char": "d",
        "block": "minecraft:vine[east=false,north=false,south=false,up=false,west=true]"
      },
      {
        "char": "j",
        "block": "minecraft:stone[weathering=false]"
      },
      {
        "char": "g",
        "block": "minecraft:glass_pane[east=true,north=false,south=false,waterlogged=false,west=true]"
      },
      {
        "char": "a",
        "block": "minecraft:mossy_cobblestone"
      },
      {
        "char": "e",
        "block": "minecraft:vine[east=false,north=true,south=false,up=false,west=false]"
      },
      {
        "char": "c",
        "block": "minecraft:cracked_stone_bricks"
      },
      {
        "char": "y",
        "block": "minecraft:stone_slab[type=top,waterlogged=false,weathering=false]"
      },
      {
        "char": "n",
        "block": "minecraft:air"
      },
      {
        "char": "A",
        "block": "minecraft:terracotta"
      },
      {
        "char": "x",
        "block": "minecraft:light_gray_carpet"
      },
      {
        "char": "σ",
        "block": "minecraft:oak_wall_sign[facing=west,waterlogged=false]",
        "tag": {
          "z": 581,
          "x": 242,
          "is_waxed": "0b",
          "ForgeCaps": {
            "supplementaries:antique_ink": {
              "ink": "0b"
            }
          },
          "id": "minecraft:sign",
          "y": 184,
          "front_text": {
            "color": "black",
            "has_glowing_text": "0b",
            "messages": [
              "{\"text\":\"\"}",
              "{\"text\":\"\"}",
              "{\"text\":\"\"}",
              "{\"text\":\"\"}"
            ]
          },
          "back_text": {
            "color": "black",
            "has_glowing_text": "0b",
            "messages": [
              "{\"text\":\"\"}",
              "{\"text\":\"\"}",
              "{\"text\":\"\"}",
              "{\"text\":\"\"}"
            ]
          }
        }
      },
      {
        "char": "Ζ",
        "block": "minecraft:smooth_stone_slab[type=bottom,waterlogged=false]"
      }
    ]
  },
  "slices": [
    [
      "  l     m       ",
      "     Q  h       ",
      "        b       ",
      "        h       ",
      "        i       ",
      "     Q  hd      ",
      "        jd      ",
      "        hd      ",
      "igbgagmgmd      ",
      "ee     ee       ",
      "                ",
      "                ",
      "                ",
      "                ",
      "                ",
      "                "
    ],
    [
      "  ljccmbj       ",
      "   jaaacb       ",
      "    bajjb       ",
      "ym icciai       ",
      "cjmcbbcca       ",
      "jbccciibbd      ",
      "mcabbaamcd      ",
      "aacaaicand      ",
      "ancaajabbd      ",
      "ee     ee       ",
      "                ",
      "                ",
      "                ",
      "                ",
      "                ",
      "                "
    ],
    [
      "  l A   i       ",
      "    A x h       ",
      "    A   c       ",
      "   x   xh       ",
      "A   A x m       ",
      "AxσΖAx  hd      ",
      "A x A   cd      ",
      "        hd      ",
      "igcgigbgnd      ",
      "       ee       ",
      "                ",
      "                ",
      "                ",
      "                ",
      "                ",
      "                "
    ],
    [
      "        b       ",
      "        h       ",
      "        j       ",
      "        h       ",
      "        b       ",
      "        hd      ",
      "        nd      ",
      "        hd      ",
      "cgigbgagbd      ",
      "       ee       ",
      "                ",
      "                ",
      "                ",
      "                ",
      "                ",
      "                "
    ],
    [
      "        a       ",
      "        b       ",
      "        a       ",
      "        b       ",
      "        b       ",
      "        ad      ",
      "        ad      ",
      "        nd      ",
      "jjciababbd      ",
      "       ee       ",
      "                ",
      "                ",
      "                ",
      "                ",
      "                ",
      "                "
    ],
    [
      "        a       ",
      "        h       ",
      "        c       ",
      "        h       ",
      "        m       ",
      "        hd      ",
      "        md      ",
      "        hd      ",
      "bgmgigbgid      ",
      "       ee       ",
      "                ",
      "                ",
      "                ",
      "                ",
      "                ",
      "                "
    ]
  ]
}