{
  "xsize": 16,
  "zsize": 16,
  "palette": {
    "palette": [
      {
        "char": " ",
        "block": "minecraft:air"
      },
      {
        "char": "k",
        "block": "minecraft:vine[east=false,north=false,south=true,up=false,west=false]"
      },
      {
        "char": "Ι",
        "block": "minecraft:vine[east=true,north=false,south=false,up=true,west=false]"
      },
      {
        "char": "c",
        "block": "minecraft:cracked_stone_bricks"
      },
      {
        "char": "g",
        "block": "minecraft:glass_pane[east=true,north=false,south=false,waterlogged=false,west=true]"
      },
      {
        "char": "a",
        "block": "minecraft:mossy_cobblestone"
      },
      {
        "char": "h",
        "block": "minecraft:glass_pane[east=false,north=true,south=true,waterlogged=false,west=false]"
      },
      {
        "char": "l",
        "block": "minecraft:oak_leaves[distance=7,persistent=true,waterlogged=false]"
      },
      {
        "char": "b",
        "block": "minecraft:mossy_stone_bricks"
      },
      {
        "char": "f",
        "block": "minecraft:vine[east=true,north=false,south=false,up=false,west=false]"
      },
      {
        "char": "i",
        "block": "minecraft:cobblestone[weathering=false]"
      },
      {
        "char": "m",
        "block": "minecraft:stone_bricks[weathering=false]"
      },
      {
        "char": "j",
        "block": "minecraft:stone[weathering=false]"
      },
      {
        "char": "n",
        "block": "minecraft:air"
      },
      {
        "char": "y",
        "block": "minecraft:stone_slab[type=top,waterlogged=false,weathering=false]"
      },
      {
        "char": "Δ",
        "block": "minecraft:glass_pane[east=true,north=false,south=true,waterlogged=false,west=true]"
      },
      {
        "char": "Ϡ",
        "block": "minecraft:spruce_stairs[facing=north,half=bottom,shape=inner_right,waterlogged=false]"
      },
      {
        "char": "Ј",
        "block": "minecraft:spruce_stairs[facing=east,half=bottom,shape=straight,waterlogged=false]"
      },
      {
        "char": "Ϛ",
        "block": "minecraft:spruce_stairs[facing=north,half=top,shape=straight,waterlogged=false]"
      },
      {
        "char": "Э",
        "block": "minecraft:spruce_stairs[facing=south,half=bottom,shape=inner_left,waterlogged=false]"
      },
      {
        "char": "Χ",
        "block": "minecraft:oak_stairs[facing=west,half=bottom,shape=straight,waterlogged=false]"
      },
      {
        "char": "C",
        "block": "minecraft:spruce_slab[type=top,waterlogged=false]"
      },
      {
        "char": "ϙ",
        "block": "minecraft:spruce_stairs[facing=south,half=top,shape=straight,waterlogged=false]"
      },
      {
        "char": "Ϳ",
        "block": "minecraft:birch_slab[type=top,waterlogged=false]"
      },
      {
        "char": "Ψ",
        "block": "minecraft:heavy_weighted_pressure_plate[power=0]"
      }
    ]
  },
  "slices": [
    [
      "                ",
      "                ",
      "                ",
      "                ",
      "                ",
      "                ",
      "              k ",
      "          kkkkkk",
      "       Ιcgcgagag",
      "        h       ",
      "       lb       ",
      "       fh       ",
      "       fb       ",
      "        h       ",
      "        a       ",
      "        h       "
    ],
    [
      "                ",
      "                ",
      "                ",
      "                ",
      "                ",
      "                ",
      "              k ",
      "          kkkkkk",
      "       laiccacbb",
      "       lmjmanabj",
      "       fmabaijbm",
      "       fimmibbab",
      "       fniibbjcn",
      "        jabajjc ",
      "        mmabc y ",
      "        mmmibc  "
    ],
    [
      "                ",
      "                ",
      "                ",
      "                ",
      "                ",
      "                ",
      "              k ",
      "          kkkkkk",
      "       lagjgjgcΔ",
      "       fh      Ϡ",
      "       fa      Ј",
      "       fh  Ϛ   Э",
      "       fn ΧC    ",
      "        h  ϙ    ",
      "        cl      ",
      "       lll  Ϳ   "
    ],
    [
      "                ",
      "                ",
      "                ",
      "                ",
      "                ",
      "                ",
      "              k ",
      "          kkkkkk",
      "       fagbgcgag",
      "       fh       ",
      "       fc       ",
      "       fh       ",
      "       fml Ψ    ",
      "        hl      ",
      "        cl      ",
      "       l l      "
    ],
    [
      "                ",
      "                ",
      "                ",
      "                ",
      "                ",
      "                ",
      "              k ",
      "          kkkkkk",
      "       fmnacbcca",
      "       fnll     ",
      "       fcl      ",
      "       fbl      ",
      "       fnl      ",
      "        nl      ",
      "        a       ",
      "        i       "
    ],
    [
      "                ",
      "                ",
      "                ",
      "                ",
      "                ",
      "                ",
      "              k ",
      "          kkkkkk",
      "       fbgngagcg",
      "       fhlllll  ",
      "       fnll     ",
      "       fh       ",
      "       fn       ",
      "                ",
      "        b       ",
      "        h       "
    ]
  ]
}