{
  "xsize": 16,
  "zsize": 16,
  "palette": {
    "palette": [
      {
        "char": " ",
        "block": "minecraft:air"
      },
      {
        "char": "b",
        "block": "minecraft:mossy_stone_bricks"
      },
      {
        "char": "h",
        "block": "minecraft:glass_pane[east=false,north=true,south=true,waterlogged=false,west=false]"
      },
      {
        "char": "c",
        "block": "minecraft:cracked_stone_bricks"
      },
      {
        "char": "d",
        "block": "minecraft:vine[east=false,north=false,south=false,up=false,west=true]"
      },
      {
        "char": "a",
        "block": "minecraft:mossy_cobblestone"
      },
      {
        "char": "j",
        "block": "minecraft:stone[weathering=false]"
      },
      {
        "char": "g",
        "block": "minecraft:glass_pane[east=true,north=false,south=false,waterlogged=false,west=true]"
      },
      {
        "char": "e",
        "block": "minecraft:vine[east=false,north=true,south=false,up=false,west=false]"
      },
      {
        "char": "i",
        "block": "minecraft:cobblestone[weathering=false]"
      },
      {
        "char": "m",
        "block": "minecraft:stone_bricks[weathering=false]"
      },
      {
        "char": "y",
        "block": "minecraft:stone_slab[type=top,waterlogged=false,weathering=false]"
      },
      {
        "char": "n",
        "block": "minecraft:air"
      },
      {
        "char": "z",
        "block": "minecraft:stone_slab[type=bottom,waterlogged=false,weathering=false]"
      },
      {
        "char": "Щ",
        "block": "minecraft:oak_fence[east=false,north=false,south=true,waterlogged=false,west=false]"
      },
      {
        "char": "ω",
        "block": "minecraft:red_wool"
      },
      {
        "char": "x",
        "block": "minecraft:light_gray_carpet"
      },
      {
        "char": "Н",
        "block": "minecraft:oak_fence_gate[facing=south,in_wall=false,open=true,powered=false]"
      },
      {
        "char": "Ζ",
        "block": "minecraft:smooth_stone_slab[type=bottom,waterlogged=false]"
      },
      {
        "char": "ϲ",
        "block": "minecraft:air"
      },
      {
        "char": "Q",
        "block": "minecraft:oak_fence[east=false,north=false,south=false,waterlogged=false,west=false]"
      },
      {
        "char": "Ќ",
        "block": "minecraft:air"
      },
      {
        "char": "З",
        "block": "minecraft:air"
      },
      {
        "char": "к",
        "block": "minecraft:air"
      },
      {
        "char": "б",
        "block": "minecraft:air"
      },
      {
        "char": "l",
        "block": "minecraft:oak_leaves[distance=7,persistent=true,waterlogged=false]"
      }
    ]
  },
  "slices": [
    [
      "        b       ",
      "        h       ",
      "        b       ",
      "        h       ",
      "        c       ",
      "        hd      ",
      "        ad      ",
      "        hd      ",
      "jgagjgjgbd      ",
      "ee     ee       ",
      "                ",
      "                ",
      "                ",
      "                ",
      "                ",
      "                "
    ],
    [
      "    iijmb       ",
      "   yinbjb       ",
      "z  ibbaic       ",
      "c   banac       ",
      "jbjbanijj       ",
      "mcjbccicbd      ",
      "ciimmaibjd      ",
      "bcjjcccbad      ",
      "abamccibnd      ",
      "ee     ee       ",
      "                ",
      "                ",
      "                ",
      "                ",
      "                ",
      "                "
    ],
    [
      "      Щ m       ",
      "      ω h       ",
      "   z  ω i       ",
      "        h       ",
      "x xx Н  j       ",
      "x xx Ζ  hd      ",
      "x x  ϲ  bd      ",
      "        hd      ",
      "bgigigmgcd      ",
      "ee     ee       ",
      "                ",
      "                ",
      "                ",
      "                ",
      "                ",
      "                "
    ],
    [
      "        n       ",
      "        h       ",
      "        b       ",
      "        h       ",
      "        j       ",
      "    Q Q hd      ",
      "     ϲ  ad      ",
      "        hd      ",
      "bgjgigjgbd      ",
      "ee     ee       ",
      "                ",
      "                ",
      "                ",
      "                ",
      "                ",
      "                "
    ],
    [
      "        b       ",
      "        m       ",
      "        i       ",
      "        i       ",
      "        a       ",
      "    Ќ Ќ nd      ",
      "    Зкб nd      ",
      "        ad      ",
      "bammmiicbd      ",
      "ee     ee       ",
      "                ",
      "                ",
      "                ",
      "                ",
      "                ",
      "                "
    ],
    [
      "        c       ",
      "        h       ",
      "        m       ",
      "        h       ",
      "        a       ",
      "        hd      ",
      "l       md      ",
      "l       hd      ",
      "cgjgbgjgad      ",
      "ee     ee       ",
      "                ",
      "                ",
      "                ",
      "                ",
      "                ",
      "                "
    ]
  ]
}