{
  "xsize": 16,
  "zsize": 16,
  "palette": {
    "palette": [
      {
        "char": " ",
        "block": "minecraft:air"
      },
      {
        "char": "l",
        "block": "minecraft:oak_leaves[distance=7,persistent=true,waterlogged=false]"
      },
      {
        "char": "c",
        "block": "minecraft:cracked_stone_bricks"
      },
      {
        "char": "h",
        "block": "minecraft:glass_pane[east=false,north=true,south=true,waterlogged=false,west=false]"
      },
      {
        "char": "f",
        "block": "minecraft:vine[east=true,north=false,south=false,up=false,west=false]"
      },
      {
        "char": "a",
        "block": "minecraft:mossy_cobblestone"
      },
      {
        "char": "m",
        "block": "minecraft:stone_bricks[weathering=false]"
      },
      {
        "char": "n",
        "block": "minecraft:air"
      },
      {
        "char": "g",
        "block": "minecraft:glass_pane[east=true,north=false,south=false,waterlogged=false,west=true]"
      },
      {
        "char": "b",
        "block": "minecraft:mossy_stone_bricks"
      },
      {
        "char": "i",
        "block": "minecraft:cobblestone[weathering=false]"
      },
      {
        "char": "e",
        "block": "minecraft:vine[east=false,north=true,south=false,up=false,west=false]"
      },
      {
        "char": "j",
        "block": "minecraft:stone[weathering=false]"
      },
      {
        "char": "z",
        "block": "minecraft:stone_slab[type=bottom,waterlogged=false,weathering=false]"
      },
      {
        "char": "x",
        "block": "minecraft:light_gray_carpet"
      },
      {
        "char": "І",
        "block": "minecraft:anvil[facing=west]"
      },
      {
        "char": "φ",
        "block": "minecraft:tripwire[attached=false,disarmed=false,east=false,north=false,powered=false,south=false,west=false]"
      },
      {
        "char": "Υ",
        "block": "minecraft:barrel[facing=north,open=false]",
        "loot": "bigbuildingsloot",
        "tag": {
          "z": 583,
          "x": 234,
          "ForgeCaps": {},
          "id": "minecraft:barrel",
          "y": 167,
          "Items": []
        }
      },
      {
        "char": "ϯ",
        "block": "minecraft:end_rod[facing=north]"
      },
      {
        "char": "Т",
        "block": "minecraft:wither_skeleton_wall_skull[facing=south]",
        "tag": {
          "z": 578,
          "x": 233,
          "ForgeCaps": {},
          "id": "minecraft:skull",
          "y": 161
        }
      }
    ]
  },
  "slices": [
    [
      "       lc       ",
      "      llhl  l   ",
      "       fal lllll",
      "       lhllllll ",
      "       fmlll    ",
      "       fh       ",
      "       fc       ",
      "       fh       ",
      "       fngbgcgig",
      "        eeeeeeee",
      "                ",
      "                ",
      "                ",
      "                ",
      "                ",
      "                "
    ],
    [
      "       lbjbcabz ",
      "       fciimmml ",
      "       fbmacball",
      "       facicbbil",
      "       fcciiijbm",
      "       fbaccjicb",
      "       fjbbijccb",
      "       fbibaiiia",
      "       fabbancbn",
      "        eeeeeeee",
      "                ",
      "                ",
      "                ",
      "                ",
      "                ",
      "                "
    ],
    [
      "        axІφІ   ",
      "       fnx    l ",
      "       fb     l ",
      "       fh    lll",
      "       fi   lllx",
      "       f    ll  ",
      "       fcΥlll  x",
      "       fh  ll   ",
      "       fcgagjgcg",
      "        eeeeeeee",
      "                ",
      "                ",
      "                ",
      "                ",
      "                ",
      "                "
    ],
    [
      "        cϯ      ",
      "       fcϯ      ",
      "       fbТ      ",
      "       f        ",
      "       fc    l  ",
      "       f    l   ",
      "       fb   l   ",
      "       f   lll  ",
      "       fbgcgigbg",
      "        eeeeeeee",
      "                ",
      "                ",
      "                ",
      "                ",
      "                ",
      "                "
    ],
    [
      "        b       ",
      "       fa       ",
      "       fm       ",
      "       fa       ",
      "       f        ",
      "       f        ",
      "       f    ll  ",
      "       fn  llll ",
      "       fcnaaaanc",
      "        eeeeeeee",
      "                ",
      "                ",
      "                ",
      "                ",
      "                ",
      "                "
    ],
    [
      "                ",
      "       f        ",
      "       f        ",
      "       f        ",
      "       f        ",
      "       f        ",
      "       f      l ",
      "       f    llll",
      "       fagagcgag",
      "        eeeeeeee",
      "                ",
      "                ",
      "                ",
      "                ",
      "                ",
      "                "
    ]
  ]
}