{
  "xsize": 16,
  "zsize": 16,
  "palette": {
    "palette": [
      {
        "char": " ",
        "block": "minecraft:air"
      },
      {
        "char": "b",
        "block": "minecraft:blackstone"
      },
      {
        "char": "d",
        "block": "minecraft:cobbled_deepslate"
      },
      {
        "char": "a",
        "block": "minecraft:cyan_terracotta"
      },
      {
        "char": "e",
        "block": "minecraft:basalt[axis=y]"
      },
      {
        "char": "c",
        "block": "minecraft:deepslate[axis=y]"
      },
      {
        "char": "为",
        "block": "minecraft:polished_andesite_stairs[facing=north,half=bottom,shape=straight,waterlogged=false]"
      },
      {
        "char": "Ѧ",
        "block": "minecraft:quartz_bricks"
      },
      {
        "char": "J",
        "block": "minecraft:diorite"
      },
      {
        "char": "C",
        "block": "minecraft:quartz_pillar[axis=y]"
      },
      {
        "char": "ϕ",
        "block": "minecraft:quartz_stairs[facing=north,half=bottom,shape=straight,waterlogged=false]"
      },
      {
        "char": "你",
        "block": "minecraft:spawner",
        "tag": {
          "SpawnData": {
            "entity": {}
          },
          "MaxNearbyEntities": "6s",
          "MinSpawnDelay": "200s",
          "z": -274,
          "x": -42,
          "MaxSpawnDelay": "800s",
          "RequiredPlayerRange": "16s",
          "SpawnCount": "4s",
          "id": "minecraft:mob_spawner",
          "SpawnPotentials": [],
          "y": 1,
          "SpawnRange": "4s",
          "Delay": "731s"
        }
      },
      {
        "char": "那",
        "block": "minecraft:white_terracotta"
      },
      {
        "char": "r",
        "block": "minecraft:polished_diorite"
      },
      {
        "char": "K",
        "block": "minecraft:quartz_block"
      },
      {
        "char": "g",
        "block": "minecraft:gray_concrete"
      },
      {
        "char": "其",
        "block": "minecraft:birch_stairs[facing=north,half=bottom,shape=straight,waterlogged=false]"
      },
      {
        "char": "x",
        "block": "minecraft:cauldron"
      },
      {
        "char": "现",
        "block": "minecraft:air"
      },
      {
        "char": "几",
        "block": "minecraft:air"
      },
      {
        "char": "车",
        "block": "minecraft:air"
      },
      {
        "char": "ӝ",
        "block": "minecraft:air"
      },
      {
        "char": "进",
        "block": "minecraft:air"
      },
      {
        "char": "才",
        "block": "minecraft:air"
      },
      {
        "char": "Ӣ",
        "block": "minecraft:air"
      },
      {
        "char": "ϓ",
        "block": "minecraft:air"
      },
      {
        "char": "ӛ",
        "block": "minecraft:air"
      },
      {
        "char": "Ѻ",
        "block": "minecraft:air"
      },
      {
        "char": "P",
        "block": "minecraft:smooth_quartz_slab[type=bottom,waterlogged=false]"
      },
      {
        "char": "Ѯ",
        "block": "minecraft:diorite_slab[type=bottom,waterlogged=false]"
      },
      {
        "char": "i",
        "block": "minecraft:light_gray_concrete"
      },
      {
        "char": "k",
        "block": "minecraft:oak_leaves[distance=7,persistent=true,waterlogged=false]"
      },
      {
        "char": "h",
        "block": "minecraft:andesite_slab[type=top,waterlogged=false]"
      },
      {
        "char": "T",
        "block": "minecraft:redstone_lamp[lit=false]"
      }
    ]
  },
  "slices": [
    [
      "bbddbaaabbdecdeb",
      "bbcacaabcdeeacce",
      "cecdccdbbabcbabc",
      "ecaceebebbebdacd",
      "bcbebeceaebbacec",
      "accabcacabcdcaec",
      "为为为ѦJѦCѦѦaacaeaa",
      "   ϕ     a你aaccd",
      "          那ccabb",
      "          那acdac",
      "          reedab",
      "          rdebdb",
      "          Ѧccaba",
      "          Kdbdce",
      "         agcabdb",
      "         agcdded"
    ],
    [
      "eccabcee        ",
      "其 其 x 其   现     ",
      "           几车 ӝ ",
      "          进才 Ӣϓӛ",
      "              Ѻ ",
      "                ",
      "   PPѮѮPPgi     ",
      "         ga     ",
      "          P     ",
      "          P     ",
      "          P     ",
      "          P     ",
      "          P     ",
      "          P     ",
      "         ia     ",
      "         aa    ӝ"
    ],
    [
      "dedaabcd        ",
      "    k           ",
      "                ",
      "                ",
      "                ",
      "                ",
      "         aa     ",
      "         aa     ",
      "                ",
      "                ",
      "                ",
      "                ",
      "                ",
      "                ",
      "         ag     ",
      "         ga     "
    ],
    [
      "cbccdacb        ",
      "    k           ",
      "                ",
      "                ",
      "                ",
      "                ",
      "         aa     ",
      "         aa     ",
      "                ",
      "                ",
      "                ",
      "                ",
      "                ",
      "                ",
      "         aa     ",
      "         aa     "
    ],
    [
      "ddedcebc        ",
      "                ",
      "                ",
      "                ",
      "                ",
      "                ",
      "         aa     ",
      "         ga     ",
      "                ",
      "                ",
      "                ",
      "                ",
      "                ",
      "                ",
      "         ia     ",
      "         aa     "
    ],
    [
      "acddcebehhhhhhhh",
      "hhhhhhhhhhhhhhhh",
      "hhhhhhhhhhhhhhhh",
      "hhhhhhhhhhhhhhhh",
      "hhhhhhhhhhhhhhhh",
      "hhhhhhhhhhhhhhhh",
      "hThhhhhhhaihhhhh",
      "hhhhhhhhhaahhhhh",
      "hhhhhhhhhhhhhhhh",
      "hhhhThhhhhhhhhhh",
      "hhhhhhhhhhhhhhhh",
      "hhhhhhhhhhhhhhhh",
      "hThhhhhhhhhhhhhh",
      "hhhhhhhhhhhhhhhh",
      "hhhhhhhhhgahhhhh",
      "hhhhThhhhaahhhhh"
    ]
  ]
}