{
  "xsize": 16,
  "zsize": 16,
  "palette": {
    "palette": [
      {
        "char": " ",
        "block": "minecraft:air"
      },
      {
        "char": "i",
        "block": "minecraft:light_gray_concrete"
      },
      {
        "char": "a",
        "block": "minecraft:cyan_terracotta"
      },
      {
        "char": "e",
        "block": "minecraft:basalt[axis=y]"
      },
      {
        "char": "c",
        "block": "minecraft:deepslate[axis=y]"
      },
      {
        "char": "b",
        "block": "minecraft:blackstone"
      },
      {
        "char": "d",
        "block": "minecraft:cobbled_deepslate"
      },
      {
        "char": "g",
        "block": "minecraft:gray_concrete"
      },
      {
        "char": "f",
        "block": "minecraft:glass"
      },
      {
        "char": "O",
        "block": "minecraft:quartz_stairs[facing=west,half=bottom,shape=straight,waterlogged=false]"
      },
      {
        "char": "s",
        "block": "minecraft:iron_trapdoor[facing=north,half=bottom,open=false,powered=false,waterlogged=false]"
      },
      {
        "char": "m",
        "block": "minecraft:iron_trapdoor[facing=west,half=bottom,open=false,powered=false,waterlogged=false]"
      },
      {
        "char": "到",
        "block": "minecraft:air"
      },
      {
        "char": "来",
        "block": "minecraft:air"
      },
      {
        "char": "Ѫ",
        "block": "minecraft:air"
      },
      {
        "char": "Ӝ",
        "block": "minecraft:air"
      },
      {
        "char": "p",
        "block": "minecraft:iron_trapdoor[facing=north,half=top,open=false,powered=false,waterlogged=false]"
      },
      {
        "char": "q",
        "block": "minecraft:iron_trapdoor[facing=west,half=top,open=false,powered=false,waterlogged=false]"
      }
    ]
  },
  "slices": [
    [
      "             iae",
      "             aai",
      "            acab",
      "            acac",
      "           aaaca",
      "           aaaed",
      "          gdadbc",
      "          aeaedb",
      "           dabcb",
      "           ciddb",
      "          bgbeed",
      "          cgdebc",
      "          eabace",
      "          egeadc",
      "         acaabba",
      "          agbbce"
    ],
    [
      "             a  ",
      "              df",
      "              f ",
      "              f ",
      "             f  ",
      "             f  ",
      "            f   ",
      "          abg  d",
      "            f Oe",
      "            f  b",
      "           f    ",
      "           f   e",
      "           f  Oe",
      "           f   a",
      "         abgacca",
      "           f    "
    ],
    [
      "             a s",
      "              d ",
      "             sf ",
      "             mf ",
      "            mf  ",
      "            mf  ",
      "           mf   ",
      "          ada   ",
      "           mf  到",
      "           mf  来",
      "          mf    ",
      "          mf    ",
      "          mf   Ѫ",
      "          m    Ӝ",
      "         adadabe",
      "          mf    "
    ],
    [
      "             a p",
      "              bf",
      "             qf ",
      "             qf ",
      "            qf  ",
      "            q   ",
      "           qf   ",
      "          ibi   ",
      "           qf   ",
      "           q    ",
      "          q     ",
      "          qf    ",
      "          qf    ",
      "          q     ",
      "         acgbebe",
      "          qf    "
    ],
    [
      "             a  ",
      "              df",
      "              f ",
      "              f ",
      "             f  ",
      "             f  ",
      "            f   ",
      "          aag   ",
      "                ",
      "                ",
      "           f    ",
      "           f    ",
      "           f    ",
      "                ",
      "         adgcccd",
      "           f    "
    ],
    [
      "             a a",
      "              ag",
      "             ai ",
      "             da ",
      "            aa  ",
      "            ba  ",
      "           eg   ",
      "          aba   ",
      "           aa   ",
      "           ba   ",
      "          ea    ",
      "          aa    ",
      "          ag    ",
      "          ea    ",
      "         adababc",
      "          ca    "
    ]
  ]
}