{
  "xsize": 16,
  "zsize": 16,
  "palette": {
    "palette": [
      {
        "char": " ",
        "block": "minecraft:air"
      },
      {
        "char": "R",
        "block": "minecraft:yellow_concrete"
      },
      {
        "char": "ϖ",
        "block": "minecraft:yellow_terracotta"
      },
      {
        "char": "d",
        "block": "minecraft:cobbled_deepslate"
      },
      {
        "char": "c",
        "block": "minecraft:deepslate[axis=y]"
      },
      {
        "char": "Ӥ",
        "block": "minecraft:stone_brick_wall[east=none,north=tall,south=none,up=true,waterlogged=false,weathering=false,west=none]"
      },
      {
        "char": "e",
        "block": "minecraft:basalt[axis=y]"
      },
      {
        "char": "a",
        "block": "minecraft:cyan_terracotta"
      },
      {
        "char": "Ҡ",
        "block": "minecraft:yellow_wool"
      },
      {
        "char": "b",
        "block": "minecraft:blackstone"
      },
      {
        "char": "g",
        "block": "minecraft:gray_concrete"
      },
      {
        "char": "ϗ",
        "block": "minecraft:stone_brick_wall[east=none,north=none,south=none,up=true,waterlogged=false,weathering=false,west=none]"
      },
      {
        "char": "á",
        "block": "minecraft:cobblestone_wall[east=none,north=none,south=none,up=true,waterlogged=false,weathering=false,west=none]"
      },
      {
        "char": "用",
        "block": "minecraft:iron_bars[east=true,north=true,south=true,waterlogged=false,west=false]"
      },
      {
        "char": "过",
        "block": "minecraft:cobblestone_wall[east=low,north=none,south=none,up=false,waterlogged=false,weathering=false,west=low]"
      },
      {
        "char": "都",
        "block": "minecraft:cobblestone_wall[east=none,north=tall,south=none,up=true,waterlogged=false,weathering=false,west=none]"
      },
      {
        "char": "ѫ",
        "block": "minecraft:quartz_slab[type=bottom,waterlogged=false]"
      },
      {
        "char": "f",
        "block": "minecraft:glass"
      },
      {
        "char": "n",
        "block": "minecraft:smooth_quartz"
      },
      {
        "char": "K",
        "block": "minecraft:quartz_block"
      },
      {
        "char": "C",
        "block": "minecraft:quartz_pillar[axis=y]"
      },
      {
        "char": "i",
        "block": "minecraft:light_gray_concrete"
      },
      {
        "char": "各",
        "block": "minecraft:air"
      },
      {
        "char": "o",
        "block": "minecraft:chiseled_quartz_block"
      }
    ]
  },
  "slices": [
    [
      "         Rϖdc Ӥ ",
      "       Rϖcc     ",
      "      Rea       ",
      "     Ҡb         ",
      "    Ҡb          ",
      "  g Rd          ",
      "   Re      ϗ  ϗ ",
      "   Rb           ",
      "  ϖa            ",
      "  Ra   d        ",
      " Rb        á  á ",
      " Rd             ",
      " ϖe             ",
      " ϖd             ",
      " ϖe             ",
      " 用a             "
    ],
    [
      "         RRcd Ӥ ",
      "       ϖRdd     ",
      "      ϖba       ",
      "     Ra         ",
      "    Rd          ",
      "  a Rb          ",
      "   Ҡe      á  ϗ ",
      "   Ra           ",
      "  Ҡe            ",
      "  ϖd   d        ",
      " Rc        ϗ  á ",
      "过Ҡa             ",
      " ϖa             ",
      "过Ra             ",
      " 用b             ",
      " 用a             "
    ],
    [
      "         Rϖbe 都 ",
      "       ϖϖed     ",
      "      Rdc       ",
      "     ϖe         ",
      "    Ҡb          ",
      "  g Re          ",
      "   ϖa      ϗ  ϗ ",
      "   ϖe           ",
      "  ϖe            ",
      "  Rc   c        ",
      " Rd        ϗ  á ",
      " ϖc             ",
      " Ҡc             ",
      " Rc             ",
      " ϖb             ",
      " ϖd             "
    ],
    [
      "         cddbcde",
      "       bbbacaeec",
      "      decaccddeb",
      "     dcbeadedabb",
      "    ecedbcdcdeec",
      "  a eedecaceedad",
      "   adbcaedaebbcd",
      "   acbdaaacaaabe",
      "  bdcbacaccabcbd",
      "  aeadaaadaaadcc",
      " cbcdaebbeecbacc",
      " abbcaeeeddaecec",
      " aedeababbdcbcbe",
      " ccaabdeaaaddcad",
      " edcbbddebddcccb",
      " adddaceecabaceb"
    ],
    [
      "       ѫѫbdbdecb",
      "      ѫadaebddea",
      "     ѫaecbadacbc",
      "    ѫdadcdcdacdd",
      "   ѫecbacceeaace",
      "  aѫdcacceeaecab",
      "  ѫdacbcdbdcadec",
      "  ѫacdceeadeacac",
      " ѫbeeebabaeeceba",
      " ѫbabcadccecddce",
      "ѫcacceacdcdbacbb",
      "ѫabdeeabdbcecdbb",
      "ѫddaccbcaedeecdf",
      "ѫbbccaedcededebb",
      "ѫbdeeaceeacbbaac",
      "ѫeeddabbceeebebc"
    ],
    [
      "         an     ",
      "       KC a     ",
      "      K         ",
      "     C          ",
      "    n           ",
      "  a C           ",
      "   a            ",
      "   Ci           ",
      "  C      ϗ  á   ",
      "  C    ϗ        ",
      " n              ",
      " C e            ",
      " C     ϗ       各",
      " C d     ϗ  ϗ   ",
      " C              ",
      " o              "
    ]
  ]
}