{
  "xsize": 16,
  "zsize": 16,
  "palette": {
    "palette": [
      {
        "char": " ",
        "block": "minecraft:air"
      },
      {
        "char": "a",
        "block": "minecraft:cyan_terracotta"
      },
      {
        "char": "d",
        "block": "minecraft:cobbled_deepslate"
      },
      {
        "char": "c",
        "block": "minecraft:deepslate[axis=y]"
      },
      {
        "char": "b",
        "block": "minecraft:blackstone"
      },
      {
        "char": "e",
        "block": "minecraft:basalt[axis=y]"
      },
      {
        "char": "Р",
        "block": "minecraft:stone_brick_stairs[facing=north,half=bottom,shape=straight,waterlogged=false,weathering=false]"
      },
      {
        "char": "z",
        "block": "minecraft:iron_bars[east=false,north=true,south=true,waterlogged=false,west=false]"
      },
      {
        "char": "Y",
        "block": "minecraft:iron_bars[east=false,north=true,south=false,waterlogged=false,west=false]"
      },
      {
        "char": "O",
        "block": "minecraft:quartz_stairs[facing=west,half=bottom,shape=straight,waterlogged=false]"
      },
      {
        "char": "П",
        "block": "minecraft:barrel[facing=up,open=false]",
        "tag": {
          "z": -275,
          "x": -15,
          "ForgeData": {
            "LockFlag": "1b"
          },
          "id": "minecraft:barrel",
          "y": 2,
          "Items": []
        }
      },
      {
        "char": "x",
        "block": "minecraft:cauldron"
      },
      {
        "char": "У",
        "block": "minecraft:stone_brick_stairs[facing=south,half=bottom,shape=straight,waterlogged=false,weathering=false]"
      },
      {
        "char": "С",
        "block": "minecraft:stone_brick_stairs[facing=north,half=top,shape=straight,waterlogged=false,weathering=false]"
      },
      {
        "char": "f",
        "block": "minecraft:glass"
      },
      {
        "char": "Ѫ",
        "block": "minecraft:air"
      },
      {
        "char": "到",
        "block": "minecraft:air"
      },
      {
        "char": "Ѵ",
        "block": "minecraft:white_stained_glass_pane[east=false,north=false,south=false,waterlogged=false,west=true]"
      },
      {
        "char": "k",
        "block": "minecraft:oak_leaves[distance=7,persistent=true,waterlogged=false]"
      },
      {
        "char": "N",
        "block": "minecraft:white_stained_glass_pane[east=true,north=false,south=false,waterlogged=false,west=true]"
      },
      {
        "char": "у",
        "block": "minecraft:stone_brick_stairs[facing=south,half=top,shape=straight,waterlogged=false,weathering=false]"
      },
      {
        "char": "j",
        "block": "minecraft:polished_andesite_slab[type=top,waterlogged=false]"
      }
    ]
  },
  "slices": [
    [
      "adcadbcbadcedbbb",
      "dcecebbebbdceeee",
      "dcdaeadadadcacba",
      "ecdcddecedbaadbc",
      "acbecebebdadceec",
      "dcadccadbdbaaddb",
      "cbdedcccbcdacced",
      "ddceceadaebadddb",
      "baddbcaacddebbdd",
      "cecebaeabdaeddaa",
      "acebdacebcccadda",
      "ddcaaddddbdecece",
      "ddbcddeabbdcРz a",
      "cddaeeeadebd z e",
      "aaaabdecdaae Y c",
      "ceedbbdaccea   a"
    ],
    [
      "    Oe    e     ",
      "     b          ",
      "                ",
      "  c  c    d     ",
      " Oa Oa    bdedbd",
      "  c  П     c  x ",
      "           e    ",
      "  a  c          ",
      " Od Ob          ",
      "  b  e          ",
      "           c    ",
      "  c  d     d b e",
      " Ob Oc     e zУe",
      "  c  e     a zСb",
      "eccdaad   ec Y b",
      "  b  e     c   a"
    ],
    [
      "f    Ѫ    e     ",
      "                ",
      "                ",
      "          a     ",
      "  到  Ѫ    bacѴ  ",
      "           d  k ",
      "           a    ",
      "                ",
      "  Ѫ  Ѫ          ",
      "                ",
      "           b    ",
      "           b b e",
      "  Ѫ  Ѫ     d z b",
      "           e zУd",
      "cccbade   bc YСb",
      "     d     e   d"
    ],
    [
      "f         d     ",
      "                ",
      "                ",
      "          c     ",
      "          cebNNN",
      "           e  k ",
      "           a    ",
      "                ",
      "                ",
      "                ",
      "           a    ",
      "           a b e",
      "           e z c",
      "           e z a",
      "daeecdc   bdуzУb",
      "     e     aeebe"
    ],
    [
      "          e     ",
      "          j     ",
      "          j     ",
      "          d     ",
      "          cdcbea",
      "           b    ",
      "           d    ",
      "           j    ",
      "           j    ",
      "           j    ",
      "           d    ",
      "           deead",
      "           e z a",
      "           cуz d",
      "ddabcabjjjeeРY b",
      "     e     d   a"
    ],
    [
      "a         d     ",
      "          a     ",
      "          d     ",
      "          a     ",
      "          baecbb",
      "           b    ",
      "           e    ",
      "           b    ",
      "           e    ",
      "           b    ",
      "           e    ",
      "           decda",
      "           bуz b",
      "           aРz d",
      "cacacbbbaace Y a",
      "     e     a   a"
    ]
  ]
}