{
  "xsize": 16,
  "zsize": 16,
  "palette": {
    "palette": [
      {
        "char": " ",
        "block": "minecraft:air"
      },
      {
        "char": "g",
        "block": "minecraft:gray_concrete"
      },
      {
        "char": "a",
        "block": "minecraft:cyan_terracotta"
      },
      {
        "char": "e",
        "block": "minecraft:basalt[axis=y]"
      },
      {
        "char": "d",
        "block": "minecraft:cobbled_deepslate"
      },
      {
        "char": "b",
        "block": "minecraft:blackstone"
      },
      {
        "char": "c",
        "block": "minecraft:deepslate[axis=y]"
      },
      {
        "char": "i",
        "block": "minecraft:light_gray_concrete"
      },
      {
        "char": "f",
        "block": "minecraft:glass"
      },
      {
        "char": "ϕ",
        "block": "minecraft:quartz_stairs[facing=north,half=bottom,shape=straight,waterlogged=false]"
      },
      {
        "char": "O",
        "block": "minecraft:quartz_stairs[facing=west,half=bottom,shape=straight,waterlogged=false]"
      },
      {
        "char": "ϓ",
        "block": "minecraft:air"
      },
      {
        "char": "ϔ",
        "block": "minecraft:quartz_stairs[facing=east,half=bottom,shape=straight,waterlogged=false]"
      },
      {
        "char": "s",
        "block": "minecraft:iron_trapdoor[facing=north,half=bottom,open=false,powered=false,waterlogged=false]"
      },
      {
        "char": "如",
        "block": "minecraft:air"
      },
      {
        "char": "l",
        "block": "minecraft:iron_trapdoor[facing=east,half=bottom,open=false,powered=false,waterlogged=false]"
      },
      {
        "char": "Ҝ",
        "block": "minecraft:air",
        "tag": {
          "z": -292,
          "x": -29,
          "id": "refurbished_furniture:computer",
          "y": 63,
          "NodePos": "-7696582590401L",
          "Connections": [
            "L"
          ]
        }
      },
      {
        "char": "p",
        "block": "minecraft:iron_trapdoor[facing=north,half=top,open=false,powered=false,waterlogged=false]"
      }
    ]
  },
  "slices": [
    [
      "                ",
      "                ",
      "                ",
      "                ",
      "                ",
      "                ",
      " g              ",
      "aeadba  aa      ",
      "aaaagacaeaaa    ",
      "aabaacgiaaabgg  ",
      "edabdcaecbaabbaa",
      "acccdecbdaabaaba",
      "dccdcceddabdacia",
      "edddaeeeeeecbedi",
      "adecdeecdeabbbcd",
      "eccdbbbdddbdddad"
    ],
    [
      "                ",
      "                ",
      "                ",
      "                ",
      "                ",
      "                ",
      " a              ",
      " c      i       ",
      " af  f  c       ",
      " d    ffgf      ",
      " a      c      a",
      " e      d    fb ",
      " c c ϕ  c     f ",
      " b d    c       ",
      " a daeaad  ϕ    ",
      " c      c Oϓϔ   "
    ],
    [
      "                ",
      "                ",
      "                ",
      "                ",
      "                ",
      "                ",
      " a              ",
      "sdssss  a       ",
      "faf f s如bs      ",
      " c    f gfss    ",
      " e      a f ss g",
      " c      e   ffa ",
      " b      e     fl",
      " c      b       ",
      " b  Ҝ Ҝ d       ",
      " b      c       "
    ],
    [
      "                ",
      "                ",
      "                ",
      "                ",
      "                ",
      "                ",
      " a              ",
      "pepppp  g       ",
      "faf ffppep      ",
      " c    ffifpp    ",
      " c      d f pp a",
      " b      b     a ",
      " d      b      p",
      " a      a      f",
      " b      c       ",
      " c      e       "
    ],
    [
      "                ",
      "                ",
      "                ",
      "                ",
      "                ",
      "                ",
      " a              ",
      " e      a       ",
      "fa ff   e       ",
      " e    ffaf      ",
      " b      c ff   a",
      " a      e    fe ",
      " d      a     f ",
      " d      e      f",
      " b      a       ",
      " d      c       "
    ],
    [
      "                ",
      "                ",
      "                ",
      "                ",
      "                ",
      "                ",
      " a              ",
      "ebbaae  i       ",
      "aaagaababe      ",
      " d    agaabc    ",
      " c      e aaac g",
      " e      d   igd ",
      " a      e     gc",
      " c      c      a",
      " a      e       ",
      " e      a       "
    ]
  ]
}