{
  "xsize": 16,
  "zsize": 16,
  "palette": {
    "palette": [
      {
        "char": " ",
        "block": "minecraft:air"
      },
      {
        "char": "b",
        "block": "minecraft:blackstone"
      },
      {
        "char": "c",
        "block": "minecraft:deepslate[axis=y]"
      },
      {
        "char": "a",
        "block": "minecraft:cyan_terracotta"
      },
      {
        "char": "e",
        "block": "minecraft:basalt[axis=y]"
      },
      {
        "char": "d",
        "block": "minecraft:cobbled_deepslate"
      },
      {
        "char": "ϕ",
        "block": "minecraft:quartz_stairs[facing=north,half=bottom,shape=straight,waterlogged=false]"
      },
      {
        "char": "O",
        "block": "minecraft:quartz_stairs[facing=west,half=bottom,shape=straight,waterlogged=false]"
      },
      {
        "char": "ϔ",
        "block": "minecraft:quartz_stairs[facing=east,half=bottom,shape=straight,waterlogged=false]"
      },
      {
        "char": "H",
        "block": "minecraft:quartz_stairs[facing=south,half=bottom,shape=straight,waterlogged=false]"
      },
      {
        "char": "x",
        "block": "minecraft:cauldron"
      },
      {
        "char": "k",
        "block": "minecraft:oak_leaves[distance=7,persistent=true,waterlogged=false]"
      },
      {
        "char": "该",
        "block": "minecraft:air"
      },
      {
        "char": "者",
        "block": "minecraft:air"
      },
      {
        "char": "言",
        "block": "minecraft:air"
      },
      {
        "char": "进",
        "block": "minecraft:air"
      },
      {
        "char": "你",
        "block": "minecraft:spawner",
        "tag": {
          "SpawnData": {
            "entity": {}
          },
          "MaxNearbyEntities": "6s",
          "MinSpawnDelay": "200s",
          "z": -274,
          "x": -42,
          "MaxSpawnDelay": "800s",
          "RequiredPlayerRange": "16s",
          "SpawnCount": "4s",
          "id": "minecraft:mob_spawner",
          "SpawnPotentials": [],
          "y": 1,
          "SpawnRange": "4s",
          "Delay": "731s"
        }
      },
      {
        "char": "I",
        "block": "minecraft:stone_slab[type=top,waterlogged=false,weathering=false]"
      }
    ]
  },
  "slices": [
    [
      "bcaeaeaeabcaeeab",
      "bbddaaedeeacadce",
      "eeaacdedeedaecaa",
      "cbaddaeacbeaabcb",
      "ceeeaccceedbcaad",
      "accabbceccdaecee",
      "aeeaaeabcbbbcace",
      "beacccabbdceacea",
      "ebaabbcabbededdb",
      "dabdaebdcaccdeac",
      "bddaeeacdebbbbbd",
      "babbacdadacbbebb",
      "   daabccbedccce",
      "    edaaeabeaaab",
      "     dccecabeeac",
      "      bcbbbbbaaa"
    ],
    [
      "eeeadebb        ",
      " b              ",
      " d           dad",
      " e          ddcb",
      "cda   ebb aϕecbc",
      " a      b Odϔade",
      "        abcHdeed",
      "       xcdabdaba",
      "        ddaebbcc",
      "      kkdcbbccbe",
      "       ccddcdcdb",
      "      aebaed    ",
      "      caca      ",
      "     cabc a     ",
      "        d   该   ",
      "        c  者言进  "
    ],
    [
      "adecbccd        ",
      " b              ",
      " d              ",
      " d           beb",
      "dcd   aad   ecbd",
      " b      a  cbeae",
      "        e  dbbbb",
      "       kc  daece",
      "        e ecd你ca",
      "        a bbad  ",
      "        c cda   ",
      "       de da    ",
      "       edd      ",
      "     ccba a     ",
      "        d       ",
      "        d       "
    ],
    [
      "eaacbabd        ",
      " d              ",
      " b              ",
      " d              ",
      "ddb   ada     db",
      " c      e    cbe",
      "        c   bcaa",
      "       ke   eaad",
      "        a  dad  ",
      "        d  db   ",
      "        d   d   ",
      "        d dc    ",
      " a      ba      ",
      "     beae a     ",
      "        c       ",
      "        b       "
    ],
    [
      "debedaec        ",
      " a              ",
      " a              ",
      " b              ",
      "acbIIIdbb       ",
      " a      b      c",
      " I      b    bcb",
      " I      c   cc  ",
      " I      b       ",
      " I      c       ",
      " I      b       ",
      " I      e eb    ",
      " c      ec      ",
      "badIIddbc a     ",
      "        b       ",
      "        a       "
    ],
    [
      "acaebdcd        ",
      " e              ",
      " d              ",
      " c              ",
      "ccbaadced       ",
      " c      c       ",
      " d      e       ",
      " d      d       ",
      " b      e       ",
      " d      d       ",
      " d      a       ",
      " b      a       ",
      " b              ",
      "cbacaebb        ",
      " c              ",
      "                "
    ]
  ]
}