{
  "xsize": 16,
  "zsize": 16,
  "palette": {
    "palette": [
      {
        "char": " ",
        "block": "minecraft:air"
      },
      {
        "char": "a",
        "block": "minecraft:cyan_terracotta"
      },
      {
        "char": "b",
        "block": "minecraft:blackstone"
      },
      {
        "char": "c",
        "block": "minecraft:deepslate[axis=y]"
      },
      {
        "char": "d",
        "block": "minecraft:cobbled_deepslate"
      },
      {
        "char": "e",
        "block": "minecraft:basalt[axis=y]"
      },
      {
        "char": "Р",
        "block": "minecraft:stone_brick_stairs[facing=north,half=bottom,shape=straight,waterlogged=false,weathering=false]"
      },
      {
        "char": "z",
        "block": "minecraft:iron_bars[east=false,north=true,south=true,waterlogged=false,west=false]"
      },
      {
        "char": "Y",
        "block": "minecraft:iron_bars[east=false,north=true,south=false,waterlogged=false,west=false]"
      },
      {
        "char": "f",
        "block": "minecraft:glass"
      },
      {
        "char": "O",
        "block": "minecraft:quartz_stairs[facing=west,half=bottom,shape=straight,waterlogged=false]"
      },
      {
        "char": "x",
        "block": "minecraft:cauldron"
      },
      {
        "char": "П",
        "block": "minecraft:barrel[facing=up,open=false]",
        "tag": {
          "z": -275,
          "x": -15,
          "ForgeData": {
            "LockFlag": "1b"
          },
          "id": "minecraft:barrel",
          "y": 2,
          "Items": []
        }
      },
      {
        "char": "У",
        "block": "minecraft:stone_brick_stairs[facing=south,half=bottom,shape=straight,waterlogged=false,weathering=false]"
      },
      {
        "char": "С",
        "block": "minecraft:stone_brick_stairs[facing=north,half=top,shape=straight,waterlogged=false,weathering=false]"
      },
      {
        "char": "Ѫ",
        "block": "minecraft:air"
      },
      {
        "char": "N",
        "block": "minecraft:white_stained_glass_pane[east=true,north=false,south=false,waterlogged=false,west=true]"
      },
      {
        "char": "Ѵ",
        "block": "minecraft:white_stained_glass_pane[east=false,north=false,south=false,waterlogged=false,west=true]"
      },
      {
        "char": "k",
        "block": "minecraft:oak_leaves[distance=7,persistent=true,waterlogged=false]"
      },
      {
        "char": "生",
        "block": "minecraft:white_stained_glass_pane[east=false,north=false,south=false,waterlogged=false,west=false]"
      },
      {
        "char": "у",
        "block": "minecraft:stone_brick_stairs[facing=south,half=top,shape=straight,waterlogged=false,weathering=false]"
      },
      {
        "char": "j",
        "block": "minecraft:polished_andesite_slab[type=top,waterlogged=false]"
      }
    ]
  },
  "slices": [
    [
      "abcaaacbddadedac",
      "edadadeabdebddeb",
      "cbcbbbaabeeeceea",
      "bcedcbaedeaacded",
      "bbadaaaadabcceca",
      "dcecbdbebecadcde",
      "dcbabdeadabebedc",
      "bbbcacbeedcedeaa",
      "eaacbeddcabaebba",
      "bdddadcabecdacbe",
      "cedecdaecacbabbc",
      "aabdbbddeddbaaad",
      "dadeeaebbdcaРz c",
      "eedbcebdcaba z c",
      "cdbdedcbcdea Y a",
      "bbbeeaccdbbb   d"
    ],
    [
      "f   Od    e     ",
      "     b          ",
      "                ",
      "  c  c    a     ",
      " Od Oe    bceeee",
      "  c  b     d  x ",
      "           a    ",
      "  b  П          ",
      " Oc Oa          ",
      "  a  e          ",
      "           a    ",
      "  e  d     c a c",
      " Oe Od     b zУd",
      "  c  a     e zСc",
      "cedaaee   cd Y c",
      "  d  c     b   d"
    ],
    [
      "f    Ѫ    b     ",
      "                ",
      "                ",
      "          b     ",
      "  Ѫ  Ѫ    edcNѴ ",
      "           d  k ",
      "           b    ",
      "                ",
      "  Ѫ  Ѫ          ",
      "                ",
      "           d    ",
      "           b d a",
      "  Ѫ  Ѫ     a z c",
      "           a zУa",
      "abadaca   da YСb",
      "     e     c   c"
    ],
    [
      "f         c     ",
      "                ",
      "                ",
      "          a     ",
      "          dae 生 ",
      "           e  k ",
      "           a    ",
      "                ",
      "                ",
      "                ",
      "           d    ",
      "           a c d",
      "           d z e",
      "           d z b",
      "ebdbeab   edуzУc",
      "     e     bcdac"
    ],
    [
      "          b     ",
      "          j     ",
      "          j     ",
      "          d     ",
      "          deeeed",
      "           e    ",
      "           a    ",
      "           j    ",
      "           j    ",
      "           j    ",
      "           b    ",
      "           dacdc",
      "           d z e",
      "           eуz e",
      "cebeaccjjjaeРY e",
      "     a     d   a"
    ],
    [
      "a         a     ",
      "          b     ",
      "          b     ",
      "          e     ",
      "          dccecc",
      "           c    ",
      "           c    ",
      "           c    ",
      "           b    ",
      "           b    ",
      "           b    ",
      "           ddbcd",
      "           cуz b",
      "           bРz e",
      "daaedbbcdeaa Y a",
      "     e     d   d"
    ]
  ]
}