{
  "xsize": 16,
  "zsize": 16,
  "palette": {
    "palette": [
      {
        "char": " ",
        "block": "minecraft:air"
      },
      {
        "char": "a",
        "block": "minecraft:cyan_terracotta"
      },
      {
        "char": "d",
        "block": "minecraft:cobbled_deepslate"
      },
      {
        "char": "c",
        "block": "minecraft:deepslate[axis=y]"
      },
      {
        "char": "b",
        "block": "minecraft:blackstone"
      },
      {
        "char": "g",
        "block": "minecraft:gray_concrete"
      },
      {
        "char": "e",
        "block": "minecraft:basalt[axis=y]"
      },
      {
        "char": "f",
        "block": "minecraft:glass"
      },
      {
        "char": "ϕ",
        "block": "minecraft:quartz_stairs[facing=north,half=bottom,shape=straight,waterlogged=false]"
      },
      {
        "char": "O",
        "block": "minecraft:quartz_stairs[facing=west,half=bottom,shape=straight,waterlogged=false]"
      },
      {
        "char": "ϓ",
        "block": "minecraft:air"
      },
      {
        "char": "ϔ",
        "block": "minecraft:quartz_stairs[facing=east,half=bottom,shape=straight,waterlogged=false]"
      },
      {
        "char": "s",
        "block": "minecraft:iron_trapdoor[facing=north,half=bottom,open=false,powered=false,waterlogged=false]"
      },
      {
        "char": "l",
        "block": "minecraft:iron_trapdoor[facing=east,half=bottom,open=false,powered=false,waterlogged=false]"
      },
      {
        "char": "很",
        "block": "minecraft:air"
      },
      {
        "char": "天",
        "block": "minecraft:air"
      },
      {
        "char": "p",
        "block": "minecraft:iron_trapdoor[facing=north,half=top,open=false,powered=false,waterlogged=false]"
      },
      {
        "char": "说",
        "block": "minecraft:air"
      }
    ]
  },
  "slices": [
    [
      "                ",
      "                ",
      "                ",
      "                ",
      "                ",
      "                ",
      " a              ",
      "dcab            ",
      "aaag            ",
      "acdd            ",
      "ebdb           a",
      "aaaba         ca",
      "dedead       cac",
      "adcbcbe     edaa",
      "daaeadadeebeadce",
      "abdbdeecaedcbccd"
    ],
    [
      "                ",
      "                ",
      "                ",
      "                ",
      "                ",
      "                ",
      " a              ",
      "be              ",
      "aaf             ",
      "eaea            ",
      "eebe           a",
      "ee ad         e ",
      " b e ϕ          ",
      " d e            ",
      " c cbbebc  ϕ    ",
      " d      a Oϓϔ   "
    ],
    [
      "                ",
      "                ",
      "                ",
      "                ",
      "                ",
      "                ",
      " a              ",
      "sess            ",
      "egff            ",
      "dc              ",
      "bb             a",
      " b            c ",
      " b            fl",
      " e             f",
      " b 很天 天很b       ",
      " d      d       "
    ],
    [
      "                ",
      "                ",
      "                ",
      "                ",
      "                ",
      "                ",
      " a              ",
      "pbp说p           ",
      " af f           ",
      " b              ",
      " a             a",
      " e           fc ",
      " c            fp",
      " a      a      f",
      " d      c       ",
      " e      c       "
    ],
    [
      "                ",
      "                ",
      "                ",
      "                ",
      "                ",
      "                ",
      "                ",
      "                ",
      "fe              ",
      " c              ",
      " d             a",
      " b          f b ",
      " b      a     f ",
      " e      d      f",
      " d      e       ",
      " b      c       "
    ],
    [
      "                ",
      "                ",
      "                ",
      "                ",
      "                ",
      "                ",
      "                ",
      "                ",
      "                ",
      "                ",
      " b         aca a",
      " d      e   aad ",
      " d      d     ac",
      " c      a      g",
      " b      e       ",
      " a      b       "
    ]
  ]
}