{
  "xsize": 16,
  "zsize": 16,
  "palette": {
    "palette": [
      {
        "char": " ",
        "block": "minecraft:air"
      },
      {
        "char": "d",
        "block": "minecraft:cobbled_deepslate"
      },
      {
        "char": "c",
        "block": "minecraft:deepslate[axis=y]"
      },
      {
        "char": "a",
        "block": "minecraft:cyan_terracotta"
      },
      {
        "char": "b",
        "block": "minecraft:blackstone"
      },
      {
        "char": "i",
        "block": "minecraft:light_gray_concrete"
      },
      {
        "char": "g",
        "block": "minecraft:gray_concrete"
      },
      {
        "char": "e",
        "block": "minecraft:basalt[axis=y]"
      },
      {
        "char": "f",
        "block": "minecraft:glass"
      },
      {
        "char": "ϔ",
        "block": "minecraft:quartz_stairs[facing=east,half=bottom,shape=straight,waterlogged=false]"
      },
      {
        "char": "П",
        "block": "minecraft:barrel[facing=up,open=false]",
        "tag": {
          "z": -275,
          "x": -15,
          "ForgeData": {
            "LockFlag": "1b"
          },
          "id": "minecraft:barrel",
          "y": 2,
          "Items": []
        }
      },
      {
        "char": "s",
        "block": "minecraft:iron_trapdoor[facing=north,half=bottom,open=false,powered=false,waterlogged=false]"
      },
      {
        "char": "l",
        "block": "minecraft:iron_trapdoor[facing=east,half=bottom,open=false,powered=false,waterlogged=false]"
      },
      {
        "char": "Ӻ",
        "block": "minecraft:air",
        "tag": {
          "z": -276,
          "x": -15,
          "id": "refurbished_furniture:computer",
          "y": 27,
          "NodePos": "-3848291827685L",
          "Connections": [
            "L"
          ]
        }
      },
      {
        "char": "p",
        "block": "minecraft:iron_trapdoor[facing=north,half=top,open=false,powered=false,waterlogged=false]"
      },
      {
        "char": "t",
        "block": "minecraft:iron_trapdoor[facing=east,half=top,open=false,powered=false,waterlogged=false]"
      }
    ]
  },
  "slices": [
    [
      "dcabig          ",
      "eecgea          ",
      "babcada         ",
      "bdbcada         ",
      "abeeaaci        ",
      "ddeedaca        ",
      "ebbaedacg       ",
      "deadcdaca       ",
      "cbabedic        ",
      "baeedcaa        ",
      "dcacbecge       ",
      "cecceabac       ",
      "eddaeccad       ",
      "badacedac       ",
      "dceeaebgag      ",
      "ceededaaa       "
    ],
    [
      "     g          ",
      "   fe           ",
      "ϔ   f           ",
      "    f           ",
      "     f          ",
      "     f          ",
      "      f         ",
      "ecaedbaca       ",
      "      f         ",
      "      f         ",
      " Пdb   f        ",
      " d     f        ",
      " c ϔ   f        ",
      " a     f        ",
      "deddbcaada      ",
      "b      f        "
    ],
    [
      "  fs a          ",
      "    b           ",
      "    fl          ",
      "    fl          ",
      "     fl         ",
      "     fl         ",
      "      fl        ",
      "dacddaaai       ",
      "       l        ",
      "      fl        ",
      "       fl       ",
      "       fl       ",
      " Ӻ     fl       ",
      "       fl       ",
      "ddbaebbaei      ",
      "       fl       "
    ],
    [
      "  fp a          ",
      "   fc           ",
      "     t          ",
      "     t          ",
      "     ft         ",
      "     ft         ",
      "      ft        ",
      "baacbbaea       ",
      "      ft        ",
      "      ft        ",
      "       ft       ",
      "        t       ",
      "       ft       ",
      "       ft       ",
      "cecdacagbg      ",
      "       ft       "
    ],
    [
      "  f  a          ",
      "   fd           ",
      "    f           ",
      "    f           ",
      "     f          ",
      "     f          ",
      "      f         ",
      "cdeabbaca       ",
      "      f         ",
      "      f         ",
      "       f        ",
      "       f        ",
      "       f        ",
      "                ",
      "eabaabbaea      ",
      "       f        "
    ],
    [
      "  ac g          ",
      "   ad           ",
      "    ab          ",
      "    ad          ",
      "     ab         ",
      "     ge         ",
      "      ie        ",
      "cadcebicg       ",
      "      ae        ",
      "      ab        ",
      "       ia       ",
      "       gb       ",
      "       ac       ",
      "       ae       ",
      "cdadebegda      ",
      "       id       "
    ]
  ]
}