{
  "xsize": 16,
  "zsize": 16,
  "palette": {
    "palette": [
      {
        "char": " ",
        "block": "minecraft:air"
      },
      {
        "char": "e",
        "block": "minecraft:basalt[axis=y]"
      },
      {
        "char": "a",
        "block": "minecraft:cyan_terracotta"
      },
      {
        "char": "c",
        "block": "minecraft:deepslate[axis=y]"
      },
      {
        "char": "d",
        "block": "minecraft:cobbled_deepslate"
      },
      {
        "char": "b",
        "block": "minecraft:blackstone"
      },
      {
        "char": "g",
        "block": "minecraft:gray_concrete"
      },
      {
        "char": "i",
        "block": "minecraft:light_gray_concrete"
      },
      {
        "char": "H",
        "block": "minecraft:quartz_stairs[facing=south,half=bottom,shape=straight,waterlogged=false]"
      },
      {
        "char": "f",
        "block": "minecraft:glass"
      },
      {
        "char": "ο",
        "block": "minecraft:air"
      },
      {
        "char": "ѧ",
        "block": "minecraft:air"
      },
      {
        "char": "l",
        "block": "minecraft:iron_trapdoor[facing=east,half=bottom,open=false,powered=false,waterlogged=false]"
      },
      {
        "char": "u",
        "block": "minecraft:iron_trapdoor[facing=south,half=bottom,open=false,powered=false,waterlogged=false]"
      },
      {
        "char": "上",
        "block": "minecraft:air"
      },
      {
        "char": "w",
        "block": "minecraft:iron_trapdoor[facing=south,half=top,open=false,powered=false,waterlogged=false]"
      },
      {
        "char": "j",
        "block": "minecraft:polished_andesite_slab[type=top,waterlogged=false]"
      }
    ]
  },
  "slices": [
    [
      "eaccadebdbdaceae",
      "cadadecadcacgada",
      "daceadeaaaaaebaa",
      "ebcabbiaagadaa  ",
      "aaagiacacdag    ",
      "dcdeed  aa      ",
      " g              ",
      "                ",
      "                ",
      "                ",
      "                ",
      "                ",
      "                ",
      "                ",
      "                ",
      "                "
    ],
    [
      "   eed aac      ",
      "    H   H   f e ",
      " b             g",
      " a     faf      ",
      " affff  a       ",
      " d      a       ",
      " g              ",
      "                ",
      "                ",
      "                ",
      "                ",
      "                ",
      "                ",
      "                ",
      "                ",
      "                "
    ],
    [
      "    οѧ  οѧ     l",
      "            f b ",
      " d        ffuu a",
      " a     fifuu    ",
      " aff fuud上      ",
      "uduuuu  g       ",
      " a              ",
      "                ",
      "                ",
      "                ",
      "                ",
      "                ",
      "                ",
      "                ",
      "                ",
      "                "
    ],
    [
      "               w",
      "            f a ",
      " d        ffww a",
      " a    f gfww    ",
      " iffffwwew      ",
      "wdwwww  a       ",
      " g              ",
      "                ",
      "                ",
      "                ",
      "                ",
      "                ",
      "                ",
      "                ",
      "                ",
      "                "
    ],
    [
      " j            f ",
      " j           fb ",
      " a        ff   a",
      " d     faf      ",
      "faffff  c       ",
      " c      a       ",
      " g              ",
      "                ",
      "                ",
      "                ",
      "                ",
      "                ",
      "                ",
      "                ",
      "                ",
      "                "
    ],
    [
      " c            ib",
      " e          aae ",
      " e        aiea g",
      " d    aggabc    ",
      "aaaaagdeea      ",
      "bbbdcb  a       ",
      " a              ",
      "                ",
      "                ",
      "                ",
      "                ",
      "                ",
      "                ",
      "                ",
      "                ",
      "                "
    ]
  ]
}