{
  "xsize": 16,
  "zsize": 16,
  "palette": {
    "palette": [
      {
        "char": " ",
        "block": "minecraft:air"
      },
      {
        "char": "i",
        "block": "minecraft:light_gray_concrete"
      },
      {
        "char": "a",
        "block": "minecraft:cyan_terracotta"
      },
      {
        "char": "g",
        "block": "minecraft:gray_concrete"
      },
      {
        "char": "e",
        "block": "minecraft:basalt[axis=y]"
      },
      {
        "char": "d",
        "block": "minecraft:cobbled_deepslate"
      },
      {
        "char": "b",
        "block": "minecraft:blackstone"
      },
      {
        "char": "c",
        "block": "minecraft:deepslate[axis=y]"
      },
      {
        "char": "x",
        "block": "minecraft:cauldron"
      },
      {
        "char": "f",
        "block": "minecraft:glass"
      },
      {
        "char": "ϔ",
        "block": "minecraft:quartz_stairs[facing=east,half=bottom,shape=straight,waterlogged=false]"
      },
      {
        "char": "k",
        "block": "minecraft:oak_leaves[distance=7,persistent=true,waterlogged=false]"
      },
      {
        "char": "l",
        "block": "minecraft:iron_trapdoor[facing=east,half=bottom,open=false,powered=false,waterlogged=false]"
      },
      {
        "char": "Ӻ",
        "block": "minecraft:air",
        "tag": {
          "z": -276,
          "x": -15,
          "id": "refurbished_furniture:computer",
          "y": 27,
          "NodePos": "-3848291827685L",
          "Connections": [
            "L"
          ]
        }
      },
      {
        "char": "t",
        "block": "minecraft:iron_trapdoor[facing=east,half=top,open=false,powered=false,waterlogged=false]"
      },
      {
        "char": "I",
        "block": "minecraft:stone_slab[type=top,waterlogged=false,weathering=false]"
      }
    ]
  },
  "slices": [
    [
      "                ",
      "                ",
      "                ",
      "                ",
      "                ",
      "i               ",
      "aagaaaia        ",
      "eedeabaga       ",
      "cacedagb        ",
      "eaacaeab        ",
      "eeacebbid       ",
      "ceeaceaab       ",
      "dbccdcdad       ",
      "abcddadga       ",
      "deadbcbidg      ",
      "acececcac       "
    ],
    [
      "                ",
      "                ",
      "                ",
      "                ",
      "                ",
      "g               ",
      "       g        ",
      "ddbebciaa       ",
      "a  x  f         ",
      "a     f         ",
      "d               ",
      "   a   f        ",
      "   e ϔ f        ",
      "a  c   f        ",
      "ceebedaiea      ",
      "e  e   f        "
    ],
    [
      "                ",
      "                ",
      "                ",
      "                ",
      "                ",
      "g               ",
      "       g        ",
      "eebaabaaa       ",
      "c  k   l        ",
      "d      l        ",
      "a      fl       ",
      "        l       ",
      "   Ӻ    l       ",
      "d      fl       ",
      "dadaebaaea      ",
      "a       l       "
    ],
    [
      "                ",
      "                ",
      "                ",
      "                ",
      "                ",
      "g               ",
      "       a        ",
      "cecbabiaa       ",
      "b  k  ft        ",
      "d     ft        ",
      "d      ft       ",
      "       ft       ",
      "        t       ",
      "c      ft       ",
      "cbdccaeaaa      ",
      "e      ft       "
    ],
    [
      "                ",
      "                ",
      "                ",
      "                ",
      "                ",
      "a               ",
      "       a        ",
      "ebeaabiaa       ",
      "c               ",
      "a               ",
      "a      f        ",
      "I      f        ",
      "I      f        ",
      "a               ",
      "accdcaeaca      ",
      "c      f        "
    ],
    [
      "                ",
      "                ",
      "                ",
      "                ",
      "                ",
      "g               ",
      "       a        ",
      "dbceeeaaa       ",
      "b     ac        ",
      "c     ad        ",
      "b      ad       ",
      "d      ac       ",
      "d      ge       ",
      "a      ab       ",
      "bebbaeaaaa      ",
      "b      gd       "
    ]
  ]
}