{
  "xsize": 16,
  "zsize": 16,
  "palette": {
    "palette": [
      {
        "char": " ",
        "block": "minecraft:air"
      },
      {
        "char": "b",
        "block": "minecraft:blackstone"
      },
      {
        "char": "d",
        "block": "minecraft:cobbled_deepslate"
      },
      {
        "char": "i",
        "block": "minecraft:light_gray_concrete"
      },
      {
        "char": "a",
        "block": "minecraft:cyan_terracotta"
      },
      {
        "char": "g",
        "block": "minecraft:gray_concrete"
      },
      {
        "char": "e",
        "block": "minecraft:basalt[axis=y]"
      },
      {
        "char": "c",
        "block": "minecraft:deepslate[axis=y]"
      },
      {
        "char": "f",
        "block": "minecraft:glass"
      },
      {
        "char": "ϔ",
        "block": "minecraft:quartz_stairs[facing=east,half=bottom,shape=straight,waterlogged=false]"
      },
      {
        "char": "П",
        "block": "minecraft:barrel[facing=up,open=false]",
        "tag": {
          "z": -275,
          "x": -15,
          "ForgeData": {
            "LockFlag": "1b"
          },
          "id": "minecraft:barrel",
          "y": 2,
          "Items": []
        }
      },
      {
        "char": "s",
        "block": "minecraft:iron_trapdoor[facing=north,half=bottom,open=false,powered=false,waterlogged=false]"
      },
      {
        "char": "l",
        "block": "minecraft:iron_trapdoor[facing=east,half=bottom,open=false,powered=false,waterlogged=false]"
      },
      {
        "char": "信",
        "block": "minecraft:air"
      },
      {
        "char": "下",
        "block": "minecraft:air"
      },
      {
        "char": "Ӟ",
        "block": "minecraft:air"
      },
      {
        "char": "p",
        "block": "minecraft:iron_trapdoor[facing=north,half=top,open=false,powered=false,waterlogged=false]"
      },
      {
        "char": "t",
        "block": "minecraft:iron_trapdoor[facing=east,half=top,open=false,powered=false,waterlogged=false]"
      }
    ]
  },
  "slices": [
    [
      "bdiaig          ",
      "deeada          ",
      "ebeaaca         ",
      "cbeaieg         ",
      "aadedaba        ",
      "dacecaaa        ",
      "ebbbcdaeg       ",
      "ccbbedaai       ",
      "becaeaae        ",
      "aaaaebia        ",
      "eccedabab       ",
      "dbdedebgd       ",
      "cacddabad       ",
      "ddcddebaa       ",
      "cbdeabaiaa      ",
      "bcccebcgb       "
    ],
    [
      "  f  a          ",
      "   fa           ",
      "ϔ   f           ",
      "    f           ",
      "                ",
      "     f          ",
      "                ",
      "acdeddacg       ",
      "      f         ",
      "      f         ",
      " Пea            ",
      " d     f        ",
      " b ϔ   f        ",
      " b     f        ",
      "dbaebdcgbg      ",
      "e      f        "
    ],
    [
      "  fs i          ",
      "   fb           ",
      "    fl          ",
      "     l          ",
      "     fl         ",
      "      l         ",
      "      fl        ",
      "decbbcaag       ",
      "      fl        ",
      "      fl        ",
      "       fl       ",
      " 信     fl       ",
      " 下     fl       ",
      "       fӞ       ",
      "aececaeaea      ",
      "信      fl       "
    ],
    [
      "   p g          ",
      "   fe           ",
      "     t          ",
      "    ft          ",
      "     ft         ",
      "     ft         ",
      "      ft        ",
      "dbccbaaea       ",
      "      ft        ",
      "       t        ",
      "       ft       ",
      "       ft       ",
      "       ft       ",
      "       ft       ",
      "daaecdbada      ",
      "       ft       "
    ],
    [
      "  f  g          ",
      "    a           ",
      "    f           ",
      "    f           ",
      "     f          ",
      "     f          ",
      "                ",
      "edcbbcada       ",
      "      f         ",
      "                ",
      "       f        ",
      "       f        ",
      "                ",
      "       f        ",
      "addbcdaica      ",
      "       f        "
    ],
    [
      "  ge a          ",
      "   gc           ",
      "    id          ",
      "    gd          ",
      "     id         ",
      "     ae         ",
      "      ac        ",
      "eeaaadaca       ",
      "      ic        ",
      "      ac        ",
      "       ga       ",
      "       ab       ",
      "       ab       ",
      "       ab       ",
      "abdcbddgcg      ",
      "       ad       "
    ]
  ]
}