{
  "xsize": 16,
  "zsize": 16,
  "palette": {
    "palette": [
      {
        "char": " ",
        "block": "minecraft:air"
      },
      {
        "char": "a",
        "block": "minecraft:cyan_terracotta"
      },
      {
        "char": "b",
        "block": "minecraft:blackstone"
      },
      {
        "char": "d",
        "block": "minecraft:cobbled_deepslate"
      },
      {
        "char": "c",
        "block": "minecraft:deepslate[axis=y]"
      },
      {
        "char": "g",
        "block": "minecraft:gray_concrete"
      },
      {
        "char": "i",
        "block": "minecraft:light_gray_concrete"
      },
      {
        "char": "e",
        "block": "minecraft:basalt[axis=y]"
      },
      {
        "char": "f",
        "block": "minecraft:glass"
      },
      {
        "char": "ϕ",
        "block": "minecraft:quartz_stairs[facing=north,half=bottom,shape=straight,waterlogged=false]"
      },
      {
        "char": "x",
        "block": "minecraft:cauldron"
      },
      {
        "char": "s",
        "block": "minecraft:iron_trapdoor[facing=north,half=bottom,open=false,powered=false,waterlogged=false]"
      },
      {
        "char": "Ҝ",
        "block": "minecraft:air",
        "tag": {
          "z": -292,
          "x": -29,
          "id": "refurbished_furniture:computer",
          "y": 63,
          "NodePos": "-7696582590401L",
          "Connections": [
            "L"
          ]
        }
      },
      {
        "char": "k",
        "block": "minecraft:oak_leaves[distance=7,persistent=true,waterlogged=false]"
      },
      {
        "char": "p",
        "block": "minecraft:iron_trapdoor[facing=north,half=top,open=false,powered=false,waterlogged=false]"
      },
      {
        "char": "I",
        "block": "minecraft:stone_slab[type=top,waterlogged=false,weathering=false]"
      }
    ]
  },
  "slices": [
    [
      "                ",
      "                ",
      "                ",
      "                ",
      "                ",
      "                ",
      " a              ",
      "bdacca  a       ",
      "aagaigbaia      ",
      "dcbeceaaaa      ",
      "abacbbcaba      ",
      "cccddaabda      ",
      "eebddabbeg      ",
      "bdbeebbbba      ",
      "abdbecbbeg      ",
      "cbecdacedga     "
    ],
    [
      "                ",
      "                ",
      "                ",
      "                ",
      "                ",
      "                ",
      " a              ",
      " b      a       ",
      "faf  f  gg      ",
      " b      a       ",
      " c ϕ    a       ",
      " c      a       ",
      "acaeb  xb       ",
      " d      d       ",
      " d      c       ",
      "bbc  daeb a     "
    ],
    [
      "                ",
      "                ",
      "                ",
      "                ",
      "                ",
      "                ",
      " a              ",
      "sdssss  i       ",
      "faf ffssia      ",
      " d      a       ",
      " a      e       ",
      " d      e       ",
      " e Ҝ   ke       ",
      " b      b       ",
      " a      d       ",
      "eba  aeae a     "
    ],
    [
      "                ",
      "                ",
      "                ",
      "                ",
      "                ",
      "                ",
      " a              ",
      "pepppp  g       ",
      "faff fppga      ",
      " c    ffg       ",
      " d      d       ",
      " e      c       ",
      " c     kb       ",
      " b      c       ",
      " e      b       ",
      "deb  adad a     "
    ],
    [
      "                ",
      "                ",
      "                ",
      "                ",
      "                ",
      "                ",
      " a              ",
      " c      g       ",
      "fafff   aa      ",
      " e    ffa       ",
      " d      a       ",
      " e      d       ",
      " e      a       ",
      " b      b       ",
      " b      b       ",
      "dbcIIebca g     "
    ],
    [
      "                ",
      "                ",
      "                ",
      "                ",
      "                ",
      "                ",
      " g              ",
      "adabbb  a       ",
      "agaaaaadaa      ",
      " b    aaa       ",
      " d      b       ",
      " a      d       ",
      " e      b       ",
      " d      c       ",
      " c      b       ",
      "ebdddeeec a     "
    ]
  ]
}