{
  "xsize": 16,
  "zsize": 16,
  "palette": {
    "palette": [
      {
        "char": " ",
        "block": "minecraft:air"
      },
      {
        "char": "D",
        "block": "minecraft:smooth_stone_slab[type=bottom,waterlogged=false]"
      },
      {
        "char": "0",
        "block": "minecraft:stone_slab[type=bottom,waterlogged=false,weathering=false]"
      },
      {
        "char": "c",
        "block": "minecraft:deepslate[axis=y]"
      },
      {
        "char": "e",
        "block": "minecraft:basalt[axis=y]"
      },
      {
        "char": "g",
        "block": "minecraft:gray_concrete"
      },
      {
        "char": "d",
        "block": "minecraft:cobbled_deepslate"
      },
      {
        "char": "a",
        "block": "minecraft:cyan_terracotta"
      },
      {
        "char": "b",
        "block": "minecraft:blackstone"
      },
      {
        "char": "i",
        "block": "minecraft:light_gray_concrete"
      },
      {
        "char": "Ѱ",
        "block": "minecraft:cobblestone_slab[type=bottom,waterlogged=false,weathering=false]"
      },
      {
        "char": "f",
        "block": "minecraft:glass"
      },
      {
        "char": "П",
        "block": "minecraft:barrel[facing=up,open=false]",
        "tag": {
          "z": -275,
          "x": -15,
          "ForgeData": {
            "LockFlag": "1b"
          },
          "id": "minecraft:barrel",
          "y": 2,
          "Items": []
        }
      },
      {
        "char": "H",
        "block": "minecraft:quartz_stairs[facing=south,half=bottom,shape=straight,waterlogged=false]"
      },
      {
        "char": "u",
        "block": "minecraft:iron_trapdoor[facing=south,half=bottom,open=false,powered=false,waterlogged=false]"
      },
      {
        "char": "ϐ",
        "block": "minecraft:air",
        "tag": {
          "z": -259,
          "x": -34,
          "id": "refurbished_furniture:computer",
          "y": -21,
          "NodePos": "-9070971985941L",
          "Connections": [
            "L"
          ]
        }
      },
      {
        "char": "w",
        "block": "minecraft:iron_trapdoor[facing=south,half=top,open=false,powered=false,waterlogged=false]"
      },
      {
        "char": "学",
        "block": "minecraft:air"
      },
      {
        "char": "站",
        "block": "minecraft:air"
      }
    ]
  },
  "slices": [
    [
      "D0cegeddacabdbac",
      "D0DDbiaeaebaeabd",
      "0D0gDbbgaecdedee",
      "DѰDD0DDbeiaaacae",
      "DDDDѰDDDDeeaeaaa",
      "DDDDD0DDDѰa0Ѱbeb",
      "        ia      ",
      "        aa      ",
      "  c      a      ",
      "                ",
      "                ",
      "                ",
      "                ",
      "                ",
      "                ",
      "                "
    ],
    [
      "    f    dac beП",
      "    d f   H   H ",
      "   a   ff       ",
      "         fa f   ",
      "          e  fff",
      "          a     ",
      "                ",
      "                ",
      "  c      e      ",
      "                ",
      "                ",
      "                ",
      "                ",
      "                ",
      "                ",
      "                "
    ],
    [
      "  uu      ϐ   ϐ ",
      "    eff         ",
      "   a uuf        ",
      "       uufif    ",
      "         ubuuff ",
      "          a  uuu",
      "                ",
      "                ",
      "  a      a      ",
      "                ",
      "                ",
      "                ",
      "                ",
      "                ",
      "                ",
      "                "
    ],
    [
      "  w学            ",
      "    b f         ",
      "   a wwf        ",
      "       wwfaff   ",
      "         wbw站   ",
      "          a  www",
      "                ",
      "                ",
      "  d      d      ",
      "                ",
      "                ",
      "                ",
      "                ",
      "                ",
      "                ",
      "                "
    ],
    [
      "    f           ",
      "    aff         ",
      "   a   f        ",
      "         fa     ",
      "          e  fff",
      "          a     ",
      "                ",
      "                ",
      "  c      b      ",
      "                ",
      "                ",
      "                ",
      "                ",
      "                ",
      "                ",
      "                "
    ],
    [
      "  bag           ",
      "    baa         ",
      "   g aeag       ",
      "       beagaa   ",
      "         aacbgaa",
      "          a  aba",
      "                ",
      "                ",
      "  d      a      ",
      "                ",
      "                ",
      "                ",
      "                ",
      "                ",
      "                ",
      "                "
    ]
  ]
}