{
  "xsize": 16,
  "zsize": 16,
  "palette": {
    "palette": [
      {
        "char": " ",
        "block": "minecraft:air"
      },
      {
        "char": "g",
        "block": "minecraft:gray_concrete"
      },
      {
        "char": "a",
        "block": "minecraft:cyan_terracotta"
      },
      {
        "char": "i",
        "block": "minecraft:light_gray_concrete"
      },
      {
        "char": "d",
        "block": "minecraft:cobbled_deepslate"
      },
      {
        "char": "e",
        "block": "minecraft:basalt[axis=y]"
      },
      {
        "char": "b",
        "block": "minecraft:blackstone"
      },
      {
        "char": "c",
        "block": "minecraft:deepslate[axis=y]"
      },
      {
        "char": "x",
        "block": "minecraft:cauldron"
      },
      {
        "char": "f",
        "block": "minecraft:glass"
      },
      {
        "char": "ϔ",
        "block": "minecraft:quartz_stairs[facing=east,half=bottom,shape=straight,waterlogged=false]"
      },
      {
        "char": "П",
        "block": "minecraft:barrel[facing=up,open=false]",
        "tag": {
          "z": -275,
          "x": -15,
          "ForgeData": {
            "LockFlag": "1b"
          },
          "id": "minecraft:barrel",
          "y": 2,
          "Items": []
        }
      },
      {
        "char": "k",
        "block": "minecraft:oak_leaves[distance=7,persistent=true,waterlogged=false]"
      },
      {
        "char": "l",
        "block": "minecraft:iron_trapdoor[facing=east,half=bottom,open=false,powered=false,waterlogged=false]"
      },
      {
        "char": "Ӻ",
        "block": "minecraft:air",
        "tag": {
          "z": -276,
          "x": -15,
          "id": "refurbished_furniture:computer",
          "y": 27,
          "NodePos": "-3848291827685L",
          "Connections": [
            "L"
          ]
        }
      },
      {
        "char": "t",
        "block": "minecraft:iron_trapdoor[facing=east,half=top,open=false,powered=false,waterlogged=false]"
      },
      {
        "char": "I",
        "block": "minecraft:stone_slab[type=top,waterlogged=false,weathering=false]"
      }
    ]
  },
  "slices": [
    [
      "                ",
      "                ",
      "                ",
      "                ",
      "                ",
      "g               ",
      "gaaaigaa        ",
      "daaeaegig       ",
      "bcdebbab        ",
      "dcbddbib        ",
      "adeadacad       ",
      "deceabaad       ",
      "aacdcecac       ",
      "aababdcac       ",
      "acecabeacg      ",
      "ddebbcead       "
    ],
    [
      "                ",
      "                ",
      "                ",
      "                ",
      "                ",
      "a               ",
      "       g        ",
      "bbabbciga       ",
      "e  x  f         ",
      "a     f         ",
      "e               ",
      "   d   f        ",
      "   d ϔ f        ",
      "a  П   f        ",
      "abdeaabaai      ",
      "b  b   f        "
    ],
    [
      "                ",
      "                ",
      "                ",
      "                ",
      "                ",
      "a               ",
      "       g        ",
      "ddbebaaaa       ",
      "c  k  fl        ",
      "d     fl        ",
      "d      fl       ",
      "       fl       ",
      "   Ӻ   fl       ",
      "e      fl       ",
      "eaccebeacg      ",
      "d       l       "
    ],
    [
      "                ",
      "                ",
      "                ",
      "                ",
      "                ",
      "a               ",
      "       g        ",
      "aedbbdiaa       ",
      "e  k   t        ",
      "b     ft        ",
      "c      ft       ",
      "       ft       ",
      "       ft       ",
      "a       t       ",
      "daebaabgeg      ",
      "b      ft       "
    ],
    [
      "                ",
      "                ",
      "                ",
      "                ",
      "                ",
      "a               ",
      "       g        ",
      "aecabcaaa       ",
      "d               ",
      "a     f         ",
      "a      f        ",
      "I      f        ",
      "I      f        ",
      "b               ",
      "accddddaba      ",
      "b      f        "
    ],
    [
      "                ",
      "                ",
      "                ",
      "                ",
      "                ",
      "g               ",
      "       a        ",
      "dbddccaag       ",
      "e     ac        ",
      "b     ab        ",
      "c      ae       ",
      "c      ga       ",
      "c      gd       ",
      "c      ae       ",
      "adeeaddada      ",
      "d      id       "
    ]
  ]
}