{
  "xsize": 16,
  "zsize": 16,
  "palette": {
    "palette": [
      {
        "char": " ",
        "block": "minecraft:air"
      },
      {
        "char": "a",
        "block": "minecraft:cyan_terracotta"
      },
      {
        "char": "d",
        "block": "minecraft:cobbled_deepslate"
      },
      {
        "char": "b",
        "block": "minecraft:blackstone"
      },
      {
        "char": "e",
        "block": "minecraft:basalt[axis=y]"
      },
      {
        "char": "c",
        "block": "minecraft:deepslate[axis=y]"
      },
      {
        "char": "Р",
        "block": "minecraft:stone_brick_stairs[facing=north,half=bottom,shape=straight,waterlogged=false,weathering=false]"
      },
      {
        "char": "z",
        "block": "minecraft:iron_bars[east=false,north=true,south=true,waterlogged=false,west=false]"
      },
      {
        "char": "Y",
        "block": "minecraft:iron_bars[east=false,north=true,south=false,waterlogged=false,west=false]"
      },
      {
        "char": "f",
        "block": "minecraft:glass"
      },
      {
        "char": "O",
        "block": "minecraft:quartz_stairs[facing=west,half=bottom,shape=straight,waterlogged=false]"
      },
      {
        "char": "П",
        "block": "minecraft:barrel[facing=up,open=false]",
        "tag": {
          "z": -275,
          "x": -15,
          "ForgeData": {
            "LockFlag": "1b"
          },
          "id": "minecraft:barrel",
          "y": 2,
          "Items": []
        }
      },
      {
        "char": "x",
        "block": "minecraft:cauldron"
      },
      {
        "char": "У",
        "block": "minecraft:stone_brick_stairs[facing=south,half=bottom,shape=straight,waterlogged=false,weathering=false]"
      },
      {
        "char": "С",
        "block": "minecraft:stone_brick_stairs[facing=north,half=top,shape=straight,waterlogged=false,weathering=false]"
      },
      {
        "char": "到",
        "block": "minecraft:air"
      },
      {
        "char": "来",
        "block": "minecraft:air"
      },
      {
        "char": "N",
        "block": "minecraft:white_stained_glass_pane[east=true,north=false,south=false,waterlogged=false,west=true]"
      },
      {
        "char": "k",
        "block": "minecraft:oak_leaves[distance=7,persistent=true,waterlogged=false]"
      },
      {
        "char": "Ѳ",
        "block": "minecraft:white_stained_glass_pane[east=true,north=false,south=false,waterlogged=false,west=false]"
      },
      {
        "char": "у",
        "block": "minecraft:stone_brick_stairs[facing=south,half=top,shape=straight,waterlogged=false,weathering=false]"
      },
      {
        "char": "j",
        "block": "minecraft:polished_andesite_slab[type=top,waterlogged=false]"
      },
      {
        "char": "i",
        "block": "minecraft:light_gray_concrete"
      }
    ]
  },
  "slices": [
    [
      "aadaabeccaeceeab",
      "bccdddbdcceaceda",
      "eacaebacceeddbce",
      "debabacddccecdbc",
      "cedcdbcbbeeeaaba",
      "cdaceeeabdaccead",
      "bdcbbdbdadcdebeb",
      "cdbebbcecedcadba",
      "bbacccaebaddbbbb",
      "aaebcebaaceccada",
      "ddedcecabddceebc",
      "abdeebcbdeaeebeb",
      "adbeeaeeaaedРz c",
      "eabdbabbdaee z d",
      "adacdddddaad Y c",
      "decceeecddde   d"
    ],
    [
      "f   Ob    e     ",
      "     a          ",
      "                ",
      "  d  b    c     ",
      " Ob Oc    ecbcdb",
      "  c  П     a  x ",
      "           b    ",
      "  b  b          ",
      " Ob Od          ",
      "  a  d          ",
      "           c    ",
      "  a  c     e d c",
      " Ob Od     c zУa",
      "  c  e     a zСb",
      "eeccbae   ad Y e",
      "  П  e     d   d"
    ],
    [
      "f    到    c     ",
      "     来          ",
      "                ",
      "          d     ",
      "  到  到    ccaNNN",
      "  来  来     d  k ",
      "           d    ",
      "                ",
      "  到  到          ",
      "  来  来          ",
      "           b    ",
      "           a a b",
      "  到  到     e z c",
      "  来  来     e zУa",
      "bbeadba   ed YСa",
      "     a     a   e"
    ],
    [
      "          d     ",
      "                ",
      "                ",
      "          b     ",
      "          adb  Ѳ",
      "           c  k ",
      "           d    ",
      "                ",
      "                ",
      "                ",
      "           c    ",
      "           b c b",
      "           c z c",
      "           c z a",
      "cedcddd   dcуzУe",
      "     d     acdce"
    ],
    [
      "f         d     ",
      "          j     ",
      "          j     ",
      "          a     ",
      "          eacbac",
      "           a    ",
      "           b    ",
      "           j    ",
      "           j    ",
      "           j    ",
      "           c    ",
      "           aadce",
      "           e z d",
      "           dуz c",
      "dacbadbjjjaaРY a",
      "     e     a   b"
    ],
    [
      "i         a     ",
      "          d     ",
      "          c     ",
      "          e     ",
      "          bcbbac",
      "           a    ",
      "           b    ",
      "           b    ",
      "           a    ",
      "           e    ",
      "           b    ",
      "           daaaa",
      "           dуz b",
      "           aРz b",
      "eccbdedbbbab Y e",
      "     c     d   a"
    ]
  ]
}