{
  "xsize": 16,
  "zsize": 16,
  "palette": {
    "palette": [
      {
        "char": " ",
        "block": "minecraft:air"
      },
      {
        "char": "a",
        "block": "minecraft:cyan_terracotta"
      },
      {
        "char": "b",
        "block": "minecraft:blackstone"
      },
      {
        "char": "e",
        "block": "minecraft:basalt[axis=y]"
      },
      {
        "char": "d",
        "block": "minecraft:cobbled_deepslate"
      },
      {
        "char": "c",
        "block": "minecraft:deepslate[axis=y]"
      },
      {
        "char": "g",
        "block": "minecraft:gray_concrete"
      },
      {
        "char": "i",
        "block": "minecraft:light_gray_concrete"
      },
      {
        "char": "ϔ",
        "block": "minecraft:quartz_stairs[facing=east,half=bottom,shape=straight,waterlogged=false]"
      },
      {
        "char": "f",
        "block": "minecraft:glass"
      },
      {
        "char": "x",
        "block": "minecraft:cauldron"
      },
      {
        "char": "H",
        "block": "minecraft:quartz_stairs[facing=south,half=bottom,shape=straight,waterlogged=false]"
      },
      {
        "char": "吗",
        "block": "minecraft:air"
      },
      {
        "char": "l",
        "block": "minecraft:iron_trapdoor[facing=east,half=bottom,open=false,powered=false,waterlogged=false]"
      },
      {
        "char": "k",
        "block": "minecraft:oak_leaves[distance=7,persistent=true,waterlogged=false]"
      },
      {
        "char": "ο",
        "block": "minecraft:air"
      },
      {
        "char": "ѧ",
        "block": "minecraft:air"
      },
      {
        "char": "u",
        "block": "minecraft:iron_trapdoor[facing=south,half=bottom,open=false,powered=false,waterlogged=false]"
      },
      {
        "char": "t",
        "block": "minecraft:iron_trapdoor[facing=east,half=top,open=false,powered=false,waterlogged=false]"
      },
      {
        "char": "w",
        "block": "minecraft:iron_trapdoor[facing=south,half=top,open=false,powered=false,waterlogged=false]"
      }
    ]
  },
  "slices": [
    [
      "abebdceaa       ",
      "deabbbbge       ",
      "aaaacabae       ",
      "dacbdaae        ",
      "edccdaaa        ",
      "dedaebiaa       ",
      "dddddcaea       ",
      "edcceadi        ",
      "bcdbbgcg        ",
      "aeebabg         ",
      "ddccibg         ",
      "eaeida          ",
      "bbaagg          ",
      "eaaca           ",
      "eaai            ",
      "aei             "
    ],
    [
      "a ϔ             ",
      "b               ",
      "cad    f        ",
      "      f         ",
      "      f         ",
      "cbbdcdgag       ",
      "  x   f         ",
      "     f          ",
      "     f          ",
      "    f           ",
      "bc  f           ",
      "H  fa           ",
      "  f  a          ",
      "  f             ",
      " f              ",
      "f               "
    ],
    [
      "吗      fl       ",
      "       fl       ",
      "        l       ",
      "      fl        ",
      "      fl        ",
      "cbbdbbgbg       ",
      "  k   fl        ",
      "     fl         ",
      "      l         ",
      "    fl          ",
      "οѧ  fl          ",
      "    c           ",
      "   u g          ",
      "  fl            ",
      " fl             ",
      "fl              "
    ],
    [
      "       ft       ",
      "       ft       ",
      "       ft       ",
      "      ft        ",
      "       t        ",
      "eeddaeada       ",
      "  k    t        ",
      "     ft         ",
      "     ft         ",
      "    ft          ",
      "     t          ",
      "   fc           ",
      "   w a          ",
      "  ft            ",
      " ft             ",
      "fw              "
    ],
    [
      "                ",
      "       f        ",
      "       f        ",
      "                ",
      "      f         ",
      "deacdaaag       ",
      "      f         ",
      "     f          ",
      "     f          ",
      "    f           ",
      "    f           ",
      "    d           ",
      "  f  a          ",
      "  f             ",
      " f              ",
      "f               "
    ],
    [
      "       aa       ",
      "       ad       ",
      "       ac       ",
      "      ab        ",
      "      ad        ",
      "bdaecdgda       ",
      "      ie        ",
      "     ge         ",
      "     ac         ",
      "    gc          ",
      "    ib          ",
      "   ae           ",
      "  aa g          ",
      "  ac            ",
      " gc             ",
      "ab              "
    ]
  ]
}