{
  "xsize": 16,
  "zsize": 16,
  "palette": {
    "palette": [
      {
        "char": " ",
        "block": "minecraft:air"
      },
      {
        "char": "a",
        "block": "minecraft:cyan_terracotta"
      },
      {
        "char": "d",
        "block": "minecraft:cobbled_deepslate"
      },
      {
        "char": "e",
        "block": "minecraft:basalt[axis=y]"
      },
      {
        "char": "c",
        "block": "minecraft:deepslate[axis=y]"
      },
      {
        "char": "b",
        "block": "minecraft:blackstone"
      },
      {
        "char": "g",
        "block": "minecraft:gray_concrete"
      },
      {
        "char": "i",
        "block": "minecraft:light_gray_concrete"
      },
      {
        "char": "f",
        "block": "minecraft:glass"
      },
      {
        "char": "m",
        "block": "minecraft:iron_trapdoor[facing=west,half=bottom,open=false,powered=false,waterlogged=false]"
      },
      {
        "char": "u",
        "block": "minecraft:iron_trapdoor[facing=south,half=bottom,open=false,powered=false,waterlogged=false]"
      },
      {
        "char": "q",
        "block": "minecraft:iron_trapdoor[facing=west,half=top,open=false,powered=false,waterlogged=false]"
      },
      {
        "char": "w",
        "block": "minecraft:iron_trapdoor[facing=south,half=top,open=false,powered=false,waterlogged=false]"
      }
    ]
  },
  "slices": [
    [
      "          aadecc",
      "          caddcd",
      "          bgcccd",
      "           eaeae",
      "           aaace",
      "          adadbb",
      "          ieadae",
      "           adged",
      "           gdade",
      "            geab",
      "            aead",
      "             adg",
      "             aae",
      "              aa",
      "               a",
      "                "
    ],
    [
      "           f    ",
      "                ",
      "           f    ",
      "            f   ",
      "            f   ",
      "          geacac",
      "                ",
      "                ",
      "             f  ",
      "              f ",
      "                ",
      "              ef",
      "             a  ",
      "                ",
      "                ",
      "                "
    ],
    [
      "          mf    ",
      "          mf    ",
      "          m     ",
      "           m    ",
      "           m    ",
      "          aeaded",
      "           mf   ",
      "            mf  ",
      "            m   ",
      "             mf ",
      "             uf ",
      "              af",
      "             a u",
      "               m",
      "                ",
      "                "
    ],
    [
      "          qf    ",
      "          qf    ",
      "          qf    ",
      "           qf   ",
      "           qf   ",
      "          aeaaee",
      "           qf   ",
      "            qf  ",
      "            qf  ",
      "             q  ",
      "             qf ",
      "              ef",
      "             a w",
      "               q",
      "                ",
      "                "
    ],
    [
      "           f    ",
      "                ",
      "           f    ",
      "            f   ",
      "            f   ",
      "          acaced",
      "                ",
      "             f  ",
      "             f  ",
      "              f ",
      "              f ",
      "              cf",
      "             a  ",
      "                ",
      "                ",
      "                "
    ],
    [
      "          bi    ",
      "          aa    ",
      "          di    ",
      "           da   ",
      "           ea   ",
      "          idaabb",
      "           aa   ",
      "            aa  ",
      "            ai  ",
      "             ca ",
      "             ca ",
      "              ca",
      "             a b",
      "               e",
      "                ",
      "                "
    ]
  ]
}