{
  "xsize": 16,
  "zsize": 16,
  "palette": {
    "palette": [
      {
        "char": " ",
        "block": "minecraft:air"
      },
      {
        "char": "a",
        "block": "minecraft:cyan_terracotta"
      },
      {
        "char": "d",
        "block": "minecraft:cobbled_deepslate"
      },
      {
        "char": "c",
        "block": "minecraft:deepslate[axis=y]"
      },
      {
        "char": "b",
        "block": "minecraft:blackstone"
      },
      {
        "char": "e",
        "block": "minecraft:basalt[axis=y]"
      },
      {
        "char": "i",
        "block": "minecraft:light_gray_concrete"
      },
      {
        "char": "g",
        "block": "minecraft:gray_concrete"
      },
      {
        "char": "f",
        "block": "minecraft:glass"
      },
      {
        "char": "ϕ",
        "block": "minecraft:quartz_stairs[facing=north,half=bottom,shape=straight,waterlogged=false]"
      },
      {
        "char": "O",
        "block": "minecraft:quartz_stairs[facing=west,half=bottom,shape=straight,waterlogged=false]"
      },
      {
        "char": "ϓ",
        "block": "minecraft:air"
      },
      {
        "char": "s",
        "block": "minecraft:iron_trapdoor[facing=north,half=bottom,open=false,powered=false,waterlogged=false]"
      },
      {
        "char": "多",
        "block": "minecraft:air"
      },
      {
        "char": "p",
        "block": "minecraft:iron_trapdoor[facing=north,half=top,open=false,powered=false,waterlogged=false]"
      }
    ]
  },
  "slices": [
    [
      "                ",
      "                ",
      "                ",
      "                ",
      "                ",
      "                ",
      " a              ",
      "dcbbbe  ig      ",
      "aaagaaabadia    ",
      "ebabdaaaaacda   ",
      "baeaeebebdag    ",
      "acbdacceabeec   ",
      "acdddbaaebae    ",
      "cacebbdbdecc    ",
      "abcdccecaedb    ",
      "cadbaebcbbeae   "
    ],
    [
      "                ",
      "                ",
      "                ",
      "                ",
      "                ",
      "                ",
      " g              ",
      " d      g       ",
      "fif ff  c       ",
      " c    ffg       ",
      " d      a ff    ",
      " c      b       ",
      " e d ϕ  a       ",
      " e d    d       ",
      " c ddbded  ϕ    ",
      " c      e Oϓ    "
    ],
    [
      "                ",
      "                ",
      "                ",
      "                ",
      "                ",
      "                ",
      " g              ",
      "sdssss  a       ",
      "fgff fssbs      ",
      " b    ffafss    ",
      " e      a f     ",
      " b      d       ",
      " a      e       ",
      " e      b       ",
      " b  多 多 e       ",
      " d      c       "
    ],
    [
      "                ",
      "                ",
      "                ",
      "                ",
      "                ",
      "                ",
      " a              ",
      "pcpppp  a       ",
      "faffffppep      ",
      " b     fa pp    ",
      " a      c f     ",
      " e      b       ",
      " e      d       ",
      " e      c       ",
      " a      b       ",
      " e      d       "
    ],
    [
      "                ",
      "                ",
      "                ",
      "                ",
      "                ",
      "                ",
      " a              ",
      " c      a       ",
      "faf ff  c       ",
      " d    ffa       ",
      " d      d f     ",
      " d      a       ",
      " d      b       ",
      " e      c       ",
      " a      e       ",
      " d      c       "
    ],
    [
      "                ",
      "                ",
      "                ",
      "                ",
      "                ",
      "                ",
      " a              ",
      "dbeddd  a       ",
      "gaaaaaebeb      ",
      " b    agggcc    ",
      " c      a ii    ",
      " c      e       ",
      " b      b       ",
      " e      e       ",
      " b      b       ",
      " e      e       "
    ]
  ]
}