{
  "xsize": 16,
  "zsize": 16,
  "palette": {
    "palette": [
      {
        "char": " ",
        "block": "minecraft:air"
      },
      {
        "char": "c",
        "block": "minecraft:deepslate[axis=y]"
      },
      {
        "char": "a",
        "block": "minecraft:cyan_terracotta"
      },
      {
        "char": "e",
        "block": "minecraft:basalt[axis=y]"
      },
      {
        "char": "b",
        "block": "minecraft:blackstone"
      },
      {
        "char": "d",
        "block": "minecraft:cobbled_deepslate"
      },
      {
        "char": "g",
        "block": "minecraft:gray_concrete"
      },
      {
        "char": "i",
        "block": "minecraft:light_gray_concrete"
      },
      {
        "char": "H",
        "block": "minecraft:quartz_stairs[facing=south,half=bottom,shape=straight,waterlogged=false]"
      },
      {
        "char": "f",
        "block": "minecraft:glass"
      },
      {
        "char": "ο",
        "block": "minecraft:air"
      },
      {
        "char": "ѧ",
        "block": "minecraft:air"
      },
      {
        "char": "ѷ",
        "block": "minecraft:air"
      },
      {
        "char": "Ҟ",
        "block": "minecraft:air"
      },
      {
        "char": "Ӟ",
        "block": "minecraft:air"
      },
      {
        "char": "u",
        "block": "minecraft:iron_trapdoor[facing=south,half=bottom,open=false,powered=false,waterlogged=false]"
      },
      {
        "char": "w",
        "block": "minecraft:iron_trapdoor[facing=south,half=top,open=false,powered=false,waterlogged=false]"
      },
      {
        "char": "j",
        "block": "minecraft:polished_andesite_slab[type=top,waterlogged=false]"
      }
    ]
  },
  "slices": [
    [
      "caebbaabeddaaaae",
      "eddbcacdeabeagcg",
      "acaedbabecagddag",
      "eabeeeiaggddgg  ",
      "agaaggabdcgg    ",
      "cebddd  gg      ",
      " a              ",
      "                ",
      "                ",
      "                ",
      "                ",
      "                ",
      "                ",
      "                ",
      "                ",
      "                "
    ],
    [
      "   eeb caa      ",
      "    H   H   f c ",
      " e        f    i",
      " e    f gf      ",
      "faffff  b       ",
      " b      a       ",
      " i              ",
      "                ",
      "                ",
      "                ",
      "                ",
      "                ",
      "                ",
      "                ",
      "                ",
      "                "
    ],
    [
      "    οѧ  ѷҞ     Ӟ",
      "            ffe ",
      " d        ffuu a",
      " b    f afuu    ",
      "fg fffuueu      ",
      "ubuuuu  i       ",
      " a              ",
      "                ",
      "                ",
      "                ",
      "                ",
      "                ",
      "                ",
      "                ",
      "                ",
      "                "
    ],
    [
      "              fw",
      "            f e ",
      " d         fww i",
      " b    ffafww    ",
      "fa fffwwdw      ",
      "wcwwww  i       ",
      " a              ",
      "                ",
      "                ",
      "                ",
      "                ",
      "                ",
      "                ",
      "                ",
      "                ",
      "                "
    ],
    [
      " j              ",
      " j          ffd ",
      " a             a",
      " e    ffif      ",
      "fgf ff  e       ",
      " a      a       ",
      " a              ",
      "                ",
      "                ",
      "                ",
      "                ",
      "                ",
      "                ",
      "                ",
      "                ",
      "                "
    ],
    [
      " d            ge",
      " a          iia ",
      " c        agab i",
      " a    igaacb    ",
      "aaaaaicabe      ",
      "cdebbc  g       ",
      " a              ",
      "                ",
      "                ",
      "                ",
      "                ",
      "                ",
      "                ",
      "                ",
      "                ",
      "                "
    ]
  ]
}