{
  "xsize": 16,
  "zsize": 16,
  "palette": {
    "palette": [
      {
        "char": " ",
        "block": "minecraft:air"
      },
      {
        "char": "a",
        "block": "minecraft:cyan_terracotta"
      },
      {
        "char": "e",
        "block": "minecraft:basalt[axis=y]"
      },
      {
        "char": "b",
        "block": "minecraft:blackstone"
      },
      {
        "char": "d",
        "block": "minecraft:cobbled_deepslate"
      },
      {
        "char": "c",
        "block": "minecraft:deepslate[axis=y]"
      },
      {
        "char": "i",
        "block": "minecraft:light_gray_concrete"
      },
      {
        "char": "g",
        "block": "minecraft:gray_concrete"
      },
      {
        "char": "f",
        "block": "minecraft:glass"
      },
      {
        "char": "H",
        "block": "minecraft:quartz_stairs[facing=south,half=bottom,shape=straight,waterlogged=false]"
      },
      {
        "char": "u",
        "block": "minecraft:iron_trapdoor[facing=south,half=bottom,open=false,powered=false,waterlogged=false]"
      },
      {
        "char": "ѷ",
        "block": "minecraft:air"
      },
      {
        "char": "Ҟ",
        "block": "minecraft:air"
      },
      {
        "char": "ο",
        "block": "minecraft:air"
      },
      {
        "char": "ѧ",
        "block": "minecraft:air"
      },
      {
        "char": "上",
        "block": "minecraft:air"
      },
      {
        "char": "w",
        "block": "minecraft:iron_trapdoor[facing=south,half=top,open=false,powered=false,waterlogged=false]"
      },
      {
        "char": "q",
        "block": "minecraft:iron_trapdoor[facing=west,half=top,open=false,powered=false,waterlogged=false]"
      }
    ]
  },
  "slices": [
    [
      " aeaababaedccacc",
      "  iabaaeeceddbee",
      "   agabiabcbaedc",
      "     aaeeaaaicca",
      "       iaeaeaaai",
      "         aa  aad",
      "                ",
      "                ",
      "                ",
      "                ",
      "                ",
      "                ",
      "                ",
      "                ",
      "                ",
      "                "
    ],
    [
      "    f    aec dae",
      "    cff   H   H ",
      "   a   ff       ",
      "         fg f   ",
      "          a  f f",
      "          g     ",
      "                ",
      "                ",
      "                ",
      "                ",
      "                ",
      "                ",
      "                ",
      "                ",
      "                ",
      "                "
    ],
    [
      "  uuf     ѷҞ  οѧ",
      "    cff         ",
      "   a uuff       ",
      "       uufaff   ",
      "         ueuufff",
      "          a  上uu",
      "                ",
      "                ",
      "                ",
      "                ",
      "                ",
      "                ",
      "                ",
      "                ",
      "                ",
      "                "
    ],
    [
      "  wqf           ",
      "    c f         ",
      "   i wwff       ",
      "       ww iff   ",
      "         wawwfff",
      "          g  www",
      "                ",
      "                ",
      "                ",
      "                ",
      "                ",
      "                ",
      "                ",
      "                ",
      "                ",
      "                "
    ],
    [
      "    f           ",
      "    dff         ",
      "   a   ff       ",
      "          gf    ",
      "          b  f f",
      "          g     ",
      "                ",
      "                ",
      "                ",
      "                ",
      "                ",
      "                ",
      "                ",
      "                ",
      "                ",
      "                "
    ],
    [
      "  aba           ",
      "    eaa         ",
      "   g bbia       ",
      "       cagaaa   ",
      "         eabbiaa",
      "          a  bad",
      "                ",
      "                ",
      "                ",
      "                ",
      "                ",
      "                ",
      "                ",
      "                ",
      "                ",
      "                "
    ]
  ]
}