{
  "xsize": 16,
  "zsize": 16,
  "palette": {
    "palette": [
      {
        "char": " ",
        "block": "minecraft:air"
      },
      {
        "char": "b",
        "block": "minecraft:blackstone"
      },
      {
        "char": "e",
        "block": "minecraft:basalt[axis=y]"
      },
      {
        "char": "c",
        "block": "minecraft:deepslate[axis=y]"
      },
      {
        "char": "a",
        "block": "minecraft:cyan_terracotta"
      },
      {
        "char": "d",
        "block": "minecraft:cobbled_deepslate"
      },
      {
        "char": "你",
        "block": "minecraft:spawner",
        "tag": {
          "SpawnData": {
            "entity": {}
          },
          "MaxNearbyEntities": "6s",
          "MinSpawnDelay": "200s",
          "z": -274,
          "x": -42,
          "MaxSpawnDelay": "800s",
          "RequiredPlayerRange": "16s",
          "SpawnCount": "4s",
          "id": "minecraft:mob_spawner",
          "SpawnPotentials": [],
          "y": 1,
          "SpawnRange": "4s",
          "Delay": "731s"
        }
      },
      {
        "char": "Z",
        "block": "minecraft:stone_brick_wall[east=tall,north=tall,south=none,up=true,waterlogged=false,weathering=false,west=tall]"
      },
      {
        "char": "G",
        "block": "minecraft:iron_bars[east=false,north=false,south=true,waterlogged=false,west=false]"
      },
      {
        "char": "H",
        "block": "minecraft:quartz_stairs[facing=south,half=bottom,shape=straight,waterlogged=false]"
      },
      {
        "char": "O",
        "block": "minecraft:quartz_stairs[facing=west,half=bottom,shape=straight,waterlogged=false]"
      },
      {
        "char": "ϓ",
        "block": "minecraft:air"
      },
      {
        "char": "x",
        "block": "minecraft:cauldron"
      },
      {
        "char": "v",
        "block": "minecraft:quartz_pillar[axis=x]"
      },
      {
        "char": "N",
        "block": "minecraft:white_stained_glass_pane[east=true,north=false,south=false,waterlogged=false,west=true]"
      },
      {
        "char": "k",
        "block": "minecraft:oak_leaves[distance=7,persistent=true,waterlogged=false]"
      },
      {
        "char": "n",
        "block": "minecraft:smooth_quartz"
      },
      {
        "char": "Ѵ",
        "block": "minecraft:white_stained_glass_pane[east=false,north=false,south=false,waterlogged=false,west=true]"
      },
      {
        "char": "o",
        "block": "minecraft:chiseled_quartz_block"
      },
      {
        "char": "j",
        "block": "minecraft:polished_andesite_slab[type=top,waterlogged=false]"
      }
    ]
  },
  "slices": [
    [
      "becabaedeccdaa  ",
      "dbdbbdbbbbcecbda",
      "edccaddcbaaabccd",
      "ccddcdbeaebbecbe",
      "ebcddcededccbbce",
      "ceeceeeabeeebcec",
      "dedeebdcdacddada",
      "cbcbbccdedded你ea",
      "eebbeababeabbcdd",
      "adeccbecceceaaba",
      "bbdadaeedabbaede",
      "eeebbcaaeedbcbec",
      "ZZZcZZZbbeaeadec",
      "   d   bbdbadeda",
      "   a   acacebada",
      " G e G bbbeaecab"
    ],
    [
      " d      a  H    ",
      " e              ",
      " a            Oϓ",
      " d      c      H",
      "bcdcbbaba       ",
      " b  x  e        ",
      "       b        ",
      "             cdb",
      "             c  ",
      "             b  ",
      "       a     a  ",
      "   a   c        ",
      "vvvcvvvd        ",
      "   e   c     d  ",
      "   b   ad   aeeb",
      " G a G c     d  "
    ],
    [
      " b      d       ",
      " d              ",
      " b              ",
      " c      e       ",
      "cbcNNNcce       ",
      " a  k  a        ",
      "       e        ",
      "             acb",
      "             d  ",
      "             c  ",
      "       c     b  ",
      "   a   a        ",
      "vvncvvvd        ",
      "   c   d     a  ",
      "   d   bc   cadd",
      " G c G c     e  "
    ],
    [
      " d      c       ",
      " a              ",
      " a              ",
      " c      c       ",
      "aeeѴ  aea       ",
      " c  k  e        ",
      "       a        ",
      "             cbc",
      "             b  ",
      "             e  ",
      "       d     a  ",
      "   d   a        ",
      "vvoavvva        ",
      "   d   a     e  ",
      "   b   dd   addc",
      " G b G c     e  "
    ],
    [
      " a      d       ",
      " d      j       ",
      " d      j       ",
      " e      c       ",
      "ebecbeedd       ",
      " a     e        ",
      "       c        ",
      "       j     dac",
      "       j     a  ",
      "       j     b  ",
      "       a     d  ",
      "jjjbjjja     j  ",
      "voodvvve     j  ",
      "   a   e     d  ",
      "   e   dcjjjbedc",
      " G e G c     a  "
    ],
    [
      " b      b       ",
      " a      c       ",
      " e      d       ",
      " a      e       ",
      "dbeecadbe       ",
      " d     e        ",
      "       c        ",
      "       a     beb",
      "       c     b  ",
      "       e     e  ",
      "       e     d  ",
      "aecccbde     c  ",
      "   c   d     a  ",
      "   d   e     d  ",
      "   b   dabbebccc",
      " G d G d     e  "
    ]
  ]
}