{
  "xsize": 16,
  "zsize": 16,
  "palette": {
    "palette": [
      {
        "char": " ",
        "block": "minecraft:air"
      },
      {
        "char": "a",
        "block": "minecraft:cyan_terracotta"
      },
      {
        "char": "d",
        "block": "minecraft:cobbled_deepslate"
      },
      {
        "char": "c",
        "block": "minecraft:deepslate[axis=y]"
      },
      {
        "char": "e",
        "block": "minecraft:basalt[axis=y]"
      },
      {
        "char": "b",
        "block": "minecraft:blackstone"
      },
      {
        "char": "Р",
        "block": "minecraft:stone_brick_stairs[facing=north,half=bottom,shape=straight,waterlogged=false,weathering=false]"
      },
      {
        "char": "z",
        "block": "minecraft:iron_bars[east=false,north=true,south=true,waterlogged=false,west=false]"
      },
      {
        "char": "Y",
        "block": "minecraft:iron_bars[east=false,north=true,south=false,waterlogged=false,west=false]"
      },
      {
        "char": "O",
        "block": "minecraft:quartz_stairs[facing=west,half=bottom,shape=straight,waterlogged=false]"
      },
      {
        "char": "П",
        "block": "minecraft:barrel[facing=up,open=false]",
        "tag": {
          "z": -275,
          "x": -15,
          "ForgeData": {
            "LockFlag": "1b"
          },
          "id": "minecraft:barrel",
          "y": 2,
          "Items": []
        }
      },
      {
        "char": "x",
        "block": "minecraft:cauldron"
      },
      {
        "char": "У",
        "block": "minecraft:stone_brick_stairs[facing=south,half=bottom,shape=straight,waterlogged=false,weathering=false]"
      },
      {
        "char": "С",
        "block": "minecraft:stone_brick_stairs[facing=north,half=top,shape=straight,waterlogged=false,weathering=false]"
      },
      {
        "char": "Ѥ",
        "block": "minecraft:air",
        "tag": {
          "z": -276,
          "x": -43,
          "id": "refurbished_furniture:computer",
          "y": -39,
          "NodePos": "-11544873218087L",
          "Connections": [
            "L"
          ]
        }
      },
      {
        "char": "N",
        "block": "minecraft:white_stained_glass_pane[east=true,north=false,south=false,waterlogged=false,west=true]"
      },
      {
        "char": "k",
        "block": "minecraft:oak_leaves[distance=7,persistent=true,waterlogged=false]"
      },
      {
        "char": "Ѵ",
        "block": "minecraft:white_stained_glass_pane[east=false,north=false,south=false,waterlogged=false,west=true]"
      },
      {
        "char": "Ѳ",
        "block": "minecraft:white_stained_glass_pane[east=true,north=false,south=false,waterlogged=false,west=false]"
      },
      {
        "char": "道",
        "block": "minecraft:air"
      },
      {
        "char": "j",
        "block": "minecraft:polished_andesite_slab[type=top,waterlogged=false]"
      },
      {
        "char": "小",
        "block": "minecraft:air"
      }
    ]
  },
  "slices": [
    [
      "a     dddacecdee",
      "ddbcdcacadbcbdac",
      "cccdcaebdecbaaec",
      "bdccddaadcdaebce",
      "acbeaceccbedddec",
      "cabaaaebeabbbdbc",
      "bccaddaaaecebdea",
      "acbeaabbdeebbbdd",
      "bbaddbddeeeabeba",
      "ecbcdbdeededcede",
      "edcceeedbbaedabd",
      "ebcbbaaedadedace",
      "eddbbedcdbccРz a",
      "bedcaacceedd z e",
      "cebccabaccbd Y a",
      "edebcdcbaaab   a"
    ],
    [
      "d         c     ",
      "cdd             ",
      "a               ",
      "  c  d    c     ",
      " Ob Oc    bdceaa",
      "  d  П     b  x ",
      "           e    ",
      "  e  b          ",
      " Oe Od          ",
      "  a  a          ",
      "           a    ",
      "  c  a     e e d",
      " Oc Ob     e zУc",
      "  b  d     e zСd",
      "edaeeec   cc Y e",
      "  a  b     c   e"
    ],
    [
      "          c     ",
      "                ",
      "                ",
      "          c     ",
      "  Ѥ  Ѥ    abcNNN",
      "           b  k ",
      "           c    ",
      "                ",
      "  Ѥ  Ѥ          ",
      "                ",
      "           c    ",
      "           a b b",
      "  Ѥ  Ѥ     e z c",
      "           d zУb",
      "accebeb   ce YСb",
      "     c     b   b"
    ],
    [
      "          d     ",
      "                ",
      "                ",
      "          a     ",
      "          ccbѴ Ѳ",
      "           e  k ",
      "           d    ",
      "                ",
      "                ",
      "                ",
      "           a    ",
      "           c b e",
      "           d z d",
      "           d z c",
      "daecceb   bd道zУa",
      "     c     eeccd"
    ],
    [
      "          e     ",
      "          j     ",
      "          j     ",
      "          a     ",
      "          dadcce",
      "           a    ",
      "           d    ",
      "           j    ",
      "           j    ",
      "           j    ",
      "           a    ",
      "           ccbee",
      "           b z e",
      "           e道z a",
      "badbcadjjjdc小Y c",
      "     e     c   c"
    ],
    [
      "          c     ",
      "          a     ",
      "          d     ",
      "          b     ",
      "          cdaacd",
      "           d    ",
      "           d    ",
      "           a    ",
      "           c    ",
      "           a    ",
      "           b    ",
      "           bbddc",
      "           c道z d",
      "           d小z a",
      "edaaeccddcdc Y b",
      "     d     e   a"
    ]
  ]
}