{
  "xsize": 16,
  "zsize": 16,
  "palette": {
    "palette": [
      {
        "char": " ",
        "block": "minecraft:air"
      },
      {
        "char": "c",
        "block": "minecraft:deepslate[axis=y]"
      },
      {
        "char": "d",
        "block": "minecraft:cobbled_deepslate"
      },
      {
        "char": "a",
        "block": "minecraft:cyan_terracotta"
      },
      {
        "char": "e",
        "block": "minecraft:basalt[axis=y]"
      },
      {
        "char": "b",
        "block": "minecraft:blackstone"
      },
      {
        "char": "Z",
        "block": "minecraft:stone_brick_wall[east=tall,north=tall,south=none,up=true,waterlogged=false,weathering=false,west=tall]"
      },
      {
        "char": "Ӿ",
        "block": "minecraft:cobblestone_wall[east=tall,north=tall,south=none,up=true,waterlogged=false,weathering=false,west=tall]"
      },
      {
        "char": "G",
        "block": "minecraft:iron_bars[east=false,north=false,south=true,waterlogged=false,west=false]"
      },
      {
        "char": "x",
        "block": "minecraft:cauldron"
      },
      {
        "char": "n",
        "block": "minecraft:smooth_quartz"
      },
      {
        "char": "v",
        "block": "minecraft:quartz_pillar[axis=x]"
      },
      {
        "char": "o",
        "block": "minecraft:chiseled_quartz_block"
      },
      {
        "char": "k",
        "block": "minecraft:oak_leaves[distance=7,persistent=true,waterlogged=false]"
      },
      {
        "char": "r",
        "block": "minecraft:polished_diorite"
      },
      {
        "char": "J",
        "block": "minecraft:diorite"
      },
      {
        "char": "I",
        "block": "minecraft:stone_slab[type=top,waterlogged=false,weathering=false]"
      },
      {
        "char": "j",
        "block": "minecraft:polished_andesite_slab[type=top,waterlogged=false]"
      }
    ]
  },
  "slices": [
    [
      "cdaaebacedeadcee",
      "ccbeaaaeceecaeea",
      "abeadccaeabadcae",
      "ccaaeddecbccecde",
      "edcdbdbbeccaabbe",
      "becbadeacbebccea",
      "bacecdbbeeadbccb",
      "cddacbbcbdacccda",
      "dbccccdbaedadcbd",
      "ceccdcdbabeecdca",
      "decdcdbcbadebacc",
      "bceadeeedeeccccc",
      "ZӾZcZZZbdadeacdd",
      "   e   aaeedccdb",
      "   b   addbecbed",
      " G c G cdbcaecaa"
    ],
    [
      " c       e      ",
      "          bc    ",
      "            a   ",
      "             a  ",
      " c            b ",
      "xax           d ",
      " c      x  x   d",
      "dcde   ecbdaebae",
      "          x  x  ",
      "                ",
      "                ",
      "   a   a        ",
      "nvoavvva        ",
      "   b   c        ",
      "   a   ae      a",
      " G e G b        "
    ],
    [
      " e       d      ",
      "          bc    ",
      "            b   ",
      "             a  ",
      " b            e ",
      "kak           d ",
      " a      k  k   b",
      "daed   cebbebeae",
      "          k  k  ",
      "                ",
      "                ",
      "   e   a        ",
      "vrvcvonc        ",
      "   e   d        ",
      "   c   ab      c",
      " G e G b        "
    ],
    [
      " a       d      ",
      "          ce    ",
      "            c   ",
      "             e  ",
      " a            e ",
      "kbk           d ",
      " b      k  k   e",
      "cadc   bbcdbbcec",
      "          k  k  ",
      "                ",
      "                ",
      "   d   b        ",
      "vvvcJnJb        ",
      "   d   e        ",
      "   c   de      e",
      " G b G d        "
    ],
    [
      " b       c      ",
      " I        ec    ",
      " I          a   ",
      " I           e  ",
      " a            a ",
      " b            e ",
      " c             a",
      "eaaaIIIacabeebed",
      "                ",
      "                ",
      "                ",
      "jjjejjjb        ",
      "vvndovod        ",
      "   c   c        ",
      "   b   caIIIIIIe",
      " G c G b        "
    ],
    [
      " b       e      ",
      " c        ed    ",
      " d          b   ",
      " e           e  ",
      " d            c ",
      " d            d ",
      " b             e",
      "bcdadaeaaddadcab",
      "                ",
      "                ",
      "                ",
      "dbbbbeeb        ",
      "   c   e        ",
      "   d   b        ",
      "   c   eeeebadaa",
      " G d G c        "
    ]
  ]
}