{
  "xsize": 16,
  "zsize": 16,
  "palette": {
    "palette": [
      {
        "char": " ",
        "block": "minecraft:air"
      },
      {
        "char": "d",
        "block": "minecraft:cobbled_deepslate"
      },
      {
        "char": "a",
        "block": "minecraft:cyan_terracotta"
      },
      {
        "char": "e",
        "block": "minecraft:basalt[axis=y]"
      },
      {
        "char": "b",
        "block": "minecraft:blackstone"
      },
      {
        "char": "c",
        "block": "minecraft:deepslate[axis=y]"
      },
      {
        "char": "g",
        "block": "minecraft:gray_concrete"
      },
      {
        "char": "i",
        "block": "minecraft:light_gray_concrete"
      },
      {
        "char": "f",
        "block": "minecraft:glass"
      },
      {
        "char": "H",
        "block": "minecraft:quartz_stairs[facing=south,half=bottom,shape=straight,waterlogged=false]"
      },
      {
        "char": "ϐ",
        "block": "minecraft:air",
        "tag": {
          "z": -259,
          "x": -34,
          "id": "refurbished_furniture:computer",
          "y": -21,
          "NodePos": "-9070971985941L",
          "Connections": [
            "L"
          ]
        }
      },
      {
        "char": "l",
        "block": "minecraft:iron_trapdoor[facing=east,half=bottom,open=false,powered=false,waterlogged=false]"
      },
      {
        "char": "u",
        "block": "minecraft:iron_trapdoor[facing=south,half=bottom,open=false,powered=false,waterlogged=false]"
      },
      {
        "char": "上",
        "block": "minecraft:air"
      },
      {
        "char": "w",
        "block": "minecraft:iron_trapdoor[facing=south,half=top,open=false,powered=false,waterlogged=false]"
      },
      {
        "char": "j",
        "block": "minecraft:polished_andesite_slab[type=top,waterlogged=false]"
      }
    ]
  },
  "slices": [
    [
      "daeebebceddddaaa",
      "bdcebdbceaabagaa",
      "baddeeebdbaaebia",
      "eceddaaaaaddga  ",
      "aagggadaddia    ",
      "baaaae  aa      ",
      " a              ",
      "                ",
      " c       e    c ",
      "                ",
      "                ",
      "                ",
      "                ",
      "                ",
      "                ",
      "                "
    ],
    [
      "   eec eda    f ",
      "    H   H   ffd ",
      " d         f   a",
      " b    ffaf      ",
      "fa fff  c       ",
      " e      g       ",
      " a              ",
      "                ",
      " d       e    e ",
      "                ",
      "                ",
      "                ",
      "                ",
      "                ",
      "                ",
      "                "
    ],
    [
      "    ϐ   ϐ     fl",
      "            ffa ",
      " e        f uu a",
      " e    ffafuu    ",
      "fafff uub上      ",
      "ucuuuu  a       ",
      " a              ",
      "                ",
      " e       e    c ",
      "                ",
      "                ",
      "                ",
      "                ",
      "                ",
      "                ",
      "                "
    ],
    [
      "              fw",
      "            f c ",
      " a        ffww a",
      " e     fafww    ",
      "faffffwwew      ",
      "wawwww  i       ",
      " a              ",
      "                ",
      " c       a    c ",
      "                ",
      "                ",
      "                ",
      "                ",
      "                ",
      "                ",
      "                "
    ],
    [
      " j              ",
      " j           fe ",
      " c        ff   a",
      " e    ffaf      ",
      "faffff  e       ",
      " e      a       ",
      " a              ",
      "                ",
      " d       a    e ",
      "                ",
      "                ",
      "                ",
      "                ",
      "                ",
      "                ",
      "                "
    ],
    [
      " b            ae",
      " a          age ",
      " b        aaad a",
      " b    aaagea    ",
      "gagaiadaac      ",
      "baaecc  a       ",
      " a              ",
      "                ",
      " e       c    d ",
      "                ",
      "                ",
      "                ",
      "                ",
      "                ",
      "                ",
      "                "
    ]
  ]
}