{
  "xsize": 16,
  "zsize": 16,
  "palette": {
    "palette": [
      {
        "char": " ",
        "block": "minecraft:air"
      },
      {
        "char": "Ӥ",
        "block": "minecraft:stone_brick_wall[east=none,north=tall,south=none,up=true,waterlogged=false,weathering=false,west=none]"
      },
      {
        "char": "e",
        "block": "minecraft:basalt[axis=y]"
      },
      {
        "char": "a",
        "block": "minecraft:cyan_terracotta"
      },
      {
        "char": "R",
        "block": "minecraft:yellow_concrete"
      },
      {
        "char": "ϖ",
        "block": "minecraft:yellow_terracotta"
      },
      {
        "char": "b",
        "block": "minecraft:blackstone"
      },
      {
        "char": "c",
        "block": "minecraft:deepslate[axis=y]"
      },
      {
        "char": "Ҡ",
        "block": "minecraft:yellow_wool"
      },
      {
        "char": "ϗ",
        "block": "minecraft:stone_brick_wall[east=none,north=none,south=none,up=true,waterlogged=false,weathering=false,west=none]"
      },
      {
        "char": "d",
        "block": "minecraft:cobbled_deepslate"
      },
      {
        "char": "á",
        "block": "minecraft:cobblestone_wall[east=none,north=none,south=none,up=true,waterlogged=false,weathering=false,west=none]"
      },
      {
        "char": "ѫ",
        "block": "minecraft:quartz_slab[type=bottom,waterlogged=false]"
      },
      {
        "char": "i",
        "block": "minecraft:light_gray_concrete"
      },
      {
        "char": "C",
        "block": "minecraft:quartz_pillar[axis=y]"
      },
      {
        "char": "o",
        "block": "minecraft:chiseled_quartz_block"
      },
      {
        "char": "n",
        "block": "minecraft:smooth_quartz"
      },
      {
        "char": "g",
        "block": "minecraft:gray_concrete"
      },
      {
        "char": "各",
        "block": "minecraft:air"
      },
      {
        "char": "己",
        "block": "minecraft:stone_brick_wall[east=tall,north=none,south=tall,up=true,waterlogged=false,weathering=false,west=none]"
      },
      {
        "char": "和",
        "block": "minecraft:stone_brick_wall[east=none,north=none,south=tall,up=true,waterlogged=false,weathering=false,west=tall]"
      },
      {
        "char": "新",
        "block": "minecraft:stone_brick_wall[east=tall,north=tall,south=none,up=true,waterlogged=false,weathering=false,west=none]"
      },
      {
        "char": "行",
        "block": "minecraft:stone_brick_wall[east=none,north=tall,south=none,up=true,waterlogged=false,weathering=false,west=tall]"
      }
    ]
  },
  "slices": [
    [
      " Ӥ  Ӥ eaRϖ      ",
      "        bcҠR    ",
      "          aaϖ   ",
      "            eR  ",
      "             bҠ ",
      "             eҠ ",
      " ϗ  ϗ  ϗ      dR",
      "              dR",
      "               e",
      "           d   d",
      " ϗ  á  ϗ        ",
      "                ",
      "                ",
      "                ",
      "                ",
      "                "
    ],
    [
      " Ӥ  Ӥ eaϖR      ",
      "        ceϖR    ",
      "          aeϖ   ",
      "            bϖ  ",
      "             eϖ ",
      "             cҠ ",
      " ϗ  ϗ  á      bR",
      "              dR",
      "               a",
      "           e   e",
      " ϗ  ϗ  ϗ        ",
      "                ",
      "                ",
      "                ",
      "                ",
      "                "
    ],
    [
      " Ӥ  Ӥ deRR      ",
      "        caRR    ",
      "          dbϖ   ",
      "            dϖ  ",
      "             cҠ ",
      "             bR ",
      " ϗ  á  ϗ      aR",
      "              cR",
      "               c",
      "           d   a",
      " ϗ  ϗ  ϗ        ",
      "                ",
      "                ",
      "                ",
      "                ",
      "                "
    ],
    [
      "dcaebbdcce      ",
      "deababcaaeac    ",
      "eaeacdcdacddc   ",
      "daabdadcaaadaa  ",
      "aaaeabdadbcedbb ",
      "bcedbbabaccadcc ",
      "eeadadaeabdbdbae",
      "acadebdddabbbcda",
      "daecddbbebdabbac",
      "adccdceddeaeeaee",
      "ddcddcbaabcebebe",
      "dbebaaaadbeaaedb",
      "bedebccecdaccdbb",
      "bbaaacaccaeeceeb",
      "eabaeabbedebbadb",
      "caeecbeebdacadba"
    ],
    [
      "eaeaecedddѫѫ    ",
      "bdcdcaadaedcѫ   ",
      "ebbcccbeebbeeѫ  ",
      "bebdedeeddebadѫ ",
      "aebaaabdabdbcbbѫ",
      "ecedccabdaddcabѫ",
      "abbcdcabbccbdaed",
      "bbdcbaadeddcaeea",
      "adbaecacdbeebbbc",
      "aeddaacccdabbadc",
      "ddabcbccbeebdbbd",
      "cceebaaceecabbba",
      "eec cadeaaebbaae",
      "aieecaacececaedd",
      "adibdaddeeddbbeb",
      "eabbcebbebdbeecb"
    ],
    [
      "  c d   Ca      ",
      "        a Co    ",
      "            C   ",
      "             C  ",
      "              n ",
      "      bd bb   C ",
      "      ba cb    g",
      "              gC",
      "      cb cd     ",
      "      dc bb     ",
      "                ",
      "      ca bd     ",
      "   各  da ea     ",
      "己a和             ",
      "dad   ba bc     ",
      "新c行   ea ca     "
    ]
  ]
}