{
  "xsize": 16,
  "zsize": 16,
  "palette": {
    "palette": [
      {
        "char": " ",
        "block": "minecraft:air"
      },
      {
        "char": "a",
        "block": "minecraft:cyan_terracotta"
      },
      {
        "char": "e",
        "block": "minecraft:basalt[axis=y]"
      },
      {
        "char": "i",
        "block": "minecraft:light_gray_concrete"
      },
      {
        "char": "c",
        "block": "minecraft:deepslate[axis=y]"
      },
      {
        "char": "b",
        "block": "minecraft:blackstone"
      },
      {
        "char": "d",
        "block": "minecraft:cobbled_deepslate"
      },
      {
        "char": "g",
        "block": "minecraft:gray_concrete"
      },
      {
        "char": "f",
        "block": "minecraft:glass"
      },
      {
        "char": "ϕ",
        "block": "minecraft:quartz_stairs[facing=north,half=bottom,shape=straight,waterlogged=false]"
      },
      {
        "char": "s",
        "block": "minecraft:iron_trapdoor[facing=north,half=bottom,open=false,powered=false,waterlogged=false]"
      },
      {
        "char": "如",
        "block": "minecraft:air"
      },
      {
        "char": "m",
        "block": "minecraft:iron_trapdoor[facing=west,half=bottom,open=false,powered=false,waterlogged=false]"
      },
      {
        "char": "多",
        "block": "minecraft:air"
      },
      {
        "char": "p",
        "block": "minecraft:iron_trapdoor[facing=north,half=top,open=false,powered=false,waterlogged=false]"
      },
      {
        "char": "q",
        "block": "minecraft:iron_trapdoor[facing=west,half=top,open=false,powered=false,waterlogged=false]"
      },
      {
        "char": "说",
        "block": "minecraft:air"
      }
    ]
  },
  "slices": [
    [
      "                ",
      "                ",
      "                ",
      "                ",
      "                ",
      "                ",
      "                ",
      "         aa  aea",
      "       aiacbdgaa",
      "     igcbagaaeba",
      "   ggbdaabeebacb",
      "  aicagdeeabaeab",
      " addgdabbaaaaeba",
      "abageebeaebeccbd",
      "baaaedabddeaddbe",
      "aaababbdbbbbeedb"
    ],
    [
      "                ",
      "                ",
      "                ",
      "                ",
      "                ",
      "                ",
      "                ",
      "          i     ",
      "          c  ff ",
      "          aff   ",
      "   a   ff c     ",
      "    dff   b     ",
      "          b ϕ   ",
      "  ff      e   b ",
      "          badad ",
      "f    d    a     "
    ],
    [
      "                ",
      "                ",
      "                ",
      "                ",
      "                ",
      "                ",
      "                ",
      "          g  sss",
      "         sbssf f",
      "       ssfgff   ",
      "   i ssf  e     ",
      "    e f   e     ",
      "  如s      d     ",
      " sff      c     ",
      "m         c 多   ",
      "          b     "
    ],
    [
      "                ",
      "                ",
      "                ",
      "                ",
      "                ",
      "                ",
      "                ",
      "          a  ppp",
      "         pcppfff",
      "       ppfaf    ",
      "   a ppf  a     ",
      "    ef    a     ",
      "  pqf     c     ",
      " 说 f      b     ",
      "pf        c     ",
      "f         d     "
    ],
    [
      "                ",
      "                ",
      "                ",
      "                ",
      "                ",
      "                ",
      "                ",
      "          a     ",
      "          b   f ",
      "         faf    ",
      "   a   ff c     ",
      "    cf    c     ",
      "    f     d     ",
      "  ff      a     ",
      " f        b     ",
      "          e     "
    ],
    [
      "                ",
      "                ",
      "                ",
      "                ",
      "                ",
      "                ",
      "                ",
      "          a  dba",
      "         adcaaaa",
      "       bcagaa   ",
      "   g daai b     ",
      "    baa   d     ",
      "  cei     c     ",
      " aai      c     ",
      "ea        d     ",
      "a         c     "
    ]
  ]
}