{
  "xsize": 16,
  "zsize": 16,
  "palette": {
    "palette": [
      {
        "char": " ",
        "block": "minecraft:air"
      },
      {
        "char": "b",
        "block": "minecraft:blackstone"
      },
      {
        "char": "a",
        "block": "minecraft:cyan_terracotta"
      },
      {
        "char": "c",
        "block": "minecraft:deepslate[axis=y]"
      },
      {
        "char": "e",
        "block": "minecraft:basalt[axis=y]"
      },
      {
        "char": "d",
        "block": "minecraft:cobbled_deepslate"
      },
      {
        "char": "g",
        "block": "minecraft:gray_concrete"
      },
      {
        "char": "i",
        "block": "minecraft:light_gray_concrete"
      },
      {
        "char": "H",
        "block": "minecraft:quartz_stairs[facing=south,half=bottom,shape=straight,waterlogged=false]"
      },
      {
        "char": "f",
        "block": "minecraft:glass"
      },
      {
        "char": "ѷ",
        "block": "minecraft:air"
      },
      {
        "char": "ο",
        "block": "minecraft:air"
      },
      {
        "char": "l",
        "block": "minecraft:iron_trapdoor[facing=east,half=bottom,open=false,powered=false,waterlogged=false]"
      },
      {
        "char": "u",
        "block": "minecraft:iron_trapdoor[facing=south,half=bottom,open=false,powered=false,waterlogged=false]"
      },
      {
        "char": "w",
        "block": "minecraft:iron_trapdoor[facing=south,half=top,open=false,powered=false,waterlogged=false]"
      },
      {
        "char": "j",
        "block": "minecraft:polished_andesite_slab[type=top,waterlogged=false]"
      }
    ]
  },
  "slices": [
    [
      "bbaceecbcdaeedac",
      "acdcacdbeaedgabg",
      "ccddecaceeagcaaa",
      "baaabcagaabaag  ",
      "agagaaaedeai    ",
      "ebacea  ga      ",
      " a              ",
      "                ",
      " c       b    e ",
      "                ",
      "                ",
      "                ",
      "                ",
      "                ",
      "                ",
      "                "
    ],
    [
      "   cbd aca      ",
      "    H   H   ffa ",
      " c        ff   a",
      " d     fif      ",
      " i f f  d       ",
      " d      a       ",
      " i              ",
      "                ",
      " e       b    e ",
      "                ",
      "                ",
      "                ",
      "                ",
      "                ",
      "                ",
      "                "
    ],
    [
      "    ѷ   ο     fl",
      "             fd ",
      " c        ffuu a",
      " e      afuu    ",
      " af f uueu      ",
      "uduuuu  a       ",
      " i              ",
      "                ",
      " b       d    e ",
      "                ",
      "                ",
      "                ",
      "                ",
      "                ",
      "                ",
      "                "
    ],
    [
      "              fw",
      "            ffc ",
      " b         fww a",
      " e     fafww    ",
      "faf  fwwdw      ",
      "wawwww  a       ",
      " a              ",
      "                ",
      " a       a    a ",
      "                ",
      "                ",
      "                ",
      "                ",
      "                ",
      "                ",
      "                "
    ],
    [
      " j              ",
      " j            c ",
      " d        f    g",
      " a     faf      ",
      " a fff  e       ",
      " d      i       ",
      " a              ",
      "                ",
      " a       a    e ",
      "                ",
      "                ",
      "                ",
      "                ",
      "                ",
      "                ",
      "                "
    ],
    [
      " d            ac",
      " e          aaa ",
      " b        aacb g",
      " b    aaiade    ",
      "agaaaacaac      ",
      "edabad  a       ",
      " g              ",
      "                ",
      " b       d    c ",
      "                ",
      "                ",
      "                ",
      "                ",
      "                ",
      "                ",
      "                "
    ]
  ]
}