{
  "xsize": 16,
  "zsize": 16,
  "palette": {
    "palette": [
      {
        "char": " ",
        "block": "minecraft:air"
      },
      {
        "char": "d",
        "block": "minecraft:cobbled_deepslate"
      },
      {
        "char": "c",
        "block": "minecraft:deepslate[axis=y]"
      },
      {
        "char": "e",
        "block": "minecraft:basalt[axis=y]"
      },
      {
        "char": "a",
        "block": "minecraft:cyan_terracotta"
      },
      {
        "char": "b",
        "block": "minecraft:blackstone"
      },
      {
        "char": "i",
        "block": "minecraft:light_gray_concrete"
      },
      {
        "char": "ϕ",
        "block": "minecraft:quartz_stairs[facing=north,half=bottom,shape=straight,waterlogged=false]"
      },
      {
        "char": "O",
        "block": "minecraft:quartz_stairs[facing=west,half=bottom,shape=straight,waterlogged=false]"
      },
      {
        "char": "ϓ",
        "block": "minecraft:air"
      },
      {
        "char": "ϔ",
        "block": "minecraft:quartz_stairs[facing=east,half=bottom,shape=straight,waterlogged=false]"
      },
      {
        "char": "x",
        "block": "minecraft:cauldron"
      },
      {
        "char": "f",
        "block": "minecraft:glass"
      },
      {
        "char": "g",
        "block": "minecraft:gray_concrete"
      },
      {
        "char": "m",
        "block": "minecraft:iron_trapdoor[facing=west,half=bottom,open=false,powered=false,waterlogged=false]"
      },
      {
        "char": "k",
        "block": "minecraft:oak_leaves[distance=7,persistent=true,waterlogged=false]"
      },
      {
        "char": "u",
        "block": "minecraft:iron_trapdoor[facing=south,half=bottom,open=false,powered=false,waterlogged=false]"
      },
      {
        "char": "q",
        "block": "minecraft:iron_trapdoor[facing=west,half=top,open=false,powered=false,waterlogged=false]"
      },
      {
        "char": "w",
        "block": "minecraft:iron_trapdoor[facing=south,half=top,open=false,powered=false,waterlogged=false]"
      },
      {
        "char": "I",
        "block": "minecraft:stone_slab[type=top,waterlogged=false,weathering=false]"
      }
    ]
  },
  "slices": [
    [
      "ddceaaaaeaadccce",
      "edeecbccbdaaceee",
      "dabecebabebdebda",
      "ebbdbcbcaaecabee",
      "bcabdbcccddbcaab",
      "eacadbccaeeacccd",
      "iaadadbecdedadae",
      "  a cadbbecacede",
      "    dcbdcbeaaaca",
      "     accbcedacad",
      "      cbdabeaeaa",
      "       babacbcbe",
      "         ccabadc",
      "        a     da",
      "                ",
      "                "
    ],
    [
      "           bbebd",
      "                ",
      "  e             ",
      "  a             ",
      "  b   ϕ   adb   ",
      "adb  Oϓϔ  c     ",
      "   bc     c     ",
      "  a       cx    ",
      "          d     ",
      "      f   d     ",
      "       ff dx    ",
      "         ee    b",
      "         ac  ceb",
      "        g       ",
      "                ",
      "                "
    ],
    [
      "           caddc",
      "                ",
      "  b             ",
      "  c             ",
      "  a       bca   ",
      "ebb       e     ",
      "   cd     a     ",
      "  a mf    ck    ",
      "    m     a     ",
      "     mf   a     ",
      "      mff dk    ",
      "       uudb     ",
      "         bc     ",
      "        a       ",
      "                ",
      "                "
    ],
    [
      "           ceece",
      "                ",
      "  c             ",
      "  a             ",
      "  d       abc   ",
      "baa       a     ",
      "   ac     a     ",
      "  a qf    bk    ",
      "    qf    d     ",
      "     wf   b     ",
      "      qff ek    ",
      "       wwbc     ",
      "         be     ",
      "        a ca    ",
      "                ",
      "                "
    ],
    [
      "  I        cbeec",
      "  I             ",
      "  d             ",
      "  a             ",
      "  b       deeIII",
      "eea       c     ",
      "   dc     e     ",
      "  g  f    d     ",
      "     f    b     ",
      "      f   c     ",
      "          a     ",
      "         bc     ",
      "         cd     ",
      "        a       ",
      "                ",
      "                "
    ],
    [
      "  e        cbbac",
      "  d             ",
      "  d             ",
      "  d             ",
      "  c       ddecbb",
      "ddc       d     ",
      "   e      b     ",
      "  i da    e     ",
      "    ea    e     ",
      "     bc   a     ",
      "      ccd d     ",
      "       aa a     ",
      "         aa     ",
      "        a       ",
      "                ",
      "                "
    ]
  ]
}