{
  "xsize": 16,
  "zsize": 16,
  "palette": {
    "palette": [
      {
        "char": " ",
        "block": "minecraft:air"
      },
      {
        "char": "a",
        "block": "minecraft:cyan_terracotta"
      },
      {
        "char": "g",
        "block": "minecraft:gray_concrete"
      },
      {
        "char": "c",
        "block": "minecraft:deepslate[axis=y]"
      },
      {
        "char": "e",
        "block": "minecraft:basalt[axis=y]"
      },
      {
        "char": "b",
        "block": "minecraft:blackstone"
      },
      {
        "char": "d",
        "block": "minecraft:cobbled_deepslate"
      },
      {
        "char": "i",
        "block": "minecraft:light_gray_concrete"
      },
      {
        "char": "x",
        "block": "minecraft:cauldron"
      },
      {
        "char": "f",
        "block": "minecraft:glass"
      },
      {
        "char": "O",
        "block": "minecraft:quartz_stairs[facing=west,half=bottom,shape=straight,waterlogged=false]"
      },
      {
        "char": "m",
        "block": "minecraft:iron_trapdoor[facing=west,half=bottom,open=false,powered=false,waterlogged=false]"
      },
      {
        "char": "k",
        "block": "minecraft:oak_leaves[distance=7,persistent=true,waterlogged=false]"
      },
      {
        "char": "Ѥ",
        "block": "minecraft:air",
        "tag": {
          "z": -276,
          "x": -43,
          "id": "refurbished_furniture:computer",
          "y": -39,
          "NodePos": "-11544873218087L",
          "Connections": [
            "L"
          ]
        }
      },
      {
        "char": "q",
        "block": "minecraft:iron_trapdoor[facing=west,half=top,open=false,powered=false,waterlogged=false]"
      }
    ]
  },
  "slices": [
    [
      "                ",
      "                ",
      "                ",
      "                ",
      "                ",
      "                ",
      "           aaaaa",
      "          gagaac",
      "           agebc",
      "           aabda",
      "          agdbdd",
      "          cidccb",
      "          cgbecc",
      "          eabcca",
      "         geadabd",
      "          aaabcd"
    ],
    [
      "                ",
      "                ",
      "                ",
      "                ",
      "                ",
      "                ",
      "           a    ",
      "          aaaaba",
      "               x",
      "            f   ",
      "           f    ",
      "           f   a",
      "             O d",
      "           f   e",
      "         abgcdca",
      "               a"
    ],
    [
      "                ",
      "                ",
      "                ",
      "                ",
      "                ",
      "                ",
      "           a    ",
      "          gaadbb",
      "           m   k",
      "           mf   ",
      "          mf    ",
      "          mf    ",
      "          mf   Ѥ",
      "          m     ",
      "         aaadccb",
      "          mf    "
    ],
    [
      "                ",
      "                ",
      "                ",
      "                ",
      "                ",
      "                ",
      "           a    ",
      "          aagede",
      "           qf  k",
      "           qf   ",
      "          q     ",
      "          qf    ",
      "          qf    ",
      "          qf    ",
      "         iagaabe",
      "          qf    "
    ],
    [
      "                ",
      "                ",
      "                ",
      "                ",
      "                ",
      "                ",
      "           i    ",
      "          gaabba",
      "            f   ",
      "            f   ",
      "           f    ",
      "                ",
      "           f    ",
      "           f    ",
      "         adaaeae",
      "           f    "
    ],
    [
      "                ",
      "                ",
      "                ",
      "                ",
      "                ",
      "                ",
      "           i    ",
      "          aaaaee",
      "           ba   ",
      "           ca   ",
      "          bg    ",
      "          ca    ",
      "          di    ",
      "          aa    ",
      "         idabecb",
      "          da    "
    ]
  ]
}