{
  "xsize": 16,
  "zsize": 16,
  "palette": {
    "palette": [
      {
        "char": " ",
        "block": "minecraft:air"
      },
      {
        "char": "b",
        "block": "minecraft:blackstone"
      },
      {
        "char": "a",
        "block": "minecraft:cyan_terracotta"
      },
      {
        "char": "d",
        "block": "minecraft:cobbled_deepslate"
      },
      {
        "char": "e",
        "block": "minecraft:basalt[axis=y]"
      },
      {
        "char": "c",
        "block": "minecraft:deepslate[axis=y]"
      },
      {
        "char": "Z",
        "block": "minecraft:stone_brick_wall[east=tall,north=tall,south=none,up=true,waterlogged=false,weathering=false,west=tall]"
      },
      {
        "char": "Ӿ",
        "block": "minecraft:cobblestone_wall[east=tall,north=tall,south=none,up=true,waterlogged=false,weathering=false,west=tall]"
      },
      {
        "char": "G",
        "block": "minecraft:iron_bars[east=false,north=false,south=true,waterlogged=false,west=false]"
      },
      {
        "char": "H",
        "block": "minecraft:quartz_stairs[facing=south,half=bottom,shape=straight,waterlogged=false]"
      },
      {
        "char": "ϕ",
        "block": "minecraft:quartz_stairs[facing=north,half=bottom,shape=straight,waterlogged=false]"
      },
      {
        "char": "O",
        "block": "minecraft:quartz_stairs[facing=west,half=bottom,shape=straight,waterlogged=false]"
      },
      {
        "char": "ϓ",
        "block": "minecraft:air"
      },
      {
        "char": "x",
        "block": "minecraft:cauldron"
      },
      {
        "char": "v",
        "block": "minecraft:quartz_pillar[axis=x]"
      },
      {
        "char": "n",
        "block": "minecraft:smooth_quartz"
      },
      {
        "char": "K",
        "block": "minecraft:quartz_block"
      },
      {
        "char": "C",
        "block": "minecraft:quartz_pillar[axis=y]"
      },
      {
        "char": "o",
        "block": "minecraft:chiseled_quartz_block"
      },
      {
        "char": "N",
        "block": "minecraft:white_stained_glass_pane[east=true,north=false,south=false,waterlogged=false,west=true]"
      },
      {
        "char": "k",
        "block": "minecraft:oak_leaves[distance=7,persistent=true,waterlogged=false]"
      },
      {
        "char": "r",
        "block": "minecraft:polished_diorite"
      },
      {
        "char": "生",
        "block": "minecraft:white_stained_glass_pane[east=false,north=false,south=false,waterlogged=false,west=false]"
      },
      {
        "char": "j",
        "block": "minecraft:polished_andesite_slab[type=top,waterlogged=false]"
      }
    ]
  },
  "slices": [
    [
      "badbeebbadbbbabc",
      "edabacbaecedaeca",
      "ccdbabcddcedebeb",
      "bcccbedcccedbacb",
      "acbbabdcbbcccaed",
      "eedccaabcbccabeb",
      "badaadeaadecdebb",
      "bededdbdcadbcbce",
      "ceaabaebaddbdead",
      "bbbbbaeabbbddbba",
      "ebacaaedccbcabca",
      "cdadeeeddddedcbd",
      "ZZZcZZӾcdcedcdcc",
      "   d   caddceaec",
      "   c   daedecdbd",
      " G b G cbbdeebaa"
    ],
    [
      " c      d  H    ",
      " d             ϕ",
      " e            Oϓ",
      " b      b      H",
      "aadddebdb       ",
      " c  x  d        ",
      "       d        ",
      "             aeb",
      "             a  ",
      "             c  ",
      "       d     e  ",
      "   c   a        ",
      "vnKaCove        ",
      "   c   b     b  ",
      "   a   ad   cbbe",
      " G d G e     a  "
    ],
    [
      " a      a       ",
      " e              ",
      " e              ",
      " d      b       ",
      "ecaNNNedd       ",
      " b  k  c        ",
      "       d        ",
      "             dbc",
      "             e  ",
      "             d  ",
      "       b     b  ",
      "   c   d        ",
      "rvvanvvb        ",
      "   a   e     a  ",
      "   c   cb   dccd",
      " G d G c     c  "
    ],
    [
      " c      d       ",
      " c              ",
      " d              ",
      " c      b       ",
      "bbc 生 bde       ",
      " c  k  a        ",
      "       d        ",
      "             cdc",
      "             d  ",
      "             b  ",
      "       c     b  ",
      "   e   e        ",
      "vvvdrrve        ",
      "   a   d     c  ",
      "   c   aa   bded",
      " G a G e     d  "
    ],
    [
      " c      a       ",
      " b      j       ",
      " a      j       ",
      " c      c       ",
      "ecacdebed       ",
      " a     c        ",
      "       d        ",
      "       j     eee",
      "       j     c  ",
      "       j     d  ",
      "       d     d  ",
      "jjjdjjjd     j  ",
      "ovvavrvb     j  ",
      "   d   b     b  ",
      "   c   cdjjjbaec",
      " G e G c     b  "
    ],
    [
      " c      b       ",
      " e      e       ",
      " d      a       ",
      " b      d       ",
      "dadcccaba       ",
      " a     d        ",
      "       a        ",
      "       a     cee",
      "       c     e  ",
      "       d     c  ",
      "       b     d  ",
      "bcceedec     c  ",
      "   c   d     d  ",
      "   a   b     c  ",
      "   c   baaebbdde",
      " G c G d     c  "
    ]
  ]
}