{
  "xsize": 16,
  "zsize": 16,
  "palette": {
    "palette": [
      {
        "char": " ",
        "block": "minecraft:air"
      },
      {
        "char": "b",
        "block": "minecraft:blackstone"
      },
      {
        "char": "e",
        "block": "minecraft:basalt[axis=y]"
      },
      {
        "char": "a",
        "block": "minecraft:cyan_terracotta"
      },
      {
        "char": "g",
        "block": "minecraft:gray_concrete"
      },
      {
        "char": "d",
        "block": "minecraft:cobbled_deepslate"
      },
      {
        "char": "i",
        "block": "minecraft:light_gray_concrete"
      },
      {
        "char": "c",
        "block": "minecraft:deepslate[axis=y]"
      },
      {
        "char": "C",
        "block": "minecraft:quartz_pillar[axis=y]"
      },
      {
        "char": "J",
        "block": "minecraft:diorite"
      },
      {
        "char": "n",
        "block": "minecraft:smooth_quartz"
      },
      {
        "char": "x",
        "block": "minecraft:cauldron"
      },
      {
        "char": "f",
        "block": "minecraft:glass"
      },
      {
        "char": "ϔ",
        "block": "minecraft:quartz_stairs[facing=east,half=bottom,shape=straight,waterlogged=false]"
      },
      {
        "char": "m",
        "block": "minecraft:iron_trapdoor[facing=west,half=bottom,open=false,powered=false,waterlogged=false]"
      },
      {
        "char": "k",
        "block": "minecraft:oak_leaves[distance=7,persistent=true,waterlogged=false]"
      },
      {
        "char": "l",
        "block": "minecraft:iron_trapdoor[facing=east,half=bottom,open=false,powered=false,waterlogged=false]"
      },
      {
        "char": "Ӻ",
        "block": "minecraft:air",
        "tag": {
          "z": -276,
          "x": -15,
          "id": "refurbished_furniture:computer",
          "y": 27,
          "NodePos": "-3848291827685L",
          "Connections": [
            "L"
          ]
        }
      },
      {
        "char": "t",
        "block": "minecraft:iron_trapdoor[facing=east,half=top,open=false,powered=false,waterlogged=false]"
      },
      {
        "char": "I",
        "block": "minecraft:stone_slab[type=top,waterlogged=false,weathering=false]"
      }
    ]
  },
  "slices": [
    [
      "beaa g          ",
      "adaie           ",
      "cedcib          ",
      "eaceab          ",
      "bcabdab         ",
      "dcdbaab         ",
      "baeebbad        ",
      "eddbcdgaa       ",
      "adcaddaa        ",
      "aabdddae        ",
      "eacaeadac       ",
      "ceabaecgb       ",
      "edbbbcdab       ",
      "cdedbdcae       ",
      "bddcbeeaba      ",
      "bbdabecga       "
    ],
    [
      "   C a          ",
      "    J           ",
      "   a C          ",
      "     n          ",
      "      C         ",
      "a     C         ",
      "       C        ",
      "cdcabcaga       ",
      "d  x  f         ",
      "a     f         ",
      "a               ",
      "   e            ",
      "   c ϔ f        ",
      "d  e   f        ",
      "eecadaegca      ",
      "c  d   f        "
    ],
    [
      "   m g          ",
      "    a           ",
      "   i m          ",
      "     m          ",
      "      m         ",
      "a     m         ",
      "       a        ",
      "adeaddaag       ",
      "c  k  fl        ",
      "b     fl        ",
      "e      fl       ",
      "       fl       ",
      "   Ӻ   fl       ",
      "d      fl       ",
      "eadaebcada      ",
      "d      fl       "
    ],
    [
      "     g          ",
      "    g           ",
      "   a            ",
      "                ",
      "                ",
      "a               ",
      "       g        ",
      "cddaccaag       ",
      "e  k  ft        ",
      "c     ft        ",
      "a      ft       ",
      "       ft       ",
      "        t       ",
      "b      ft       ",
      "dcddbddaba      ",
      "d      ft       "
    ],
    [
      "                ",
      "                ",
      "                ",
      "                ",
      "                ",
      "a               ",
      "       a        ",
      "cacedaaaa       ",
      "c     f         ",
      "a     f         ",
      "b      f        ",
      "I      f        ",
      "I      f        ",
      "c      f        ",
      "cdeeaacica      ",
      "d               "
    ],
    [
      "                ",
      "                ",
      "                ",
      "                ",
      "                ",
      "g               ",
      "       a        ",
      "deabccaia       ",
      "d     ac        ",
      "c     ad        ",
      "b      gd       ",
      "d      id       ",
      "c      ad       ",
      "c      id       ",
      "dbbbebbada      ",
      "b      aa       "
    ]
  ]
}