{
  "xsize": 16,
  "zsize": 16,
  "palette": {
    "palette": [
      {
        "char": " ",
        "block": "minecraft:air"
      },
      {
        "char": "a",
        "block": "minecraft:cyan_terracotta"
      },
      {
        "char": "c",
        "block": "minecraft:deepslate[axis=y]"
      },
      {
        "char": "g",
        "block": "minecraft:gray_concrete"
      },
      {
        "char": "b",
        "block": "minecraft:blackstone"
      },
      {
        "char": "d",
        "block": "minecraft:cobbled_deepslate"
      },
      {
        "char": "e",
        "block": "minecraft:basalt[axis=y]"
      },
      {
        "char": "f",
        "block": "minecraft:glass"
      },
      {
        "char": "ϕ",
        "block": "minecraft:quartz_stairs[facing=north,half=bottom,shape=straight,waterlogged=false]"
      },
      {
        "char": "x",
        "block": "minecraft:cauldron"
      },
      {
        "char": "s",
        "block": "minecraft:iron_trapdoor[facing=north,half=bottom,open=false,powered=false,waterlogged=false]"
      },
      {
        "char": "i",
        "block": "minecraft:light_gray_concrete"
      },
      {
        "char": "Ҝ",
        "block": "minecraft:air",
        "tag": {
          "z": -292,
          "x": -29,
          "id": "refurbished_furniture:computer",
          "y": 63,
          "NodePos": "-7696582590401L",
          "Connections": [
            "L"
          ]
        }
      },
      {
        "char": "k",
        "block": "minecraft:oak_leaves[distance=7,persistent=true,waterlogged=false]"
      },
      {
        "char": "p",
        "block": "minecraft:iron_trapdoor[facing=north,half=top,open=false,powered=false,waterlogged=false]"
      },
      {
        "char": "I",
        "block": "minecraft:stone_slab[type=top,waterlogged=false,weathering=false]"
      }
    ]
  },
  "slices": [
    [
      "                ",
      "                ",
      "                ",
      "                ",
      "                ",
      "                ",
      " a              ",
      "caccaa  a       ",
      "aaaagabdaa      ",
      "cadaabagaa      ",
      "cdcbdcbdda      ",
      "cbbbccceda      ",
      "eebedaaaaa      ",
      "eaacabedba      ",
      "baaacdbecg      ",
      "aceddcabaag     "
    ],
    [
      "                ",
      "                ",
      "                ",
      "                ",
      "                ",
      "                ",
      " a              ",
      " e      a       ",
      "faff    aa      ",
      " c    ffa       ",
      " e ϕ    b       ",
      " b      e       ",
      "eadba  xd       ",
      " c      b       ",
      " d      d       ",
      "bdd  bcbb g     "
    ],
    [
      "                ",
      "                ",
      "                ",
      "                ",
      "                ",
      "                ",
      " a              ",
      "sdssss  a       ",
      "fiffffssga      ",
      " d    ffa       ",
      " e      c       ",
      " d      d       ",
      " a Ҝ   ka       ",
      " a      d       ",
      " e      d       ",
      "eae  ccbc a     "
    ],
    [
      "                ",
      "                ",
      "                ",
      "                ",
      "                ",
      "                ",
      " g              ",
      "papppp  a       ",
      "faffffppia      ",
      " e    f i       ",
      " d      b       ",
      " c      a       ",
      " e     ke       ",
      " d      c       ",
      " a      e       ",
      "cee  ccec g     "
    ],
    [
      "                ",
      "                ",
      "                ",
      "                ",
      "                ",
      "                ",
      " a              ",
      " b      g       ",
      " afff   aa      ",
      " a    ffg       ",
      " d      b       ",
      " d      b       ",
      " c      d       ",
      " d      a       ",
      " c      b       ",
      "dabIIcaea a     "
    ],
    [
      "                ",
      "                ",
      "                ",
      "                ",
      "                ",
      "                ",
      " a              ",
      "bcdebd  a       ",
      "gaggaaadaa      ",
      " a    gga       ",
      " b      b       ",
      " d      e       ",
      " c      b       ",
      " b      d       ",
      " e      b       ",
      "deedacbdd a     "
    ]
  ]
}