{
  "xsize": 16,
  "zsize": 16,
  "palette": {
    "palette": [
      {
        "char": " ",
        "block": "minecraft:air"
      },
      {
        "char": "e",
        "block": "minecraft:basalt[axis=y]"
      },
      {
        "char": "c",
        "block": "minecraft:deepslate[axis=y]"
      },
      {
        "char": "b",
        "block": "minecraft:blackstone"
      },
      {
        "char": "d",
        "block": "minecraft:cobbled_deepslate"
      },
      {
        "char": "a",
        "block": "minecraft:cyan_terracotta"
      },
      {
        "char": "x",
        "block": "minecraft:cauldron"
      },
      {
        "char": "k",
        "block": "minecraft:oak_leaves[distance=7,persistent=true,waterlogged=false]"
      },
      {
        "char": "I",
        "block": "minecraft:stone_slab[type=top,waterlogged=false,weathering=false]"
      }
    ]
  },
  "slices": [
    [
      "ecbeccbebdeeaeed",
      "eabebececdcec   ",
      "cadeddadebcc    ",
      "addbcecebdd     ",
      "dbdeecbcca      ",
      "deceeabbee      ",
      "eeadaabacd      ",
      "bceecabeac      ",
      "aaacbedbb       ",
      "bcbedae         ",
      "babccc          ",
      "abbeba          ",
      "adddd           ",
      "abaca           ",
      "cbdba           ",
      "                "
    ],
    [
      "dcebcdce        ",
      " e              ",
      " d              ",
      " e              ",
      "aba   edc       ",
      " c      a       ",
      "        d       ",
      "       xa       ",
      "        e       ",
      "                ",
      "                ",
      "                ",
      " b              ",
      "bcb             ",
      " b              ",
      "                "
    ],
    [
      "dedacccd        ",
      " d              ",
      " b              ",
      " d              ",
      "eba   abe       ",
      " d      b       ",
      "        a       ",
      "       ke       ",
      "        b       ",
      "        e       ",
      "                ",
      "                ",
      " a              ",
      "ccb             ",
      " d              ",
      "                "
    ],
    [
      "aaeebada        ",
      " b              ",
      " d              ",
      " d              ",
      "ace   cba       ",
      " c      e       ",
      "        a       ",
      "       kc       ",
      "        d       ",
      "        c       ",
      "                ",
      "                ",
      " a              ",
      "edd             ",
      " d              ",
      "                "
    ],
    [
      "ddccacda        ",
      " c              ",
      " b              ",
      " e              ",
      "bceIIIddd       ",
      " d      d       ",
      " I      c       ",
      " I      e       ",
      " I      a       ",
      " I      d       ",
      " I              ",
      " I              ",
      " d              ",
      "ddc             ",
      " b              ",
      "                "
    ],
    [
      "eaaabeac        ",
      " b              ",
      " b              ",
      " a              ",
      "cbddaebdd       ",
      " a      b       ",
      " a      b       ",
      " e      e       ",
      " b      c       ",
      " d      a       ",
      " a              ",
      " c              ",
      " a              ",
      "eec             ",
      "                ",
      "                "
    ]
  ]
}