{
  "xsize": 16,
  "zsize": 16,
  "palette": {
    "palette": [
      {
        "char": " ",
        "block": "minecraft:air"
      },
      {
        "char": "d",
        "block": "minecraft:cobbled_deepslate"
      },
      {
        "char": "a",
        "block": "minecraft:cyan_terracotta"
      },
      {
        "char": "e",
        "block": "minecraft:basalt[axis=y]"
      },
      {
        "char": "c",
        "block": "minecraft:deepslate[axis=y]"
      },
      {
        "char": "b",
        "block": "minecraft:blackstone"
      },
      {
        "char": "g",
        "block": "minecraft:gray_concrete"
      },
      {
        "char": "i",
        "block": "minecraft:light_gray_concrete"
      },
      {
        "char": "f",
        "block": "minecraft:glass"
      },
      {
        "char": "m",
        "block": "minecraft:iron_trapdoor[facing=west,half=bottom,open=false,powered=false,waterlogged=false]"
      },
      {
        "char": "u",
        "block": "minecraft:iron_trapdoor[facing=south,half=bottom,open=false,powered=false,waterlogged=false]"
      },
      {
        "char": "q",
        "block": "minecraft:iron_trapdoor[facing=west,half=top,open=false,powered=false,waterlogged=false]"
      },
      {
        "char": "w",
        "block": "minecraft:iron_trapdoor[facing=south,half=top,open=false,powered=false,waterlogged=false]"
      }
    ]
  },
  "slices": [
    [
      "          daaecd",
      "          bacdeb",
      "          cabcca",
      "           daeec",
      "           aadbb",
      "          gbgeac",
      "          acadda",
      "           aaabe",
      "           idgbd",
      "            aeac",
      "            abab",
      "             adg",
      "             igd",
      "              gc",
      "               i",
      "                "
    ],
    [
      "                ",
      "                ",
      "           f    ",
      "            f   ",
      "                ",
      "          acabca",
      "            f   ",
      "             f  ",
      "             f  ",
      "              f ",
      "              f ",
      "              df",
      "             a  ",
      "                ",
      "                ",
      "                "
    ],
    [
      "          m     ",
      "          mf    ",
      "          m     ",
      "           m    ",
      "           mf   ",
      "          iagdcd",
      "           m    ",
      "            mf  ",
      "            mf  ",
      "             mf ",
      "             uf ",
      "              ef",
      "             a u",
      "               m",
      "                ",
      "                "
    ],
    [
      "          qf    ",
      "          qf    ",
      "          qf    ",
      "           q    ",
      "           qf   ",
      "          ababce",
      "           qf   ",
      "            qf  ",
      "            qf  ",
      "             qf ",
      "             qf ",
      "              cf",
      "             i w",
      "               q",
      "                ",
      "                "
    ],
    [
      "           f    ",
      "                ",
      "                ",
      "            f   ",
      "            f   ",
      "          adgcda",
      "                ",
      "             f  ",
      "             f  ",
      "                ",
      "                ",
      "              bf",
      "             a  ",
      "                ",
      "                ",
      "                "
    ],
    [
      "          ea    ",
      "          bg    ",
      "          bi    ",
      "           ba   ",
      "           bg   ",
      "          aeaccd",
      "           aa   ",
      "            ca  ",
      "            ea  ",
      "             ea ",
      "             ba ",
      "              ea",
      "             a b",
      "               b",
      "                ",
      "                "
    ]
  ]
}