{
  "xsize": 16,
  "zsize": 16,
  "palette": {
    "palette": [
      {
        "char": " ",
        "block": "minecraft:air"
      },
      {
        "char": "a",
        "block": "minecraft:cyan_terracotta"
      },
      {
        "char": "c",
        "block": "minecraft:deepslate[axis=y]"
      },
      {
        "char": "b",
        "block": "minecraft:blackstone"
      },
      {
        "char": "i",
        "block": "minecraft:light_gray_concrete"
      },
      {
        "char": "d",
        "block": "minecraft:cobbled_deepslate"
      },
      {
        "char": "e",
        "block": "minecraft:basalt[axis=y]"
      },
      {
        "char": "g",
        "block": "minecraft:gray_concrete"
      },
      {
        "char": "f",
        "block": "minecraft:glass"
      },
      {
        "char": "m",
        "block": "minecraft:iron_trapdoor[facing=west,half=bottom,open=false,powered=false,waterlogged=false]"
      },
      {
        "char": "u",
        "block": "minecraft:iron_trapdoor[facing=south,half=bottom,open=false,powered=false,waterlogged=false]"
      },
      {
        "char": "q",
        "block": "minecraft:iron_trapdoor[facing=west,half=top,open=false,powered=false,waterlogged=false]"
      },
      {
        "char": "w",
        "block": "minecraft:iron_trapdoor[facing=south,half=top,open=false,powered=false,waterlogged=false]"
      }
    ]
  },
  "slices": [
    [
      "         aaaacbc",
      "         acidcbd",
      "         aeabece",
      "          gaacdb",
      "          gdacbb",
      "          aaacab",
      "          aeaaab",
      "           acieb",
      "           acgdc",
      "            aaab",
      "            aeab",
      "             aaa",
      "             aae",
      "              ge",
      "               i",
      "                "
    ],
    [
      "           f    ",
      "                ",
      "                ",
      "            f   ",
      "                ",
      "          acacea",
      "            f   ",
      "             f  ",
      "             f  ",
      "              f ",
      "              f ",
      "              df",
      "             a  ",
      "                ",
      "                ",
      "                "
    ],
    [
      "          mf    ",
      "          m     ",
      "          m     ",
      "           m    ",
      "           m    ",
      "          adabca",
      "           mf   ",
      "            mf  ",
      "            m   ",
      "             mf ",
      "             u  ",
      "              b ",
      "             a u",
      "               m",
      "                ",
      "                "
    ],
    [
      "          qf    ",
      "          qf    ",
      "          qf    ",
      "           qf   ",
      "           qf   ",
      "          abaeee",
      "           q    ",
      "            q   ",
      "            qf  ",
      "             qf ",
      "             q  ",
      "              df",
      "             a w",
      "               q",
      "                ",
      "                "
    ],
    [
      "           f    ",
      "                ",
      "                ",
      "            f   ",
      "            f   ",
      "          aaaacb",
      "            f   ",
      "             f  ",
      "             f  ",
      "              f ",
      "              f ",
      "              af",
      "             a  ",
      "                ",
      "                ",
      "                "
    ],
    [
      "          ba    ",
      "          cg    ",
      "          dg    ",
      "           ca   ",
      "           da   ",
      "          aegeda",
      "           eg   ",
      "            aa  ",
      "            ca  ",
      "             aa ",
      "             ca ",
      "              eg",
      "             a d",
      "               b",
      "                ",
      "                "
    ]
  ]
}