{
  "xsize": 16,
  "zsize": 16,
  "palette": {
    "palette": [
      {
        "char": " ",
        "block": "minecraft:air"
      },
      {
        "char": "g",
        "block": "minecraft:gray_concrete"
      },
      {
        "char": "b",
        "block": "minecraft:blackstone"
      },
      {
        "char": "a",
        "block": "minecraft:cyan_terracotta"
      },
      {
        "char": "d",
        "block": "minecraft:cobbled_deepslate"
      },
      {
        "char": "e",
        "block": "minecraft:basalt[axis=y]"
      },
      {
        "char": "c",
        "block": "minecraft:deepslate[axis=y]"
      },
      {
        "char": "i",
        "block": "minecraft:light_gray_concrete"
      },
      {
        "char": "f",
        "block": "minecraft:glass"
      },
      {
        "char": "O",
        "block": "minecraft:quartz_stairs[facing=west,half=bottom,shape=straight,waterlogged=false]"
      },
      {
        "char": "ϓ",
        "block": "minecraft:air"
      },
      {
        "char": "s",
        "block": "minecraft:iron_trapdoor[facing=north,half=bottom,open=false,powered=false,waterlogged=false]"
      },
      {
        "char": "很",
        "block": "minecraft:air"
      },
      {
        "char": "天",
        "block": "minecraft:air"
      },
      {
        "char": "多",
        "block": "minecraft:air"
      },
      {
        "char": "成",
        "block": "minecraft:air"
      },
      {
        "char": "p",
        "block": "minecraft:iron_trapdoor[facing=north,half=top,open=false,powered=false,waterlogged=false]"
      }
    ]
  },
  "slices": [
    [
      "                ",
      "                ",
      "                ",
      "                ",
      "                ",
      "                ",
      " g              ",
      "bbaadb  ag      ",
      "aaagaaebaeaa    ",
      "abadcaiaiidci   ",
      "ccccbbadbcai    ",
      "daaebaeeeeab    ",
      "cbeeeaacebac    ",
      "aaeceaecdeeb    ",
      "dabcaacdcbdb    ",
      "dceaaabacebbc   "
    ],
    [
      "                ",
      "                ",
      "                ",
      "                ",
      "                ",
      "                ",
      " i              ",
      " d      ac      ",
      "fa fffcdbeab    ",
      " e eabdbeaebb   ",
      " a  bdebcced    ",
      " b   deaccec    ",
      " a d  eaebad    ",
      " d a    a ce    ",
      " a bbeeed       ",
      " a      d Oϓ    "
    ],
    [
      "                ",
      "                ",
      "                ",
      "                ",
      "                ",
      "                ",
      " a              ",
      "sessss          ",
      "fa f fdcdae     ",
      " c   ceaeeaad   ",
      " b    acacce    ",
      " e    caeccd    ",
      " e      e c     ",
      " b      c       ",
      " b 很天 多成e       ",
      " c      d       "
    ],
    [
      "                ",
      "                ",
      "                ",
      "                ",
      "                ",
      "                ",
      " g              ",
      "peppp           ",
      " a ff           ",
      " a     cbd      ",
      " a      edb    a",
      " d       e    b ",
      " e             p",
      " a      b       ",
      " d      c       ",
      " b      d       "
    ],
    [
      "                ",
      "                ",
      "                ",
      "                ",
      "                ",
      "                ",
      " a              ",
      " a              ",
      "fg f            ",
      " c              ",
      " b             g",
      " a            a ",
      " c              ",
      " b              ",
      " d      d       ",
      " d      c       "
    ],
    [
      "                ",
      "                ",
      "                ",
      "                ",
      "                ",
      "                ",
      " g              ",
      "abcd            ",
      "gagg            ",
      " a              ",
      " e             a",
      " a            a ",
      " d            aa",
      " a             a",
      " a      d       ",
      " c      d       "
    ]
  ]
}