{
  "xsize": 16,
  "zsize": 16,
  "palette": {
    "palette": [
      {
        "char": " ",
        "block": "minecraft:air"
      },
      {
        "char": "g",
        "block": "minecraft:gray_concrete"
      },
      {
        "char": "e",
        "block": "minecraft:basalt[axis=y]"
      },
      {
        "char": "a",
        "block": "minecraft:cyan_terracotta"
      },
      {
        "char": "d",
        "block": "minecraft:cobbled_deepslate"
      },
      {
        "char": "c",
        "block": "minecraft:deepslate[axis=y]"
      },
      {
        "char": "b",
        "block": "minecraft:blackstone"
      },
      {
        "char": "i",
        "block": "minecraft:light_gray_concrete"
      },
      {
        "char": "f",
        "block": "minecraft:glass"
      },
      {
        "char": "H",
        "block": "minecraft:quartz_stairs[facing=south,half=bottom,shape=straight,waterlogged=false]"
      },
      {
        "char": "u",
        "block": "minecraft:iron_trapdoor[facing=south,half=bottom,open=false,powered=false,waterlogged=false]"
      },
      {
        "char": "ϐ",
        "block": "minecraft:air",
        "tag": {
          "z": -259,
          "x": -34,
          "id": "refurbished_furniture:computer",
          "y": -21,
          "NodePos": "-9070971985941L",
          "Connections": [
            "L"
          ]
        }
      },
      {
        "char": "w",
        "block": "minecraft:iron_trapdoor[facing=south,half=top,open=false,powered=false,waterlogged=false]"
      },
      {
        "char": "q",
        "block": "minecraft:iron_trapdoor[facing=west,half=top,open=false,powered=false,waterlogged=false]"
      }
    ]
  },
  "slices": [
    [
      " geageddcedecedb",
      "  aaaaadcdedeadd",
      "   aaadaabecaacd",
      "     aaaaagaiceb",
      "       aadbbdaga",
      "         aa  ded",
      "                ",
      "                ",
      "  d      a      ",
      "                ",
      "                ",
      "                ",
      "                ",
      "                ",
      "                ",
      "                "
    ],
    [
      "    f    ebd dbe",
      "    bf    H   H ",
      "   g   ff       ",
      "         fi f   ",
      "          c  fff",
      "          g     ",
      "                ",
      "                ",
      "  a      c      ",
      "                ",
      "                ",
      "                ",
      "                ",
      "                ",
      "                ",
      "                "
    ],
    [
      "  uu      ϐ   ϐ ",
      "    c           ",
      "   a uuff       ",
      "       uufa f   ",
      "         ubuufff",
      "          a  uuu",
      "                ",
      "                ",
      "  b      a      ",
      "                ",
      "                ",
      "                ",
      "                ",
      "                ",
      "                ",
      "                "
    ],
    [
      "  wqf           ",
      "    cff         ",
      "   a wwff       ",
      "       ww aff   ",
      "         wawwfff",
      "          a  www",
      "                ",
      "                ",
      "  a      d      ",
      "                ",
      "                ",
      "                ",
      "                ",
      "                ",
      "                ",
      "                "
    ],
    [
      "                ",
      "    eff         ",
      "   a   ff       ",
      "          a     ",
      "          d  f f",
      "          i     ",
      "                ",
      "                ",
      "  d      e      ",
      "                ",
      "                ",
      "                ",
      "                ",
      "                ",
      "                ",
      "                "
    ],
    [
      "  beg           ",
      "    aga         ",
      "   a cdii       ",
      "       ceaaaa   ",
      "         dcacagg",
      "          a  ccd",
      "                ",
      "                ",
      "  e      b      ",
      "                ",
      "                ",
      "                ",
      "                ",
      "                ",
      "                ",
      "                "
    ]
  ]
}