{
  "xsize": 16,
  "zsize": 16,
  "palette": {
    "palette": [
      {
        "char": " ",
        "block": "minecraft:air"
      },
      {
        "char": "Ѧ",
        "block": "minecraft:quartz_bricks"
      },
      {
        "char": "e",
        "block": "minecraft:basalt[axis=y]"
      },
      {
        "char": "b",
        "block": "minecraft:blackstone"
      },
      {
        "char": "a",
        "block": "minecraft:cyan_terracotta"
      },
      {
        "char": "o",
        "block": "minecraft:chiseled_quartz_block"
      },
      {
        "char": "d",
        "block": "minecraft:cobbled_deepslate"
      },
      {
        "char": "c",
        "block": "minecraft:deepslate[axis=y]"
      },
      {
        "char": "那",
        "block": "minecraft:white_terracotta"
      },
      {
        "char": "g",
        "block": "minecraft:gray_concrete"
      },
      {
        "char": "n",
        "block": "minecraft:smooth_quartz"
      },
      {
        "char": "Z",
        "block": "minecraft:stone_brick_wall[east=tall,north=tall,south=none,up=true,waterlogged=false,weathering=false,west=tall]"
      },
      {
        "char": "Ӿ",
        "block": "minecraft:cobblestone_wall[east=tall,north=tall,south=none,up=true,waterlogged=false,weathering=false,west=tall]"
      },
      {
        "char": "G",
        "block": "minecraft:iron_bars[east=false,north=false,south=true,waterlogged=false,west=false]"
      },
      {
        "char": "P",
        "block": "minecraft:smooth_quartz_slab[type=bottom,waterlogged=false]"
      },
      {
        "char": "x",
        "block": "minecraft:cauldron"
      },
      {
        "char": "Ӣ",
        "block": "minecraft:air"
      },
      {
        "char": "ϓ",
        "block": "minecraft:air"
      },
      {
        "char": "Ѻ",
        "block": "minecraft:air"
      },
      {
        "char": "Ѯ",
        "block": "minecraft:diorite_slab[type=bottom,waterlogged=false]"
      },
      {
        "char": "ӝ",
        "block": "minecraft:air"
      },
      {
        "char": "ӛ",
        "block": "minecraft:air"
      },
      {
        "char": "v",
        "block": "minecraft:quartz_pillar[axis=x]"
      },
      {
        "char": "k",
        "block": "minecraft:oak_leaves[distance=7,persistent=true,waterlogged=false]"
      },
      {
        "char": "i",
        "block": "minecraft:light_gray_concrete"
      },
      {
        "char": "r",
        "block": "minecraft:polished_diorite"
      },
      {
        "char": "j",
        "block": "minecraft:polished_andesite_slab[type=top,waterlogged=false]"
      },
      {
        "char": "C",
        "block": "minecraft:quartz_pillar[axis=y]"
      },
      {
        "char": "h",
        "block": "minecraft:andesite_slab[type=top,waterlogged=false]"
      },
      {
        "char": "T",
        "block": "minecraft:redstone_lamp[lit=false]"
      }
    ]
  },
  "slices": [
    [
      "          Ѧebbab",
      "          obbedb",
      "          Ѧecbca",
      "          那ddeac",
      "          Ѧbcedb",
      "         ggacecd",
      "oѦ那ѦonѦѦѦaadbbbe",
      "ebabbdedadebecdd",
      "acebeacdbcebeaad",
      "eaccadaaedcedbdb",
      "beaaceecadaabdec",
      "dcddbcdeecbdcccd",
      "ZZZaZZӾeeeacaaec",
      "   e   ecdbcdaed",
      "   a   aaccbbaec",
      " G a G babdbacab"
    ],
    [
      "          Px  Ӣϓ",
      "          P    Ѻ",
      "          P     ",
      "          Px    ",
      "          P     ",
      "         aa     ",
      "PPPPѮPPPPga     ",
      "                ",
      "              ӝ ",
      "             Ӣϓӛ",
      "              Ѻ ",
      "   e   b        ",
      "vvvevvnax       ",
      "   b   c      ӝ ",
      "   a   b     Ӣϓӛ",
      " G d G bx     Ѻ "
    ],
    [
      "           k    ",
      "                ",
      "                ",
      "           k    ",
      "                ",
      "         ag     ",
      "         ii     ",
      "                ",
      "                ",
      "                ",
      "                ",
      "   b   e        ",
      "vrvcvvvck       ",
      "   b   a        ",
      "   a   d        ",
      " G b G bk       "
    ],
    [
      "           k    ",
      "                ",
      "                ",
      "           k    ",
      "                ",
      "         aa     ",
      "         aa     ",
      "                ",
      "                ",
      "                ",
      "                ",
      "   c   b        ",
      "vvravvvak       ",
      "   a   d        ",
      "   c   e        ",
      " G b G dk       "
    ],
    [
      "                ",
      "                ",
      "                ",
      "                ",
      "                ",
      "         ia     ",
      "         gi     ",
      "                ",
      "                ",
      "                ",
      "                ",
      "jjjbjjja        ",
      "vvCbvvve        ",
      "   c   d        ",
      "   e   c        ",
      " G c G b        "
    ],
    [
      "hhhhhhhhhhhhhhhh",
      "hhhhhhhhhhhhhhhh",
      "hhhhhhhhhhhhhhhh",
      "hThhhhhhhhhhhhhh",
      "hhhhhhhhhhhhhhhh",
      "hhhhhhhhhaihhhhh",
      "hhhhhhhhhaghhhhh",
      "hhhhhhhhhhhhhhhh",
      "hhhhhhhhhhhhhhhh",
      "hhhhhhhhhhhhhhhh",
      "hhhhhhhhhhhhhhhh",
      "cdebcacchhhhhhhh",
      "adddceadhhhhhhhh",
      "   a   bhhhhhhhh",
      "   b   ahhhhhhhh",
      " G c G chhhhhhhh"
    ]
  ]
}