{
  "xsize": 16,
  "zsize": 16,
  "palette": {
    "palette": [
      {
        "char": " ",
        "block": "minecraft:air"
      },
      {
        "char": "c",
        "block": "minecraft:deepslate[axis=y]"
      },
      {
        "char": "b",
        "block": "minecraft:blackstone"
      },
      {
        "char": "d",
        "block": "minecraft:cobbled_deepslate"
      },
      {
        "char": "a",
        "block": "minecraft:cyan_terracotta"
      },
      {
        "char": "e",
        "block": "minecraft:basalt[axis=y]"
      },
      {
        "char": "i",
        "block": "minecraft:light_gray_concrete"
      },
      {
        "char": "然",
        "block": "minecraft:air"
      },
      {
        "char": "ϕ",
        "block": "minecraft:quartz_stairs[facing=north,half=bottom,shape=straight,waterlogged=false]"
      },
      {
        "char": "O",
        "block": "minecraft:quartz_stairs[facing=west,half=bottom,shape=straight,waterlogged=false]"
      },
      {
        "char": "ϓ",
        "block": "minecraft:air"
      },
      {
        "char": "ϔ",
        "block": "minecraft:quartz_stairs[facing=east,half=bottom,shape=straight,waterlogged=false]"
      },
      {
        "char": "f",
        "block": "minecraft:glass"
      },
      {
        "char": "x",
        "block": "minecraft:cauldron"
      },
      {
        "char": "m",
        "block": "minecraft:iron_trapdoor[facing=west,half=bottom,open=false,powered=false,waterlogged=false]"
      },
      {
        "char": "k",
        "block": "minecraft:oak_leaves[distance=7,persistent=true,waterlogged=false]"
      },
      {
        "char": "u",
        "block": "minecraft:iron_trapdoor[facing=south,half=bottom,open=false,powered=false,waterlogged=false]"
      },
      {
        "char": "q",
        "block": "minecraft:iron_trapdoor[facing=west,half=top,open=false,powered=false,waterlogged=false]"
      },
      {
        "char": "w",
        "block": "minecraft:iron_trapdoor[facing=south,half=top,open=false,powered=false,waterlogged=false]"
      },
      {
        "char": "I",
        "block": "minecraft:stone_slab[type=top,waterlogged=false,weathering=false]"
      },
      {
        "char": "g",
        "block": "minecraft:gray_concrete"
      }
    ]
  },
  "slices": [
    [
      "cbcccdabebaeeacc",
      "cabbababaeadcdae",
      "bceccbabebacdbcb",
      "bbacbdeacbdabcbd",
      "cebdabcdbabddadd",
      "bdceeaacbeaaccbd",
      "aaieabccedaadbab",
      "  a adacdebbbaaa",
      "    ddcdbacedcac",
      "     acdbcbeadad",
      "      beaaabcad ",
      "       cdceced  ",
      "         adbb   ",
      "        a       ",
      "                ",
      "                "
    ],
    [
      "           bdeba",
      "                ",
      "  d            然",
      "  c             ",
      "  e   ϕ   cbb   ",
      "ceb  Oϓϔ  a     ",
      "   db     c     ",
      "  a  f    dx    ",
      "          e     ",
      "          d     ",
      "       ff bx    ",
      "         ca     ",
      "         cb     ",
      "        a       ",
      "                ",
      "                "
    ],
    [
      "           eaaec",
      "                ",
      "  d             ",
      "  d             ",
      "  e       bab   ",
      "ece       a     ",
      "   be     c     ",
      "  a mf    dk    ",
      "    mf    d     ",
      "     m    b     ",
      "      m f ek    ",
      "       uueb     ",
      "         ac     ",
      "        a       ",
      "                ",
      "                "
    ],
    [
      "           cceaa",
      "                ",
      "  d             ",
      "  d             ",
      "  d       eab   ",
      "eaa       e     ",
      "   dc     c     ",
      "  a qf    ck    ",
      "    qf    c     ",
      "     wf   e     ",
      "      qff ak    ",
      "       wwad     ",
      "         cd     ",
      "        a ae    ",
      "                ",
      "                "
    ],
    [
      "  I        edbbe",
      "  I             ",
      "  c             ",
      "  b             ",
      "  a       debIII",
      "dcc       e     ",
      "   bc     a     ",
      "  a  f    b     ",
      "     f    d     ",
      "      f   c     ",
      "          c     ",
      "         ee     ",
      "         dc     ",
      "        a ec    ",
      "                ",
      "                "
    ],
    [
      "  c        bddaa",
      "  b             ",
      "  d             ",
      "  b             ",
      "  c       eebcda",
      "dce       d     ",
      "   a      b     ",
      "  g eb    a     ",
      "    ca    b     ",
      "     dc   c     ",
      "      aad d     ",
      "       ab c     ",
      "         ad     ",
      "        a       ",
      "                ",
      "                "
    ]
  ]
}