{
  "xsize": 16,
  "zsize": 16,
  "palette": {
    "palette": [
      {
        "char": " ",
        "block": "minecraft:air"
      },
      {
        "char": "c",
        "block": "minecraft:deepslate[axis=y]"
      },
      {
        "char": "a",
        "block": "minecraft:cyan_terracotta"
      },
      {
        "char": "d",
        "block": "minecraft:cobbled_deepslate"
      },
      {
        "char": "b",
        "block": "minecraft:blackstone"
      },
      {
        "char": "e",
        "block": "minecraft:basalt[axis=y]"
      },
      {
        "char": "i",
        "block": "minecraft:light_gray_concrete"
      },
      {
        "char": "g",
        "block": "minecraft:gray_concrete"
      },
      {
        "char": "f",
        "block": "minecraft:glass"
      },
      {
        "char": "m",
        "block": "minecraft:iron_trapdoor[facing=west,half=bottom,open=false,powered=false,waterlogged=false]"
      },
      {
        "char": "u",
        "block": "minecraft:iron_trapdoor[facing=south,half=bottom,open=false,powered=false,waterlogged=false]"
      },
      {
        "char": "了",
        "block": "minecraft:air"
      },
      {
        "char": "q",
        "block": "minecraft:iron_trapdoor[facing=west,half=top,open=false,powered=false,waterlogged=false]"
      },
      {
        "char": "w",
        "block": "minecraft:iron_trapdoor[facing=south,half=top,open=false,powered=false,waterlogged=false]"
      }
    ]
  },
  "slices": [
    [
      "          cadcdc",
      "          aacdca",
      "          baadda",
      "           aaaba",
      "           eabab",
      "          idaecd",
      "          geacee",
      "           abaac",
      "           adaac",
      "            adaa",
      "            gbad",
      "             aea",
      "             agc",
      "              ia",
      "               a",
      "                "
    ],
    [
      "           f    ",
      "           f    ",
      "                ",
      "            f   ",
      "            f   ",
      "          aaaebc",
      "            f   ",
      "             f  ",
      "             f  ",
      "                ",
      "                ",
      "              ef",
      "             a  ",
      "                ",
      "                ",
      "                "
    ],
    [
      "          mf    ",
      "          mf    ",
      "          m     ",
      "           mf   ",
      "           m    ",
      "          icaedb",
      "           m    ",
      "            mf  ",
      "            mf  ",
      "             m  ",
      "             uf ",
      "              e ",
      "             i u",
      "               了",
      "                ",
      "                "
    ],
    [
      "          qf    ",
      "          qf    ",
      "          qf    ",
      "           qf   ",
      "           qf   ",
      "          aaaeaa",
      "           qf   ",
      "            qf  ",
      "            qf  ",
      "             q  ",
      "             qf ",
      "              df",
      "             a w",
      "               q",
      "                ",
      "                "
    ],
    [
      "           f    ",
      "           f    ",
      "           f    ",
      "                ",
      "            f   ",
      "          abgedd",
      "            f   ",
      "             f  ",
      "             f  ",
      "              f ",
      "              f ",
      "              af",
      "             g  ",
      "                ",
      "                ",
      "                "
    ],
    [
      "          ai    ",
      "          bg    ",
      "          bg    ",
      "           aa   ",
      "           ei   ",
      "          acaece",
      "           da   ",
      "            ba  ",
      "            ca  ",
      "             ba ",
      "             da ",
      "              dg",
      "             a a",
      "               a",
      "                ",
      "                "
    ]
  ]
}