{
  "xsize": 16,
  "zsize": 16,
  "palette": {
    "palette": [
      {
        "char": " ",
        "block": "minecraft:air"
      },
      {
        "char": "b",
        "block": "minecraft:blackstone"
      },
      {
        "char": "c",
        "block": "minecraft:deepslate[axis=y]"
      },
      {
        "char": "g",
        "block": "minecraft:gray_concrete"
      },
      {
        "char": "e",
        "block": "minecraft:basalt[axis=y]"
      },
      {
        "char": "a",
        "block": "minecraft:cyan_terracotta"
      },
      {
        "char": "d",
        "block": "minecraft:cobbled_deepslate"
      },
      {
        "char": "i",
        "block": "minecraft:light_gray_concrete"
      },
      {
        "char": "f",
        "block": "minecraft:glass"
      },
      {
        "char": "ϔ",
        "block": "minecraft:quartz_stairs[facing=east,half=bottom,shape=straight,waterlogged=false]"
      },
      {
        "char": "П",
        "block": "minecraft:barrel[facing=up,open=false]",
        "tag": {
          "z": -275,
          "x": -15,
          "ForgeData": {
            "LockFlag": "1b"
          },
          "id": "minecraft:barrel",
          "y": 2,
          "Items": []
        }
      },
      {
        "char": "s",
        "block": "minecraft:iron_trapdoor[facing=north,half=bottom,open=false,powered=false,waterlogged=false]"
      },
      {
        "char": "l",
        "block": "minecraft:iron_trapdoor[facing=east,half=bottom,open=false,powered=false,waterlogged=false]"
      },
      {
        "char": "因",
        "block": "minecraft:air"
      },
      {
        "char": "吗",
        "block": "minecraft:air"
      },
      {
        "char": "信",
        "block": "minecraft:air"
      },
      {
        "char": "p",
        "block": "minecraft:iron_trapdoor[facing=north,half=top,open=false,powered=false,waterlogged=false]"
      },
      {
        "char": "t",
        "block": "minecraft:iron_trapdoor[facing=east,half=top,open=false,powered=false,waterlogged=false]"
      }
    ]
  },
  "slices": [
    [
      "bcgeaa          ",
      "bacaca          ",
      "abbcgda         ",
      "ccbdaea         ",
      "aaaacgea        ",
      "adeadaag        ",
      "eebecdaag       ",
      "caeaebabi       ",
      "aaaabbae        ",
      "accbeaad        ",
      "dddcadcab       ",
      "abdacacab       ",
      "ddacdaege       ",
      "ddeaeeeab       ",
      "eeaedbegba      ",
      "edbeabeaa       "
    ],
    [
      "  f  a          ",
      "   fa           ",
      "ϔ   f           ",
      "                ",
      "     f          ",
      "                ",
      "      f         ",
      "eebbecaea       ",
      "                ",
      "      f         ",
      " deb            ",
      " a     f        ",
      " b ϔ   f        ",
      " П     f        ",
      "debcecdiai      ",
      "d      f        "
    ],
    [
      "   s a          ",
      "   fb           ",
      "     l          ",
      "    fl          ",
      "     fl         ",
      "     fl         ",
      "      fl        ",
      "aebeadica       ",
      "      fl        ",
      "      fl        ",
      "       fl       ",
      " 因     fl       ",
      " 吗      l       ",
      "        l       ",
      "adaaeaeaea      ",
      "信      fl       "
    ],
    [
      "  fp g          ",
      "   fa           ",
      "     t          ",
      "     t          ",
      "     ft         ",
      "     ft         ",
      "      ft        ",
      "aaaaebaba       ",
      "       t        ",
      "      ft        ",
      "       ft       ",
      "       ft       ",
      "       ft       ",
      "        t       ",
      "ddaeeddaba      ",
      "       ft       "
    ],
    [
      "     a          ",
      "   fc           ",
      "    f           ",
      "    f           ",
      "     f          ",
      "                ",
      "      f         ",
      "bbaecegaa       ",
      "      f         ",
      "                ",
      "       f        ",
      "       f        ",
      "                ",
      "                ",
      "adacaabadi      ",
      "       f        "
    ],
    [
      "  aa a          ",
      "   ac           ",
      "    ga          ",
      "    ae          ",
      "     ad         ",
      "     gd         ",
      "      ad        ",
      "ebecddaag       ",
      "      aa        ",
      "      ab        ",
      "       ie       ",
      "       aa       ",
      "       ab       ",
      "       gb       ",
      "eceaaaeaaa      ",
      "       ac       "
    ]
  ]
}