{
  "xsize": 16,
  "zsize": 16,
  "palette": {
    "palette": [
      {
        "char": " ",
        "block": "minecraft:air"
      },
      {
        "char": "d",
        "block": "minecraft:cobbled_deepslate"
      },
      {
        "char": "a",
        "block": "minecraft:cyan_terracotta"
      },
      {
        "char": "b",
        "block": "minecraft:blackstone"
      },
      {
        "char": "c",
        "block": "minecraft:deepslate[axis=y]"
      },
      {
        "char": "e",
        "block": "minecraft:basalt[axis=y]"
      },
      {
        "char": "Р",
        "block": "minecraft:stone_brick_stairs[facing=north,half=bottom,shape=straight,waterlogged=false,weathering=false]"
      },
      {
        "char": "z",
        "block": "minecraft:iron_bars[east=false,north=true,south=true,waterlogged=false,west=false]"
      },
      {
        "char": "Y",
        "block": "minecraft:iron_bars[east=false,north=true,south=false,waterlogged=false,west=false]"
      },
      {
        "char": "f",
        "block": "minecraft:glass"
      },
      {
        "char": "g",
        "block": "minecraft:gray_concrete"
      },
      {
        "char": "x",
        "block": "minecraft:cauldron"
      },
      {
        "char": "У",
        "block": "minecraft:stone_brick_stairs[facing=south,half=bottom,shape=straight,waterlogged=false,weathering=false]"
      },
      {
        "char": "С",
        "block": "minecraft:stone_brick_stairs[facing=north,half=top,shape=straight,waterlogged=false,weathering=false]"
      },
      {
        "char": "如",
        "block": "minecraft:air"
      },
      {
        "char": "m",
        "block": "minecraft:iron_trapdoor[facing=west,half=bottom,open=false,powered=false,waterlogged=false]"
      },
      {
        "char": "k",
        "block": "minecraft:oak_leaves[distance=7,persistent=true,waterlogged=false]"
      },
      {
        "char": "p",
        "block": "minecraft:iron_trapdoor[facing=north,half=top,open=false,powered=false,waterlogged=false]"
      },
      {
        "char": "q",
        "block": "minecraft:iron_trapdoor[facing=west,half=top,open=false,powered=false,waterlogged=false]"
      },
      {
        "char": "у",
        "block": "minecraft:stone_brick_stairs[facing=south,half=top,shape=straight,waterlogged=false,weathering=false]"
      },
      {
        "char": "i",
        "block": "minecraft:light_gray_concrete"
      },
      {
        "char": "I",
        "block": "minecraft:stone_slab[type=top,waterlogged=false,weathering=false]"
      }
    ]
  },
  "slices": [
    [
      "         dababcd",
      "       dabaecddc",
      "      decdbaceeb",
      "     edcabcdcaca",
      "    eddbbdeedeee",
      "  a ddaccdcddadc",
      "aaaacccaebbbbaba",
      "dbcddabbeaadceac",
      "cbbaeddbbbbbdbec",
      "daadbbddeabeeeea",
      "daaaddaecebdeebb",
      "abacbbebdaedddee",
      "ccebadbaaaeeРz d",
      "addeebecabab z d",
      "ebbcbbacbdee Y b",
      "dccedcadebaa   b"
    ],
    [
      "         e      ",
      "         c      ",
      "                ",
      "                ",
      "     f          ",
      "  g  f          ",
      "   ea     x     ",
      "aebadebabaee   d",
      "  c  x  x       ",
      "  b             ",
      "  a             ",
      "           a b b",
      "           a zУb",
      "  c        b zСb",
      "bdd        a Y b",
      "  e        e   b"
    ],
    [
      "         c      ",
      "       如如d      ",
      "      mff       ",
      "     m          ",
      "    m           ",
      "  a mf          ",
      "   cc     k     ",
      "eadeedebadda   a",
      "  d  k  k       ",
      "  c             ",
      "  c             ",
      "           a e d",
      "           a z a",
      "  c        c zУb",
      "aba        d YСc",
      "  b        b   e"
    ],
    [
      "         d      ",
      "       ppc      ",
      "      q f       ",
      "     pf         ",
      "    q           ",
      "  a qf          ",
      "   ed     k     ",
      "dcbbabbeadeb   e",
      "  b  k  k       ",
      "  b             ",
      "  b             ",
      "           d d b",
      "           b z b",
      "  c        c z b",
      "eee        aуzУb",
      "  d        acaeb"
    ],
    [
      "         d      ",
      "         d      ",
      "       ff       ",
      "                ",
      "     f          ",
      "  i  f          ",
      "   ec           ",
      "edcdbedadacaIIIa",
      "  c             ",
      "  e             ",
      "  d             ",
      "  I        eddce",
      "  I        e z b",
      "  c        dуz c",
      "daa        cРY a",
      "  d        a   c"
    ],
    [
      "         b      ",
      "       de       ",
      "      cda       ",
      "     ce         ",
      "    ce          ",
      "  g cc          ",
      "   c            ",
      "cadcdabceacdcacc",
      "  d             ",
      "  e             ",
      "  d             ",
      "  d        adbab",
      "  c        aуz c",
      "  b        eРz a",
      "cee        d Y d",
      "  e        d   a"
    ]
  ]
}