{
  "xsize": 16,
  "zsize": 16,
  "palette": {
    "palette": [
      {
        "char": " ",
        "block": "minecraft:air"
      },
      {
        "char": "b",
        "block": "minecraft:blackstone"
      },
      {
        "char": "e",
        "block": "minecraft:basalt[axis=y]"
      },
      {
        "char": "a",
        "block": "minecraft:cyan_terracotta"
      },
      {
        "char": "c",
        "block": "minecraft:deepslate[axis=y]"
      },
      {
        "char": "d",
        "block": "minecraft:cobbled_deepslate"
      },
      {
        "char": "g",
        "block": "minecraft:gray_concrete"
      },
      {
        "char": "ϕ",
        "block": "minecraft:quartz_stairs[facing=north,half=bottom,shape=straight,waterlogged=false]"
      },
      {
        "char": "O",
        "block": "minecraft:quartz_stairs[facing=west,half=bottom,shape=straight,waterlogged=false]"
      },
      {
        "char": "ϓ",
        "block": "minecraft:air"
      },
      {
        "char": "ϔ",
        "block": "minecraft:quartz_stairs[facing=east,half=bottom,shape=straight,waterlogged=false]"
      },
      {
        "char": "f",
        "block": "minecraft:glass"
      },
      {
        "char": "x",
        "block": "minecraft:cauldron"
      },
      {
        "char": "m",
        "block": "minecraft:iron_trapdoor[facing=west,half=bottom,open=false,powered=false,waterlogged=false]"
      },
      {
        "char": "k",
        "block": "minecraft:oak_leaves[distance=7,persistent=true,waterlogged=false]"
      },
      {
        "char": "u",
        "block": "minecraft:iron_trapdoor[facing=south,half=bottom,open=false,powered=false,waterlogged=false]"
      },
      {
        "char": "q",
        "block": "minecraft:iron_trapdoor[facing=west,half=top,open=false,powered=false,waterlogged=false]"
      },
      {
        "char": "w",
        "block": "minecraft:iron_trapdoor[facing=south,half=top,open=false,powered=false,waterlogged=false]"
      },
      {
        "char": "站",
        "block": "minecraft:air"
      },
      {
        "char": "I",
        "block": "minecraft:stone_slab[type=top,waterlogged=false,weathering=false]"
      }
    ]
  },
  "slices": [
    [
      "bebebebacbbbbebc",
      "ebbaadcccadcdabd",
      "edbeacacdcedcbbe",
      "bebecacabdceadcd",
      "cbaaacddcdacbeae",
      "bbcebccdacdcbdea",
      "gaacdbadacebbabd",
      "  a adccbbbdcbba",
      "    deeaeabababa",
      "     badbecceace",
      "      deeebdaddc",
      "       ebdcdebaa",
      "         bcacedb",
      "        a     bc",
      "               b",
      "                "
    ],
    [
      "           bdada",
      "                ",
      "  e             ",
      "  c             ",
      "  d   ϕ   dce   ",
      "daa  Oϓϔ  b     ",
      "   bd     c     ",
      "  a  f    bx    ",
      "          a     ",
      "      f   a     ",
      "       ff cx    ",
      "         ea     ",
      "         bc     ",
      "        a       ",
      "                ",
      "                "
    ],
    [
      "           cdeba",
      "                ",
      "  a             ",
      "  d             ",
      "  c       eeb   ",
      "cdc       b     ",
      "   db     e     ",
      "  a m     bk    ",
      "    mf    b     ",
      "     mf   e     ",
      "      m f ak    ",
      "       uuad     ",
      "         be     ",
      "        a    e  ",
      "                ",
      "                "
    ],
    [
      "           dbeea",
      "                ",
      "  d             ",
      "  d             ",
      "  b       eba   ",
      "cbd       d     ",
      "   dd     d     ",
      "  a qf    ek    ",
      "    qf    c     ",
      "     wf   c     ",
      "      q f bk    ",
      "       w站da     ",
      "         be     ",
      "        g aada  ",
      "                ",
      "                "
    ],
    [
      "  I        ebcce",
      "  I             ",
      "  a             ",
      "  a             ",
      "  d       deaIII",
      "ede       b     ",
      "   cb     d     ",
      "  a       d     ",
      "          b     ",
      "          e     ",
      "       ff d     ",
      "         ae     ",
      "         ed     ",
      "        a    dII",
      "                ",
      "                "
    ],
    [
      "  d        eabeb",
      "  c             ",
      "  e             ",
      "  e             ",
      "  e       aaeaec",
      "dea       e     ",
      "   e      b     ",
      "  a ba    a     ",
      "    ea    e     ",
      "     bc   c     ",
      "      aaa d     ",
      "       bc c     ",
      "         de     ",
      "        a     ee",
      "                ",
      "                "
    ]
  ]
}