{
  "xsize": 16,
  "zsize": 16,
  "palette": {
    "palette": [
      {
        "char": " ",
        "block": "minecraft:air"
      },
      {
        "char": "i",
        "block": "minecraft:light_gray_concrete"
      },
      {
        "char": "c",
        "block": "minecraft:deepslate[axis=y]"
      },
      {
        "char": "d",
        "block": "minecraft:cobbled_deepslate"
      },
      {
        "char": "b",
        "block": "minecraft:blackstone"
      },
      {
        "char": "g",
        "block": "minecraft:gray_concrete"
      },
      {
        "char": "a",
        "block": "minecraft:cyan_terracotta"
      },
      {
        "char": "e",
        "block": "minecraft:basalt[axis=y]"
      },
      {
        "char": "f",
        "block": "minecraft:glass"
      },
      {
        "char": "ϕ",
        "block": "minecraft:quartz_stairs[facing=north,half=bottom,shape=straight,waterlogged=false]"
      },
      {
        "char": "x",
        "block": "minecraft:cauldron"
      },
      {
        "char": "s",
        "block": "minecraft:iron_trapdoor[facing=north,half=bottom,open=false,powered=false,waterlogged=false]"
      },
      {
        "char": "Ҝ",
        "block": "minecraft:air",
        "tag": {
          "z": -292,
          "x": -29,
          "id": "refurbished_furniture:computer",
          "y": 63,
          "NodePos": "-7696582590401L",
          "Connections": [
            "L"
          ]
        }
      },
      {
        "char": "k",
        "block": "minecraft:oak_leaves[distance=7,persistent=true,waterlogged=false]"
      },
      {
        "char": "p",
        "block": "minecraft:iron_trapdoor[facing=north,half=top,open=false,powered=false,waterlogged=false]"
      },
      {
        "char": "I",
        "block": "minecraft:stone_slab[type=top,waterlogged=false,weathering=false]"
      }
    ]
  },
  "slices": [
    [
      "                ",
      "                ",
      "                ",
      "                ",
      "                ",
      "                ",
      " i              ",
      "cdcdbb  g       ",
      "aaaaaadega      ",
      "cdcbdbgaag      ",
      "deaebeadcg      ",
      "bedbdcdeea      ",
      "baaccddcdg      ",
      "beedacabeg      ",
      "dcbbdeaaaa      ",
      "cdbebdcdeaa     "
    ],
    [
      "                ",
      "                ",
      "                ",
      "                ",
      "                ",
      "                ",
      " a              ",
      " d      a       ",
      " gfff   gg      ",
      " d    ffa       ",
      " a ϕ    b       ",
      " c      c       ",
      "dcccb  xa       ",
      " a      c       ",
      " b      e       ",
      "cbd  abdc a     "
    ],
    [
      "                ",
      "                ",
      "                ",
      "                ",
      "                ",
      "                ",
      " a              ",
      "scssss  a       ",
      "fgffffssga      ",
      " b    ffa       ",
      " c      c       ",
      " d      a       ",
      " e Ҝ   ka       ",
      " b      b       ",
      " c      c       ",
      "eda  eacb a     "
    ],
    [
      "                ",
      "                ",
      "                ",
      "                ",
      "                ",
      "                ",
      " g              ",
      "pepppp  g       ",
      "fgff fppag      ",
      " c    ffa       ",
      " b      e       ",
      " a      d       ",
      " d     kc       ",
      " c      e       ",
      " c      e       ",
      "dcd  cdda a     "
    ],
    [
      "                ",
      "                ",
      "                ",
      "                ",
      "                ",
      "                ",
      " a              ",
      " b      a       ",
      "faf f   gg      ",
      " d    f i       ",
      " c      c       ",
      " b      a       ",
      " b      e       ",
      " a      a       ",
      " a      e       ",
      "aebIIebad a     "
    ],
    [
      "                ",
      "                ",
      "                ",
      "                ",
      "                ",
      "                ",
      " g              ",
      "decbdb  a       ",
      "aaaaagbega      ",
      " a    iaa       ",
      " a      a       ",
      " e      c       ",
      " b      c       ",
      " b      b       ",
      " d      b       ",
      "dcdaeebda a     "
    ]
  ]
}