{
  "xsize": 16,
  "zsize": 16,
  "palette": {
    "palette": [
      {
        "char": " ",
        "block": "minecraft:air"
      },
      {
        "char": "g",
        "block": "minecraft:gray_concrete"
      },
      {
        "char": "c",
        "block": "minecraft:deepslate[axis=y]"
      },
      {
        "char": "a",
        "block": "minecraft:cyan_terracotta"
      },
      {
        "char": "b",
        "block": "minecraft:blackstone"
      },
      {
        "char": "d",
        "block": "minecraft:cobbled_deepslate"
      },
      {
        "char": "e",
        "block": "minecraft:basalt[axis=y]"
      },
      {
        "char": "i",
        "block": "minecraft:light_gray_concrete"
      },
      {
        "char": "f",
        "block": "minecraft:glass"
      },
      {
        "char": "O",
        "block": "minecraft:quartz_stairs[facing=west,half=bottom,shape=straight,waterlogged=false]"
      },
      {
        "char": "П",
        "block": "minecraft:barrel[facing=up,open=false]",
        "tag": {
          "z": -275,
          "x": -15,
          "ForgeData": {
            "LockFlag": "1b"
          },
          "id": "minecraft:barrel",
          "y": 2,
          "Items": []
        }
      },
      {
        "char": "s",
        "block": "minecraft:iron_trapdoor[facing=north,half=bottom,open=false,powered=false,waterlogged=false]"
      },
      {
        "char": "m",
        "block": "minecraft:iron_trapdoor[facing=west,half=bottom,open=false,powered=false,waterlogged=false]"
      },
      {
        "char": "Ѥ",
        "block": "minecraft:air",
        "tag": {
          "z": -276,
          "x": -43,
          "id": "refurbished_furniture:computer",
          "y": -39,
          "NodePos": "-11544873218087L",
          "Connections": [
            "L"
          ]
        }
      },
      {
        "char": "p",
        "block": "minecraft:iron_trapdoor[facing=north,half=top,open=false,powered=false,waterlogged=false]"
      },
      {
        "char": "学",
        "block": "minecraft:air"
      },
      {
        "char": "q",
        "block": "minecraft:iron_trapdoor[facing=west,half=top,open=false,powered=false,waterlogged=false]"
      }
    ]
  },
  "slices": [
    [
      "             ggc",
      "             aba",
      "            acac",
      "            acab",
      "           gdabd",
      "           ababd",
      "          acadca",
      "          gbaedd",
      "           baded",
      "           cacea",
      "          cabbed",
      "          dadbeb",
      "          agedcb",
      "          aaaded",
      "         acidceb",
      "          badead"
    ],
    [
      "             g  ",
      "              ef",
      "                ",
      "              f ",
      "             f  ",
      "                ",
      "            f   ",
      "          adg  b",
      "            f Oa",
      "            f  П",
      "           f    ",
      "           f   a",
      "           f  Od",
      "               c",
      "         geaddaa",
      "           f    "
    ],
    [
      "             i s",
      "              df",
      "             sf ",
      "             mf ",
      "            m   ",
      "            mf  ",
      "           mf   ",
      "          aci   ",
      "           m   Ѥ",
      "           mf   ",
      "          mf    ",
      "          mf    ",
      "          m    Ѥ",
      "          mf    ",
      "         aegdcdd",
      "          mf    "
    ],
    [
      "             a p",
      "              ef",
      "             学  ",
      "             qf ",
      "            qf  ",
      "            qf  ",
      "           qf   ",
      "          ica   ",
      "           qf   ",
      "           qf   ",
      "          qf    ",
      "          qf    ",
      "          qf    ",
      "          qf    ",
      "         acaaeda",
      "          q     "
    ],
    [
      "             a  ",
      "              ef",
      "              f ",
      "              f ",
      "             f  ",
      "                ",
      "            f   ",
      "          gaa   ",
      "            f   ",
      "            f   ",
      "                ",
      "           f    ",
      "           f    ",
      "           f    ",
      "         gbacbcb",
      "                "
    ],
    [
      "             a e",
      "              da",
      "             ci ",
      "             ba ",
      "            ba  ",
      "            da  ",
      "           eg   ",
      "          abi   ",
      "           ai   ",
      "           cg   ",
      "          da    ",
      "          ea    ",
      "          cg    ",
      "          bg    ",
      "         aegedca",
      "          ea    "
    ]
  ]
}