{
  "xsize": 16,
  "zsize": 16,
  "palette": {
    "palette": [
      {
        "char": " ",
        "block": "minecraft:air"
      },
      {
        "char": "a",
        "block": "minecraft:cyan_terracotta"
      },
      {
        "char": "b",
        "block": "minecraft:blackstone"
      },
      {
        "char": "e",
        "block": "minecraft:basalt[axis=y]"
      },
      {
        "char": "d",
        "block": "minecraft:cobbled_deepslate"
      },
      {
        "char": "g",
        "block": "minecraft:gray_concrete"
      },
      {
        "char": "c",
        "block": "minecraft:deepslate[axis=y]"
      },
      {
        "char": "f",
        "block": "minecraft:glass"
      },
      {
        "char": "ϕ",
        "block": "minecraft:quartz_stairs[facing=north,half=bottom,shape=straight,waterlogged=false]"
      },
      {
        "char": "s",
        "block": "minecraft:iron_trapdoor[facing=north,half=bottom,open=false,powered=false,waterlogged=false]"
      },
      {
        "char": "m",
        "block": "minecraft:iron_trapdoor[facing=west,half=bottom,open=false,powered=false,waterlogged=false]"
      },
      {
        "char": "成",
        "block": "minecraft:air"
      },
      {
        "char": "多",
        "block": "minecraft:air"
      },
      {
        "char": "p",
        "block": "minecraft:iron_trapdoor[facing=north,half=top,open=false,powered=false,waterlogged=false]"
      },
      {
        "char": "q",
        "block": "minecraft:iron_trapdoor[facing=west,half=top,open=false,powered=false,waterlogged=false]"
      },
      {
        "char": "i",
        "block": "minecraft:light_gray_concrete"
      }
    ]
  },
  "slices": [
    [
      "                ",
      "                ",
      "                ",
      "                ",
      "                ",
      "                ",
      "                ",
      "         aa  ab ",
      "       aabaedaa ",
      "     agebgaagdb ",
      "   agbcaabbcaaba",
      "  aabaaeaebcdcde",
      " gecaebabbaebcbe",
      "abaaceedcacdcbbb",
      "aabecadedbcebbde",
      "gbeeaebdadcbeccb"
    ],
    [
      "                ",
      "                ",
      "                ",
      "                ",
      "                ",
      "                ",
      "                ",
      "          a     ",
      "          a  fe ",
      "         fg fed ",
      "   a   ff c   eb",
      "    bff   c    e",
      "    f     b ϕ   ",
      "  ff      e   d ",
      " f        eccca ",
      "     e    e     "
    ],
    [
      "                ",
      "                ",
      "                ",
      "                ",
      "                ",
      "                ",
      "                ",
      "          a  s  ",
      "         scss   ",
      "       ss a     ",
      "   a ssf  c     ",
      "    eff   e     ",
      "  ssf     e     ",
      " sf       c     ",
      "mf        b成多   ",
      "f         e     "
    ],
    [
      "                ",
      "                ",
      "                ",
      "                ",
      "                ",
      "                ",
      "                ",
      "          a  p  ",
      "         pcpp   ",
      "       ppfaff   ",
      "   a ppff c     ",
      "    cf    a     ",
      "  pqf     d     ",
      " p        a     ",
      "pf        a     ",
      "f         e     "
    ],
    [
      "                ",
      "                ",
      "                ",
      "                ",
      "                ",
      "                ",
      "                ",
      "          i     ",
      "          b  f  ",
      "         fgff   ",
      "   a   ff e     ",
      "    bff   d     ",
      "    f     d     ",
      "  ff      c     ",
      " f        a     ",
      "f         a     "
    ],
    [
      "                ",
      "                ",
      "                ",
      "                ",
      "                ",
      "                ",
      "                ",
      "          a  d  ",
      "         bccaa  ",
      "       deaaia   ",
      "   i ccgg c     ",
      "    dag   d     ",
      "  abg     b     ",
      " dai      d     ",
      "eg        c     ",
      "a         b     "
    ]
  ]
}