{
  "xsize": 16,
  "zsize": 16,
  "palette": {
    "palette": [
      {
        "char": " ",
        "block": "minecraft:air"
      },
      {
        "char": "b",
        "block": "minecraft:blackstone"
      },
      {
        "char": "e",
        "block": "minecraft:basalt[axis=y]"
      },
      {
        "char": "a",
        "block": "minecraft:cyan_terracotta"
      },
      {
        "char": "c",
        "block": "minecraft:deepslate[axis=y]"
      },
      {
        "char": "d",
        "block": "minecraft:cobbled_deepslate"
      },
      {
        "char": "g",
        "block": "minecraft:gray_concrete"
      },
      {
        "char": "i",
        "block": "minecraft:light_gray_concrete"
      },
      {
        "char": "Р",
        "block": "minecraft:stone_brick_stairs[facing=north,half=bottom,shape=straight,waterlogged=false,weathering=false]"
      },
      {
        "char": "z",
        "block": "minecraft:iron_bars[east=false,north=true,south=true,waterlogged=false,west=false]"
      },
      {
        "char": "Y",
        "block": "minecraft:iron_bars[east=false,north=true,south=false,waterlogged=false,west=false]"
      },
      {
        "char": "f",
        "block": "minecraft:glass"
      },
      {
        "char": "x",
        "block": "minecraft:cauldron"
      },
      {
        "char": "У",
        "block": "minecraft:stone_brick_stairs[facing=south,half=bottom,shape=straight,waterlogged=false,weathering=false]"
      },
      {
        "char": "С",
        "block": "minecraft:stone_brick_stairs[facing=north,half=top,shape=straight,waterlogged=false,weathering=false]"
      },
      {
        "char": "s",
        "block": "minecraft:iron_trapdoor[facing=north,half=bottom,open=false,powered=false,waterlogged=false]"
      },
      {
        "char": "m",
        "block": "minecraft:iron_trapdoor[facing=west,half=bottom,open=false,powered=false,waterlogged=false]"
      },
      {
        "char": "k",
        "block": "minecraft:oak_leaves[distance=7,persistent=true,waterlogged=false]"
      },
      {
        "char": "p",
        "block": "minecraft:iron_trapdoor[facing=north,half=top,open=false,powered=false,waterlogged=false]"
      },
      {
        "char": "q",
        "block": "minecraft:iron_trapdoor[facing=west,half=top,open=false,powered=false,waterlogged=false]"
      },
      {
        "char": "у",
        "block": "minecraft:stone_brick_stairs[facing=south,half=top,shape=straight,waterlogged=false,weathering=false]"
      },
      {
        "char": "I",
        "block": "minecraft:stone_slab[type=top,waterlogged=false,weathering=false]"
      },
      {
        "char": "道",
        "block": "minecraft:air"
      }
    ]
  },
  "slices": [
    [
      "         beeabbc",
      "       dcdaabcec",
      "      dbbaaacbed",
      "     becacaeadee",
      "    bbbeebaaccae",
      "  g aecacababdaa",
      "aaidecdecdebabbb",
      "eededcacceebbebe",
      "bbeeaeecaacdcdee",
      "daedebebdabbcead",
      "eebcdddccaeadaeb",
      "bbdaacedcccddadb",
      "cdcecacdebcbРz d",
      "adbdeadbbcdb z e",
      "ceadddddedeb Y c",
      "ccdaddabeeae   c"
    ],
    [
      "         e      ",
      "         d      ",
      "       ffa      ",
      "      f         ",
      "                ",
      "  a  f          ",
      "   acc    x     ",
      "dcdcddbebcaa   a",
      "  a  x  x       ",
      "  e             ",
      "  a             ",
      "           e d e",
      "           c zУe",
      "  a        c zСc",
      "dab        a Y d",
      "  c        c   c"
    ],
    [
      "         c      ",
      "       ssd      ",
      "      m fe      ",
      "     mf         ",
      "    mf          ",
      "  a mf          ",
      "   daa    k     ",
      "bdccabbbacbd   d",
      "  c  k  k       ",
      "  b             ",
      "  d             ",
      "           a b c",
      "           b z c",
      "  c        b zУc",
      "edc        d YСb",
      "  b        b   d"
    ],
    [
      "         c      ",
      "       ppa      ",
      "      qf e      ",
      "     pf         ",
      "    q           ",
      "  a qf          ",
      "   bcd    k     ",
      "cebeeeebbbbb   d",
      "  b  k  k       ",
      "  e             ",
      "  a             ",
      "           b b c",
      "           e z b",
      "  b        a z d",
      "dbc        dуzУc",
      "  b        adcbd"
    ],
    [
      "         d      ",
      "         d      ",
      "       ffa      ",
      "      f         ",
      "     f          ",
      "  a             ",
      "   ecc          ",
      "bbeccdebceacIIIa",
      "  a             ",
      "  c             ",
      "  e             ",
      "  I        dbebe",
      "  I        a z d",
      "  e        cуz e",
      "cae        aРY b",
      "  b        e   a"
    ],
    [
      "         e      ",
      "       bca      ",
      "      baee      ",
      "     bb         ",
      "    eb          ",
      "  a ab          ",
      "   bbc          ",
      "cecabadceeadceac",
      "  d             ",
      "  c             ",
      "  c             ",
      "  d        aacbe",
      "  e        c道z a",
      "  b        dРz a",
      "bea        e Y e",
      "  b        a   e"
    ]
  ]
}