{
  "xsize": 16,
  "zsize": 16,
  "palette": {
    "palette": [
      {
        "char": " ",
        "block": "minecraft:air"
      },
      {
        "char": "a",
        "block": "minecraft:cyan_terracotta"
      },
      {
        "char": "e",
        "block": "minecraft:basalt[axis=y]"
      },
      {
        "char": "d",
        "block": "minecraft:cobbled_deepslate"
      },
      {
        "char": "b",
        "block": "minecraft:blackstone"
      },
      {
        "char": "c",
        "block": "minecraft:deepslate[axis=y]"
      },
      {
        "char": "ϒ",
        "block": "minecraft:polished_andesite_stairs[facing=east,half=top,shape=straight,waterlogged=false]"
      },
      {
        "char": "将",
        "block": "minecraft:cobblestone_wall[east=low,north=low,south=none,up=true,waterlogged=false,weathering=false,west=none]"
      },
      {
        "char": "起",
        "block": "minecraft:cobblestone_wall[east=none,north=none,south=none,up=true,waterlogged=false,weathering=false,west=low]"
      },
      {
        "char": "交",
        "block": "minecraft:polished_andesite_stairs[facing=west,half=bottom,shape=straight,waterlogged=false]"
      },
      {
        "char": "电",
        "block": "minecraft:stone_brick_wall[east=low,north=none,south=none,up=true,waterlogged=false,weathering=false,west=none]"
      },
      {
        "char": "力",
        "block": "minecraft:stone_brick_wall[east=none,north=none,south=none,up=true,waterlogged=false,weathering=false,west=low]"
      },
      {
        "char": "叁",
        "block": "minecraft:cobblestone_wall[east=none,north=none,south=none,up=true,waterlogged=false,weathering=false,west=tall]"
      },
      {
        "char": "Ѵ",
        "block": "minecraft:white_stained_glass_pane[east=false,north=false,south=false,waterlogged=false,west=true]"
      },
      {
        "char": "ѯ",
        "block": "minecraft:stone_brick_wall[east=none,north=low,south=low,up=false,waterlogged=false,weathering=false,west=none]"
      },
      {
        "char": "女",
        "block": "minecraft:cobblestone_wall[east=low,north=low,south=low,up=true,waterlogged=false,weathering=false,west=none]"
      },
      {
        "char": "表",
        "block": "minecraft:stone_brick_wall[east=tall,north=low,south=low,up=true,waterlogged=false,weathering=false,west=low]"
      },
      {
        "char": "找",
        "block": "minecraft:stone_brick_wall[east=tall,north=tall,south=low,up=true,waterlogged=false,weathering=false,west=tall]"
      },
      {
        "char": "Ҽ",
        "block": "minecraft:birch_wall_sign[facing=south,waterlogged=false]",
        "tag": {
          "z": -283,
          "x": -20,
          "is_waxed": "0b",
          "id": "minecraft:sign",
          "y": -49,
          "front_text": {
            "color": "black",
            "has_glowing_text": "0b",
            "messages": [
              "{\"text\":\"\"}",
              "{\"text\":\"INFORMATION\"}",
              "{\"text\":\"\"}",
              "{\"text\":\"\"}"
            ]
          },
          "back_text": {
            "color": "black",
            "has_glowing_text": "0b",
            "messages": [
              "{\"text\":\"\"}",
              "{\"text\":\"\"}",
              "{\"text\":\"\"}",
              "{\"text\":\"\"}"
            ]
          }
        }
      },
      {
        "char": "十",
        "block": "minecraft:stone_brick_wall[east=low,north=low,south=none,up=true,waterlogged=false,weathering=false,west=low]"
      }
    ]
  },
  "slices": [
    [
      "aeedbcda        ",
      "ϒc              ",
      "ϒe              ",
      " 将起             ",
      "                ",
      "                ",
      "                ",
      "                ",
      "                ",
      "                ",
      "                ",
      "                ",
      "                ",
      "                ",
      "                ",
      "                "
    ],
    [
      "cdeacedb        ",
      "交               ",
      "交               ",
      "电力              ",
      "                ",
      "                ",
      "                ",
      "                ",
      "                ",
      "                ",
      "                ",
      "                ",
      "                ",
      "                ",
      "                ",
      "                "
    ],
    [
      "acbaddab       ϒ",
      "                ",
      "                ",
      "叁               ",
      "                ",
      "                ",
      "                ",
      "                ",
      "                ",
      "                ",
      "                ",
      "                ",
      "                ",
      "                ",
      "                ",
      "                "
    ],
    [
      "aabecdebeebcbcab",
      "   eeeaeccbdcaea",
      "   bcadcdbcda   ",
      "eadcdecbbacb    ",
      "eabdbbbbbe      ",
      "cebdeecca       ",
      "aecdadde        ",
      "ecbdbbb         ",
      "babecd          ",
      "                ",
      "                ",
      "                ",
      "                ",
      "                ",
      "                ",
      "                "
    ],
    [
      "cccaabedѴ  ceece",
      "   ѯ   d   cbced",
      "   女cb     ed   ",
      "cae表eeee  ee    ",
      "ebeabdcae       ",
      "bbdeaea         ",
      "ecc找ac          ",
      " edcb           ",
      "                ",
      "                ",
      "                ",
      "                ",
      "                ",
      "                ",
      "                ",
      "                "
    ],
    [
      "cdedeeea   ddcca",
      "       b   dda  ",
      "       Ҽ   a    ",
      "   电e          b",
      "c   ee          ",
      "dcbdc           ",
      " ee十a           ",
      "                ",
      "                ",
      "                ",
      "                ",
      "                ",
      "                ",
      "                ",
      "                ",
      "                "
    ]
  ]
}