{
  "xsize": 16,
  "zsize": 16,
  "palette": {
    "palette": [
      {
        "char": " ",
        "block": "minecraft:air"
      },
      {
        "char": "E",
        "block": "minecraft:red_terracotta"
      },
      {
        "char": "d",
        "block": "minecraft:cobbled_deepslate"
      },
      {
        "char": "c",
        "block": "minecraft:deepslate[axis=y]"
      },
      {
        "char": "a",
        "block": "minecraft:cyan_terracotta"
      },
      {
        "char": "b",
        "block": "minecraft:blackstone"
      },
      {
        "char": "e",
        "block": "minecraft:basalt[axis=y]"
      },
      {
        "char": "A",
        "block": "minecraft:red_concrete"
      },
      {
        "char": "ϗ",
        "block": "minecraft:stone_brick_wall[east=none,north=none,south=none,up=true,waterlogged=false,weathering=false,west=none]"
      },
      {
        "char": "á",
        "block": "minecraft:cobblestone_wall[east=none,north=none,south=none,up=true,waterlogged=false,weathering=false,west=none]"
      },
      {
        "char": "i",
        "block": "minecraft:light_gray_concrete"
      },
      {
        "char": "X",
        "block": "minecraft:red_wool"
      },
      {
        "char": "用",
        "block": "minecraft:iron_bars[east=true,north=true,south=true,waterlogged=false,west=false]"
      },
      {
        "char": "g",
        "block": "minecraft:gray_concrete"
      },
      {
        "char": "H",
        "block": "minecraft:quartz_stairs[facing=south,half=bottom,shape=straight,waterlogged=false]"
      },
      {
        "char": "题",
        "block": "minecraft:stone_brick_wall[east=none,north=none,south=low,up=true,waterlogged=false,weathering=false,west=none]"
      },
      {
        "char": "就",
        "block": "minecraft:stone_brick_wall[east=none,north=low,south=none,up=true,waterlogged=false,weathering=false,west=none]"
      },
      {
        "char": "ѯ",
        "block": "minecraft:stone_brick_wall[east=none,north=low,south=low,up=false,waterlogged=false,weathering=false,west=none]"
      },
      {
        "char": "理",
        "block": "minecraft:air"
      },
      {
        "char": "台",
        "block": "minecraft:cobblestone_wall[east=none,north=low,south=low,up=false,waterlogged=false,weathering=false,west=none]"
      },
      {
        "char": "出",
        "block": "minecraft:cobblestone_wall[east=none,north=low,south=none,up=true,waterlogged=false,weathering=false,west=none]"
      },
      {
        "char": "S",
        "block": "minecraft:orange_terracotta"
      },
      {
        "char": "ϑ",
        "block": "minecraft:orange_concrete"
      },
      {
        "char": "ӡ",
        "block": "minecraft:orange_wool"
      }
    ]
  },
  "slices": [
    [
      " Edcddabeaabaccd",
      " Ad             ",
      " Ee             ",
      "  Ac          ϗ ",
      "  Aa            ",
      "   Ee           ",
      "   Ad         á ",
      "  i Ed          ",
      "    Ac          ",
      "     Ac         ",
      "      Ada       ",
      "       A        ",
      "                ",
      "                ",
      "                ",
      "                "
    ],
    [
      " Aedbddbeebcbecc",
      " Ae             ",
      " Xc             ",
      "  Xe          ϗ ",
      "  Ad            ",
      "   Ad           ",
      "   Aa         á ",
      "  i Ad          ",
      "    Ae          ",
      "     Ea         ",
      "      Aa        ",
      "       X        ",
      "                ",
      "                ",
      "                ",
      "                "
    ],
    [
      " Xbaaeeeeeaacdaa",
      " Ed             ",
      " Ac             ",
      "  Ae          ϗ ",
      "  Ad            ",
      "   Xd           ",
      "   Ee         á ",
      "  a 用d          ",
      "    Ac          ",
      "     A   ϗ      ",
      "                ",
      "                ",
      "                ",
      "                ",
      "                ",
      "                "
    ],
    [
      " Eaedeaccdcdcbce",
      " Eddddabdceddbdb",
      " Ebebecdcbeeddba",
      "  Ebbbdbeaeaaceb",
      "  Eacdedbaceaed ",
      "   Adcebeedbdab ",
      "   Addbeaaecadc ",
      "  g Ecdebdebdea ",
      "    E           ",
      "         á      ",
      "                ",
      "                ",
      "                ",
      "                ",
      "                ",
      "                "
    ],
    [
      " Aa             ",
      " Eb             ",
      " Ae    H H H    ",
      "  Ab          题 ",
      "  Ea   H e    就 ",
      "   Ad    d      ",
      "   Ed    ѯ      ",
      "  g 理    台      ",
      "         ѯ      ",
      "         出      ",
      "                ",
      "                ",
      "                ",
      "                ",
      "                ",
      "                "
    ],
    [
      " Sa             ",
      " Sa             ",
      " ϑa             ",
      "  ӡb            ",
      "  ϑb            ",
      "   Sd           ",
      "   Sb           ",
      "  a             ",
      "                ",
      "                ",
      "                ",
      "                ",
      "                ",
      "                ",
      "                ",
      "                "
    ]
  ]
}