{
  "xsize": 16,
  "zsize": 16,
  "palette": {
    "palette": [
      {
        "char": " ",
        "block": "minecraft:air"
      },
      {
        "char": "e",
        "block": "minecraft:basalt[axis=y]"
      },
      {
        "char": "b",
        "block": "minecraft:blackstone"
      },
      {
        "char": "c",
        "block": "minecraft:deepslate[axis=y]"
      },
      {
        "char": "d",
        "block": "minecraft:cobbled_deepslate"
      },
      {
        "char": "a",
        "block": "minecraft:cyan_terracotta"
      },
      {
        "char": "g",
        "block": "minecraft:gray_concrete"
      },
      {
        "char": "i",
        "block": "minecraft:light_gray_concrete"
      },
      {
        "char": "ϔ",
        "block": "minecraft:quartz_stairs[facing=east,half=bottom,shape=straight,waterlogged=false]"
      },
      {
        "char": "f",
        "block": "minecraft:glass"
      },
      {
        "char": "x",
        "block": "minecraft:cauldron"
      },
      {
        "char": "H",
        "block": "minecraft:quartz_stairs[facing=south,half=bottom,shape=straight,waterlogged=false]"
      },
      {
        "char": "Ӻ",
        "block": "minecraft:air",
        "tag": {
          "z": -276,
          "x": -15,
          "id": "refurbished_furniture:computer",
          "y": 27,
          "NodePos": "-3848291827685L",
          "Connections": [
            "L"
          ]
        }
      },
      {
        "char": "l",
        "block": "minecraft:iron_trapdoor[facing=east,half=bottom,open=false,powered=false,waterlogged=false]"
      },
      {
        "char": "k",
        "block": "minecraft:oak_leaves[distance=7,persistent=true,waterlogged=false]"
      },
      {
        "char": "Ӟ",
        "block": "minecraft:air"
      },
      {
        "char": "ϐ",
        "block": "minecraft:air",
        "tag": {
          "z": -259,
          "x": -34,
          "id": "refurbished_furniture:computer",
          "y": -21,
          "NodePos": "-9070971985941L",
          "Connections": [
            "L"
          ]
        }
      },
      {
        "char": "u",
        "block": "minecraft:iron_trapdoor[facing=south,half=bottom,open=false,powered=false,waterlogged=false]"
      },
      {
        "char": "在",
        "block": "minecraft:air"
      },
      {
        "char": "t",
        "block": "minecraft:iron_trapdoor[facing=east,half=top,open=false,powered=false,waterlogged=false]"
      },
      {
        "char": "w",
        "block": "minecraft:iron_trapdoor[facing=south,half=top,open=false,powered=false,waterlogged=false]"
      }
    ]
  },
  "slices": [
    [
      "ebbecbdac       ",
      "bbedebaae       ",
      "cebaaedae       ",
      "cdeeadga        ",
      "ccacedab        ",
      "babdbaaea       ",
      "bcbeceab        ",
      "daacbia         ",
      "bdcbdae         ",
      "dcbeac          ",
      "bcdbac          ",
      "cccaa           ",
      "bbacaa          ",
      "abaaa           ",
      "cibg            ",
      "gag             "
    ],
    [
      "b ϔ             ",
      "b      f        ",
      "cea             ",
      "      f         ",
      "      f         ",
      "dbbbceaea       ",
      "  x   f         ",
      "     f          ",
      "                ",
      "                ",
      "cd              ",
      "H  fa           ",
      "  f  a          ",
      "  f             ",
      " f              ",
      "f               "
    ],
    [
      "Ӻ      fl       ",
      "       fl       ",
      "       fl       ",
      "      fl        ",
      "      fl        ",
      "daccbagaa       ",
      "  k   fl        ",
      "      Ӟ         ",
      "     fl         ",
      "    fl          ",
      "ϐ    Ӟ          ",
      "    a           ",
      "   u g          ",
      "  fl            ",
      "  l             ",
      "fl              "
    ],
    [
      "       f在       ",
      "       f在       ",
      "       ft       ",
      "       t        ",
      "      ft        ",
      "ddeaddiaa       ",
      "  k    t        ",
      "     ft         ",
      "     ft         ",
      "    ft          ",
      "    ft          ",
      "   fe           ",
      "  fw g          ",
      "   t            ",
      " ft             ",
      " w              "
    ],
    [
      "       f        ",
      "                ",
      "       f        ",
      "      f         ",
      "      f         ",
      "cdaceeaag       ",
      "      f         ",
      "     f          ",
      "     f          ",
      "    f           ",
      "                ",
      "    a           ",
      "  f  a          ",
      "                ",
      " f              ",
      "f               "
    ],
    [
      "       ga       ",
      "       ae       ",
      "       id       ",
      "      gc        ",
      "      aa        ",
      "ebedaegca       ",
      "      ia        ",
      "     ac         ",
      "     gc         ",
      "    ab          ",
      "    aa          ",
      "   ae           ",
      "  aa a          ",
      "  ga            ",
      " ac             ",
      "ac              "
    ]
  ]
}