{
  "xsize": 16,
  "zsize": 16,
  "palette": {
    "palette": [
      {
        "char": " ",
        "block": "minecraft:air"
      },
      {
        "char": "a",
        "block": "minecraft:cyan_terracotta"
      },
      {
        "char": "e",
        "block": "minecraft:basalt[axis=y]"
      },
      {
        "char": "b",
        "block": "minecraft:blackstone"
      },
      {
        "char": "d",
        "block": "minecraft:cobbled_deepslate"
      },
      {
        "char": "c",
        "block": "minecraft:deepslate[axis=y]"
      },
      {
        "char": "i",
        "block": "minecraft:light_gray_concrete"
      },
      {
        "char": "g",
        "block": "minecraft:gray_concrete"
      },
      {
        "char": "ϔ",
        "block": "minecraft:quartz_stairs[facing=east,half=bottom,shape=straight,waterlogged=false]"
      },
      {
        "char": "f",
        "block": "minecraft:glass"
      },
      {
        "char": "П",
        "block": "minecraft:barrel[facing=up,open=false]",
        "tag": {
          "z": -275,
          "x": -15,
          "ForgeData": {
            "LockFlag": "1b"
          },
          "id": "minecraft:barrel",
          "y": 2,
          "Items": []
        }
      },
      {
        "char": "x",
        "block": "minecraft:cauldron"
      },
      {
        "char": "H",
        "block": "minecraft:quartz_stairs[facing=south,half=bottom,shape=straight,waterlogged=false]"
      },
      {
        "char": "吗",
        "block": "minecraft:air"
      },
      {
        "char": "l",
        "block": "minecraft:iron_trapdoor[facing=east,half=bottom,open=false,powered=false,waterlogged=false]"
      },
      {
        "char": "k",
        "block": "minecraft:oak_leaves[distance=7,persistent=true,waterlogged=false]"
      },
      {
        "char": "ο",
        "block": "minecraft:air"
      },
      {
        "char": "Ҟ",
        "block": "minecraft:air"
      },
      {
        "char": "u",
        "block": "minecraft:iron_trapdoor[facing=south,half=bottom,open=false,powered=false,waterlogged=false]"
      },
      {
        "char": "t",
        "block": "minecraft:iron_trapdoor[facing=east,half=top,open=false,powered=false,waterlogged=false]"
      },
      {
        "char": "w",
        "block": "minecraft:iron_trapdoor[facing=south,half=top,open=false,powered=false,waterlogged=false]"
      }
    ]
  },
  "slices": [
    [
      "aeeeabaad       ",
      "dcceddaae       ",
      "adeddcbie       ",
      "dacaedie        ",
      "addbbcac        ",
      "cbeacbaea       ",
      "ebceacada       ",
      "eecccaba        ",
      "ededeicg        ",
      "cbacada         ",
      "abddaaa         ",
      "daeaaa          ",
      "bcaeai          ",
      "ddaba           ",
      "eaaa            ",
      "acg             "
    ],
    [
      "a ϔ    f        ",
      "a      f        ",
      "Пda    f        ",
      "      f         ",
      "      f         ",
      "ddadbeaci       ",
      "  x             ",
      "     f          ",
      "                ",
      "    f           ",
      "eb  f           ",
      "H  fc           ",
      "  f  a          ",
      "  f             ",
      "                ",
      "f               "
    ],
    [
      "吗      fl       ",
      "        l       ",
      "       fl       ",
      "      fl        ",
      "      fl        ",
      "cddabeaca       ",
      "  k   fl        ",
      "     fl         ",
      "      l         ",
      "    fl          ",
      "οҞ  fl          ",
      "   fb           ",
      "   u g          ",
      "  fl            ",
      "  l             ",
      " l              "
    ],
    [
      "       ft       ",
      "       ft       ",
      "       ft       ",
      "      ft        ",
      "       t        ",
      "edbcbdiba       ",
      "  k   ft        ",
      "      t         ",
      "     ft         ",
      "    ft          ",
      "     t          ",
      "   fb           ",
      "   w a          ",
      "  ft            ",
      "  t             ",
      "fw              "
    ],
    [
      "       f        ",
      "       f        ",
      "       f        ",
      "                ",
      "                ",
      "bdeadegeg       ",
      "      f         ",
      "     f          ",
      "     f          ",
      "    f           ",
      "    f           ",
      "   fc           ",
      "  f  g          ",
      "                ",
      "                ",
      "f               "
    ],
    [
      "       ad       ",
      "       ga       ",
      "       gb       ",
      "      ac        ",
      "      ad        ",
      "ceedacgaa       ",
      "      ae        ",
      "     ia         ",
      "     aa         ",
      "    ad          ",
      "    ac          ",
      "   ad           ",
      "  ab g          ",
      "  ge            ",
      " ac             ",
      "aa              "
    ]
  ]
}