{
  "xsize": 16,
  "zsize": 16,
  "palette": {
    "palette": [
      {
        "char": " ",
        "block": "minecraft:air"
      },
      {
        "char": "c",
        "block": "minecraft:deepslate[axis=y]"
      },
      {
        "char": "d",
        "block": "minecraft:cobbled_deepslate"
      },
      {
        "char": "a",
        "block": "minecraft:cyan_terracotta"
      },
      {
        "char": "i",
        "block": "minecraft:light_gray_concrete"
      },
      {
        "char": "g",
        "block": "minecraft:gray_concrete"
      },
      {
        "char": "e",
        "block": "minecraft:basalt[axis=y]"
      },
      {
        "char": "b",
        "block": "minecraft:blackstone"
      },
      {
        "char": "f",
        "block": "minecraft:glass"
      },
      {
        "char": "ϔ",
        "block": "minecraft:quartz_stairs[facing=east,half=bottom,shape=straight,waterlogged=false]"
      },
      {
        "char": "s",
        "block": "minecraft:iron_trapdoor[facing=north,half=bottom,open=false,powered=false,waterlogged=false]"
      },
      {
        "char": "l",
        "block": "minecraft:iron_trapdoor[facing=east,half=bottom,open=false,powered=false,waterlogged=false]"
      },
      {
        "char": "Ӻ",
        "block": "minecraft:air",
        "tag": {
          "z": -276,
          "x": -15,
          "id": "refurbished_furniture:computer",
          "y": 27,
          "NodePos": "-3848291827685L",
          "Connections": [
            "L"
          ]
        }
      },
      {
        "char": "p",
        "block": "minecraft:iron_trapdoor[facing=north,half=top,open=false,powered=false,waterlogged=false]"
      },
      {
        "char": "t",
        "block": "minecraft:iron_trapdoor[facing=east,half=top,open=false,powered=false,waterlogged=false]"
      }
    ]
  },
  "slices": [
    [
      "cdadig          ",
      "edbgaa          ",
      "bceaiba         ",
      "bbdcgag         ",
      "adbeeici        ",
      "eabacabg        ",
      "bddeeeabg       ",
      "ddaacdgaa       ",
      "baababaa        ",
      "bdaccdae        ",
      "badecbeae       ",
      "adcebeaad       ",
      "acbdeaead       ",
      "cdbaaccad       ",
      "cbebdceada      ",
      "addcaabgb       "
    ],
    [
      "  f  i          ",
      "   fb           ",
      "ϔ   f           ",
      "    f           ",
      "     f          ",
      "     f          ",
      "                ",
      "acadbdacg       ",
      "      f         ",
      "      f         ",
      " ada   f        ",
      " e     f        ",
      " c ϔ   f        ",
      " a              ",
      "eaeececgag      ",
      "c               "
    ],
    [
      "   s a          ",
      "   fb           ",
      "     l          ",
      "    fl          ",
      "     fl         ",
      "     fl         ",
      "      fl        ",
      "dceccdacg       ",
      "      fl        ",
      "      fl        ",
      "       fl       ",
      "       fl       ",
      " Ӻ     fl       ",
      "       fl       ",
      "bacabcbaai      ",
      "       fl       "
    ],
    [
      "  fp a          ",
      "   fc           ",
      "    ft          ",
      "    ft          ",
      "     ft         ",
      "      t         ",
      "      ft        ",
      "ebeebagaa       ",
      "      ft        ",
      "      ft        ",
      "       ft       ",
      "        t       ",
      "        t       ",
      "       ft       ",
      "baacbbcaeg      ",
      "        t       "
    ],
    [
      "  f  a          ",
      "    e           ",
      "    f           ",
      "    f           ",
      "                ",
      "     f          ",
      "                ",
      "ecbdecaaa       ",
      "      f         ",
      "      f         ",
      "                ",
      "       f        ",
      "       f        ",
      "       f        ",
      "beacccdgca      ",
      "                "
    ],
    [
      "  ad i          ",
      "   ad           ",
      "    ad          ",
      "    ab          ",
      "     ab         ",
      "     ae         ",
      "      ad        ",
      "acccedaea       ",
      "      ad        ",
      "      ac        ",
      "       aa       ",
      "       ac       ",
      "       ab       ",
      "       ga       ",
      "edbcbbdgea      ",
      "       ac       "
    ]
  ]
}