{
  "xsize": 16,
  "zsize": 16,
  "palette": {
    "palette": [
      {
        "char": " ",
        "block": "minecraft:air"
      },
      {
        "char": "b",
        "block": "minecraft:blackstone"
      },
      {
        "char": "a",
        "block": "minecraft:cyan_terracotta"
      },
      {
        "char": "c",
        "block": "minecraft:deepslate[axis=y]"
      },
      {
        "char": "e",
        "block": "minecraft:basalt[axis=y]"
      },
      {
        "char": "d",
        "block": "minecraft:cobbled_deepslate"
      },
      {
        "char": "x",
        "block": "minecraft:cauldron"
      },
      {
        "char": "k",
        "block": "minecraft:oak_leaves[distance=7,persistent=true,waterlogged=false]"
      },
      {
        "char": "I",
        "block": "minecraft:stone_slab[type=top,waterlogged=false,weathering=false]"
      }
    ]
  },
  "slices": [
    [
      "bababcecbacecaaa",
      "cebcbcdcbdaeeabe",
      "abaedecdeecc    ",
      "becebaeadeb     ",
      "acacadbcba      ",
      "ccdbbccabe      ",
      "cededdaabd      ",
      "caedaabece      ",
      "caadadbdce      ",
      "abeeeccbdd      ",
      "bcaacb          ",
      "abbda           ",
      "bceb            ",
      "bea             ",
      "                ",
      "                "
    ],
    [
      "ccddcaae        ",
      " b              ",
      " d              ",
      " b              ",
      "bbc   ebb       ",
      " b      a       ",
      "        c       ",
      "       xd       ",
      "        c       ",
      "        e       ",
      " bdbb           ",
      "ebcb            ",
      "aab             ",
      "ac              ",
      "                ",
      "                "
    ],
    [
      "bbebcdbc        ",
      " e              ",
      " d              ",
      " a              ",
      "ede   dbe       ",
      " a      d       ",
      "        d       ",
      "       kd       ",
      "        b       ",
      "                ",
      "                ",
      "                ",
      "                ",
      "                ",
      "                ",
      "                "
    ],
    [
      "dcaeddbd        ",
      " d              ",
      " d              ",
      " e              ",
      "cca   cae       ",
      " a      e       ",
      "        b       ",
      "       kd       ",
      "                ",
      "                ",
      "                ",
      "                ",
      "                ",
      "                ",
      "                ",
      "                "
    ],
    [
      "caedebda        ",
      " b              ",
      " b              ",
      " a              ",
      "cecIIIedb       ",
      " c      b       ",
      " I      e       ",
      " I              ",
      " I              ",
      " I              ",
      "                ",
      "                ",
      "                ",
      "                ",
      "                ",
      "                "
    ],
    [
      "cdaacaec        ",
      " a              ",
      " c              ",
      " e              ",
      "bcdecadbd       ",
      " c      b       ",
      " e      e       ",
      " e              ",
      " b              ",
      " d              ",
      "                ",
      "                ",
      "                ",
      "                ",
      "                ",
      "                "
    ]
  ]
}