{
  "xsize": 16,
  "zsize": 16,
  "palette": {
    "palette": [
      {
        "char": " ",
        "block": "minecraft:air"
      },
      {
        "char": "e",
        "block": "minecraft:basalt[axis=y]"
      },
      {
        "char": "a",
        "block": "minecraft:cyan_terracotta"
      },
      {
        "char": "g",
        "block": "minecraft:gray_concrete"
      },
      {
        "char": "d",
        "block": "minecraft:cobbled_deepslate"
      },
      {
        "char": "D",
        "block": "minecraft:smooth_stone_slab[type=bottom,waterlogged=false]"
      },
      {
        "char": "i",
        "block": "minecraft:light_gray_concrete"
      },
      {
        "char": "0",
        "block": "minecraft:stone_slab[type=bottom,waterlogged=false,weathering=false]"
      },
      {
        "char": "c",
        "block": "minecraft:deepslate[axis=y]"
      },
      {
        "char": "E",
        "block": "minecraft:red_terracotta"
      },
      {
        "char": "A",
        "block": "minecraft:red_concrete"
      },
      {
        "char": "b",
        "block": "minecraft:blackstone"
      },
      {
        "char": "Ѱ",
        "block": "minecraft:cobblestone_slab[type=bottom,waterlogged=false,weathering=false]"
      },
      {
        "char": "f",
        "block": "minecraft:glass"
      },
      {
        "char": "ϗ",
        "block": "minecraft:stone_brick_wall[east=none,north=none,south=none,up=true,waterlogged=false,weathering=false,west=none]"
      },
      {
        "char": "ϔ",
        "block": "minecraft:quartz_stairs[facing=east,half=bottom,shape=straight,waterlogged=false]"
      },
      {
        "char": "也",
        "block": "minecraft:stone_brick_wall[east=tall,north=none,south=none,up=true,waterlogged=false,weathering=false,west=none]"
      },
      {
        "char": "s",
        "block": "minecraft:iron_trapdoor[facing=north,half=bottom,open=false,powered=false,waterlogged=false]"
      },
      {
        "char": "l",
        "block": "minecraft:iron_trapdoor[facing=east,half=bottom,open=false,powered=false,waterlogged=false]"
      },
      {
        "char": "Ӻ",
        "block": "minecraft:air",
        "tag": {
          "z": -276,
          "x": -15,
          "id": "refurbished_furniture:computer",
          "y": 27,
          "NodePos": "-3848291827685L",
          "Connections": [
            "L"
          ]
        }
      },
      {
        "char": "p",
        "block": "minecraft:iron_trapdoor[facing=north,half=top,open=false,powered=false,waterlogged=false]"
      },
      {
        "char": "点",
        "block": "minecraft:stone_brick_wall[east=tall,north=low,south=low,up=true,waterlogged=false,weathering=false,west=none]"
      },
      {
        "char": "ѯ",
        "block": "minecraft:stone_brick_wall[east=none,north=low,south=low,up=false,waterlogged=false,weathering=false,west=none]"
      },
      {
        "char": "t",
        "block": "minecraft:iron_trapdoor[facing=east,half=top,open=false,powered=false,waterlogged=false]"
      },
      {
        "char": "意",
        "block": "minecraft:stone_brick_wall[east=low,north=low,south=none,up=true,waterlogged=false,weathering=false,west=none]"
      },
      {
        "char": "在",
        "block": "minecraft:air"
      },
      {
        "char": "电",
        "block": "minecraft:stone_brick_wall[east=low,north=none,south=none,up=true,waterlogged=false,weathering=false,west=none]"
      }
    ]
  },
  "slices": [
    [
      "eagdDi0DcE      ",
      "daeadDD0DA      ",
      "bacaacD0eE      ",
      "ecbdgcѰѰD       ",
      "eccdcabDD       ",
      "cbdcdacDDaa     ",
      "acdaeegcDaa     ",
      "cceeadaca       ",
      "dabecbacD       ",
      "eabdcdab0       ",
      "ddcdbadaa       ",
      "cebedeead       ",
      "cacaedbgc       ",
      "dabacdeib       ",
      "abbccbdacg      ",
      "deceedcad       "
    ],
    [
      "  f  i  ϗ       ",
      "   fa           ",
      "ϔ       也E      ",
      "    f           ",
      "     f          ",
      "     f          ",
      "      f         ",
      "edaedagbg       ",
      "      f         ",
      "      f         ",
      " bda   f        ",
      " e     f        ",
      " a ϔ   f        ",
      " e     f        ",
      "eaeececaai      ",
      "d               "
    ],
    [
      "  fs a  也E      ",
      "    c           ",
      "    fl  也A      ",
      "    fl          ",
      "     fl         ",
      "      l         ",
      "      fl        ",
      "eaabcbaag       ",
      "      fl        ",
      "      fl        ",
      "       fl       ",
      "       fl       ",
      " Ӻ     fl       ",
      "       fl       ",
      "eebbaccaaa      ",
      "       fl       "
    ],
    [
      "  fp a  点A      ",
      "   fd   ѯ       ",
      "    ft  意E      ",
      "    ft          ",
      "      在         ",
      "     ft         ",
      "      f在        ",
      "daccacadg       ",
      "      ft        ",
      "       在        ",
      "       ft       ",
      "        t       ",
      "       ft       ",
      "       ft       ",
      "bdbddadaeg      ",
      "       ft       "
    ],
    [
      "  f  a  电A      ",
      "   fc           ",
      "    f    E      ",
      "    f           ",
      "     f          ",
      "     f          ",
      "      f         ",
      "cbbeedaaa       ",
      "      f         ",
      "                ",
      "       f        ",
      "                ",
      "       f        ",
      "       f        ",
      "aeabecbaaa      ",
      "       f        "
    ],
    [
      "  aa i   E      ",
      "   ab           ",
      "    ab          ",
      "    aa          ",
      "     ad         ",
      "     ae         ",
      "      ab        ",
      "dcadaaada       ",
      "      ac        ",
      "      ad        ",
      "       gb       ",
      "       ab       ",
      "       ad       ",
      "       ac       ",
      "cabcbbcaea      ",
      "       ad       "
    ]
  ]
}