{
  "xsize": 16,
  "zsize": 16,
  "palette": {
    "palette": [
      {
        "char": " ",
        "block": "minecraft:air"
      },
      {
        "char": "a",
        "block": "minecraft:air"
      },
      {
        "char": "y",
        "block": "minecraft:air"
      },
      {
        "char": "d",
        "block": "minecraft:air"
      },
      {
        "char": "b",
        "block": "minecraft:air"
      },
      {
        "char": "c",
        "block": "minecraft:air"
      },
      {
        "char": "Q",
        "block": "minecraft:air"
      },
      {
        "char": "n",
        "block": "minecraft:air"
      },
      {
        "char": "C",
        "block": "minecraft:air"
      },
      {
        "char": "r",
        "block": "minecraft:air"
      },
      {
        "char": "o",
        "block": "minecraft:air"
      },
      {
        "char": "K",
        "block": "minecraft:air"
      },
      {
        "char": "J",
        "block": "minecraft:air"
      },
      {
        "char": "B",
        "block": "minecraft:air"
      },
      {
        "char": "T",
        "block": "minecraft:air"
      },
      {
        "char": "U",
        "block": "minecraft:tall_grass[half=lower]"
      },
      {
        "char": "g",
        "block": "minecraft:air"
      },
      {
        "char": "e",
        "block": "minecraft:air"
      },
      {
        "char": "z",
        "block": "minecraft:air"
      },
      {
        "char": "ϕ",
        "block": "minecraft:air"
      },
      {
        "char": "ϓ",
        "block": "minecraft:air"
      },
      {
        "char": "ϔ",
        "block": "minecraft:air"
      },
      {
        "char": "O",
        "block": "minecraft:air"
      },
      {
        "char": "H",
        "block": "minecraft:air"
      },
      {
        "char": "谁",
        "block": "minecraft:air"
      },
      {
        "char": "у",
        "block": "minecraft:air"
      },
      {
        "char": "F",
        "block": "minecraft:air"
      },
      {
        "char": "无",
        "block": "minecraft:air"
      },
      {
        "char": "V",
        "block": "minecraft:tall_grass[half=upper]"
      },
      {
        "char": "实",
        "block": "minecraft:air"
      },
      {
        "char": "X",
        "block": "minecraft:air"
      },
      {
        "char": "E",
        "block": "minecraft:air"
      },
      {
        "char": "Ѳ",
        "block": "minecraft:air"
      },
      {
        "char": "i",
        "block": "minecraft:air"
      },
      {
        "char": "N",
        "block": "minecraft:air"
      },
      {
        "char": "A",
        "block": "minecraft:air"
      },
      {
        "char": "ѩ",
        "block": "minecraft:air"
      },
      {
        "char": "M",
        "block": "minecraft:air"
      },
      {
        "char": "ҽ",
        "block": "minecraft:air"
      }
    ]
  },
  "slices": [
    [
      "aaydbdddcydycyyy",
      "acQbcdabadaaddQd",
      "ydabaycQyaaacdyd",
      "nCnroCoQQnKKooQK",
      "nobnKrncbnncKJKn",
      "oKrnbrJJcbrrbnnJ",
      "ydadcQdbaccbcoon",
      "BBBBBBBrnJJnCTTn",
      "BBBBBBBdJrrroTTr",
      "BBBBBBBbrCCJroKC",
      "BBBBBBByCroorJoK",
      "BBBBBBBcrrrnoTTJ",
      "BBBBBBBorCrKJTTC",
      "BBBBBBBrCCKrJJrJ",
      "BBBBBBBnoonoooJo",
      "BBBBBBBoonoKnTTn"
    ],
    [
      "                ",
      "  U           U ",
      "       U        ",
      "       UU     U ",
      "                ",
      "        ga   a  ",
      "  a    cgaabea  ",
      "       e        ",
      "       z        ",
      "ϕ      z        ",
      "ϓϔ O   z Oϓϔ    ",
      "H   H  z  H     ",
      "       b        ",
      "    ϕ  baa      ",
      "   Oϓϔ bga   谁уу",
      "FF  H  b     无dd"
    ],
    [
      "                ",
      "  V           V ",
      "       V        ",
      "       VV     V ",
      "                ",
      "        aa   a  ",
      "  e    aga   a  ",
      "       d        ",
      "       z        ",
      "       z        ",
      "实      z        ",
      "       z        ",
      "       e        ",
      "       bag      ",
      "    实  caa      ",
      "       e      XE"
    ],
    [
      "                ",
      "                ",
      "                ",
      "                ",
      "                ",
      "        aa   a  ",
      "  d    caa  Ѳa  ",
      "       a        ",
      "       z        ",
      "       z        ",
      "       z        ",
      "       z        ",
      "       e        ",
      "       dia      ",
      "       caa      ",
      "       b      X "
    ],
    [
      "                ",
      "                ",
      "                ",
      "                ",
      "                ",
      "        ga   i  ",
      "  e    aaiNNNa  ",
      "       a        ",
      "       z        ",
      "       z        ",
      "       z        ",
      "       z        ",
      "       e        ",
      "       daa      ",
      "       caa      ",
      "FF     c      A "
    ],
    [
      "                ",
      "                ",
      "                ",
      "                ",
      "                ",
      "        ai   g  ",
      "NNb ѲNNbga ѲNa  ",
      "       dѩ       ",
      "       cM       ",
      "       aѩ       ",
      "       aM       ",
      "       aM       ",
      "       aѩ       ",
      "       caa      ",
      "ҽҽ     aag      ",
      "FFҽ    aѩ     A "
    ]
  ]
}