{
  "xsize": 16,
  "zsize": 16,
  "palette": {
    "palette": [
      {
        "char": " ",
        "block": "minecraft:air"
      },
      {
        "char": "d",
        "block": "minecraft:cobbled_deepslate"
      },
      {
        "char": "c",
        "block": "minecraft:deepslate[axis=y]"
      },
      {
        "char": "b",
        "block": "minecraft:blackstone"
      },
      {
        "char": "a",
        "block": "minecraft:cyan_terracotta"
      },
      {
        "char": "e",
        "block": "minecraft:basalt[axis=y]"
      },
      {
        "char": "Z",
        "block": "minecraft:stone_brick_wall[east=tall,north=tall,south=none,up=true,waterlogged=false,weathering=false,west=tall]"
      },
      {
        "char": "G",
        "block": "minecraft:iron_bars[east=false,north=false,south=true,waterlogged=false,west=false]"
      },
      {
        "char": "H",
        "block": "minecraft:quartz_stairs[facing=south,half=bottom,shape=straight,waterlogged=false]"
      },
      {
        "char": "ϕ",
        "block": "minecraft:quartz_stairs[facing=north,half=bottom,shape=straight,waterlogged=false]"
      },
      {
        "char": "O",
        "block": "minecraft:quartz_stairs[facing=west,half=bottom,shape=straight,waterlogged=false]"
      },
      {
        "char": "ϓ",
        "block": "minecraft:air"
      },
      {
        "char": "x",
        "block": "minecraft:cauldron"
      },
      {
        "char": "v",
        "block": "minecraft:quartz_pillar[axis=x]"
      },
      {
        "char": "n",
        "block": "minecraft:smooth_quartz"
      },
      {
        "char": "Ѳ",
        "block": "minecraft:white_stained_glass_pane[east=true,north=false,south=false,waterlogged=false,west=false]"
      },
      {
        "char": "N",
        "block": "minecraft:white_stained_glass_pane[east=true,north=false,south=false,waterlogged=false,west=true]"
      },
      {
        "char": "k",
        "block": "minecraft:oak_leaves[distance=7,persistent=true,waterlogged=false]"
      },
      {
        "char": "o",
        "block": "minecraft:chiseled_quartz_block"
      },
      {
        "char": "j",
        "block": "minecraft:polished_andesite_slab[type=top,waterlogged=false]"
      }
    ]
  },
  "slices": [
    [
      "dcbdddaeabddbeaa",
      "ebceeadedbbddddd",
      "accaceecaaaecbbc",
      "abbdeabecccabbcc",
      "eeacaeaaebaccaee",
      "cbeecbeddbdebdbd",
      "caeedababdabbeca",
      "abaeaebbabbcedea",
      "dbcccacdbceeebad",
      "eacecbebedcbcabd",
      "deeebcabbaabcbaa",
      "acdcbcaeceddddbb",
      "ZZZaZZZddbddccde",
      "   e   becbdbbbe",
      "   a   bcebacdad",
      " G b G cbaeceaab"
    ],
    [
      " c      e  H    ",
      " b             ϕ",
      " c            Oϓ",
      " d      c      H",
      "cedceaebe       ",
      " c  x  e        ",
      "       c        ",
      "             eeb",
      "             c  ",
      "             d  ",
      "       d     a  ",
      "   a   d        ",
      "vvnavvvd        ",
      "   d   c     c  ",
      "   a   de   cbea",
      " G a G d     d  "
    ],
    [
      " d      a       ",
      " e              ",
      " a              ",
      " a      e       ",
      "dcb ѲNaab       ",
      " b  k  a        ",
      "       e        ",
      "             bba",
      "             c  ",
      "             c  ",
      "       d     a  ",
      "   e   c        ",
      "vvvevooa        ",
      "   b   a     a  ",
      "   a   da   dbee",
      " G b G c     d  "
    ],
    [
      " c      d       ",
      " a              ",
      " c              ",
      " e      c       ",
      "ade ѲNebc       ",
      " a  k  a        ",
      "       e        ",
      "             ebb",
      "             b  ",
      "             e  ",
      "       e     a  ",
      "   e   d        ",
      "vvvbvvvc        ",
      "   d   d     d  ",
      "   e   cc   ddcd",
      " G d G b     b  "
    ],
    [
      " b      e       ",
      " a      j       ",
      " e      j       ",
      " e      a       ",
      "ccacadcad       ",
      " e     b        ",
      "       c        ",
      "       j     bce",
      "       j     a  ",
      "       j     b  ",
      "       e     b  ",
      "jjjejjjc     j  ",
      "vvvcvova     j  ",
      "   e   d     c  ",
      "   e   cajjjcbdc",
      " G c G b     c  "
    ],
    [
      " b      a       ",
      " e      d       ",
      " d      e       ",
      " a      b       ",
      "dcbcbaaad       ",
      " b     d        ",
      "       b        ",
      "       d     cee",
      "       b     e  ",
      "       c     b  ",
      "       b     a  ",
      "eadabadb     c  ",
      "   a   b     d  ",
      "   a   b     e  ",
      "   d   dbbbacbec",
      " G e G a     b  "
    ]
  ]
}