{
  "xsize": 16,
  "zsize": 16,
  "palette": {
    "palette": [
      {
        "char": " ",
        "block": "minecraft:air"
      },
      {
        "char": "g",
        "block": "minecraft:gray_concrete"
      },
      {
        "char": "a",
        "block": "minecraft:cyan_terracotta"
      },
      {
        "char": "e",
        "block": "minecraft:basalt[axis=y]"
      },
      {
        "char": "b",
        "block": "minecraft:blackstone"
      },
      {
        "char": "d",
        "block": "minecraft:cobbled_deepslate"
      },
      {
        "char": "c",
        "block": "minecraft:deepslate[axis=y]"
      },
      {
        "char": "i",
        "block": "minecraft:light_gray_concrete"
      },
      {
        "char": "f",
        "block": "minecraft:glass"
      },
      {
        "char": "O",
        "block": "minecraft:quartz_stairs[facing=west,half=bottom,shape=straight,waterlogged=false]"
      },
      {
        "char": "s",
        "block": "minecraft:iron_trapdoor[facing=north,half=bottom,open=false,powered=false,waterlogged=false]"
      },
      {
        "char": "m",
        "block": "minecraft:iron_trapdoor[facing=west,half=bottom,open=false,powered=false,waterlogged=false]"
      },
      {
        "char": "Ѫ",
        "block": "minecraft:air"
      },
      {
        "char": "p",
        "block": "minecraft:iron_trapdoor[facing=north,half=top,open=false,powered=false,waterlogged=false]"
      },
      {
        "char": "q",
        "block": "minecraft:iron_trapdoor[facing=west,half=top,open=false,powered=false,waterlogged=false]"
      },
      {
        "char": "学",
        "block": "minecraft:air"
      }
    ]
  },
  "slices": [
    [
      "             gaa",
      "             aea",
      "            aaab",
      "            gegb",
      "           aaabd",
      "           adaae",
      "          adgbdc",
      "          acaadc",
      "          gbaacc",
      "          gaadcb",
      "         abgaccc",
      "         aeiedae",
      "         acaccee",
      "         gcaacee",
      "         ababbda",
      "         acgbdee"
    ],
    [
      "             i  ",
      "              bf",
      "              f ",
      "              f ",
      "             f  ",
      "                ",
      "            f   ",
      "          adg  d",
      "              Oe",
      "               b",
      "           f    ",
      "           f   d",
      "           f  Oe",
      "           f   a",
      "         ieaeabb",
      "           f    "
    ],
    [
      "             a s",
      "              ef",
      "             s  ",
      "             mf ",
      "            m   ",
      "            mf  ",
      "           mf   ",
      "          aei   ",
      "           mf  Ѫ",
      "           mf   ",
      "          mf    ",
      "          m     ",
      "          mf   Ѫ",
      "          mf    ",
      "         abacabd",
      "          m     "
    ],
    [
      "             a p",
      "              af",
      "             q  ",
      "             qf ",
      "            qf  ",
      "            学f  ",
      "           qf   ",
      "          aea   ",
      "           学    ",
      "           qf   ",
      "          q     ",
      "          qf    ",
      "          qf    ",
      "          q     ",
      "         abiedca",
      "          qf    "
    ],
    [
      "             i  ",
      "              bf",
      "              f ",
      "                ",
      "                ",
      "             f  ",
      "                ",
      "          gcg   ",
      "                ",
      "            f   ",
      "           f    ",
      "           f    ",
      "           f    ",
      "           f    ",
      "         adabdce",
      "           f    "
    ],
    [
      "             a a",
      "              ea",
      "             ea ",
      "             ea ",
      "            ca  ",
      "            di  ",
      "           aa   ",
      "          ada   ",
      "           aa   ",
      "           ba   ",
      "          cg    ",
      "          ba    ",
      "          ea    ",
      "          da    ",
      "         icaeced",
      "          ba    "
    ]
  ]
}