{
  "xsize": 16,
  "zsize": 16,
  "palette": {
    "palette": [
      {
        "char": " ",
        "block": "minecraft:air"
      },
      {
        "char": "b",
        "block": "minecraft:blackstone"
      },
      {
        "char": "d",
        "block": "minecraft:cobbled_deepslate"
      },
      {
        "char": "a",
        "block": "minecraft:cyan_terracotta"
      },
      {
        "char": "i",
        "block": "minecraft:light_gray_concrete"
      },
      {
        "char": "e",
        "block": "minecraft:basalt[axis=y]"
      },
      {
        "char": "c",
        "block": "minecraft:deepslate[axis=y]"
      },
      {
        "char": "g",
        "block": "minecraft:gray_concrete"
      },
      {
        "char": "f",
        "block": "minecraft:glass"
      },
      {
        "char": "ϔ",
        "block": "minecraft:quartz_stairs[facing=east,half=bottom,shape=straight,waterlogged=false]"
      },
      {
        "char": "П",
        "block": "minecraft:barrel[facing=up,open=false]",
        "tag": {
          "z": -275,
          "x": -15,
          "ForgeData": {
            "LockFlag": "1b"
          },
          "id": "minecraft:barrel",
          "y": 2,
          "Items": []
        }
      },
      {
        "char": "s",
        "block": "minecraft:iron_trapdoor[facing=north,half=bottom,open=false,powered=false,waterlogged=false]"
      },
      {
        "char": "l",
        "block": "minecraft:iron_trapdoor[facing=east,half=bottom,open=false,powered=false,waterlogged=false]"
      },
      {
        "char": "信",
        "block": "minecraft:air"
      },
      {
        "char": "下",
        "block": "minecraft:air"
      },
      {
        "char": "p",
        "block": "minecraft:iron_trapdoor[facing=north,half=top,open=false,powered=false,waterlogged=false]"
      },
      {
        "char": "t",
        "block": "minecraft:iron_trapdoor[facing=east,half=top,open=false,powered=false,waterlogged=false]"
      }
    ]
  },
  "slices": [
    [
      "bdadai          ",
      "abeaea          ",
      "aadaadi         ",
      "bebdada         ",
      "eeccdaca        ",
      "bebaaadg        ",
      "abcdcdada       ",
      "beebeaabg       ",
      "aceedeaba       ",
      "dadceaaca       ",
      "adededeaci      ",
      "babececaag      ",
      "cceeceaadi      ",
      "aaddddcabg      ",
      "ededeeagaa      ",
      "aacbabbaea      "
    ],
    [
      "  f  a          ",
      "   fe           ",
      "ϔ   f           ",
      "    f           ",
      "     f          ",
      "     f          ",
      "      f         ",
      "dddaceaea       ",
      "                ",
      "      f         ",
      " Пce   f        ",
      " d     f        ",
      " b ϔ   f        ",
      " b     f        ",
      "eabdadaadi      ",
      "c               "
    ],
    [
      "  fs a          ",
      "   fa           ",
      "     l          ",
      "    fl          ",
      "     fl         ",
      "     fl         ",
      "       l        ",
      "bbeeecada       ",
      "       l        ",
      "       l        ",
      "       fl       ",
      " 信     fl       ",
      " 下     fl       ",
      "       fl       ",
      "accceacaba      ",
      "信      fl       "
    ],
    [
      "  fp a          ",
      "   fe           ",
      "    ft          ",
      "     t          ",
      "     ft         ",
      "     ft         ",
      "      ft        ",
      "bbaccaaea       ",
      "       t        ",
      "      ft        ",
      "        t       ",
      "       ft       ",
      "       ft       ",
      "       ft       ",
      "eebbeaaabi      ",
      "       ft       "
    ],
    [
      "  f  i          ",
      "   fb           ",
      "    f           ",
      "    f           ",
      "     f          ",
      "                ",
      "      f         ",
      "ddaedcabg       ",
      "      f         ",
      "      f         ",
      "       f        ",
      "       f        ",
      "       f        ",
      "       f        ",
      "aadaadcaaa      ",
      "                "
    ],
    [
      "  ae a          ",
      "   ad           ",
      "    ad          ",
      "    gd          ",
      "     id         ",
      "     ia         ",
      "      ae        ",
      "aaedbcaaa       ",
      "      ac        ",
      "      gb        ",
      "       id       ",
      "       gc       ",
      "       ad       ",
      "       gc       ",
      "ccaadedgag      ",
      "       ab       "
    ]
  ]
}