{
  "xsize": 16,
  "zsize": 16,
  "palette": {
    "palette": [
      {
        "char": " ",
        "block": "minecraft:air"
      },
      {
        "char": "g",
        "block": "minecraft:gray_concrete"
      },
      {
        "char": "d",
        "block": "minecraft:cobbled_deepslate"
      },
      {
        "char": "e",
        "block": "minecraft:basalt[axis=y]"
      },
      {
        "char": "b",
        "block": "minecraft:blackstone"
      },
      {
        "char": "a",
        "block": "minecraft:cyan_terracotta"
      },
      {
        "char": "c",
        "block": "minecraft:deepslate[axis=y]"
      },
      {
        "char": "i",
        "block": "minecraft:light_gray_concrete"
      },
      {
        "char": "f",
        "block": "minecraft:glass"
      },
      {
        "char": "ϕ",
        "block": "minecraft:quartz_stairs[facing=north,half=bottom,shape=straight,waterlogged=false]"
      },
      {
        "char": "x",
        "block": "minecraft:cauldron"
      },
      {
        "char": "s",
        "block": "minecraft:iron_trapdoor[facing=north,half=bottom,open=false,powered=false,waterlogged=false]"
      },
      {
        "char": "Ҝ",
        "block": "minecraft:air",
        "tag": {
          "z": -292,
          "x": -29,
          "id": "refurbished_furniture:computer",
          "y": 63,
          "NodePos": "-7696582590401L",
          "Connections": [
            "L"
          ]
        }
      },
      {
        "char": "k",
        "block": "minecraft:oak_leaves[distance=7,persistent=true,waterlogged=false]"
      },
      {
        "char": "p",
        "block": "minecraft:iron_trapdoor[facing=north,half=top,open=false,powered=false,waterlogged=false]"
      },
      {
        "char": "I",
        "block": "minecraft:stone_slab[type=top,waterlogged=false,weathering=false]"
      }
    ]
  },
  "slices": [
    [
      "                ",
      "                ",
      "                ",
      "                ",
      "                ",
      "                ",
      " g              ",
      "dedbde  a       ",
      "gagagaedaa      ",
      "ddcdddgagi      ",
      "acbcdadebg      ",
      "ceeaaebcba      ",
      "ebabddbddi      ",
      "cedabdcada      ",
      "abbbabbaea      ",
      "debdbcaaaaa     "
    ],
    [
      "                ",
      "                ",
      "                ",
      "                ",
      "                ",
      "                ",
      " i              ",
      " d      i       ",
      "faffff  aa      ",
      " d     fa       ",
      " b ϕ    e       ",
      " b      e       ",
      "ccbbe  xb       ",
      " d      d       ",
      " a      e       ",
      "ced  ebbb i     "
    ],
    [
      "                ",
      "                ",
      "                ",
      "                ",
      "                ",
      "                ",
      " g              ",
      "sbssss  g       ",
      "faff  ssai      ",
      " e    f a       ",
      " b      a       ",
      " c      c       ",
      " e Ҝ   ke       ",
      " d      c       ",
      " b      a       ",
      "dba  dedd i     "
    ],
    [
      "                ",
      "                ",
      "                ",
      "                ",
      "                ",
      "                ",
      " g              ",
      "papppp  a       ",
      "fa fffppaa      ",
      " e    ffa       ",
      " b      a       ",
      " e      a       ",
      " a     ka       ",
      " a      e       ",
      " e      b       ",
      "baa  eada i     "
    ],
    [
      "                ",
      "                ",
      "                ",
      "                ",
      "                ",
      "                ",
      " i              ",
      " a      a       ",
      "faffff  aa      ",
      " b    ffg       ",
      " e      a       ",
      " e      c       ",
      " e      a       ",
      " c      c       ",
      " c      c       ",
      "bbcIIcdbc a     "
    ],
    [
      "                ",
      "                ",
      "                ",
      "                ",
      "                ",
      "                ",
      " i              ",
      "cbacbc  a       ",
      "aaaagadbga      ",
      " b    aia       ",
      " b      d       ",
      " b      e       ",
      " c      e       ",
      " d      d       ",
      " a      d       ",
      "cabcadecb a     "
    ]
  ]
}