{
  "xsize": 16,
  "zsize": 16,
  "palette": {
    "palette": [
      {
        "char": " ",
        "block": "minecraft:air"
      },
      {
        "char": "a",
        "block": "minecraft:cyan_terracotta"
      },
      {
        "char": "c",
        "block": "minecraft:deepslate[axis=y]"
      },
      {
        "char": "e",
        "block": "minecraft:basalt[axis=y]"
      },
      {
        "char": "b",
        "block": "minecraft:blackstone"
      },
      {
        "char": "d",
        "block": "minecraft:cobbled_deepslate"
      },
      {
        "char": "g",
        "block": "minecraft:gray_concrete"
      },
      {
        "char": "i",
        "block": "minecraft:light_gray_concrete"
      },
      {
        "char": "H",
        "block": "minecraft:quartz_stairs[facing=south,half=bottom,shape=straight,waterlogged=false]"
      },
      {
        "char": "f",
        "block": "minecraft:glass"
      },
      {
        "char": "u",
        "block": "minecraft:iron_trapdoor[facing=south,half=bottom,open=false,powered=false,waterlogged=false]"
      },
      {
        "char": "ϐ",
        "block": "minecraft:air",
        "tag": {
          "z": -259,
          "x": -34,
          "id": "refurbished_furniture:computer",
          "y": -21,
          "NodePos": "-9070971985941L",
          "Connections": [
            "L"
          ]
        }
      },
      {
        "char": "w",
        "block": "minecraft:iron_trapdoor[facing=south,half=top,open=false,powered=false,waterlogged=false]"
      },
      {
        "char": "q",
        "block": "minecraft:iron_trapdoor[facing=west,half=top,open=false,powered=false,waterlogged=false]"
      }
    ]
  },
  "slices": [
    [
      " aceabdcaeebddcc",
      "  aacgidcadeccad",
      "   agecaicebdccb",
      "     aaabgaaacba",
      "       aacbeeaaa",
      "         aagaaeb",
      "             aai",
      "                ",
      "  b      c      ",
      "                ",
      "                ",
      "                ",
      "                ",
      "                ",
      "                ",
      "                "
    ],
    [
      "         dce dbd",
      "    a     H   H ",
      "   a   ff       ",
      "         fa f   ",
      "          a  f f",
      "          a     ",
      "                ",
      "                ",
      "  c      c      ",
      "                ",
      "                ",
      "                ",
      "                ",
      "                ",
      "                ",
      "                "
    ],
    [
      "  uuf     ϐ   ϐ ",
      "    e f         ",
      "   a uuff       ",
      "       uufg     ",
      "         ucuufff",
      "          a  uuu",
      "                ",
      "                ",
      "  d      d      ",
      "                ",
      "                ",
      "                ",
      "                ",
      "                ",
      "                ",
      "                "
    ],
    [
      "  wqf           ",
      "    bff         ",
      "   a wwf        ",
      "       wwfaff   ",
      "         wbwwff ",
      "          i  www",
      "                ",
      "                ",
      "  c      d      ",
      "                ",
      "                ",
      "                ",
      "                ",
      "                ",
      "                ",
      "                "
    ],
    [
      "                ",
      "    dff         ",
      "   g   ff       ",
      "         faff   ",
      "          a  fff",
      "          a     ",
      "                ",
      "                ",
      "  b      d      ",
      "                ",
      "                ",
      "                ",
      "                ",
      "                ",
      "                ",
      "                "
    ],
    [
      "  dda           ",
      "    daa         ",
      "   g abaa       ",
      "       ddagaa   ",
      "         aaadiai",
      "          a  dbb",
      "                ",
      "                ",
      "  e      a      ",
      "                ",
      "                ",
      "                ",
      "                ",
      "                ",
      "                ",
      "                "
    ]
  ]
}