{
  "xsize": 16,
  "zsize": 16,
  "palette": {
    "palette": [
      {
        "char": " ",
        "block": "minecraft:air"
      },
      {
        "char": "e",
        "block": "minecraft:basalt[axis=y]"
      },
      {
        "char": "a",
        "block": "minecraft:cyan_terracotta"
      },
      {
        "char": "c",
        "block": "minecraft:deepslate[axis=y]"
      },
      {
        "char": "b",
        "block": "minecraft:blackstone"
      },
      {
        "char": "d",
        "block": "minecraft:cobbled_deepslate"
      },
      {
        "char": "你",
        "block": "minecraft:spawner",
        "tag": {
          "SpawnData": {
            "entity": {}
          },
          "MaxNearbyEntities": "6s",
          "MinSpawnDelay": "200s",
          "z": -274,
          "x": -42,
          "MaxSpawnDelay": "800s",
          "RequiredPlayerRange": "16s",
          "SpawnCount": "4s",
          "id": "minecraft:mob_spawner",
          "SpawnPotentials": [],
          "y": 1,
          "SpawnRange": "4s",
          "Delay": "731s"
        }
      },
      {
        "char": "Z",
        "block": "minecraft:stone_brick_wall[east=tall,north=tall,south=none,up=true,waterlogged=false,weathering=false,west=tall]"
      },
      {
        "char": "Ӿ",
        "block": "minecraft:cobblestone_wall[east=tall,north=tall,south=none,up=true,waterlogged=false,weathering=false,west=tall]"
      },
      {
        "char": "G",
        "block": "minecraft:iron_bars[east=false,north=false,south=true,waterlogged=false,west=false]"
      },
      {
        "char": "H",
        "block": "minecraft:quartz_stairs[facing=south,half=bottom,shape=straight,waterlogged=false]"
      },
      {
        "char": "O",
        "block": "minecraft:quartz_stairs[facing=west,half=bottom,shape=straight,waterlogged=false]"
      },
      {
        "char": "ϓ",
        "block": "minecraft:air"
      },
      {
        "char": "x",
        "block": "minecraft:cauldron"
      },
      {
        "char": "v",
        "block": "minecraft:quartz_pillar[axis=x]"
      },
      {
        "char": "K",
        "block": "minecraft:quartz_block"
      },
      {
        "char": "J",
        "block": "minecraft:diorite"
      },
      {
        "char": "C",
        "block": "minecraft:quartz_pillar[axis=y]"
      },
      {
        "char": "N",
        "block": "minecraft:white_stained_glass_pane[east=true,north=false,south=false,waterlogged=false,west=true]"
      },
      {
        "char": "k",
        "block": "minecraft:oak_leaves[distance=7,persistent=true,waterlogged=false]"
      },
      {
        "char": "n",
        "block": "minecraft:smooth_quartz"
      },
      {
        "char": "Ѵ",
        "block": "minecraft:white_stained_glass_pane[east=false,north=false,south=false,waterlogged=false,west=true]"
      },
      {
        "char": "Ѳ",
        "block": "minecraft:white_stained_glass_pane[east=true,north=false,south=false,waterlogged=false,west=false]"
      },
      {
        "char": "j",
        "block": "minecraft:polished_andesite_slab[type=top,waterlogged=false]"
      },
      {
        "char": "o",
        "block": "minecraft:chiseled_quartz_block"
      }
    ]
  },
  "slices": [
    [
      "eeacbabecbbeecbb",
      "dddeccacbbaaeaee",
      "eecbacbcdadccbee",
      "bbecebcaeaaddaaa",
      "bebedecdeacbcbda",
      "cccebbcdecbcbcdb",
      "cbbceecdcbdbbbca",
      "eedaeeeecceccbee",
      "dabddababeaeaaab",
      "ededeeaebeeaacbd",
      "cdaddbbaceabddac",
      "dee你eccaeeebaaba",
      "ZӾZbZӾZbecccceae",
      "   b   dcbdbcdde",
      "   e   dceadbabc",
      " G b G caebdbade"
    ],
    [
      " e      b  H  be",
      " d             b",
      " c            Oϓ",
      " b      e      H",
      "ccddcdedb       ",
      " c  x  b        ",
      "       c        ",
      "             ebb",
      "             d  ",
      "             d  ",
      "       a     a  ",
      "   a   e        ",
      "vvKbJCvc        ",
      "   c   c     e  ",
      "   d   ad   dbbd",
      " G b G d     c  "
    ],
    [
      " b      b      a",
      " a              ",
      " d              ",
      " a      a       ",
      "eeaNNNcec       ",
      " b  k  b        ",
      "       c        ",
      "             bcb",
      "             c  ",
      "             b  ",
      "       c     c  ",
      "   d   c        ",
      "vnvaKvva        ",
      "   a   b     c  ",
      "   a   db   bbdd",
      " G c G b     e  "
    ],
    [
      " b      a       ",
      " a              ",
      " b              ",
      " c      d       ",
      "debѴ Ѳacb       ",
      " d  k  a        ",
      "       a        ",
      "             dbb",
      "             d  ",
      "             d  ",
      "       d     c  ",
      "   b   c        ",
      "vvvevvKd        ",
      "   b   b     a  ",
      "   a   be   ecac",
      " G d G e     b  "
    ],
    [
      " a      a       ",
      " d      j       ",
      " a      j       ",
      " b      a       ",
      "eacebecdc       ",
      " b     a        ",
      "       a        ",
      "       j     edd",
      "       j     e  ",
      "       j     c  ",
      "       d     d  ",
      "jjjajjjc     j  ",
      "novevvva     j  ",
      "   c   a     d  ",
      "   b   ecjjjcecb",
      " G e G a     c  "
    ],
    [
      " a      a       ",
      " c      d       ",
      " d      b       ",
      " d      e       ",
      "dedebcdca       ",
      " d     b        ",
      "       d        ",
      "       d     cca",
      "       a     e  ",
      "       d     c  ",
      "       a     b  ",
      "ebcdeded     c  ",
      "   d   d     b  ",
      "   e   b     d  ",
      "   c   dcbcceabc",
      " G a G b     a  "
    ]
  ]
}