{
  "xsize": 16,
  "zsize": 16,
  "palette": {
    "palette": [
      {
        "char": " ",
        "block": "minecraft:air"
      },
      {
        "char": "i",
        "block": "minecraft:light_gray_concrete"
      },
      {
        "char": "b",
        "block": "minecraft:blackstone"
      },
      {
        "char": "a",
        "block": "minecraft:cyan_terracotta"
      },
      {
        "char": "c",
        "block": "minecraft:deepslate[axis=y]"
      },
      {
        "char": "d",
        "block": "minecraft:cobbled_deepslate"
      },
      {
        "char": "e",
        "block": "minecraft:basalt[axis=y]"
      },
      {
        "char": "Р",
        "block": "minecraft:stone_brick_stairs[facing=north,half=bottom,shape=straight,waterlogged=false,weathering=false]"
      },
      {
        "char": "z",
        "block": "minecraft:iron_bars[east=false,north=true,south=true,waterlogged=false,west=false]"
      },
      {
        "char": "Y",
        "block": "minecraft:iron_bars[east=false,north=true,south=false,waterlogged=false,west=false]"
      },
      {
        "char": "f",
        "block": "minecraft:glass"
      },
      {
        "char": "O",
        "block": "minecraft:quartz_stairs[facing=west,half=bottom,shape=straight,waterlogged=false]"
      },
      {
        "char": "П",
        "block": "minecraft:barrel[facing=up,open=false]",
        "tag": {
          "z": -275,
          "x": -15,
          "ForgeData": {
            "LockFlag": "1b"
          },
          "id": "minecraft:barrel",
          "y": 2,
          "Items": []
        }
      },
      {
        "char": "x",
        "block": "minecraft:cauldron"
      },
      {
        "char": "У",
        "block": "minecraft:stone_brick_stairs[facing=south,half=bottom,shape=straight,waterlogged=false,weathering=false]"
      },
      {
        "char": "С",
        "block": "minecraft:stone_brick_stairs[facing=north,half=top,shape=straight,waterlogged=false,weathering=false]"
      },
      {
        "char": "Ѫ",
        "block": "minecraft:air"
      },
      {
        "char": "Ӝ",
        "block": "minecraft:air"
      },
      {
        "char": "N",
        "block": "minecraft:white_stained_glass_pane[east=true,north=false,south=false,waterlogged=false,west=true]"
      },
      {
        "char": "k",
        "block": "minecraft:oak_leaves[distance=7,persistent=true,waterlogged=false]"
      },
      {
        "char": "у",
        "block": "minecraft:stone_brick_stairs[facing=south,half=top,shape=straight,waterlogged=false,weathering=false]"
      },
      {
        "char": "没",
        "block": "minecraft:air"
      },
      {
        "char": "j",
        "block": "minecraft:polished_andesite_slab[type=top,waterlogged=false]"
      }
    ]
  },
  "slices": [
    [
      "ibacdabeddbabcca",
      "dcededbdebbbacec",
      "abecedceedeeacca",
      "ecaacbccaaabeace",
      "eadacbccddbcabed",
      "ebeedcaaeddbdcdd",
      "ceeccadedcedeceb",
      "aabaddbabaabcade",
      "aabbcccedbbbbdae",
      "dbadeeaaaddcaeec",
      "baaaaccabacdebde",
      "dadeebedabeacbca",
      "eaceddeebdabРz c",
      "baeedeeaceae z e",
      "cddbadbcceaa Y c",
      "cebdcebeceec   e"
    ],
    [
      "f   Oa    a     ",
      "     b          ",
      "                ",
      "  c  b    a     ",
      " Ob Oa    cedaea",
      "  П  a     e  x ",
      "           d    ",
      "  c  e          ",
      " Od Oe          ",
      "  c  d          ",
      "           a    ",
      "  d  d     d b c",
      " Oc Od     d zУe",
      "  c  c     c zСb",
      "bcadccd   ae Y e",
      "  d  e     b   e"
    ],
    [
      "f    Ѫ    a     ",
      "     Ӝ          ",
      "                ",
      "  Ӝ       a     ",
      "  Ѫ  Ѫ    cecNNN",
      "     Ӝ     b  k ",
      "           e    ",
      "                ",
      "  Ѫ  Ѫ          ",
      "  Ӝ  Ӝ          ",
      "           a    ",
      "           c a a",
      "  Ѫ  Ѫ     c z b",
      "  Ӝ  Ӝ     c zУd",
      "bbdcaad   bb YСb",
      "     c     a   a"
    ],
    [
      "          d     ",
      "                ",
      "                ",
      "          d     ",
      "          bccNNN",
      "           c  k ",
      "           a    ",
      "                ",
      "                ",
      "                ",
      "           e    ",
      "           a a d",
      "           b z b",
      "           e z e",
      "eaceadd   eaуz没d",
      "     c     cedbe"
    ],
    [
      "f         a     ",
      "          j     ",
      "          j     ",
      "          c     ",
      "          aaddbe",
      "           c    ",
      "           c    ",
      "           j    ",
      "           j    ",
      "           j    ",
      "           a    ",
      "           eecde",
      "           a z a",
      "           dуz e",
      "eedddabjjjacРY a",
      "     a     b   b"
    ],
    [
      "a         e     ",
      "          e     ",
      "          b     ",
      "          d     ",
      "          ebdece",
      "           e    ",
      "           a    ",
      "           b    ",
      "           d    ",
      "           d    ",
      "           a    ",
      "           cdecb",
      "           dуz e",
      "           eРz d",
      "eedbbebeabaa Y a",
      "     c     a   a"
    ]
  ]
}