{
  "xsize": 16,
  "zsize": 16,
  "palette": {
    "palette": [
      {
        "char": " ",
        "block": "minecraft:air"
      },
      {
        "char": "a",
        "block": "minecraft:cyan_terracotta"
      },
      {
        "char": "g",
        "block": "minecraft:gray_concrete"
      },
      {
        "char": "b",
        "block": "minecraft:blackstone"
      },
      {
        "char": "e",
        "block": "minecraft:basalt[axis=y]"
      },
      {
        "char": "c",
        "block": "minecraft:deepslate[axis=y]"
      },
      {
        "char": "d",
        "block": "minecraft:cobbled_deepslate"
      },
      {
        "char": "ӟ",
        "block": "minecraft:iron_bars[east=true,north=false,south=true,waterlogged=false,west=true]"
      },
      {
        "char": "ѹ",
        "block": "minecraft:iron_bars[east=true,north=false,south=false,waterlogged=false,west=true]"
      },
      {
        "char": "o",
        "block": "minecraft:chiseled_quartz_block"
      },
      {
        "char": "n",
        "block": "minecraft:smooth_quartz"
      },
      {
        "char": "r",
        "block": "minecraft:polished_diorite"
      },
      {
        "char": "C",
        "block": "minecraft:quartz_pillar[axis=y]"
      },
      {
        "char": "i",
        "block": "minecraft:light_gray_concrete"
      },
      {
        "char": "了",
        "block": "minecraft:air"
      },
      {
        "char": "m",
        "block": "minecraft:iron_trapdoor[facing=west,half=bottom,open=false,powered=false,waterlogged=false]"
      },
      {
        "char": "无",
        "block": "minecraft:stone_brick_stairs[facing=east,half=top,shape=straight,waterlogged=false,weathering=false]"
      },
      {
        "char": "关",
        "block": "minecraft:stone_stairs[facing=west,half=top,shape=straight,waterlogged=false,weathering=false]"
      }
    ]
  },
  "slices": [
    [
      "                ",
      "                ",
      "                ",
      "                ",
      "                ",
      "a               ",
      "aagaagga        ",
      "beccceaaa       ",
      "daeebdae        ",
      "aebbceae        ",
      "eeccdcdab       ",
      "abbbabaga       ",
      "abcbecbge       ",
      "ceebabead       ",
      "babddeaada      ",
      "ebaeccdae       "
    ],
    [
      "                ",
      "                ",
      "                ",
      "                ",
      "                ",
      "a               ",
      "       a        ",
      "ӟѹѹѹѹѹaag       ",
      "e      o        ",
      "a      n        ",
      "ce      o       ",
      "ac      r       ",
      "bb e    C       ",
      "ac      C       ",
      "ec a   aii      ",
      "了了      C       "
    ],
    [
      "                ",
      "                ",
      "                ",
      "                ",
      "                ",
      "a               ",
      "                ",
      "      aaa       ",
      "e      m        ",
      "c      了        ",
      "bb      m       ",
      "bc      m       ",
      "dd a    m       ",
      "de      m       ",
      "ba c   aaa      ",
      "        m       "
    ],
    [
      "                ",
      "                ",
      "                ",
      "                ",
      "                ",
      "a               ",
      "                ",
      "       aa       ",
      "e               ",
      "e               ",
      "ed              ",
      "ba              ",
      "ce d            ",
      "cd              ",
      "bb e    ga      ",
      "无关              "
    ],
    [
      "                ",
      "                ",
      "                ",
      "                ",
      "                ",
      "a               ",
      "                ",
      "                ",
      "e               ",
      "b               ",
      "db              ",
      "dd              ",
      "bb b            ",
      "ce              ",
      "cc c            ",
      "ec              "
    ],
    [
      "                ",
      "                ",
      "                ",
      "                ",
      "                ",
      "a               ",
      "                ",
      "                ",
      "b               ",
      "a               ",
      "ca              ",
      "eb              ",
      "bd b            ",
      "ee              ",
      "bb a            ",
      "ae              "
    ]
  ]
}