{
  "xsize": 16,
  "zsize": 16,
  "palette": {
    "palette": [
      {
        "char": " ",
        "block": "minecraft:air"
      },
      {
        "char": "a",
        "block": "minecraft:cyan_terracotta"
      },
      {
        "char": "d",
        "block": "minecraft:cobbled_deepslate"
      },
      {
        "char": "b",
        "block": "minecraft:blackstone"
      },
      {
        "char": "c",
        "block": "minecraft:deepslate[axis=y]"
      },
      {
        "char": "e",
        "block": "minecraft:basalt[axis=y]"
      },
      {
        "char": "g",
        "block": "minecraft:gray_concrete"
      },
      {
        "char": "i",
        "block": "minecraft:light_gray_concrete"
      },
      {
        "char": "f",
        "block": "minecraft:glass"
      },
      {
        "char": "o",
        "block": "minecraft:chiseled_quartz_block"
      },
      {
        "char": "C",
        "block": "minecraft:quartz_pillar[axis=y]"
      },
      {
        "char": "n",
        "block": "minecraft:smooth_quartz"
      },
      {
        "char": "ϕ",
        "block": "minecraft:quartz_stairs[facing=north,half=bottom,shape=straight,waterlogged=false]"
      },
      {
        "char": "x",
        "block": "minecraft:cauldron"
      },
      {
        "char": "s",
        "block": "minecraft:iron_trapdoor[facing=north,half=bottom,open=false,powered=false,waterlogged=false]"
      },
      {
        "char": "u",
        "block": "minecraft:iron_trapdoor[facing=south,half=bottom,open=false,powered=false,waterlogged=false]"
      },
      {
        "char": "Ҝ",
        "block": "minecraft:air",
        "tag": {
          "z": -292,
          "x": -29,
          "id": "refurbished_furniture:computer",
          "y": 63,
          "NodePos": "-7696582590401L",
          "Connections": [
            "L"
          ]
        }
      },
      {
        "char": "k",
        "block": "minecraft:oak_leaves[distance=7,persistent=true,waterlogged=false]"
      },
      {
        "char": "p",
        "block": "minecraft:iron_trapdoor[facing=north,half=top,open=false,powered=false,waterlogged=false]"
      },
      {
        "char": "I",
        "block": "minecraft:stone_slab[type=top,waterlogged=false,weathering=false]"
      }
    ]
  },
  "slices": [
    [
      "                ",
      "                ",
      "                ",
      "                ",
      "                ",
      "                ",
      " a              ",
      "dbbcea  g       ",
      "gaaaaacdec      ",
      "ebeaadaaaaec    ",
      "edebacbabbaaeb i",
      "ddaaeecdbadbage ",
      "adcedbebcedaddab",
      "edcdebbeebbcabci",
      "bbdacadabbaccdec",
      "acccbeaeabeedbbd"
    ],
    [
      "                ",
      "                ",
      "                ",
      "                ",
      "                ",
      "                ",
      " a              ",
      " c      g       ",
      " g ff   ao      ",
      " b    ffa Cn    ",
      " e ϕ    c   Co a",
      " b      a     C ",
      "eddce  xc    g C",
      " d      c       ",
      " a      b       ",
      "cbb  eaad i     "
    ],
    [
      "                ",
      "                ",
      "                ",
      "                ",
      "                ",
      "                ",
      " g              ",
      "sessss  a       ",
      " gf ffssga      ",
      " c    ffg uu    ",
      " d      a   uu a",
      " e      b     i ",
      " d Ҝ   ka    a u",
      " d      d       ",
      " d      d       ",
      "eba  bdbd g     "
    ],
    [
      "                ",
      "                ",
      "                ",
      "                ",
      "                ",
      "                ",
      " a              ",
      "pdpppp  a       ",
      "faf ffppaa      ",
      " b    ffg       ",
      " b      c      i",
      " d      a     a ",
      " e     ka    a  ",
      " c      b       ",
      " a      d       ",
      "abc  baed a     "
    ],
    [
      "                ",
      "                ",
      "                ",
      "                ",
      "                ",
      "                ",
      " g              ",
      " a      a       ",
      " affff  ia      ",
      " c    ffa       ",
      " e      e       ",
      " c      e       ",
      " a      c       ",
      " d      b       ",
      " a      a       ",
      "becIIdcbe a     "
    ],
    [
      "                ",
      "                ",
      "                ",
      "                ",
      "                ",
      "                ",
      " g              ",
      "dbdbcd  g       ",
      "agaaiadega      ",
      " c    agg       ",
      " b      b       ",
      " c      b       ",
      " b      d       ",
      " e      b       ",
      " b      e       ",
      "dcbbddbda a     "
    ]
  ]
}