{
  "xsize": 16,
  "zsize": 16,
  "palette": {
    "palette": [
      {
        "char": " ",
        "block": "minecraft:air"
      },
      {
        "char": "a",
        "block": "minecraft:cyan_terracotta"
      },
      {
        "char": "d",
        "block": "minecraft:cobbled_deepslate"
      },
      {
        "char": "g",
        "block": "minecraft:gray_concrete"
      },
      {
        "char": "c",
        "block": "minecraft:deepslate[axis=y]"
      },
      {
        "char": "e",
        "block": "minecraft:basalt[axis=y]"
      },
      {
        "char": "b",
        "block": "minecraft:blackstone"
      },
      {
        "char": "i",
        "block": "minecraft:light_gray_concrete"
      },
      {
        "char": "f",
        "block": "minecraft:glass"
      },
      {
        "char": "O",
        "block": "minecraft:quartz_stairs[facing=west,half=bottom,shape=straight,waterlogged=false]"
      },
      {
        "char": "s",
        "block": "minecraft:iron_trapdoor[facing=north,half=bottom,open=false,powered=false,waterlogged=false]"
      },
      {
        "char": "m",
        "block": "minecraft:iron_trapdoor[facing=west,half=bottom,open=false,powered=false,waterlogged=false]"
      },
      {
        "char": "了",
        "block": "minecraft:air"
      },
      {
        "char": "Ѥ",
        "block": "minecraft:air",
        "tag": {
          "z": -276,
          "x": -43,
          "id": "refurbished_furniture:computer",
          "y": -39,
          "NodePos": "-11544873218087L",
          "Connections": [
            "L"
          ]
        }
      },
      {
        "char": "p",
        "block": "minecraft:iron_trapdoor[facing=north,half=top,open=false,powered=false,waterlogged=false]"
      },
      {
        "char": "q",
        "block": "minecraft:iron_trapdoor[facing=west,half=top,open=false,powered=false,waterlogged=false]"
      }
    ]
  },
  "slices": [
    [
      "             aad",
      "             gca",
      "            aagd",
      "            aeac",
      "           gdaae",
      "           acgda",
      "          abaace",
      "          acaeda",
      "           daeae",
      "           caeae",
      "          aaaeab",
      "          aacbae",
      "          aadabb",
      "          ciaaca",
      "         acgabde",
      "          dacbea"
    ],
    [
      "             g  ",
      "              d ",
      "              f ",
      "              f ",
      "             f  ",
      "             f  ",
      "                ",
      "          acg  b",
      "            f Ob",
      "            f  b",
      "           f    ",
      "           f   b",
      "           f  Oe",
      "           f   b",
      "         gegbdda",
      "                "
    ],
    [
      "             a s",
      "              cf",
      "             s  ",
      "             mf ",
      "            mf  ",
      "            mf  ",
      "           m    ",
      "          ada   ",
      "           了f  Ѥ",
      "           mf   ",
      "          m     ",
      "          m     ",
      "          m    Ѥ",
      "          m     ",
      "         idaaacd",
      "          m     "
    ],
    [
      "             i p",
      "              cf",
      "             qf ",
      "             qf ",
      "            qf  ",
      "            qf  ",
      "           qf   ",
      "          aba   ",
      "           qf   ",
      "           q    ",
      "          qf    ",
      "          qf    ",
      "          qf    ",
      "          qf    ",
      "         gcacead",
      "          qf    "
    ],
    [
      "             a  ",
      "              af",
      "              f ",
      "              f ",
      "             f  ",
      "             f  ",
      "            f   ",
      "          aba   ",
      "            f   ",
      "            f   ",
      "                ",
      "           f    ",
      "           f    ",
      "                ",
      "         aeaaaed",
      "           f    "
    ],
    [
      "             a c",
      "              ea",
      "             ba ",
      "             da ",
      "            ba  ",
      "            ca  ",
      "           dg   ",
      "          aaa   ",
      "           bg   ",
      "           ea   ",
      "          cg    ",
      "          bi    ",
      "          ea    ",
      "          dg    ",
      "         adaebcb",
      "          ag    "
    ]
  ]
}