{
  "xsize": 16,
  "zsize": 16,
  "palette": {
    "palette": [
      {
        "char": " ",
        "block": "minecraft:air"
      },
      {
        "char": "a",
        "block": "minecraft:cyan_terracotta"
      },
      {
        "char": "c",
        "block": "minecraft:deepslate[axis=y]"
      },
      {
        "char": "d",
        "block": "minecraft:cobbled_deepslate"
      },
      {
        "char": "b",
        "block": "minecraft:blackstone"
      },
      {
        "char": "g",
        "block": "minecraft:gray_concrete"
      },
      {
        "char": "i",
        "block": "minecraft:light_gray_concrete"
      },
      {
        "char": "e",
        "block": "minecraft:basalt[axis=y]"
      },
      {
        "char": "f",
        "block": "minecraft:glass"
      },
      {
        "char": "ϕ",
        "block": "minecraft:quartz_stairs[facing=north,half=bottom,shape=straight,waterlogged=false]"
      },
      {
        "char": "O",
        "block": "minecraft:quartz_stairs[facing=west,half=bottom,shape=straight,waterlogged=false]"
      },
      {
        "char": "ϓ",
        "block": "minecraft:air"
      },
      {
        "char": "ϔ",
        "block": "minecraft:quartz_stairs[facing=east,half=bottom,shape=straight,waterlogged=false]"
      },
      {
        "char": "s",
        "block": "minecraft:iron_trapdoor[facing=north,half=bottom,open=false,powered=false,waterlogged=false]"
      },
      {
        "char": "l",
        "block": "minecraft:iron_trapdoor[facing=east,half=bottom,open=false,powered=false,waterlogged=false]"
      },
      {
        "char": "Ҝ",
        "block": "minecraft:air",
        "tag": {
          "z": -292,
          "x": -29,
          "id": "refurbished_furniture:computer",
          "y": 63,
          "NodePos": "-7696582590401L",
          "Connections": [
            "L"
          ]
        }
      },
      {
        "char": "p",
        "block": "minecraft:iron_trapdoor[facing=north,half=top,open=false,powered=false,waterlogged=false]"
      }
    ]
  },
  "slices": [
    [
      "                ",
      "                ",
      "                ",
      "                ",
      "                ",
      "                ",
      " a              ",
      "cdabab  ag      ",
      "iaagagccedii    ",
      "bccaecgaaibaga  ",
      "bdddbddbadaadcaa",
      "cdeeadcbebdeagdg",
      "bdedbeaeeadaaaab",
      "ebadddaaecccddba",
      "ccaeabeeacddbaed",
      "dcbabdeddcceacac"
    ],
    [
      "                ",
      "                ",
      "                ",
      "                ",
      "                ",
      "                ",
      " a              ",
      " b      a       ",
      "fifff   c       ",
      " b    ffaf      ",
      " e      d f    g",
      " b      b   ffd ",
      " b a ϕ  a     f ",
      " a a    a      f",
      " c ccbbdc  ϕ    ",
      " b      e Oϓϔ   "
    ],
    [
      "                ",
      "                ",
      "                ",
      "                ",
      "                ",
      "                ",
      " g              ",
      "sessss  a       ",
      "faff fsses      ",
      " e    ffa ss    ",
      " a      c ffss a",
      " c      a    fa ",
      " a      a     fl",
      " a      e      f",
      " b  Ҝ Ҝ a       ",
      " e      c       "
    ],
    [
      "                ",
      "                ",
      "                ",
      "                ",
      "                ",
      "                ",
      " i              ",
      "papppp  a       ",
      " affffppcp      ",
      " c    f afpp    ",
      " a      b f pp a",
      " a      e   f c ",
      " b      e     fp",
      " e      c      f",
      " d      a       ",
      " c      c       "
    ],
    [
      "                ",
      "                ",
      "                ",
      "                ",
      "                ",
      "                ",
      " g              ",
      " d      g       ",
      " aff f  c       ",
      " e    ffaf      ",
      " d      e ff   g",
      " b      d   ffd ",
      " c      b     f ",
      " a      c      f",
      " d      b       ",
      " e      c       "
    ],
    [
      "                ",
      "                ",
      "                ",
      "                ",
      "                ",
      "                ",
      " a              ",
      "dadded  g       ",
      "ggaaagadcc      ",
      " b    giaade    ",
      " c      e iidc g",
      " e      a   aab ",
      " d      c     ad",
      " d      b      a",
      " d      a       ",
      " c      e       "
    ]
  ]
}