{
  "xsize": 16,
  "zsize": 16,
  "palette": {
    "palette": [
      {
        "char": " ",
        "block": "minecraft:air"
      },
      {
        "char": "a",
        "block": "minecraft:cyan_terracotta"
      },
      {
        "char": "b",
        "block": "minecraft:blackstone"
      },
      {
        "char": "c",
        "block": "minecraft:deepslate[axis=y]"
      },
      {
        "char": "i",
        "block": "minecraft:light_gray_concrete"
      },
      {
        "char": "d",
        "block": "minecraft:cobbled_deepslate"
      },
      {
        "char": "g",
        "block": "minecraft:gray_concrete"
      },
      {
        "char": "e",
        "block": "minecraft:basalt[axis=y]"
      },
      {
        "char": "C",
        "block": "minecraft:quartz_pillar[axis=y]"
      },
      {
        "char": "J",
        "block": "minecraft:diorite"
      },
      {
        "char": "f",
        "block": "minecraft:glass"
      },
      {
        "char": "x",
        "block": "minecraft:cauldron"
      },
      {
        "char": "П",
        "block": "minecraft:barrel[facing=up,open=false]",
        "tag": {
          "z": -275,
          "x": -15,
          "ForgeData": {
            "LockFlag": "1b"
          },
          "id": "minecraft:barrel",
          "y": 2,
          "Items": []
        }
      },
      {
        "char": "O",
        "block": "minecraft:quartz_stairs[facing=west,half=bottom,shape=straight,waterlogged=false]"
      },
      {
        "char": "l",
        "block": "minecraft:iron_trapdoor[facing=east,half=bottom,open=false,powered=false,waterlogged=false]"
      },
      {
        "char": "m",
        "block": "minecraft:iron_trapdoor[facing=west,half=bottom,open=false,powered=false,waterlogged=false]"
      },
      {
        "char": "k",
        "block": "minecraft:oak_leaves[distance=7,persistent=true,waterlogged=false]"
      },
      {
        "char": "Ѥ",
        "block": "minecraft:air",
        "tag": {
          "z": -276,
          "x": -43,
          "id": "refurbished_furniture:computer",
          "y": -39,
          "NodePos": "-11544873218087L",
          "Connections": [
            "L"
          ]
        }
      },
      {
        "char": "q",
        "block": "minecraft:iron_trapdoor[facing=west,half=top,open=false,powered=false,waterlogged=false]"
      },
      {
        "char": "学",
        "block": "minecraft:air"
      }
    ]
  },
  "slices": [
    [
      "                ",
      "                ",
      "                ",
      "             aa ",
      "            aaba",
      "            cibc",
      "           cabdd",
      "          gdaadb",
      "           babee",
      "           eaeab",
      "          baecda",
      "          caceae",
      "          bgacbd",
      "          eaeaab",
      "         gagbcca",
      "          eadbdd"
    ],
    [
      "                ",
      "                ",
      "                ",
      "             C  ",
      "            C   ",
      "            C   ",
      "           J    ",
      "          aggbea",
      "            f  x",
      "            f   ",
      "           f    ",
      "               П",
      "           f O d",
      "           f   c",
      "         abaeded",
      "           f   d"
    ],
    [
      "                ",
      "                ",
      "                ",
      "             l  ",
      "            l   ",
      "            l   ",
      "           g    ",
      "          aggeca",
      "           m   k",
      "           m    ",
      "          m     ",
      "          mf    ",
      "          mf   Ѥ",
      "          mf    ",
      "         gaaacbd",
      "          mf    "
    ],
    [
      "                ",
      "                ",
      "                ",
      "                ",
      "                ",
      "                ",
      "           g    ",
      "          aiiabe",
      "           qf  k",
      "           学f   ",
      "          qf    ",
      "          qf    ",
      "          qf    ",
      "          qf    ",
      "         abadbba",
      "          qf    "
    ],
    [
      "                ",
      "                ",
      "                ",
      "                ",
      "                ",
      "                ",
      "           a    ",
      "          aaabad",
      "            f   ",
      "                ",
      "           f    ",
      "           f    ",
      "                ",
      "           f    ",
      "         aegcddb",
      "           f    "
    ],
    [
      "                ",
      "                ",
      "                ",
      "                ",
      "                ",
      "                ",
      "           a    ",
      "          giaaae",
      "           da   ",
      "           da   ",
      "          ba    ",
      "          cg    ",
      "          ba    ",
      "          dg    ",
      "         aeadbbd",
      "          ba    "
    ]
  ]
}