{
  "xsize": 16,
  "zsize": 16,
  "palette": {
    "palette": [
      {
        "char": " ",
        "block": "minecraft:air"
      },
      {
        "char": "a",
        "block": "minecraft:cyan_terracotta"
      },
      {
        "char": "d",
        "block": "minecraft:cobbled_deepslate"
      },
      {
        "char": "e",
        "block": "minecraft:basalt[axis=y]"
      },
      {
        "char": "b",
        "block": "minecraft:blackstone"
      },
      {
        "char": "c",
        "block": "minecraft:deepslate[axis=y]"
      },
      {
        "char": "Р",
        "block": "minecraft:stone_brick_stairs[facing=north,half=bottom,shape=straight,waterlogged=false,weathering=false]"
      },
      {
        "char": "z",
        "block": "minecraft:iron_bars[east=false,north=true,south=true,waterlogged=false,west=false]"
      },
      {
        "char": "Y",
        "block": "minecraft:iron_bars[east=false,north=true,south=false,waterlogged=false,west=false]"
      },
      {
        "char": "f",
        "block": "minecraft:glass"
      },
      {
        "char": "O",
        "block": "minecraft:quartz_stairs[facing=west,half=bottom,shape=straight,waterlogged=false]"
      },
      {
        "char": "x",
        "block": "minecraft:cauldron"
      },
      {
        "char": "П",
        "block": "minecraft:barrel[facing=up,open=false]",
        "tag": {
          "z": -275,
          "x": -15,
          "ForgeData": {
            "LockFlag": "1b"
          },
          "id": "minecraft:barrel",
          "y": 2,
          "Items": []
        }
      },
      {
        "char": "У",
        "block": "minecraft:stone_brick_stairs[facing=south,half=bottom,shape=straight,waterlogged=false,weathering=false]"
      },
      {
        "char": "С",
        "block": "minecraft:stone_brick_stairs[facing=north,half=top,shape=straight,waterlogged=false,weathering=false]"
      },
      {
        "char": "Ѥ",
        "block": "minecraft:air",
        "tag": {
          "z": -276,
          "x": -43,
          "id": "refurbished_furniture:computer",
          "y": -39,
          "NodePos": "-11544873218087L",
          "Connections": [
            "L"
          ]
        }
      },
      {
        "char": "Ѳ",
        "block": "minecraft:white_stained_glass_pane[east=true,north=false,south=false,waterlogged=false,west=false]"
      },
      {
        "char": "N",
        "block": "minecraft:white_stained_glass_pane[east=true,north=false,south=false,waterlogged=false,west=true]"
      },
      {
        "char": "k",
        "block": "minecraft:oak_leaves[distance=7,persistent=true,waterlogged=false]"
      },
      {
        "char": "у",
        "block": "minecraft:stone_brick_stairs[facing=south,half=top,shape=straight,waterlogged=false,weathering=false]"
      },
      {
        "char": "j",
        "block": "minecraft:polished_andesite_slab[type=top,waterlogged=false]"
      },
      {
        "char": "g",
        "block": "minecraft:gray_concrete"
      }
    ]
  },
  "slices": [
    [
      "adaedeeaddeabacb",
      "eccebdbdcaeaeebc",
      "cbdaacdaeddcdeac",
      "abaddddcadadecab",
      "acdbcaaebebabbce",
      "bacabdbceadccaba",
      "dcccdbedcdeddbed",
      "adbadcdbaedbecab",
      "beeecbcbacbbaddc",
      "cebdeadedceccaac",
      "abcdbecdabedcbea",
      "ccebdddeacebdbdd",
      "acaecbcadeedРz c",
      "daeeeaaabacc z b",
      "eaaaadeaaeee Y a",
      "bdbcdbadaaca   d"
    ],
    [
      "f   Oe    b     ",
      "     b          ",
      "                ",
      "  d  a    b     ",
      " Oc Oa    cadeeb",
      "  c  a     b  x ",
      "           e    ",
      "  b  d          ",
      " Oa Oc          ",
      "  c  П          ",
      "           d    ",
      "  e  c     c c c",
      " Oe Oc     e zУa",
      "  c  e     d zСb",
      "bebabca   da Y c",
      "  c  e     c   a"
    ],
    [
      "f    Ѥ    b     ",
      "                ",
      "                ",
      "          c     ",
      "  Ѥ  Ѥ    eab ѲN",
      "           b  k ",
      "           a    ",
      "                ",
      "  Ѥ  Ѥ          ",
      "                ",
      "           a    ",
      "           a a b",
      "  Ѥ  Ѥ     c z c",
      "           e zУa",
      "aaededb   ac YСd",
      "     a     e   e"
    ],
    [
      "f         d     ",
      "                ",
      "                ",
      "          c     ",
      "          add ѲN",
      "           b  k ",
      "           b    ",
      "                ",
      "                ",
      "                ",
      "           e    ",
      "           e d e",
      "           e z b",
      "           d z d",
      "ddddbcd   cdуzУa",
      "     d     ccecd"
    ],
    [
      "          c     ",
      "          j     ",
      "          j     ",
      "          e     ",
      "          eaacac",
      "           a    ",
      "           e    ",
      "           j    ",
      "           j    ",
      "           j    ",
      "           d    ",
      "           edbad",
      "           b z b",
      "           eуz b",
      "ceaecccjjjabРY c",
      "     e     b   d"
    ],
    [
      "g         c     ",
      "          d     ",
      "          b     ",
      "          e     ",
      "          cdecbb",
      "           c    ",
      "           e    ",
      "           b    ",
      "           a    ",
      "           e    ",
      "           b    ",
      "           ebeac",
      "           aуz d",
      "           bРz b",
      "ccaabeeeaaec Y d",
      "     b     d   d"
    ]
  ]
}