{
  "xsize": 16,
  "zsize": 16,
  "palette": {
    "palette": [
      {
        "char": " ",
        "block": "minecraft:air"
      },
      {
        "char": "d",
        "block": "minecraft:cobbled_deepslate"
      },
      {
        "char": "b",
        "block": "minecraft:blackstone"
      },
      {
        "char": "e",
        "block": "minecraft:basalt[axis=y]"
      },
      {
        "char": "a",
        "block": "minecraft:cyan_terracotta"
      },
      {
        "char": "c",
        "block": "minecraft:deepslate[axis=y]"
      },
      {
        "char": "j",
        "block": "minecraft:polished_andesite_slab[type=top,waterlogged=false]"
      },
      {
        "char": "i",
        "block": "minecraft:light_gray_concrete"
      },
      {
        "char": "g",
        "block": "minecraft:gray_concrete"
      },
      {
        "char": "ӛ",
        "block": "minecraft:air"
      },
      {
        "char": "ѵ",
        "block": "minecraft:dark_oak_planks"
      },
      {
        "char": "能",
        "block": "minecraft:lime_terracotta"
      },
      {
        "char": "f",
        "block": "minecraft:glass"
      },
      {
        "char": "ѱ",
        "block": "minecraft:brown_carpet"
      },
      {
        "char": "Ѯ",
        "block": "minecraft:diorite_slab[type=bottom,waterlogged=false]"
      },
      {
        "char": "P",
        "block": "minecraft:smooth_quartz_slab[type=bottom,waterlogged=false]"
      },
      {
        "char": "M",
        "block": "minecraft:smooth_quartz_slab[type=top,waterlogged=false]"
      },
      {
        "char": "ѩ",
        "block": "minecraft:diorite_slab[type=top,waterlogged=false]"
      },
      {
        "char": "h",
        "block": "minecraft:andesite_slab[type=top,waterlogged=false]"
      },
      {
        "char": "ϒ",
        "block": "minecraft:polished_andesite_stairs[facing=east,half=top,shape=straight,waterlogged=false]"
      },
      {
        "char": "合",
        "block": "minecraft:polished_andesite_stairs[facing=south,half=top,shape=outer_left,waterlogged=false]"
      },
      {
        "char": "凰",
        "block": "minecraft:polished_andesite_stairs[facing=east,half=top,shape=inner_right,waterlogged=false]"
      },
      {
        "char": "W",
        "block": "minecraft:polished_andesite_stairs[facing=south,half=top,shape=straight,waterlogged=false]"
      }
    ]
  },
  "slices": [
    [
      "dbdbdeedacj     ",
      "ceeeddecce      ",
      "cdeebcdedb      ",
      "daeaecceaaa     ",
      "ecaebdedbai     ",
      "aadcacaaca      ",
      "cddeaaagdd      ",
      "      ag        ",
      "   b      d     ",
      "                ",
      "                ",
      "                ",
      "                ",
      "                ",
      "                ",
      "                "
    ],
    [
      "ӛ       ѵd能     ",
      "         c      ",
      "        ѵc      ",
      "        ѵag     ",
      "        ѵaa     ",
      "ѵѵѵ ѵѵѵ  e      ",
      "dacaebggde      ",
      "      aa        ",
      "   e      b     ",
      "                ",
      "                ",
      "                ",
      "                ",
      "                ",
      "                ",
      "                "
    ],
    [
      "        fc能     ",
      "         a      ",
      "        fe      ",
      "        fgg     ",
      "        faa     ",
      "f f f f  b      ",
      "dbeebcggee      ",
      "      ag        ",
      "   e      b     ",
      "                ",
      "                ",
      "                ",
      "                ",
      "                ",
      "                ",
      "                "
    ],
    [
      "        ѱcѮ     ",
      "         aP     ",
      "        ѱdP     ",
      "        ѱaa     ",
      "        ѱaa     ",
      "ѱ ѱ ѱ ѱ  cP     ",
      "eeaaeeaaadP     ",
      "      aaѮPP     ",
      "   c      c     ",
      "                ",
      "                ",
      "                ",
      "                ",
      "                ",
      "                ",
      "                "
    ],
    [
      "         aM     ",
      "         eM     ",
      "         eM     ",
      "         ag     ",
      "         aa     ",
      "         eM     ",
      "bcccecaiaeM     ",
      "MMMMѩMigMMM     ",
      "   d      e     ",
      "                ",
      "                ",
      "                ",
      "                ",
      "                ",
      "                ",
      "                "
    ],
    [
      "hhhhhhhhϒe      ",
      "hhhhhhhhϒa      ",
      "hhhhhhhhϒd      ",
      "hhhhhhhhϒag     ",
      "hhhhhhh合凰aa     ",
      "WWWWWWW凰dc      ",
      "addeecedcd      ",
      "      ga        ",
      "   e      a     ",
      "                ",
      "                ",
      "                ",
      "                ",
      "                ",
      "                ",
      "                "
    ]
  ]
}