{
  "xsize": 16,
  "zsize": 16,
  "palette": {
    "palette": [
      {
        "char": " ",
        "block": "minecraft:air"
      },
      {
        "char": "d",
        "block": "minecraft:cobbled_deepslate"
      },
      {
        "char": "c",
        "block": "minecraft:deepslate[axis=y]"
      },
      {
        "char": "e",
        "block": "minecraft:basalt[axis=y]"
      },
      {
        "char": "a",
        "block": "minecraft:cyan_terracotta"
      },
      {
        "char": "b",
        "block": "minecraft:blackstone"
      },
      {
        "char": "g",
        "block": "minecraft:gray_concrete"
      },
      {
        "char": "0",
        "block": "minecraft:stone_slab[type=bottom,waterlogged=false,weathering=false]"
      },
      {
        "char": "D",
        "block": "minecraft:smooth_stone_slab[type=bottom,waterlogged=false]"
      },
      {
        "char": "Ѱ",
        "block": "minecraft:cobblestone_slab[type=bottom,waterlogged=false,weathering=false]"
      },
      {
        "char": "i",
        "block": "minecraft:light_gray_concrete"
      },
      {
        "char": "ϔ",
        "block": "minecraft:quartz_stairs[facing=east,half=bottom,shape=straight,waterlogged=false]"
      },
      {
        "char": "f",
        "block": "minecraft:glass"
      },
      {
        "char": "x",
        "block": "minecraft:cauldron"
      },
      {
        "char": "H",
        "block": "minecraft:quartz_stairs[facing=south,half=bottom,shape=straight,waterlogged=false]"
      },
      {
        "char": "Ӻ",
        "block": "minecraft:air",
        "tag": {
          "z": -276,
          "x": -15,
          "id": "refurbished_furniture:computer",
          "y": 27,
          "NodePos": "-3848291827685L",
          "Connections": [
            "L"
          ]
        }
      },
      {
        "char": "l",
        "block": "minecraft:iron_trapdoor[facing=east,half=bottom,open=false,powered=false,waterlogged=false]"
      },
      {
        "char": "k",
        "block": "minecraft:oak_leaves[distance=7,persistent=true,waterlogged=false]"
      },
      {
        "char": "ϐ",
        "block": "minecraft:air",
        "tag": {
          "z": -259,
          "x": -34,
          "id": "refurbished_furniture:computer",
          "y": -21,
          "NodePos": "-9070971985941L",
          "Connections": [
            "L"
          ]
        }
      },
      {
        "char": "u",
        "block": "minecraft:iron_trapdoor[facing=south,half=bottom,open=false,powered=false,waterlogged=false]"
      },
      {
        "char": "Ӟ",
        "block": "minecraft:air"
      },
      {
        "char": "t",
        "block": "minecraft:iron_trapdoor[facing=east,half=top,open=false,powered=false,waterlogged=false]"
      },
      {
        "char": "在",
        "block": "minecraft:air"
      },
      {
        "char": "w",
        "block": "minecraft:iron_trapdoor[facing=south,half=top,open=false,powered=false,waterlogged=false]"
      }
    ]
  },
  "slices": [
    [
      "dcdecacaa       ",
      "dcbdbcbgb       ",
      "aebdcdcaa       ",
      "cdeaeaad0       ",
      "ccccbcgaD       ",
      "aebebaacg       ",
      "edaadaaeDga     ",
      "aeaedgcDDag     ",
      "deedbgeDD       ",
      "cbcagaDDD       ",
      "dbbdadD0D       ",
      "ccbgc0DѰD       ",
      "adab0iDDD       ",
      "bbidD0DD0       ",
      "caaDDDDѰ0       ",
      "ae0DDDDDD       "
    ],
    [
      "c ϔ    f        ",
      "a               ",
      "cdd    f        ",
      "                ",
      "      f         ",
      "deedaegaa       ",
      "  x   f         ",
      "     f          ",
      "     f          ",
      "    f           ",
      "be  f           ",
      "H   d           ",
      "  f  a          ",
      "  f             ",
      " f              ",
      "f               "
    ],
    [
      "Ӻ      fl       ",
      "       fl       ",
      "        l       ",
      "      fl        ",
      "      fl        ",
      "bbeacagdg       ",
      "  k   fl        ",
      "     fl         ",
      "     fl         ",
      "     l          ",
      "ϐ   fl          ",
      "    b           ",
      "   u a          ",
      "  fӞ            ",
      "  Ӟ             ",
      "fl              "
    ],
    [
      "       ft       ",
      "       ft       ",
      "       ft       ",
      "      ft        ",
      "      ft        ",
      "bcbdabaea       ",
      "  k    t        ",
      "     ft         ",
      "      t         ",
      "     t          ",
      "    f在          ",
      "    d           ",
      "  fw a          ",
      "  ft            ",
      " ft             ",
      " w              "
    ],
    [
      "                ",
      "       f        ",
      "       f        ",
      "      f         ",
      "      f         ",
      "daeeceada       ",
      "      f         ",
      "     f          ",
      "     f          ",
      "    f           ",
      "    f           ",
      "   fa           ",
      "     a          ",
      "                ",
      " f              ",
      "f               "
    ],
    [
      "       aa       ",
      "       ie       ",
      "       ab       ",
      "      ab        ",
      "      ia        ",
      "ecdebdgcg       ",
      "      ib        ",
      "     gc         ",
      "     ab         ",
      "    ib          ",
      "    ad          ",
      "   ab           ",
      "  ae a          ",
      "  ab            ",
      " aa             ",
      "ac              "
    ]
  ]
}