{
  "xsize": 16,
  "zsize": 16,
  "palette": {
    "palette": [
      {
        "char": " ",
        "block": "minecraft:air"
      },
      {
        "char": "a",
        "block": "minecraft:cyan_terracotta"
      },
      {
        "char": "b",
        "block": "minecraft:blackstone"
      },
      {
        "char": "d",
        "block": "minecraft:cobbled_deepslate"
      },
      {
        "char": "e",
        "block": "minecraft:basalt[axis=y]"
      },
      {
        "char": "g",
        "block": "minecraft:gray_concrete"
      },
      {
        "char": "c",
        "block": "minecraft:deepslate[axis=y]"
      },
      {
        "char": "i",
        "block": "minecraft:light_gray_concrete"
      },
      {
        "char": "f",
        "block": "minecraft:glass"
      },
      {
        "char": "ϕ",
        "block": "minecraft:quartz_stairs[facing=north,half=bottom,shape=straight,waterlogged=false]"
      },
      {
        "char": "П",
        "block": "minecraft:barrel[facing=up,open=false]",
        "tag": {
          "z": -275,
          "x": -15,
          "ForgeData": {
            "LockFlag": "1b"
          },
          "id": "minecraft:barrel",
          "y": 2,
          "Items": []
        }
      },
      {
        "char": "x",
        "block": "minecraft:cauldron"
      },
      {
        "char": "s",
        "block": "minecraft:iron_trapdoor[facing=north,half=bottom,open=false,powered=false,waterlogged=false]"
      },
      {
        "char": "Ҝ",
        "block": "minecraft:air",
        "tag": {
          "z": -292,
          "x": -29,
          "id": "refurbished_furniture:computer",
          "y": 63,
          "NodePos": "-7696582590401L",
          "Connections": [
            "L"
          ]
        }
      },
      {
        "char": "k",
        "block": "minecraft:oak_leaves[distance=7,persistent=true,waterlogged=false]"
      },
      {
        "char": "p",
        "block": "minecraft:iron_trapdoor[facing=north,half=top,open=false,powered=false,waterlogged=false]"
      },
      {
        "char": "说",
        "block": "minecraft:air"
      },
      {
        "char": "I",
        "block": "minecraft:stone_slab[type=top,waterlogged=false,weathering=false]"
      }
    ]
  },
  "slices": [
    [
      "                ",
      "                ",
      "                ",
      "                ",
      "                ",
      "                ",
      " a              ",
      "bdaeae  g       ",
      "agaaagaeaa      ",
      "abaeeaaaag      ",
      "caeccebbea      ",
      "ecccddbdaa      ",
      "cdabbabcag      ",
      "eebbdecdda      ",
      "eeadcecbea      ",
      "aeeaacdabii     "
    ],
    [
      "                ",
      "                ",
      "                ",
      "                ",
      "                ",
      "                ",
      " a              ",
      " c      g       ",
      " a f f  ag      ",
      " b    f a       ",
      " b ϕ    c       ",
      " c      a       ",
      "acПac  xd       ",
      " b      a       ",
      " b      c       ",
      "cad  ddea i     "
    ],
    [
      "                ",
      "                ",
      "                ",
      "                ",
      "                ",
      "                ",
      " g              ",
      "sdssss  g       ",
      " afff ssag      ",
      " c    f a       ",
      " b      e       ",
      " e      c       ",
      " d Ҝ   ka       ",
      " d      d       ",
      " a      c       ",
      "eec  edee i     "
    ],
    [
      "                ",
      "                ",
      "                ",
      "                ",
      "                ",
      "                ",
      " g              ",
      "papppp  a       ",
      "fi   f说pga      ",
      " c    ffg       ",
      " c      c       ",
      " d      c       ",
      " c     kd       ",
      " b      d       ",
      " e      c       ",
      "eaa  aedd a     "
    ],
    [
      "                ",
      "                ",
      "                ",
      "                ",
      "                ",
      "                ",
      " g              ",
      " a      i       ",
      " aff f  aa      ",
      " d     fa       ",
      " e      a       ",
      " b      c       ",
      " a      e       ",
      " a      c       ",
      " a      a       ",
      "aacIIcbeb a     "
    ],
    [
      "                ",
      "                ",
      "                ",
      "                ",
      "                ",
      "                ",
      " i              ",
      "ccdcbe  a       ",
      "giaaaaadga      ",
      " b    aga       ",
      " b      a       ",
      " b      c       ",
      " a      c       ",
      " e      b       ",
      " b      a       ",
      "cbbecdeba a     "
    ]
  ]
}