{
  "xsize": 16,
  "zsize": 16,
  "palette": {
    "palette": [
      {
        "char": " ",
        "block": "minecraft:air"
      },
      {
        "char": "d",
        "block": "minecraft:cobbled_deepslate"
      },
      {
        "char": "J",
        "block": "minecraft:diorite"
      },
      {
        "char": "b",
        "block": "minecraft:blackstone"
      },
      {
        "char": "C",
        "block": "minecraft:quartz_pillar[axis=y]"
      },
      {
        "char": "o",
        "block": "minecraft:chiseled_quartz_block"
      },
      {
        "char": "a",
        "block": "minecraft:cyan_terracotta"
      },
      {
        "char": "g",
        "block": "minecraft:gray_concrete"
      },
      {
        "char": "e",
        "block": "minecraft:basalt[axis=y]"
      },
      {
        "char": "Ѧ",
        "block": "minecraft:quartz_bricks"
      },
      {
        "char": "K",
        "block": "minecraft:quartz_block"
      },
      {
        "char": "那",
        "block": "minecraft:white_terracotta"
      },
      {
        "char": "c",
        "block": "minecraft:deepslate[axis=y]"
      },
      {
        "char": "j",
        "block": "minecraft:polished_andesite_slab[type=top,waterlogged=false]"
      },
      {
        "char": "x",
        "block": "minecraft:cauldron"
      },
      {
        "char": "P",
        "block": "minecraft:smooth_quartz_slab[type=bottom,waterlogged=false]"
      },
      {
        "char": "Ѯ",
        "block": "minecraft:diorite_slab[type=bottom,waterlogged=false]"
      },
      {
        "char": "麽",
        "block": "minecraft:white_stained_glass_pane[east=false,north=false,south=true,waterlogged=false,west=false]"
      },
      {
        "char": "Ѩ",
        "block": "minecraft:white_stained_glass_pane[east=false,north=true,south=true,waterlogged=false,west=false]"
      },
      {
        "char": "章",
        "block": "minecraft:white_stained_glass_pane[east=false,north=true,south=false,waterlogged=false,west=false]"
      },
      {
        "char": "i",
        "block": "minecraft:light_gray_concrete"
      },
      {
        "char": "ѵ",
        "block": "minecraft:dark_oak_planks"
      },
      {
        "char": "能",
        "block": "minecraft:lime_terracotta"
      },
      {
        "char": "ӝ",
        "block": "minecraft:air"
      },
      {
        "char": "Ӣ",
        "block": "minecraft:air"
      },
      {
        "char": "ϓ",
        "block": "minecraft:air"
      },
      {
        "char": "ӛ",
        "block": "minecraft:air"
      },
      {
        "char": "Ѻ",
        "block": "minecraft:air"
      },
      {
        "char": "k",
        "block": "minecraft:oak_leaves[distance=7,persistent=true,waterlogged=false]"
      },
      {
        "char": "ҝ",
        "block": "minecraft:stone_brick_slab[type=top,waterlogged=false,weathering=false]"
      },
      {
        "char": "f",
        "block": "minecraft:glass"
      },
      {
        "char": "ѱ",
        "block": "minecraft:brown_carpet"
      },
      {
        "char": "M",
        "block": "minecraft:smooth_quartz_slab[type=top,waterlogged=false]"
      },
      {
        "char": "ѩ",
        "block": "minecraft:diorite_slab[type=top,waterlogged=false]"
      },
      {
        "char": "h",
        "block": "minecraft:andesite_slab[type=top,waterlogged=false]"
      },
      {
        "char": "ϒ",
        "block": "minecraft:polished_andesite_stairs[facing=east,half=top,shape=straight,waterlogged=false]"
      }
    ]
  },
  "slices": [
    [
      "dJ       b      ",
      "bC       d      ",
      "do       ag     ",
      "ao       b      ",
      "eѦ       e      ",
      "aK       a      ",
      "dag      aa     ",
      "aaaѦѦѦѦ那Ѧag     ",
      "bcbbeadede      ",
      "becccbcdac      ",
      "aadddbedabj     ",
      "eebdbbbbacj     ",
      "cabeccdcbej     ",
      "dcedbedbcbj     ",
      "ddcecbedebj     ",
      "addadcbadaj     "
    ],
    [
      "xP              ",
      " Ѯ       麽      ",
      " P       aa     ",
      " P       Ѩ      ",
      " P       章      ",
      " P              ",
      " gg      aa     ",
      " iaѮPѮPѮPai     ",
      "    x  x d      ",
      "         e      ",
      "        ѵb能     ",
      "        ѵb能     ",
      "    ӝ   ѵb能     ",
      "   Ӣϓӛ   a能     ",
      "    Ѻ   ѵb能     ",
      "        ѵd能     "
    ],
    [
      "k        ҝ      ",
      "         ҝ      ",
      "         ai     ",
      "         ҝ      ",
      "         ҝ      ",
      "         ҝ      ",
      " ag      aa     ",
      " aa      aa     ",
      "    k  k c      ",
      "         a      ",
      "         d能     ",
      "        fe能     ",
      "        fc能     ",
      "         e能     ",
      "        fb能     ",
      "         b能     "
    ],
    [
      "k        dP     ",
      "         cP     ",
      "         bѮ     ",
      "         aP     ",
      "         bѮ     ",
      "         cѮ     ",
      " ga      ag     ",
      " aa      ag     ",
      "    k  k bP     ",
      "         eP     ",
      "         eP     ",
      "        ѱdP     ",
      "        ѱbѮ     ",
      "         cP     ",
      "        ѱdѮ     ",
      "         dѮ     "
    ],
    [
      "         aM     ",
      "         eM     ",
      "         eM     ",
      "         cM     ",
      "         cM     ",
      "         bѩ     ",
      " aa      ag     ",
      " ag      aa     ",
      "         bM     ",
      "         cM     ",
      "         dM     ",
      "         dM     ",
      "         aM     ",
      "         cM     ",
      "         aM     ",
      "         bѩ     "
    ],
    [
      "hhhhhhhhϒd      ",
      "hhhhhhhhϒd      ",
      "hhhhhhhhϒd      ",
      "hhhhhhhhϒd      ",
      "hhhhhhhhϒd      ",
      "hhhhhhhhϒd      ",
      "hgahhhhhϒag     ",
      "hgahhhhhϒda     ",
      "hhhhhhhhϒa      ",
      "hhhhhhhhϒc      ",
      "hhhhhhhhϒb      ",
      "hhhhhhhhϒe      ",
      "hhhhhhhhϒd      ",
      "hhhhhhhhϒd      ",
      "hhhhhhhhϒa      ",
      "hhhhhhhhϒd      "
    ]
  ]
}