{
  "xsize": 16,
  "zsize": 16,
  "palette": {
    "palette": [
      {
        "char": " ",
        "block": "minecraft:air"
      },
      {
        "char": "e",
        "block": "minecraft:basalt[axis=y]"
      },
      {
        "char": "a",
        "block": "minecraft:cyan_terracotta"
      },
      {
        "char": "b",
        "block": "minecraft:blackstone"
      },
      {
        "char": "d",
        "block": "minecraft:cobbled_deepslate"
      },
      {
        "char": "c",
        "block": "minecraft:deepslate[axis=y]"
      },
      {
        "char": "Z",
        "block": "minecraft:stone_brick_wall[east=tall,north=tall,south=none,up=true,waterlogged=false,weathering=false,west=tall]"
      },
      {
        "char": "G",
        "block": "minecraft:iron_bars[east=false,north=false,south=true,waterlogged=false,west=false]"
      },
      {
        "char": "H",
        "block": "minecraft:quartz_stairs[facing=south,half=bottom,shape=straight,waterlogged=false]"
      },
      {
        "char": "ϕ",
        "block": "minecraft:quartz_stairs[facing=north,half=bottom,shape=straight,waterlogged=false]"
      },
      {
        "char": "O",
        "block": "minecraft:quartz_stairs[facing=west,half=bottom,shape=straight,waterlogged=false]"
      },
      {
        "char": "ϓ",
        "block": "minecraft:air"
      },
      {
        "char": "x",
        "block": "minecraft:cauldron"
      },
      {
        "char": "v",
        "block": "minecraft:quartz_pillar[axis=x]"
      },
      {
        "char": "n",
        "block": "minecraft:smooth_quartz"
      },
      {
        "char": "K",
        "block": "minecraft:quartz_block"
      },
      {
        "char": "C",
        "block": "minecraft:quartz_pillar[axis=y]"
      },
      {
        "char": "Ѵ",
        "block": "minecraft:white_stained_glass_pane[east=false,north=false,south=false,waterlogged=false,west=true]"
      },
      {
        "char": "k",
        "block": "minecraft:oak_leaves[distance=7,persistent=true,waterlogged=false]"
      },
      {
        "char": "r",
        "block": "minecraft:polished_diorite"
      },
      {
        "char": "Ѳ",
        "block": "minecraft:white_stained_glass_pane[east=true,north=false,south=false,waterlogged=false,west=false]"
      },
      {
        "char": "j",
        "block": "minecraft:polished_andesite_slab[type=top,waterlogged=false]"
      }
    ]
  },
  "slices": [
    [
      "eaaabbadeaeacbbc",
      "eddaeaaeaadbbddd",
      "caaaebedecbdabec",
      "eeaaddcacbcdadaa",
      "bcddcebebdebbcda",
      "cacddeebbacaebdc",
      "cadeabebcabddcee",
      "eeadebbeadabdbda",
      "caecbeaacdbcabda",
      "bdedaddbbbedaeac",
      "bbcccceceadedcad",
      "edbdbdeeddebadde",
      "ZZZaZZZeadcbdecd",
      "   e   abadddcba",
      "   b   abbbbeebc",
      " G e G adddbbaee"
    ],
    [
      " a      d  H    ",
      " a             ϕ",
      " c            Oϓ",
      " c      b      H",
      "bdccadbdb       ",
      " e  x  b        ",
      "       d        ",
      "             dda",
      "             c  ",
      "             b  ",
      "       a     c  ",
      "   c   c        ",
      "vvncKvCd        ",
      "   b   b     c  ",
      "   e   ea   cbce",
      " G a G e     c  "
    ],
    [
      " d      e       ",
      " c              ",
      " a              ",
      " d      d       ",
      "eebѴ  dac       ",
      " c  k  e        ",
      "       e        ",
      "             adc",
      "             c  ",
      "             c  ",
      "       a     a  ",
      "   d   c        ",
      "rvKevrve        ",
      "   b   c     e  ",
      "   d   db   cdab",
      " G b G e     a  "
    ],
    [
      " c      a       ",
      " e              ",
      " d              ",
      " d      a       ",
      "eddѴ Ѳbec       ",
      " b  k  e        ",
      "       e        ",
      "             ecc",
      "             b  ",
      "             b  ",
      "       c     b  ",
      "   e   b        ",
      "nvvevrve        ",
      "   e   b     a  ",
      "   b   bd   caad",
      " G c G a     e  "
    ],
    [
      " a      b       ",
      " d      j       ",
      " e      j       ",
      " b      a       ",
      "ceaeadcdc       ",
      " d     c        ",
      "       d        ",
      "       j     ebc",
      "       j     d  ",
      "       j     d  ",
      "       a     a  ",
      "jjjejjjb     j  ",
      "vvndvvrb     j  ",
      "   a   e     a  ",
      "   b   ebjjjddcd",
      " G b G a     c  "
    ],
    [
      " c      a       ",
      " c      b       ",
      " c      c       ",
      " d      a       ",
      "eedcedccb       ",
      " c     b        ",
      "       c        ",
      "       e     ead",
      "       b     c  ",
      "       d     b  ",
      "       c     a  ",
      "ebcbecbc     c  ",
      "   b   c     b  ",
      "   e   c     d  ",
      "   d   edaddcdaa",
      " G c G d     d  "
    ]
  ]
}