{
  "xsize": 16,
  "zsize": 16,
  "palette": {
    "palette": [
      {
        "char": " ",
        "block": "minecraft:air"
      },
      {
        "char": "a",
        "block": "minecraft:cyan_terracotta"
      },
      {
        "char": "g",
        "block": "minecraft:gray_concrete"
      },
      {
        "char": "i",
        "block": "minecraft:light_gray_concrete"
      },
      {
        "char": "e",
        "block": "minecraft:basalt[axis=y]"
      },
      {
        "char": "c",
        "block": "minecraft:deepslate[axis=y]"
      },
      {
        "char": "d",
        "block": "minecraft:cobbled_deepslate"
      },
      {
        "char": "b",
        "block": "minecraft:blackstone"
      },
      {
        "char": "f",
        "block": "minecraft:glass"
      },
      {
        "char": "x",
        "block": "minecraft:cauldron"
      },
      {
        "char": "O",
        "block": "minecraft:quartz_stairs[facing=west,half=bottom,shape=straight,waterlogged=false]"
      },
      {
        "char": "m",
        "block": "minecraft:iron_trapdoor[facing=west,half=bottom,open=false,powered=false,waterlogged=false]"
      },
      {
        "char": "k",
        "block": "minecraft:oak_leaves[distance=7,persistent=true,waterlogged=false]"
      },
      {
        "char": "Ѥ",
        "block": "minecraft:air",
        "tag": {
          "z": -276,
          "x": -43,
          "id": "refurbished_furniture:computer",
          "y": -39,
          "NodePos": "-11544873218087L",
          "Connections": [
            "L"
          ]
        }
      },
      {
        "char": "q",
        "block": "minecraft:iron_trapdoor[facing=west,half=top,open=false,powered=false,waterlogged=false]"
      }
    ]
  },
  "slices": [
    [
      "                ",
      "                ",
      "                ",
      "                ",
      "                ",
      "                ",
      "           aagaa",
      "          aigeac",
      "           cadac",
      "           caeda",
      "          baaeee",
      "          eaecad",
      "          ageaba",
      "          caabee",
      "         gaidbac",
      "          cgdddc"
    ],
    [
      "                ",
      "                ",
      "                ",
      "                ",
      "                ",
      "                ",
      "           i    ",
      "          agadcb",
      "            f  x",
      "                ",
      "           f    ",
      "           f   d",
      "           f O d",
      "           f   a",
      "         aaaecde",
      "           f   a"
    ],
    [
      "                ",
      "                ",
      "                ",
      "                ",
      "                ",
      "                ",
      "           g    ",
      "          aaaaea",
      "           mf  k",
      "           mf   ",
      "          mf    ",
      "          mf    ",
      "          mf   Ѥ",
      "          mf    ",
      "         aeabcde",
      "          m     "
    ],
    [
      "                ",
      "                ",
      "                ",
      "                ",
      "                ",
      "                ",
      "           a    ",
      "          gaaedc",
      "           q   k",
      "           qf   ",
      "          q     ",
      "          qf    ",
      "          qf    ",
      "          qf    ",
      "         aaaedbb",
      "          qf    "
    ],
    [
      "                ",
      "                ",
      "                ",
      "                ",
      "                ",
      "                ",
      "           a    ",
      "          gageab",
      "            f   ",
      "                ",
      "                ",
      "           f    ",
      "           f    ",
      "           f    ",
      "         aeaaabc",
      "           f    "
    ],
    [
      "                ",
      "                ",
      "                ",
      "                ",
      "                ",
      "                ",
      "           a    ",
      "          aaadbe",
      "           da   ",
      "           ea   ",
      "          ea    ",
      "          da    ",
      "          ea    ",
      "          dg    ",
      "         gdgbdeb",
      "          cg    "
    ]
  ]
}