{
  "xsize": 16,
  "zsize": 16,
  "palette": {
    "palette": [
      {
        "char": " ",
        "block": "minecraft:air"
      },
      {
        "char": "b",
        "block": "minecraft:blackstone"
      },
      {
        "char": "e",
        "block": "minecraft:basalt[axis=y]"
      },
      {
        "char": "c",
        "block": "minecraft:deepslate[axis=y]"
      },
      {
        "char": "d",
        "block": "minecraft:cobbled_deepslate"
      },
      {
        "char": "a",
        "block": "minecraft:cyan_terracotta"
      },
      {
        "char": "光",
        "block": "minecraft:air"
      },
      {
        "char": "然",
        "block": "minecraft:air"
      },
      {
        "char": "I",
        "block": "minecraft:stone_slab[type=top,waterlogged=false,weathering=false]"
      }
    ]
  },
  "slices": [
    [
      "beeecdceeadaceaa",
      "aaaeabaedbaedcde",
      "ddaceecbaeec    ",
      "abeebdbecad     ",
      "dbdeedbacb      ",
      "dddacaaced      ",
      "badddbbcac      ",
      "cbbbbcb         ",
      "dacecc          ",
      "deaad           ",
      "                ",
      "                ",
      "                ",
      "                ",
      "                ",
      "                "
    ],
    [
      "eaeaebbd        ",
      " a              ",
      "光a              ",
      "然b              ",
      "bec   ccb       ",
      " a      c       ",
      "        a       ",
      "                ",
      "                ",
      "                ",
      "                ",
      "                ",
      "                ",
      "                ",
      "                ",
      "                "
    ],
    [
      "cbecadec        ",
      " e              ",
      " a              ",
      " b              ",
      "dab   ebb       ",
      " e      c       ",
      "        d       ",
      "                ",
      "                ",
      "                ",
      "                ",
      "                ",
      "                ",
      "                ",
      "                ",
      "                "
    ],
    [
      "dcaabdea        ",
      " c              ",
      " b              ",
      " c              ",
      "add   ccb       ",
      " d      d       ",
      "                ",
      "                ",
      "                ",
      "                ",
      "                ",
      "                ",
      "                ",
      "                ",
      "                ",
      "                "
    ],
    [
      "bdaddedc        ",
      " c              ",
      " c              ",
      " c              ",
      "edbIIIeba       ",
      " b      e       ",
      " I              ",
      " I              ",
      " I              ",
      " I              ",
      "                ",
      "                ",
      "                ",
      "                ",
      "                ",
      "                "
    ],
    [
      "bbcbcebc        ",
      " b              ",
      " b              ",
      " c              ",
      "eccebeecc       ",
      " b              ",
      " d              ",
      " e              ",
      " c              ",
      " a              ",
      "                ",
      "                ",
      "                ",
      "                ",
      "                ",
      "                "
    ]
  ]
}