{
  "xsize": 16,
  "zsize": 16,
  "palette": {
    "palette": [
      {
        "char": " ",
        "block": "minecraft:air"
      },
      {
        "char": "a",
        "block": "minecraft:cyan_terracotta"
      },
      {
        "char": "b",
        "block": "minecraft:blackstone"
      },
      {
        "char": "d",
        "block": "minecraft:cobbled_deepslate"
      },
      {
        "char": "c",
        "block": "minecraft:deepslate[axis=y]"
      },
      {
        "char": "e",
        "block": "minecraft:basalt[axis=y]"
      },
      {
        "char": "Р",
        "block": "minecraft:stone_brick_stairs[facing=north,half=bottom,shape=straight,waterlogged=false,weathering=false]"
      },
      {
        "char": "z",
        "block": "minecraft:iron_bars[east=false,north=true,south=true,waterlogged=false,west=false]"
      },
      {
        "char": "Y",
        "block": "minecraft:iron_bars[east=false,north=true,south=false,waterlogged=false,west=false]"
      },
      {
        "char": "f",
        "block": "minecraft:glass"
      },
      {
        "char": "O",
        "block": "minecraft:quartz_stairs[facing=west,half=bottom,shape=straight,waterlogged=false]"
      },
      {
        "char": "П",
        "block": "minecraft:barrel[facing=up,open=false]",
        "tag": {
          "z": -275,
          "x": -15,
          "ForgeData": {
            "LockFlag": "1b"
          },
          "id": "minecraft:barrel",
          "y": 2,
          "Items": []
        }
      },
      {
        "char": "x",
        "block": "minecraft:cauldron"
      },
      {
        "char": "没",
        "block": "minecraft:air"
      },
      {
        "char": "机",
        "block": "minecraft:air"
      },
      {
        "char": "Ѥ",
        "block": "minecraft:air",
        "tag": {
          "z": -276,
          "x": -43,
          "id": "refurbished_furniture:computer",
          "y": -39,
          "NodePos": "-11544873218087L",
          "Connections": [
            "L"
          ]
        }
      },
      {
        "char": "Ѵ",
        "block": "minecraft:white_stained_glass_pane[east=false,north=false,south=false,waterlogged=false,west=true]"
      },
      {
        "char": "k",
        "block": "minecraft:oak_leaves[distance=7,persistent=true,waterlogged=false]"
      },
      {
        "char": "У",
        "block": "minecraft:stone_brick_stairs[facing=south,half=bottom,shape=straight,waterlogged=false,weathering=false]"
      },
      {
        "char": "С",
        "block": "minecraft:stone_brick_stairs[facing=north,half=top,shape=straight,waterlogged=false,weathering=false]"
      },
      {
        "char": "Ѳ",
        "block": "minecraft:white_stained_glass_pane[east=true,north=false,south=false,waterlogged=false,west=false]"
      },
      {
        "char": "у",
        "block": "minecraft:stone_brick_stairs[facing=south,half=top,shape=straight,waterlogged=false,weathering=false]"
      },
      {
        "char": "j",
        "block": "minecraft:polished_andesite_slab[type=top,waterlogged=false]"
      }
    ]
  },
  "slices": [
    [
      "abaabbdccaeaaecc",
      "aedecaebebdebabc",
      "adbbcbccebbbddae",
      "bdbbbbaaceaadeda",
      "dbdcdeeedeeececb",
      "aaecbbeabdcbbcab",
      "deedcacebbecbacd",
      "accababcadbacdcb",
      "bbadaddecbeedaee",
      "abdcbdceccbdaaac",
      "debabcadabebdaaa",
      "adcaaddbeeabcbdb",
      "acebbecaecabРz c",
      "bcbacdecaaaa z e",
      "ebddadcabded Y b",
      "cdebabddecea   d"
    ],
    [
      "fbce a    b     ",
      "     a          ",
      "                ",
      "  d  c    d     ",
      " Oa Oc    bbdaba",
      "  e  П     c  x ",
      "           c    ",
      "  b  d          ",
      " Oc Od          ",
      "  c  e          ",
      "           d    ",
      "  b  a     e b e",
      " Od Oc     a z没a",
      "  e  e     b z机c",
      "ceedeaa   ed Y b",
      "  a  e     d   b"
    ],
    [
      "f         c     ",
      "                ",
      "                ",
      "          b     ",
      "  Ѥ  Ѥ    caaѴ  ",
      "           e  k ",
      "           d    ",
      "                ",
      "  Ѥ  Ѥ          ",
      "                ",
      "           b    ",
      "           d b d",
      "  Ѥ  Ѥ     a z a",
      "           e zУd",
      "dbacedd   ad YСc",
      "     e     c   e"
    ],
    [
      "f         e     ",
      "                ",
      "                ",
      "          b     ",
      "          adeѴ Ѳ",
      "           b  k ",
      "           a    ",
      "                ",
      "                ",
      "                ",
      "           a    ",
      "           e d d",
      "           e z e",
      "           b z b",
      "beaeedb   acуzУb",
      "     c     beddd"
    ],
    [
      "f         b     ",
      "          j     ",
      "          j     ",
      "          b     ",
      "          dbcdbd",
      "           d    ",
      "           b    ",
      "           j    ",
      "           j    ",
      "           j    ",
      "           a    ",
      "           dbebe",
      "           c z a",
      "           cуz e",
      "deadedejjjcaРY b",
      "     b     c   e"
    ],
    [
      "a         c     ",
      "          b     ",
      "          c     ",
      "          a     ",
      "          bcdcba",
      "           b    ",
      "           b    ",
      "           a    ",
      "           e    ",
      "           e    ",
      "           e    ",
      "           ccacd",
      "           aуz a",
      "           bРz d",
      "cbbedddbaebe Y b",
      "     c     e   a"
    ]
  ]
}