{
  "xsize": 16,
  "zsize": 16,
  "palette": {
    "palette": [
      {
        "char": " ",
        "block": "minecraft:air"
      },
      {
        "char": "a",
        "block": "minecraft:cyan_terracotta"
      },
      {
        "char": "d",
        "block": "minecraft:cobbled_deepslate"
      },
      {
        "char": "e",
        "block": "minecraft:basalt[axis=y]"
      },
      {
        "char": "c",
        "block": "minecraft:deepslate[axis=y]"
      },
      {
        "char": "b",
        "block": "minecraft:blackstone"
      },
      {
        "char": "i",
        "block": "minecraft:light_gray_concrete"
      },
      {
        "char": "g",
        "block": "minecraft:gray_concrete"
      },
      {
        "char": "x",
        "block": "minecraft:cauldron"
      },
      {
        "char": "k",
        "block": "minecraft:oak_leaves[distance=7,persistent=true,waterlogged=false]"
      },
      {
        "char": "Ѯ",
        "block": "minecraft:diorite_slab[type=bottom,waterlogged=false]"
      },
      {
        "char": "P",
        "block": "minecraft:smooth_quartz_slab[type=bottom,waterlogged=false]"
      },
      {
        "char": "ѩ",
        "block": "minecraft:diorite_slab[type=top,waterlogged=false]"
      },
      {
        "char": "M",
        "block": "minecraft:smooth_quartz_slab[type=top,waterlogged=false]"
      },
      {
        "char": "ѭ",
        "block": "minecraft:polished_andesite_stairs[facing=west,half=top,shape=straight,waterlogged=false]"
      },
      {
        "char": "h",
        "block": "minecraft:andesite_slab[type=top,waterlogged=false]"
      },
      {
        "char": "何",
        "block": "minecraft:polished_andesite_stairs[facing=south,half=top,shape=inner_right,waterlogged=false]"
      },
      {
        "char": "相",
        "block": "minecraft:polished_andesite_stairs[facing=west,half=top,shape=outer_left,waterlogged=false]"
      },
      {
        "char": "W",
        "block": "minecraft:polished_andesite_stairs[facing=south,half=top,shape=straight,waterlogged=false]"
      }
    ]
  },
  "slices": [
    [
      "         adedcda",
      "         adbeddd",
      "         bccebed",
      "        igbaedea",
      "        aaabdaec",
      "         bebdacc",
      "         adagebb",
      "           aa   ",
      "                ",
      "                ",
      "                ",
      "                ",
      "                ",
      "                ",
      "                ",
      "                "
    ],
    [
      "         ex     ",
      "         c      ",
      "         c      ",
      "        iax     ",
      "        ga      ",
      "         b      ",
      "         beaaeee",
      "           ga   ",
      "                ",
      "                ",
      "                ",
      "                ",
      "                ",
      "                ",
      "                ",
      "                "
    ],
    [
      "         bk     ",
      "         e      ",
      "         b      ",
      "        aak     ",
      "        ag      ",
      "         e      ",
      "         bbagcad",
      "           aa   ",
      "                ",
      "                ",
      "                ",
      "                ",
      "                ",
      "                ",
      "                ",
      "                "
    ],
    [
      "        Ѯak     ",
      "        Ѯe      ",
      "        Pe      ",
      "        ggk     ",
      "        ia      ",
      "        Ѯb      ",
      "        Pddaicac",
      "        PѮPaaPPP",
      "                ",
      "                ",
      "                ",
      "                ",
      "                ",
      "                ",
      "                ",
      "                "
    ],
    [
      "        ѩa      ",
      "        Mc      ",
      "        Me      ",
      "        ag      ",
      "        aa      ",
      "        Md      ",
      "        Mebiiebb",
      "        MѩMiaѩMM",
      "                ",
      "                ",
      "                ",
      "                ",
      "                ",
      "                ",
      "                ",
      "                "
    ],
    [
      "         aѭhhhhh",
      "         aѭhhhhh",
      "         cѭhhhhh",
      "        gbѭhhhhh",
      "        ae何相hhhh",
      "         ed何WWWW",
      "         ceeeeaa",
      "           ga   ",
      "                ",
      "                ",
      "                ",
      "                ",
      "                ",
      "                ",
      "                ",
      "                "
    ]
  ]
}