{
  "xsize": 16,
  "zsize": 16,
  "palette": {
    "palette": [
      {
        "char": " ",
        "block": "minecraft:air"
      },
      {
        "char": "e",
        "block": "minecraft:basalt[axis=y]"
      },
      {
        "char": "d",
        "block": "minecraft:cobbled_deepslate"
      },
      {
        "char": "c",
        "block": "minecraft:deepslate[axis=y]"
      },
      {
        "char": "b",
        "block": "minecraft:blackstone"
      },
      {
        "char": "a",
        "block": "minecraft:cyan_terracotta"
      },
      {
        "char": "Ӿ",
        "block": "minecraft:cobblestone_wall[east=tall,north=tall,south=none,up=true,waterlogged=false,weathering=false,west=tall]"
      },
      {
        "char": "Z",
        "block": "minecraft:stone_brick_wall[east=tall,north=tall,south=none,up=true,waterlogged=false,weathering=false,west=tall]"
      },
      {
        "char": "G",
        "block": "minecraft:iron_bars[east=false,north=false,south=true,waterlogged=false,west=false]"
      },
      {
        "char": "H",
        "block": "minecraft:quartz_stairs[facing=south,half=bottom,shape=straight,waterlogged=false]"
      },
      {
        "char": "ϕ",
        "block": "minecraft:quartz_stairs[facing=north,half=bottom,shape=straight,waterlogged=false]"
      },
      {
        "char": "O",
        "block": "minecraft:quartz_stairs[facing=west,half=bottom,shape=straight,waterlogged=false]"
      },
      {
        "char": "ϓ",
        "block": "minecraft:air"
      },
      {
        "char": "x",
        "block": "minecraft:cauldron"
      },
      {
        "char": "v",
        "block": "minecraft:quartz_pillar[axis=x]"
      },
      {
        "char": "N",
        "block": "minecraft:white_stained_glass_pane[east=true,north=false,south=false,waterlogged=false,west=true]"
      },
      {
        "char": "Ѵ",
        "block": "minecraft:white_stained_glass_pane[east=false,north=false,south=false,waterlogged=false,west=true]"
      },
      {
        "char": "k",
        "block": "minecraft:oak_leaves[distance=7,persistent=true,waterlogged=false]"
      },
      {
        "char": "J",
        "block": "minecraft:diorite"
      },
      {
        "char": "j",
        "block": "minecraft:polished_andesite_slab[type=top,waterlogged=false]"
      },
      {
        "char": "o",
        "block": "minecraft:chiseled_quartz_block"
      }
    ]
  },
  "slices": [
    [
      "eedccbedacddbdcd",
      "badddbaececeaebd",
      "dccdacdbedbbadcb",
      "bdebbcebcaacbbcd",
      "aabddedadccbbaac",
      "cdbaacbacebeabbd",
      "ebccceaebbeededc",
      "aacceecccccaacec",
      "ccbaabcecadecbce",
      "eaebaaddbeaabbbe",
      "cedaaabeceadecca",
      "ddccdecaaceddeba",
      "ӾZZaZӾZccdaacead",
      "   c   ecedcbebc",
      "   a   dabbceadd",
      " G a G eedddeaec"
    ],
    [
      " b      c  H    ",
      " c             ϕ",
      " b            Oϓ",
      " d      a      H",
      "ebacbadeb       ",
      " c  x  d        ",
      "       b        ",
      "             ebc",
      "             d  ",
      "             b  ",
      "       a     c  ",
      "   e   d        ",
      "vvvbvvvd        ",
      "   e   c     e  ",
      "   c   be   bebb",
      " G d G d     e  "
    ],
    [
      " e      b       ",
      " b              ",
      " e              ",
      " a      e       ",
      "dccNѴ aeb       ",
      " e  k  b        ",
      "       b        ",
      "             dcb",
      "             a  ",
      "             b  ",
      "       d     d  ",
      "   e   c        ",
      "vvvcvvvc        ",
      "   a   a     c  ",
      "   c   be   bbce",
      " G d G d     e  "
    ],
    [
      " a      c       ",
      " b              ",
      " a              ",
      " e      d       ",
      "deeNѴ edb       ",
      " c  k  a        ",
      "       c        ",
      "             cca",
      "             e  ",
      "             e  ",
      "       c     c  ",
      "   a   d        ",
      "vvJavJve        ",
      "   d   b     e  ",
      "   d   dc   daec",
      " G c G c     e  "
    ],
    [
      " c      e       ",
      " c      j       ",
      " d      j       ",
      " e      a       ",
      "eddaeeceb       ",
      " e     c        ",
      "       c        ",
      "       j     cec",
      "       j     b  ",
      "       j     e  ",
      "       d     c  ",
      "jjjejjjb     j  ",
      "vvvevovd     j  ",
      "   a   e     e  ",
      "   a   acjjjeadd",
      " G c G b     b  "
    ],
    [
      " b      b       ",
      " e      e       ",
      " c      b       ",
      " e      b       ",
      "eadcaaabd       ",
      " d     d        ",
      "       c        ",
      "       a     cbb",
      "       d     d  ",
      "       d     d  ",
      "       b     e  ",
      "adbcceeb     b  ",
      "   a   c     a  ",
      "   d   d     c  ",
      "   c   ddaeebbdc",
      " G a G c     d  "
    ]
  ]
}