{
  "xsize": 16,
  "zsize": 16,
  "palette": {
    "palette": [
      {
        "char": " ",
        "block": "minecraft:air"
      },
      {
        "char": "a",
        "block": "minecraft:cyan_terracotta"
      },
      {
        "char": "i",
        "block": "minecraft:light_gray_concrete"
      },
      {
        "char": "d",
        "block": "minecraft:cobbled_deepslate"
      },
      {
        "char": "b",
        "block": "minecraft:blackstone"
      },
      {
        "char": "c",
        "block": "minecraft:deepslate[axis=y]"
      },
      {
        "char": "e",
        "block": "minecraft:basalt[axis=y]"
      },
      {
        "char": "g",
        "block": "minecraft:gray_concrete"
      },
      {
        "char": "f",
        "block": "minecraft:glass"
      },
      {
        "char": "ϕ",
        "block": "minecraft:quartz_stairs[facing=north,half=bottom,shape=straight,waterlogged=false]"
      },
      {
        "char": "s",
        "block": "minecraft:iron_trapdoor[facing=north,half=bottom,open=false,powered=false,waterlogged=false]"
      },
      {
        "char": "m",
        "block": "minecraft:iron_trapdoor[facing=west,half=bottom,open=false,powered=false,waterlogged=false]"
      },
      {
        "char": "Ҝ",
        "block": "minecraft:air",
        "tag": {
          "z": -292,
          "x": -29,
          "id": "refurbished_furniture:computer",
          "y": 63,
          "NodePos": "-7696582590401L",
          "Connections": [
            "L"
          ]
        }
      },
      {
        "char": "p",
        "block": "minecraft:iron_trapdoor[facing=north,half=top,open=false,powered=false,waterlogged=false]"
      },
      {
        "char": "q",
        "block": "minecraft:iron_trapdoor[facing=west,half=top,open=false,powered=false,waterlogged=false]"
      }
    ]
  },
  "slices": [
    [
      "                ",
      "                ",
      "                ",
      "                ",
      "                ",
      "                ",
      "                ",
      "         ai  dad",
      "       aabcaegaa",
      "     gabeiaagade",
      "   agbbaaccababe",
      "  ggdaaadebaeabd",
      " abaacddcccbcced",
      "gbagaceddebdabbb",
      "aicccccdbcbcddad",
      "gcddbdacbabbeecd"
    ],
    [
      "                ",
      "                ",
      "                ",
      "                ",
      "                ",
      "                ",
      "                ",
      "          a     ",
      "          c   ff",
      "         fg f   ",
      "   a   ff d     ",
      "    bff   a     ",
      "    f     c ϕ   ",
      "  ff      e   d ",
      " f        acabc ",
      "f    d    c     "
    ],
    [
      "                ",
      "                ",
      "                ",
      "                ",
      "                ",
      "                ",
      "                ",
      "          g  sss",
      "         scssfff",
      "       ssfa f   ",
      "   a ss f d     ",
      "    e f   c     ",
      "  ss      a     ",
      " sff      c     ",
      "mf        c Ҝ   ",
      "f         a     "
    ],
    [
      "                ",
      "                ",
      "                ",
      "                ",
      "                ",
      "                ",
      "                ",
      "          a  ppp",
      "         pappff ",
      "       ppfa f   ",
      "   a ppff c     ",
      "    aff   a     ",
      "  pqf     e     ",
      " pff      d     ",
      "pf        b     ",
      "          c     "
    ],
    [
      "                ",
      "                ",
      "                ",
      "                ",
      "                ",
      "                ",
      "                ",
      "          a     ",
      "          b  ff ",
      "          a f   ",
      "   a    f e     ",
      "    d f   e     ",
      "          b     ",
      "  f       d     ",
      " f        a     ",
      "f         c     "
    ],
    [
      "                ",
      "                ",
      "                ",
      "                ",
      "                ",
      "                ",
      "                ",
      "          g  deb",
      "         dddcgag",
      "       acaaia   ",
      "   g cdaa b     ",
      "    ega   c     ",
      "  bag     c     ",
      " aag      b     ",
      "ea        a     ",
      "g         c     "
    ]
  ]
}