{
  "xsize": 16,
  "zsize": 16,
  "palette": {
    "palette": [
      {
        "char": " ",
        "block": "minecraft:air"
      },
      {
        "char": "c",
        "block": "minecraft:deepslate[axis=y]"
      },
      {
        "char": "d",
        "block": "minecraft:cobbled_deepslate"
      },
      {
        "char": "e",
        "block": "minecraft:basalt[axis=y]"
      },
      {
        "char": "a",
        "block": "minecraft:cyan_terracotta"
      },
      {
        "char": "b",
        "block": "minecraft:blackstone"
      },
      {
        "char": "g",
        "block": "minecraft:gray_concrete"
      },
      {
        "char": "i",
        "block": "minecraft:light_gray_concrete"
      },
      {
        "char": "ϔ",
        "block": "minecraft:quartz_stairs[facing=east,half=bottom,shape=straight,waterlogged=false]"
      },
      {
        "char": "f",
        "block": "minecraft:glass"
      },
      {
        "char": "x",
        "block": "minecraft:cauldron"
      },
      {
        "char": "H",
        "block": "minecraft:quartz_stairs[facing=south,half=bottom,shape=straight,waterlogged=false]"
      },
      {
        "char": "下",
        "block": "minecraft:air"
      },
      {
        "char": "l",
        "block": "minecraft:iron_trapdoor[facing=east,half=bottom,open=false,powered=false,waterlogged=false]"
      },
      {
        "char": "k",
        "block": "minecraft:oak_leaves[distance=7,persistent=true,waterlogged=false]"
      },
      {
        "char": "ѷ",
        "block": "minecraft:air"
      },
      {
        "char": "u",
        "block": "minecraft:iron_trapdoor[facing=south,half=bottom,open=false,powered=false,waterlogged=false]"
      },
      {
        "char": "t",
        "block": "minecraft:iron_trapdoor[facing=east,half=top,open=false,powered=false,waterlogged=false]"
      },
      {
        "char": "w",
        "block": "minecraft:iron_trapdoor[facing=south,half=top,open=false,powered=false,waterlogged=false]"
      }
    ]
  },
  "slices": [
    [
      "cccdeccae       ",
      "aaebccdge       ",
      "ecadbdbac       ",
      "cdebcegc        ",
      "abebacae        ",
      "cbcddegba       ",
      "acdbebgbg       ",
      "accadaba        ",
      "eccedica        ",
      "eeebaag         ",
      "cdeeiea         ",
      "deagag          ",
      "eaaaaa          ",
      "edada           ",
      "daaa            ",
      "aai             "
    ],
    [
      "c ϔ    f        ",
      "c      f        ",
      "ecd    f        ",
      "                ",
      "      f         ",
      "cddddcaba       ",
      "  x             ",
      "     f          ",
      "     f          ",
      "    f           ",
      "ab  f           ",
      "H   d           ",
      "  f  g          ",
      "  f             ",
      "                ",
      "f               "
    ],
    [
      "下      fl       ",
      "       fl       ",
      "       fl       ",
      "      fl        ",
      "      fl        ",
      "dedddagba       ",
      "  k   fl        ",
      "     fl         ",
      "     fl         ",
      "    fl          ",
      "ѷ   fl          ",
      "   fe           ",
      "   u a          ",
      "  fl            ",
      "  l             ",
      " l              "
    ],
    [
      "       ft       ",
      "       ft       ",
      "       ft       ",
      "      ft        ",
      "      ft        ",
      "bbdceaaag       ",
      "  k   ft        ",
      "     ft         ",
      "      t         ",
      "    ft          ",
      "    ft          ",
      "   fa           ",
      "   w a          ",
      "   t            ",
      " ft             ",
      "fw              "
    ],
    [
      "       f        ",
      "       f        ",
      "       f        ",
      "                ",
      "                ",
      "cbbabbgca       ",
      "                ",
      "     f          ",
      "                ",
      "    f           ",
      "    f           ",
      "   fc           ",
      "  f  i          ",
      "  f             ",
      " f              ",
      "f               "
    ],
    [
      "       id       ",
      "       ab       ",
      "       ad       ",
      "      ac        ",
      "      ie        ",
      "abdabaaei       ",
      "      ab        ",
      "     gb         ",
      "     ic         ",
      "    gc          ",
      "    ae          ",
      "   ac           ",
      "  aa a          ",
      "  gc            ",
      " ia             ",
      "ae              "
    ]
  ]
}