{
  "xsize": 16,
  "zsize": 16,
  "palette": {
    "palette": [
      {
        "char": " ",
        "block": "minecraft:air"
      },
      {
        "char": "a",
        "block": "minecraft:cyan_terracotta"
      },
      {
        "char": "b",
        "block": "minecraft:blackstone"
      },
      {
        "char": "e",
        "block": "minecraft:basalt[axis=y]"
      },
      {
        "char": "c",
        "block": "minecraft:deepslate[axis=y]"
      },
      {
        "char": "d",
        "block": "minecraft:cobbled_deepslate"
      },
      {
        "char": "g",
        "block": "minecraft:gray_concrete"
      },
      {
        "char": "ϔ",
        "block": "minecraft:quartz_stairs[facing=east,half=bottom,shape=straight,waterlogged=false]"
      },
      {
        "char": "f",
        "block": "minecraft:glass"
      },
      {
        "char": "i",
        "block": "minecraft:light_gray_concrete"
      },
      {
        "char": "K",
        "block": "minecraft:quartz_block"
      },
      {
        "char": "C",
        "block": "minecraft:quartz_pillar[axis=y]"
      },
      {
        "char": "o",
        "block": "minecraft:chiseled_quartz_block"
      },
      {
        "char": "Ӻ",
        "block": "minecraft:air",
        "tag": {
          "z": -276,
          "x": -15,
          "id": "refurbished_furniture:computer",
          "y": 27,
          "NodePos": "-3848291827685L",
          "Connections": [
            "L"
          ]
        }
      },
      {
        "char": "l",
        "block": "minecraft:iron_trapdoor[facing=east,half=bottom,open=false,powered=false,waterlogged=false]"
      },
      {
        "char": "u",
        "block": "minecraft:iron_trapdoor[facing=south,half=bottom,open=false,powered=false,waterlogged=false]"
      },
      {
        "char": "t",
        "block": "minecraft:iron_trapdoor[facing=east,half=top,open=false,powered=false,waterlogged=false]"
      },
      {
        "char": "I",
        "block": "minecraft:stone_slab[type=top,waterlogged=false,weathering=false]"
      }
    ]
  },
  "slices": [
    [
      "abebeccae       ",
      "bdaabeagd       ",
      "dcdbaddgc       ",
      "cdaddcaa        ",
      "ecbacdab        ",
      "bbbddaaca       ",
      "bacedbga        ",
      "aeebbgc         ",
      "ddabdab         ",
      "dcebge          ",
      "deebgd          ",
      "edage           ",
      "bdga a          ",
      "cdab            ",
      "dae             ",
      "ab              "
    ],
    [
      "   c ϔ          ",
      "   e   f        ",
      "de     f        ",
      "bbee  f         ",
      "abeac f         ",
      "cdaabbiai       ",
      "abccc  K        ",
      "daee  C         ",
      "aabb  C         ",
      "d    C          ",
      "   a C          ",
      "    o           ",
      "   K a          ",
      "   C            ",
      "  o             ",
      " C              "
    ],
    [
      "   Ӻ   fl       ",
      "       fl       ",
      "b       l       ",
      "ec    fl        ",
      "bbd   fl        ",
      "cebebegig       ",
      "eca    g        ",
      "eb    l         ",
      "      l         ",
      "     l          ",
      "   a l          ",
      "    a           ",
      "   u a          ",
      "   u            ",
      "  u             ",
      " u              "
    ],
    [
      "       ft       ",
      "        t       ",
      "        t       ",
      "      ft        ",
      "dd    ft        ",
      "dc  bbgia       ",
      "ee     a        ",
      "                ",
      "                ",
      "                ",
      "   a            ",
      "    a           ",
      "     a          ",
      "                ",
      "                ",
      "                "
    ],
    [
      "I      f        ",
      "                ",
      "                ",
      "      f         ",
      "      f         ",
      "     daga       ",
      "       a        ",
      "                ",
      "                ",
      "                ",
      "                ",
      "                ",
      "                ",
      "                ",
      "                ",
      "                "
    ],
    [
      "b      ab       ",
      "       aa       ",
      "       ad       ",
      "      ae        ",
      "      ab        ",
      "     agaa       ",
      "       a        ",
      "                ",
      "                ",
      "                ",
      "                ",
      "                ",
      "                ",
      "                ",
      "                ",
      "                "
    ]
  ]
}