{
  "xsize": 16,
  "zsize": 16,
  "palette": {
    "palette": [
      {
        "char": " ",
        "block": "minecraft:air"
      },
      {
        "char": "g",
        "block": "minecraft:gray_concrete"
      },
      {
        "char": "a",
        "block": "minecraft:cyan_terracotta"
      },
      {
        "char": "b",
        "block": "minecraft:blackstone"
      },
      {
        "char": "c",
        "block": "minecraft:deepslate[axis=y]"
      },
      {
        "char": "d",
        "block": "minecraft:cobbled_deepslate"
      },
      {
        "char": "i",
        "block": "minecraft:light_gray_concrete"
      },
      {
        "char": "e",
        "block": "minecraft:basalt[axis=y]"
      },
      {
        "char": "f",
        "block": "minecraft:glass"
      },
      {
        "char": "O",
        "block": "minecraft:quartz_stairs[facing=west,half=bottom,shape=straight,waterlogged=false]"
      },
      {
        "char": "s",
        "block": "minecraft:iron_trapdoor[facing=north,half=bottom,open=false,powered=false,waterlogged=false]"
      },
      {
        "char": "m",
        "block": "minecraft:iron_trapdoor[facing=west,half=bottom,open=false,powered=false,waterlogged=false]"
      },
      {
        "char": "Ѫ",
        "block": "minecraft:air"
      },
      {
        "char": "到",
        "block": "minecraft:air"
      },
      {
        "char": "来",
        "block": "minecraft:air"
      },
      {
        "char": "p",
        "block": "minecraft:iron_trapdoor[facing=north,half=top,open=false,powered=false,waterlogged=false]"
      },
      {
        "char": "q",
        "block": "minecraft:iron_trapdoor[facing=west,half=top,open=false,powered=false,waterlogged=false]"
      }
    ]
  },
  "slices": [
    [
      "             gab",
      "             aag",
      "            abac",
      "            abgd",
      "           aaica",
      "           adadc",
      "          aeadec",
      "          gbaebd",
      "           baaae",
      "           bgbdc",
      "          eaaeab",
      "          baeadd",
      "          baeeab",
      "          dieaed",
      "         geaaabd",
      "          cicade"
    ],
    [
      "             a  ",
      "              af",
      "                ",
      "                ",
      "             f  ",
      "             f  ",
      "            f   ",
      "          idg  c",
      "            f Oe",
      "            f  b",
      "                ",
      "               b",
      "              Oe",
      "               d",
      "         icabedb",
      "           f    "
    ],
    [
      "             g s",
      "              c ",
      "             sf ",
      "             mf ",
      "            mf  ",
      "            m   ",
      "           m    ",
      "          ada   ",
      "           m   Ѫ",
      "           mf   ",
      "          mf    ",
      "          mf    ",
      "          mf   到",
      "          mf   来",
      "         acaeced",
      "          mf    "
    ],
    [
      "             a p",
      "              af",
      "             q  ",
      "             qf ",
      "            q   ",
      "            qf  ",
      "           qf   ",
      "          aaa   ",
      "           qf   ",
      "           qf   ",
      "          qf    ",
      "          qf    ",
      "          qf    ",
      "          qf    ",
      "         acgbcae",
      "          qf    "
    ],
    [
      "             a  ",
      "              e ",
      "              f ",
      "              f ",
      "             f  ",
      "             f  ",
      "            f   ",
      "          adg   ",
      "            f   ",
      "            f   ",
      "           f    ",
      "           f    ",
      "           f    ",
      "           f    ",
      "         adaaecc",
      "           f    "
    ],
    [
      "             a b",
      "              bi",
      "             cg ",
      "             cg ",
      "            aa  ",
      "            bg  ",
      "           eg   ",
      "          aba   ",
      "           ea   ",
      "           ea   ",
      "          ai    ",
      "          ea    ",
      "          cg    ",
      "          da    ",
      "         acacadc",
      "          bg    "
    ]
  ]
}