{
  "xsize": 16,
  "zsize": 16,
  "palette": {
    "palette": [
      {
        "char": " ",
        "block": "minecraft:air"
      },
      {
        "char": "c",
        "block": "minecraft:deepslate[axis=y]"
      },
      {
        "char": "b",
        "block": "minecraft:blackstone"
      },
      {
        "char": "d",
        "block": "minecraft:cobbled_deepslate"
      },
      {
        "char": "e",
        "block": "minecraft:basalt[axis=y]"
      },
      {
        "char": "a",
        "block": "minecraft:cyan_terracotta"
      },
      {
        "char": "你",
        "block": "minecraft:spawner",
        "tag": {
          "SpawnData": {
            "entity": {}
          },
          "MaxNearbyEntities": "6s",
          "MinSpawnDelay": "200s",
          "z": -274,
          "x": -42,
          "MaxSpawnDelay": "800s",
          "RequiredPlayerRange": "16s",
          "SpawnCount": "4s",
          "id": "minecraft:mob_spawner",
          "SpawnPotentials": [],
          "y": 1,
          "SpawnRange": "4s",
          "Delay": "731s"
        }
      },
      {
        "char": "等",
        "block": "minecraft:air"
      },
      {
        "char": "Z",
        "block": "minecraft:stone_brick_wall[east=tall,north=tall,south=none,up=true,waterlogged=false,weathering=false,west=tall]"
      },
      {
        "char": "G",
        "block": "minecraft:iron_bars[east=false,north=false,south=true,waterlogged=false,west=false]"
      },
      {
        "char": "H",
        "block": "minecraft:quartz_stairs[facing=south,half=bottom,shape=straight,waterlogged=false]"
      },
      {
        "char": "ϕ",
        "block": "minecraft:quartz_stairs[facing=north,half=bottom,shape=straight,waterlogged=false]"
      },
      {
        "char": "O",
        "block": "minecraft:quartz_stairs[facing=west,half=bottom,shape=straight,waterlogged=false]"
      },
      {
        "char": "ϓ",
        "block": "minecraft:air"
      },
      {
        "char": "x",
        "block": "minecraft:cauldron"
      },
      {
        "char": "v",
        "block": "minecraft:quartz_pillar[axis=x]"
      },
      {
        "char": "J",
        "block": "minecraft:diorite"
      },
      {
        "char": "n",
        "block": "minecraft:smooth_quartz"
      },
      {
        "char": "N",
        "block": "minecraft:white_stained_glass_pane[east=true,north=false,south=false,waterlogged=false,west=true]"
      },
      {
        "char": "Ѵ",
        "block": "minecraft:white_stained_glass_pane[east=false,north=false,south=false,waterlogged=false,west=true]"
      },
      {
        "char": "k",
        "block": "minecraft:oak_leaves[distance=7,persistent=true,waterlogged=false]"
      },
      {
        "char": "r",
        "block": "minecraft:polished_diorite"
      },
      {
        "char": "o",
        "block": "minecraft:chiseled_quartz_block"
      },
      {
        "char": "生",
        "block": "minecraft:white_stained_glass_pane[east=false,north=false,south=false,waterlogged=false,west=false]"
      },
      {
        "char": "j",
        "block": "minecraft:polished_andesite_slab[type=top,waterlogged=false]"
      }
    ]
  },
  "slices": [
    [
      "cbcdeadceecbeadd",
      "cbbaacdacabbbaad",
      "ecbecdbebbeaedca",
      "ababdacedebcbedb",
      "dceedcdabbdecbce",
      "abecbbbdcaedecab",
      "cdacbac你ccaeabad",
      "abbbaaedcaababdd",
      "abdcbcbcaedaacdd",
      "ecaebacdbaaadace",
      "ceedbecacbbadbca",
      "ebeedddbdadbdbbd",
      "等等ZaZZZdcdcdddce",
      "   e   aebdbdaeb",
      "   b   cabadcabb",
      " G e G eebbaabae"
    ],
    [
      " d      b  H    ",
      " d             ϕ",
      " c            Oϓ",
      " d      a      H",
      "ccecbedbb       ",
      " c  x  d        ",
      "       e        ",
      "             aad",
      "             e  ",
      "             d  ",
      "       c     d  ",
      "   e   a        ",
      "vJvevnvb        ",
      "   e   d     a  ",
      "   e   ab   eede",
      " G d G b     e  "
    ],
    [
      " e      b       ",
      " e              ",
      " b              ",
      " e      b       ",
      "cacNѴ bbc       ",
      " b  k  a        ",
      "       d        ",
      "             add",
      "             c  ",
      "             d  ",
      "       a     a  ",
      "   c   a        ",
      "vroevvva        ",
      "   c   c     b  ",
      "   b   de   bdee",
      " G b G c     b  "
    ],
    [
      " a      b       ",
      " a              ",
      " e              ",
      " a      c       ",
      "bdd 生 bba       ",
      " a  k  b        ",
      "       a        ",
      "             bda",
      "             a  ",
      "             e  ",
      "       d     b  ",
      "   a   d        ",
      "vvvavvJa        ",
      "   b   c     c  ",
      "   c   ae   aacd",
      " G b G e     c  "
    ],
    [
      " b      d       ",
      " c      j       ",
      " d      j       ",
      " a      b       ",
      "aecbbcbcb       ",
      " b     d        ",
      "       d        ",
      "       j     aaa",
      "       j     e  ",
      "       j     b  ",
      "       a     d  ",
      "jjjajjjd     j  ",
      "vvvevJva     j  ",
      "   a   c     e  ",
      "   a   dejjjedbd",
      " G e G c     a  "
    ],
    [
      " c      c       ",
      " b      b       ",
      " a      e       ",
      " e      d       ",
      "cbdcceedb       ",
      " a     c        ",
      "       a        ",
      "       c     bbb",
      "       b     a  ",
      "       d     a  ",
      "       e     d  ",
      "eeaeaecd     c  ",
      "   e   b     b  ",
      "   b   b     e  ",
      "   c   bcebabdee",
      " G a G d     c  "
    ]
  ]
}