{
  "xsize": 16,
  "zsize": 16,
  "palette": {
    "palette": [
      {
        "char": " ",
        "block": "minecraft:air"
      },
      {
        "char": "a",
        "block": "minecraft:cyan_terracotta"
      },
      {
        "char": "d",
        "block": "minecraft:cobbled_deepslate"
      },
      {
        "char": "c",
        "block": "minecraft:deepslate[axis=y]"
      },
      {
        "char": "b",
        "block": "minecraft:blackstone"
      },
      {
        "char": "e",
        "block": "minecraft:basalt[axis=y]"
      },
      {
        "char": "i",
        "block": "minecraft:light_gray_concrete"
      },
      {
        "char": "g",
        "block": "minecraft:gray_concrete"
      },
      {
        "char": "f",
        "block": "minecraft:glass"
      },
      {
        "char": "H",
        "block": "minecraft:quartz_stairs[facing=south,half=bottom,shape=straight,waterlogged=false]"
      },
      {
        "char": "W",
        "block": "minecraft:polished_andesite_stairs[facing=south,half=top,shape=straight,waterlogged=false]"
      },
      {
        "char": "ϐ",
        "block": "minecraft:air",
        "tag": {
          "z": -259,
          "x": -34,
          "id": "refurbished_furniture:computer",
          "y": -21,
          "NodePos": "-9070971985941L",
          "Connections": [
            "L"
          ]
        }
      },
      {
        "char": "l",
        "block": "minecraft:iron_trapdoor[facing=east,half=bottom,open=false,powered=false,waterlogged=false]"
      },
      {
        "char": "u",
        "block": "minecraft:iron_trapdoor[facing=south,half=bottom,open=false,powered=false,waterlogged=false]"
      },
      {
        "char": "w",
        "block": "minecraft:iron_trapdoor[facing=south,half=top,open=false,powered=false,waterlogged=false]"
      },
      {
        "char": "j",
        "block": "minecraft:polished_andesite_slab[type=top,waterlogged=false]"
      }
    ]
  },
  "slices": [
    [
      "adccbdbdeeaadeib",
      "abddaeacbdacaada",
      "edeecbadcbaacdai",
      "edeeecaagaaaaa  ",
      "aaaiaaabddga    ",
      "ebebde  ai      ",
      " g              ",
      "                ",
      " a       a    b ",
      "                ",
      "                ",
      "                ",
      "                ",
      "                ",
      "                ",
      "                "
    ],
    [
      "   eeb eda    f ",
      "    H   H   ffd ",
      " b        ff   g",
      " b      af      ",
      "fa fff  c       ",
      " c      g       ",
      " i              ",
      "                ",
      "WdWWWWWWWaWWWWd ",
      "                ",
      "                ",
      "                ",
      "                ",
      "                ",
      "                ",
      "                "
    ],
    [
      "    ϐ   ϐ     fl",
      "            ffe ",
      " e         fuu a",
      " d    ffafuu    ",
      "fiffffuueu      ",
      "ubuuuu  a       ",
      " a              ",
      "                ",
      "              d ",
      "                ",
      "                ",
      "                ",
      "                ",
      "                ",
      "                ",
      "                "
    ],
    [
      "               w",
      "             fd ",
      " b        ffww a",
      " d    f afww    ",
      "fa fffwwew      ",
      "wewwww  g       ",
      " g              ",
      "                ",
      "              b ",
      "                ",
      "                ",
      "                ",
      "                ",
      "                ",
      "                ",
      "                "
    ],
    [
      " j              ",
      " j          ffb ",
      " c        ff   g",
      " b      af      ",
      "fgfff   e       ",
      " b      a       ",
      " a              ",
      "                ",
      "              a ",
      "                ",
      "                ",
      "                ",
      "                ",
      "                ",
      "                ",
      "                "
    ],
    [
      " e            gc",
      " c          aac ",
      " a        aaeb a",
      " a    aaaacd    ",
      "aaaaiadacb      ",
      "edadea  a       ",
      " a              ",
      "                ",
      "              a ",
      "                ",
      "                ",
      "                ",
      "                ",
      "                ",
      "                ",
      "                "
    ]
  ]
}