{
  "xsize": 16,
  "zsize": 16,
  "palette": {
    "palette": [
      {
        "char": " ",
        "block": "minecraft:air"
      },
      {
        "char": "a",
        "block": "minecraft:cyan_terracotta"
      },
      {
        "char": "g",
        "block": "minecraft:gray_concrete"
      },
      {
        "char": "e",
        "block": "minecraft:basalt[axis=y]"
      },
      {
        "char": "b",
        "block": "minecraft:blackstone"
      },
      {
        "char": "d",
        "block": "minecraft:cobbled_deepslate"
      },
      {
        "char": "i",
        "block": "minecraft:light_gray_concrete"
      },
      {
        "char": "c",
        "block": "minecraft:deepslate[axis=y]"
      },
      {
        "char": "f",
        "block": "minecraft:glass"
      },
      {
        "char": "ϕ",
        "block": "minecraft:quartz_stairs[facing=north,half=bottom,shape=straight,waterlogged=false]"
      },
      {
        "char": "s",
        "block": "minecraft:iron_trapdoor[facing=north,half=bottom,open=false,powered=false,waterlogged=false]"
      },
      {
        "char": "m",
        "block": "minecraft:iron_trapdoor[facing=west,half=bottom,open=false,powered=false,waterlogged=false]"
      },
      {
        "char": "Ҝ",
        "block": "minecraft:air",
        "tag": {
          "z": -292,
          "x": -29,
          "id": "refurbished_furniture:computer",
          "y": 63,
          "NodePos": "-7696582590401L",
          "Connections": [
            "L"
          ]
        }
      },
      {
        "char": "p",
        "block": "minecraft:iron_trapdoor[facing=north,half=top,open=false,powered=false,waterlogged=false]"
      },
      {
        "char": "学",
        "block": "minecraft:air"
      }
    ]
  },
  "slices": [
    [
      "                ",
      "                ",
      "                ",
      "                ",
      "                ",
      "                ",
      "             aag",
      "         gaaaeba",
      "       aabbdaiii",
      "     ggaaagagede",
      "   aaadiacabdcbb",
      "  agcgaceddedcdc",
      " aadaeaddecdadbd",
      "aciiccbdecbccadd",
      "aaaccbedacabdaed",
      "accddacccdcbddce"
    ],
    [
      "                ",
      "                ",
      "                ",
      "                ",
      "                ",
      "                ",
      "                ",
      "          i     ",
      "          e  fff",
      "         fgff   ",
      "   a   ff e     ",
      "    eff   c     ",
      "    f     a ϕ   ",
      "  ff      a   b ",
      " f        bebea ",
      "f    c    e     "
    ],
    [
      "                ",
      "                ",
      "                ",
      "                ",
      "                ",
      "                ",
      "                ",
      "          a  sss",
      "         sass ff",
      "       ssfaf    ",
      "   a ssff a     ",
      "    df    c     ",
      "  ss      d     ",
      " sf       d     ",
      "mf        b Ҝ   ",
      "f         b     "
    ],
    [
      "                ",
      "                ",
      "                ",
      "                ",
      "                ",
      "                ",
      "                ",
      "          a  ppp",
      "         pappfff",
      "       ppfa f   ",
      "   a ppff b     ",
      "    d f   e     ",
      "  p学      b     ",
      " pff      c     ",
      "pf        b     ",
      "          e     "
    ],
    [
      "                ",
      "                ",
      "                ",
      "                ",
      "                ",
      "                ",
      "                ",
      "          g     ",
      "          c  fff",
      "          gf    ",
      "   a    f a     ",
      "    bff   d     ",
      "    f     a     ",
      "  ff      a     ",
      " f        c     ",
      "          d     "
    ],
    [
      "                ",
      "                ",
      "                ",
      "                ",
      "                ",
      "                ",
      "                ",
      "          a  ccc",
      "         dbabaai",
      "       ddaaia   ",
      "   i bcaa e     ",
      "    ega   b     ",
      "  dca     e     ",
      " eaa      d     ",
      "ba        a     ",
      "a         a     "
    ]
  ]
}