{
  "xsize": 16,
  "zsize": 16,
  "palette": {
    "palette": [
      {
        "char": " ",
        "block": "minecraft:air"
      },
      {
        "char": "c",
        "block": "minecraft:deepslate[axis=y]"
      },
      {
        "char": "d",
        "block": "minecraft:cobbled_deepslate"
      },
      {
        "char": "b",
        "block": "minecraft:blackstone"
      },
      {
        "char": "e",
        "block": "minecraft:basalt[axis=y]"
      },
      {
        "char": "a",
        "block": "minecraft:cyan_terracotta"
      },
      {
        "char": "g",
        "block": "minecraft:gray_concrete"
      },
      {
        "char": "i",
        "block": "minecraft:light_gray_concrete"
      },
      {
        "char": "ϔ",
        "block": "minecraft:quartz_stairs[facing=east,half=bottom,shape=straight,waterlogged=false]"
      },
      {
        "char": "f",
        "block": "minecraft:glass"
      },
      {
        "char": "x",
        "block": "minecraft:cauldron"
      },
      {
        "char": "H",
        "block": "minecraft:quartz_stairs[facing=south,half=bottom,shape=straight,waterlogged=false]"
      },
      {
        "char": "Ӻ",
        "block": "minecraft:air",
        "tag": {
          "z": -276,
          "x": -15,
          "id": "refurbished_furniture:computer",
          "y": 27,
          "NodePos": "-3848291827685L",
          "Connections": [
            "L"
          ]
        }
      },
      {
        "char": "l",
        "block": "minecraft:iron_trapdoor[facing=east,half=bottom,open=false,powered=false,waterlogged=false]"
      },
      {
        "char": "k",
        "block": "minecraft:oak_leaves[distance=7,persistent=true,waterlogged=false]"
      },
      {
        "char": "ϐ",
        "block": "minecraft:air",
        "tag": {
          "z": -259,
          "x": -34,
          "id": "refurbished_furniture:computer",
          "y": -21,
          "NodePos": "-9070971985941L",
          "Connections": [
            "L"
          ]
        }
      },
      {
        "char": "u",
        "block": "minecraft:iron_trapdoor[facing=south,half=bottom,open=false,powered=false,waterlogged=false]"
      },
      {
        "char": "t",
        "block": "minecraft:iron_trapdoor[facing=east,half=top,open=false,powered=false,waterlogged=false]"
      },
      {
        "char": "w",
        "block": "minecraft:iron_trapdoor[facing=south,half=top,open=false,powered=false,waterlogged=false]"
      }
    ]
  },
  "slices": [
    [
      "cdbeeecab       ",
      "daabaabaa       ",
      "caaabebab       ",
      "bccbedga        ",
      "abadceab        ",
      "abcdbdaea       ",
      "becabegea       ",
      "baaecaea        ",
      "cedbcgca        ",
      "ceceaaa         ",
      "dbdcada         ",
      "beaaca          ",
      "dbaaaa          ",
      "ababg           ",
      "aaai            ",
      "aca             "
    ],
    [
      "e ϔ             ",
      "d      f        ",
      "cae    f        ",
      "      f         ",
      "                ",
      "badeccgaa       ",
      "  x   f         ",
      "                ",
      "                ",
      "                ",
      "da  f           ",
      "H  fb           ",
      "  f  a          ",
      "  f             ",
      " f              ",
      "f               "
    ],
    [
      "Ӻ      fl       ",
      "       fl       ",
      "       fl       ",
      "      fl        ",
      "      fl        ",
      "cedadbgbg       ",
      "  k    l        ",
      "     fl         ",
      "     fl         ",
      "    fl          ",
      "ϐ   fl          ",
      "   fa           ",
      "  fu a          ",
      "  fl            ",
      " fl             ",
      " l              "
    ],
    [
      "       ft       ",
      "        t       ",
      "       ft       ",
      "      ft        ",
      "      ft        ",
      "eacaababa       ",
      "  k   ft        ",
      "     ft         ",
      "     ft         ",
      "     t          ",
      "    ft          ",
      "   fd           ",
      "  fw a          ",
      "  ft            ",
      " ft             ",
      "fw              "
    ],
    [
      "       f        ",
      "       f        ",
      "                ",
      "      f         ",
      "      f         ",
      "eceebbaea       ",
      "                ",
      "                ",
      "     f          ",
      "                ",
      "    f           ",
      "   fb           ",
      "  f  i          ",
      "                ",
      " f              ",
      "f               "
    ],
    [
      "       ga       ",
      "       ab       ",
      "       ab       ",
      "      gc        ",
      "      ae        ",
      "dbaedcida       ",
      "      ab        ",
      "     ae         ",
      "     aa         ",
      "    ab          ",
      "    ga          ",
      "   aa           ",
      "  ae g          ",
      "  ab            ",
      " ib             ",
      "ga              "
    ]
  ]
}