{
  "xsize": 16,
  "zsize": 16,
  "palette": {
    "palette": [
      {
        "char": " ",
        "block": "minecraft:air"
      },
      {
        "char": "d",
        "block": "minecraft:cobbled_deepslate"
      },
      {
        "char": "b",
        "block": "minecraft:blackstone"
      },
      {
        "char": "a",
        "block": "minecraft:cyan_terracotta"
      },
      {
        "char": "c",
        "block": "minecraft:deepslate[axis=y]"
      },
      {
        "char": "e",
        "block": "minecraft:basalt[axis=y]"
      },
      {
        "char": "你",
        "block": "minecraft:spawner",
        "tag": {
          "SpawnData": {
            "entity": {}
          },
          "MaxNearbyEntities": "6s",
          "MinSpawnDelay": "200s",
          "z": -274,
          "x": -42,
          "MaxSpawnDelay": "800s",
          "RequiredPlayerRange": "16s",
          "SpawnCount": "4s",
          "id": "minecraft:mob_spawner",
          "SpawnPotentials": [],
          "y": 1,
          "SpawnRange": "4s",
          "Delay": "731s"
        }
      },
      {
        "char": "Ӿ",
        "block": "minecraft:cobblestone_wall[east=tall,north=tall,south=none,up=true,waterlogged=false,weathering=false,west=tall]"
      },
      {
        "char": "Z",
        "block": "minecraft:stone_brick_wall[east=tall,north=tall,south=none,up=true,waterlogged=false,weathering=false,west=tall]"
      },
      {
        "char": "G",
        "block": "minecraft:iron_bars[east=false,north=false,south=true,waterlogged=false,west=false]"
      },
      {
        "char": "H",
        "block": "minecraft:quartz_stairs[facing=south,half=bottom,shape=straight,waterlogged=false]"
      },
      {
        "char": "ϕ",
        "block": "minecraft:quartz_stairs[facing=north,half=bottom,shape=straight,waterlogged=false]"
      },
      {
        "char": "O",
        "block": "minecraft:quartz_stairs[facing=west,half=bottom,shape=straight,waterlogged=false]"
      },
      {
        "char": "ϓ",
        "block": "minecraft:air"
      },
      {
        "char": "x",
        "block": "minecraft:cauldron"
      },
      {
        "char": "然",
        "block": "minecraft:air"
      },
      {
        "char": "者",
        "block": "minecraft:air"
      },
      {
        "char": "见",
        "block": "minecraft:air"
      },
      {
        "char": "谢",
        "block": "minecraft:air"
      },
      {
        "char": "水",
        "block": "minecraft:air"
      },
      {
        "char": "v",
        "block": "minecraft:quartz_pillar[axis=x]"
      },
      {
        "char": "J",
        "block": "minecraft:diorite"
      },
      {
        "char": "N",
        "block": "minecraft:white_stained_glass_pane[east=true,north=false,south=false,waterlogged=false,west=true]"
      },
      {
        "char": "k",
        "block": "minecraft:oak_leaves[distance=7,persistent=true,waterlogged=false]"
      },
      {
        "char": "r",
        "block": "minecraft:polished_diorite"
      },
      {
        "char": "n",
        "block": "minecraft:smooth_quartz"
      },
      {
        "char": "j",
        "block": "minecraft:polished_andesite_slab[type=top,waterlogged=false]"
      },
      {
        "char": "o",
        "block": "minecraft:chiseled_quartz_block"
      }
    ]
  },
  "slices": [
    [
      "dbadcbbeacadbadc",
      "cbcccabdbbbddeda",
      "cdadeddbddcdecbe",
      "dbaecdbcbbcaccea",
      "ecdbcecacebeaecd",
      "addacdcdcdaacdae",
      "cdbcedbeccdbcecd",
      "ddbeacddeedac你eb",
      "ebebccddabbeeaba",
      "cbeecbbdbcdcacbc",
      "bbcaaeddddeaeebe",
      "becbeebdabcdbbba",
      "ӾZZeZZZddebecebd",
      "   e   dbddaacdd",
      "   a   ebeedcbec",
      " G c G abcbaddcc"
    ],
    [
      " d      d  H    ",
      " b             ϕ",
      " c            Oϓ",
      " d      a      H",
      "bdeebbeae       ",
      " d  x  d        ",
      "       c        ",
      "          然  dbe",
      "        者见谢  b  ",
      "        水    b  ",
      "       a     a  ",
      "   b   c        ",
      "vvvcvJva        ",
      "   c   d     b  ",
      "   e   aa   eceb",
      " G b G a     c  "
    ],
    [
      " e      c       ",
      " e              ",
      " d              ",
      " b      b       ",
      "bcbNNNaae       ",
      " e  k  b        ",
      "       c        ",
      "             ecc",
      "             c  ",
      "             a  ",
      "       a     e  ",
      "   a   e        ",
      "vvvbrvvc        ",
      "   d   b     b  ",
      "   b   ac   aede",
      " G a G c     a  "
    ],
    [
      " b      a       ",
      " a              ",
      " c              ",
      " d      a       ",
      "bcdNNNcdc       ",
      " a  k  c        ",
      "       e        ",
      "             ede",
      "             a  ",
      "             e  ",
      "       a     d  ",
      "   e   a        ",
      "vrvdvvne        ",
      "   a   c     a  ",
      "   e   cb   aeae",
      " G a G b     d  "
    ],
    [
      " c      b       ",
      " b      j       ",
      " e      j       ",
      " c      e       ",
      "aceaaeacc       ",
      " a     c        ",
      "       b        ",
      "       j     bbe",
      "       j     d  ",
      "       j     a  ",
      "       a     c  ",
      "jjjdjjje     j  ",
      "ovJcrnve     j  ",
      "   c   b     d  ",
      "   d   acjjjbabb",
      " G c G e     e  "
    ],
    [
      " b      a       ",
      " c      e       ",
      " c      e       ",
      " e      e       ",
      "ddebdbaeb       ",
      " e     e        ",
      "       d        ",
      "       d     eba",
      "       d     c  ",
      "       e     b  ",
      "       a     d  ",
      "baecdacd     e  ",
      "   a   c     e  ",
      "   a   c     e  ",
      "   c   accbaaece",
      " G b G e     b  "
    ]
  ]
}