{
  "xsize": 16,
  "zsize": 16,
  "palette": {
    "palette": [
      {
        "char": " ",
        "block": "minecraft:air"
      },
      {
        "char": "F",
        "block": "minecraft:light_blue_terracotta"
      },
      {
        "char": "E",
        "block": "minecraft:red_terracotta"
      },
      {
        "char": "A",
        "block": "minecraft:red_concrete"
      },
      {
        "char": "东",
        "block": "minecraft:air"
      },
      {
        "char": "b",
        "block": "minecraft:blackstone"
      },
      {
        "char": "e",
        "block": "minecraft:basalt[axis=y]"
      },
      {
        "char": "ѱ",
        "block": "minecraft:brown_carpet"
      },
      {
        "char": "a",
        "block": "minecraft:cyan_terracotta"
      },
      {
        "char": "c",
        "block": "minecraft:deepslate[axis=y]"
      },
      {
        "char": "d",
        "block": "minecraft:cobbled_deepslate"
      },
      {
        "char": "ӿ",
        "block": "minecraft:black_concrete"
      },
      {
        "char": "重",
        "block": "minecraft:air"
      },
      {
        "char": "把",
        "block": "minecraft:air"
      },
      {
        "char": "名",
        "block": "minecraft:dark_oak_fence_gate[facing=north,in_wall=false,open=true,powered=false]"
      },
      {
        "char": "主",
        "block": "minecraft:birch_wall_sign[facing=north,waterlogged=false]",
        "tag": {
          "z": -273,
          "x": -31,
          "is_waxed": "0b",
          "id": "minecraft:sign",
          "y": 85,
          "front_text": {
            "color": "black",
            "has_glowing_text": "0b",
            "messages": [
              "{\"text\":\"Start News\"}",
              "{\"text\":\"Broadcast\"}",
              "{\"text\":\"\"}",
              "{\"text\":\"VVVVVV\"}"
            ]
          },
          "back_text": {
            "color": "black",
            "has_glowing_text": "0b",
            "messages": [
              "{\"text\":\"\"}",
              "{\"text\":\"\"}",
              "{\"text\":\"\"}",
              "{\"text\":\"\"}"
            ]
          }
        }
      },
      {
        "char": "ӟ",
        "block": "minecraft:iron_bars[east=true,north=false,south=true,waterlogged=false,west=true]"
      },
      {
        "char": "X",
        "block": "minecraft:red_wool"
      },
      {
        "char": "吧",
        "block": "minecraft:air"
      },
      {
        "char": "N",
        "block": "minecraft:white_stained_glass_pane[east=true,north=false,south=false,waterlogged=false,west=true]"
      },
      {
        "char": "Ѵ",
        "block": "minecraft:white_stained_glass_pane[east=false,north=false,south=false,waterlogged=false,west=true]"
      },
      {
        "char": "生",
        "block": "minecraft:white_stained_glass_pane[east=false,north=false,south=false,waterlogged=false,west=false]"
      },
      {
        "char": "Ѳ",
        "block": "minecraft:white_stained_glass_pane[east=true,north=false,south=false,waterlogged=false,west=false]"
      },
      {
        "char": "S",
        "block": "minecraft:orange_terracotta"
      },
      {
        "char": "国",
        "block": "minecraft:air"
      },
      {
        "char": "ϑ",
        "block": "minecraft:orange_concrete"
      },
      {
        "char": "ӡ",
        "block": "minecraft:orange_wool"
      }
    ]
  },
  "slices": [
    [
      "      FFEA      ",
      "        FFAE    ",
      "          FFA   ",
      " 东         beE  ",
      "   ѱѱ        aA ",
      "ѱѱѱѱ         cE ",
      "              bA",
      "              eA",
      "               e",
      "           a   d",
      "                ",
      " ӿ              ",
      "重ӿ把             ",
      " 名              ",
      "                ",
      "主主主    d   c    "
    ],
    [
      "      FFEA      ",
      "        FFӟA    ",
      "          FFA   ",
      "           caE  ",
      "             dE ",
      "             dE ",
      "              dA",
      "              aE",
      "               b",
      "           c   a",
      "                ",
      "                ",
      "                ",
      "                ",
      "                ",
      "       bedae    "
    ],
    [
      "      FFAE      ",
      "        FFAA    ",
      "          FFE   ",
      "           ceA  ",
      "             bE ",
      "             dE ",
      "              bE",
      "              dA",
      "               d",
      "           e   d",
      "                ",
      "                ",
      "                ",
      "                ",
      "                ",
      "                "
    ],
    [
      "      FFAX      ",
      "        FFAX    ",
      "          FFE   ",
      "           deX  ",
      "             eA ",
      "             c吧 ",
      "              bX",
      "              dA",
      "               e",
      "           c   e",
      "                ",
      "                ",
      "                ",
      "                ",
      "                ",
      "beedecdecabccdcc"
    ],
    [
      "      FFAA      ",
      "        FFEA    ",
      "          FFA   ",
      "           abA  ",
      "             aE ",
      "             aE ",
      "              bA",
      "              dA",
      "               e",
      "           a   a",
      "                ",
      "                ",
      "                ",
      "                ",
      "                ",
      "NNNѴ  生    ѲѴ  e"
    ],
    [
      "      FFS国      ",
      "        FFSϑ    ",
      "          FFS   ",
      "           deS  ",
      "             b国 ",
      "             bS ",
      "              aӡ",
      "              bϑ",
      "               a",
      "           a   b",
      "                ",
      "                ",
      "                ",
      "                ",
      "                ",
      " ѲѴ  ѲNNNNѴ ѲNNc"
    ]
  ]
}