{
  "xsize": 16,
  "zsize": 16,
  "palette": {
    "palette": [
      {
        "char": " ",
        "block": "minecraft:air"
      },
      {
        "char": "a",
        "block": "minecraft:cyan_terracotta"
      },
      {
        "char": "c",
        "block": "minecraft:deepslate[axis=y]"
      },
      {
        "char": "b",
        "block": "minecraft:blackstone"
      },
      {
        "char": "d",
        "block": "minecraft:cobbled_deepslate"
      },
      {
        "char": "e",
        "block": "minecraft:basalt[axis=y]"
      },
      {
        "char": "Z",
        "block": "minecraft:stone_brick_wall[east=tall,north=tall,south=none,up=true,waterlogged=false,weathering=false,west=tall]"
      },
      {
        "char": "G",
        "block": "minecraft:iron_bars[east=false,north=false,south=true,waterlogged=false,west=false]"
      },
      {
        "char": "H",
        "block": "minecraft:quartz_stairs[facing=south,half=bottom,shape=straight,waterlogged=false]"
      },
      {
        "char": "ϕ",
        "block": "minecraft:quartz_stairs[facing=north,half=bottom,shape=straight,waterlogged=false]"
      },
      {
        "char": "O",
        "block": "minecraft:quartz_stairs[facing=west,half=bottom,shape=straight,waterlogged=false]"
      },
      {
        "char": "ϓ",
        "block": "minecraft:air"
      },
      {
        "char": "x",
        "block": "minecraft:cauldron"
      },
      {
        "char": "v",
        "block": "minecraft:quartz_pillar[axis=x]"
      },
      {
        "char": "o",
        "block": "minecraft:chiseled_quartz_block"
      },
      {
        "char": "n",
        "block": "minecraft:smooth_quartz"
      },
      {
        "char": "N",
        "block": "minecraft:white_stained_glass_pane[east=true,north=false,south=false,waterlogged=false,west=true]"
      },
      {
        "char": "k",
        "block": "minecraft:oak_leaves[distance=7,persistent=true,waterlogged=false]"
      },
      {
        "char": "r",
        "block": "minecraft:polished_diorite"
      },
      {
        "char": "Ѳ",
        "block": "minecraft:white_stained_glass_pane[east=true,north=false,south=false,waterlogged=false,west=false]"
      },
      {
        "char": "j",
        "block": "minecraft:polished_andesite_slab[type=top,waterlogged=false]"
      }
    ]
  },
  "slices": [
    [
      "acaabcdcdeadbdcb",
      "adeebdebceeeedae",
      "cebacedeabcbbecb",
      "dcdeaabcdaaccebb",
      "bddeacbacdcaeaac",
      "ddecddceaeececbb",
      "dddeecbebcdbabdc",
      "beacbebbadebcdcd",
      "eaedcbcebbaadcbc",
      "bcdbddcdbdadbedb",
      "aeaecaabcbeeeeca",
      "aaeccceeccddadab",
      "ZZZbZZZaebbdadba",
      "   e   accaedeab",
      "   a   baaedbbad",
      " G b G ccbeadbbc"
    ],
    [
      " a      e  H    ",
      " e             ϕ",
      " a            Oϓ",
      " b      e      H",
      "bccddabcc       ",
      " e  x  e        ",
      "       d        ",
      "             dad",
      "             e  ",
      "             b  ",
      "       e     e  ",
      "   d   c        ",
      "vovcvnva        ",
      "   a   d     b  ",
      "   e   ab   bdee",
      " G b G c     b  "
    ],
    [
      " a      a       ",
      " c              ",
      " a              ",
      " c      c       ",
      "eddNNNaad       ",
      " a  k  e        ",
      "       c        ",
      "             aea",
      "             e  ",
      "             c  ",
      "       d     d  ",
      "   b   d        ",
      "vvvcrvrd        ",
      "   e   a     d  ",
      "   a   cb   caea",
      " G c G d     d  "
    ],
    [
      " b      a       ",
      " b              ",
      " d              ",
      " c      c       ",
      "edc ѲNedd       ",
      " e  k  c        ",
      "       c        ",
      "             ddc",
      "             e  ",
      "             c  ",
      "       a     c  ",
      "   a   a        ",
      "vvvcrvvb        ",
      "   a   d     c  ",
      "   d   dd   aeeb",
      " G d G b     d  "
    ],
    [
      " a      b       ",
      " a      j       ",
      " a      j       ",
      " c      d       ",
      "bdedebddc       ",
      " e     b        ",
      "       c        ",
      "       j     cbd",
      "       j     a  ",
      "       j     c  ",
      "       a     c  ",
      "jjjcjjje     j  ",
      "vvvavvvc     j  ",
      "   c   b     e  ",
      "   d   aejjjccea",
      " G a G a     e  "
    ],
    [
      " a      d       ",
      " c      d       ",
      " b      b       ",
      " d      a       ",
      "aeeebbebc       ",
      " d     c        ",
      "       d        ",
      "       b     cec",
      "       e     c  ",
      "       a     e  ",
      "       a     c  ",
      "dadaadbe     d  ",
      "   b   d     e  ",
      "   e   c     e  ",
      "   d   acbdbeebc",
      " G d G e     b  "
    ]
  ]
}