{
  "xsize": 16,
  "zsize": 16,
  "palette": {
    "palette": [
      {
        "char": " ",
        "block": "minecraft:air"
      },
      {
        "char": "a",
        "block": "minecraft:cyan_terracotta"
      },
      {
        "char": "c",
        "block": "minecraft:deepslate[axis=y]"
      },
      {
        "char": "d",
        "block": "minecraft:cobbled_deepslate"
      },
      {
        "char": "b",
        "block": "minecraft:blackstone"
      },
      {
        "char": "e",
        "block": "minecraft:basalt[axis=y]"
      },
      {
        "char": "小",
        "block": "minecraft:air"
      },
      {
        "char": "z",
        "block": "minecraft:iron_bars[east=false,north=true,south=true,waterlogged=false,west=false]"
      },
      {
        "char": "你",
        "block": "minecraft:spawner",
        "tag": {
          "SpawnData": {
            "entity": {}
          },
          "MaxNearbyEntities": "6s",
          "MinSpawnDelay": "200s",
          "z": -274,
          "x": -42,
          "MaxSpawnDelay": "800s",
          "RequiredPlayerRange": "16s",
          "SpawnCount": "4s",
          "id": "minecraft:mob_spawner",
          "SpawnPotentials": [],
          "y": 1,
          "SpawnRange": "4s",
          "Delay": "731s"
        }
      },
      {
        "char": "Y",
        "block": "minecraft:iron_bars[east=false,north=true,south=false,waterlogged=false,west=false]"
      },
      {
        "char": "f",
        "block": "minecraft:glass"
      },
      {
        "char": "O",
        "block": "minecraft:quartz_stairs[facing=west,half=bottom,shape=straight,waterlogged=false]"
      },
      {
        "char": "x",
        "block": "minecraft:cauldron"
      },
      {
        "char": "П",
        "block": "minecraft:barrel[facing=up,open=false]",
        "tag": {
          "z": -275,
          "x": -15,
          "ForgeData": {
            "LockFlag": "1b"
          },
          "id": "minecraft:barrel",
          "y": 2,
          "Items": []
        }
      },
      {
        "char": "У",
        "block": "minecraft:stone_brick_stairs[facing=south,half=bottom,shape=straight,waterlogged=false,weathering=false]"
      },
      {
        "char": "С",
        "block": "minecraft:stone_brick_stairs[facing=north,half=top,shape=straight,waterlogged=false,weathering=false]"
      },
      {
        "char": "Ѫ",
        "block": "minecraft:air"
      },
      {
        "char": "Ӝ",
        "block": "minecraft:air"
      },
      {
        "char": "N",
        "block": "minecraft:white_stained_glass_pane[east=true,north=false,south=false,waterlogged=false,west=true]"
      },
      {
        "char": "k",
        "block": "minecraft:oak_leaves[distance=7,persistent=true,waterlogged=false]"
      },
      {
        "char": "到",
        "block": "minecraft:air"
      },
      {
        "char": "来",
        "block": "minecraft:air"
      },
      {
        "char": "у",
        "block": "minecraft:stone_brick_stairs[facing=south,half=top,shape=straight,waterlogged=false,weathering=false]"
      },
      {
        "char": "j",
        "block": "minecraft:polished_andesite_slab[type=top,waterlogged=false]"
      },
      {
        "char": "Р",
        "block": "minecraft:stone_brick_stairs[facing=north,half=bottom,shape=straight,waterlogged=false,weathering=false]"
      }
    ]
  },
  "slices": [
    [
      "acdbdebeabdcadcd",
      "cadbaaaabbdeadce",
      "daceeaacbcccbeec",
      "bcdcecaeaaaceeba",
      "deccbccbeeaaaedd",
      "cdbecdccebdacadb",
      "edbaaddacaaaeacd",
      "acdccdddcddaeced",
      "caabcadeccceedbe",
      "adbadbeeddecebaa",
      "bccdeeecbabeabab",
      "cbadcdaebacccdec",
      "ebddecaeeacd小z d",
      "cabaccadbbbe z b",
      "cbcddc你dbbcb Y c",
      "acdadaaddbbe   a"
    ],
    [
      "f   Od    e     ",
      "     c          ",
      "                ",
      "  e  c    b     ",
      " Oe Oc    ddbdec",
      "  b  b     a  x ",
      "           b    ",
      "  b  c          ",
      " Oe Ob          ",
      "  c  П          ",
      "           a    ",
      "  b  a     c b a",
      " Oc Od     e zУb",
      "  b  d     c zСb",
      "aebbccd   bb Y c",
      "  b  a     c   d"
    ],
    [
      "f    Ѫ    a     ",
      "     Ӝ          ",
      "                ",
      "          b     ",
      "  Ѫ  Ѫ    eebNNN",
      "  Ӝ  Ӝ     e  k ",
      "           b    ",
      "                ",
      "  到  Ѫ          ",
      "  来  Ӝ          ",
      "           e    ",
      "           e e c",
      "  Ѫ  到     b z b",
      "  Ӝ  来     e zУb",
      "beecbda   ce YСa",
      "     e     b   a"
    ],
    [
      "f         e     ",
      "                ",
      "                ",
      "          e     ",
      "          aceNNN",
      "           e  k ",
      "           d    ",
      "                ",
      "                ",
      "                ",
      "           d    ",
      "           e e b",
      "           b z c",
      "           e z e",
      "deeccbe   caуzУd",
      "     b     baaeb"
    ],
    [
      "f         d     ",
      "          j     ",
      "          j     ",
      "          e     ",
      "          edebdc",
      "           c    ",
      "           d    ",
      "           j    ",
      "           j    ",
      "           j    ",
      "           a    ",
      "           dbbca",
      "           b z e",
      "           eуz c",
      "abaececjjjaeРY c",
      "     c     d   d"
    ],
    [
      "a         b     ",
      "          b     ",
      "          a     ",
      "          e     ",
      "          eecbab",
      "           d    ",
      "           e    ",
      "           b    ",
      "           b    ",
      "           b    ",
      "           e    ",
      "           bdbea",
      "           dуz e",
      "           eРz a",
      "abcacecaddbc Y c",
      "     d     c   b"
    ]
  ]
}