{
  "xsize": 16,
  "zsize": 16,
  "palette": {
    "palette": [
      {
        "char": " ",
        "block": "minecraft:air"
      },
      {
        "char": "c",
        "block": "minecraft:deepslate[axis=y]"
      },
      {
        "char": "e",
        "block": "minecraft:basalt[axis=y]"
      },
      {
        "char": "d",
        "block": "minecraft:cobbled_deepslate"
      },
      {
        "char": "b",
        "block": "minecraft:blackstone"
      },
      {
        "char": "a",
        "block": "minecraft:cyan_terracotta"
      },
      {
        "char": "Z",
        "block": "minecraft:stone_brick_wall[east=tall,north=tall,south=none,up=true,waterlogged=false,weathering=false,west=tall]"
      },
      {
        "char": "G",
        "block": "minecraft:iron_bars[east=false,north=false,south=true,waterlogged=false,west=false]"
      },
      {
        "char": "f",
        "block": "minecraft:glass"
      },
      {
        "char": "x",
        "block": "minecraft:cauldron"
      },
      {
        "char": "n",
        "block": "minecraft:smooth_quartz"
      },
      {
        "char": "v",
        "block": "minecraft:quartz_pillar[axis=x]"
      },
      {
        "char": "J",
        "block": "minecraft:diorite"
      },
      {
        "char": "s",
        "block": "minecraft:iron_trapdoor[facing=north,half=bottom,open=false,powered=false,waterlogged=false]"
      },
      {
        "char": "l",
        "block": "minecraft:iron_trapdoor[facing=east,half=bottom,open=false,powered=false,waterlogged=false]"
      },
      {
        "char": "k",
        "block": "minecraft:oak_leaves[distance=7,persistent=true,waterlogged=false]"
      },
      {
        "char": "Ӟ",
        "block": "minecraft:air"
      },
      {
        "char": "p",
        "block": "minecraft:iron_trapdoor[facing=north,half=top,open=false,powered=false,waterlogged=false]"
      },
      {
        "char": "在",
        "block": "minecraft:air"
      },
      {
        "char": "C",
        "block": "minecraft:quartz_pillar[axis=y]"
      },
      {
        "char": "r",
        "block": "minecraft:polished_diorite"
      },
      {
        "char": "I",
        "block": "minecraft:stone_slab[type=top,waterlogged=false,weathering=false]"
      },
      {
        "char": "j",
        "block": "minecraft:polished_andesite_slab[type=top,waterlogged=false]"
      },
      {
        "char": "K",
        "block": "minecraft:quartz_block"
      }
    ]
  },
  "slices": [
    [
      "cccedbadaa      ",
      "dcdccbceabdb    ",
      "ccecbbaccdcdc   ",
      "aeccaccbaddbbd  ",
      "aeddbbbdecaadcb ",
      "aaadcddaeeabacd ",
      "cdeecabeacdbebdb",
      "bccabcabccbadeee",
      "aedbeaddddaedabd",
      "eeebdcbabbebeddb",
      "ceacaecbbabdddbb",
      "cbbdddecabcecaea",
      "ZZZcZZZbecdcdacb",
      "   b   edddccabd",
      "   c   bbeaedaea",
      " G c G eabdebede"
    ],
    [
      " e       b      ",
      "         d      ",
      "          f     ",
      "            f   ",
      " a              ",
      "xax          f  ",
      " e      x     ee",
      "bdcb   bebccbbcb",
      "          x  x  ",
      "                ",
      "                ",
      "   e   e        ",
      "nvnbvJvb        ",
      "   b   b        ",
      "   d   da      d",
      " G b G d        "
    ],
    [
      " c       c      ",
      "         dss    ",
      "          f s   ",
      "            fl  ",
      " a           fl ",
      "kbk           Ӟ ",
      " b      k     ce",
      "ccab   beedadeab",
      "          k  k  ",
      "                ",
      "                ",
      "   d   b        ",
      "nnvavvne        ",
      "   c   c        ",
      "   c   ca      b",
      " G e G e        "
    ],
    [
      " e       d      ",
      "         cpp    ",
      "          ffp   ",
      "            fp  ",
      " b            在 ",
      "kdk          fp ",
      " c      k     de",
      "adde   ebcccccbb",
      "          k  k  ",
      "                ",
      "                ",
      "   a   c        ",
      "vJCdvvre        ",
      "   e   b        ",
      "   b   ee      d",
      " G b G b        "
    ],
    [
      " c       b      ",
      " I       a      ",
      " I        f     ",
      " I          f   ",
      " b              ",
      " d              ",
      " a            ab",
      "bdccIIIbeacaebed",
      "                ",
      "                ",
      "                ",
      "jjjejjjc        ",
      "vKCervvb        ",
      "   b   c        ",
      "   a   ecIIIIIIe",
      " G a G e        "
    ],
    [
      " d       c      ",
      " b        ee    ",
      " a        bbd   ",
      " d          cb  ",
      " a           bc ",
      " d           ea ",
      " b             d",
      "cedbdeeaaecaebeb",
      "                ",
      "                ",
      "                ",
      "eeeedecb        ",
      "   c   d        ",
      "   b   b        ",
      "   d   aecdcebdb",
      " G d G e        "
    ]
  ]
}