{
  "xsize": 16,
  "zsize": 16,
  "palette": {
    "palette": [
      {
        "char": " ",
        "block": "minecraft:air"
      },
      {
        "char": "b",
        "block": "minecraft:blackstone"
      },
      {
        "char": "c",
        "block": "minecraft:deepslate[axis=y]"
      },
      {
        "char": "e",
        "block": "minecraft:basalt[axis=y]"
      },
      {
        "char": "a",
        "block": "minecraft:cyan_terracotta"
      },
      {
        "char": "d",
        "block": "minecraft:cobbled_deepslate"
      },
      {
        "char": "x",
        "block": "minecraft:cauldron"
      },
      {
        "char": "k",
        "block": "minecraft:oak_leaves[distance=7,persistent=true,waterlogged=false]"
      },
      {
        "char": "I",
        "block": "minecraft:stone_slab[type=top,waterlogged=false,weathering=false]"
      }
    ]
  },
  "slices": [
    [
      "bbcceabeaacdedea",
      "dcadaecdacdec   ",
      "baeeedcbbdbc    ",
      "dbbcedcebba     ",
      "caaedcccaa      ",
      "ccccdbeabc      ",
      "abbeedadeb      ",
      "ccaeedaccd      ",
      "acebceaade      ",
      "dbdbaeeeeab     ",
      "aeabcdcc        ",
      "aeeadba         ",
      "aeeacab         ",
      "aabbcca         ",
      "cebccdd         ",
      "dbebd           "
    ],
    [
      "ccabbeac        ",
      " d              ",
      " e              ",
      " a              ",
      "dda   dee       ",
      " b      b       ",
      "        a       ",
      "       xb       ",
      "        d       ",
      "      be        ",
      "     cda        ",
      "     ae         ",
      " b   cc         ",
      "edd  a          ",
      " e              ",
      " b ad           "
    ],
    [
      "dcacabbe        ",
      " c              ",
      " a              ",
      " d              ",
      "bec   aad       ",
      " a      b       ",
      "        c       ",
      "       ke       ",
      "        e       ",
      "                ",
      "      b         ",
      "      c         ",
      " d              ",
      "eca             ",
      " a              ",
      " b              "
    ],
    [
      "debdbeaa        ",
      " c              ",
      " e              ",
      " d              ",
      "cec   bbc       ",
      " e      e       ",
      "        d       ",
      "       kd       ",
      "                ",
      "                ",
      "                ",
      "                ",
      " c              ",
      "bbc             ",
      " d              ",
      "                "
    ],
    [
      "cccceeda        ",
      " e              ",
      " c              ",
      " c              ",
      "dbeIIIbac       ",
      " e      d       ",
      " I      d       ",
      " I      b       ",
      " I              ",
      " I              ",
      " I              ",
      " I              ",
      " a              ",
      "cadII           ",
      " c              ",
      "                "
    ],
    [
      "bbdeaedc        ",
      " a              ",
      " c              ",
      " a              ",
      "dbdeabdea       ",
      " a      a       ",
      " d      b       ",
      " e      a       ",
      " a              ",
      " a              ",
      " c              ",
      " a              ",
      " a              ",
      "bbadc           ",
      " c              ",
      "                "
    ]
  ]
}