{
  "xsize": 16,
  "zsize": 16,
  "palette": {
    "palette": [
      {
        "char": " ",
        "block": "minecraft:air"
      },
      {
        "char": "b",
        "block": "minecraft:blackstone"
      },
      {
        "char": "e",
        "block": "minecraft:basalt[axis=y]"
      },
      {
        "char": "g",
        "block": "minecraft:gray_concrete"
      },
      {
        "char": "i",
        "block": "minecraft:light_gray_concrete"
      },
      {
        "char": "a",
        "block": "minecraft:cyan_terracotta"
      },
      {
        "char": "d",
        "block": "minecraft:cobbled_deepslate"
      },
      {
        "char": "c",
        "block": "minecraft:deepslate[axis=y]"
      },
      {
        "char": "f",
        "block": "minecraft:glass"
      },
      {
        "char": "ϔ",
        "block": "minecraft:quartz_stairs[facing=east,half=bottom,shape=straight,waterlogged=false]"
      },
      {
        "char": "П",
        "block": "minecraft:barrel[facing=up,open=false]",
        "tag": {
          "z": -275,
          "x": -15,
          "ForgeData": {
            "LockFlag": "1b"
          },
          "id": "minecraft:barrel",
          "y": 2,
          "Items": []
        }
      },
      {
        "char": "s",
        "block": "minecraft:iron_trapdoor[facing=north,half=bottom,open=false,powered=false,waterlogged=false]"
      },
      {
        "char": "l",
        "block": "minecraft:iron_trapdoor[facing=east,half=bottom,open=false,powered=false,waterlogged=false]"
      },
      {
        "char": "因",
        "block": "minecraft:air"
      },
      {
        "char": "吗",
        "block": "minecraft:air"
      },
      {
        "char": "p",
        "block": "minecraft:iron_trapdoor[facing=north,half=top,open=false,powered=false,waterlogged=false]"
      },
      {
        "char": "t",
        "block": "minecraft:iron_trapdoor[facing=east,half=top,open=false,powered=false,waterlogged=false]"
      }
    ]
  },
  "slices": [
    [
      "begeig          ",
      "abeaei          ",
      "abdegca         ",
      "acddiea         ",
      "cadaeaba        ",
      "ddecbgci        ",
      "cecdcaaea       ",
      "abddadaca       ",
      "bcabebaa        ",
      "eeceaaab        ",
      "adddbbead       ",
      "eceaecbgd       ",
      "abcaaddae       ",
      "ebaeacdae       ",
      "deadabdaaa      ",
      "caaddecaa       "
    ],
    [
      "  f  a          ",
      "   fb           ",
      "ϔ               ",
      "    f           ",
      "     f          ",
      "                ",
      "      f         ",
      "aaecebaca       ",
      "      f         ",
      "      f         ",
      " eba            ",
      " b     f        ",
      " a ϔ   f        ",
      " a              ",
      "accbdbdada      ",
      "П      f        "
    ],
    [
      "  fs g          ",
      "   fb           ",
      "    fl          ",
      "    fl          ",
      "     fl         ",
      "     fl         ",
      "      fl        ",
      "dddeeaaaa       ",
      "      fl        ",
      "      fl        ",
      "       fl       ",
      " 因     fl       ",
      " 吗     fl       ",
      "       fl       ",
      "edeacdeada      ",
      "因      fl       "
    ],
    [
      "  fp a          ",
      "   fb           ",
      "    ft          ",
      "    ft          ",
      "     ft         ",
      "     ft         ",
      "      ft        ",
      "edabdaada       ",
      "      ft        ",
      "      ft        ",
      "       ft       ",
      "       ft       ",
      "       ft       ",
      "       ft       ",
      "eaecbbcgda      ",
      "        t       "
    ],
    [
      "     g          ",
      "   fb           ",
      "    f           ",
      "    f           ",
      "     f          ",
      "                ",
      "                ",
      "accdbbaea       ",
      "      f         ",
      "      f         ",
      "       f        ",
      "       f        ",
      "                ",
      "       f        ",
      "ebcddbbgca      ",
      "       f        "
    ],
    [
      "  ab a          ",
      "   ab           ",
      "    gc          ",
      "    ia          ",
      "     aa         ",
      "     ab         ",
      "      ab        ",
      "bbdeedibg       ",
      "      ab        ",
      "      aa        ",
      "       ab       ",
      "       ib       ",
      "       ge       ",
      "       gd       ",
      "aeecdcagei      ",
      "       aa       "
    ]
  ]
}