{
  "xsize": 16,
  "zsize": 16,
  "palette": {
    "palette": [
      {
        "char": " ",
        "block": "minecraft:air"
      },
      {
        "char": "a",
        "block": "minecraft:cyan_terracotta"
      },
      {
        "char": "d",
        "block": "minecraft:cobbled_deepslate"
      },
      {
        "char": "c",
        "block": "minecraft:deepslate[axis=y]"
      },
      {
        "char": "b",
        "block": "minecraft:blackstone"
      },
      {
        "char": "e",
        "block": "minecraft:basalt[axis=y]"
      },
      {
        "char": "g",
        "block": "minecraft:gray_concrete"
      },
      {
        "char": "i",
        "block": "minecraft:light_gray_concrete"
      },
      {
        "char": "f",
        "block": "minecraft:glass"
      },
      {
        "char": "m",
        "block": "minecraft:iron_trapdoor[facing=west,half=bottom,open=false,powered=false,waterlogged=false]"
      },
      {
        "char": "u",
        "block": "minecraft:iron_trapdoor[facing=south,half=bottom,open=false,powered=false,waterlogged=false]"
      },
      {
        "char": "q",
        "block": "minecraft:iron_trapdoor[facing=west,half=top,open=false,powered=false,waterlogged=false]"
      },
      {
        "char": "w",
        "block": "minecraft:iron_trapdoor[facing=south,half=top,open=false,powered=false,waterlogged=false]"
      }
    ]
  },
  "slices": [
    [
      "          aadcbe",
      "          dadeea",
      "          caeeea",
      "           cgdbc",
      "           dgcea",
      "          adgeaa",
      "          aeacda",
      "           gdabd",
      "           adacc",
      "            acae",
      "            gcab",
      "             iaa",
      "             aic",
      "              aa",
      "               a",
      "                "
    ],
    [
      "           f    ",
      "                ",
      "           f    ",
      "                ",
      "            f   ",
      "          acaaae",
      "            f   ",
      "             f  ",
      "             f  ",
      "              f ",
      "              f ",
      "              ef",
      "             a  ",
      "                ",
      "                ",
      "                "
    ],
    [
      "          mf    ",
      "          mf    ",
      "          mf    ",
      "           mf   ",
      "           mf   ",
      "          acaceb",
      "           mf   ",
      "            mf  ",
      "            mf  ",
      "             mf ",
      "             uf ",
      "              bf",
      "             a u",
      "               m",
      "                ",
      "                "
    ],
    [
      "          qf    ",
      "          qf    ",
      "          qf    ",
      "           qf   ",
      "           qf   ",
      "          aegebb",
      "           qf   ",
      "            qf  ",
      "            qf  ",
      "             q  ",
      "             q  ",
      "              af",
      "             a w",
      "               q",
      "                ",
      "                "
    ],
    [
      "           f    ",
      "           f    ",
      "           f    ",
      "                ",
      "            f   ",
      "          gciaab",
      "            f   ",
      "             f  ",
      "             f  ",
      "              f ",
      "                ",
      "              ef",
      "             g  ",
      "                ",
      "                ",
      "                "
    ],
    [
      "          ag    ",
      "          ag    ",
      "          di    ",
      "           aa   ",
      "           ca   ",
      "          abaedd",
      "           aa   ",
      "            ba  ",
      "            ei  ",
      "             ea ",
      "             aa ",
      "              bg",
      "             a d",
      "               b",
      "                ",
      "                "
    ]
  ]
}