{
  "xsize": 16,
  "zsize": 16,
  "palette": {
    "palette": [
      {
        "char": " ",
        "block": "minecraft:air"
      },
      {
        "char": "i",
        "block": "minecraft:light_gray_concrete"
      },
      {
        "char": "d",
        "block": "minecraft:cobbled_deepslate"
      },
      {
        "char": "b",
        "block": "minecraft:blackstone"
      },
      {
        "char": "a",
        "block": "minecraft:cyan_terracotta"
      },
      {
        "char": "e",
        "block": "minecraft:basalt[axis=y]"
      },
      {
        "char": "c",
        "block": "minecraft:deepslate[axis=y]"
      },
      {
        "char": "Р",
        "block": "minecraft:stone_brick_stairs[facing=north,half=bottom,shape=straight,waterlogged=false,weathering=false]"
      },
      {
        "char": "z",
        "block": "minecraft:iron_bars[east=false,north=true,south=true,waterlogged=false,west=false]"
      },
      {
        "char": "Y",
        "block": "minecraft:iron_bars[east=false,north=true,south=false,waterlogged=false,west=false]"
      },
      {
        "char": "f",
        "block": "minecraft:glass"
      },
      {
        "char": "O",
        "block": "minecraft:quartz_stairs[facing=west,half=bottom,shape=straight,waterlogged=false]"
      },
      {
        "char": "x",
        "block": "minecraft:cauldron"
      },
      {
        "char": "П",
        "block": "minecraft:barrel[facing=up,open=false]",
        "tag": {
          "z": -275,
          "x": -15,
          "ForgeData": {
            "LockFlag": "1b"
          },
          "id": "minecraft:barrel",
          "y": 2,
          "Items": []
        }
      },
      {
        "char": "У",
        "block": "minecraft:stone_brick_stairs[facing=south,half=bottom,shape=straight,waterlogged=false,weathering=false]"
      },
      {
        "char": "С",
        "block": "minecraft:stone_brick_stairs[facing=north,half=top,shape=straight,waterlogged=false,weathering=false]"
      },
      {
        "char": "Ѫ",
        "block": "minecraft:air"
      },
      {
        "char": "Ӝ",
        "block": "minecraft:air"
      },
      {
        "char": "N",
        "block": "minecraft:white_stained_glass_pane[east=true,north=false,south=false,waterlogged=false,west=true]"
      },
      {
        "char": "k",
        "block": "minecraft:oak_leaves[distance=7,persistent=true,waterlogged=false]"
      },
      {
        "char": "у",
        "block": "minecraft:stone_brick_stairs[facing=south,half=top,shape=straight,waterlogged=false,weathering=false]"
      },
      {
        "char": "j",
        "block": "minecraft:polished_andesite_slab[type=top,waterlogged=false]"
      }
    ]
  },
  "slices": [
    [
      "idddbaedaabcdeea",
      "ecadedbddebebbeb",
      "debccaeaaeedacca",
      "ebbebbeacaadebed",
      "aaecbeaebdbdadda",
      "dabadeeebedbceeb",
      "adccbbbbbaedbbee",
      "bbedcebabebcceab",
      "cdbbabdcdedaaaac",
      "cadddaaaedcbddbe",
      "cccaaceadaadeade",
      "edeedebbadedbebd",
      "eecbecdeedeeРz b",
      "ddaaccacbded z e",
      "cdbbbdbedacd Y c",
      "badbcacedccd   b"
    ],
    [
      "f   Oa    b     ",
      "     e          ",
      "                ",
      "  a  a    d     ",
      " Oc Oc    ecccbe",
      "  d  d     d  x ",
      "           d    ",
      "  a  П          ",
      " Ob Oe          ",
      "  d  b          ",
      "           a    ",
      "  d  e     d a b",
      " Oc Oc     e zУd",
      "  e  c     d zСe",
      "aaddbad   ca Y d",
      "  c  d     c   b"
    ],
    [
      "f    Ѫ    a     ",
      "     Ӝ          ",
      "                ",
      "          b     ",
      "  Ѫ  Ѫ    cdaNNN",
      "  Ӝ  Ӝ     d  k ",
      "           a    ",
      "                ",
      "  Ѫ  Ѫ          ",
      "  Ӝ  Ӝ          ",
      "           e    ",
      "           e d b",
      "  Ѫ  Ѫ     a z d",
      "  Ӝ  Ӝ     c zУa",
      "ecbecba   be YСc",
      "     b     a   c"
    ],
    [
      "          c     ",
      "                ",
      "                ",
      "          c     ",
      "          cdaNNN",
      "           a  k ",
      "           e    ",
      "                ",
      "                ",
      "                ",
      "           b    ",
      "           e e a",
      "           b z a",
      "           b z a",
      "edddcbc   cbуzУe",
      "     e     cacad"
    ],
    [
      "f         b     ",
      "          j     ",
      "          j     ",
      "          a     ",
      "          ddebae",
      "           b    ",
      "           a    ",
      "           j    ",
      "           j    ",
      "           j    ",
      "           b    ",
      "           dbdba",
      "           d z c",
      "           eуz a",
      "dbbbdbejjjbbРY a",
      "     a     b   a"
    ],
    [
      "a         d     ",
      "          a     ",
      "          d     ",
      "          d     ",
      "          aaaeee",
      "           e    ",
      "           b    ",
      "           b    ",
      "           d    ",
      "           c    ",
      "           d    ",
      "           cccba",
      "           dуz b",
      "           eРz e",
      "bdebbeaecada Y d",
      "     b     b   b"
    ]
  ]
}