{
  "xsize": 16,
  "zsize": 16,
  "palette": {
    "palette": [
      {
        "char": " ",
        "block": "minecraft:air"
      },
      {
        "char": "a",
        "block": "minecraft:cyan_terracotta"
      },
      {
        "char": "e",
        "block": "minecraft:basalt[axis=y]"
      },
      {
        "char": "d",
        "block": "minecraft:cobbled_deepslate"
      },
      {
        "char": "c",
        "block": "minecraft:deepslate[axis=y]"
      },
      {
        "char": "b",
        "block": "minecraft:blackstone"
      },
      {
        "char": "g",
        "block": "minecraft:gray_concrete"
      },
      {
        "char": "会",
        "block": "minecraft:birch_stairs[facing=east,half=bottom,shape=straight,waterlogged=false]"
      },
      {
        "char": "好",
        "block": "minecraft:birch_stairs[facing=west,half=bottom,shape=straight,waterlogged=false]"
      },
      {
        "char": "x",
        "block": "minecraft:cauldron"
      },
      {
        "char": "问",
        "block": "minecraft:birch_trapdoor[facing=south,half=bottom,open=true,powered=false,waterlogged=false]"
      },
      {
        "char": "k",
        "block": "minecraft:oak_leaves[distance=7,persistent=true,waterlogged=false]"
      },
      {
        "char": "P",
        "block": "minecraft:smooth_quartz_slab[type=bottom,waterlogged=false]"
      },
      {
        "char": "Ѯ",
        "block": "minecraft:diorite_slab[type=bottom,waterlogged=false]"
      },
      {
        "char": "M",
        "block": "minecraft:smooth_quartz_slab[type=top,waterlogged=false]"
      },
      {
        "char": "i",
        "block": "minecraft:light_gray_concrete"
      },
      {
        "char": "ѩ",
        "block": "minecraft:diorite_slab[type=top,waterlogged=false]"
      },
      {
        "char": "ѭ",
        "block": "minecraft:polished_andesite_stairs[facing=west,half=top,shape=straight,waterlogged=false]"
      },
      {
        "char": "h",
        "block": "minecraft:andesite_slab[type=top,waterlogged=false]"
      },
      {
        "char": "们",
        "block": "minecraft:polished_andesite_stairs[facing=west,half=top,shape=inner_right,waterlogged=false]"
      },
      {
        "char": "Т",
        "block": "minecraft:polished_andesite_stairs[facing=north,half=top,shape=straight,waterlogged=false]"
      }
    ]
  },
  "slices": [
    [
      "         aeaedaa",
      "         adcdcbd",
      "         ebabdea",
      "         bebcacb",
      "         bdbccab",
      "        aaaebacc",
      "        agdacaae",
      "         bccedce",
      "         cdcacec",
      "         bcadebc",
      "         eeacceb",
      "         eadaeba",
      "         cbcacde",
      "         bdadabb",
      "         ebabdbe",
      "         cbdbaea"
    ],
    [
      "         b   会好 ",
      "         b   会好 ",
      "         bx  会好 ",
      "         d   问问 ",
      "         d      ",
      "        agx     ",
      "        aa      ",
      "         d      ",
      "         ax     ",
      "         b      ",
      "         e      ",
      "         ca    d",
      "         d      ",
      "         a      ",
      "         ax     ",
      "         d      "
    ],
    [
      "         a      ",
      "         b      ",
      "         dk     ",
      "         d      ",
      "         c      ",
      "        gak     ",
      "        aa      ",
      "         e      ",
      "         bk     ",
      "         e      ",
      "         c      ",
      "         da    e",
      "         a      ",
      "         a      ",
      "         ak     ",
      "         e      "
    ],
    [
      "        Pd      ",
      "        Ѯb      ",
      "        Pdk     ",
      "        Ѯb      ",
      "        Ѯb      ",
      "        gak     ",
      "        ga      ",
      "        Ѯa      ",
      "        Ѯck     ",
      "        Pe      ",
      "        Pc      ",
      "        Pee    c",
      "        Pd      ",
      "        Pb      ",
      "        Pck     ",
      "        Pa      "
    ],
    [
      "        Ma      ",
      "        Mb      ",
      "        Md      ",
      "        Md      ",
      "        Ma      ",
      "        aa      ",
      "        ai      ",
      "        ѩc      ",
      "        Ma      ",
      "        Md      ",
      "        ѩe      ",
      "        ѩce    c",
      "        Me      ",
      "        Ma      ",
      "        Md      ",
      "        ѩb      "
    ],
    [
      "         eѭhhhhh",
      "         aѭhhhhh",
      "         cѭhhhhh",
      "         dѭhhhhh",
      "         eѭhhhhh",
      "        adѭhhhhh",
      "        aaѭhhhhh",
      "         bѭhhhhh",
      "         aѭhhhhh",
      "         dѭhhhhh",
      "         eѭhhhhh",
      "         cabeadd",
      "         e们ТТТТТ",
      "         dѭhhhhh",
      "         gѭhhhhh",
      "         bѭhhhhh"
    ]
  ]
}