{
  "xsize": 16,
  "zsize": 16,
  "palette": {
    "palette": [
      {
        "char": " ",
        "block": "minecraft:air"
      },
      {
        "char": "B",
        "block": "minecraft:birch_planks"
      },
      {
        "char": "y",
        "block": "minecraft:basalt[axis=x]"
      },
      {
        "char": "J",
        "block": "minecraft:diorite"
      },
      {
        "char": "Q",
        "block": "minecraft:grass_block[snowy=false]"
      },
      {
        "char": "d",
        "block": "minecraft:cobbled_deepslate"
      },
      {
        "char": "r",
        "block": "minecraft:polished_diorite"
      },
      {
        "char": "c",
        "block": "minecraft:deepslate[axis=y]"
      },
      {
        "char": "b",
        "block": "minecraft:blackstone"
      },
      {
        "char": "n",
        "block": "minecraft:smooth_quartz"
      },
      {
        "char": "a",
        "block": "minecraft:cyan_terracotta"
      },
      {
        "char": "资",
        "block": "minecraft:dirt"
      },
      {
        "char": "e",
        "block": "minecraft:basalt[axis=y]"
      },
      {
        "char": "C",
        "block": "minecraft:quartz_pillar[axis=y]"
      },
      {
        "char": "o",
        "block": "minecraft:chiseled_quartz_block"
      },
      {
        "char": "Ѷ",
        "block": "minecraft:spruce_planks"
      },
      {
        "char": "U",
        "block": "minecraft:air"
      },
      {
        "char": "Ѭ",
        "block": "minecraft:bookshelf"
      },
      {
        "char": "g",
        "block": "minecraft:gray_concrete"
      },
      {
        "char": "ú",
        "block": "minecraft:iron_bars[east=false,north=true,south=true,waterlogged=false,west=true]"
      },
      {
        "char": "i",
        "block": "minecraft:light_gray_concrete"
      },
      {
        "char": "z",
        "block": "minecraft:iron_bars[east=false,north=true,south=true,waterlogged=false,west=false]"
      },
      {
        "char": "f",
        "block": "minecraft:glass"
      },
      {
        "char": "V",
        "block": "minecraft:air"
      },
      {
        "char": "G",
        "block": "minecraft:iron_bars[east=false,north=false,south=true,waterlogged=false,west=false]"
      },
      {
        "char": "ѱ",
        "block": "minecraft:brown_carpet"
      },
      {
        "char": "像",
        "block": "minecraft:iron_bars[east=false,north=true,south=false,waterlogged=false,west=true]"
      },
      {
        "char": "麽",
        "block": "minecraft:white_stained_glass_pane[east=false,north=false,south=true,waterlogged=false,west=false]"
      }
    ]
  },
  "slices": [
    [
      "BBBBBBBBByJyQddQ",
      "BBBBBBBBBQrcbydc",
      "BBBBBBBBBdnacyyd",
      "BBBBBBBBBccyaydd",
      "BBBBBBBBB资eadQaQ",
      "BBBBBBBBBdbayQda",
      "CybrCorccoQybcbb",
      "cQyyQy资babdyyacb",
      "yacaaaddQycaddac",
      "cyabcaacQbbabcdc",
      "acyyddaydbQbQada",
      "bdycyydacbQbcyyd",
      "ayybaQbyyddydbQb",
      "ccbbbyydQydQcQbb",
      "bQbccdyabydydcbc",
      "aQdayccacbcaQayd"
    ],
    [
      "    ѶѶѶ     U  U",
      "                ",
      "    ѶѶѶ  e      ",
      "    ѶѶѶ Ѭaa     ",
      "        Ѭga  U U",
      " ѬѬѬѬ ѬѬѬdú  U  ",
      "baceabiaaaú     ",
      " U  U aa  z     ",
      "   b    U a     ",
      "        U       ",
      "          U U   ",
      "          U     ",
      "     U        U ",
      "        U  U U  ",
      " U              ",
      " U          U   "
    ],
    [
      "    f f     V  V",
      "                ",
      "    fff  b      ",
      "    ff  Ѭaa     ",
      "        Ѭga  V V",
      " ѬѬѬѬ ѬѬѬb   V  ",
      "dbddebaadc      ",
      " V  V ia  G     ",
      "   d    V b     ",
      "        V       ",
      "          V V   ",
      "          V     ",
      "     V        V ",
      "        V  V V  ",
      " V              ",
      " V          V   "
    ],
    [
      "    ѱ ѱ         ",
      "                ",
      "    ѱѱѱ  b      ",
      "    ѱѱ  Ѭag     ",
      "        Ѭaa     ",
      " ѬѬѬѬ ѬѬѬeú     ",
      "cccbdagada像     ",
      "      ga        ",
      "   c      d     ",
      "                ",
      "                ",
      "                ",
      "                ",
      "                ",
      "                ",
      "                "
    ],
    [
      "                ",
      "                ",
      "         e      ",
      "        Ѭig     ",
      "        Ѭai     ",
      " ѬѬѬѬ ѬѬѬbú     ",
      "bddeaeaadbú     ",
      "      aa  z     ",
      "   c      d     ",
      "                ",
      "                ",
      "                ",
      "                ",
      "                ",
      "                ",
      "                "
    ],
    [
      "                ",
      "         麽      ",
      "         a      ",
      "         ag     ",
      "         ag     ",
      "         b      ",
      "eadbedaaee      ",
      "      ga        ",
      "   d      d     ",
      "                ",
      "                ",
      "                ",
      "                ",
      "                ",
      "                ",
      "                "
    ]
  ]
}