{
  "xsize": 16,
  "zsize": 16,
  "palette": {
    "palette": [
      {
        "char": " ",
        "block": "minecraft:air"
      },
      {
        "char": "c",
        "block": "minecraft:deepslate[axis=y]"
      },
      {
        "char": "a",
        "block": "minecraft:cyan_terracotta"
      },
      {
        "char": "d",
        "block": "minecraft:cobbled_deepslate"
      },
      {
        "char": "b",
        "block": "minecraft:blackstone"
      },
      {
        "char": "e",
        "block": "minecraft:basalt[axis=y]"
      },
      {
        "char": "g",
        "block": "minecraft:gray_concrete"
      },
      {
        "char": "i",
        "block": "minecraft:light_gray_concrete"
      },
      {
        "char": "ϔ",
        "block": "minecraft:quartz_stairs[facing=east,half=bottom,shape=straight,waterlogged=false]"
      },
      {
        "char": "f",
        "block": "minecraft:glass"
      },
      {
        "char": "П",
        "block": "minecraft:barrel[facing=up,open=false]",
        "tag": {
          "z": -275,
          "x": -15,
          "ForgeData": {
            "LockFlag": "1b"
          },
          "id": "minecraft:barrel",
          "y": 2,
          "Items": []
        }
      },
      {
        "char": "x",
        "block": "minecraft:cauldron"
      },
      {
        "char": "H",
        "block": "minecraft:quartz_stairs[facing=south,half=bottom,shape=straight,waterlogged=false]"
      },
      {
        "char": "下",
        "block": "minecraft:air"
      },
      {
        "char": "l",
        "block": "minecraft:iron_trapdoor[facing=east,half=bottom,open=false,powered=false,waterlogged=false]"
      },
      {
        "char": "k",
        "block": "minecraft:oak_leaves[distance=7,persistent=true,waterlogged=false]"
      },
      {
        "char": "ο",
        "block": "minecraft:air"
      },
      {
        "char": "ѧ",
        "block": "minecraft:air"
      },
      {
        "char": "u",
        "block": "minecraft:iron_trapdoor[facing=south,half=bottom,open=false,powered=false,waterlogged=false]"
      },
      {
        "char": "t",
        "block": "minecraft:iron_trapdoor[facing=east,half=top,open=false,powered=false,waterlogged=false]"
      },
      {
        "char": "w",
        "block": "minecraft:iron_trapdoor[facing=south,half=top,open=false,powered=false,waterlogged=false]"
      },
      {
        "char": "在",
        "block": "minecraft:air"
      }
    ]
  },
  "slices": [
    [
      "cadbcedaaa      ",
      "cdcdedcgcg      ",
      "beebddagbg      ",
      "dababeadi       ",
      "abaeeeica       ",
      "ceedabaeg       ",
      "eedbcagcg       ",
      "daaccaaa        ",
      "bacaaaca        ",
      "eecdgea         ",
      "dbaegeg         ",
      "abcaca          ",
      "baacag          ",
      "bagci           ",
      "aaea            ",
      "aea             "
    ],
    [
      "b ϔ    f        ",
      "b               ",
      "Пba    f        ",
      "      f         ",
      "      f         ",
      "ddbddbaca       ",
      "  x   f         ",
      "     f          ",
      "     f          ",
      "    f           ",
      "ca  f           ",
      "H  fe           ",
      "  f  a          ",
      "  f             ",
      " f              ",
      "f               "
    ],
    [
      "下      fl       ",
      "       fl       ",
      "       fl       ",
      "      fl        ",
      "      fl        ",
      "dacbcaaaa       ",
      "  k    l        ",
      "      l         ",
      "      l         ",
      "     l          ",
      "οѧ  fl          ",
      "   fd           ",
      "   u a          ",
      "  fl            ",
      " fl             ",
      "fl              "
    ],
    [
      "        t       ",
      "       ft       ",
      "       ft       ",
      "       t        ",
      "      ft        ",
      "ceeabdaba       ",
      "  k   ft        ",
      "     ft         ",
      "     ft         ",
      "    ft          ",
      "    ft          ",
      "   fb           ",
      "  fw a          ",
      "   在            ",
      " ft             ",
      " w              "
    ],
    [
      "       f        ",
      "       f        ",
      "       f        ",
      "      f         ",
      "                ",
      "eaadbagdg       ",
      "      f         ",
      "     f          ",
      "                ",
      "    f           ",
      "    f           ",
      "    b           ",
      "  f  a          ",
      "  f             ",
      " f              ",
      "f               "
    ],
    [
      "       ge       ",
      "       ad       ",
      "       aa       ",
      "      ae        ",
      "      ac        ",
      "caeeaaaea       ",
      "      ad        ",
      "     ae         ",
      "     ad         ",
      "    gd          ",
      "    ae          ",
      "   gb           ",
      "  ae a          ",
      "  ad            ",
      " ab             ",
      "aa              "
    ]
  ]
}