{
  "xsize": 16,
  "zsize": 16,
  "palette": {
    "palette": [
      {
        "char": " ",
        "block": "minecraft:air"
      },
      {
        "char": "c",
        "block": "minecraft:deepslate[axis=y]"
      },
      {
        "char": "a",
        "block": "minecraft:cyan_terracotta"
      },
      {
        "char": "e",
        "block": "minecraft:basalt[axis=y]"
      },
      {
        "char": "d",
        "block": "minecraft:cobbled_deepslate"
      },
      {
        "char": "b",
        "block": "minecraft:blackstone"
      },
      {
        "char": "Ӿ",
        "block": "minecraft:cobblestone_wall[east=tall,north=tall,south=none,up=true,waterlogged=false,weathering=false,west=tall]"
      },
      {
        "char": "Z",
        "block": "minecraft:stone_brick_wall[east=tall,north=tall,south=none,up=true,waterlogged=false,weathering=false,west=tall]"
      },
      {
        "char": "G",
        "block": "minecraft:iron_bars[east=false,north=false,south=true,waterlogged=false,west=false]"
      },
      {
        "char": "f",
        "block": "minecraft:glass"
      },
      {
        "char": "x",
        "block": "minecraft:cauldron"
      },
      {
        "char": "r",
        "block": "minecraft:polished_diorite"
      },
      {
        "char": "v",
        "block": "minecraft:quartz_pillar[axis=x]"
      },
      {
        "char": "o",
        "block": "minecraft:chiseled_quartz_block"
      },
      {
        "char": "如",
        "block": "minecraft:air"
      },
      {
        "char": "s",
        "block": "minecraft:iron_trapdoor[facing=north,half=bottom,open=false,powered=false,waterlogged=false]"
      },
      {
        "char": "l",
        "block": "minecraft:iron_trapdoor[facing=east,half=bottom,open=false,powered=false,waterlogged=false]"
      },
      {
        "char": "k",
        "block": "minecraft:oak_leaves[distance=7,persistent=true,waterlogged=false]"
      },
      {
        "char": "n",
        "block": "minecraft:smooth_quartz"
      },
      {
        "char": "p",
        "block": "minecraft:iron_trapdoor[facing=north,half=top,open=false,powered=false,waterlogged=false]"
      },
      {
        "char": "t",
        "block": "minecraft:iron_trapdoor[facing=east,half=top,open=false,powered=false,waterlogged=false]"
      },
      {
        "char": "K",
        "block": "minecraft:quartz_block"
      },
      {
        "char": "I",
        "block": "minecraft:stone_slab[type=top,waterlogged=false,weathering=false]"
      },
      {
        "char": "j",
        "block": "minecraft:polished_andesite_slab[type=top,waterlogged=false]"
      }
    ]
  },
  "slices": [
    [
      "caeddaddbe      ",
      "ebabddedaaab    ",
      "caddcebddeaae   ",
      "cbebcdbcabccbc  ",
      "bdaacdaeaaadddc ",
      "bdcdeaeecabecbb ",
      "deaebdabccececeb",
      "eadcdbaebeaaebbd",
      "dceacdccecacabdc",
      "dcddeaedbcecdbba",
      "decdecebdbddebde",
      "ecbdabbecedadace",
      "ӾZZdZZZdcaaeadaa",
      "   c   daabedabc",
      "   d   badeebabc",
      " G b G edacabacb"
    ],
    [
      " e       b      ",
      "         b      ",
      "          ff    ",
      "                ",
      " b           f  ",
      "xdx          f  ",
      " d      x     ec",
      "dada   aadaaecce",
      "          x  x  ",
      "                ",
      "                ",
      "   d   e        ",
      "rvvbvovd        ",
      "   a   d        ",
      "   a   ce      a",
      " G b G c        "
    ],
    [
      " d       c      ",
      "         e如s    ",
      "           fs   ",
      "            fl  ",
      " e           fl ",
      "kck          fl ",
      " d      k     ab",
      "bbaa   dedebdaeb",
      "          k  k  ",
      "                ",
      "                ",
      "   b   a        ",
      "nvvbvvva        ",
      "   e   c        ",
      "   b   ba      b",
      " G c G c        "
    ],
    [
      " c       c      ",
      "         dpp    ",
      "          ffp   ",
      "            fp  ",
      " d            t ",
      "kak          fp ",
      " d      k     ad",
      "ecac   baaedeaba",
      "          k  k  ",
      "                ",
      "                ",
      "   b   a        ",
      "KvKevvvc        ",
      "   e   e        ",
      "   d   ee      d",
      " G b G d        "
    ],
    [
      " a       c      ",
      " I       c      ",
      " I        ff    ",
      " I          f   ",
      " c           f  ",
      " e           f  ",
      " d            ec",
      "ebedIIIbaaccabbc",
      "                ",
      "                ",
      "                ",
      "jjjajjjb        ",
      "vovevvrd        ",
      "   c   d        ",
      "   c   ebIIIIIIa",
      " G e G d        "
    ],
    [
      " d       b      ",
      " e        cb    ",
      " b        deb   ",
      " d          cc  ",
      " a           ae ",
      " c           dc ",
      " d             d",
      "cbabadedceeebadb",
      "                ",
      "                ",
      "                ",
      "dbdebacd        ",
      "   c   a        ",
      "   d   c        ",
      "   b   dbddebebe",
      " G e G e        "
    ]
  ]
}