{
  "xsize": 16,
  "zsize": 16,
  "palette": {
    "palette": [
      {
        "char": " ",
        "block": "minecraft:air"
      },
      {
        "char": "c",
        "block": "minecraft:deepslate[axis=y]"
      },
      {
        "char": "b",
        "block": "minecraft:blackstone"
      },
      {
        "char": "e",
        "block": "minecraft:basalt[axis=y]"
      },
      {
        "char": "a",
        "block": "minecraft:cyan_terracotta"
      },
      {
        "char": "d",
        "block": "minecraft:cobbled_deepslate"
      },
      {
        "char": "g",
        "block": "minecraft:gray_concrete"
      },
      {
        "char": "i",
        "block": "minecraft:light_gray_concrete"
      },
      {
        "char": "f",
        "block": "minecraft:glass"
      },
      {
        "char": "H",
        "block": "minecraft:quartz_stairs[facing=south,half=bottom,shape=straight,waterlogged=false]"
      },
      {
        "char": "ϐ",
        "block": "minecraft:air",
        "tag": {
          "z": -259,
          "x": -34,
          "id": "refurbished_furniture:computer",
          "y": -21,
          "NodePos": "-9070971985941L",
          "Connections": [
            "L"
          ]
        }
      },
      {
        "char": "l",
        "block": "minecraft:iron_trapdoor[facing=east,half=bottom,open=false,powered=false,waterlogged=false]"
      },
      {
        "char": "u",
        "block": "minecraft:iron_trapdoor[facing=south,half=bottom,open=false,powered=false,waterlogged=false]"
      },
      {
        "char": "w",
        "block": "minecraft:iron_trapdoor[facing=south,half=top,open=false,powered=false,waterlogged=false]"
      }
    ]
  },
  "slices": [
    [
      "cbbeeeacbcaadeac",
      "acbaaedbabecaaeg",
      "bbcbaeaaadaiac a",
      "aedeeaaaaaeb    ",
      "gggaigdaad      ",
      "ceceea  a       ",
      " a              ",
      "                ",
      "                ",
      "                ",
      "                ",
      "                ",
      "                ",
      "                ",
      "                ",
      "                "
    ],
    [
      "eebbcbacdc    f ",
      "caeeHcb H   ffb ",
      "ccbabca   ff   g",
      "daeedcbeaf      ",
      "caecdb  c       ",
      " bbae   a       ",
      " a              ",
      "                ",
      "                ",
      "                ",
      "                ",
      "                ",
      "                ",
      "                ",
      "                ",
      "                "
    ],
    [
      "bddbac  ϐ     fl",
      " cdeda      ffb ",
      " eaacda   f uu a",
      " aadbab gfuu    ",
      " bbbbcuubu      ",
      " dacc   i       ",
      " a              ",
      "                ",
      "                ",
      "                ",
      "                ",
      "                ",
      "                ",
      "                ",
      "                ",
      "                "
    ],
    [
      " dbad          w",
      "  ddc       ffe ",
      "  deaa    f ww a",
      "  cbae  g ww    ",
      "  cbe   bw      ",
      "   ce   g       ",
      " a              ",
      "                ",
      "                ",
      "                ",
      "                ",
      "                ",
      "                ",
      "                ",
      "                ",
      "                "
    ],
    [
      "  e           f ",
      "  ac        ffd ",
      "   d      ff   a",
      "   eb   gf      ",
      "    c   e       ",
      "        a       ",
      "                ",
      "                ",
      "                ",
      "                ",
      "                ",
      "                ",
      "                ",
      "                ",
      "                ",
      "                "
    ],
    [
      "              gc",
      "            gae ",
      "          aade g",
      "      aiaaae    ",
      "     adddb      ",
      "    ac  g       ",
      "                ",
      "                ",
      "                ",
      "                ",
      "                ",
      "                ",
      "                ",
      "                ",
      "                ",
      "                "
    ]
  ]
}