{
  "xsize": 16,
  "zsize": 16,
  "palette": {
    "palette": [
      {
        "char": " ",
        "block": "minecraft:air"
      },
      {
        "char": "a",
        "block": "minecraft:cyan_terracotta"
      },
      {
        "char": "d",
        "block": "minecraft:cobbled_deepslate"
      },
      {
        "char": "e",
        "block": "minecraft:basalt[axis=y]"
      },
      {
        "char": "c",
        "block": "minecraft:deepslate[axis=y]"
      },
      {
        "char": "b",
        "block": "minecraft:blackstone"
      },
      {
        "char": "i",
        "block": "minecraft:light_gray_concrete"
      },
      {
        "char": "Р",
        "block": "minecraft:stone_brick_stairs[facing=north,half=bottom,shape=straight,waterlogged=false,weathering=false]"
      },
      {
        "char": "z",
        "block": "minecraft:iron_bars[east=false,north=true,south=true,waterlogged=false,west=false]"
      },
      {
        "char": "Y",
        "block": "minecraft:iron_bars[east=false,north=true,south=false,waterlogged=false,west=false]"
      },
      {
        "char": "f",
        "block": "minecraft:glass"
      },
      {
        "char": "x",
        "block": "minecraft:cauldron"
      },
      {
        "char": "У",
        "block": "minecraft:stone_brick_stairs[facing=south,half=bottom,shape=straight,waterlogged=false,weathering=false]"
      },
      {
        "char": "С",
        "block": "minecraft:stone_brick_stairs[facing=north,half=top,shape=straight,waterlogged=false,weathering=false]"
      },
      {
        "char": "s",
        "block": "minecraft:iron_trapdoor[facing=north,half=bottom,open=false,powered=false,waterlogged=false]"
      },
      {
        "char": "m",
        "block": "minecraft:iron_trapdoor[facing=west,half=bottom,open=false,powered=false,waterlogged=false]"
      },
      {
        "char": "k",
        "block": "minecraft:oak_leaves[distance=7,persistent=true,waterlogged=false]"
      },
      {
        "char": "p",
        "block": "minecraft:iron_trapdoor[facing=north,half=top,open=false,powered=false,waterlogged=false]"
      },
      {
        "char": "q",
        "block": "minecraft:iron_trapdoor[facing=west,half=top,open=false,powered=false,waterlogged=false]"
      },
      {
        "char": "у",
        "block": "minecraft:stone_brick_stairs[facing=south,half=top,shape=straight,waterlogged=false,weathering=false]"
      },
      {
        "char": "I",
        "block": "minecraft:stone_slab[type=top,waterlogged=false,weathering=false]"
      },
      {
        "char": "给",
        "block": "minecraft:stone_brick_stairs[facing=south,half=top,shape=straight,waterlogged=false,weathering=true]"
      },
      {
        "char": "小",
        "block": "minecraft:air"
      }
    ]
  },
  "slices": [
    [
      "         adeaecb",
      "       cdeabedbd",
      "      adcaeaceda",
      "     eccabedbddb",
      "    ebaeceeededd",
      "  i dbecaeccbedd",
      "iaaedbdaaecdebec",
      "dabeedcdbeeddcce",
      "bdbaceadacedbeeb",
      "adecacccebbcebbb",
      "cabbedecaceecaeb",
      "ebdccbabaecbecec",
      "bdddabbadeadРz c",
      "babebeadacdd z a",
      "eddbcdeaacbb Y c",
      "cbcaecaedcac   a"
    ],
    [
      "         e      ",
      "         b      ",
      "       ff       ",
      "      f         ",
      "     f          ",
      "  i  f          ",
      "   aa     x     ",
      "ebceccdabcdb   b",
      "  b  x  x       ",
      "  d             ",
      "  c             ",
      "           a b c",
      "           b zУb",
      "  c        d zСa",
      "ebb        b Y c",
      "  b        d   d"
    ],
    [
      "         a      ",
      "       ssb      ",
      "      mf        ",
      "     mf         ",
      "    mf          ",
      "  a mf          ",
      "   ae     k     ",
      "bdeeedbeacae   b",
      "  a  k  k       ",
      "  c             ",
      "  a             ",
      "           e a a",
      "           d z b",
      "  e        c zУe",
      "aad        c YСe",
      "  a        a   b"
    ],
    [
      "         b      ",
      "       ppc      ",
      "      qff       ",
      "     p          ",
      "    qf          ",
      "  a q           ",
      "   ec     k     ",
      "dbdbcebebbba   a",
      "  a  k  k       ",
      "  d             ",
      "  c             ",
      "           b d d",
      "           d z b",
      "  b        e z a",
      "dbb        aуzУc",
      "  c        dcdcc"
    ],
    [
      "         a      ",
      "         e      ",
      "       ff       ",
      "                ",
      "                ",
      "  a  f          ",
      "   cd           ",
      "cccbdaabcadaIIIb",
      "  a             ",
      "  a             ",
      "  c             ",
      "  I        cbcac",
      "  I        a z d",
      "  d        aуz a",
      "bbd        bРY b",
      "  a        d   a"
    ],
    [
      "         d      ",
      "       de       ",
      "      dbb       ",
      "     da         ",
      "    ca          ",
      "  a bd          ",
      "   d            ",
      "eebdecccaeeeddbc",
      "  e             ",
      "  e             ",
      "  e             ",
      "  e        bbaba",
      "  b        a给z e",
      "  a        a小z a",
      "aeb        e Y b",
      "  a        b   c"
    ]
  ]
}