{
  "xsize": 16,
  "zsize": 16,
  "palette": {
    "palette": [
      {
        "char": " ",
        "block": "minecraft:air"
      },
      {
        "char": "c",
        "block": "minecraft:deepslate[axis=y]"
      },
      {
        "char": "e",
        "block": "minecraft:basalt[axis=y]"
      },
      {
        "char": "d",
        "block": "minecraft:cobbled_deepslate"
      },
      {
        "char": "b",
        "block": "minecraft:blackstone"
      },
      {
        "char": "a",
        "block": "minecraft:cyan_terracotta"
      },
      {
        "char": "I",
        "block": "minecraft:stone_slab[type=top,waterlogged=false,weathering=false]"
      }
    ]
  },
  "slices": [
    [
      "ceddbbeeaecddbaa",
      "dbbdcdebcbede   ",
      "ebbdcededbaa    ",
      "beaddbabbcb     ",
      "daeedacbac      ",
      "bcdebbba        ",
      "acdaece         ",
      "dbbbab          ",
      "aaceb           ",
      "bdab            ",
      "                ",
      "                ",
      "                ",
      "                ",
      "                ",
      "                "
    ],
    [
      "bbdcbeaa        ",
      " e              ",
      " e              ",
      " e              ",
      "ece   aed       ",
      " a              ",
      "                ",
      "                ",
      "                ",
      "                ",
      "                ",
      "                ",
      "                ",
      "                ",
      "                ",
      "                "
    ],
    [
      "cedeeaac        ",
      " d              ",
      " b              ",
      " b              ",
      "dcb   dab       ",
      " d      b       ",
      "                ",
      "                ",
      "                ",
      "                ",
      "                ",
      "                ",
      "                ",
      "                ",
      "                ",
      "                "
    ],
    [
      "ccddddba        ",
      " a              ",
      " c              ",
      " a              ",
      "dbb   cdd       ",
      " b      c       ",
      "                ",
      "                ",
      "                ",
      "                ",
      "                ",
      "                ",
      "                ",
      "                ",
      "                ",
      "                "
    ],
    [
      "bebeeecb        ",
      " e              ",
      " e              ",
      " e              ",
      "abbIIIcea       ",
      " a      a       ",
      " I      d       ",
      " I              ",
      " I              ",
      " I              ",
      " I              ",
      "                ",
      "                ",
      "                ",
      "                ",
      "                "
    ],
    [
      "eadeecaa        ",
      " b              ",
      " a              ",
      " b              ",
      "ecdcaddec       ",
      " a      d       ",
      " c              ",
      " c              ",
      " d              ",
      " a              ",
      "                ",
      "                ",
      "                ",
      "                ",
      "                ",
      "                "
    ]
  ]
}