{
  "xsize": 16,
  "zsize": 16,
  "palette": {
    "palette": [
      {
        "char": " ",
        "block": "minecraft:air"
      },
      {
        "char": "D",
        "block": "minecraft:smooth_stone_slab[type=bottom,waterlogged=false]"
      },
      {
        "char": "0",
        "block": "minecraft:stone_slab[type=bottom,waterlogged=false,weathering=false]"
      },
      {
        "char": "a",
        "block": "minecraft:cyan_terracotta"
      },
      {
        "char": "d",
        "block": "minecraft:cobbled_deepslate"
      },
      {
        "char": "Ѱ",
        "block": "minecraft:cobblestone_slab[type=bottom,waterlogged=false,weathering=false]"
      },
      {
        "char": "e",
        "block": "minecraft:basalt[axis=y]"
      },
      {
        "char": "b",
        "block": "minecraft:blackstone"
      },
      {
        "char": "g",
        "block": "minecraft:gray_concrete"
      },
      {
        "char": "c",
        "block": "minecraft:deepslate[axis=y]"
      },
      {
        "char": "i",
        "block": "minecraft:light_gray_concrete"
      },
      {
        "char": "f",
        "block": "minecraft:glass"
      },
      {
        "char": "O",
        "block": "minecraft:quartz_stairs[facing=west,half=bottom,shape=straight,waterlogged=false]"
      },
      {
        "char": "П",
        "block": "minecraft:barrel[facing=up,open=false]",
        "tag": {
          "z": -275,
          "x": -15,
          "ForgeData": {
            "LockFlag": "1b"
          },
          "id": "minecraft:barrel",
          "y": 2,
          "Items": []
        }
      },
      {
        "char": "s",
        "block": "minecraft:iron_trapdoor[facing=north,half=bottom,open=false,powered=false,waterlogged=false]"
      },
      {
        "char": "m",
        "block": "minecraft:iron_trapdoor[facing=west,half=bottom,open=false,powered=false,waterlogged=false]"
      },
      {
        "char": "Ѥ",
        "block": "minecraft:air",
        "tag": {
          "z": -276,
          "x": -43,
          "id": "refurbished_furniture:computer",
          "y": -39,
          "NodePos": "-11544873218087L",
          "Connections": [
            "L"
          ]
        }
      },
      {
        "char": "p",
        "block": "minecraft:iron_trapdoor[facing=north,half=top,open=false,powered=false,waterlogged=false]"
      },
      {
        "char": "q",
        "block": "minecraft:iron_trapdoor[facing=west,half=top,open=false,powered=false,waterlogged=false]"
      },
      {
        "char": "学",
        "block": "minecraft:air"
      }
    ]
  },
  "slices": [
    [
      "          DD0a0d",
      "          DѰD0aa",
      "          DD0aad",
      "          DDDead",
      "          0Dbabd",
      "        agDѰcaba",
      "        agDeaeaa",
      "          acgdbe",
      "          Dagbcd",
      "          Dcacca",
      "          egeeea",
      "          baeebd",
      "          daebbe",
      "          bgeaad",
      "         aeibcca",
      "          biddae"
    ],
    [
      "             a  ",
      "              e ",
      "              f ",
      "              f ",
      "                ",
      "             f  ",
      "            f   ",
      "          abg  b",
      "            f Ob",
      "               П",
      "           f    ",
      "               b",
      "           f  Ob",
      "           f   b",
      "         aeadbee",
      "           f    "
    ],
    [
      "             a s",
      "              cf",
      "             sf ",
      "             mf ",
      "            m   ",
      "            m   ",
      "           mf   ",
      "          ada   ",
      "           mf  Ѥ",
      "           mf   ",
      "          mf    ",
      "          mf    ",
      "          mf   Ѥ",
      "          mf    ",
      "         aaadebe",
      "          mf    "
    ],
    [
      "             a p",
      "              bf",
      "             qf ",
      "             q  ",
      "            qf  ",
      "            qf  ",
      "           qf   ",
      "          acg   ",
      "           qf   ",
      "           学f   ",
      "          qf    ",
      "          qf    ",
      "          qf    ",
      "          qf    ",
      "         adiccba",
      "          qf    "
    ],
    [
      "             a  ",
      "              af",
      "              f ",
      "                ",
      "             f  ",
      "             f  ",
      "            f   ",
      "          aea   ",
      "                ",
      "            f   ",
      "           f    ",
      "                ",
      "           f    ",
      "           f    ",
      "         aaadabc",
      "                "
    ],
    [
      "             i a",
      "              da",
      "             cg ",
      "             ag ",
      "            da  ",
      "            aa  ",
      "           ca   ",
      "          iea   ",
      "           cg   ",
      "           ba   ",
      "          aa    ",
      "          eg    ",
      "          ag    ",
      "          dg    ",
      "         aeaaccc",
      "          ba    "
    ]
  ]
}