{
  "xsize": 16,
  "zsize": 16,
  "palette": {
    "palette": [
      {
        "char": " ",
        "block": "minecraft:air"
      },
      {
        "char": "B",
        "block": "minecraft:air"
      },
      {
        "char": "y",
        "block": "minecraft:air"
      },
      {
        "char": "J",
        "block": "minecraft:air"
      },
      {
        "char": "Q",
        "block": "minecraft:air"
      },
      {
        "char": "d",
        "block": "minecraft:air"
      },
      {
        "char": "r",
        "block": "minecraft:air"
      },
      {
        "char": "c",
        "block": "minecraft:air"
      },
      {
        "char": "b",
        "block": "minecraft:air"
      },
      {
        "char": "n",
        "block": "minecraft:air"
      },
      {
        "char": "a",
        "block": "minecraft:air"
      },
      {
        "char": "资",
        "block": "minecraft:air"
      },
      {
        "char": "e",
        "block": "minecraft:air"
      },
      {
        "char": "C",
        "block": "minecraft:air"
      },
      {
        "char": "o",
        "block": "minecraft:air"
      },
      {
        "char": "Ѷ",
        "block": "minecraft:air"
      },
      {
        "char": "U",
        "block": "minecraft:tall_grass[half=lower]"
      },
      {
        "char": "Ѭ",
        "block": "minecraft:air"
      },
      {
        "char": "g",
        "block": "minecraft:air"
      },
      {
        "char": "ú",
        "block": "minecraft:air"
      },
      {
        "char": "i",
        "block": "minecraft:air"
      },
      {
        "char": "z",
        "block": "minecraft:air"
      },
      {
        "char": "f",
        "block": "minecraft:air"
      },
      {
        "char": "V",
        "block": "minecraft:tall_grass[half=upper]"
      },
      {
        "char": "G",
        "block": "minecraft:air"
      },
      {
        "char": "ѱ",
        "block": "minecraft:air"
      },
      {
        "char": "像",
        "block": "minecraft:air"
      },
      {
        "char": "麽",
        "block": "minecraft:air"
      }
    ]
  },
  "slices": [
    [
      "BBBBBBBBByJyQddQ",
      "BBBBBBBBBQrcbydc",
      "BBBBBBBBBdnacyyd",
      "BBBBBBBBBccyaydd",
      "BBBBBBBBB资eadQaQ",
      "BBBBBBBBBdbayQda",
      "CybrCorccoQybcbb",
      "cQyyQy资babdyyacb",
      "yacaaaddQycaddac",
      "cyabcaacQbbabcdc",
      "acyyddaydbQbQada",
      "bdycyydacbQbcyyd",
      "ayybaQbyyddydbQb",
      "ccbbbyydQydQcQbb",
      "bQbccdyabydydcbc",
      "aQdayccacbcaQayd"
    ],
    [
      "    ѶѶѶ     U  U",
      "                ",
      "    ѶѶѶ  e      ",
      "    ѶѶѶ Ѭaa     ",
      "        Ѭga  U U",
      " ѬѬѬѬ ѬѬѬdú  U  ",
      "baceabiaaaú     ",
      " U  U aa  z     ",
      "   b    U a     ",
      "        U       ",
      "          U U   ",
      "          U     ",
      "     U        U ",
      "        U  U U  ",
      " U              ",
      " U          U   "
    ],
    [
      "    f f     V  V",
      "                ",
      "    fff  b      ",
      "    ff  Ѭaa     ",
      "        Ѭga  V V",
      " ѬѬѬѬ ѬѬѬb   V  ",
      "dbddebaadc      ",
      " V  V ia  G     ",
      "   d    V b     ",
      "        V       ",
      "          V V   ",
      "          V     ",
      "     V        V ",
      "        V  V V  ",
      " V              ",
      " V          V   "
    ],
    [
      "    ѱ ѱ         ",
      "                ",
      "    ѱѱѱ  b      ",
      "    ѱѱ  Ѭag     ",
      "        Ѭaa     ",
      " ѬѬѬѬ ѬѬѬeú     ",
      "cccbdagada像     ",
      "      ga        ",
      "   c      d     ",
      "                ",
      "                ",
      "                ",
      "                ",
      "                ",
      "                ",
      "                "
    ],
    [
      "                ",
      "                ",
      "         e      ",
      "        Ѭig     ",
      "        Ѭai     ",
      " ѬѬѬѬ ѬѬѬbú     ",
      "bddeaeaadbú     ",
      "      aa  z     ",
      "   c      d     ",
      "                ",
      "                ",
      "                ",
      "                ",
      "                ",
      "                ",
      "                "
    ],
    [
      "                ",
      "         麽      ",
      "         a      ",
      "         ag     ",
      "         ag     ",
      "         b      ",
      "eadbedaaee      ",
      "      ga        ",
      "   d      d     ",
      "                ",
      "                ",
      "                ",
      "                ",
      "                ",
      "                ",
      "                "
    ]
  ]
}