{
  "xsize": 16,
  "zsize": 16,
  "palette": {
    "palette": [
      {
        "char": " ",
        "block": "minecraft:air"
      },
      {
        "char": "a",
        "block": "minecraft:cyan_terracotta"
      },
      {
        "char": "g",
        "block": "minecraft:gray_concrete"
      },
      {
        "char": "d",
        "block": "minecraft:cobbled_deepslate"
      },
      {
        "char": "e",
        "block": "minecraft:basalt[axis=y]"
      },
      {
        "char": "b",
        "block": "minecraft:blackstone"
      },
      {
        "char": "c",
        "block": "minecraft:deepslate[axis=y]"
      },
      {
        "char": "i",
        "block": "minecraft:light_gray_concrete"
      },
      {
        "char": "f",
        "block": "minecraft:glass"
      },
      {
        "char": "ϕ",
        "block": "minecraft:quartz_stairs[facing=north,half=bottom,shape=straight,waterlogged=false]"
      },
      {
        "char": "O",
        "block": "minecraft:quartz_stairs[facing=west,half=bottom,shape=straight,waterlogged=false]"
      },
      {
        "char": "ϓ",
        "block": "minecraft:air"
      },
      {
        "char": "ϔ",
        "block": "minecraft:quartz_stairs[facing=east,half=bottom,shape=straight,waterlogged=false]"
      },
      {
        "char": "s",
        "block": "minecraft:iron_trapdoor[facing=north,half=bottom,open=false,powered=false,waterlogged=false]"
      },
      {
        "char": "l",
        "block": "minecraft:iron_trapdoor[facing=east,half=bottom,open=false,powered=false,waterlogged=false]"
      },
      {
        "char": "成",
        "block": "minecraft:air"
      },
      {
        "char": "多",
        "block": "minecraft:air"
      },
      {
        "char": "p",
        "block": "minecraft:iron_trapdoor[facing=north,half=top,open=false,powered=false,waterlogged=false]"
      }
    ]
  },
  "slices": [
    [
      "                ",
      "                ",
      "                ",
      "                ",
      "                ",
      "                ",
      "aagaaa          ",
      "daebcdgaga      ",
      "aaaaagdcabaa    ",
      "eccedeagaaeaig  ",
      "debcdebbabaadbga",
      "cbaecddddaecgabi",
      "cbbeeeedeccbeead",
      "dcebcdbabcaaedeg",
      "baccbbaccadedebc",
      "aeeadbeedeecdbdb"
    ],
    [
      "                ",
      "                ",
      "                ",
      "                ",
      "                ",
      "                ",
      " a              ",
      " d      g       ",
      " g fff  e       ",
      " a    ffaf      ",
      " b      b ff   a",
      " d      a   ffb ",
      " d a ϕ  e     f ",
      " b b    a      f",
      " d eeaabc  ϕ    ",
      " d      c Oϓϔ   "
    ],
    [
      "                ",
      "                ",
      "                ",
      "                ",
      "                ",
      "                ",
      " g              ",
      "sdssss  a       ",
      "fa  ffsscs      ",
      " a    ffafss    ",
      " e      c ffss a",
      " b      b   ffb ",
      " a      d      l",
      " e      d      f",
      " b 成多 多成e       ",
      " b      b       "
    ],
    [
      "                ",
      "                ",
      "                ",
      "                ",
      "                ",
      "                ",
      " g              ",
      "pepppp  a       ",
      " gffffppbp      ",
      " e     fafpp    ",
      " e      d ffpp a",
      " b      d    fc ",
      " e      e     fp",
      " d      d      f",
      " b      d       ",
      " d      e       "
    ],
    [
      "                ",
      "                ",
      "                ",
      "                ",
      "                ",
      "                ",
      " a              ",
      " c      a       ",
      " afff   a       ",
      " b    ffg       ",
      " b      a ff   g",
      " e      c   ffc ",
      " b      d     f ",
      " d      e      f",
      " d      c       ",
      " c      c       "
    ],
    [
      "                ",
      "                ",
      "                ",
      "                ",
      "                ",
      "                ",
      " a              ",
      "ebebaa  i       ",
      "aaagageedc      ",
      " c    iaaaee    ",
      " a      c aaeb i",
      " e      a   aic ",
      " d      d     ad",
      " b      c      g",
      " b      a       ",
      " a      a       "
    ]
  ]
}