{
  "xsize": 16,
  "zsize": 16,
  "palette": {
    "palette": [
      {
        "char": " ",
        "block": "minecraft:air"
      },
      {
        "char": "d",
        "block": "minecraft:cobbled_deepslate"
      },
      {
        "char": "a",
        "block": "minecraft:cyan_terracotta"
      },
      {
        "char": "c",
        "block": "minecraft:deepslate[axis=y]"
      },
      {
        "char": "b",
        "block": "minecraft:blackstone"
      },
      {
        "char": "e",
        "block": "minecraft:basalt[axis=y]"
      },
      {
        "char": "Z",
        "block": "minecraft:stone_brick_wall[east=tall,north=tall,south=none,up=true,waterlogged=false,weathering=false,west=tall]"
      },
      {
        "char": "Ӿ",
        "block": "minecraft:cobblestone_wall[east=tall,north=tall,south=none,up=true,waterlogged=false,weathering=false,west=tall]"
      },
      {
        "char": "G",
        "block": "minecraft:iron_bars[east=false,north=false,south=true,waterlogged=false,west=false]"
      },
      {
        "char": "H",
        "block": "minecraft:quartz_stairs[facing=south,half=bottom,shape=straight,waterlogged=false]"
      },
      {
        "char": "O",
        "block": "minecraft:quartz_stairs[facing=west,half=bottom,shape=straight,waterlogged=false]"
      },
      {
        "char": "ϓ",
        "block": "minecraft:air"
      },
      {
        "char": "x",
        "block": "minecraft:cauldron"
      },
      {
        "char": "C",
        "block": "minecraft:quartz_pillar[axis=y]"
      },
      {
        "char": "v",
        "block": "minecraft:quartz_pillar[axis=x]"
      },
      {
        "char": "o",
        "block": "minecraft:chiseled_quartz_block"
      },
      {
        "char": "Ѳ",
        "block": "minecraft:white_stained_glass_pane[east=true,north=false,south=false,waterlogged=false,west=false]"
      },
      {
        "char": "N",
        "block": "minecraft:white_stained_glass_pane[east=true,north=false,south=false,waterlogged=false,west=true]"
      },
      {
        "char": "k",
        "block": "minecraft:oak_leaves[distance=7,persistent=true,waterlogged=false]"
      },
      {
        "char": "n",
        "block": "minecraft:smooth_quartz"
      },
      {
        "char": "K",
        "block": "minecraft:quartz_block"
      },
      {
        "char": "j",
        "block": "minecraft:polished_andesite_slab[type=top,waterlogged=false]"
      },
      {
        "char": "r",
        "block": "minecraft:polished_diorite"
      }
    ]
  },
  "slices": [
    [
      "ddacaabedbcdbc  ",
      "eadcaabdadeceaae",
      "baccbcccddcaebac",
      "edbbabedbdabdada",
      "ebaaaeaaedbbddda",
      "eeedaceabdbeeabd",
      "ededaacdbceecabe",
      "dbcadeebadaacedc",
      "acdaaadedaeeadae",
      "ecdcdeebaeeeaddd",
      "baebcdeecebcddba",
      "cebbababddbdeaec",
      "ZZZbӾZӾdbedecccb",
      "   c   baaadbdbc",
      "   b   acbdecdad",
      " G e G dccebdeed"
    ],
    [
      " d      d  H    ",
      " c              ",
      " d            Oϓ",
      " e      d      H",
      "dacbeebde       ",
      " b  x  b        ",
      "       a        ",
      "             cae",
      "             e  ",
      "             b  ",
      "       a     b  ",
      "   c   e        ",
      "Cvoevvva        ",
      "   b   d     a  ",
      "   c   cc   aabb",
      " G a G a     d  "
    ],
    [
      " d      b       ",
      " b              ",
      " d              ",
      " e      a       ",
      "ebe ѲNabe       ",
      " b  k  c        ",
      "       d        ",
      "             aab",
      "             b  ",
      "             e  ",
      "       c     d  ",
      "   e   b        ",
      "vvndKnvc        ",
      "   c   e     d  ",
      "   a   cc   dcac",
      " G c G d     e  "
    ],
    [
      " d      a       ",
      " d              ",
      " e              ",
      " a      e       ",
      "eabNNNbae       ",
      " b  k  d        ",
      "       d        ",
      "             eab",
      "             a  ",
      "             b  ",
      "       a     c  ",
      "   c   d        ",
      "nvvdvvvd        ",
      "   b   e     e  ",
      "   c   de   abde",
      " G a G c     a  "
    ],
    [
      " b      c       ",
      " b      j       ",
      " b      j       ",
      " d      c       ",
      "adceacdcd       ",
      " a     d        ",
      "       e        ",
      "       j     aab",
      "       j     d  ",
      "       j     a  ",
      "       b     d  ",
      "jjjbjjje     j  ",
      "vordvvvc     j  ",
      "   a   a     e  ",
      "   e   bajjjcdcd",
      " G e G b     c  "
    ],
    [
      " c      b       ",
      " d      b       ",
      " a      c       ",
      " a      e       ",
      "aeeaeddcc       ",
      " b     e        ",
      "       c        ",
      "       e     dbc",
      "       e     b  ",
      "       d     b  ",
      "       c     b  ",
      "ccebabde     e  ",
      "   b   c     c  ",
      "   e   e     e  ",
      "   a   ecedcdaea",
      " G b G d     c  "
    ]
  ]
}