{
  "xsize": 16,
  "zsize": 16,
  "palette": {
    "palette": [
      {
        "char": " ",
        "block": "minecraft:air"
      },
      {
        "char": "a",
        "block": "minecraft:cyan_terracotta"
      },
      {
        "char": "e",
        "block": "minecraft:basalt[axis=y]"
      },
      {
        "char": "b",
        "block": "minecraft:blackstone"
      },
      {
        "char": "c",
        "block": "minecraft:deepslate[axis=y]"
      },
      {
        "char": "d",
        "block": "minecraft:cobbled_deepslate"
      },
      {
        "char": "g",
        "block": "minecraft:gray_concrete"
      },
      {
        "char": "i",
        "block": "minecraft:light_gray_concrete"
      },
      {
        "char": "f",
        "block": "minecraft:glass"
      },
      {
        "char": "H",
        "block": "minecraft:quartz_stairs[facing=south,half=bottom,shape=straight,waterlogged=false]"
      },
      {
        "char": "u",
        "block": "minecraft:iron_trapdoor[facing=south,half=bottom,open=false,powered=false,waterlogged=false]"
      },
      {
        "char": "ϐ",
        "block": "minecraft:air",
        "tag": {
          "z": -259,
          "x": -34,
          "id": "refurbished_furniture:computer",
          "y": -21,
          "NodePos": "-9070971985941L",
          "Connections": [
            "L"
          ]
        }
      },
      {
        "char": "w",
        "block": "minecraft:iron_trapdoor[facing=south,half=top,open=false,powered=false,waterlogged=false]"
      },
      {
        "char": "q",
        "block": "minecraft:iron_trapdoor[facing=west,half=top,open=false,powered=false,waterlogged=false]"
      }
    ]
  },
  "slices": [
    [
      " aaaaebeaaacbecd",
      "  aaeageedbbbbcb",
      "   agedaaaccaaba",
      "     aiaaaaaideb",
      "       aaaecbaaa",
      "         aa  eda",
      "                ",
      "                ",
      "  d      d      ",
      "                ",
      "                ",
      "                ",
      "                ",
      "                ",
      "                ",
      "                "
    ],
    [
      "    f    aee bee",
      "    bff   H   H ",
      "   a   ff       ",
      "          gff   ",
      "          e  f f",
      "          a     ",
      "                ",
      "                ",
      "  a      b      ",
      "                ",
      "                ",
      "                ",
      "                ",
      "                ",
      "                ",
      "                "
    ],
    [
      "  uuf     ϐ   ϐ ",
      "    bff         ",
      "   a uuff       ",
      "       uufgff   ",
      "         ucuuff ",
      "          a  uuu",
      "                ",
      "                ",
      "  e      c      ",
      "                ",
      "                ",
      "                ",
      "                ",
      "                ",
      "                ",
      "                "
    ],
    [
      "  wqf           ",
      "    e f         ",
      "   a wwf        ",
      "       wwfgff   ",
      "         wawwff ",
      "          a  www",
      "                ",
      "                ",
      "  d      c      ",
      "                ",
      "                ",
      "                ",
      "                ",
      "                ",
      "                ",
      "                "
    ],
    [
      "    f           ",
      "    ef          ",
      "   g   ff       ",
      "         faff   ",
      "          e  f f",
      "          a     ",
      "                ",
      "                ",
      "  a      e      ",
      "                ",
      "                ",
      "                ",
      "                ",
      "                ",
      "                ",
      "                "
    ],
    [
      "  dbi           ",
      "    aaa         ",
      "   a acaa       ",
      "       ecgaaa   ",
      "         eeaegaa",
      "          a  aba",
      "                ",
      "                ",
      "  c      c      ",
      "                ",
      "                ",
      "                ",
      "                ",
      "                ",
      "                ",
      "                "
    ]
  ]
}