{
  "xsize": 16,
  "zsize": 16,
  "palette": {
    "palette": [
      {
        "char": " ",
        "block": "minecraft:air"
      },
      {
        "char": "c",
        "block": "minecraft:deepslate[axis=y]"
      },
      {
        "char": "e",
        "block": "minecraft:basalt[axis=y]"
      },
      {
        "char": "d",
        "block": "minecraft:cobbled_deepslate"
      },
      {
        "char": "a",
        "block": "minecraft:cyan_terracotta"
      },
      {
        "char": "b",
        "block": "minecraft:blackstone"
      },
      {
        "char": "g",
        "block": "minecraft:gray_concrete"
      },
      {
        "char": "i",
        "block": "minecraft:light_gray_concrete"
      },
      {
        "char": "ϔ",
        "block": "minecraft:quartz_stairs[facing=east,half=bottom,shape=straight,waterlogged=false]"
      },
      {
        "char": "f",
        "block": "minecraft:glass"
      },
      {
        "char": "П",
        "block": "minecraft:barrel[facing=up,open=false]",
        "tag": {
          "z": -275,
          "x": -15,
          "ForgeData": {
            "LockFlag": "1b"
          },
          "id": "minecraft:barrel",
          "y": 2,
          "Items": []
        }
      },
      {
        "char": "x",
        "block": "minecraft:cauldron"
      },
      {
        "char": "H",
        "block": "minecraft:quartz_stairs[facing=south,half=bottom,shape=straight,waterlogged=false]"
      },
      {
        "char": "下",
        "block": "minecraft:air"
      },
      {
        "char": "Ӟ",
        "block": "minecraft:air"
      },
      {
        "char": "l",
        "block": "minecraft:iron_trapdoor[facing=east,half=bottom,open=false,powered=false,waterlogged=false]"
      },
      {
        "char": "k",
        "block": "minecraft:oak_leaves[distance=7,persistent=true,waterlogged=false]"
      },
      {
        "char": "ο",
        "block": "minecraft:air"
      },
      {
        "char": "ѧ",
        "block": "minecraft:air"
      },
      {
        "char": "u",
        "block": "minecraft:iron_trapdoor[facing=south,half=bottom,open=false,powered=false,waterlogged=false]"
      },
      {
        "char": "t",
        "block": "minecraft:iron_trapdoor[facing=east,half=top,open=false,powered=false,waterlogged=false]"
      },
      {
        "char": "w",
        "block": "minecraft:iron_trapdoor[facing=south,half=top,open=false,powered=false,waterlogged=false]"
      }
    ]
  },
  "slices": [
    [
      "cecdecdae       ",
      "eadbeadac       ",
      "dbacaccge       ",
      "ccadcdaa        ",
      "dbbeeeaa        ",
      "ecbcbdacg       ",
      "cdccceacg       ",
      "babbagcg        ",
      "cadeaaca        ",
      "bbababg         ",
      "daadaba         ",
      "ccbaei          ",
      "ebadai          ",
      "cdgea           ",
      "eida            ",
      "ada             "
    ],
    [
      "d ϔ    f        ",
      "a      f        ",
      "Пaa    f        ",
      "      f         ",
      "      f         ",
      "aedecdaaa       ",
      "  x   f         ",
      "     f          ",
      "                ",
      "                ",
      "cd  f           ",
      "H  fd           ",
      "  f  a          ",
      "  f             ",
      "                ",
      "f               "
    ],
    [
      "下      fӞ       ",
      "       fl       ",
      "        l       ",
      "      fl        ",
      "      fl        ",
      "ccaeedaeg       ",
      "  k   fl        ",
      "     fl         ",
      "     fl         ",
      "    fl          ",
      "οѧ  fl          ",
      "   fa           ",
      "  fu a          ",
      "  fl            ",
      " fl             ",
      "fl              "
    ],
    [
      "       ft       ",
      "       ft       ",
      "       ft       ",
      "      ft        ",
      "      ft        ",
      "cccaecgda       ",
      "  k   ft        ",
      "     ft         ",
      "     ft         ",
      "    ft          ",
      "     t          ",
      "    a           ",
      "   w a          ",
      "   t            ",
      " ft             ",
      " w              "
    ],
    [
      "       f        ",
      "       f        ",
      "       f        ",
      "      f         ",
      "                ",
      "daccaegea       ",
      "      f         ",
      "     f          ",
      "     f          ",
      "                ",
      "    f           ",
      "   fe           ",
      "     a          ",
      "                ",
      " f              ",
      "                "
    ],
    [
      "       ad       ",
      "       ac       ",
      "       gd       ",
      "      ab        ",
      "      ad        ",
      "beabaaabi       ",
      "      gd        ",
      "     ad         ",
      "     ad         ",
      "    ge          ",
      "    ac          ",
      "   ad           ",
      "  gc a          ",
      "  ae            ",
      " id             ",
      "ac              "
    ]
  ]
}