{
  "xsize": 16,
  "zsize": 16,
  "palette": {
    "palette": [
      {
        "char": " ",
        "block": "minecraft:air"
      },
      {
        "char": "a",
        "block": "minecraft:cyan_terracotta"
      },
      {
        "char": "d",
        "block": "minecraft:cobbled_deepslate"
      },
      {
        "char": "e",
        "block": "minecraft:basalt[axis=y]"
      },
      {
        "char": "b",
        "block": "minecraft:blackstone"
      },
      {
        "char": "c",
        "block": "minecraft:deepslate[axis=y]"
      },
      {
        "char": "Z",
        "block": "minecraft:stone_brick_wall[east=tall,north=tall,south=none,up=true,waterlogged=false,weathering=false,west=tall]"
      },
      {
        "char": "G",
        "block": "minecraft:iron_bars[east=false,north=false,south=true,waterlogged=false,west=false]"
      },
      {
        "char": "H",
        "block": "minecraft:quartz_stairs[facing=south,half=bottom,shape=straight,waterlogged=false]"
      },
      {
        "char": "ϕ",
        "block": "minecraft:quartz_stairs[facing=north,half=bottom,shape=straight,waterlogged=false]"
      },
      {
        "char": "O",
        "block": "minecraft:quartz_stairs[facing=west,half=bottom,shape=straight,waterlogged=false]"
      },
      {
        "char": "ϓ",
        "block": "minecraft:air"
      },
      {
        "char": "x",
        "block": "minecraft:cauldron"
      },
      {
        "char": "v",
        "block": "minecraft:quartz_pillar[axis=x]"
      },
      {
        "char": "J",
        "block": "minecraft:diorite"
      },
      {
        "char": "N",
        "block": "minecraft:white_stained_glass_pane[east=true,north=false,south=false,waterlogged=false,west=true]"
      },
      {
        "char": "k",
        "block": "minecraft:oak_leaves[distance=7,persistent=true,waterlogged=false]"
      },
      {
        "char": "o",
        "block": "minecraft:chiseled_quartz_block"
      },
      {
        "char": "n",
        "block": "minecraft:smooth_quartz"
      },
      {
        "char": "j",
        "block": "minecraft:polished_andesite_slab[type=top,waterlogged=false]"
      },
      {
        "char": "r",
        "block": "minecraft:polished_diorite"
      },
      {
        "char": "C",
        "block": "minecraft:quartz_pillar[axis=y]"
      }
    ]
  },
  "slices": [
    [
      "addebccbaaecbcac",
      "dbedbeaceaededeb",
      "dbbbcbabaddabbba",
      "caebeaaccddecaee",
      "dbccdcebebcbdaed",
      "debdeebddeeeaedd",
      "deabdaeddadaadbc",
      "acddbddddaebbbba",
      "edaaaddabaeaeabb",
      "ebdccbcabddaeaec",
      "ccdadcebacbdacce",
      "ccdaaeaaddbdbbba",
      "ZZZeZZZbdcceaeaa",
      "   c   cbbdaeeca",
      "   d   eccbddddc",
      " G e G cbaedbbec"
    ],
    [
      " e      e  H    ",
      " e             ϕ",
      " a            Oϓ",
      " b      c      H",
      "bdcaeecbc       ",
      " e  x  d        ",
      "       a        ",
      "             dcb",
      "             c  ",
      "             a  ",
      "       a     b  ",
      "   d   d        ",
      "vvvdvJve        ",
      "   d   b     e  ",
      "   b   cc   cdeb",
      " G d G c     b  "
    ],
    [
      " a      a       ",
      " e              ",
      " d              ",
      " e      e       ",
      "ddcNNNeba       ",
      " c  k  d        ",
      "       a        ",
      "             bac",
      "             a  ",
      "             e  ",
      "       a     b  ",
      "   b   b        ",
      "vovcvvne        ",
      "   a   a     c  ",
      "   c   db   ceee",
      " G b G e     b  "
    ],
    [
      " e      d       ",
      " a              ",
      " c              ",
      " e      b       ",
      "eabNNNdaa       ",
      " e  k  e        ",
      "       b        ",
      "             acd",
      "             b  ",
      "             b  ",
      "       c     b  ",
      "   e   d        ",
      "vvocvvva        ",
      "   b   c     e  ",
      "   d   ed   ceda",
      " G b G a     a  "
    ],
    [
      " d      a       ",
      " c      j       ",
      " b      j       ",
      " c      b       ",
      "addccedcb       ",
      " a     e        ",
      "       d        ",
      "       j     eed",
      "       j     a  ",
      "       j     d  ",
      "       b     b  ",
      "jjjejjjd     j  ",
      "rvCcvvve     j  ",
      "   e   d     a  ",
      "   e   dbjjjdced",
      " G e G e     b  "
    ],
    [
      " e      a       ",
      " b      e       ",
      " c      d       ",
      " c      c       ",
      "aacbdabda       ",
      " c     c        ",
      "       c        ",
      "       e     cdc",
      "       c     e  ",
      "       d     d  ",
      "       d     a  ",
      "dcbecbec     d  ",
      "   b   c     b  ",
      "   d   c     c  ",
      "   b   cabceccab",
      " G a G e     c  "
    ]
  ]
}