{
  "xsize": 16,
  "zsize": 16,
  "palette": {
    "palette": [
      {
        "char": " ",
        "block": "minecraft:air"
      },
      {
        "char": "a",
        "block": "minecraft:cyan_terracotta"
      },
      {
        "char": "b",
        "block": "minecraft:blackstone"
      },
      {
        "char": "e",
        "block": "minecraft:basalt[axis=y]"
      },
      {
        "char": "i",
        "block": "minecraft:light_gray_concrete"
      },
      {
        "char": "c",
        "block": "minecraft:deepslate[axis=y]"
      },
      {
        "char": "d",
        "block": "minecraft:cobbled_deepslate"
      },
      {
        "char": "g",
        "block": "minecraft:gray_concrete"
      },
      {
        "char": "f",
        "block": "minecraft:glass"
      },
      {
        "char": "ϔ",
        "block": "minecraft:quartz_stairs[facing=east,half=bottom,shape=straight,waterlogged=false]"
      },
      {
        "char": "s",
        "block": "minecraft:iron_trapdoor[facing=north,half=bottom,open=false,powered=false,waterlogged=false]"
      },
      {
        "char": "l",
        "block": "minecraft:iron_trapdoor[facing=east,half=bottom,open=false,powered=false,waterlogged=false]"
      },
      {
        "char": "信",
        "block": "minecraft:air"
      },
      {
        "char": "下",
        "block": "minecraft:air"
      },
      {
        "char": "因",
        "block": "minecraft:air"
      },
      {
        "char": "p",
        "block": "minecraft:iron_trapdoor[facing=north,half=top,open=false,powered=false,waterlogged=false]"
      },
      {
        "char": "t",
        "block": "minecraft:iron_trapdoor[facing=east,half=top,open=false,powered=false,waterlogged=false]"
      }
    ]
  },
  "slices": [
    [
      "   aaa          ",
      "abaaba          ",
      "ebebica         ",
      "acbdadg         ",
      "bcdaagcg        ",
      "babccada        ",
      "bbccceaca       ",
      "ecbbeeadg       ",
      "baaacdgd        ",
      "dcbabcab        ",
      "ccbabebga       ",
      "aaabbddgc       ",
      "dededadie       ",
      "bdbecbcab       ",
      "ecbbaaaabi      ",
      "cdeccaaac       "
    ],
    [
      "     g          ",
      "   fc           ",
      "    f           ",
      "    f           ",
      "                ",
      "     f          ",
      "      f         ",
      "adaeeeaba       ",
      "      f         ",
      "      f         ",
      " aab   f        ",
      " c     f        ",
      " d ϔ            ",
      " d              ",
      "ddeeaadaaa      ",
      "d      f        "
    ],
    [
      "  fs i          ",
      "    e           ",
      "    fl          ",
      "    fl          ",
      "     fl         ",
      "      l         ",
      "      fl        ",
      "ccaebbaaa       ",
      "       l        ",
      "      fl        ",
      "       fl       ",
      " 信      l       ",
      " 下     fl       ",
      "       fl       ",
      "dabaacdaea      ",
      "因      fl       "
    ],
    [
      "  fp a          ",
      "   fd           ",
      "    ft          ",
      "    ft          ",
      "     ft         ",
      "     ft         ",
      "      ft        ",
      "cdbbccabi       ",
      "      ft        ",
      "      ft        ",
      "       ft       ",
      "       ft       ",
      "        t       ",
      "       ft       ",
      "ebaadeaaca      ",
      "       ft       "
    ],
    [
      "  f  a          ",
      "   fd           ",
      "                ",
      "    f           ",
      "     f          ",
      "     f          ",
      "      f         ",
      "eecacbici       ",
      "      f         ",
      "      f         ",
      "       f        ",
      "       f        ",
      "                ",
      "       f        ",
      "abbcccagcg      ",
      "       f        "
    ],
    [
      "  ae g          ",
      "   ad           ",
      "    gd          ",
      "    ae          ",
      "     aa         ",
      "     ae         ",
      "      gb        ",
      "ccabebabg       ",
      "      ac        ",
      "      aa        ",
      "       ad       ",
      "       id       ",
      "       ab       ",
      "       ab       ",
      "bbcdeaeida      ",
      "       ac       "
    ]
  ]
}