{
  "xsize": 16,
  "zsize": 16,
  "palette": {
    "palette": [
      {
        "char": " ",
        "block": "minecraft:air"
      },
      {
        "char": "g",
        "block": "minecraft:gray_concrete"
      },
      {
        "char": "c",
        "block": "minecraft:deepslate[axis=y]"
      },
      {
        "char": "a",
        "block": "minecraft:cyan_terracotta"
      },
      {
        "char": "d",
        "block": "minecraft:cobbled_deepslate"
      },
      {
        "char": "e",
        "block": "minecraft:basalt[axis=y]"
      },
      {
        "char": "i",
        "block": "minecraft:light_gray_concrete"
      },
      {
        "char": "b",
        "block": "minecraft:blackstone"
      },
      {
        "char": "f",
        "block": "minecraft:glass"
      },
      {
        "char": "ϕ",
        "block": "minecraft:quartz_stairs[facing=north,half=bottom,shape=straight,waterlogged=false]"
      },
      {
        "char": "O",
        "block": "minecraft:quartz_stairs[facing=west,half=bottom,shape=straight,waterlogged=false]"
      },
      {
        "char": "ϓ",
        "block": "minecraft:air"
      },
      {
        "char": "ϔ",
        "block": "minecraft:quartz_stairs[facing=east,half=bottom,shape=straight,waterlogged=false]"
      },
      {
        "char": "s",
        "block": "minecraft:iron_trapdoor[facing=north,half=bottom,open=false,powered=false,waterlogged=false]"
      },
      {
        "char": "l",
        "block": "minecraft:iron_trapdoor[facing=east,half=bottom,open=false,powered=false,waterlogged=false]"
      },
      {
        "char": "Ҝ",
        "block": "minecraft:air",
        "tag": {
          "z": -292,
          "x": -29,
          "id": "refurbished_furniture:computer",
          "y": 63,
          "NodePos": "-7696582590401L",
          "Connections": [
            "L"
          ]
        }
      },
      {
        "char": "p",
        "block": "minecraft:iron_trapdoor[facing=north,half=top,open=false,powered=false,waterlogged=false]"
      }
    ]
  },
  "slices": [
    [
      "                ",
      "                ",
      "                ",
      "                ",
      "                ",
      "                ",
      " g              ",
      "caadea  a       ",
      "aaiaaaeedd      ",
      "edaccciigibe    ",
      "aacddbbcbcaaca g",
      "dbdbceddbdaaaaag",
      "edadebccececbeaa",
      "acacbdecbbedabea",
      "ddacabcbccabaadc",
      "ecceeceadecdbecc"
    ],
    [
      "                ",
      "                ",
      "                ",
      "                ",
      "                ",
      "                ",
      " a              ",
      " b      a       ",
      "faf  f  d       ",
      " a    ffaf      ",
      " c      d ff   a",
      " e      a   ffd ",
      " b e ϕ  a     f ",
      " d e    d      f",
      " b daadad  ϕ    ",
      " c      b Oϓϔ   "
    ],
    [
      "                ",
      "                ",
      "                ",
      "                ",
      "                ",
      "                ",
      " a              ",
      "sbssss  i       ",
      "fa ff ssbs      ",
      " e    f a ss    ",
      " c      d f ss i",
      " a      a    fc ",
      " b      c     fl",
      " c      d      f",
      " c  Ҝ Ҝ c       ",
      " a      c       "
    ],
    [
      "                ",
      "                ",
      "                ",
      "                ",
      "                ",
      "                ",
      " a              ",
      "pcpppp  a       ",
      "faf  fppep      ",
      " b    f afpp    ",
      " d      a ffpp g",
      " a      a   ffd ",
      " a      a      p",
      " d      d      f",
      " a      d       ",
      " c      b       "
    ],
    [
      "                ",
      "                ",
      "                ",
      "                ",
      "                ",
      "                ",
      " g              ",
      " c      g       ",
      " af ff  b       ",
      " b    ffgf      ",
      " e      d f    a",
      " a      c   ffe ",
      " c      a     f ",
      " d      c       ",
      " c      a       ",
      " a      c       "
    ],
    [
      "                ",
      "                ",
      "                ",
      "                ",
      "                ",
      "                ",
      " a              ",
      "abdeee  g       ",
      "igaaiacbca      ",
      " e    aiggbd    ",
      " b      d aabc i",
      " d      b   gab ",
      " a      c     aa",
      " b      a      a",
      " e      c       ",
      " a      e       "
    ]
  ]
}