{
  "xsize": 16,
  "zsize": 16,
  "palette": {
    "palette": [
      {
        "char": " ",
        "block": "minecraft:air"
      },
      {
        "char": "g",
        "block": "minecraft:gray_concrete"
      },
      {
        "char": "a",
        "block": "minecraft:cyan_terracotta"
      },
      {
        "char": "d",
        "block": "minecraft:cobbled_deepslate"
      },
      {
        "char": "c",
        "block": "minecraft:deepslate[axis=y]"
      },
      {
        "char": "i",
        "block": "minecraft:light_gray_concrete"
      },
      {
        "char": "e",
        "block": "minecraft:basalt[axis=y]"
      },
      {
        "char": "b",
        "block": "minecraft:blackstone"
      },
      {
        "char": "f",
        "block": "minecraft:glass"
      },
      {
        "char": "O",
        "block": "minecraft:quartz_stairs[facing=west,half=bottom,shape=straight,waterlogged=false]"
      },
      {
        "char": "s",
        "block": "minecraft:iron_trapdoor[facing=north,half=bottom,open=false,powered=false,waterlogged=false]"
      },
      {
        "char": "m",
        "block": "minecraft:iron_trapdoor[facing=west,half=bottom,open=false,powered=false,waterlogged=false]"
      },
      {
        "char": "Ѫ",
        "block": "minecraft:air"
      },
      {
        "char": "Ӝ",
        "block": "minecraft:air"
      },
      {
        "char": "p",
        "block": "minecraft:iron_trapdoor[facing=north,half=top,open=false,powered=false,waterlogged=false]"
      },
      {
        "char": "q",
        "block": "minecraft:iron_trapdoor[facing=west,half=top,open=false,powered=false,waterlogged=false]"
      }
    ]
  },
  "slices": [
    [
      "             gad",
      "             aag",
      "            acia",
      "            aaae",
      "           adacb",
      "           abibc",
      "          acabbc",
      "          gbadab",
      "           agcab",
      "           agdec",
      "          baaecb",
      "          cadcbe",
      "          eaabca",
      "          babcac",
      "         aeacdae",
      "          eaeddd"
    ],
    [
      "             a  ",
      "              d ",
      "              f ",
      "              f ",
      "             f  ",
      "             f  ",
      "            f   ",
      "          abg  d",
      "            f Od",
      "            f  e",
      "           f    ",
      "           f   e",
      "              Oa",
      "           f   e",
      "         gdgaeba",
      "           f    "
    ],
    [
      "             a s",
      "              bf",
      "             sf ",
      "             m  ",
      "            mf  ",
      "            m   ",
      "           mf   ",
      "          gda   ",
      "           mf  Ѫ",
      "           mf  Ӝ",
      "          mf    ",
      "          mf    ",
      "          mf   Ѫ",
      "          m    Ӝ",
      "         aaaeaab",
      "          mf    "
    ],
    [
      "             a p",
      "              e ",
      "             qf ",
      "             q  ",
      "            qf  ",
      "            q   ",
      "           qf   ",
      "          abg   ",
      "           qf   ",
      "           qf   ",
      "          qf    ",
      "          qf    ",
      "          qf    ",
      "          qf    ",
      "         gdaabbd",
      "          qf    "
    ],
    [
      "             a  ",
      "              ef",
      "              f ",
      "                ",
      "                ",
      "                ",
      "            f   ",
      "          aba   ",
      "            f   ",
      "                ",
      "           f    ",
      "           f    ",
      "           f    ",
      "                ",
      "         aeidaee",
      "           f    "
    ],
    [
      "             g c",
      "              ea",
      "             ca ",
      "             eg ",
      "            da  ",
      "            aa  ",
      "           ca   ",
      "          aaa   ",
      "           da   ",
      "           bi   ",
      "          aa    ",
      "          da    ",
      "          aa    ",
      "          ca    ",
      "         ibgccbd",
      "          bg    "
    ]
  ]
}