{
  "xsize": 16,
  "zsize": 16,
  "palette": {
    "palette": [
      {
        "char": " ",
        "block": "minecraft:air"
      },
      {
        "char": "g",
        "block": "minecraft:gray_concrete"
      },
      {
        "char": "i",
        "block": "minecraft:light_gray_concrete"
      },
      {
        "char": "a",
        "block": "minecraft:cyan_terracotta"
      },
      {
        "char": "b",
        "block": "minecraft:blackstone"
      },
      {
        "char": "c",
        "block": "minecraft:deepslate[axis=y]"
      },
      {
        "char": "d",
        "block": "minecraft:cobbled_deepslate"
      },
      {
        "char": "e",
        "block": "minecraft:basalt[axis=y]"
      },
      {
        "char": "x",
        "block": "minecraft:cauldron"
      },
      {
        "char": "f",
        "block": "minecraft:glass"
      },
      {
        "char": "П",
        "block": "minecraft:barrel[facing=up,open=false]",
        "tag": {
          "z": -275,
          "x": -15,
          "ForgeData": {
            "LockFlag": "1b"
          },
          "id": "minecraft:barrel",
          "y": 2,
          "Items": []
        }
      },
      {
        "char": "ϔ",
        "block": "minecraft:quartz_stairs[facing=east,half=bottom,shape=straight,waterlogged=false]"
      },
      {
        "char": "k",
        "block": "minecraft:oak_leaves[distance=7,persistent=true,waterlogged=false]"
      },
      {
        "char": "l",
        "block": "minecraft:iron_trapdoor[facing=east,half=bottom,open=false,powered=false,waterlogged=false]"
      },
      {
        "char": "Ӻ",
        "block": "minecraft:air",
        "tag": {
          "z": -276,
          "x": -15,
          "id": "refurbished_furniture:computer",
          "y": 27,
          "NodePos": "-3848291827685L",
          "Connections": [
            "L"
          ]
        }
      },
      {
        "char": "t",
        "block": "minecraft:iron_trapdoor[facing=east,half=top,open=false,powered=false,waterlogged=false]"
      },
      {
        "char": "I",
        "block": "minecraft:stone_slab[type=top,waterlogged=false,weathering=false]"
      }
    ]
  },
  "slices": [
    [
      "                ",
      "                ",
      "                ",
      "                ",
      "                ",
      "g               ",
      "iaaagaaa        ",
      "bcaaddaaa       ",
      "ebcaecae        ",
      "eaebdeab        ",
      "eaaaddegb       ",
      "cceaaabad       ",
      "accaddeaa       ",
      "debbecaae       ",
      "eebecabaaa      ",
      "eadbddeac       "
    ],
    [
      "                ",
      "                ",
      "                ",
      "                ",
      "                ",
      "a               ",
      "       a        ",
      "abcebaiaa       ",
      "e  x            ",
      "a     f         ",
      "b      f        ",
      "   П            ",
      "   a ϔ f        ",
      "a  b   f        ",
      "cbebaaeaba      ",
      "c  b   f        "
    ],
    [
      "                ",
      "                ",
      "                ",
      "                ",
      "                ",
      "a               ",
      "       a        ",
      "dcdedbaia       ",
      "a  k   l        ",
      "e     fl        ",
      "c      fl       ",
      "       fl       ",
      "   Ӻ    l       ",
      "a      fl       ",
      "eedccedaai      ",
      "b      fl       "
    ],
    [
      "                ",
      "                ",
      "                ",
      "                ",
      "                ",
      "a               ",
      "       a        ",
      "bebaaeaaa       ",
      "b  k  ft        ",
      "b     ft        ",
      "d      ft       ",
      "        t       ",
      "       ft       ",
      "e      ft       ",
      "dbebdabgcg      ",
      "c      ft       "
    ],
    [
      "                ",
      "                ",
      "                ",
      "                ",
      "                ",
      "g               ",
      "       a        ",
      "ecddbbaag       ",
      "d     f         ",
      "d     f         ",
      "b      f        ",
      "I      f        ",
      "I      f        ",
      "e               ",
      "aebabebaea      ",
      "c               "
    ],
    [
      "                ",
      "                ",
      "                ",
      "                ",
      "                ",
      "a               ",
      "       a        ",
      "cdbaeaiaa       ",
      "a     ac        ",
      "e     ac        ",
      "a      gb       ",
      "c      ac       ",
      "d      id       ",
      "d      ae       ",
      "bbbaebaadg      ",
      "a      ad       "
    ]
  ]
}