{
  "xsize": 16,
  "zsize": 16,
  "palette": {
    "palette": [
      {
        "char": " ",
        "block": "minecraft:air"
      },
      {
        "char": "a",
        "block": "minecraft:cyan_terracotta"
      },
      {
        "char": "c",
        "block": "minecraft:deepslate[axis=y]"
      },
      {
        "char": "e",
        "block": "minecraft:basalt[axis=y]"
      },
      {
        "char": "b",
        "block": "minecraft:blackstone"
      },
      {
        "char": "d",
        "block": "minecraft:cobbled_deepslate"
      },
      {
        "char": "g",
        "block": "minecraft:gray_concrete"
      },
      {
        "char": "i",
        "block": "minecraft:light_gray_concrete"
      },
      {
        "char": "f",
        "block": "minecraft:glass"
      },
      {
        "char": "H",
        "block": "minecraft:quartz_stairs[facing=south,half=bottom,shape=straight,waterlogged=false]"
      },
      {
        "char": "ο",
        "block": "minecraft:air"
      },
      {
        "char": "ѧ",
        "block": "minecraft:air"
      },
      {
        "char": "l",
        "block": "minecraft:iron_trapdoor[facing=east,half=bottom,open=false,powered=false,waterlogged=false]"
      },
      {
        "char": "上",
        "block": "minecraft:air"
      },
      {
        "char": "u",
        "block": "minecraft:iron_trapdoor[facing=south,half=bottom,open=false,powered=false,waterlogged=false]"
      },
      {
        "char": "w",
        "block": "minecraft:iron_trapdoor[facing=south,half=top,open=false,powered=false,waterlogged=false]"
      },
      {
        "char": "j",
        "block": "minecraft:polished_andesite_slab[type=top,waterlogged=false]"
      }
    ]
  },
  "slices": [
    [
      "aceebccdabbbdcaa",
      "aacecadbccabaaaa",
      "aadebceedeaaebaa",
      "aaecbeagaabcag  ",
      "iaaaagecacaa    ",
      "ebdddbagia      ",
      "giagaa          ",
      "                ",
      " e       d    e ",
      "                ",
      "                ",
      "                ",
      "                ",
      "                ",
      "                ",
      "                "
    ],
    [
      "   dab bcb    f ",
      "    H   H   ffc ",
      " c        f    a",
      " d     fgf      ",
      "faffff  e       ",
      " c      a       ",
      " g              ",
      "                ",
      " c       e    e ",
      "                ",
      "                ",
      "                ",
      "                ",
      "                ",
      "                ",
      "                "
    ],
    [
      "    οѧ  οѧ    fl",
      "            ffb ",
      " d        ff上u a",
      " c    ffifuu    ",
      "faf ffuudu      ",
      "uauuuu  g       ",
      " a              ",
      "                ",
      " c       a    a ",
      "                ",
      "                ",
      "                ",
      "                ",
      "                ",
      "                ",
      "                "
    ],
    [
      "              fw",
      "            f a ",
      " c        f ww a",
      " d    ffg ww    ",
      "fafff wwcw      ",
      "wbwwww  a       ",
      " a              ",
      "                ",
      " d       a    c ",
      "                ",
      "                ",
      "                ",
      "                ",
      "                ",
      "                ",
      "                "
    ],
    [
      " j            f ",
      " j          f c ",
      " d        f    a",
      " d    ffgf      ",
      "faf f   c       ",
      " c      a       ",
      " g              ",
      "                ",
      " d       a    d ",
      "                ",
      "                ",
      "                ",
      "                ",
      "                ",
      "                ",
      "                "
    ],
    [
      " d            ge",
      " b          aaa ",
      " a        agae a",
      " d    gaaaad    ",
      "aaaagaebae      ",
      "deadbb  a       ",
      " g              ",
      "                ",
      " b       a    b ",
      "                ",
      "                ",
      "                ",
      "                ",
      "                ",
      "                ",
      "                "
    ]
  ]
}