{
  "xsize": 16,
  "zsize": 16,
  "palette": {
    "palette": [
      {
        "char": " ",
        "block": "minecraft:air"
      },
      {
        "char": "a",
        "block": "minecraft:cyan_terracotta"
      },
      {
        "char": "g",
        "block": "minecraft:gray_concrete"
      },
      {
        "char": "i",
        "block": "minecraft:light_gray_concrete"
      },
      {
        "char": "e",
        "block": "minecraft:basalt[axis=y]"
      },
      {
        "char": "c",
        "block": "minecraft:deepslate[axis=y]"
      },
      {
        "char": "d",
        "block": "minecraft:cobbled_deepslate"
      },
      {
        "char": "b",
        "block": "minecraft:blackstone"
      },
      {
        "char": "x",
        "block": "minecraft:cauldron"
      },
      {
        "char": "ϔ",
        "block": "minecraft:quartz_stairs[facing=east,half=bottom,shape=straight,waterlogged=false]"
      },
      {
        "char": "f",
        "block": "minecraft:glass"
      },
      {
        "char": "П",
        "block": "minecraft:barrel[facing=up,open=false]",
        "tag": {
          "z": -275,
          "x": -15,
          "ForgeData": {
            "LockFlag": "1b"
          },
          "id": "minecraft:barrel",
          "y": 2,
          "Items": []
        }
      },
      {
        "char": "k",
        "block": "minecraft:oak_leaves[distance=7,persistent=true,waterlogged=false]"
      },
      {
        "char": "l",
        "block": "minecraft:iron_trapdoor[facing=east,half=bottom,open=false,powered=false,waterlogged=false]"
      },
      {
        "char": "Ӻ",
        "block": "minecraft:air",
        "tag": {
          "z": -276,
          "x": -15,
          "id": "refurbished_furniture:computer",
          "y": 27,
          "NodePos": "-3848291827685L",
          "Connections": [
            "L"
          ]
        }
      },
      {
        "char": "t",
        "block": "minecraft:iron_trapdoor[facing=east,half=top,open=false,powered=false,waterlogged=false]"
      },
      {
        "char": "I",
        "block": "minecraft:stone_slab[type=top,waterlogged=false,weathering=false]"
      }
    ]
  },
  "slices": [
    [
      "                ",
      "                ",
      "                ",
      "                ",
      "                ",
      "a               ",
      "giaaagai        ",
      "eaecdaaaa       ",
      "aadbdcac        ",
      "acbdeaac        ",
      "abceacead       ",
      "accecdbac       ",
      "bcabeccid       ",
      "caecadbae       ",
      "adbaaacaaa      ",
      "cbbbaccab       "
    ],
    [
      "                ",
      "                ",
      "                ",
      "                ",
      "                ",
      "i               ",
      "       a        ",
      "dcbdbaaag       ",
      "c  x            ",
      "a               ",
      "d               ",
      "   d            ",
      "   d ϔ f        ",
      "e  c   f        ",
      "babeceeaci      ",
      "e  П   f        "
    ],
    [
      "                ",
      "                ",
      "                ",
      "                ",
      "                ",
      "a               ",
      "       a        ",
      "baecacgga       ",
      "b  k   l        ",
      "d     fl        ",
      "b       l       ",
      "       fl       ",
      "   Ӻ   fl       ",
      "c      fl       ",
      "cadbedaaaa      ",
      "a      fl       "
    ],
    [
      "                ",
      "                ",
      "                ",
      "                ",
      "                ",
      "g               ",
      "       a        ",
      "ebabcaaaa       ",
      "c  k  ft        ",
      "b     ft        ",
      "a      ft       ",
      "       ft       ",
      "       ft       ",
      "a      ft       ",
      "eeccedbgci      ",
      "e      ft       "
    ],
    [
      "                ",
      "                ",
      "                ",
      "                ",
      "                ",
      "a               ",
      "       a        ",
      "eaeeeeiaa       ",
      "c     f         ",
      "d               ",
      "b      f        ",
      "I      f        ",
      "I      f        ",
      "b      f        ",
      "eaadcdaaaa      ",
      "c      f        "
    ],
    [
      "                ",
      "                ",
      "                ",
      "                ",
      "                ",
      "g               ",
      "       a        ",
      "aeecdbaaa       ",
      "b     ab        ",
      "d     aa        ",
      "b      gd       ",
      "c      ac       ",
      "e      ad       ",
      "d      gd       ",
      "edccbdcaba      ",
      "a      ac       "
    ]
  ]
}