{
  "xsize": 16,
  "zsize": 16,
  "palette": {
    "palette": [
      {
        "char": " ",
        "block": "minecraft:air"
      },
      {
        "char": "c",
        "block": "minecraft:deepslate[axis=y]"
      },
      {
        "char": "d",
        "block": "minecraft:cobbled_deepslate"
      },
      {
        "char": "b",
        "block": "minecraft:blackstone"
      },
      {
        "char": "a",
        "block": "minecraft:cyan_terracotta"
      },
      {
        "char": "e",
        "block": "minecraft:basalt[axis=y]"
      },
      {
        "char": "i",
        "block": "minecraft:light_gray_concrete"
      },
      {
        "char": "g",
        "block": "minecraft:gray_concrete"
      },
      {
        "char": "ϔ",
        "block": "minecraft:quartz_stairs[facing=east,half=bottom,shape=straight,waterlogged=false]"
      },
      {
        "char": "f",
        "block": "minecraft:glass"
      },
      {
        "char": "x",
        "block": "minecraft:cauldron"
      },
      {
        "char": "H",
        "block": "minecraft:quartz_stairs[facing=south,half=bottom,shape=straight,waterlogged=false]"
      },
      {
        "char": "吗",
        "block": "minecraft:air"
      },
      {
        "char": "l",
        "block": "minecraft:iron_trapdoor[facing=east,half=bottom,open=false,powered=false,waterlogged=false]"
      },
      {
        "char": "k",
        "block": "minecraft:oak_leaves[distance=7,persistent=true,waterlogged=false]"
      },
      {
        "char": "ѷ",
        "block": "minecraft:air"
      },
      {
        "char": "Ҟ",
        "block": "minecraft:air"
      },
      {
        "char": "u",
        "block": "minecraft:iron_trapdoor[facing=south,half=bottom,open=false,powered=false,waterlogged=false]"
      },
      {
        "char": "t",
        "block": "minecraft:iron_trapdoor[facing=east,half=top,open=false,powered=false,waterlogged=false]"
      },
      {
        "char": "在",
        "block": "minecraft:air"
      },
      {
        "char": "w",
        "block": "minecraft:iron_trapdoor[facing=south,half=top,open=false,powered=false,waterlogged=false]"
      }
    ]
  },
  "slices": [
    [
      "cddbcacab       ",
      "eacbdccab       ",
      "dcbddbbac       ",
      "cacbabia        ",
      "acdcaead        ",
      "edabaaaea       ",
      "ebabeaaba       ",
      "dbeecgea        ",
      "baeeeaca        ",
      "ccadaba         ",
      "abecaca         ",
      "abeaag          ",
      "ecgbai          ",
      "baaba           ",
      "bgda            ",
      "ieg             "
    ],
    [
      "d ϔ    f        ",
      "a      f        ",
      "bad    f        ",
      "                ",
      "      f         ",
      "daeabbiaa       ",
      "  x   f         ",
      "     f          ",
      "     f          ",
      "    f           ",
      "dc              ",
      "H  fb           ",
      "  f  i          ",
      "  f             ",
      " f              ",
      "                "
    ],
    [
      "吗      fl       ",
      "       fl       ",
      "        l       ",
      "      fl        ",
      "      fl        ",
      "abceeaaea       ",
      "  k   fl        ",
      "     fl         ",
      "     fl         ",
      "    fl          ",
      "ѷҞ  fl          ",
      "   fb           ",
      "  fu a          ",
      "  fl            ",
      "  l             ",
      "fl              "
    ],
    [
      "       ft       ",
      "       ft       ",
      "       ft       ",
      "      ft        ",
      "       t        ",
      "ccbdbdaea       ",
      "  k   ft        ",
      "      t         ",
      "     ft         ",
      "    f在          ",
      "    ft          ",
      "   fd           ",
      "   w a          ",
      "  ft            ",
      " ft             ",
      "fw              "
    ],
    [
      "       f        ",
      "       f        ",
      "       f        ",
      "      f         ",
      "      f         ",
      "ceecadaea       ",
      "      f         ",
      "     f          ",
      "     f          ",
      "    f           ",
      "    f           ",
      "   fd           ",
      "  f  a          ",
      "  f             ",
      " f              ",
      "f               "
    ],
    [
      "       ad       ",
      "       ac       ",
      "       ac       ",
      "      ge        ",
      "      ie        ",
      "ddeaabaei       ",
      "      gb        ",
      "     ac         ",
      "     ae         ",
      "    ac          ",
      "    ac          ",
      "   ab           ",
      "  gb a          ",
      "  ad            ",
      " id             ",
      "ac              "
    ]
  ]
}