{
  "xsize": 16,
  "zsize": 16,
  "palette": {
    "palette": [
      {
        "char": " ",
        "block": "minecraft:air"
      },
      {
        "char": "c",
        "block": "minecraft:deepslate[axis=y]"
      },
      {
        "char": "e",
        "block": "minecraft:basalt[axis=y]"
      },
      {
        "char": "a",
        "block": "minecraft:cyan_terracotta"
      },
      {
        "char": "b",
        "block": "minecraft:blackstone"
      },
      {
        "char": "d",
        "block": "minecraft:cobbled_deepslate"
      },
      {
        "char": "i",
        "block": "minecraft:light_gray_concrete"
      },
      {
        "char": "g",
        "block": "minecraft:gray_concrete"
      },
      {
        "char": "H",
        "block": "minecraft:quartz_stairs[facing=south,half=bottom,shape=straight,waterlogged=false]"
      },
      {
        "char": "f",
        "block": "minecraft:glass"
      },
      {
        "char": "ѷ",
        "block": "minecraft:air"
      },
      {
        "char": "Ҟ",
        "block": "minecraft:air"
      },
      {
        "char": "l",
        "block": "minecraft:iron_trapdoor[facing=east,half=bottom,open=false,powered=false,waterlogged=false]"
      },
      {
        "char": "u",
        "block": "minecraft:iron_trapdoor[facing=south,half=bottom,open=false,powered=false,waterlogged=false]"
      },
      {
        "char": "w",
        "block": "minecraft:iron_trapdoor[facing=south,half=top,open=false,powered=false,waterlogged=false]"
      },
      {
        "char": "j",
        "block": "minecraft:polished_andesite_slab[type=top,waterlogged=false]"
      }
    ]
  },
  "slices": [
    [
      "cceeaecabedcbcid",
      "ceccbdcecabdgaaa",
      "cbddbdeaecaadcaa",
      "dcbeeeaaaadbga  ",
      "gaaaaaebbaai    ",
      "ceddbd  gg      ",
      " a              ",
      "                ",
      "                ",
      "                ",
      "                ",
      "                ",
      "                ",
      "                ",
      "                ",
      "                "
    ],
    [
      "   bda eba      ",
      "    H   H   ffb ",
      " e         f   a",
      " e    ffaf      ",
      "fiff f  e       ",
      " c      a       ",
      " a              ",
      "                ",
      "                ",
      "                ",
      "                ",
      "                ",
      "                ",
      "                ",
      "                ",
      "                "
    ],
    [
      "    ѷҞ  ѷҞ    fl",
      "            ffa ",
      " b        ffuu i",
      " d    ffafuu    ",
      " a f fuudu      ",
      "uauuuu  a       ",
      " i              ",
      "                ",
      "                ",
      "                ",
      "                ",
      "                ",
      "                ",
      "                ",
      "                ",
      "                "
    ],
    [
      "              fw",
      "            ffb ",
      " a        ffww i",
      " a    ffifww    ",
      "faffffwwdw      ",
      "wcwwww  a       ",
      " i              ",
      "                ",
      "                ",
      "                ",
      "                ",
      "                ",
      "                ",
      "                ",
      "                ",
      "                "
    ],
    [
      " j            f ",
      " j          ffd ",
      " e             a",
      " e    ffaf      ",
      "fgffff  a       ",
      " e      a       ",
      " g              ",
      "                ",
      "                ",
      "                ",
      "                ",
      "                ",
      "                ",
      "                ",
      "                ",
      "                "
    ],
    [
      " a            ic",
      " c          gae ",
      " a        igeb a",
      " e    aaagbe    ",
      "aaaiaadbda      ",
      "ddccdb  a       ",
      " a              ",
      "                ",
      "                ",
      "                ",
      "                ",
      "                ",
      "                ",
      "                ",
      "                ",
      "                "
    ]
  ]
}