{
  "xsize": 16,
  "zsize": 16,
  "palette": {
    "palette": [
      {
        "char": " ",
        "block": "minecraft:air"
      },
      {
        "char": "a",
        "block": "minecraft:cyan_terracotta"
      },
      {
        "char": "d",
        "block": "minecraft:cobbled_deepslate"
      },
      {
        "char": "e",
        "block": "minecraft:basalt[axis=y]"
      },
      {
        "char": "c",
        "block": "minecraft:deepslate[axis=y]"
      },
      {
        "char": "b",
        "block": "minecraft:blackstone"
      },
      {
        "char": "g",
        "block": "minecraft:gray_concrete"
      },
      {
        "char": "i",
        "block": "minecraft:light_gray_concrete"
      },
      {
        "char": "ϔ",
        "block": "minecraft:quartz_stairs[facing=east,half=bottom,shape=straight,waterlogged=false]"
      },
      {
        "char": "f",
        "block": "minecraft:glass"
      },
      {
        "char": "x",
        "block": "minecraft:cauldron"
      },
      {
        "char": "H",
        "block": "minecraft:quartz_stairs[facing=south,half=bottom,shape=straight,waterlogged=false]"
      },
      {
        "char": "Ӻ",
        "block": "minecraft:air",
        "tag": {
          "z": -276,
          "x": -15,
          "id": "refurbished_furniture:computer",
          "y": 27,
          "NodePos": "-3848291827685L",
          "Connections": [
            "L"
          ]
        }
      },
      {
        "char": "l",
        "block": "minecraft:iron_trapdoor[facing=east,half=bottom,open=false,powered=false,waterlogged=false]"
      },
      {
        "char": "k",
        "block": "minecraft:oak_leaves[distance=7,persistent=true,waterlogged=false]"
      },
      {
        "char": "ϐ",
        "block": "minecraft:air",
        "tag": {
          "z": -259,
          "x": -34,
          "id": "refurbished_furniture:computer",
          "y": -21,
          "NodePos": "-9070971985941L",
          "Connections": [
            "L"
          ]
        }
      },
      {
        "char": "u",
        "block": "minecraft:iron_trapdoor[facing=south,half=bottom,open=false,powered=false,waterlogged=false]"
      },
      {
        "char": "Ӟ",
        "block": "minecraft:air"
      },
      {
        "char": "t",
        "block": "minecraft:iron_trapdoor[facing=east,half=top,open=false,powered=false,waterlogged=false]"
      },
      {
        "char": "w",
        "block": "minecraft:iron_trapdoor[facing=south,half=top,open=false,powered=false,waterlogged=false]"
      },
      {
        "char": "在",
        "block": "minecraft:air"
      }
    ]
  },
  "slices": [
    [
      "addeecbgd       ",
      "ebacdbcge       ",
      "baacaeeia       ",
      "ccdbcbac        ",
      "deceedgb        ",
      "dcbadaaeg       ",
      "eebaaciaa       ",
      "dacbeabi        ",
      "cceedaei        ",
      "cdcbaag         ",
      "eacbaea         ",
      "cbeaea          ",
      "aciegg          ",
      "bagca           ",
      "eida            ",
      "adg             "
    ],
    [
      "b ϔ    f        ",
      "c      f        ",
      "aeb    f        ",
      "      f         ",
      "      f         ",
      "cdabdbaba       ",
      "  x   f         ",
      "     f          ",
      "     f          ",
      "    f           ",
      "cb  f           ",
      "H   e           ",
      "  f  g          ",
      "  f             ",
      " f              ",
      "f               "
    ],
    [
      "Ӻ      fl       ",
      "       fl       ",
      "       fl       ",
      "      fl        ",
      "      fl        ",
      "dacedeaaa       ",
      "  k   fl        ",
      "     fl         ",
      "     fl         ",
      "    fl          ",
      "ϐ   fl          ",
      "   fb           ",
      "  fu g          ",
      "  fl            ",
      "  l             ",
      "fӞ              "
    ],
    [
      "       ft       ",
      "       ft       ",
      "       ft       ",
      "       t        ",
      "      ft        ",
      "dddaebgba       ",
      "  k   ft        ",
      "      t         ",
      "     ft         ",
      "    ft          ",
      "     t          ",
      "   fa           ",
      "  fw i          ",
      "   t            ",
      " f在             ",
      "fw              "
    ],
    [
      "       f        ",
      "       f        ",
      "       f        ",
      "      f         ",
      "                ",
      "bbbdbcgai       ",
      "      f         ",
      "     f          ",
      "                ",
      "    f           ",
      "    f           ",
      "   fe           ",
      "  f  a          ",
      "                ",
      "                ",
      "f               "
    ],
    [
      "       ga       ",
      "       ab       ",
      "       ad       ",
      "      gb        ",
      "      aa        ",
      "dadeddaba       ",
      "      aa        ",
      "     ad         ",
      "     aa         ",
      "    gc          ",
      "    ac          ",
      "   gb           ",
      "  ab a          ",
      "  ad            ",
      " ae             ",
      "ae              "
    ]
  ]
}