{
  "xsize": 16,
  "zsize": 16,
  "palette": {
    "palette": [
      {
        "char": " ",
        "block": "minecraft:air"
      },
      {
        "char": "c",
        "block": "minecraft:deepslate[axis=y]"
      },
      {
        "char": "资",
        "block": "minecraft:dirt"
      },
      {
        "char": "b",
        "block": "minecraft:blackstone"
      },
      {
        "char": "d",
        "block": "minecraft:cobbled_deepslate"
      },
      {
        "char": "y",
        "block": "minecraft:basalt[axis=x]"
      },
      {
        "char": "K",
        "block": "minecraft:quartz_block"
      },
      {
        "char": "J",
        "block": "minecraft:diorite"
      },
      {
        "char": "o",
        "block": "minecraft:chiseled_quartz_block"
      },
      {
        "char": "r",
        "block": "minecraft:polished_diorite"
      },
      {
        "char": "C",
        "block": "minecraft:quartz_pillar[axis=y]"
      },
      {
        "char": "n",
        "block": "minecraft:smooth_quartz"
      },
      {
        "char": "B",
        "block": "minecraft:birch_planks"
      },
      {
        "char": "e",
        "block": "minecraft:basalt[axis=y]"
      },
      {
        "char": "a",
        "block": "minecraft:cyan_terracotta"
      },
      {
        "char": "ӝ",
        "block": "minecraft:air"
      },
      {
        "char": "x",
        "block": "minecraft:cauldron"
      },
      {
        "char": "Ӣ",
        "block": "minecraft:air"
      },
      {
        "char": "ϓ",
        "block": "minecraft:air"
      },
      {
        "char": "ӛ",
        "block": "minecraft:air"
      },
      {
        "char": "Ѻ",
        "block": "minecraft:air"
      },
      {
        "char": "所",
        "block": "minecraft:quartz_stairs[facing=south,half=top,shape=straight,waterlogged=false]"
      },
      {
        "char": "W",
        "block": "minecraft:polished_andesite_stairs[facing=south,half=top,shape=straight,waterlogged=false]"
      },
      {
        "char": "为",
        "block": "minecraft:polished_andesite_stairs[facing=north,half=bottom,shape=straight,waterlogged=false]"
      },
      {
        "char": "ϕ",
        "block": "minecraft:quartz_stairs[facing=north,half=bottom,shape=straight,waterlogged=false]"
      },
      {
        "char": "Ѷ",
        "block": "minecraft:spruce_planks"
      },
      {
        "char": "k",
        "block": "minecraft:oak_leaves[distance=7,persistent=true,waterlogged=false]"
      },
      {
        "char": "g",
        "block": "minecraft:gray_concrete"
      },
      {
        "char": "i",
        "block": "minecraft:light_gray_concrete"
      },
      {
        "char": "Ѧ",
        "block": "minecraft:quartz_bricks"
      },
      {
        "char": "Ѩ",
        "block": "minecraft:white_stained_glass_pane[east=false,north=true,south=true,waterlogged=false,west=false]"
      },
      {
        "char": "N",
        "block": "minecraft:white_stained_glass_pane[east=true,north=false,south=false,waterlogged=false,west=true]"
      },
      {
        "char": "Ѳ",
        "block": "minecraft:white_stained_glass_pane[east=true,north=false,south=false,waterlogged=false,west=false]"
      },
      {
        "char": "那",
        "block": "minecraft:white_terracotta"
      },
      {
        "char": "M",
        "block": "minecraft:smooth_quartz_slab[type=top,waterlogged=false]"
      },
      {
        "char": "ѩ",
        "block": "minecraft:diorite_slab[type=top,waterlogged=false]"
      }
    ]
  },
  "slices": [
    [
      "c资bdycddKJoJrJCC",
      "nCnJrnrnnoKonnro",
      "onorrJrrrCoJnnKo",
      "CnCnnrrJrJorJooo",
      "oroJoonCKCCnoCnC",
      "roJrnoCJrooKnJKJ",
      "ronKrJJnKoooJorr",
      "ConnJrrJnJorrKJn",
      "CCoCoorCrrnCooKo",
      "nKooonJrJJnJBBBB",
      "onrorJrnoorrBBBB",
      "KoooJnJnornnBBBB",
      "nJKnCJrrrKnrBBBB",
      "JronoCCorCnrBBBB",
      "nooKnJnrKrrnBBBB",
      "ConKnornJoJoBBBB"
    ],
    [
      "cbedbbea      ӝ ",
      " x   x       Ӣϓӛ",
      "              Ѻ ",
      "                ",
      "              ӝ ",
      "             Ӣϓӛ",
      "         aa   Ѻ ",
      "         aa     ",
      "           bdcaa",
      "   所       a    ",
      "WWWJ    ӝ  d    ",
      "为为为Kx  Ӣϓӛ d    ",
      "   ϕ    Ѻ  e    ",
      "           c    ",
      "         aac    ",
      "         aaaѶ ѶѶ"
    ],
    [
      "aadddeaa        ",
      " k   k          ",
      "                ",
      "                ",
      "                ",
      "                ",
      "         gi     ",
      "         ga     ",
      "   所       bd  e",
      "WWWѦ       b    ",
      "为为为Ѧ       Ѩ    ",
      "   ϕk      Ѩ    ",
      "           c    ",
      "           d    ",
      "         aab    ",
      "         agb    "
    ],
    [
      "cacdbdac        ",
      " k   k          ",
      "                ",
      "                ",
      "                ",
      "                ",
      "         ii     ",
      "   所     ga     ",
      "WWWѦ       aeNNe",
      "为为为n       e    ",
      "   ϕ       Ѩ    ",
      "    k      Ѩ    ",
      "           b    ",
      "           b    ",
      "         aad    ",
      "         iab    "
    ],
    [
      "cdebeeac        ",
      "                ",
      "                ",
      "                ",
      "                ",
      "                ",
      "   所     ig     ",
      "WWWK     ai     ",
      "为为为Ѧ       cb Ѳe",
      "   ϕ       b    ",
      "           Ѩ    ",
      "           Ѩ    ",
      "           a    ",
      "           a    ",
      "         aac    ",
      "         agc    "
    ],
    [
      "acddccca        ",
      "                ",
      "                ",
      "                ",
      "                ",
      "   所            ",
      "WWW那MMMMMaa     ",
      "为为为Ѧ     aa     ",
      "   ϕ      ѩaeacb",
      "          ѩe    ",
      "          ѩa    ",
      "          ѩb    ",
      "          Md    ",
      "          Mb    ",
      "         iab    ",
      "         gab    "
    ]
  ]
}