{
  "xsize": 16,
  "zsize": 16,
  "palette": {
    "palette": [
      {
        "char": " ",
        "block": "minecraft:air"
      },
      {
        "char": "a",
        "block": "minecraft:cyan_terracotta"
      },
      {
        "char": "e",
        "block": "minecraft:basalt[axis=y]"
      },
      {
        "char": "c",
        "block": "minecraft:deepslate[axis=y]"
      },
      {
        "char": "d",
        "block": "minecraft:cobbled_deepslate"
      },
      {
        "char": "b",
        "block": "minecraft:blackstone"
      },
      {
        "char": "g",
        "block": "minecraft:gray_concrete"
      },
      {
        "char": "i",
        "block": "minecraft:light_gray_concrete"
      },
      {
        "char": "f",
        "block": "minecraft:glass"
      },
      {
        "char": "m",
        "block": "minecraft:iron_trapdoor[facing=west,half=bottom,open=false,powered=false,waterlogged=false]"
      },
      {
        "char": "u",
        "block": "minecraft:iron_trapdoor[facing=south,half=bottom,open=false,powered=false,waterlogged=false]"
      },
      {
        "char": "q",
        "block": "minecraft:iron_trapdoor[facing=west,half=top,open=false,powered=false,waterlogged=false]"
      },
      {
        "char": "学",
        "block": "minecraft:air"
      },
      {
        "char": "w",
        "block": "minecraft:iron_trapdoor[facing=south,half=top,open=false,powered=false,waterlogged=false]"
      }
    ]
  },
  "slices": [
    [
      "          aaecda",
      "          aadbbb",
      "          aacaad",
      "           cgabb",
      "           egeda",
      "          acaebe",
      "          gcgecc",
      "           geacc",
      "           icaac",
      "            adia",
      "            gdaa",
      "             adg",
      "             gac",
      "              ib",
      "               a",
      "                "
    ],
    [
      "           f    ",
      "           f    ",
      "           f    ",
      "            f   ",
      "            f   ",
      "          aeaecc",
      "            f   ",
      "             f  ",
      "                ",
      "                ",
      "                ",
      "              ef",
      "             a  ",
      "                ",
      "                ",
      "                "
    ],
    [
      "          mf    ",
      "          m     ",
      "          mf    ",
      "           mf   ",
      "           mf   ",
      "          adaece",
      "           m    ",
      "            mf  ",
      "            mf  ",
      "             m  ",
      "             u  ",
      "              b ",
      "             a u",
      "               m",
      "                ",
      "                "
    ],
    [
      "          q     ",
      "          q     ",
      "          qf    ",
      "           qf   ",
      "           qf   ",
      "          abacae",
      "           学f   ",
      "            q   ",
      "            qf  ",
      "             q  ",
      "             q  ",
      "              bf",
      "             g w",
      "               q",
      "                ",
      "                "
    ],
    [
      "           f    ",
      "           f    ",
      "           f    ",
      "            f   ",
      "            f   ",
      "          gdgdab",
      "            f   ",
      "             f  ",
      "             f  ",
      "              f ",
      "              f ",
      "              df",
      "             a  ",
      "                ",
      "                ",
      "                "
    ],
    [
      "          ba    ",
      "          bg    ",
      "          ag    ",
      "           da   ",
      "           da   ",
      "          aagadb",
      "           ca   ",
      "            da  ",
      "            ca  ",
      "             da ",
      "             eg ",
      "              ea",
      "             g b",
      "               d",
      "                ",
      "                "
    ]
  ]
}