{
  "xsize": 16,
  "zsize": 16,
  "palette": {
    "palette": [
      {
        "char": " ",
        "block": "minecraft:air"
      },
      {
        "char": "d",
        "block": "minecraft:cobbled_deepslate"
      },
      {
        "char": "a",
        "block": "minecraft:cyan_terracotta"
      },
      {
        "char": "i",
        "block": "minecraft:light_gray_concrete"
      },
      {
        "char": "b",
        "block": "minecraft:blackstone"
      },
      {
        "char": "g",
        "block": "minecraft:gray_concrete"
      },
      {
        "char": "e",
        "block": "minecraft:basalt[axis=y]"
      },
      {
        "char": "c",
        "block": "minecraft:deepslate[axis=y]"
      },
      {
        "char": "f",
        "block": "minecraft:glass"
      },
      {
        "char": "ϔ",
        "block": "minecraft:quartz_stairs[facing=east,half=bottom,shape=straight,waterlogged=false]"
      },
      {
        "char": "s",
        "block": "minecraft:iron_trapdoor[facing=north,half=bottom,open=false,powered=false,waterlogged=false]"
      },
      {
        "char": "l",
        "block": "minecraft:iron_trapdoor[facing=east,half=bottom,open=false,powered=false,waterlogged=false]"
      },
      {
        "char": "Ӟ",
        "block": "minecraft:air"
      },
      {
        "char": "信",
        "block": "minecraft:air"
      },
      {
        "char": "下",
        "block": "minecraft:air"
      },
      {
        "char": "因",
        "block": "minecraft:air"
      },
      {
        "char": "p",
        "block": "minecraft:iron_trapdoor[facing=north,half=top,open=false,powered=false,waterlogged=false]"
      },
      {
        "char": "t",
        "block": "minecraft:iron_trapdoor[facing=east,half=top,open=false,powered=false,waterlogged=false]"
      },
      {
        "char": "在",
        "block": "minecraft:air"
      }
    ]
  },
  "slices": [
    [
      "ddaaaa          ",
      "dddibg          ",
      "badeica         ",
      "cbccgba         ",
      "bdaecida        ",
      "bceaegaa        ",
      "bddedcaba       ",
      "ebebcaaba       ",
      "dddeabia        ",
      "bddcbbaa        ",
      "baccaeeac       ",
      "dbcbdbeaa       ",
      "bcccddbga       ",
      "aeeeebbia       ",
      "bebabbdiag      ",
      "bdbaddcac       "
    ],
    [
      "  f  a          ",
      "   fb           ",
      "ϔ               ",
      "                ",
      "     f          ",
      "     f          ",
      "      f         ",
      "cbbddcaci       ",
      "      f         ",
      "      f         ",
      " cbd            ",
      " d              ",
      " b ϔ   f        ",
      " b     f        ",
      "dadbcaaaea      ",
      "e      f        "
    ],
    [
      "  fs a          ",
      "   fa           ",
      "     l          ",
      "     Ӟ          ",
      "     fl         ",
      "     fl         ",
      "      fl        ",
      "bdbaddaba       ",
      "      fl        ",
      "      fl        ",
      "       fl       ",
      " 信     fl       ",
      " 下     fl       ",
      "       fl       ",
      "baecbbdgea      ",
      "因      fl       "
    ],
    [
      "  fp i          ",
      "   fd           ",
      "    ft          ",
      "    ft          ",
      "      在         ",
      "     ft         ",
      "      ft        ",
      "daceccaeg       ",
      "      ft        ",
      "       t        ",
      "        t       ",
      "       ft       ",
      "       ft       ",
      "       ft       ",
      "eccdeabada      ",
      "       ft       "
    ],
    [
      "  f  a          ",
      "    d           ",
      "    f           ",
      "    f           ",
      "                ",
      "     f          ",
      "                ",
      "cbaabdaca       ",
      "                ",
      "      f         ",
      "       f        ",
      "       f        ",
      "       f        ",
      "                ",
      "eedcbcdabg      ",
      "       f        "
    ],
    [
      "  gd a          ",
      "   ie           ",
      "    aa          ",
      "    aa          ",
      "     ab         ",
      "     id         ",
      "      aa        ",
      "acebbeaaa       ",
      "      ab        ",
      "      gb        ",
      "       ad       ",
      "       ge       ",
      "       ib       ",
      "       aa       ",
      "abccecdaaa      ",
      "       aa       "
    ]
  ]
}