{
  "xsize": 16,
  "zsize": 16,
  "palette": {
    "palette": [
      {
        "char": " ",
        "block": "minecraft:air"
      },
      {
        "char": "e",
        "block": "minecraft:basalt[axis=y]"
      },
      {
        "char": "a",
        "block": "minecraft:cyan_terracotta"
      },
      {
        "char": "d",
        "block": "minecraft:cobbled_deepslate"
      },
      {
        "char": "b",
        "block": "minecraft:blackstone"
      },
      {
        "char": "g",
        "block": "minecraft:gray_concrete"
      },
      {
        "char": "c",
        "block": "minecraft:deepslate[axis=y]"
      },
      {
        "char": "i",
        "block": "minecraft:light_gray_concrete"
      },
      {
        "char": "f",
        "block": "minecraft:glass"
      },
      {
        "char": "m",
        "block": "minecraft:iron_trapdoor[facing=west,half=bottom,open=false,powered=false,waterlogged=false]"
      },
      {
        "char": "了",
        "block": "minecraft:air"
      },
      {
        "char": "u",
        "block": "minecraft:iron_trapdoor[facing=south,half=bottom,open=false,powered=false,waterlogged=false]"
      },
      {
        "char": "q",
        "block": "minecraft:iron_trapdoor[facing=west,half=top,open=false,powered=false,waterlogged=false]"
      },
      {
        "char": "w",
        "block": "minecraft:iron_trapdoor[facing=south,half=top,open=false,powered=false,waterlogged=false]"
      }
    ]
  },
  "slices": [
    [
      "          eadbab",
      "          aaaeae",
      "          bgadda",
      "           eabad",
      "           dgbed",
      "          gcgabd",
      "          gaacbc",
      "           adgce",
      "           aeacc",
      "            adic",
      "            gcab",
      "             ada",
      "             aaa",
      "              ae",
      "               a",
      "                "
    ],
    [
      "           f    ",
      "           f    ",
      "           f    ",
      "            f   ",
      "                ",
      "          gaacce",
      "                ",
      "             f  ",
      "                ",
      "              f ",
      "              f ",
      "              cf",
      "             a  ",
      "                ",
      "                ",
      "                "
    ],
    [
      "          mf    ",
      "          mf    ",
      "          mf    ",
      "           mf   ",
      "           mf   ",
      "          gcaaae",
      "           了f   ",
      "            mf  ",
      "            m   ",
      "             mf ",
      "             uf ",
      "              cf",
      "             a u",
      "               m",
      "                ",
      "                "
    ],
    [
      "          qf    ",
      "          qf    ",
      "          q     ",
      "           qf   ",
      "           q    ",
      "          aagcad",
      "           qf   ",
      "            q   ",
      "            qf  ",
      "             qf ",
      "             q  ",
      "              b ",
      "             i w",
      "               q",
      "                ",
      "                "
    ],
    [
      "           f    ",
      "                ",
      "           f    ",
      "                ",
      "            f   ",
      "          ibaadb",
      "            f   ",
      "             f  ",
      "             f  ",
      "              f ",
      "              f ",
      "              af",
      "             a  ",
      "                ",
      "                ",
      "                "
    ],
    [
      "          ca    ",
      "          da    ",
      "          da    ",
      "           ea   ",
      "           dg   ",
      "          adgade",
      "           ba   ",
      "            ca  ",
      "            ca  ",
      "             ca ",
      "             dg ",
      "              cg",
      "             g c",
      "               b",
      "                ",
      "                "
    ]
  ]
}