{
  "xsize": 16,
  "zsize": 16,
  "palette": {
    "palette": [
      {
        "char": " ",
        "block": "minecraft:air"
      },
      {
        "char": "d",
        "block": "minecraft:air"
      },
      {
        "char": "y",
        "block": "minecraft:air"
      },
      {
        "char": "b",
        "block": "minecraft:air"
      },
      {
        "char": "c",
        "block": "minecraft:air"
      },
      {
        "char": "Q",
        "block": "minecraft:air"
      },
      {
        "char": "a",
        "block": "minecraft:air"
      },
      {
        "char": "r",
        "block": "minecraft:air"
      },
      {
        "char": "o",
        "block": "minecraft:air"
      },
      {
        "char": "n",
        "block": "minecraft:air"
      },
      {
        "char": "J",
        "block": "minecraft:air"
      },
      {
        "char": "C",
        "block": "minecraft:air"
      },
      {
        "char": "K",
        "block": "minecraft:air"
      },
      {
        "char": "资",
        "block": "minecraft:air"
      },
      {
        "char": "B",
        "block": "minecraft:air"
      },
      {
        "char": "U",
        "block": "minecraft:tall_grass[half=lower]"
      },
      {
        "char": "时",
        "block": "minecraft:grass"
      },
      {
        "char": "g",
        "block": "minecraft:air"
      },
      {
        "char": "ϕ",
        "block": "minecraft:air"
      },
      {
        "char": "O",
        "block": "minecraft:air"
      },
      {
        "char": "ϓ",
        "block": "minecraft:air"
      },
      {
        "char": "ϔ",
        "block": "minecraft:air"
      },
      {
        "char": "H",
        "block": "minecraft:air"
      },
      {
        "char": "F",
        "block": "minecraft:air"
      },
      {
        "char": "V",
        "block": "minecraft:tall_grass[half=upper]"
      },
      {
        "char": "i",
        "block": "minecraft:air"
      },
      {
        "char": "实",
        "block": "minecraft:air"
      },
      {
        "char": "e",
        "block": "minecraft:air"
      },
      {
        "char": "N",
        "block": "minecraft:air"
      },
      {
        "char": "ҽ",
        "block": "minecraft:air"
      }
    ]
  },
  "slices": [
    [
      "dybdcccQcyaycQcb",
      "dacayybyyycddQbc",
      "byddbccaQbacyada",
      "QycyQbccrocronJr",
      "cQcbaddyyoooCodr",
      "dccacyaaKrabaorn",
      "acQaacbyaybycd资y",
      "abyccQacbyBBBBBB",
      "yydQbayacdBBBBBB",
      "QycydbayccBBBBBB",
      "ydybQQQabdBBBBBB",
      "dbdabaabQaBBBBBB",
      "cybcbQaaQcBBBBBB",
      "bdQbQbdcabBBBBBB",
      "cQcQbybcbaBBBBBB",
      "QaydbcbbbdcQbbcc"
    ],
    [
      "       U     U  ",
      "             U  ",
      "        U       ",
      "时   U           ",
      " U              ",
      "           aa   ",
      "  U     bacgga  ",
      "     U   a      ",
      "   U    ag      ",
      "时       aa  ϕ   ",
      "    UUU  d Oϓϔ O",
      "        Uc  H   ",
      "     U  Ua      ",
      "  U U    a      ",
      " U U     cFFFFFF",
      "时        b      "
    ],
    [
      "       V     V  ",
      "             V  ",
      "        V       ",
      "    V           ",
      " V              ",
      "           ag   ",
      "  V     cabgib  ",
      "     V   d      ",
      "   V    aa      ",
      "        ga      ",
      "    VVV  b  实   ",
      "        Vb      ",
      "     V  Vd      ",
      "  V V    e      ",
      " V V     e      ",
      "         b      "
    ],
    [
      "                ",
      "                ",
      "                ",
      "                ",
      "                ",
      "           aa   ",
      "        aaeaad  ",
      "         a      ",
      "        ig      ",
      "        aa      ",
      "         d      ",
      "         d      ",
      "         e      ",
      "         d      ",
      "         b      ",
      "         d      "
    ],
    [
      "                ",
      "                ",
      "                ",
      "                ",
      "                ",
      "           ag   ",
      "        cbbiaa  ",
      "         a      ",
      "        ga      ",
      "        ga      ",
      "         d      ",
      "         e      ",
      "         e      ",
      "         e      ",
      "         eFFFFFF",
      "         a      "
    ],
    [
      "                ",
      "                ",
      "                ",
      "                ",
      "                ",
      "           ag   ",
      "        dccigcNN",
      "         a      ",
      "        aa      ",
      "        aa      ",
      "         c      ",
      "         d      ",
      "         b      ",
      "         aҽҽҽҽҽҽ",
      "         bFFFFFF",
      "         e      "
    ]
  ]
}