{
  "xsize": 16,
  "zsize": 16,
  "palette": {
    "palette": [
      {
        "char": " ",
        "block": "minecraft:air"
      },
      {
        "char": "a",
        "block": "minecraft:cyan_terracotta"
      },
      {
        "char": "b",
        "block": "minecraft:blackstone"
      },
      {
        "char": "d",
        "block": "minecraft:cobbled_deepslate"
      },
      {
        "char": "i",
        "block": "minecraft:light_gray_concrete"
      },
      {
        "char": "c",
        "block": "minecraft:deepslate[axis=y]"
      },
      {
        "char": "e",
        "block": "minecraft:basalt[axis=y]"
      },
      {
        "char": "g",
        "block": "minecraft:gray_concrete"
      },
      {
        "char": "f",
        "block": "minecraft:glass"
      },
      {
        "char": "ϕ",
        "block": "minecraft:quartz_stairs[facing=north,half=bottom,shape=straight,waterlogged=false]"
      },
      {
        "char": "s",
        "block": "minecraft:iron_trapdoor[facing=north,half=bottom,open=false,powered=false,waterlogged=false]"
      },
      {
        "char": "m",
        "block": "minecraft:iron_trapdoor[facing=west,half=bottom,open=false,powered=false,waterlogged=false]"
      },
      {
        "char": "成",
        "block": "minecraft:air"
      },
      {
        "char": "多",
        "block": "minecraft:air"
      },
      {
        "char": "p",
        "block": "minecraft:iron_trapdoor[facing=north,half=top,open=false,powered=false,waterlogged=false]"
      },
      {
        "char": "q",
        "block": "minecraft:iron_trapdoor[facing=west,half=top,open=false,powered=false,waterlogged=false]"
      }
    ]
  },
  "slices": [
    [
      "                ",
      "                ",
      "                ",
      "                ",
      "                ",
      "                ",
      "                ",
      "         aa  bdd",
      "       aiceccgaa",
      "     aabbagaaaee",
      "   gaceaaacceaab",
      "  agagabccacbcbd",
      " geaaedcdaaebdce",
      "adagcacecabecebc",
      "eadeddaebddbeada",
      "ibbcdccdaacbadce"
    ],
    [
      "                ",
      "                ",
      "                ",
      "                ",
      "                ",
      "                ",
      "                ",
      "          g     ",
      "          e  ff ",
      "         fg     ",
      "   g   ff b     ",
      "    aff   c     ",
      "    f     d ϕ   ",
      "  ff      c   e ",
      " f        dcbda ",
      "f    a    d     "
    ],
    [
      "                ",
      "                ",
      "                ",
      "                ",
      "                ",
      "                ",
      "                ",
      "          a  sss",
      "         sbss ff",
      "       ssfgff   ",
      "   a ss   b     ",
      "    cff   d     ",
      "  ssf     c     ",
      " sf       a     ",
      "m         c成多   ",
      "          e     "
    ],
    [
      "                ",
      "                ",
      "                ",
      "                ",
      "                ",
      "                ",
      "                ",
      "          i  ppp",
      "         pbppf f",
      "       ppfa     ",
      "   a ppf  a     ",
      "    bff   b     ",
      "  pqf     a     ",
      " p f      e     ",
      "pf        e     ",
      "f         a     "
    ],
    [
      "                ",
      "                ",
      "                ",
      "                ",
      "                ",
      "                ",
      "                ",
      "          a     ",
      "          a  fff",
      "         fgff   ",
      "   a   f  d     ",
      "    cff   d     ",
      "    f     a     ",
      "  ff      c     ",
      "          c     ",
      "          d     "
    ],
    [
      "                ",
      "                ",
      "                ",
      "                ",
      "                ",
      "                ",
      "                ",
      "          a  caa",
      "         bdbbaai",
      "       adaaga   ",
      "   a bcig d     ",
      "    eia   a     ",
      "  dbg     d     ",
      " aag      e     ",
      "ea        c     ",
      "a         d     "
    ]
  ]
}