{
  "xsize": 16,
  "zsize": 16,
  "palette": {
    "palette": [
      {
        "char": " ",
        "block": "minecraft:air"
      },
      {
        "char": "d",
        "block": "minecraft:cobbled_deepslate"
      },
      {
        "char": "b",
        "block": "minecraft:blackstone"
      },
      {
        "char": "a",
        "block": "minecraft:cyan_terracotta"
      },
      {
        "char": "e",
        "block": "minecraft:basalt[axis=y]"
      },
      {
        "char": "c",
        "block": "minecraft:deepslate[axis=y]"
      },
      {
        "char": "你",
        "block": "minecraft:spawner",
        "tag": {
          "SpawnData": {
            "entity": {}
          },
          "MaxNearbyEntities": "6s",
          "MinSpawnDelay": "200s",
          "z": -274,
          "x": -42,
          "MaxSpawnDelay": "800s",
          "RequiredPlayerRange": "16s",
          "SpawnCount": "4s",
          "id": "minecraft:mob_spawner",
          "SpawnPotentials": [],
          "y": 1,
          "SpawnRange": "4s",
          "Delay": "731s"
        }
      },
      {
        "char": "Z",
        "block": "minecraft:stone_brick_wall[east=tall,north=tall,south=none,up=true,waterlogged=false,weathering=false,west=tall]"
      },
      {
        "char": "G",
        "block": "minecraft:iron_bars[east=false,north=false,south=true,waterlogged=false,west=false]"
      },
      {
        "char": "H",
        "block": "minecraft:quartz_stairs[facing=south,half=bottom,shape=straight,waterlogged=false]"
      },
      {
        "char": "ϕ",
        "block": "minecraft:quartz_stairs[facing=north,half=bottom,shape=straight,waterlogged=false]"
      },
      {
        "char": "O",
        "block": "minecraft:quartz_stairs[facing=west,half=bottom,shape=straight,waterlogged=false]"
      },
      {
        "char": "ϓ",
        "block": "minecraft:air"
      },
      {
        "char": "x",
        "block": "minecraft:cauldron"
      },
      {
        "char": "v",
        "block": "minecraft:quartz_pillar[axis=x]"
      },
      {
        "char": "生",
        "block": "minecraft:white_stained_glass_pane[east=false,north=false,south=false,waterlogged=false,west=false]"
      },
      {
        "char": "k",
        "block": "minecraft:oak_leaves[distance=7,persistent=true,waterlogged=false]"
      },
      {
        "char": "n",
        "block": "minecraft:smooth_quartz"
      },
      {
        "char": "o",
        "block": "minecraft:chiseled_quartz_block"
      },
      {
        "char": "Ѵ",
        "block": "minecraft:white_stained_glass_pane[east=false,north=false,south=false,waterlogged=false,west=true]"
      },
      {
        "char": "Ѳ",
        "block": "minecraft:white_stained_glass_pane[east=true,north=false,south=false,waterlogged=false,west=false]"
      },
      {
        "char": "J",
        "block": "minecraft:diorite"
      },
      {
        "char": "r",
        "block": "minecraft:polished_diorite"
      },
      {
        "char": "j",
        "block": "minecraft:polished_andesite_slab[type=top,waterlogged=false]"
      }
    ]
  },
  "slices": [
    [
      "dbdadeddaabbabcc",
      "eebeaeecaecaaeea",
      "eaabededcdaeeecd",
      "eeaacaacaddceccb",
      "badecdabadeddbad",
      "dabebbdcdedeeede",
      "eadccdbbecaeaeed",
      "abdddbecbbdbc你bd",
      "cdbacebcecdebddc",
      "cdccababecbeebad",
      "cbcddbacdaaaedae",
      "deaceebdedeadece",
      "ZZZbZZZeadbeceaa",
      "   d   beddeabae",
      "   b   edeabeaad",
      " G b G ecdeeecbd"
    ],
    [
      " e      b  H    ",
      " b             ϕ",
      " c            Oϓ",
      " a      c      H",
      "ccbaddaed       ",
      " c  x  c        ",
      "       a        ",
      "             aed",
      "             c  ",
      "             a  ",
      "       c     b  ",
      "   d   d        ",
      "vvvevvvb        ",
      "   c   c     d  ",
      "   d   bb   eded",
      " G a G b     c  "
    ],
    [
      " d      b       ",
      " c              ",
      " c              ",
      " a      b       ",
      "bbd 生 ddb       ",
      " c  k  e        ",
      "       c        ",
      "             daa",
      "             d  ",
      "             b  ",
      "       e     a  ",
      "   d   e        ",
      "nvvavnoe        ",
      "   b   c     e  ",
      "   d   aa   aabe",
      " G c G d     c  "
    ],
    [
      " a      e       ",
      " d              ",
      " d              ",
      " a      b       ",
      "babѴ Ѳbee       ",
      " c  k  c        ",
      "       a        ",
      "             eed",
      "             d  ",
      "             a  ",
      "       a     d  ",
      "   c   b        ",
      "vJrcvvvb        ",
      "   d   e     a  ",
      "   e   da   ecbe",
      " G a G d     a  "
    ],
    [
      " a      e       ",
      " a      j       ",
      " a      j       ",
      " d      d       ",
      "babbabeed       ",
      " d     e        ",
      "       a        ",
      "       j     ddb",
      "       j     e  ",
      "       j     d  ",
      "       e     c  ",
      "jjjdjjjc     j  ",
      "vvvdovna     j  ",
      "   c   a     c  ",
      "   a   dajjjdcdd",
      " G a G e     e  "
    ],
    [
      " d      e       ",
      " d      c       ",
      " c      d       ",
      " b      d       ",
      "bebeddaca       ",
      " c     d        ",
      "       e        ",
      "       d     bca",
      "       c     a  ",
      "       d     a  ",
      "       c     c  ",
      "bbdbcecd     b  ",
      "   d   d     e  ",
      "   a   b     e  ",
      "   b   baabcebed",
      " G c G d     b  "
    ]
  ]
}