{
  "xsize": 16,
  "zsize": 16,
  "palette": {
    "palette": [
      {
        "char": " ",
        "block": "minecraft:air"
      },
      {
        "char": "d",
        "block": "minecraft:cobbled_deepslate"
      },
      {
        "char": "b",
        "block": "minecraft:blackstone"
      },
      {
        "char": "a",
        "block": "minecraft:cyan_terracotta"
      },
      {
        "char": "c",
        "block": "minecraft:deepslate[axis=y]"
      },
      {
        "char": "g",
        "block": "minecraft:gray_concrete"
      },
      {
        "char": "e",
        "block": "minecraft:basalt[axis=y]"
      },
      {
        "char": "i",
        "block": "minecraft:light_gray_concrete"
      },
      {
        "char": "f",
        "block": "minecraft:glass"
      },
      {
        "char": "ϔ",
        "block": "minecraft:quartz_stairs[facing=east,half=bottom,shape=straight,waterlogged=false]"
      },
      {
        "char": "s",
        "block": "minecraft:iron_trapdoor[facing=north,half=bottom,open=false,powered=false,waterlogged=false]"
      },
      {
        "char": "l",
        "block": "minecraft:iron_trapdoor[facing=east,half=bottom,open=false,powered=false,waterlogged=false]"
      },
      {
        "char": "下",
        "block": "minecraft:air"
      },
      {
        "char": "p",
        "block": "minecraft:iron_trapdoor[facing=north,half=top,open=false,powered=false,waterlogged=false]"
      },
      {
        "char": "t",
        "block": "minecraft:iron_trapdoor[facing=east,half=top,open=false,powered=false,waterlogged=false]"
      }
    ]
  },
  "slices": [
    [
      "dbadaa          ",
      "acbgda          ",
      "daceaeg         ",
      "dcbcada         ",
      "dddbdada        ",
      "dceadgea        ",
      "cceeceida       ",
      "ddcecdadg       ",
      "aedcebgc        ",
      "cdacadae        ",
      "aeaccbbia       ",
      "daccceaad       ",
      "decabcbaa       ",
      "cccbcabae       ",
      "aeadedbgei      ",
      "cbbbeadgd       "
    ],
    [
      "  f  g          ",
      "    e           ",
      "ϔ   f           ",
      "    f           ",
      "     f          ",
      "     f          ",
      "      f         ",
      "ebdeadgea       ",
      "      f         ",
      "      f         ",
      " eca   f        ",
      " b              ",
      " d ϔ            ",
      " c              ",
      "caebbabaaa      ",
      "e      f        "
    ],
    [
      "  fs g          ",
      "   fe           ",
      "    fl          ",
      "    fl          ",
      "     fl         ",
      "     fl         ",
      "       l        ",
      "aceaacgca       ",
      "      fl        ",
      "       l        ",
      "       fl       ",
      "       fl       ",
      " 下     fl       ",
      "        l       ",
      "bccdbeaaca      ",
      "       fl       "
    ],
    [
      "   p g          ",
      "   fb           ",
      "    ft          ",
      "    ft          ",
      "     ft         ",
      "     ft         ",
      "      ft        ",
      "abcdddaca       ",
      "      ft        ",
      "      ft        ",
      "       ft       ",
      "       ft       ",
      "       ft       ",
      "       ft       ",
      "ebbaaecabi      ",
      "       ft       "
    ],
    [
      "  f  a          ",
      "    a           ",
      "                ",
      "    f           ",
      "     f          ",
      "     f          ",
      "                ",
      "dbbaaaaeg       ",
      "                ",
      "                ",
      "                ",
      "       f        ",
      "       f        ",
      "       f        ",
      "cedeccbaag      ",
      "                "
    ],
    [
      "  aa g          ",
      "   ge           ",
      "    gc          ",
      "    aa          ",
      "     ac         ",
      "     ae         ",
      "      ae        ",
      "acdeebiea       ",
      "      ab        ",
      "      gd        ",
      "       gc       ",
      "       ga       ",
      "       ge       ",
      "       ac       ",
      "eaaccebaea      ",
      "       ad       "
    ]
  ]
}