{
  "xsize": 16,
  "zsize": 16,
  "palette": {
    "palette": [
      {
        "char": " ",
        "block": "minecraft:air"
      },
      {
        "char": "y",
        "block": "minecraft:basalt[axis=x]"
      },
      {
        "char": "Q",
        "block": "minecraft:grass_block[snowy=false]"
      },
      {
        "char": "b",
        "block": "minecraft:blackstone"
      },
      {
        "char": "a",
        "block": "minecraft:cyan_terracotta"
      },
      {
        "char": "d",
        "block": "minecraft:cobbled_deepslate"
      },
      {
        "char": "c",
        "block": "minecraft:deepslate[axis=y]"
      },
      {
        "char": "r",
        "block": "minecraft:polished_diorite"
      },
      {
        "char": "J",
        "block": "minecraft:diorite"
      },
      {
        "char": "C",
        "block": "minecraft:quartz_pillar[axis=y]"
      },
      {
        "char": "n",
        "block": "minecraft:smooth_quartz"
      },
      {
        "char": "o",
        "block": "minecraft:chiseled_quartz_block"
      },
      {
        "char": "K",
        "block": "minecraft:quartz_block"
      },
      {
        "char": "资",
        "block": "minecraft:dirt"
      },
      {
        "char": "U",
        "block": "minecraft:air"
      },
      {
        "char": "x",
        "block": "minecraft:cauldron"
      },
      {
        "char": "e",
        "block": "minecraft:basalt[axis=y]"
      },
      {
        "char": "明",
        "block": "minecraft:air",
        "tag": {
          "z": -256,
          "x": -49,
          "ForgeCaps": {},
          "id": "refurbished_furniture:basin",
          "y": -52,
          "FluidTank": {
            "FluidTank": {
              "Amount": 0,
              "FluidName": "minecraft:empty"
            }
          }
        }
      },
      {
        "char": "事",
        "block": "minecraft:spruce_door[facing=north,half=lower,hinge=left,open=false,powered=false]"
      },
      {
        "char": "g",
        "block": "minecraft:gray_concrete"
      },
      {
        "char": "时",
        "block": "minecraft:air"
      },
      {
        "char": "i",
        "block": "minecraft:light_gray_concrete"
      },
      {
        "char": "心",
        "block": "minecraft:spruce_door[facing=south,half=lower,hinge=left,open=false,powered=false]"
      },
      {
        "char": "路",
        "block": "minecraft:air"
      },
      {
        "char": "V",
        "block": "minecraft:air"
      },
      {
        "char": "ҟ",
        "block": "minecraft:spruce_trapdoor[facing=south,half=bottom,open=false,powered=false,waterlogged=false]"
      },
      {
        "char": "经",
        "block": "minecraft:spruce_door[facing=north,half=upper,hinge=left,open=false,powered=false]"
      },
      {
        "char": "工",
        "block": "minecraft:spruce_door[facing=south,half=upper,hinge=left,open=false,powered=false]"
      },
      {
        "char": "自",
        "block": "minecraft:spruce_trapdoor[facing=north,half=bottom,open=false,powered=false,waterlogged=false]"
      },
      {
        "char": "对",
        "block": "minecraft:polished_andesite_slab[type=bottom,waterlogged=false]"
      }
    ]
  },
  "slices": [
    [
      "yyQbadbcbcrrrJCn",
      "ybbdcQbacaCoonnn",
      "cabaabcadaonoKro",
      "ybdQcdacb资JrJJnJ",
      "QacyydcaydCorJoJ",
      "Qdcaddycy资roKoKo",
      "cbQcaaaayycaccb资",
      "bQydddcyccbbadyb",
      "cydbayaybcQQaayd",
      "cbcadadQbaaaaycy",
      "ddabydaycaQcdcbb",
      "yQadQddbccdbydcd",
      "dbQbycadcddycacc",
      "QbccbaaayaaQadcy",
      "acydcbddbbbbyddc",
      "abydddbcayydddaa"
    ],
    [
      "  U     bcxexa 明",
      "     U   b事c事b  ",
      "         d      ",
      "   U    ga      ",
      "时       ia心b心c心b",
      "时       路cxcxbxe",
      "  U      acaadac",
      " U         aa   ",
      "          UU    ",
      "       U        ",
      "          U     ",
      " U  U           ",
      "  U             ",
      "时          U    ",
      "                ",
      "                "
    ],
    [
      "  V      eҟdҟd  ",
      "     V   a经c经d  ",
      "         a      ",
      "   V    aa      ",
      "        ag工c工b工d",
      "        路e自a自e自e",
      "  V      edaacbe",
      " V         ai   ",
      "          VV    ",
      "       V        ",
      "          V     ",
      " V  V           ",
      "  V             ",
      "           V    ",
      "                ",
      "                "
    ],
    [
      "         a b d  ",
      "         a a e  ",
      "         c      ",
      "        aa      ",
      "        ga a d b",
      "        路d d e a",
      "         deaidcc",
      "           ia   ",
      "                ",
      "                ",
      "                ",
      "                ",
      "                ",
      "                ",
      "                ",
      "                "
    ],
    [
      "         e      ",
      "         a      ",
      "         e      ",
      "        aa      ",
      "        gg      ",
      "        对a      ",
      "         cdgacda",
      "           aa   ",
      "                ",
      "                ",
      "                ",
      "                ",
      "                ",
      "                ",
      "                ",
      "                "
    ],
    [
      "         b      ",
      "         e      ",
      "         d      ",
      "        aa      ",
      "        aa      ",
      "         d      ",
      "         ebaadad",
      "           aa   ",
      "                ",
      "                ",
      "                ",
      "                ",
      "                ",
      "                ",
      "                ",
      "                "
    ]
  ]
}