{
  "xsize": 16,
  "zsize": 16,
  "palette": {
    "palette": [
      {
        "char": " ",
        "block": "minecraft:air"
      },
      {
        "char": "b",
        "block": "minecraft:blackstone"
      },
      {
        "char": "c",
        "block": "minecraft:deepslate[axis=y]"
      },
      {
        "char": "a",
        "block": "minecraft:cyan_terracotta"
      },
      {
        "char": "e",
        "block": "minecraft:basalt[axis=y]"
      },
      {
        "char": "d",
        "block": "minecraft:cobbled_deepslate"
      },
      {
        "char": "i",
        "block": "minecraft:light_gray_concrete"
      },
      {
        "char": "ϕ",
        "block": "minecraft:quartz_stairs[facing=north,half=bottom,shape=straight,waterlogged=false]"
      },
      {
        "char": "O",
        "block": "minecraft:quartz_stairs[facing=west,half=bottom,shape=straight,waterlogged=false]"
      },
      {
        "char": "ϓ",
        "block": "minecraft:air"
      },
      {
        "char": "ϔ",
        "block": "minecraft:quartz_stairs[facing=east,half=bottom,shape=straight,waterlogged=false]"
      },
      {
        "char": "f",
        "block": "minecraft:glass"
      },
      {
        "char": "x",
        "block": "minecraft:cauldron"
      },
      {
        "char": "m",
        "block": "minecraft:iron_trapdoor[facing=west,half=bottom,open=false,powered=false,waterlogged=false]"
      },
      {
        "char": "k",
        "block": "minecraft:oak_leaves[distance=7,persistent=true,waterlogged=false]"
      },
      {
        "char": "u",
        "block": "minecraft:iron_trapdoor[facing=south,half=bottom,open=false,powered=false,waterlogged=false]"
      },
      {
        "char": "g",
        "block": "minecraft:gray_concrete"
      },
      {
        "char": "q",
        "block": "minecraft:iron_trapdoor[facing=west,half=top,open=false,powered=false,waterlogged=false]"
      },
      {
        "char": "w",
        "block": "minecraft:iron_trapdoor[facing=south,half=top,open=false,powered=false,waterlogged=false]"
      },
      {
        "char": "I",
        "block": "minecraft:stone_slab[type=top,waterlogged=false,weathering=false]"
      }
    ]
  },
  "slices": [
    [
      "bcaaaabedaacbace",
      "addcaebcbcaebaea",
      "deeaeeeccddbcbbc",
      "ebddadeccaacabea",
      "cabbdabcccbeceaa",
      "cedeeddcbcaebecc",
      "aaadecabeadeeaee",
      "  i aabdeddeeeeb",
      "    bedabbcabaec",
      "     daadeabeaec",
      "      abaccbacad",
      "       ccbbbdeaa",
      "         dccedab",
      "        i     ba",
      "               c",
      "                "
    ],
    [
      "           cdeec",
      "                ",
      "  e             ",
      "  e             ",
      "  b   ϕ   cda   ",
      "cce  Oϓϔ  b     ",
      "   ba     c     ",
      "  a  f    dx    ",
      "     f    c     ",
      "      f   b     ",
      "       ff dx    ",
      "         aa     ",
      "         ad     ",
      "        a       ",
      "                ",
      "                "
    ],
    [
      "           eaccc",
      "                ",
      "  b             ",
      "  c             ",
      "  a       ebb   ",
      "eaa       e     ",
      "   ec     a     ",
      "  i mf    bk    ",
      "    mf    c     ",
      "     mf   b     ",
      "      mff bk    ",
      "       uuab     ",
      "         ee     ",
      "        a       ",
      "                ",
      "                "
    ],
    [
      "           dbdba",
      "                ",
      "  b             ",
      "  e             ",
      "  e       dae   ",
      "deb       a     ",
      "   db     e     ",
      "  g qf    ck    ",
      "    q     e     ",
      "     wf   d     ",
      "      qff ck    ",
      "       wweb     ",
      "         bd     ",
      "        a aca   ",
      "                ",
      "                "
    ],
    [
      "  I        abcee",
      "  I             ",
      "  a             ",
      "  b             ",
      "  c       eeaIII",
      "adb       b     ",
      "   ad     b     ",
      "  a  f    d     ",
      "     f    a     ",
      "          d     ",
      "       f  c     ",
      "         da     ",
      "         ce     ",
      "        a    bII",
      "                ",
      "                "
    ],
    [
      "  d        dbabe",
      "  d             ",
      "  c             ",
      "  c             ",
      "  c       dbedee",
      "ebc       c     ",
      "   a      c     ",
      "  g bd    a     ",
      "    da    b     ",
      "     ee   b     ",
      "      cbe b     ",
      "       bc d     ",
      "         ad     ",
      "        a     aa",
      "                ",
      "                "
    ]
  ]
}