{
  "xsize": 16,
  "zsize": 16,
  "palette": {
    "palette": [
      {
        "char": " ",
        "block": "minecraft:air"
      },
      {
        "char": "e",
        "block": "minecraft:basalt[axis=y]"
      },
      {
        "char": "c",
        "block": "minecraft:deepslate[axis=y]"
      },
      {
        "char": "d",
        "block": "minecraft:cobbled_deepslate"
      },
      {
        "char": "b",
        "block": "minecraft:blackstone"
      },
      {
        "char": "a",
        "block": "minecraft:cyan_terracotta"
      },
      {
        "char": "i",
        "block": "minecraft:light_gray_concrete"
      },
      {
        "char": "x",
        "block": "minecraft:cauldron"
      },
      {
        "char": "g",
        "block": "minecraft:gray_concrete"
      },
      {
        "char": "k",
        "block": "minecraft:oak_leaves[distance=7,persistent=true,waterlogged=false]"
      },
      {
        "char": "P",
        "block": "minecraft:smooth_quartz_slab[type=bottom,waterlogged=false]"
      },
      {
        "char": "Ѯ",
        "block": "minecraft:diorite_slab[type=bottom,waterlogged=false]"
      },
      {
        "char": "M",
        "block": "minecraft:smooth_quartz_slab[type=top,waterlogged=false]"
      },
      {
        "char": "ѩ",
        "block": "minecraft:diorite_slab[type=top,waterlogged=false]"
      },
      {
        "char": "ѭ",
        "block": "minecraft:polished_andesite_stairs[facing=west,half=top,shape=straight,waterlogged=false]"
      },
      {
        "char": "h",
        "block": "minecraft:andesite_slab[type=top,waterlogged=false]"
      }
    ]
  },
  "slices": [
    [
      "         eceeeec",
      "         dcbbdbd",
      "         ddecced",
      "         ceaedad",
      "         eebadca",
      "         cbecbab",
      "        aicaabed",
      "        iidebbce",
      "         ccedeba",
      "         caeaaac",
      "         edbaadb",
      "         babddaa",
      "         ecdbcec",
      "         bbddeda",
      "         aaeecec",
      "         eeeadad"
    ],
    [
      "         c      ",
      "         bx     ",
      "         d      ",
      "         a      ",
      "         dx     ",
      "         e      ",
      "        ia      ",
      "        gge    b",
      "         b      ",
      "         b      ",
      "         bx     ",
      "         e      ",
      "         a      ",
      "         bx     ",
      "         c      ",
      "         c      "
    ],
    [
      "         e      ",
      "         ek     ",
      "         d      ",
      "         b      ",
      "         ak     ",
      "         e      ",
      "        aa      ",
      "        aae    e",
      "         e      ",
      "         e      ",
      "         ek     ",
      "         b      ",
      "         a      ",
      "         ek     ",
      "         a      ",
      "         b      "
    ],
    [
      "        Pd      ",
      "        Pck     ",
      "        Pa      ",
      "        Pe      ",
      "        Pek     ",
      "        Pc      ",
      "        ag      ",
      "        aic    b",
      "        Pb      ",
      "        Ѯb      ",
      "        Pdk     ",
      "        Pd      ",
      "        Pe      ",
      "        Pek     ",
      "        Pd      ",
      "        Pc      "
    ],
    [
      "        Ma      ",
      "        ѩa      ",
      "        Mc      ",
      "        ѩe      ",
      "        Mb      ",
      "        Ma      ",
      "        ag      ",
      "        aae    c",
      "        Md      ",
      "        Me      ",
      "        Mc      ",
      "        Ma      ",
      "        Me      ",
      "        Mb      ",
      "        ѩe      ",
      "        Ma      "
    ],
    [
      "         eѭhhhhh",
      "         bѭhhhhh",
      "         aѭhhhhh",
      "         cѭhhhhh",
      "         cѭhhhhh",
      "         eѭhhhhh",
      "        abѭhhhhh",
      "        gdbadcea",
      "         cѭhhhhh",
      "         bѭhhhhh",
      "         eѭhhhhh",
      "         cѭhhhhh",
      "         dѭhhhhh",
      "         dѭhhhhh",
      "         cѭhhhhh",
      "         eѭhhhhh"
    ]
  ]
}