{
  "xsize": 16,
  "zsize": 16,
  "palette": {
    "palette": [
      {
        "char": " ",
        "block": "minecraft:air"
      },
      {
        "char": "e",
        "block": "minecraft:basalt[axis=y]"
      },
      {
        "char": "c",
        "block": "minecraft:deepslate[axis=y]"
      },
      {
        "char": "a",
        "block": "minecraft:cyan_terracotta"
      },
      {
        "char": "b",
        "block": "minecraft:blackstone"
      },
      {
        "char": "d",
        "block": "minecraft:cobbled_deepslate"
      },
      {
        "char": "Z",
        "block": "minecraft:stone_brick_wall[east=tall,north=tall,south=none,up=true,waterlogged=false,weathering=false,west=tall]"
      },
      {
        "char": "Ӿ",
        "block": "minecraft:cobblestone_wall[east=tall,north=tall,south=none,up=true,waterlogged=false,weathering=false,west=tall]"
      },
      {
        "char": "你",
        "block": "minecraft:spawner",
        "tag": {
          "SpawnData": {
            "entity": {}
          },
          "MaxNearbyEntities": "6s",
          "MinSpawnDelay": "200s",
          "z": -274,
          "x": -42,
          "MaxSpawnDelay": "800s",
          "RequiredPlayerRange": "16s",
          "SpawnCount": "4s",
          "id": "minecraft:mob_spawner",
          "SpawnPotentials": [],
          "y": 1,
          "SpawnRange": "4s",
          "Delay": "731s"
        }
      },
      {
        "char": "G",
        "block": "minecraft:iron_bars[east=false,north=false,south=true,waterlogged=false,west=false]"
      },
      {
        "char": "H",
        "block": "minecraft:quartz_stairs[facing=south,half=bottom,shape=straight,waterlogged=false]"
      },
      {
        "char": "ϕ",
        "block": "minecraft:quartz_stairs[facing=north,half=bottom,shape=straight,waterlogged=false]"
      },
      {
        "char": "O",
        "block": "minecraft:quartz_stairs[facing=west,half=bottom,shape=straight,waterlogged=false]"
      },
      {
        "char": "ϓ",
        "block": "minecraft:air"
      },
      {
        "char": "x",
        "block": "minecraft:cauldron"
      },
      {
        "char": "v",
        "block": "minecraft:quartz_pillar[axis=x]"
      },
      {
        "char": "o",
        "block": "minecraft:chiseled_quartz_block"
      },
      {
        "char": "K",
        "block": "minecraft:quartz_block"
      },
      {
        "char": "N",
        "block": "minecraft:white_stained_glass_pane[east=true,north=false,south=false,waterlogged=false,west=true]"
      },
      {
        "char": "k",
        "block": "minecraft:oak_leaves[distance=7,persistent=true,waterlogged=false]"
      },
      {
        "char": "J",
        "block": "minecraft:diorite"
      },
      {
        "char": "Ѳ",
        "block": "minecraft:white_stained_glass_pane[east=true,north=false,south=false,waterlogged=false,west=false]"
      },
      {
        "char": "r",
        "block": "minecraft:polished_diorite"
      },
      {
        "char": "n",
        "block": "minecraft:smooth_quartz"
      },
      {
        "char": "j",
        "block": "minecraft:polished_andesite_slab[type=top,waterlogged=false]"
      },
      {
        "char": "C",
        "block": "minecraft:quartz_pillar[axis=y]"
      }
    ]
  },
  "slices": [
    [
      "eccaabdcbceacdee",
      "cadeccbcacdbeadc",
      "abaaeeacebddadac",
      "ccdcaacaebcebcea",
      "ddecabbcbaeaecab",
      "abcaddbeaeaedddc",
      "baecbaabcaceeaae",
      "ebdbbcbcbaeebcdb",
      "dbacbacebadedcab",
      "ebbeeecedbceaebb",
      "aecbddcadacedebe",
      "aebddedacdabebde",
      "ZZӾeZZZbaedaeced",
      "   c   aabcea你ab",
      "   a   ececc你你cc",
      " G a G accbcddbc"
    ],
    [
      " d      c  H    ",
      " c             ϕ",
      " e            Oϓ",
      " d      a      H",
      "acecaeadd       ",
      " d  x  d        ",
      "       d        ",
      "             aed",
      "             c  ",
      "             a  ",
      "       e     c  ",
      "   a   b        ",
      "vvveoKvc        ",
      "   c   c     e  ",
      "   d   ed   cddd",
      " G a G d     a  "
    ],
    [
      " a      a       ",
      " c              ",
      " d              ",
      " e      b       ",
      "badNNNbbe       ",
      " a  k  a        ",
      "       a        ",
      "             adb",
      "             a  ",
      "             a  ",
      "       a     e  ",
      "   b   c        ",
      "vvvavvJd        ",
      "   c   c     c  ",
      "   e   dc   adec",
      " G b G b     e  "
    ],
    [
      " a      c       ",
      " d              ",
      " a              ",
      " d      b       ",
      "dcd ѲNccb       ",
      " c  k  b        ",
      "       e        ",
      "             ebd",
      "             a  ",
      "             c  ",
      "       d     c  ",
      "   e   a        ",
      "orvenrva        ",
      "   b   e     c  ",
      "   b   aa   eaab",
      " G e G c     c  "
    ],
    [
      " b      a       ",
      " d      j       ",
      " d      j       ",
      " d      a       ",
      "beccbaaca       ",
      " b     e        ",
      "       b        ",
      "       j     aee",
      "       j     d  ",
      "       j     b  ",
      "       e     a  ",
      "jjjcjjja     j  ",
      "vCvcvvnc     j  ",
      "   d   b     d  ",
      "   d   eajjjbecd",
      " G b G d     d  "
    ],
    [
      " b      b       ",
      " c      c       ",
      " c      b       ",
      " c      c       ",
      "aaabeaedb       ",
      " a     e        ",
      "       b        ",
      "       d     ede",
      "       e     d  ",
      "       a     b  ",
      "       c     e  ",
      "caceabae     b  ",
      "   b   b     c  ",
      "   e   b     e  ",
      "   c   ccccdaacb",
      " G e G e     b  "
    ]
  ]
}