{
  "xsize": 16,
  "zsize": 16,
  "palette": {
    "palette": [
      {
        "char": " ",
        "block": "minecraft:air"
      },
      {
        "char": "a",
        "block": "minecraft:cyan_terracotta"
      },
      {
        "char": "e",
        "block": "minecraft:basalt[axis=y]"
      },
      {
        "char": "c",
        "block": "minecraft:deepslate[axis=y]"
      },
      {
        "char": "i",
        "block": "minecraft:light_gray_concrete"
      },
      {
        "char": "g",
        "block": "minecraft:gray_concrete"
      },
      {
        "char": "b",
        "block": "minecraft:blackstone"
      },
      {
        "char": "d",
        "block": "minecraft:cobbled_deepslate"
      },
      {
        "char": "f",
        "block": "minecraft:glass"
      },
      {
        "char": "ϕ",
        "block": "minecraft:quartz_stairs[facing=north,half=bottom,shape=straight,waterlogged=false]"
      },
      {
        "char": "П",
        "block": "minecraft:barrel[facing=up,open=false]",
        "tag": {
          "z": -275,
          "x": -15,
          "ForgeData": {
            "LockFlag": "1b"
          },
          "id": "minecraft:barrel",
          "y": 2,
          "Items": []
        }
      },
      {
        "char": "O",
        "block": "minecraft:quartz_stairs[facing=west,half=bottom,shape=straight,waterlogged=false]"
      },
      {
        "char": "ϓ",
        "block": "minecraft:air"
      },
      {
        "char": "ϔ",
        "block": "minecraft:quartz_stairs[facing=east,half=bottom,shape=straight,waterlogged=false]"
      },
      {
        "char": "s",
        "block": "minecraft:iron_trapdoor[facing=north,half=bottom,open=false,powered=false,waterlogged=false]"
      },
      {
        "char": "l",
        "block": "minecraft:iron_trapdoor[facing=east,half=bottom,open=false,powered=false,waterlogged=false]"
      },
      {
        "char": "天",
        "block": "minecraft:air"
      },
      {
        "char": "p",
        "block": "minecraft:iron_trapdoor[facing=north,half=top,open=false,powered=false,waterlogged=false]"
      }
    ]
  },
  "slices": [
    [
      "                ",
      "                ",
      "                ",
      "                ",
      "                ",
      "                ",
      "                ",
      "   aec  ai      ",
      "   agabbccaa    ",
      "   edaaagicbga  ",
      "  ddceadadaaeeaa",
      " dadbbeaddbbagea",
      "cedbdbbbbdededac",
      "aeecccbceebbabea",
      "aecdbadecacbdead",
      "eccccaceeeebeeaa"
    ],
    [
      "                ",
      "                ",
      "                ",
      "                ",
      "                ",
      "                ",
      "                ",
      "        a       ",
      "   f    a       ",
      "       fa       ",
      "        a  f   a",
      " d      c   f a ",
      " a d ϕ  d     f ",
      " a a    c       ",
      " a dbacПd  ϕ    ",
      " b      c Oϓϔ   "
    ],
    [
      "                ",
      "                ",
      "                ",
      "                ",
      "                ",
      "                ",
      "                ",
      "  ssss  a       ",
      "  ffffsscs      ",
      "       fg ss    ",
      " d      d ffss a",
      " c      e   f d ",
      " d      a     fl",
      " b      d       ",
      " e  天 天 a       ",
      " b      c       "
    ],
    [
      "                ",
      "                ",
      "                ",
      "                ",
      "                ",
      "                ",
      " a              ",
      " dpppp  g       ",
      " afff ppbp      ",
      " d     fa pp    ",
      " d      d ffpp a",
      " b      c    fd ",
      " e      e     fp",
      " e      b       ",
      " d      a       ",
      " c      b       "
    ],
    [
      "                ",
      "                ",
      "                ",
      "                ",
      "                ",
      "                ",
      " g              ",
      " a      a       ",
      "fa fff  e       ",
      " a    ffif      ",
      " c      c ff   a",
      " b      a   ffd ",
      " b      d     f ",
      " d      c       ",
      " e      d       ",
      " a      a       "
    ],
    [
      "                ",
      "                ",
      "                ",
      "                ",
      "                ",
      "                ",
      " a              ",
      "badedd  a       ",
      "agiiaadceb      ",
      " d    aagaad    ",
      " b      a agbb a",
      " d      d   aad ",
      " b      c     ae",
      " b      b      a",
      " c      d       ",
      " d      d       "
    ]
  ]
}