{
  "xsize": 16,
  "zsize": 16,
  "palette": {
    "palette": [
      {
        "char": " ",
        "block": "minecraft:air"
      },
      {
        "char": "f",
        "block": "minecraft:polished_diorite"
      },
      {
        "char": "e",
        "block": "minecraft:smooth_quartz"
      },
      {
        "char": "o",
        "block": "minecraft:quartz_block"
      },
      {
        "char": "p",
        "block": "minecraft:diorite"
      },
      {
        "char": "h",
        "block": "minecraft:white_stained_glass"
      },
      {
        "char": "x",
        "block": "minecraft:smooth_stone"
      },
      {
        "char": "头",
        "block": "minecraft:rail[shape=south_east,waterlogged=false]"
      },
      {
        "char": "考",
        "block": "minecraft:rail[shape=south_west,waterlogged=false]"
      },
      {
        "char": "难",
        "block": "minecraft:rail[shape=north_east,waterlogged=false]"
      },
      {
        "char": "喜",
        "block": "minecraft:rail[shape=north_west,waterlogged=false]"
      },
      {
        "char": "结",
        "block": "minecraft:rail[shape=east_west,waterlogged=false]"
      }
    ]
  },
  "slices": [
    [
      "fefefffoeeppefep",
      "hheeeffffohhhhhh",
      "hhfeffofeehhhhhh",
      "hhpeefffefhhhhhh",
      "hhfefpppfohhhhhh",
      "hheffpofpehhhhhh",
      "hheepoeefehhhhhh",
      "hhfooofepfhhhhhh",
      "eoeefeoeoefffeoe",
      "ppohhhhhheepppfo",
      "eefhhhhhhppeeefe",
      "fephhhhhhoepffoo",
      "pophhhhhhooffoee",
      "efehhhhhhfoefoep",
      "eoohhhhhhfpeoeff",
      "fefhhhhhhepepefo"
    ],
    [
      "                ",
      "                ",
      "                ",
      "     xx         ",
      "     xx         ",
      "     xx         ",
      "                ",
      "                ",
      "                ",
      "                ",
      "                ",
      "                ",
      "                ",
      "                ",
      "                ",
      "                "
    ],
    [
      "                ",
      "                ",
      "                ",
      "     头考         ",
      "     难喜         ",
      "     结结         ",
      "                ",
      "                ",
      "                ",
      "                ",
      "                ",
      "                ",
      "                ",
      "                ",
      "                ",
      "                "
    ],
    [
      "                ",
      "                ",
      "                ",
      "                ",
      "                ",
      "                ",
      "                ",
      "                ",
      "                ",
      "                ",
      "                ",
      "                ",
      "                ",
      "                ",
      "                ",
      "                "
    ],
    [
      "                ",
      "                ",
      "                ",
      "                ",
      "                ",
      "                ",
      "                ",
      "                ",
      "                ",
      "                ",
      "                ",
      "                ",
      "                ",
      "                ",
      "                ",
      "                "
    ],
    [
      "                ",
      "                ",
      "                ",
      "                ",
      "                ",
      "                ",
      "                ",
      "                ",
      "                ",
      "                ",
      "                ",
      "                ",
      "                ",
      "                ",
      "                ",
      "                "
    ]
  ]
}