{
  "xsize": 16,
  "zsize": 16,
  "palette": {
    "palette": [
      {
        "char": " ",
        "block": "minecraft:air"
      },
      {
        "char": "E",
        "block": "minecraft:stone_bricks[weathering=false]"
      },
      {
        "char": "C",
        "block": "minecraft:mossy_cobblestone"
      },
      {
        "char": "z",
        "block": "minecraft:mossy_stone_bricks"
      },
      {
        "char": "D",
        "block": "minecraft:cracked_stone_bricks"
      },
      {
        "char": "e",
        "block": "minecraft:smooth_quartz"
      },
      {
        "char": "o",
        "block": "minecraft:quartz_block"
      },
      {
        "char": "p",
        "block": "minecraft:diorite"
      },
      {
        "char": "h",
        "block": "minecraft:white_stained_glass"
      },
      {
        "char": "f",
        "block": "minecraft:polished_diorite"
      },
      {
        "char": "x",
        "block": "minecraft:smooth_stone"
      },
      {
        "char": "头",
        "block": "minecraft:rail[shape=south_east,waterlogged=false]"
      },
      {
        "char": "考",
        "block": "minecraft:rail[shape=south_west,waterlogged=false]"
      },
      {
        "char": "难",
        "block": "minecraft:rail[shape=north_east,waterlogged=false]"
      },
      {
        "char": "喜",
        "block": "minecraft:rail[shape=north_west,waterlogged=false]"
      },
      {
        "char": "结",
        "block": "minecraft:rail[shape=east_west,waterlogged=false]"
      },
      {
        "char": "城",
        "block": "minecraft:rail[shape=north_south,waterlogged=false]"
      }
    ]
  },
  "slices": [
    [
      "ECzzDCzDCCeeoeep",
      "hhffopfppfhhhhhh",
      "hhfeoeoppehhhhhh",
      "hhfeefepfehhhhhh",
      "hhfoefooeehhhhhh",
      "hheofofpefhhhhhh",
      "hhfepofpffhhhhhh",
      "hhfffpoefehhhhhh",
      "feffepofeeofeeof",
      "eephhhhhhpfofpfp",
      "effhhhhhhpepfppe",
      "pophhhhhheeefpof",
      "opehhhhhhefffeoe",
      "efehhhhhheffpeoe",
      "eephhhhhheofefff",
      "epehhhhhhpeeeffe"
    ],
    [
      "                ",
      "                ",
      "                ",
      "     xx         ",
      "     xx         ",
      "     xx         ",
      "                ",
      "                ",
      "                ",
      "                ",
      "                ",
      "                ",
      "             xx ",
      "             xx ",
      "             xx ",
      "                "
    ],
    [
      "                ",
      "                ",
      "                ",
      "     头考         ",
      "     难喜         ",
      "     结结         ",
      "                ",
      "                ",
      "                ",
      "                ",
      "                ",
      "                ",
      "             头考 ",
      "             城城 ",
      "             难喜 ",
      "                "
    ],
    [
      "                ",
      "                ",
      "                ",
      "                ",
      "                ",
      "                ",
      "                ",
      "                ",
      "                ",
      "                ",
      "                ",
      "                ",
      "                ",
      "                ",
      "                ",
      "                "
    ],
    [
      "                ",
      "                ",
      "                ",
      "                ",
      "                ",
      "                ",
      "                ",
      "                ",
      "                ",
      "                ",
      "                ",
      "                ",
      "                ",
      "                ",
      "                ",
      "                "
    ],
    [
      "                ",
      "                ",
      "                ",
      "                ",
      "                ",
      "                ",
      "                ",
      "                ",
      "                ",
      "                ",
      "                ",
      "                ",
      "                ",
      "                ",
      "                ",
      "                "
    ]
  ]
}