{
  "xsize": 16,
  "zsize": 16,
  "palette": {
    "palette": [
      {
        "char": " ",
        "block": "minecraft:air"
      },
      {
        "char": "l",
        "block": "minecraft:vine[east=true,north=false,south=false,up=false,west=false]"
      },
      {
        "char": "z",
        "block": "minecraft:mossy_stone_bricks"
      },
      {
        "char": "K",
        "block": "minecraft:cobblestone_slab[type=double,waterlogged=false,weathering=false]"
      },
      {
        "char": "Ҩ",
        "block": "minecraft:cobblestone_slab[type=top,waterlogged=false,weathering=false]"
      },
      {
        "char": "Ұ",
        "block": "minecraft:vine[east=true,north=true,south=false,up=false,west=false]"
      },
      {
        "char": "p",
        "block": "minecraft:diorite"
      },
      {
        "char": "g",
        "block": "minecraft:blue_concrete"
      },
      {
        "char": "j",
        "block": "minecraft:vine[east=false,north=false,south=false,up=false,west=true]"
      },
      {
        "char": "e",
        "block": "minecraft:smooth_quartz"
      },
      {
        "char": "f",
        "block": "minecraft:polished_diorite"
      },
      {
        "char": "o",
        "block": "minecraft:quartz_block"
      },
      {
        "char": "m",
        "block": "minecraft:vine[east=false,north=false,south=true,up=false,west=false]"
      },
      {
        "char": "E",
        "block": "minecraft:stone_bricks[weathering=false]"
      },
      {
        "char": "y",
        "block": "minecraft:quartz_pillar[axis=y]"
      },
      {
        "char": "C",
        "block": "minecraft:mossy_cobblestone"
      },
      {
        "char": "i",
        "block": "minecraft:vine[east=false,north=true,south=false,up=false,west=false]"
      },
      {
        "char": "D",
        "block": "minecraft:cracked_stone_bricks"
      },
      {
        "char": "毕",
        "block": "minecraft:cobblestone_wall[east=none,north=low,south=none,up=true,waterlogged=false,weathering=false,west=tall]"
      },
      {
        "char": "投",
        "block": "minecraft:cobblestone_wall[east=none,north=low,south=tall,up=true,waterlogged=false,weathering=false,west=none]"
      },
      {
        "char": "G",
        "block": "minecraft:air"
      },
      {
        "char": "A",
        "block": "minecraft:air"
      },
      {
        "char": "听",
        "block": "minecraft:cobblestone_wall[east=low,north=none,south=none,up=false,waterlogged=false,weathering=false,west=low]"
      },
      {
        "char": "常",
        "block": "minecraft:cobblestone_wall[east=low,north=low,south=none,up=true,waterlogged=false,weathering=false,west=low]"
      },
      {
        "char": "口",
        "block": "minecraft:cobblestone_wall[east=none,north=none,south=low,up=true,waterlogged=false,weathering=false,west=low]"
      },
      {
        "char": "H",
        "block": "minecraft:cobblestone[weathering=false]"
      },
      {
        "char": "天",
        "block": "minecraft:stone_slab[type=double,waterlogged=false,weathering=false]"
      },
      {
        "char": "t",
        "block": "minecraft:stone_slab[type=bottom,waterlogged=false,weathering=false]"
      },
      {
        "char": "他",
        "block": "minecraft:air"
      },
      {
        "char": "v",
        "block": "minecraft:vine[east=false,north=false,south=false,up=true,west=false]"
      },
      {
        "char": "更",
        "block": "minecraft:vine[east=false,north=false,south=false,up=true,west=true]"
      }
    ]
  },
  "slices": [
    [
      "         lzzKҨK ",
      "          Ұp  gj",
      "          lej   ",
      "           p    ",
      "          lfj   ",
      "          loj   ",
      "          lfj   ",
      "          lpjm m",
      "          zEyyfy",
      "         lzCiiii",
      "          iz    ",
      "          lD    ",
      "          lC    ",
      "          lD    ",
      "          lzzDDz",
      "           i  ii"
    ],
    [
      "         lDD毕 投 ",
      "          Ұf  gj",
      "          lej   ",
      "           p    ",
      "          lej   ",
      "          lej   ",
      "          lyj   ",
      "          lfjm m",
      "          CDeyep",
      "         lzDiiii",
      "          iG    ",
      "           G    ",
      "           G    ",
      "           G    ",
      "          lCAAAA",
      "           i    "
    ],
    [
      "         lCC听常口 ",
      "          Ұf  gj",
      "          lfj   ",
      "           e    ",
      "          lpj   ",
      "          lp    ",
      "          loj   ",
      "           e   m",
      "          DDeffe",
      "         lCCiii ",
      "          iG    ",
      "           G    ",
      "           G    ",
      "           G    ",
      "          lzAAAA",
      "           i    "
    ],
    [
      "         lCz    ",
      "          Ұe    ",
      "           pj   ",
      "           f    ",
      "           e    ",
      "          le    ",
      "           oj   ",
      "           p   m",
      "          zEfeye",
      "         lDziii ",
      "          i     ",
      "                ",
      "                ",
      "                ",
      "          lCj   ",
      "           i    "
    ],
    [
      "         lHD    ",
      "          Ұf    ",
      "           ej   ",
      "           f    ",
      "           o    ",
      "          lp    ",
      "           f    ",
      "           f    ",
      "          CEpooe",
      "          Hziii ",
      "                ",
      "                ",
      "                ",
      "                ",
      "                ",
      "                "
    ],
    [
      "         lDD天tt他",
      "           y   v",
      "           e更   ",
      "           f    ",
      "           p  v ",
      "           f    ",
      "           f    ",
      "           e    ",
      "          EEpeep",
      "          Cziii ",
      "                ",
      "                ",
      "                ",
      "                ",
      "                ",
      "                "
    ]
  ]
}