{
  "xsize": 16,
  "zsize": 16,
  "palette": {
    "palette": [
      {
        "char": " ",
        "block": "minecraft:air"
      },
      {
        "char": "c",
        "block": "minecraft:air"
      },
      {
        "char": "k",
        "block": "minecraft:air"
      },
      {
        "char": "b",
        "block": "minecraft:air"
      },
      {
        "char": "d",
        "block": "minecraft:air"
      },
      {
        "char": "a",
        "block": "minecraft:air"
      },
      {
        "char": "s",
        "block": "minecraft:air"
      },
      {
        "char": "r",
        "block": "minecraft:air"
      },
      {
        "char": "J",
        "block": "minecraft:air"
      },
      {
        "char": "开",
        "block": "minecraft:air",
        "tag": {
          "SpawnData": {
            "entity": {}
          },
          "MaxNearbyEntities": "6s",
          "MinSpawnDelay": "200s",
          "z": 387,
          "x": 24,
          "MaxSpawnDelay": "800s",
          "RequiredPlayerRange": "16s",
          "SpawnCount": "4s",
          "ForgeCaps": {},
          "id": "minecraft:mob_spawner",
          "SpawnPotentials": [],
          "y": 132,
          "SpawnRange": "4s",
          "Delay": "584s"
        }
      },
      {
        "char": "I",
        "block": "minecraft:air"
      },
      {
        "char": "多",
        "block": "minecraft:air"
      },
      {
        "char": "q",
        "block": "minecraft:grass"
      },
      {
        "char": "动",
        "block": "minecraft:tall_grass[half=lower]"
      },
      {
        "char": "水",
        "block": "minecraft:air"
      },
      {
        "char": "园",
        "block": "minecraft:air"
      },
      {
        "char": "博",
        "block": "minecraft:air"
      },
      {
        "char": "u",
        "block": "minecraft:air"
      },
      {
        "char": "与",
        "block": "minecraft:air"
      },
      {
        "char": "千",
        "block": "minecraft:air"
      },
      {
        "char": "N",
        "block": "minecraft:air"
      },
      {
        "char": "龙",
        "block": "minecraft:tall_grass[half=upper]"
      },
      {
        "char": "杀",
        "block": "minecraft:air"
      },
      {
        "char": "Ҫ",
        "block": "minecraft:air"
      },
      {
        "char": "L",
        "block": "minecraft:air"
      },
      {
        "char": "问",
        "block": "minecraft:air"
      },
      {
        "char": "比",
        "block": "minecraft:air"
      },
      {
        "char": "度",
        "block": "minecraft:air"
      },
      {
        "char": "版",
        "block": "minecraft:air"
      },
      {
        "char": "林",
        "block": "minecraft:air"
      },
      {
        "char": "没",
        "block": "minecraft:air"
      },
      {
        "char": "跟",
        "block": "minecraft:air"
      },
      {
        "char": "空",
        "block": "minecraft:air"
      }
    ]
  },
  "slices": [
    [
      "cckcbdbaasbrrrcc",
      "brdbadadkJkrrrab",
      "baakdadbbsarrr开c",
      "dcksssJssJarrrcd",
      "cbckkradksbrrrkd",
      "acbcrbaabJbrIrak",
      "rkddacckbsbrrrca",
      "rbbsssssssarrrbb",
      "kkakdaacasbrrrbc",
      "dkaaackakscrrrad",
      "dbbadbcdcsarrr开b",
      "cbdJsssssJdrrrak",
      "bcdrddaccJarrrad",
      "bkckkradbscrrrbb",
      "kkbacrkkbsbrrraa",
      "dccsssssss开rIrab"
    ],
    [
      "          多qqq多 ",
      " q        多qqq多 ",
      "          多q动动多 ",
      "q         多水园动多 ",
      "          多q博水多 ",
      "    q  q  u水与q多 ",
      "q         多qqq多 ",
      "q         多q水水多 ",
      "          多qqq多 ",
      "          多qq动多 ",
      "         q多千qq多 ",
      "         N多qqq多 ",
      "   q      多q动q多 ",
      "     q    多qqq多 ",
      "     q    多qqq多 ",
      "          多水与qu "
    ],
    [
      "                ",
      "                ",
      "            龙龙  ",
      "             龙  ",
      "                ",
      "            与   ",
      "                ",
      "                ",
      "                ",
      "             龙  ",
      "           杀    ",
      "         N      ",
      "            龙   ",
      "           ҪLҪ  ",
      "          ҪL问LҪ ",
      "          L问与问L "
    ],
    [
      "                ",
      "                ",
      "                ",
      "                ",
      "                ",
      "            与   ",
      "                ",
      "                ",
      "                ",
      "                ",
      "                ",
      "         N      ",
      "                ",
      "          比ҪLҪ比 ",
      "          ҪL问LҪ ",
      "          L问与问L "
    ],
    [
      "                ",
      "                ",
      "                ",
      "           ҪLҪ比 ",
      "          ҪL问LҪ ",
      "          L问与问L ",
      "          ҪL问LҪ ",
      "           ҪLҪ  ",
      "                ",
      "                ",
      "                ",
      "         N      ",
      "                ",
      "                ",
      "           L问   ",
      "           问与问  "
    ],
    [
      "        度 度     ",
      "                ",
      "                ",
      "           ҪLҪ  ",
      "          ҪL问LҪ ",
      "          L问与问L ",
      "          ҪL问LҪ ",
      "           ҪLҪ  ",
      "                ",
      "                ",
      "        版 版     ",
      "       林没跟没空    ",
      "        度 度     ",
      "                ",
      "            L   ",
      "           L问L  "
    ]
  ]
}