{
  "xsize": 16,
  "zsize": 16,
  "palette": {
    "palette": [
      {
        "char": " ",
        "block": "minecraft:air"
      },
      {
        "char": "c",
        "block": "minecraft:air"
      },
      {
        "char": "J",
        "block": "minecraft:air"
      },
      {
        "char": "a",
        "block": "minecraft:air"
      },
      {
        "char": "d",
        "block": "minecraft:air"
      },
      {
        "char": "r",
        "block": "minecraft:air"
      },
      {
        "char": "e",
        "block": "minecraft:air"
      },
      {
        "char": "k",
        "block": "minecraft:air"
      },
      {
        "char": "b",
        "block": "minecraft:air"
      },
      {
        "char": "s",
        "block": "minecraft:air"
      },
      {
        "char": "y",
        "block": "minecraft:air"
      },
      {
        "char": "p",
        "block": "minecraft:air"
      },
      {
        "char": "o",
        "block": "minecraft:air"
      },
      {
        "char": "f",
        "block": "minecraft:air"
      },
      {
        "char": "q",
        "block": "minecraft:grass"
      },
      {
        "char": "提",
        "block": "minecraft:air"
      },
      {
        "char": "之",
        "block": "minecraft:air"
      },
      {
        "char": "任",
        "block": "minecraft:air"
      },
      {
        "char": "说",
        "block": "minecraft:air"
      },
      {
        "char": "魔",
        "block": "minecraft:air",
        "tag": {
          "z": 402,
          "x": 59,
          "ForgeData": {
            "LockFlag": "1b"
          },
          "ForgeCaps": {},
          "id": "minecraft:barrel",
          "y": 134,
          "Items": []
        }
      },
      {
        "char": "猫",
        "block": "minecraft:air"
      },
      {
        "char": "h",
        "block": "minecraft:air"
      },
      {
        "char": "形",
        "block": "minecraft:air"
      },
      {
        "char": "专",
        "block": "minecraft:air"
      },
      {
        "char": "般",
        "block": "minecraft:air"
      },
      {
        "char": "边",
        "block": "minecraft:air"
      }
    ]
  },
  "slices": [
    [
      "cJadadreeekcacbk",
      "Jscbakabkabckcbr",
      "bsrdbadkbadakkbk",
      "ssabbkbarbacckak",
      "kskbdckrkbkcdkac",
      "sJabbkaabkcbdrkk",
      "rskabddbdddkrkbk",
      "Jskckkbckbddcadk",
      "ksbbbkacdddbakda",
      "sssJsssssssJsssJ",
      "srcskdscksdbsddJ",
      "ksccsacJcrsbbsbd",
      "drsdaJbbsddsdasc",
      "sbksbdsabsdcscrs",
      "sssssssssssssssJ",
      "beaecycpepyofpee"
    ],
    [
      "      q   提 提   ",
      "          之 之  q",
      "  q   q   提提提   ",
      "    q   任       ",
      "       q        ",
      "             q  ",
      "                ",
      "        q       ",
      "                ",
      "         q      ",
      "                ",
      "         q      ",
      " q              ",
      "              q ",
      "                ",
      "                "
    ],
    [
      "          说说说   ",
      "          说说说   ",
      "          说魔说   ",
      "                ",
      "                ",
      "                ",
      "                ",
      "                ",
      "                ",
      "                ",
      "                ",
      "                ",
      "                ",
      "                ",
      "                ",
      "                "
    ],
    [
      "          猫 猫   ",
      "          说h说   ",
      "          说形说   ",
      "                ",
      "                ",
      "                ",
      "                ",
      "                ",
      "                ",
      "                ",
      "                ",
      "                ",
      "                ",
      "                ",
      "                ",
      "                "
    ],
    [
      "          专般形   ",
      "          专边形   ",
      "                ",
      "                ",
      "                ",
      "                ",
      "                ",
      "                ",
      "                ",
      "                ",
      "                ",
      "                ",
      "                ",
      "                ",
      "                ",
      "                "
    ],
    [
      "                ",
      "                ",
      "                ",
      "                ",
      "                ",
      "                ",
      "                ",
      "                ",
      "                ",
      "                ",
      "                ",
      "                ",
      "                ",
      "                ",
      "                ",
      "                "
    ]
  ]
}