{
  "xsize": 16,
  "zsize": 16,
  "palette": {
    "palette": [
      {
        "char": " ",
        "block": "minecraft:air"
      },
      {
        "char": "d",
        "block": "minecraft:air"
      },
      {
        "char": "b",
        "block": "minecraft:air"
      },
      {
        "char": "c",
        "block": "minecraft:air"
      },
      {
        "char": "k",
        "block": "minecraft:air"
      },
      {
        "char": "r",
        "block": "minecraft:air"
      },
      {
        "char": "J",
        "block": "minecraft:air"
      },
      {
        "char": "a",
        "block": "minecraft:air"
      },
      {
        "char": "s",
        "block": "minecraft:air"
      },
      {
        "char": "开",
        "block": "minecraft:air",
        "tag": {
          "SpawnData": {
            "entity": {}
          },
          "MaxNearbyEntities": "6s",
          "MinSpawnDelay": "200s",
          "z": 387,
          "x": 24,
          "MaxSpawnDelay": "800s",
          "RequiredPlayerRange": "16s",
          "SpawnCount": "4s",
          "ForgeCaps": {},
          "id": "minecraft:mob_spawner",
          "SpawnPotentials": [],
          "y": 132,
          "SpawnRange": "4s",
          "Delay": "584s"
        }
      },
      {
        "char": "p",
        "block": "minecraft:air"
      },
      {
        "char": "e",
        "block": "minecraft:air"
      },
      {
        "char": "f",
        "block": "minecraft:air"
      },
      {
        "char": "o",
        "block": "minecraft:air"
      },
      {
        "char": "I",
        "block": "minecraft:air"
      },
      {
        "char": "多",
        "block": "minecraft:air"
      },
      {
        "char": "q",
        "block": "minecraft:grass"
      },
      {
        "char": "水",
        "block": "minecraft:air"
      },
      {
        "char": "与",
        "block": "minecraft:air"
      },
      {
        "char": "动",
        "block": "minecraft:tall_grass[half=lower]"
      },
      {
        "char": "N",
        "block": "minecraft:air"
      },
      {
        "char": "千",
        "block": "minecraft:air"
      },
      {
        "char": "u",
        "block": "minecraft:air"
      },
      {
        "char": "比",
        "block": "minecraft:air"
      },
      {
        "char": "Ҫ",
        "block": "minecraft:air"
      },
      {
        "char": "L",
        "block": "minecraft:air"
      },
      {
        "char": "问",
        "block": "minecraft:air"
      },
      {
        "char": "龙",
        "block": "minecraft:tall_grass[half=upper]"
      },
      {
        "char": "杀",
        "block": "minecraft:air"
      },
      {
        "char": "气",
        "block": "minecraft:air"
      },
      {
        "char": "度",
        "block": "minecraft:air"
      },
      {
        "char": "版",
        "block": "minecraft:air"
      },
      {
        "char": "林",
        "block": "minecraft:air"
      },
      {
        "char": "没",
        "block": "minecraft:air"
      },
      {
        "char": "跟",
        "block": "minecraft:air"
      },
      {
        "char": "空",
        "block": "minecraft:air"
      }
    ]
  },
  "slices": [
    [
      "dbcddckrrrcJdadc",
      "bbcckbbrrrasbaac",
      "kckakcarrrkskkdd",
      "cbkaccdrrraJJsss",
      "kcbkcddrrrasdcbd",
      "dckdkrdr开rcscccb",
      "kbkdkkcrrraskkkk",
      "kdkakbarrrbsJJsJ",
      "bkdbkcarrrbsaccc",
      "aaaddbbrrrksrbda",
      "kkaddckrrrcsakdd",
      "dddckkkrrrdJssss",
      "dbbadkcrrrdskbdd",
      "paedfbbrrrksckak",
      "obpkfbcrrrbsckbd",
      "ekpbodarIrcJssss"
    ],
    [
      "      多qqq多     ",
      "   q  多qq 多     ",
      "      多qqq多     ",
      "      多qqq多     ",
      "      多qqq多     ",
      " q   q多水与水多     ",
      "      多qqq多     ",
      "      多qqq多     ",
      "      多qq动多     ",
      "      多q动q多 q   ",
      "      多qqq多     ",
      "      多q动q多Nq   ",
      "      多q水千多     ",
      "      多水水水多     ",
      "      多q水动多水q q ",
      "      uq与qu水    "
    ],
    [
      "                ",
      "                ",
      "                ",
      "      比ҪLҪ比     ",
      "      ҪL问LҪ     ",
      "      L问与问L     ",
      "      ҪL问LҪ     ",
      "       ҪLҪ      ",
      "         龙      ",
      "        龙       ",
      "                ",
      "        龙  N    ",
      "         杀      ",
      "                ",
      "         龙      ",
      "        与       "
    ],
    [
      "                ",
      "                ",
      "                ",
      "       ҪLҪ      ",
      "      ҪL问LҪ     ",
      "      L问与问L     ",
      "      ҪL问LҪ     ",
      "      比ҪLҪ比     ",
      "                ",
      "                ",
      "                ",
      "           N    ",
      "                ",
      "                ",
      "                ",
      "        与       "
    ],
    [
      "                ",
      "                ",
      "                ",
      "                ",
      "        问L      ",
      "       问与问      ",
      "        问       ",
      "                ",
      "                ",
      "                ",
      "                ",
      "           N    ",
      "                ",
      "         问      ",
      "        问气问     ",
      "        与问      "
    ],
    [
      "          度 度   ",
      "                ",
      "                ",
      "                ",
      "        L       ",
      "       L问L      ",
      "        L       ",
      "                ",
      "                ",
      "                ",
      "          版 版   ",
      "         林没跟没空  ",
      "        ҪҪ度 度   ",
      "       ҪLLҪ比    ",
      "       L问问LҪ    ",
      "       问与问LҪ    "
    ]
  ]
}