{
  "xsize": 16,
  "zsize": 16,
  "palette": {
    "palette": [
      {
        "char": " ",
        "block": "minecraft:air"
      },
      {
        "char": "m",
        "block": "minecraft:vine[east=false,north=false,south=true,up=false,west=false]"
      },
      {
        "char": "性",
        "block": "minecraft:vine[east=false,north=false,south=true,up=false,west=true]"
      },
      {
        "char": "e",
        "block": "minecraft:smooth_quartz"
      },
      {
        "char": "f",
        "block": "minecraft:polished_diorite"
      },
      {
        "char": "g",
        "block": "minecraft:blue_concrete"
      },
      {
        "char": "D",
        "block": "minecraft:cracked_stone_bricks"
      },
      {
        "char": "C",
        "block": "minecraft:mossy_cobblestone"
      },
      {
        "char": "o",
        "block": "minecraft:quartz_block"
      },
      {
        "char": "y",
        "block": "minecraft:quartz_pillar[axis=y]"
      },
      {
        "char": "p",
        "block": "minecraft:diorite"
      },
      {
        "char": "i",
        "block": "minecraft:vine[east=false,north=true,south=false,up=false,west=false]"
      },
      {
        "char": "H",
        "block": "minecraft:cobblestone[weathering=false]"
      },
      {
        "char": "E",
        "block": "minecraft:stone_bricks[weathering=false]"
      },
      {
        "char": "z",
        "block": "minecraft:mossy_stone_bricks"
      },
      {
        "char": "u",
        "block": "minecraft:smooth_quartz_slab[type=bottom,waterlogged=false]"
      },
      {
        "char": "数",
        "block": "minecraft:vine[east=false,north=false,south=true,up=true,west=false]"
      },
      {
        "char": "天",
        "block": "minecraft:stone_slab[type=double,waterlogged=false,weathering=false]"
      },
      {
        "char": "受",
        "block": "minecraft:vine[east=false,north=true,south=false,up=true,west=false]"
      },
      {
        "char": "v",
        "block": "minecraft:vine[east=false,north=false,south=false,up=true,west=false]"
      },
      {
        "char": "t",
        "block": "minecraft:stone_slab[type=bottom,waterlogged=false,weathering=false]"
      },
      {
        "char": "他",
        "block": "minecraft:air"
      }
    ]
  },
  "slices": [
    [
      "                ",
      "        m  mmmm ",
      "性m m mmme mf  fm",
      "gggggggggggggggg",
      "gggggggggggggggg",
      "gggggggggggggggg",
      "gggggggggggggggg",
      "gDgggggggDgggggg",
      "fCofyoyooCoyefop",
      " iiiii iiiiiiiii",
      "                ",
      "                ",
      "                ",
      "                ",
      "                ",
      "                "
    ],
    [
      "                ",
      "        m   mmm ",
      "性m m mmmf m feem",
      "gggggggggggggggg",
      "gggggggggggggggg",
      "gggggggggggggggg",
      "gggggggggggggggg",
      "gDgggggggCgggggg",
      "fHyepffpeEeeeeef",
      " ii ii iiiiii ii",
      "                ",
      "                ",
      "                ",
      "                ",
      "                ",
      "                "
    ],
    [
      "                ",
      "        m    mm ",
      "性m   mm f me  pm",
      "gggggggggggggggg",
      "gggggggggggggggg",
      "gggggggggggggggg",
      "gggggggggggggggg",
      "gDgggggggzgggggg",
      "yDfepofyfHoeefpf",
      " ii  i iiiiii ii",
      "                ",
      "                ",
      "                ",
      "                ",
      "                ",
      "                "
    ],
    [
      "                ",
      "        m    m  ",
      "性m   m pfpm ofum",
      "gggggggggggggggg",
      "gggggggggggggggg",
      "gggggggggggggggg",
      "gggggggggggggggg",
      "gDgggggggzgggggg",
      "fHefeeeyeCppefoe",
      " ii  i   iiii  i",
      "                ",
      "                ",
      "                ",
      "                ",
      "                ",
      "                "
    ],
    [
      "                ",
      "                ",
      "性m     mmmm  m m",
      "gggggggggggggggg",
      "gggggggggggggggg",
      "gggggggggggggggg",
      "gggggggggggggggg",
      "gCgggggggEgggggg",
      "eCfofyfpeEppeyfe",
      "  i       iii   ",
      "                ",
      "                ",
      "                ",
      "                ",
      "                ",
      "                "
    ],
    [
      "                ",
      "                ",
      "性m     mmmm  数  ",
      "gggggggggggggggg",
      "gggggggggggggggg",
      "gggggggggggggggg",
      "gggggggggggggggg",
      "gzgggggggEgggggg",
      "yEpfyeoyfCeopeyf",
      " 天       天受受受  v",
      " t  vv   t   v  ",
      " t   vv  他      ",
      " t  v   v他 v vv ",
      " 他  v  v t      ",
      "v他  v    t      ",
      " t       t      "
    ]
  ]
}