{
  "xsize": 16,
  "zsize": 16,
  "palette": {
    "palette": [
      {
        "char": " ",
        "block": "minecraft:air"
      },
      {
        "char": "b",
        "block": "minecraft:basalt[axis=x]"
      },
      {
        "char": "a",
        "block": "minecraft:cyan_terracotta"
      },
      {
        "char": "c",
        "block": "minecraft:cobbled_deepslate"
      },
      {
        "char": "k",
        "block": "minecraft:blackstone"
      },
      {
        "char": "d",
        "block": "minecraft:deepslate[axis=y]"
      },
      {
        "char": "r",
        "block": "minecraft:grass_block[snowy=false]"
      },
      {
        "char": "I",
        "block": "minecraft:dirt"
      },
      {
        "char": "Ҩ",
        "block": "minecraft:cobblestone_slab[type=top,waterlogged=false,weathering=false]"
      },
      {
        "char": "n",
        "block": "minecraft:oak_slab[type=top,waterlogged=false]"
      },
      {
        "char": "q",
        "block": "minecraft:air"
      },
      {
        "char": "活",
        "block": "minecraft:stone_button[face=wall,facing=west,powered=false]"
      },
      {
        "char": "之",
        "block": "minecraft:black_concrete"
      },
      {
        "char": "义",
        "block": "minecraft:stone_button[face=wall,facing=east,powered=false]"
      },
      {
        "char": "备",
        "block": "minecraft:dandelion"
      },
      {
        "char": "动",
        "block": "minecraft:air"
      },
      {
        "char": "社",
        "block": "minecraft:spruce_stairs[facing=south,half=top,shape=straight,waterlogged=false]"
      },
      {
        "char": "Ҭ",
        "block": "minecraft:smooth_stone_slab[type=bottom,waterlogged=false]"
      },
      {
        "char": "龙",
        "block": "minecraft:air"
      },
      {
        "char": "Ү",
        "block": "minecraft:sand"
      }
    ]
  },
  "slices": [
    [
      "bbaackkaabbcdrdb",
      "bddkkbcackkbrrca",
      "rccddackcIckIrkb",
      "akcbkcckdccaarca",
      "bcaraccabkbdcdrd",
      "ckadkcdkbIckIdra",
      "bkkbkaabdkkarcbr",
      "dakkbdadcdcbrbbr",
      "cbdkkakabcrarbrk",
      "cdabbbadkbrrrarc",
      "kbdkabacbakrccra",
      "bkdbcakbkkbraabd",
      "ccbcaaarbkrradcr",
      "cdkbcrdbbbrackar",
      "ddddbbdadbraddrd",
      "crrdddrkcbrkcdcb"
    ],
    [
      "         ҨnnҨq  ",
      "         ҨnnҨq  ",
      "q       活之nn之义  ",
      "         ҨnnҨ备  ",
      "       q ҨnnҨ q ",
      " q      活之ҨҨ之 q ",
      "            q  q",
      "            q  q",
      "          q q q ",
      "  q       q q   ",
      "           q  q ",
      "           q    ",
      "           q   q",
      "     q    q    q",
      "          q   q ",
      " q动   q   q     "
    ],
    [
      "          社社社   ",
      "                ",
      "         Ҭ  Ҭ   ",
      "                ",
      "                ",
      "         Ҭ  Ҭ   ",
      "                ",
      "                ",
      "                ",
      "                ",
      "                ",
      "                ",
      "                ",
      "                ",
      "                ",
      "  龙             "
    ],
    [
      "          ҮҮҮ   ",
      "                ",
      "                ",
      "                ",
      "                ",
      "                ",
      "                ",
      "                ",
      "                ",
      "                ",
      "                ",
      "                ",
      "                ",
      "                ",
      "                ",
      "                "
    ],
    [
      "          ҮҮҮ   ",
      "                ",
      "                ",
      "                ",
      "                ",
      "                ",
      "                ",
      "                ",
      "                ",
      "                ",
      "                ",
      "                ",
      "                ",
      "                ",
      "                ",
      "                "
    ],
    [
      "                ",
      "                ",
      "                ",
      "                ",
      "                ",
      "                ",
      "                ",
      "                ",
      "                ",
      "                ",
      "                ",
      "                ",
      "                ",
      "                ",
      "                ",
      "                "
    ]
  ]
}