{
  "xsize": 16,
  "zsize": 16,
  "palette": {
    "palette": [
      {
        "char": " ",
        "block": "minecraft:air"
      },
      {
        "char": "s",
        "block": "minecraft:yellow_concrete"
      },
      {
        "char": "k",
        "block": "minecraft:blackstone"
      },
      {
        "char": "d",
        "block": "minecraft:deepslate[axis=y]"
      },
      {
        "char": "c",
        "block": "minecraft:cobbled_deepslate"
      },
      {
        "char": "b",
        "block": "minecraft:basalt[axis=x]"
      },
      {
        "char": "r",
        "block": "minecraft:grass_block[snowy=false]"
      },
      {
        "char": "a",
        "block": "minecraft:cyan_terracotta"
      },
      {
        "char": "J",
        "block": "minecraft:yellow_terracotta"
      },
      {
        "char": "f",
        "block": "minecraft:polished_diorite"
      },
      {
        "char": "q",
        "block": "minecraft:air"
      },
      {
        "char": "任",
        "block": "minecraft:azure_bluet"
      },
      {
        "char": "N",
        "block": "minecraft:cobblestone_wall[east=none,north=none,south=none,up=true,waterlogged=false,weathering=false,west=none]"
      },
      {
        "char": "提",
        "block": "minecraft:smooth_stone_slab[type=top,waterlogged=false]"
      },
      {
        "char": "报",
        "block": "minecraft:air"
      },
      {
        "char": "之",
        "block": "minecraft:black_concrete"
      },
      {
        "char": "极",
        "block": "minecraft:air"
      },
      {
        "char": "说",
        "block": "minecraft:air"
      },
      {
        "char": "脑",
        "block": "minecraft:air"
      },
      {
        "char": "介",
        "block": "minecraft:white_stained_glass_pane[east=true,north=false,south=true,waterlogged=false,west=false]"
      },
      {
        "char": "元",
        "block": "minecraft:white_stained_glass_pane[east=true,north=false,south=false,waterlogged=false,west=true]"
      },
      {
        "char": "段",
        "block": "minecraft:white_stained_glass_pane[east=false,north=false,south=true,waterlogged=false,west=true]"
      },
      {
        "char": "专",
        "block": "minecraft:air"
      },
      {
        "char": "形",
        "block": "minecraft:air"
      },
      {
        "char": "般",
        "block": "minecraft:air"
      },
      {
        "char": "边",
        "block": "minecraft:air"
      },
      {
        "char": "度",
        "block": "minecraft:oak_trapdoor[facing=south,half=top,open=true,powered=false,waterlogged=false]"
      },
      {
        "char": "版",
        "block": "minecraft:oak_trapdoor[facing=north,half=top,open=true,powered=false,waterlogged=false]"
      },
      {
        "char": "跟",
        "block": "minecraft:cobblestone_wall[east=low,north=none,south=none,up=true,waterlogged=false,weathering=false,west=low]"
      },
      {
        "char": "没",
        "block": "minecraft:redstone_lamp[lit=false]"
      },
      {
        "char": "空",
        "block": "minecraft:oak_trapdoor[facing=east,half=top,open=true,powered=false,waterlogged=false]"
      }
    ]
  },
  "slices": [
    [
      "skddcbkdbbkckbdc",
      "sdckddkdcbkrkkdd",
      "sbkkdarccdbadcdb",
      "sssssssdbcarbabs",
      "Jaadddaabadrdabc",
      "sddbcdbccddcckkc",
      "Jcacddcbbaakbrrc",
      "Jsssssskkrkabcks",
      "scaaaabackdrkbbd",
      "scbbaddkbrcaabab",
      "sacdbbcckcbaadda",
      "sJsssssdacabcdks",
      "Jkbackdkakaabccc",
      "sbarbadkabaddrba",
      "sbcaakcbccdaccab",
      "ssssssskbafkkaks"
    ],
    [
      "                ",
      "                ",
      "      q       q ",
      "        q  q    ",
      "           q    ",
      "                ",
      "             qq ",
      "         q      ",
      "           q    ",
      "         任      ",
      "                ",
      "N               ",
      "                ",
      "   q      提提提q  ",
      "         报之 之   ",
      "q       报极提 提   "
    ],
    [
      "                ",
      "                ",
      "                ",
      "                ",
      "                ",
      "                ",
      "                ",
      "                ",
      "                ",
      "                ",
      "                ",
      "N               ",
      "                ",
      "          说说说   ",
      "          说说说   ",
      "          说说说   "
    ],
    [
      "                ",
      "                ",
      "                ",
      "                ",
      "                ",
      "                ",
      "                ",
      "                ",
      "                ",
      "                ",
      "                ",
      "N               ",
      "                ",
      "           脑    ",
      "          介元段   ",
      "          说 说   "
    ],
    [
      "                ",
      "                ",
      "                ",
      "                ",
      "                ",
      "                ",
      "                ",
      "                ",
      "                ",
      "                ",
      "                ",
      "N               ",
      "                ",
      "                ",
      "          专形形   ",
      "          专般边   "
    ],
    [
      " 度              ",
      "                ",
      "                ",
      "                ",
      "                ",
      "                ",
      "                ",
      "                ",
      "                ",
      "                ",
      " 版              ",
      "跟没空             ",
      " 度              ",
      "                ",
      "                ",
      "                "
    ]
  ]
}