{
  "xsize": 16,
  "zsize": 16,
  "palette": {
    "palette": [
      {
        "char": " ",
        "block": "minecraft:air"
      },
      {
        "char": "e",
        "block": "minecraft:smooth_quartz"
      },
      {
        "char": "f",
        "block": "minecraft:polished_diorite"
      },
      {
        "char": "o",
        "block": "minecraft:quartz_block"
      },
      {
        "char": "E",
        "block": "minecraft:stone_bricks[weathering=false]"
      },
      {
        "char": "i",
        "block": "minecraft:vine[east=false,north=true,south=false,up=false,west=false]"
      },
      {
        "char": "请",
        "block": "minecraft:vine[east=false,north=true,south=false,up=false,west=true]"
      },
      {
        "char": "O",
        "block": "minecraft:dark_oak_fence[east=false,north=false,south=false,waterlogged=false,west=false]"
      },
      {
        "char": "m",
        "block": "minecraft:vine[east=false,north=false,south=true,up=false,west=false]"
      },
      {
        "char": "l",
        "block": "minecraft:vine[east=true,north=false,south=false,up=false,west=false]"
      },
      {
        "char": "g",
        "block": "minecraft:blue_concrete"
      },
      {
        "char": "j",
        "block": "minecraft:vine[east=false,north=false,south=false,up=false,west=true]"
      },
      {
        "char": "y",
        "block": "minecraft:quartz_pillar[axis=y]"
      },
      {
        "char": "p",
        "block": "minecraft:diorite"
      },
      {
        "char": "D",
        "block": "minecraft:cracked_stone_bricks"
      },
      {
        "char": "z",
        "block": "minecraft:mossy_stone_bricks"
      },
      {
        "char": "C",
        "block": "minecraft:mossy_cobblestone"
      },
      {
        "char": "天",
        "block": "minecraft:stone_slab[type=double,waterlogged=false,weathering=false]"
      },
      {
        "char": "t",
        "block": "minecraft:stone_slab[type=bottom,waterlogged=false,weathering=false]"
      },
      {
        "char": "拉",
        "block": "minecraft:vine[east=false,north=true,south=false,up=true,west=true]"
      },
      {
        "char": "受",
        "block": "minecraft:vine[east=false,north=true,south=false,up=true,west=false]"
      },
      {
        "char": "怪",
        "block": "minecraft:air"
      },
      {
        "char": "他",
        "block": "minecraft:air"
      },
      {
        "char": "v",
        "block": "minecraft:vine[east=false,north=false,south=false,up=true,west=false]"
      }
    ]
  },
  "slices": [
    [
      "eeefoeeefE      ",
      "ii 请ii  i       ",
      "                ",
      "     O         O",
      "                ",
      "                ",
      "                ",
      "     O         O",
      "                ",
      "                ",
      "                ",
      "                ",
      "                ",
      "                ",
      " m    m         ",
      "lgj  lgj    mm m"
    ],
    [
      "fooyyeofyE      ",
      "ii 请ii  i       ",
      "                ",
      "     O         O",
      "                ",
      "                ",
      "                ",
      "     O         O",
      "                ",
      "                ",
      "                ",
      "                ",
      "                ",
      "                ",
      " m    m         ",
      "lgj  lgj        "
    ],
    [
      "eefefepyyD      ",
      "ii 请ii  i       ",
      "                ",
      "     O         O",
      "                ",
      "                ",
      "                ",
      "     O         O",
      "                ",
      "                ",
      "                ",
      "                ",
      "                ",
      "                ",
      " m    m         ",
      " gj  lg         "
    ],
    [
      "oeeoppppez      ",
      "ii 请ii  i       ",
      "                ",
      "     O         O",
      "                ",
      "                ",
      "                ",
      "     O         O",
      "                ",
      "                ",
      "                ",
      "                ",
      "                ",
      "                ",
      "                ",
      "                "
    ],
    [
      "oyeofooyyE      ",
      "   请ii  i       ",
      "                ",
      "     O         O",
      "                ",
      "                ",
      "                ",
      "     O         O",
      "                ",
      "                ",
      "                ",
      "                ",
      "                ",
      "                ",
      "                ",
      "                "
    ],
    [
      "fyeofeoppC天ttttt",
      "  天拉受    怪      ",
      "  t      他    v ",
      " vt  Ov  他    vO",
      " vt  v  v他 v  v ",
      "  t      t      ",
      "  t      t  v   ",
      "  t  O   t     O",
      "tt天tttttt天tttttt",
      "  t      t      ",
      "  t  v   t      ",
      "  他v v v t vvv  ",
      "v 他v    vtv   v ",
      "  t  v v t   v  ",
      "  t  v   t      ",
      "  t      t      "
    ]
  ]
}