{
  "xsize": 16,
  "zsize": 16,
  "palette": {
    "palette": [
      {
        "char": " ",
        "block": "minecraft:air"
      },
      {
        "char": "b",
        "block": "minecraft:air"
      },
      {
        "char": "k",
        "block": "minecraft:air"
      },
      {
        "char": "a",
        "block": "minecraft:air"
      },
      {
        "char": "r",
        "block": "minecraft:air"
      },
      {
        "char": "d",
        "block": "minecraft:air"
      },
      {
        "char": "c",
        "block": "minecraft:air"
      },
      {
        "char": "y",
        "block": "minecraft:air"
      },
      {
        "char": "p",
        "block": "minecraft:air"
      },
      {
        "char": "f",
        "block": "minecraft:air"
      },
      {
        "char": "I",
        "block": "minecraft:air"
      },
      {
        "char": "s",
        "block": "minecraft:air"
      },
      {
        "char": "J",
        "block": "minecraft:air"
      },
      {
        "char": "动",
        "block": "minecraft:tall_grass[half=lower]"
      },
      {
        "char": "q",
        "block": "minecraft:grass"
      },
      {
        "char": "水",
        "block": "minecraft:air"
      },
      {
        "char": "u",
        "block": "minecraft:air"
      },
      {
        "char": "多",
        "block": "minecraft:air"
      },
      {
        "char": "与",
        "block": "minecraft:air"
      },
      {
        "char": "N",
        "block": "minecraft:air"
      },
      {
        "char": "龙",
        "block": "minecraft:tall_grass[half=upper]"
      },
      {
        "char": "Ҫ",
        "block": "minecraft:air"
      },
      {
        "char": "L",
        "block": "minecraft:air"
      },
      {
        "char": "比",
        "block": "minecraft:air"
      },
      {
        "char": "问",
        "block": "minecraft:air"
      },
      {
        "char": "版",
        "block": "minecraft:air"
      },
      {
        "char": "林",
        "block": "minecraft:air"
      },
      {
        "char": "没",
        "block": "minecraft:air"
      },
      {
        "char": "跟",
        "block": "minecraft:air"
      },
      {
        "char": "空",
        "block": "minecraft:air"
      }
    ]
  },
  "slices": [
    [
      "bbkkbaardcbbrkbb",
      "ckbkkaackacbddck",
      "kdccrcdacdkackkc",
      "dkabdcrdaccbkcbc",
      "daarbbkadkkddkbd",
      "cbycrkbbaccbckca",
      "ckpbracbkaarddcb",
      "dcfacccccdaackda",
      "dddkakbddddbbkbd",
      "ddakkabkdabkdraa",
      "abckakbbcabdkkda",
      "cdkcracrIrassJJJ",
      "crcdbbcrrrksackk",
      "cdkackdrrrdJdbkr",
      "acbadcarrrcJkdbd",
      "kcadbadrrrdsssss"
    ],
    [
      "       动   qq   ",
      "  q 水           ",
      "    q           ",
      "      q         ",
      "  qq            ",
      "    动           ",
      "    q           ",
      "         q      ",
      "                ",
      "      水 水水水  q  ",
      "       uuu水     ",
      "      多水与水多     ",
      " q    多q q多     ",
      "      多水q水多    q",
      "      多  q多     ",
      "      多q q多N    "
    ],
    [
      "       龙        ",
      "                ",
      "                ",
      "                ",
      "                ",
      "    龙           ",
      "                ",
      "                ",
      "                ",
      "                ",
      "                ",
      "        与       ",
      "                ",
      "                ",
      "                ",
      "           N    "
    ],
    [
      "                ",
      "                ",
      "                ",
      "                ",
      "                ",
      "                ",
      "                ",
      "                ",
      "                ",
      "                ",
      "                ",
      "        与       ",
      "                ",
      "                ",
      "                ",
      "           N    "
    ],
    [
      "                ",
      "                ",
      "                ",
      "                ",
      "                ",
      "                ",
      "                ",
      "                ",
      "                ",
      "       ҪLҪ比     ",
      "      ҪL问LҪ     ",
      "      L问与问L     ",
      "      ҪL问LҪ     ",
      "      比ҪLҪ      ",
      "                ",
      "           N    "
    ],
    [
      "                ",
      "                ",
      "                ",
      "                ",
      "                ",
      "                ",
      "                ",
      "                ",
      "                ",
      "      比ҪLҪ      ",
      "      ҪL问LҪ     ",
      "      L问与问L     ",
      "      ҪL问LҪ     ",
      "       ҪLҪ比     ",
      "          版 版   ",
      "         林没跟没空  "
    ]
  ]
}