{
  "xsize": 16,
  "zsize": 16,
  "palette": {
    "palette": [
      {
        "char": " ",
        "block": "minecraft:air"
      },
      {
        "char": "s",
        "block": "minecraft:yellow_concrete"
      },
      {
        "char": "k",
        "block": "minecraft:blackstone"
      },
      {
        "char": "d",
        "block": "minecraft:deepslate[axis=y]"
      },
      {
        "char": "a",
        "block": "minecraft:cyan_terracotta"
      },
      {
        "char": "c",
        "block": "minecraft:cobbled_deepslate"
      },
      {
        "char": "b",
        "block": "minecraft:basalt[axis=x]"
      },
      {
        "char": "J",
        "block": "minecraft:yellow_terracotta"
      },
      {
        "char": "r",
        "block": "minecraft:grass_block[snowy=false]"
      },
      {
        "char": "q",
        "block": "minecraft:air"
      },
      {
        "char": "ү",
        "block": "minecraft:stone_slab[type=top,waterlogged=false,weathering=false]"
      },
      {
        "char": "码",
        "block": "minecraft:air"
      },
      {
        "char": "自",
        "block": "minecraft:smooth_quartz_slab[type=double,waterlogged=false]"
      },
      {
        "char": "调",
        "block": "minecraft:acacia_trapdoor[facing=east,half=top,open=true,powered=false,waterlogged=false]"
      },
      {
        "char": "m",
        "block": "minecraft:vine[east=false,north=false,south=true,up=false,west=false]"
      },
      {
        "char": "断",
        "block": "minecraft:acacia_trapdoor[facing=east,half=bottom,open=true,powered=false,waterlogged=false]"
      },
      {
        "char": "i",
        "block": "minecraft:vine[east=false,north=true,south=false,up=false,west=false]"
      }
    ]
  },
  "slices": [
    [
      "sssskdacbabddcba",
      "cdssakbbckacabbd",
      "aksJbdrdbkckbabd",
      "ddsJrbckakcadcbd",
      "bbssbcakdkcbdaad",
      "ddssacabaraadakb",
      "daJJdbdddcadcccc",
      "absJrccbacbrbbbb",
      "sJJsdcccbbacacda",
      "dbssabbdacaababr",
      "dkssacrcbabcdkak",
      "aaJsckbcadadbbca",
      "cdssbkbdrcadback",
      "adJsaabbaabaabbc",
      "sssskcdbddkdakdc",
      "rkcdkdkbradadbck"
    ],
    [
      "    q           ",
      "             q  ",
      "      qq        ",
      "    q           ",
      "ү               ",
      "ү    q   q      ",
      " q     q   q    ",
      "    q q    q    ",
      "    q           ",
      "               码",
      "      q        q",
      "      q      q  ",
      "        q       ",
      "       q        ",
      "   q            ",
      "q       q       "
    ],
    [
      "                ",
      "                ",
      "                ",
      "自               ",
      "自调              ",
      "自调              ",
      "自               ",
      "                ",
      "                ",
      "                ",
      "                ",
      "                ",
      "                ",
      "                ",
      "                ",
      "m               "
    ],
    [
      "                ",
      "                ",
      "                ",
      "                ",
      "自断              ",
      "自断              ",
      "i               ",
      "                ",
      "                ",
      "                ",
      "                ",
      "                ",
      "                ",
      "                ",
      "                ",
      "m               "
    ],
    [
      "                ",
      "                ",
      "                ",
      "                ",
      "                ",
      "                ",
      "                ",
      "                ",
      "                ",
      "                ",
      "                ",
      "                ",
      "                ",
      "                ",
      "                ",
      "m               "
    ],
    [
      "                ",
      "                ",
      "                ",
      "                ",
      "                ",
      "                ",
      "                ",
      "                ",
      "                ",
      "                ",
      "                ",
      "                ",
      "                ",
      "                ",
      "                ",
      "m               "
    ]
  ]
}