{
  "xsize": 16,
  "zsize": 16,
  "palette": {
    "palette": [
      {
        "char": " ",
        "block": "minecraft:air"
      },
      {
        "char": "m",
        "block": "minecraft:vine[east=false,north=false,south=true,up=false,west=false]"
      },
      {
        "char": "D",
        "block": "minecraft:cracked_stone_bricks"
      },
      {
        "char": "消",
        "block": "minecraft:air"
      },
      {
        "char": "B",
        "block": "minecraft:smooth_quartz_slab[type=top,waterlogged=false]"
      },
      {
        "char": "C",
        "block": "minecraft:mossy_cobblestone"
      },
      {
        "char": "l",
        "block": "minecraft:vine[east=true,north=false,south=false,up=false,west=false]"
      },
      {
        "char": "f",
        "block": "minecraft:polished_diorite"
      },
      {
        "char": "黑",
        "block": "minecraft:vine[east=false,north=false,south=true,up=true,west=true]"
      },
      {
        "char": "抓",
        "block": "minecraft:vine[east=true,north=false,south=true,up=true,west=false]"
      },
      {
        "char": "e",
        "block": "minecraft:smooth_quartz"
      },
      {
        "char": "u",
        "block": "minecraft:smooth_quartz_slab[type=bottom,waterlogged=false]"
      },
      {
        "char": "g",
        "block": "minecraft:blue_concrete"
      },
      {
        "char": "y",
        "block": "minecraft:quartz_pillar[axis=y]"
      },
      {
        "char": "自",
        "block": "minecraft:smooth_quartz_slab[type=double,waterlogged=false]"
      },
      {
        "char": "没",
        "block": "minecraft:redstone_lamp[lit=false]"
      },
      {
        "char": "数",
        "block": "minecraft:vine[east=false,north=false,south=true,up=true,west=false]"
      },
      {
        "char": "p",
        "block": "minecraft:diorite"
      },
      {
        "char": "O",
        "block": "minecraft:dark_oak_fence[east=false,north=false,south=false,waterlogged=false,west=false]"
      }
    ]
  },
  "slices": [
    [
      "   m            ",
      "                ",
      "            D   ",
      "                ",
      "                ",
      "                ",
      "                ",
      "                ",
      "              mm",
      "                ",
      "                ",
      "       消        ",
      "                ",
      "                ",
      "                ",
      "m      mmmm     "
    ],
    [
      "   m            ",
      "BBBBBBBBBBBBBB  ",
      "BBBBBBBBBBBBCB  ",
      "             B  ",
      "             B  ",
      "             B  ",
      "             B  ",
      "             B  ",
      "             Bmm",
      "             B  ",
      "             B  ",
      "             B  ",
      "             B  ",
      "             B  ",
      "             B  ",
      "m      mmmm  B  "
    ],
    [
      "   m            ",
      "  lf黑抓e    Bu   ",
      "gggyggegggg自u   ",
      "           Bu   ",
      "           Bu   ",
      " 没没没  没没没  Bu   ",
      "           Bu   ",
      "           Bu   ",
      "           Bummm",
      "           Bu   ",
      "           Bu   ",
      " 没没没  没没没  Bu   ",
      "           Bu   ",
      "           Bu   ",
      "           Bu   ",
      "       mmm数Bu   "
    ],
    [
      "                ",
      "B   ff   Bu     ",
      "自gggfpggg自u     ",
      "B        Bu     ",
      "B        Bu     ",
      "BO O  O OBu     ",
      "B        Bu     ",
      "B        Bu     ",
      "B        Bum mmm",
      "B        Bu     ",
      "B        Bu     ",
      "BO O  O OBu     ",
      "B        Bu     ",
      "B        Bu     ",
      "B        Bu     ",
      "B      m数Bu     "
    ],
    [
      "                ",
      " uB    Bu       ",
      " u自gggg自u       ",
      " uB    Bu       ",
      " uB    Bu       ",
      " uBO  OBu       ",
      " uB    Bu       ",
      " uB    Bu       ",
      "muB    Bum m mmm",
      " uB    Bu       ",
      " uB    Bu       ",
      " uBO  OBu       ",
      " uB    Bu       ",
      " uB    Bu       ",
      " uB    Bu       ",
      " uB    Bu       "
    ],
    [
      "                ",
      "   uBBu         ",
      "   u自自u         ",
      "   uBBu         ",
      "   uBBu         ",
      "   uBBu         ",
      "   uBBu         ",
      "   uBBu         ",
      "mmmuBBu mm m mmm",
      "   uBBu         ",
      "   uBBu         ",
      "   uBBu         ",
      "   uBBu         ",
      "   uBBu         ",
      "   uBBu         ",
      "   uBBu         "
    ]
  ]
}