{
  "xsize": 16,
  "zsize": 16,
  "palette": {
    "palette": [
      {
        "char": " ",
        "block": "minecraft:air"
      },
      {
        "char": "d",
        "block": "minecraft:air"
      },
      {
        "char": "k",
        "block": "minecraft:air"
      },
      {
        "char": "a",
        "block": "minecraft:air"
      },
      {
        "char": "c",
        "block": "minecraft:air"
      },
      {
        "char": "b",
        "block": "minecraft:air"
      },
      {
        "char": "r",
        "block": "minecraft:air"
      },
      {
        "char": "s",
        "block": "minecraft:air"
      },
      {
        "char": "J",
        "block": "minecraft:air"
      },
      {
        "char": "e",
        "block": "minecraft:air"
      },
      {
        "char": "f",
        "block": "minecraft:air"
      },
      {
        "char": "p",
        "block": "minecraft:air"
      },
      {
        "char": "l",
        "block": "minecraft:air"
      },
      {
        "char": "与",
        "block": "minecraft:air"
      },
      {
        "char": "ҫ",
        "block": "minecraft:air"
      },
      {
        "char": "j",
        "block": "minecraft:air"
      },
      {
        "char": "q",
        "block": "minecraft:grass"
      },
      {
        "char": "i",
        "block": "minecraft:air"
      },
      {
        "char": "实",
        "block": "minecraft:air"
      },
      {
        "char": "爱",
        "block": "minecraft:air"
      },
      {
        "char": "把",
        "block": "minecraft:air"
      },
      {
        "char": "讯",
        "block": "minecraft:air"
      },
      {
        "char": "H",
        "block": "minecraft:air"
      },
      {
        "char": "而",
        "block": "minecraft:air"
      },
      {
        "char": "线",
        "block": "minecraft:air"
      },
      {
        "char": "视",
        "block": "minecraft:air"
      }
    ]
  },
  "slices": [
    [
      "dkkaccakdbarbcab",
      "acdbdkcbdcddacdk",
      "ckaccaabbkacrbbc",
      "dbcbkkcdddkabcak",
      "adcadbaacbbccbak",
      "acacddkcbdkdbbrb",
      "kkkckbdbdadkbbcb",
      "aarcaackabdddadc",
      "kabccaacbbcddbrd",
      "dabbacbkbbbssJss",
      "badrbcbraksskdsd",
      "cdbcrbabbksasabs",
      "dbcckcdrbdscksdb",
      "ackbbbabcdsdbask",
      "bdbadabcddrsJssJ",
      "bcakkakdakbefepf"
    ],
    [
      "   l与ҫҫҫ与j q    ",
      "       ii      q",
      "            q   ",
      "                ",
      "实               ",
      "              q ",
      "                ",
      "                ",
      "              q ",
      "                ",
      "       q        ",
      "    q           ",
      "      qq        ",
      "                ",
      "          q     ",
      "                "
    ],
    [
      "   l与ҫ爱ҫ与j      ",
      "       ii       ",
      "                ",
      "                ",
      "                ",
      "                ",
      "                ",
      "                ",
      "                ",
      "                ",
      "                ",
      "                ",
      "                ",
      "                ",
      "                ",
      "                "
    ],
    [
      "   把与ҫҫҫ与j      ",
      "       ii       ",
      "                ",
      "                ",
      "                ",
      "                ",
      "                ",
      "                ",
      "                ",
      "                ",
      "                ",
      "                ",
      "                ",
      "                ",
      "                ",
      "                "
    ],
    [
      "   讯HҫҫҫH而      ",
      "   讯线   视而      ",
      "                ",
      "                ",
      "                ",
      "                ",
      "                ",
      "                ",
      "                ",
      "                ",
      "                ",
      "                ",
      "                ",
      "                ",
      "                ",
      "                "
    ],
    [
      "    讯HҫH而       ",
      "    讯线 视而       ",
      "                ",
      "                ",
      "                ",
      "                ",
      "                ",
      "                ",
      "                ",
      "                ",
      "                ",
      "                ",
      "                ",
      "                ",
      "                ",
      "                "
    ]
  ]
}