{
  "xsize": 16,
  "zsize": 16,
  "palette": {
    "palette": [
      {
        "char": " ",
        "block": "minecraft:air"
      },
      {
        "char": "c",
        "block": "minecraft:cobbled_deepslate"
      },
      {
        "char": "k",
        "block": "minecraft:blackstone"
      },
      {
        "char": "a",
        "block": "minecraft:cyan_terracotta"
      },
      {
        "char": "b",
        "block": "minecraft:basalt[axis=x]"
      },
      {
        "char": "r",
        "block": "minecraft:grass_block[snowy=false]"
      },
      {
        "char": "d",
        "block": "minecraft:deepslate[axis=y]"
      },
      {
        "char": "s",
        "block": "minecraft:yellow_concrete"
      },
      {
        "char": "J",
        "block": "minecraft:yellow_terracotta"
      },
      {
        "char": "q",
        "block": "minecraft:air"
      },
      {
        "char": "度",
        "block": "minecraft:oak_trapdoor[facing=south,half=top,open=true,powered=false,waterlogged=false]"
      },
      {
        "char": "版",
        "block": "minecraft:oak_trapdoor[facing=north,half=top,open=true,powered=false,waterlogged=false]"
      },
      {
        "char": "林",
        "block": "minecraft:oak_trapdoor[facing=west,half=top,open=true,powered=false,waterlogged=false]"
      },
      {
        "char": "没",
        "block": "minecraft:redstone_lamp[lit=false]"
      }
    ]
  },
  "slices": [
    [
      "cckaabrkcadacccc",
      "cbakkcadadaabccr",
      "kcabddbdbabckkad",
      "bcardbckbbssssss",
      "kdcdaabackbbrdbb",
      "radabkcbbdbbkaka",
      "abacabkbkkacbkac",
      "kakdacbkbcsJssss",
      "akbdcdddbcdddakd",
      "kbbaaadccckdrbcd",
      "adkccaakkrbbkacd",
      "dcbcaadaaksssJss",
      "bddbcbdbkbakabkk",
      "kdcakkcbkcabdrac",
      "acadkaacbabdkbcc",
      "ddcbkddckasJJsss"
    ],
    [
      "      q         ",
      "               q",
      "                ",
      "   q            ",
      "            q   ",
      "q               ",
      "                ",
      "                ",
      "                ",
      "            q   ",
      "         q      ",
      "                ",
      "                ",
      "             q  ",
      "                ",
      "  q             "
    ],
    [
      "                ",
      "                ",
      "                ",
      "                ",
      "                ",
      "                ",
      "                ",
      "                ",
      "                ",
      "                ",
      "                ",
      "                ",
      "                ",
      "                ",
      "                ",
      "                "
    ],
    [
      "                ",
      "                ",
      "                ",
      "                ",
      "                ",
      "                ",
      "                ",
      "                ",
      "                ",
      "                ",
      "                ",
      "                ",
      "                ",
      "                ",
      "                ",
      "                "
    ],
    [
      "                ",
      "                ",
      "                ",
      "                ",
      "                ",
      "                ",
      "                ",
      "                ",
      "                ",
      "                ",
      "                ",
      "                ",
      "                ",
      "                ",
      "                ",
      "                "
    ],
    [
      "               度",
      "                ",
      "                ",
      "                ",
      "                ",
      "                ",
      "                ",
      "                ",
      "                ",
      "                ",
      "               版",
      "              林没",
      "               度",
      "                ",
      "                ",
      "                "
    ]
  ]
}