{
  "xsize": 16,
  "zsize": 16,
  "palette": {
    "palette": [
      {
        "char": " ",
        "block": "minecraft:air"
      },
      {
        "char": "m",
        "block": "minecraft:vine[east=false,north=false,south=true,up=false,west=false]"
      },
      {
        "char": "D",
        "block": "minecraft:cracked_stone_bricks"
      },
      {
        "char": "z",
        "block": "minecraft:mossy_stone_bricks"
      },
      {
        "char": "l",
        "block": "minecraft:vine[east=true,north=false,south=false,up=false,west=false]"
      },
      {
        "char": "o",
        "block": "minecraft:quartz_block"
      },
      {
        "char": "e",
        "block": "minecraft:smooth_quartz"
      },
      {
        "char": "p",
        "block": "minecraft:diorite"
      },
      {
        "char": "i",
        "block": "minecraft:vine[east=false,north=true,south=false,up=false,west=false]"
      },
      {
        "char": "y",
        "block": "minecraft:quartz_pillar[axis=y]"
      },
      {
        "char": "j",
        "block": "minecraft:vine[east=false,north=false,south=false,up=false,west=true]"
      },
      {
        "char": "f",
        "block": "minecraft:polished_diorite"
      },
      {
        "char": "E",
        "block": "minecraft:stone_bricks[weathering=false]"
      },
      {
        "char": "C",
        "block": "minecraft:mossy_cobblestone"
      },
      {
        "char": "H",
        "block": "minecraft:cobblestone[weathering=false]"
      }
    ]
  },
  "slices": [
    [
      "                ",
      "              mm",
      "              Dz",
      "              DD",
      "              lo",
      "              le",
      "         m    lp",
      "       lzDmm  lo",
      " m m mmlzDepoopo",
      "         o    i ",
      "         e      ",
      "        le      ",
      "        lyj     ",
      "        lf      ",
      "         fj     ",
      "   mmm   f      "
    ],
    [
      "                ",
      "              mm",
      "              zz",
      "              Ez",
      "              lf",
      "              lp",
      "         m    lf",
      "       lzzmm  lo",
      " m m mmlzzfeffye",
      "         p    i ",
      "         f      ",
      "        le      ",
      "        lej     ",
      "        lf      ",
      "         yj     ",
      "   m m   f      "
    ],
    [
      "                ",
      "              mm",
      "              DD",
      "              Cz",
      "              ly",
      "              lf",
      "         m    lo",
      "       lzCmm  le",
      " m m mmlDzoeeofo",
      "         p    i ",
      "         y      ",
      "        lo      ",
      "        lej     ",
      "        lf      ",
      "         fj     ",
      "     m   e      "
    ],
    [
      "                ",
      "              mm",
      "              Hz",
      "              DE",
      "              le",
      "              le",
      "         m    lf",
      "       lzzmm  lf",
      " m m mmlHEfpfpfp",
      "         e      ",
      "         f      ",
      "        lf      ",
      "        lej     ",
      "        lo      ",
      "         fj     ",
      "     m   o      "
    ],
    [
      "                ",
      "              mm",
      "              Dz",
      "              EH",
      "               e",
      "              lf",
      "         m    lf",
      "       lDzmm  lf",
      " m m mmlDDfoeoyy",
      "         e      ",
      "         o      ",
      "         f      ",
      "         yj     ",
      "         y      ",
      "         ej     ",
      "         e      "
    ],
    [
      "                ",
      "               m",
      "              Ez",
      "              Hz",
      "               y",
      "              ly",
      "         m     o",
      "        Ez    lf",
      " m m mm zzopfyfp",
      "         f      ",
      "         o      ",
      "         p      ",
      "         y      ",
      "         e      ",
      "         f      ",
      "         e      "
    ]
  ]
}