{
  "xsize": 16,
  "zsize": 16,
  "palette": {
    "palette": [
      {
        "char": " ",
        "block": "minecraft:air"
      },
      {
        "char": "a",
        "block": "minecraft:air"
      },
      {
        "char": "k",
        "block": "minecraft:air"
      },
      {
        "char": "d",
        "block": "minecraft:air"
      },
      {
        "char": "s",
        "block": "minecraft:air"
      },
      {
        "char": "c",
        "block": "minecraft:air"
      },
      {
        "char": "r",
        "block": "minecraft:air"
      },
      {
        "char": "b",
        "block": "minecraft:air"
      },
      {
        "char": "J",
        "block": "minecraft:air"
      },
      {
        "char": "y",
        "block": "minecraft:air"
      },
      {
        "char": "q",
        "block": "minecraft:grass"
      },
      {
        "char": "动",
        "block": "minecraft:tall_grass[half=lower]"
      },
      {
        "char": "N",
        "block": "minecraft:air"
      },
      {
        "char": "龙",
        "block": "minecraft:tall_grass[half=upper]"
      },
      {
        "char": "度",
        "block": "minecraft:air"
      },
      {
        "char": "版",
        "block": "minecraft:air"
      },
      {
        "char": "林",
        "block": "minecraft:air"
      },
      {
        "char": "没",
        "block": "minecraft:air"
      },
      {
        "char": "跟",
        "block": "minecraft:air"
      },
      {
        "char": "空",
        "block": "minecraft:air"
      }
    ]
  },
  "slices": [
    [
      "akkdsdccrbracbca",
      "akkdsdakdbdbddkd",
      "bbadsccarrcbdkdb",
      "sJsssssJssskkddc",
      "bdacsdarrrrkdkaa",
      "aabcsardcarcabbc",
      "rcrdJddbkccckcdb",
      "Jsssssssssskdbac",
      "baabJdaakdccddbk",
      "bbkcJccdcabkkckb",
      "bdbksbakarcrkbcb",
      "ssJssssssssddkad",
      "kakaJbccdcaabrcd",
      "bccbskbddcacccbb",
      "adaksbadraccabkb",
      "sssssssssJsrcbya"
    ],
    [
      "        q q     ",
      "                ",
      "        动q      ",
      "                ",
      "       qq动q     ",
      "      qq  q     ",
      "q q             ",
      "                ",
      "                ",
      "                ",
      "         q q    ",
      "    N           ",
      "             q  ",
      "                ",
      "        q       ",
      "          qq    "
    ],
    [
      "                ",
      "                ",
      "        龙       ",
      "                ",
      "         龙      ",
      "                ",
      "                ",
      "                ",
      "                ",
      "                ",
      "                ",
      "    N           ",
      "                ",
      "                ",
      "                ",
      "                "
    ],
    [
      "                ",
      "                ",
      "                ",
      "                ",
      "                ",
      "                ",
      "                ",
      "                ",
      "                ",
      "                ",
      "                ",
      "    N           ",
      "                ",
      "                ",
      "                ",
      "                "
    ],
    [
      "                ",
      "                ",
      "                ",
      "                ",
      "                ",
      "                ",
      "                ",
      "                ",
      "                ",
      "                ",
      "                ",
      "    N           ",
      "                ",
      "                ",
      "                ",
      "                "
    ],
    [
      "   度 度          ",
      "                ",
      "                ",
      "                ",
      "                ",
      "                ",
      "                ",
      "                ",
      "                ",
      "                ",
      "   版 版          ",
      "  林没跟没空         ",
      "   度 度          ",
      "                ",
      "                ",
      "                "
    ]
  ]
}