{
  "xsize": 16,
  "zsize": 16,
  "palette": {
    "palette": [
      {
        "char": " ",
        "block": "minecraft:air"
      },
      {
        "char": "b",
        "block": "minecraft:air"
      },
      {
        "char": "k",
        "block": "minecraft:air"
      },
      {
        "char": "c",
        "block": "minecraft:air"
      },
      {
        "char": "a",
        "block": "minecraft:air"
      },
      {
        "char": "d",
        "block": "minecraft:air"
      },
      {
        "char": "r",
        "block": "minecraft:air"
      },
      {
        "char": "J",
        "block": "minecraft:air"
      },
      {
        "char": "s",
        "block": "minecraft:air"
      },
      {
        "char": "f",
        "block": "minecraft:air"
      },
      {
        "char": "e",
        "block": "minecraft:air"
      },
      {
        "char": "p",
        "block": "minecraft:air"
      },
      {
        "char": "o",
        "block": "minecraft:air"
      },
      {
        "char": "q",
        "block": "minecraft:grass"
      },
      {
        "char": "m",
        "block": "minecraft:air"
      },
      {
        "char": "时",
        "block": "minecraft:air",
        "tag": {
          "z": 434,
          "x": 58,
          "is_waxed": "0b",
          "ForgeCaps": {
            "supplementaries:antique_ink": {
              "ink": "0b"
            }
          },
          "id": "minecraft:sign",
          "y": 133,
          "front_text": {
            "color": "black",
            "has_glowing_text": "0b",
            "messages": [
              "{\"extra\":[{\"text\":\"Loom\"}],\"text\":\"\"}",
              "{\"extra\":[{\"text\":\">>>\"}],\"text\":\"\"}",
              "{\"text\":\"\"}",
              "{\"text\":\"\"}"
            ]
          },
          "back_text": {
            "color": "black",
            "has_glowing_text": "0b",
            "messages": [
              "{\"text\":\"\"}",
              "{\"text\":\"\"}",
              "{\"text\":\"\"}",
              "{\"text\":\"\"}"
            ]
          }
        }
      },
      {
        "char": "光",
        "block": "minecraft:air"
      },
      {
        "char": "站",
        "block": "minecraft:air"
      },
      {
        "char": "买",
        "block": "minecraft:air"
      },
      {
        "char": "j",
        "block": "minecraft:air"
      },
      {
        "char": "Ү",
        "block": "minecraft:air"
      },
      {
        "char": "ҩ",
        "block": "minecraft:air"
      }
    ]
  },
  "slices": [
    [
      "bbkcbackcbkdkcac",
      "aadbrbbadcckkkdd",
      "cdkdkkkbcdrbcbad",
      "kcabcdcbbbcbkaab",
      "kckbbbcadrckcbac",
      "dkdaccakkkbbbbad",
      "akdadrbkdbadkcbc",
      "kbrddcabbkkaardd",
      "ddadckaabkaacaak",
      "dbabaccdbkrddaba",
      "rbkdcrckcarckadk",
      "adaacdacakckdabc",
      "kkcabdadbdcbcbcc",
      "Jssssssabbcckdbc",
      "fefpeoodkkdabcba",
      "oefffofadddkdkkd"
    ],
    [
      "                ",
      "    q           ",
      "          q     ",
      "                ",
      "         q      ",
      "       q        ",
      "    qq          ",
      "  q          q  ",
      "               q",
      "          q     ",
      "q    q    q     ",
      "          q     ",
      "                ",
      "m时m 时m          ",
      "光站买光站买      q   ",
      "光站买光站买j       q "
    ],
    [
      "                ",
      "                ",
      "                ",
      "                ",
      "                ",
      "                ",
      "                ",
      "                ",
      "                ",
      "                ",
      "                ",
      "                ",
      "                ",
      "m m mm          ",
      "ҮҮҮҩҩҩ          ",
      "ҮҮҮҩҩҩj         "
    ],
    [
      "                ",
      "                ",
      "                ",
      "                ",
      "                ",
      "                ",
      "                ",
      "                ",
      "                ",
      "                ",
      "                ",
      "                ",
      "                ",
      "m   mm          ",
      "ҮҮҮҩҩҩ          ",
      "ҮҮҮҩҩҩj         "
    ],
    [
      "                ",
      "                ",
      "                ",
      "                ",
      "                ",
      "                ",
      "                ",
      "                ",
      "                ",
      "                ",
      "                ",
      "                ",
      "                ",
      "                ",
      "                ",
      "                "
    ],
    [
      "                ",
      "                ",
      "                ",
      "                ",
      "                ",
      "                ",
      "                ",
      "                ",
      "                ",
      "                ",
      "                ",
      "                ",
      "                ",
      "                ",
      "                ",
      "                "
    ]
  ]
}