{
  "xsize": 16,
  "zsize": 16,
  "palette": {
    "palette": [
      {
        "char": " ",
        "block": "minecraft:air"
      },
      {
        "char": "o",
        "block": "minecraft:quartz_block"
      },
      {
        "char": "e",
        "block": "minecraft:smooth_quartz"
      },
      {
        "char": "f",
        "block": "minecraft:polished_diorite"
      },
      {
        "char": "m",
        "block": "minecraft:vine[east=false,north=false,south=true,up=false,west=false]"
      },
      {
        "char": "p",
        "block": "minecraft:diorite"
      },
      {
        "char": "E",
        "block": "minecraft:stone_bricks[weathering=false]"
      },
      {
        "char": "y",
        "block": "minecraft:quartz_pillar[axis=y]"
      },
      {
        "char": "Ұ",
        "block": "minecraft:vine[east=true,north=true,south=false,up=false,west=false]"
      },
      {
        "char": "C",
        "block": "minecraft:mossy_cobblestone"
      },
      {
        "char": "i",
        "block": "minecraft:vine[east=false,north=true,south=false,up=false,west=false]"
      },
      {
        "char": "j",
        "block": "minecraft:vine[east=false,north=false,south=false,up=false,west=true]"
      },
      {
        "char": "l",
        "block": "minecraft:vine[east=true,north=false,south=false,up=false,west=false]"
      },
      {
        "char": "那",
        "block": "minecraft:vine[east=true,north=false,south=true,up=false,west=false]"
      },
      {
        "char": "D",
        "block": "minecraft:cracked_stone_bricks"
      },
      {
        "char": "z",
        "block": "minecraft:mossy_stone_bricks"
      },
      {
        "char": "H",
        "block": "minecraft:cobblestone[weathering=false]"
      },
      {
        "char": "A",
        "block": "minecraft:air"
      },
      {
        "char": "t",
        "block": "minecraft:stone_slab[type=bottom,waterlogged=false,weathering=false]"
      },
      {
        "char": "天",
        "block": "minecraft:stone_slab[type=double,waterlogged=false,weathering=false]"
      },
      {
        "char": "他",
        "block": "minecraft:air"
      },
      {
        "char": "v",
        "block": "minecraft:vine[east=false,north=false,south=false,up=true,west=false]"
      },
      {
        "char": "怪",
        "block": "minecraft:air"
      }
    ]
  },
  "slices": [
    [
      " o              ",
      " e              ",
      " o              ",
      " f              ",
      " f              ",
      " f              ",
      " f              ",
      "mem    m m      ",
      "pEyeoeeeyy      ",
      "ҰCi  ii  fj     ",
      " i      lp      ",
      "        ly      ",
      "         y      ",
      "        那o m mmm",
      "DCEzEECCHEefpfee",
      "ii   i   ziiiiii"
    ],
    [
      " o              ",
      " p              ",
      " o              ",
      " e              ",
      " f              ",
      " e              ",
      " e              ",
      "me     m m      ",
      "fCfoeyepoe      ",
      "ҰEi  ii  fj     ",
      " i      lf      ",
      "        ly      ",
      "         e      ",
      "        le m mm ",
      "AAAAAAAAzzefffef",
      "         Diiiiii"
    ],
    [
      "                ",
      "                ",
      "                ",
      "                ",
      "                ",
      "                ",
      "                ",
      "m      m        ",
      "ezfyfoyepp      ",
      "ҰCi   i  o      ",
      " i      ly      ",
      "        lo      ",
      "         e      ",
      "         p m mm ",
      "AAAAAAAAHDypeffp",
      "         ziiiiii"
    ],
    [
      "                ",
      "                ",
      "                ",
      "                ",
      "                ",
      "                ",
      "                ",
      "       m        ",
      "fEoeefffef      ",
      "ҰEi      f      ",
      " i      lp      ",
      "        lf      ",
      "         o      ",
      "         f m mm ",
      "        Ezfefpof",
      "         Hiiiiii"
    ],
    [
      "                ",
      "                ",
      "                ",
      "                ",
      "                ",
      "                ",
      "                ",
      "                ",
      "oDyoyfffpo      ",
      "lzi      f      ",
      " i       e      ",
      "         y      ",
      "         y      ",
      "         f m  m ",
      "        EEpeeoef",
      "         Eiiii i"
    ],
    [
      "t天ttttttt天tttt他t",
      " t       t    vv",
      " t v v   t  v   ",
      " t v  v vt    v ",
      " tvv     t   v  ",
      " t       t      ",
      " t    v  t  v v ",
      " 天      v怪      ",
      "yDfyoffyfe天ttttt",
      "lCi      e      ",
      " i       e v v v",
      "         e   v  ",
      "         o      ",
      "         o   v  ",
      "        DDpoeppy",
      "         E i   i"
    ]
  ]
}