{
  "xsize": 16,
  "zsize": 16,
  "palette": {
    "palette": [
      {
        "char": " ",
        "block": "minecraft:air"
      },
      {
        "char": "m",
        "block": "minecraft:vine[east=false,north=false,south=true,up=false,west=false]"
      },
      {
        "char": "数",
        "block": "minecraft:vine[east=false,north=false,south=true,up=true,west=false]"
      },
      {
        "char": "l",
        "block": "minecraft:vine[east=true,north=false,south=false,up=false,west=false]"
      },
      {
        "char": "z",
        "block": "minecraft:mossy_stone_bricks"
      },
      {
        "char": "E",
        "block": "minecraft:stone_bricks[weathering=false]"
      },
      {
        "char": "D",
        "block": "minecraft:cracked_stone_bricks"
      },
      {
        "char": "C",
        "block": "minecraft:mossy_cobblestone"
      },
      {
        "char": "f",
        "block": "minecraft:polished_diorite"
      },
      {
        "char": "受",
        "block": "minecraft:vine[east=false,north=true,south=false,up=true,west=false]"
      },
      {
        "char": "i",
        "block": "minecraft:vine[east=false,north=true,south=false,up=false,west=false]"
      },
      {
        "char": "e",
        "block": "minecraft:smooth_quartz"
      },
      {
        "char": "h",
        "block": "minecraft:white_stained_glass"
      },
      {
        "char": "v",
        "block": "minecraft:vine[east=false,north=false,south=false,up=true,west=false]"
      },
      {
        "char": "公",
        "block": "minecraft:vine[east=true,north=false,south=false,up=false,west=true]"
      },
      {
        "char": "H",
        "block": "minecraft:cobblestone[weathering=false]"
      },
      {
        "char": "把",
        "block": "minecraft:vine[east=true,north=false,south=false,up=true,west=false]"
      },
      {
        "char": "更",
        "block": "minecraft:vine[east=false,north=false,south=false,up=true,west=true]"
      },
      {
        "char": "j",
        "block": "minecraft:vine[east=false,north=false,south=false,up=false,west=true]"
      },
      {
        "char": "那",
        "block": "minecraft:vine[east=true,north=false,south=true,up=false,west=false]"
      },
      {
        "char": "u",
        "block": "minecraft:smooth_quartz_slab[type=bottom,waterlogged=false]"
      },
      {
        "char": "自",
        "block": "minecraft:smooth_quartz_slab[type=double,waterlogged=false]"
      },
      {
        "char": "A",
        "block": "minecraft:air"
      },
      {
        "char": "星",
        "block": "minecraft:air"
      },
      {
        "char": "g",
        "block": "minecraft:blue_concrete"
      },
      {
        "char": "G",
        "block": "minecraft:air"
      },
      {
        "char": "p",
        "block": "minecraft:diorite"
      },
      {
        "char": "o",
        "block": "minecraft:quartz_block"
      },
      {
        "char": "B",
        "block": "minecraft:smooth_quartz_slab[type=top,waterlogged=false]"
      },
      {
        "char": "F",
        "block": "minecraft:stone_brick_slab[type=top,waterlogged=false,weathering=false]"
      },
      {
        "char": "别",
        "block": "minecraft:mossy_stone_brick_slab[type=top,waterlogged=false]"
      },
      {
        "char": "身",
        "block": "minecraft:stone_brick_slab[type=bottom,waterlogged=false,weathering=false]"
      }
    ]
  },
  "slices": [
    [
      "  mmmmmm  m 数数数 ",
      " lzzEzzDzDDzzCCE",
      " lz f受 受fif   e ",
      " lC hv  h h   h公",
      " lElh   h h   h ",
      "  Hlhv 把h h   h ",
      "  D h更jvh h   hl",
      "  D hv 把h h   hl",
      " lC h更 把h h   h ",
      "  Elh   h h   h ",
      " lH公h更 vh h   hl",
      " lz h更  h h   h ",
      "  Elh更 vh h   h ",
      "  z h  vh h   h ",
      "  C h更 把h h   hj",
      "那EDjh   hlh   hj"
    ],
    [
      "  m         u自uu",
      " lDAA星星星AAACu自gg",
      "  G  feej  fffi ",
      "  G  f e   e f  ",
      "  G lfvpj lo oj ",
      "  G  p e   e fj ",
      "  G  p更fj  e ej ",
      "  G  e p   f pj ",
      "  G lp oj  f fj ",
      "  G le p  le oj ",
      " lzj o p   e o  ",
      "  G  f f   e ej ",
      "  G  o f   e e  ",
      "  G lo oj  p fj ",
      "  G  e o   e fj ",
      "那CDj o p   e p  "
    ],
    [
      "  m           uB",
      " lzAAA星AAAAC  u自",
      "  G   fj   lo   ",
      "  G  lh    lh   ",
      "  G   h     h   ",
      "  G  lhj    h   ",
      "  G  lh     h   ",
      "  G   h     h   ",
      "  G   hj    h   ",
      "  G   h     h   ",
      " lCj  h     h   ",
      "  G   h     h   ",
      "  G  lh     h   ",
      "  G   h     hj  ",
      "  G   h     h   ",
      "那Czj  h     h   "
    ],
    [
      "  m             ",
      " lC        C    ",
      "  i             ",
      "                ",
      "                ",
      "                ",
      "                ",
      "                ",
      "                ",
      "                ",
      "  Dj            ",
      "                ",
      "                ",
      "                ",
      "                ",
      "mDDj            "
    ],
    [
      "                ",
      "                ",
      "                ",
      "                ",
      "                ",
      "                ",
      "                ",
      "                ",
      "                ",
      "                ",
      "                ",
      "                ",
      "                ",
      "                ",
      "FFFF            ",
      "FDD别            "
    ],
    [
      "                ",
      "                ",
      "                ",
      "                ",
      "                ",
      "                ",
      "                ",
      "                ",
      "                ",
      "                ",
      "                ",
      "                ",
      "                ",
      "身身身身身           ",
      "    身           ",
      "    身           "
    ]
  ]
}