{
  "xsize": 16,
  "zsize": 16,
  "palette": {
    "palette": [
      {
        "char": " ",
        "block": "minecraft:air"
      },
      {
        "char": "d",
        "block": "minecraft:air"
      },
      {
        "char": "b",
        "block": "minecraft:air"
      },
      {
        "char": "c",
        "block": "minecraft:air"
      },
      {
        "char": "a",
        "block": "minecraft:air"
      },
      {
        "char": "k",
        "block": "minecraft:air"
      },
      {
        "char": "r",
        "block": "minecraft:air"
      },
      {
        "char": "s",
        "block": "minecraft:air"
      },
      {
        "char": "J",
        "block": "minecraft:air"
      },
      {
        "char": "开",
        "block": "minecraft:air",
        "tag": {
          "SpawnData": {
            "entity": {}
          },
          "MaxNearbyEntities": "6s",
          "MinSpawnDelay": "200s",
          "z": 387,
          "x": 24,
          "MaxSpawnDelay": "800s",
          "RequiredPlayerRange": "16s",
          "SpawnCount": "4s",
          "ForgeCaps": {},
          "id": "minecraft:mob_spawner",
          "SpawnPotentials": [],
          "y": 132,
          "SpawnRange": "4s",
          "Delay": "584s"
        }
      },
      {
        "char": "f",
        "block": "minecraft:air"
      },
      {
        "char": "q",
        "block": "minecraft:grass"
      },
      {
        "char": "提",
        "block": "minecraft:air"
      },
      {
        "char": "之",
        "block": "minecraft:air"
      },
      {
        "char": "测",
        "block": "minecraft:air"
      },
      {
        "char": "除",
        "block": "minecraft:air"
      },
      {
        "char": "动",
        "block": "minecraft:tall_grass[half=lower]"
      },
      {
        "char": "说",
        "block": "minecraft:air"
      },
      {
        "char": "病",
        "block": "minecraft:air",
        "tag": {
          "z": 393,
          "x": 133,
          "ForgeData": {
            "LockFlag": "1b"
          },
          "ForgeCaps": {},
          "id": "minecraft:barrel",
          "y": 134,
          "Items": []
        }
      },
      {
        "char": "医",
        "block": "minecraft:air"
      },
      {
        "char": "龙",
        "block": "minecraft:tall_grass[half=upper]"
      },
      {
        "char": "介",
        "block": "minecraft:air"
      },
      {
        "char": "元",
        "block": "minecraft:air"
      },
      {
        "char": "阿",
        "block": "minecraft:air"
      },
      {
        "char": "猫",
        "block": "minecraft:air"
      },
      {
        "char": "h",
        "block": "minecraft:air"
      },
      {
        "char": "便",
        "block": "minecraft:air"
      },
      {
        "char": "院",
        "block": "minecraft:air"
      },
      {
        "char": "般",
        "block": "minecraft:air"
      },
      {
        "char": "度",
        "block": "minecraft:air"
      },
      {
        "char": "版",
        "block": "minecraft:air"
      },
      {
        "char": "没",
        "block": "minecraft:air"
      },
      {
        "char": "空",
        "block": "minecraft:air"
      }
    ]
  },
  "slices": [
    [
      "dbddcacdkcdbadbc",
      "abdackdddrkcdbbk",
      "dbkbcrbcddkkkaad",
      "sssssscacbddkrsJ",
      "ccrcbkabkcddddda",
      "adbkccbdakcakcbk",
      "kbacbrbbdcbkacca",
      "sssssJdcdcbadaJs",
      "bacb开kadbakcaakk",
      "kbbkdkadcaabbadk",
      "dabdabbdkdbackab",
      "sssssskdkadbdrss",
      "cdbbkbbkckcakbca",
      "rcbcdrdaarcbrbaa",
      "bbaakbrcbbabddbc",
      "sssssJrabfkdbaJs"
    ],
    [
      "                ",
      "         q      ",
      "     q          ",
      "             q  ",
      "                ",
      "                ",
      "     q          ",
      "                ",
      "提之提提之提          ",
      "提    提          ",
      "提之提提之提          ",
      "q 测   q      q  ",
      "                ",
      "q    q   q  除   ",
      "      动         ",
      "      q         "
    ],
    [
      "                ",
      "                ",
      "                ",
      "                ",
      "                ",
      "                ",
      "                ",
      "                ",
      "说说说说说说          ",
      "说说说说说病医         ",
      "说说说说说说          ",
      "                ",
      "                ",
      "                ",
      "      龙         ",
      "                "
    ],
    [
      "                ",
      "                ",
      "                ",
      "                ",
      "                ",
      "                ",
      "                ",
      "                ",
      " 介说元说           ",
      "阿猫  h便          ",
      " 院说元说           ",
      "                ",
      "                ",
      "                ",
      "                ",
      "                "
    ],
    [
      "                ",
      "                ",
      "                ",
      "                ",
      "                ",
      "                ",
      "                ",
      "                ",
      " 阿阿阿阿           ",
      " 阿般般便           ",
      " 阿便便便           ",
      "                ",
      "                ",
      "                ",
      "                ",
      "                "
    ],
    [
      "度               ",
      "                ",
      "                ",
      "                ",
      "                ",
      "                ",
      "                ",
      "                ",
      "                ",
      "                ",
      "版               ",
      "没空              ",
      "度               ",
      "                ",
      "                ",
      "                "
    ]
  ]
}