{
  "xsize": 16,
  "zsize": 16,
  "palette": {
    "palette": [
      {
        "char": " ",
        "block": "minecraft:air"
      },
      {
        "char": "C",
        "block": "minecraft:mossy_cobblestone"
      },
      {
        "char": "E",
        "block": "minecraft:stone_bricks[weathering=false]"
      },
      {
        "char": "j",
        "block": "minecraft:vine[east=false,north=false,south=false,up=false,west=true]"
      },
      {
        "char": "o",
        "block": "minecraft:quartz_block"
      },
      {
        "char": "请",
        "block": "minecraft:vine[east=false,north=true,south=false,up=false,west=true]"
      },
      {
        "char": "l",
        "block": "minecraft:vine[east=true,north=false,south=false,up=false,west=false]"
      },
      {
        "char": "e",
        "block": "minecraft:smooth_quartz"
      },
      {
        "char": "f",
        "block": "minecraft:polished_diorite"
      },
      {
        "char": "性",
        "block": "minecraft:vine[east=false,north=false,south=true,up=false,west=true]"
      },
      {
        "char": "H",
        "block": "minecraft:cobblestone[weathering=false]"
      },
      {
        "char": "y",
        "block": "minecraft:quartz_pillar[axis=y]"
      },
      {
        "char": "p",
        "block": "minecraft:diorite"
      },
      {
        "char": "m",
        "block": "minecraft:vine[east=false,north=false,south=true,up=false,west=false]"
      },
      {
        "char": "D",
        "block": "minecraft:cracked_stone_bricks"
      },
      {
        "char": "i",
        "block": "minecraft:vine[east=false,north=true,south=false,up=false,west=false]"
      },
      {
        "char": "z",
        "block": "minecraft:mossy_stone_bricks"
      },
      {
        "char": "A",
        "block": "minecraft:air"
      },
      {
        "char": "t",
        "block": "minecraft:stone_slab[type=bottom,waterlogged=false,weathering=false]"
      },
      {
        "char": "天",
        "block": "minecraft:stone_slab[type=double,waterlogged=false,weathering=false]"
      },
      {
        "char": "他",
        "block": "minecraft:air"
      },
      {
        "char": "v",
        "block": "minecraft:vine[east=false,north=false,south=false,up=true,west=false]"
      }
    ]
  },
  "slices": [
    [
      "         CEj    ",
      "         o请     ",
      "        lej     ",
      "        lfj     ",
      "        lej     ",
      "         oj     ",
      "        lej     ",
      "         o性     ",
      "         CH     ",
      "        lf请     ",
      "         yj     ",
      "         e      ",
      "         p      ",
      "    mmm  o性     ",
      "fDfypeefeDC     ",
      "iz请  i iizz请i ii"
    ],
    [
      "         HCj    ",
      "         e请     ",
      "         ej     ",
      "         fj     ",
      "        lfj     ",
      "         ej     ",
      "        lpj     ",
      "         f性     ",
      "         CE     ",
      "        lo请     ",
      "         o      ",
      "         e      ",
      "         f      ",
      "    mm   e性     ",
      "oDeffpppyEC     ",
      "iE请  i iiHC请i ii"
    ],
    [
      "         zE     ",
      "         y请     ",
      "         fj     ",
      "         ej     ",
      "         ej     ",
      "         fj     ",
      "        lyj     ",
      "         p性     ",
      "         CC     ",
      "         e请     ",
      "         e      ",
      "         e      ",
      "         f      ",
      "         oj     ",
      "yCefoeyoozD     ",
      "iCj  i iiDD请i ii"
    ],
    [
      "         zzAAAAA",
      "         p请     ",
      "         ej     ",
      "         y      ",
      "         oj     ",
      "         pj     ",
      "         yj     ",
      "         y      ",
      "         DDAAAAA",
      "         y      ",
      "         y      ",
      "         e      ",
      "         e      ",
      "         p      ",
      "pzoeeeefoHHAAAAA",
      "iCj  i iiHz请i ii"
    ],
    [
      "         Cz     ",
      "         e请     ",
      "         pj     ",
      "         f      ",
      "         ej     ",
      "         fj     ",
      "         oj     ",
      "         o      ",
      "         Dz     ",
      "         e      ",
      "         o      ",
      "         p      ",
      "         y      ",
      "         e      ",
      "fDeeeeeoeEC     ",
      "iC   i iiECii ii"
    ],
    [
      "t天t他tttttEC  v v",
      " t       oi     ",
      " t v v   fj     ",
      " t       e      ",
      "vt vvv   ej     ",
      " t   vv  e      ",
      " t       e      ",
      " t   v   y      ",
      "ttttt他他t天Dz     ",
      " t       f      ",
      " t       e      ",
      "v他       f      ",
      " 他       p      ",
      " 天       y      ",
      "fzfofeyfoHE     ",
      " E     iiCHii ii"
    ]
  ]
}