{
  "xsize": 16,
  "zsize": 16,
  "palette": {
    "palette": [
      {
        "char": " ",
        "block": "minecraft:air"
      },
      {
        "char": "d",
        "block": "minecraft:deepslate[axis=y]"
      },
      {
        "char": "k",
        "block": "minecraft:blackstone"
      },
      {
        "char": "a",
        "block": "minecraft:cyan_terracotta"
      },
      {
        "char": "c",
        "block": "minecraft:cobbled_deepslate"
      },
      {
        "char": "b",
        "block": "minecraft:basalt[axis=x]"
      },
      {
        "char": "r",
        "block": "minecraft:grass_block[snowy=false]"
      },
      {
        "char": "s",
        "block": "minecraft:yellow_concrete"
      },
      {
        "char": "J",
        "block": "minecraft:yellow_terracotta"
      },
      {
        "char": "e",
        "block": "minecraft:smooth_quartz"
      },
      {
        "char": "f",
        "block": "minecraft:polished_diorite"
      },
      {
        "char": "p",
        "block": "minecraft:diorite"
      },
      {
        "char": "l",
        "block": "minecraft:vine[east=true,north=false,south=false,up=false,west=false]"
      },
      {
        "char": "与",
        "block": "minecraft:oak_log[axis=y]"
      },
      {
        "char": "ҫ",
        "block": "minecraft:oak_planks"
      },
      {
        "char": "j",
        "block": "minecraft:vine[east=false,north=false,south=false,up=false,west=true]"
      },
      {
        "char": "q",
        "block": "minecraft:air"
      },
      {
        "char": "i",
        "block": "minecraft:vine[east=false,north=true,south=false,up=false,west=false]"
      },
      {
        "char": "实",
        "block": "minecraft:light_gray_concrete"
      },
      {
        "char": "爱",
        "block": "minecraft:glass_pane[east=true,north=false,south=false,waterlogged=false,west=true]"
      },
      {
        "char": "把",
        "block": "minecraft:vine[east=true,north=false,south=false,up=true,west=false]"
      },
      {
        "char": "讯",
        "block": "minecraft:cobblestone_stairs[facing=east,half=bottom,shape=straight,waterlogged=false,weathering=false]"
      },
      {
        "char": "H",
        "block": "minecraft:cobblestone[weathering=false]"
      },
      {
        "char": "而",
        "block": "minecraft:cobblestone_stairs[facing=west,half=bottom,shape=straight,waterlogged=false,weathering=false]"
      },
      {
        "char": "线",
        "block": "minecraft:cobblestone_stairs[facing=west,half=top,shape=straight,waterlogged=false,weathering=false]"
      },
      {
        "char": "视",
        "block": "minecraft:cobblestone_stairs[facing=east,half=top,shape=straight,waterlogged=false,weathering=false]"
      }
    ]
  },
  "slices": [
    [
      "dkkaccakdbarbcab",
      "acdbdkcbdcddacdk",
      "ckaccaabbkacrbbc",
      "dbcbkkcdddkabcak",
      "adcadbaacbbccbak",
      "acacddkcbdkdbbrb",
      "kkkckbdbdadkbbcb",
      "aarcaackabdddadc",
      "kabccaacbbcddbrd",
      "dabbacbkbbbssJss",
      "badrbcbraksskdsd",
      "cdbcrbabbksasabs",
      "dbcckcdrbdscksdb",
      "ackbbbabcdsdbask",
      "bdbadabcddrsJssJ",
      "bcakkakdakbefepf"
    ],
    [
      "   l与ҫҫҫ与j q    ",
      "       ii      q",
      "            q   ",
      "                ",
      "实               ",
      "              q ",
      "                ",
      "                ",
      "              q ",
      "                ",
      "       q        ",
      "    q           ",
      "      qq        ",
      "                ",
      "          q     ",
      "                "
    ],
    [
      "   l与ҫ爱ҫ与j      ",
      "       ii       ",
      "                ",
      "                ",
      "                ",
      "                ",
      "                ",
      "                ",
      "                ",
      "                ",
      "                ",
      "                ",
      "                ",
      "                ",
      "                ",
      "                "
    ],
    [
      "   把与ҫҫҫ与j      ",
      "       ii       ",
      "                ",
      "                ",
      "                ",
      "                ",
      "                ",
      "                ",
      "                ",
      "                ",
      "                ",
      "                ",
      "                ",
      "                ",
      "                ",
      "                "
    ],
    [
      "   讯HҫҫҫH而      ",
      "   讯线   视而      ",
      "                ",
      "                ",
      "                ",
      "                ",
      "                ",
      "                ",
      "                ",
      "                ",
      "                ",
      "                ",
      "                ",
      "                ",
      "                ",
      "                "
    ],
    [
      "    讯HҫH而       ",
      "    讯线 视而       ",
      "                ",
      "                ",
      "                ",
      "                ",
      "                ",
      "                ",
      "                ",
      "                ",
      "                ",
      "                ",
      "                ",
      "                ",
      "                ",
      "                "
    ]
  ]
}