{
  "xsize": 16,
  "zsize": 16,
  "palette": {
    "palette": [
      {
        "char": " ",
        "block": "minecraft:air"
      },
      {
        "char": "b",
        "block": "minecraft:basalt[axis=x]"
      },
      {
        "char": "k",
        "block": "minecraft:blackstone"
      },
      {
        "char": "c",
        "block": "minecraft:cobbled_deepslate"
      },
      {
        "char": "a",
        "block": "minecraft:cyan_terracotta"
      },
      {
        "char": "d",
        "block": "minecraft:deepslate[axis=y]"
      },
      {
        "char": "r",
        "block": "minecraft:grass_block[snowy=false]"
      },
      {
        "char": "J",
        "block": "minecraft:yellow_terracotta"
      },
      {
        "char": "s",
        "block": "minecraft:yellow_concrete"
      },
      {
        "char": "f",
        "block": "minecraft:polished_diorite"
      },
      {
        "char": "e",
        "block": "minecraft:smooth_quartz"
      },
      {
        "char": "p",
        "block": "minecraft:diorite"
      },
      {
        "char": "o",
        "block": "minecraft:quartz_block"
      },
      {
        "char": "q",
        "block": "minecraft:air"
      },
      {
        "char": "m",
        "block": "minecraft:vine[east=false,north=false,south=true,up=false,west=false]"
      },
      {
        "char": "时",
        "block": "minecraft:oak_wall_sign[facing=north,waterlogged=false]",
        "tag": {
          "z": 434,
          "x": 58,
          "is_waxed": "0b",
          "ForgeCaps": {
            "supplementaries:antique_ink": {
              "ink": "0b"
            }
          },
          "id": "minecraft:sign",
          "y": 133,
          "front_text": {
            "color": "black",
            "has_glowing_text": "0b",
            "messages": [
              "{\"extra\":[{\"text\":\"Loom\"}],\"text\":\"\"}",
              "{\"extra\":[{\"text\":\">>>\"}],\"text\":\"\"}",
              "{\"text\":\"\"}",
              "{\"text\":\"\"}"
            ]
          },
          "back_text": {
            "color": "black",
            "has_glowing_text": "0b",
            "messages": [
              "{\"text\":\"\"}",
              "{\"text\":\"\"}",
              "{\"text\":\"\"}",
              "{\"text\":\"\"}"
            ]
          }
        }
      },
      {
        "char": "光",
        "block": "minecraft:spruce_stairs[facing=west,half=top,shape=straight,waterlogged=false]"
      },
      {
        "char": "站",
        "block": "minecraft:spruce_slab[type=top,waterlogged=false]"
      },
      {
        "char": "买",
        "block": "minecraft:spruce_stairs[facing=east,half=top,shape=straight,waterlogged=false]"
      },
      {
        "char": "j",
        "block": "minecraft:vine[east=false,north=false,south=false,up=false,west=true]"
      },
      {
        "char": "Ү",
        "block": "minecraft:sand"
      },
      {
        "char": "ҩ",
        "block": "minecraft:gravel"
      }
    ]
  },
  "slices": [
    [
      "bbkcbackcbkdkcac",
      "aadbrbbadcckkkdd",
      "cdkdkkkbcdrbcbad",
      "kcabcdcbbbcbkaab",
      "kckbbbcadrckcbac",
      "dkdaccakkkbbbbad",
      "akdadrbkdbadkcbc",
      "kbrddcabbkkaardd",
      "ddadckaabkaacaak",
      "dbabaccdbkrddaba",
      "rbkdcrckcarckadk",
      "adaacdacakckdabc",
      "kkcabdadbdcbcbcc",
      "Jssssssabbcckdbc",
      "fefpeoodkkdabcba",
      "oefffofadddkdkkd"
    ],
    [
      "                ",
      "    q           ",
      "          q     ",
      "                ",
      "         q      ",
      "       q        ",
      "    qq          ",
      "  q          q  ",
      "               q",
      "          q     ",
      "q    q    q     ",
      "          q     ",
      "                ",
      "m时m 时m          ",
      "光站买光站买      q   ",
      "光站买光站买j       q "
    ],
    [
      "                ",
      "                ",
      "                ",
      "                ",
      "                ",
      "                ",
      "                ",
      "                ",
      "                ",
      "                ",
      "                ",
      "                ",
      "                ",
      "m m mm          ",
      "ҮҮҮҩҩҩ          ",
      "ҮҮҮҩҩҩj         "
    ],
    [
      "                ",
      "                ",
      "                ",
      "                ",
      "                ",
      "                ",
      "                ",
      "                ",
      "                ",
      "                ",
      "                ",
      "                ",
      "                ",
      "m   mm          ",
      "ҮҮҮҩҩҩ          ",
      "ҮҮҮҩҩҩj         "
    ],
    [
      "                ",
      "                ",
      "                ",
      "                ",
      "                ",
      "                ",
      "                ",
      "                ",
      "                ",
      "                ",
      "                ",
      "                ",
      "                ",
      "                ",
      "                ",
      "                "
    ],
    [
      "                ",
      "                ",
      "                ",
      "                ",
      "                ",
      "                ",
      "                ",
      "                ",
      "                ",
      "                ",
      "                ",
      "                ",
      "                ",
      "                ",
      "                ",
      "                "
    ]
  ]
}