{
  "xsize": 16,
  "zsize": 16,
  "palette": {
    "palette": [
      {
        "char": " ",
        "block": "minecraft:air"
      },
      {
        "char": "g",
        "block": "minecraft:blue_concrete"
      },
      {
        "char": "Ѕ",
        "block": "minecraft:oak_wall_sign[facing=east,waterlogged=false]",
        "tag": {
          "z": 471,
          "x": 31,
          "is_waxed": "0b",
          "ForgeCaps": {
            "supplementaries:antique_ink": {
              "ink": "0b"
            }
          },
          "id": "minecraft:sign",
          "y": 138,
          "front_text": {
            "color": "black",
            "has_glowing_text": "0b",
            "messages": [
              "{\"extra\":[{\"text\":\"Birch logs\"}],\"text\":\"\"}",
              "{\"text\":\"\"}",
              "{\"text\":\"\"}",
              "{\"text\":\"\"}"
            ]
          },
          "back_text": {
            "color": "black",
            "has_glowing_text": "0b",
            "messages": [
              "{\"text\":\"\"}",
              "{\"text\":\"\"}",
              "{\"text\":\"\"}",
              "{\"text\":\"\"}"
            ]
          }
        }
      },
      {
        "char": "ҧ",
        "block": "minecraft:oak_wall_sign[facing=west,waterlogged=false]",
        "tag": {
          "z": 463,
          "x": 74,
          "is_waxed": "0b",
          "ForgeCaps": {
            "supplementaries:antique_ink": {
              "ink": "0b"
            }
          },
          "id": "minecraft:sign",
          "y": 138,
          "front_text": {
            "color": "black",
            "has_glowing_text": "0b",
            "messages": [
              "{\"extra\":[{\"text\":\"Aisle 6\"}],\"text\":\"\"}",
              "{\"text\":\"\"}",
              "{\"text\":\"\"}",
              "{\"text\":\"\"}"
            ]
          },
          "back_text": {
            "color": "black",
            "has_glowing_text": "0b",
            "messages": [
              "{\"text\":\"\"}",
              "{\"text\":\"\"}",
              "{\"text\":\"\"}",
              "{\"text\":\"\"}"
            ]
          }
        }
      },
      {
        "char": "j",
        "block": "minecraft:vine[east=false,north=false,south=false,up=false,west=true]"
      },
      {
        "char": "l",
        "block": "minecraft:vine[east=true,north=false,south=false,up=false,west=false]"
      },
      {
        "char": "没",
        "block": "minecraft:redstone_lamp[lit=false]"
      },
      {
        "char": "O",
        "block": "minecraft:dark_oak_fence[east=false,north=false,south=false,waterlogged=false,west=false]"
      },
      {
        "char": "t",
        "block": "minecraft:stone_slab[type=bottom,waterlogged=false,weathering=false]"
      },
      {
        "char": "天",
        "block": "minecraft:stone_slab[type=double,waterlogged=false,weathering=false]"
      },
      {
        "char": "v",
        "block": "minecraft:vine[east=false,north=false,south=false,up=true,west=false]"
      },
      {
        "char": "他",
        "block": "minecraft:air"
      }
    ]
  },
  "slices": [
    [
      "gЅ     ҧggggggЅ ",
      "gj     lg没gg没g  ",
      "g       g没gg没gj ",
      "gj     lggggggj ",
      "gj      gggggg  ",
      "gj      g没gg没gj ",
      "g      lg没gg没g  ",
      "gj     lggggggj ",
      "gj     lgggggg  ",
      "g       g没gg没g  ",
      "g      lg没gg没gj ",
      "g       ggggggj ",
      "gj     lggggggj ",
      "gj     lg没gg没gj ",
      "gj      g没gg没g  ",
      "gЅ     ҧggggggЅ "
    ],
    [
      "O       O    O  ",
      "                ",
      "                ",
      "                ",
      "                ",
      "                ",
      "                ",
      "                ",
      "                ",
      "                ",
      "                ",
      "                ",
      "                ",
      "                ",
      "                ",
      "O       O    O  "
    ],
    [
      "O       O    O  ",
      "                ",
      "                ",
      "                ",
      "                ",
      "                ",
      "                ",
      "                ",
      "                ",
      "                ",
      "                ",
      "                ",
      "                ",
      "                ",
      "                ",
      "O       O    O  "
    ],
    [
      "O       O    O  ",
      "                ",
      "                ",
      "                ",
      "                ",
      "                ",
      "                ",
      "                ",
      "                ",
      "                ",
      "                ",
      "                ",
      "                ",
      "                ",
      "                ",
      "O       O    O  "
    ],
    [
      "O       O    O  ",
      "                ",
      "                ",
      "                ",
      "                ",
      "                ",
      "                ",
      "                ",
      "                ",
      "                ",
      "                ",
      "                ",
      "                ",
      "                ",
      "                ",
      "O       O    O  "
    ],
    [
      "t天ttttttt天tttttt",
      " t       t      ",
      " t       t      ",
      "v他  vv   t  v v ",
      " 他     v t v    ",
      " t       t      ",
      " 他v  v  v他  v   ",
      " t       t      ",
      "t天ttttttt天tt他ttt",
      " t       t  vv  ",
      " t    vv t    v ",
      " t v  v  t vvv v",
      " t    v vt v  v ",
      " 他v vv   t     v",
      " t  v    t  v   ",
      "Ot      Ot   O  "
    ]
  ]
}