{
  "xsize": 16,
  "zsize": 16,
  "palette": {
    "palette": [
      {
        "char": " ",
        "block": "minecraft:air"
      },
      {
        "char": "a",
        "block": "minecraft:air"
      },
      {
        "char": "b",
        "block": "minecraft:air"
      },
      {
        "char": "c",
        "block": "minecraft:air"
      },
      {
        "char": "k",
        "block": "minecraft:air"
      },
      {
        "char": "r",
        "block": "minecraft:air"
      },
      {
        "char": "d",
        "block": "minecraft:air"
      },
      {
        "char": "q",
        "block": "minecraft:grass"
      },
      {
        "char": "ҭ",
        "block": "minecraft:air"
      },
      {
        "char": "备",
        "block": "minecraft:air"
      }
    ]
  },
  "slices": [
    [
      "abcbkbarkcbakaak",
      "acbdbbcdcbckkadk",
      "dbcdkdkcabardabr",
      "krcbaccddkccaadd",
      "dacckaaabraackar",
      "adcbcbkbkbddcbdc",
      "ddabkdkdcbdckdbr",
      "kakdrdbckbbbdkck",
      "cckkcbkrcbbrkkab",
      "cbddbkbbbakackdd",
      "daackdaccbbbbaca",
      "aaacckaacbcrbkcr",
      "ackakkakdcadcdkc",
      "dcbkkdkccbdckarb",
      "baadcdkdcdbaabkb",
      "bdbddkbckdddckab"
    ],
    [
      "       q        ",
      "       q   q   q",
      "           q   q",
      " q              ",
      "         q    ҭҭ",
      "               q",
      "       q       q",
      "    q           ",
      "       备  qq    ",
      "        q       ",
      "             q  ",
      "    ҭ          q",
      "   ҭҭҭҭ     ҭҭ  ",
      "   ҭҭҭҭ  q  ҭҭҭ ",
      "  ҭ  ҭ          ",
      "    ҭ           "
    ],
    [
      "                ",
      "                ",
      "                ",
      "                ",
      "                ",
      "                ",
      "                ",
      "                ",
      "                ",
      "                ",
      "                ",
      "                ",
      "    ҭ           ",
      "    ҭҭ       ҭ  ",
      "             ҭ  ",
      "                "
    ],
    [
      "                ",
      "                ",
      "                ",
      "                ",
      "                ",
      "                ",
      "                ",
      "                ",
      "                ",
      "                ",
      "                ",
      "                ",
      "                ",
      "                ",
      "                ",
      "                "
    ],
    [
      "                ",
      "                ",
      "                ",
      "                ",
      "                ",
      "                ",
      "                ",
      "                ",
      "                ",
      "                ",
      "                ",
      "                ",
      "                ",
      "                ",
      "                ",
      "                "
    ],
    [
      "                ",
      "                ",
      "                ",
      "                ",
      "                ",
      "                ",
      "                ",
      "                ",
      "                ",
      "                ",
      "                ",
      "                ",
      "                ",
      "                ",
      "                ",
      "                "
    ]
  ]
}