{
  "xsize": 16,
  "zsize": 16,
  "palette": {
    "palette": [
      {
        "char": " ",
        "block": "minecraft:air"
      },
      {
        "char": "a",
        "block": "minecraft:cyan_terracotta"
      },
      {
        "char": "d",
        "block": "minecraft:deepslate[axis=y]"
      },
      {
        "char": "k",
        "block": "minecraft:blackstone"
      },
      {
        "char": "c",
        "block": "minecraft:cobbled_deepslate"
      },
      {
        "char": "b",
        "block": "minecraft:basalt[axis=x]"
      },
      {
        "char": "r",
        "block": "minecraft:grass_block[snowy=false]"
      },
      {
        "char": "e",
        "block": "minecraft:smooth_quartz"
      },
      {
        "char": "y",
        "block": "minecraft:quartz_pillar[axis=y]"
      },
      {
        "char": "J",
        "block": "minecraft:yellow_terracotta"
      },
      {
        "char": "s",
        "block": "minecraft:yellow_concrete"
      },
      {
        "char": "o",
        "block": "minecraft:quartz_block"
      },
      {
        "char": "q",
        "block": "minecraft:air"
      },
      {
        "char": "任",
        "block": "minecraft:azure_bluet"
      },
      {
        "char": "N",
        "block": "minecraft:cobblestone_wall[east=none,north=none,south=none,up=true,waterlogged=false,weathering=false,west=none]"
      },
      {
        "char": "版",
        "block": "minecraft:oak_trapdoor[facing=north,half=top,open=true,powered=false,waterlogged=false]"
      },
      {
        "char": "林",
        "block": "minecraft:oak_trapdoor[facing=west,half=top,open=true,powered=false,waterlogged=false]"
      },
      {
        "char": "没",
        "block": "minecraft:redstone_lamp[lit=false]"
      },
      {
        "char": "跟",
        "block": "minecraft:cobblestone_wall[east=low,north=none,south=none,up=true,waterlogged=false,weathering=false,west=low]"
      },
      {
        "char": "空",
        "block": "minecraft:oak_trapdoor[facing=east,half=top,open=true,powered=false,waterlogged=false]"
      }
    ]
  },
  "slices": [
    [
      "adkcacbrkbcdaakc",
      "ckkbkbkckbrcdbcb",
      "cabkkrrbddkdabkc",
      "adkaacaadaabbcka",
      "kdrackaakdcaadaa",
      "akdcdbddckcabddc",
      "addabdbrdbeyycak",
      "dcraccbbkckabaak",
      "ckbdddkdbdaacbca",
      "cackckdadaaadbda",
      "kadbaaakbdabkdkr",
      "JJsssssssssJdcdo",
      "bacbcJcdaakacdck",
      "bcdkcsakcabkbdcc",
      "ckaccsdbbdckbbbb",
      "ssssssJsssssrack"
    ],
    [
      "     q q        ",
      "          q     ",
      "     q任         ",
      "                ",
      "  q             ",
      "                ",
      "       q        ",
      "  q             ",
      "     q          ",
      "                ",
      "               q",
      "                ",
      "                ",
      "                ",
      "                ",
      "     N      q   "
    ],
    [
      "                ",
      "                ",
      "                ",
      "                ",
      "                ",
      "                ",
      "                ",
      "                ",
      "                ",
      "                ",
      "                ",
      "                ",
      "                ",
      "                ",
      "                ",
      "     N          "
    ],
    [
      "                ",
      "                ",
      "                ",
      "                ",
      "                ",
      "                ",
      "                ",
      "                ",
      "                ",
      "                ",
      "                ",
      "                ",
      "                ",
      "                ",
      "                ",
      "     N          "
    ],
    [
      "                ",
      "                ",
      "                ",
      "                ",
      "                ",
      "                ",
      "                ",
      "                ",
      "                ",
      "                ",
      "                ",
      "                ",
      "                ",
      "                ",
      "                ",
      "     N          "
    ],
    [
      "                ",
      "                ",
      "                ",
      "                ",
      "                ",
      "                ",
      "                ",
      "                ",
      "                ",
      "                ",
      "                ",
      "                ",
      "                ",
      "                ",
      "    版 版         ",
      "   林没跟没空        "
    ]
  ]
}