{
  "xsize": 16,
  "zsize": 16,
  "palette": {
    "palette": [
      {
        "char": " ",
        "block": "minecraft:air"
      },
      {
        "char": "o",
        "block": "minecraft:quartz_block"
      },
      {
        "char": "p",
        "block": "minecraft:diorite"
      },
      {
        "char": "f",
        "block": "minecraft:polished_diorite"
      },
      {
        "char": "e",
        "block": "minecraft:smooth_quartz"
      },
      {
        "char": "h",
        "block": "minecraft:white_stained_glass"
      },
      {
        "char": "x",
        "block": "minecraft:smooth_stone"
      },
      {
        "char": "头",
        "block": "minecraft:rail[shape=south_east,waterlogged=false]"
      },
      {
        "char": "考",
        "block": "minecraft:rail[shape=south_west,waterlogged=false]"
      },
      {
        "char": "城",
        "block": "minecraft:rail[shape=north_south,waterlogged=false]"
      },
      {
        "char": "难",
        "block": "minecraft:rail[shape=north_east,waterlogged=false]"
      },
      {
        "char": "喜",
        "block": "minecraft:rail[shape=north_west,waterlogged=false]"
      },
      {
        "char": "结",
        "block": "minecraft:rail[shape=east_west,waterlogged=false]"
      }
    ]
  },
  "slices": [
    [
      "opfpoefpopeeopfe",
      "hheoeffepphhhhhh",
      "hheffffeoehhhhhh",
      "hhfffffofohhhhhh",
      "hheopfpoffhhhhhh",
      "hhfffpeofphhhhhh",
      "hhpeeefeoohhhhhh",
      "hheoefeeeehhhhhh",
      "ffepoffefeepffff",
      "fephhhhhhfeopfoe",
      "fpfhhhhhhpefffef",
      "fefhhhhhhoefppoe",
      "fefhhhhhhfeeeffe",
      "eeehhhhhhepfoeoe",
      "pofhhhhhhpeeeepp",
      "foehhhhhheffoefe"
    ],
    [
      "                ",
      "                ",
      "                ",
      "     xx         ",
      "     xx         ",
      "     xx         ",
      "                ",
      "                ",
      "                ",
      "                ",
      "                ",
      "                ",
      "             xx ",
      "             xx ",
      "             xx ",
      "                "
    ],
    [
      "                ",
      "                ",
      "                ",
      "     头考         ",
      "     城城         ",
      "     难喜         ",
      "                ",
      "                ",
      "                ",
      "                ",
      "                ",
      "                ",
      "             头考 ",
      "             难喜 ",
      "             结结 ",
      "                "
    ],
    [
      "                ",
      "                ",
      "                ",
      "                ",
      "                ",
      "                ",
      "                ",
      "                ",
      "                ",
      "                ",
      "                ",
      "                ",
      "                ",
      "                ",
      "                ",
      "                "
    ],
    [
      "                ",
      "                ",
      "                ",
      "                ",
      "                ",
      "                ",
      "                ",
      "                ",
      "                ",
      "                ",
      "                ",
      "                ",
      "                ",
      "                ",
      "                ",
      "                "
    ],
    [
      "                ",
      "                ",
      "                ",
      "                ",
      "                ",
      "                ",
      "                ",
      "                ",
      "                ",
      "                ",
      "                ",
      "                ",
      "                ",
      "                ",
      "                ",
      "                "
    ]
  ]
}