{
  "xsize": 16,
  "zsize": 16,
  "palette": {
    "palette": [
      {
        "char": " ",
        "block": "minecraft:air"
      },
      {
        "char": "m",
        "block": "minecraft:vine[east=false,north=false,south=true,up=false,west=false]"
      },
      {
        "char": "f",
        "block": "minecraft:polished_diorite"
      },
      {
        "char": "性",
        "block": "minecraft:vine[east=false,north=false,south=true,up=false,west=true]"
      },
      {
        "char": "p",
        "block": "minecraft:diorite"
      },
      {
        "char": "g",
        "block": "minecraft:blue_concrete"
      },
      {
        "char": "E",
        "block": "minecraft:stone_bricks[weathering=false]"
      },
      {
        "char": "z",
        "block": "minecraft:mossy_stone_bricks"
      },
      {
        "char": "D",
        "block": "minecraft:cracked_stone_bricks"
      },
      {
        "char": "y",
        "block": "minecraft:quartz_pillar[axis=y]"
      },
      {
        "char": "e",
        "block": "minecraft:smooth_quartz"
      },
      {
        "char": "H",
        "block": "minecraft:cobblestone[weathering=false]"
      },
      {
        "char": "i",
        "block": "minecraft:vine[east=false,north=true,south=false,up=false,west=false]"
      },
      {
        "char": "呵",
        "block": "minecraft:vine[east=true,north=true,south=true,up=false,west=true]"
      },
      {
        "char": "思",
        "block": "minecraft:vine[east=true,north=true,south=false,up=false,west=true]"
      },
      {
        "char": "l",
        "block": "minecraft:vine[east=true,north=false,south=false,up=false,west=false]"
      },
      {
        "char": "j",
        "block": "minecraft:vine[east=false,north=false,south=false,up=false,west=true]"
      },
      {
        "char": "队",
        "block": "minecraft:vine[east=true,north=true,south=true,up=false,west=false]"
      },
      {
        "char": "必",
        "block": "minecraft:vine[east=false,north=true,south=true,up=false,west=true]"
      },
      {
        "char": "那",
        "block": "minecraft:vine[east=true,north=false,south=true,up=false,west=false]"
      },
      {
        "char": "o",
        "block": "minecraft:quartz_block"
      },
      {
        "char": "黑",
        "block": "minecraft:vine[east=false,north=false,south=true,up=true,west=true]"
      },
      {
        "char": "数",
        "block": "minecraft:vine[east=false,north=false,south=true,up=true,west=false]"
      },
      {
        "char": "C",
        "block": "minecraft:mossy_cobblestone"
      },
      {
        "char": "受",
        "block": "minecraft:vine[east=false,north=true,south=false,up=true,west=false]"
      },
      {
        "char": "ҭ",
        "block": "minecraft:oak_leaves[distance=7,persistent=true,waterlogged=false]"
      },
      {
        "char": "天",
        "block": "minecraft:stone_slab[type=double,waterlogged=false,weathering=false]"
      },
      {
        "char": "t",
        "block": "minecraft:stone_slab[type=bottom,waterlogged=false,weathering=false]"
      },
      {
        "char": "v",
        "block": "minecraft:vine[east=false,north=false,south=false,up=true,west=false]"
      },
      {
        "char": "他",
        "block": "minecraft:air"
      }
    ]
  },
  "slices": [
    [
      "                ",
      " mmmm m  mm  mm ",
      "mf  fmf性  f ffpm",
      "gggggggggggggggg",
      "gggggggggggggggg",
      "gggggggggggggggg",
      "gggggggggggggggg",
      "gEgggggggzgggggg",
      "fDfyfppepHeepfff",
      "iiiiii ii ii iii",
      "                ",
      "                ",
      "    呵           ",
      "     思 l        ",
      "     j队         ",
      "    必那          "
    ],
    [
      "                ",
      "  mmm m  mm   m ",
      "meoff f黑p f mmfm",
      "gggggggggggggggg",
      "gggggggggggggggg",
      "gggggggggggggggg",
      "gggggggggggggggg",
      "gzgggggggEgggggg",
      "fDoffefyeHppeeyy",
      "iiii   ii ii iii",
      "                ",
      "                ",
      "    呵           ",
      "     思 l        ",
      "     j队         ",
      "    必那          "
    ],
    [
      "                ",
      "   mm m  m    m ",
      "mf数 e fomeo mmem",
      "gggggggggggggggg",
      "gggggggggggggggg",
      "gggggggggggggggg",
      "gggggggggggggggg",
      "gCgggggggCgggggg",
      "fCyyeeoypCeyoyee",
      "iiii   ii ii   i",
      "                ",
      "                ",
      "    呵           ",
      "     思 l        ",
      "     j队         ",
      "    必那          "
    ],
    [
      "                ",
      "   m            ",
      "m那of  ommme mmfm",
      "gggggggggggggggg",
      "gggggggggggggggg",
      "gggggggggggggggg",
      "gggggggggggggggg",
      "gDgggggggDgggggg",
      "pDeyfyeeoHpfoyff",
      "i ii   ii ii   受",
      "                ",
      "                ",
      "    呵           ",
      "     思 l        ",
      "     j队         ",
      "    必那          "
    ],
    [
      "                ",
      "                ",
      "  mm  m mm  m mm",
      "gggggggggggggggg",
      "gggggggggggggggg",
      "gggggggggggggggg",
      "gggggggggggggggg",
      "gHgggggggDgggggg",
      "yCpfeepofCffeffo",
      "  ii           ҭ",
      "                ",
      "                ",
      "    呵           ",
      "     思 l        ",
      "     j队         ",
      "    必那          "
    ],
    [
      "                ",
      "                ",
      "  mm  数 mm    mm",
      "gggggggggggggggg",
      "gggggggggggggggg",
      "gggggggggggggggg",
      "gggggggggggggggg",
      "gEgggggggDgggggg",
      "fzeoyfypeDeoffof",
      " 天       天    ҭ ",
      " t       t      ",
      " t    v  t   v  ",
      " t  呵vvvv他  vv  ",
      " t  v思vlv他      ",
      " t  vj队v tv    v",
      "v他  必那v  t     v"
    ]
  ]
}