{
  "xsize": 16,
  "zsize": 16,
  "palette": {
    "palette": [
      {
        "char": " ",
        "block": "minecraft:air"
      },
      {
        "char": "a",
        "block": "minecraft:cyan_terracotta"
      },
      {
        "char": "b",
        "block": "minecraft:basalt[axis=x]"
      },
      {
        "char": "c",
        "block": "minecraft:cobbled_deepslate"
      },
      {
        "char": "k",
        "block": "minecraft:blackstone"
      },
      {
        "char": "r",
        "block": "minecraft:grass_block[snowy=false]"
      },
      {
        "char": "d",
        "block": "minecraft:deepslate[axis=y]"
      },
      {
        "char": "q",
        "block": "minecraft:air"
      },
      {
        "char": "ҭ",
        "block": "minecraft:oak_leaves[distance=7,persistent=true,waterlogged=false]"
      },
      {
        "char": "备",
        "block": "minecraft:dandelion"
      }
    ]
  },
  "slices": [
    [
      "abcbkbarkcbakaak",
      "acbdbbcdcbckkadk",
      "dbcdkdkcabardabr",
      "krcbaccddkccaadd",
      "dacckaaabraackar",
      "adcbcbkbkbddcbdc",
      "ddabkdkdcbdckdbr",
      "kakdrdbckbbbdkck",
      "cckkcbkrcbbrkkab",
      "cbddbkbbbakackdd",
      "daackdaccbbbbaca",
      "aaacckaacbcrbkcr",
      "ackakkakdcadcdkc",
      "dcbkkdkccbdckarb",
      "baadcdkdcdbaabkb",
      "bdbddkbckdddckab"
    ],
    [
      "       q        ",
      "       q   q   q",
      "           q   q",
      " q              ",
      "         q    ҭҭ",
      "               q",
      "       q       q",
      "    q           ",
      "       备  qq    ",
      "        q       ",
      "             q  ",
      "    ҭ          q",
      "   ҭҭҭҭ     ҭҭ  ",
      "   ҭҭҭҭ  q  ҭҭҭ ",
      "  ҭ  ҭ          ",
      "    ҭ           "
    ],
    [
      "                ",
      "                ",
      "                ",
      "                ",
      "                ",
      "                ",
      "                ",
      "                ",
      "                ",
      "                ",
      "                ",
      "                ",
      "    ҭ           ",
      "    ҭҭ       ҭ  ",
      "             ҭ  ",
      "                "
    ],
    [
      "                ",
      "                ",
      "                ",
      "                ",
      "                ",
      "                ",
      "                ",
      "                ",
      "                ",
      "                ",
      "                ",
      "                ",
      "                ",
      "                ",
      "                ",
      "                "
    ],
    [
      "                ",
      "                ",
      "                ",
      "                ",
      "                ",
      "                ",
      "                ",
      "                ",
      "                ",
      "                ",
      "                ",
      "                ",
      "                ",
      "                ",
      "                ",
      "                "
    ],
    [
      "                ",
      "                ",
      "                ",
      "                ",
      "                ",
      "                ",
      "                ",
      "                ",
      "                ",
      "                ",
      "                ",
      "                ",
      "                ",
      "                ",
      "                ",
      "                "
    ]
  ]
}