{
  "xsize": 16,
  "zsize": 16,
  "palette": {
    "palette": [
      {
        "char": " ",
        "block": "minecraft:air"
      },
      {
        "char": "r",
        "block": "minecraft:air"
      },
      {
        "char": "a",
        "block": "minecraft:air"
      },
      {
        "char": "d",
        "block": "minecraft:air"
      },
      {
        "char": "b",
        "block": "minecraft:air"
      },
      {
        "char": "k",
        "block": "minecraft:air"
      },
      {
        "char": "c",
        "block": "minecraft:air"
      },
      {
        "char": "s",
        "block": "minecraft:air"
      },
      {
        "char": "J",
        "block": "minecraft:air"
      },
      {
        "char": "开",
        "block": "minecraft:air",
        "tag": {
          "SpawnData": {
            "entity": {}
          },
          "MaxNearbyEntities": "6s",
          "MinSpawnDelay": "200s",
          "z": 387,
          "x": 24,
          "MaxSpawnDelay": "800s",
          "RequiredPlayerRange": "16s",
          "SpawnCount": "4s",
          "ForgeCaps": {},
          "id": "minecraft:mob_spawner",
          "SpawnPotentials": [],
          "y": 132,
          "SpawnRange": "4s",
          "Delay": "584s"
        }
      },
      {
        "char": "q",
        "block": "minecraft:grass"
      },
      {
        "char": "提",
        "block": "minecraft:air"
      },
      {
        "char": "之",
        "block": "minecraft:air"
      },
      {
        "char": "说",
        "block": "minecraft:air"
      },
      {
        "char": "嗯",
        "block": "minecraft:air"
      },
      {
        "char": "某",
        "block": "minecraft:air",
        "tag": {
          "z": 385,
          "x": 162,
          "ForgeData": {
            "LockFlag": "1b"
          },
          "ForgeCaps": {},
          "id": "minecraft:barrel",
          "y": 134,
          "Items": []
        }
      },
      {
        "char": "元",
        "block": "minecraft:air"
      },
      {
        "char": "段",
        "block": "minecraft:air"
      },
      {
        "char": "边",
        "block": "minecraft:air"
      },
      {
        "char": "h",
        "block": "minecraft:air"
      },
      {
        "char": "猫",
        "block": "minecraft:air"
      },
      {
        "char": "形",
        "block": "minecraft:air"
      },
      {
        "char": "图",
        "block": "minecraft:air"
      },
      {
        "char": "脑",
        "block": "minecraft:air"
      },
      {
        "char": "专",
        "block": "minecraft:air"
      },
      {
        "char": "般",
        "block": "minecraft:air"
      },
      {
        "char": "版",
        "block": "minecraft:air"
      },
      {
        "char": "林",
        "block": "minecraft:air"
      },
      {
        "char": "没",
        "block": "minecraft:air"
      }
    ]
  },
  "slices": [
    [
      "raadddadbkckkdkb",
      "bbkaaakadbcrdckc",
      "bcbcrbdacadbbkbk",
      "kckrdccccacccbrk",
      "rkddckkadkbdkack",
      "ccdbkbbcbbrdaadk",
      "kddkbabkdbbddcdd",
      "kbkckbrcdabdddac",
      "cbbkcbbcbdkbacaa",
      "brcakcacbbccraba",
      "ckbkkcbkdbkcakka",
      "adbkcbddcksssssJ",
      "aaabddbdcbckcbbb",
      "akadckcddccdccca",
      "kkkrbaakadbbcd开d",
      "bcbkkkcddrssJsJs"
    ],
    [
      "q               ",
      "      q    q    ",
      " q  q          q",
      "   q          q ",
      "                ",
      "                ",
      "                ",
      "      q  q      ",
      "        q       ",
      "            q   ",
      "                ",
      "            q   ",
      "          提之提提之提",
      "          提    提",
      "          提之提提之提",
      "         q      "
    ],
    [
      "                ",
      "                ",
      "                ",
      "                ",
      "                ",
      "                ",
      "                ",
      "                ",
      "                ",
      "                ",
      "                ",
      "                ",
      "          说说说说说说",
      "         嗯某说说说说说",
      "          说说说说说说",
      "                "
    ],
    [
      "                ",
      "                ",
      "                ",
      "                ",
      "                ",
      "                ",
      "                ",
      "                ",
      "                ",
      "                ",
      "                ",
      "                ",
      "          说说元说段 ",
      "          边h  猫形",
      "          说说元说图 ",
      "                "
    ],
    [
      "                ",
      "                ",
      "                ",
      "                ",
      "                ",
      "                ",
      "                ",
      "                ",
      "                ",
      "                ",
      "                ",
      "                ",
      "           脑脑脑脑 ",
      "           专般般脑 ",
      "           专边边脑 ",
      "                "
    ],
    [
      "                ",
      "                ",
      "                ",
      "                ",
      "                ",
      "                ",
      "                ",
      "                ",
      "                ",
      "                ",
      "                ",
      "                ",
      "                ",
      "                ",
      "               版",
      "              林没"
    ]
  ]
}