{
  "xsize": 16,
  "zsize": 16,
  "palette": {
    "palette": [
      {
        "char": " ",
        "block": "minecraft:air"
      },
      {
        "char": "d",
        "block": "minecraft:air"
      },
      {
        "char": "b",
        "block": "minecraft:air"
      },
      {
        "char": "c",
        "block": "minecraft:air"
      },
      {
        "char": "a",
        "block": "minecraft:air"
      },
      {
        "char": "k",
        "block": "minecraft:air"
      },
      {
        "char": "r",
        "block": "minecraft:air"
      },
      {
        "char": "I",
        "block": "minecraft:air"
      },
      {
        "char": "q",
        "block": "minecraft:grass"
      },
      {
        "char": "ҭ",
        "block": "minecraft:air"
      },
      {
        "char": "朋",
        "block": "minecraft:air"
      },
      {
        "char": "易",
        "block": "minecraft:air"
      },
      {
        "char": "Ҫ",
        "block": "minecraft:air"
      },
      {
        "char": "L",
        "block": "minecraft:air"
      },
      {
        "char": "哪",
        "block": "minecraft:air"
      },
      {
        "char": "命",
        "block": "minecraft:air"
      },
      {
        "char": "比",
        "block": "minecraft:air"
      },
      {
        "char": "问",
        "block": "minecraft:air"
      },
      {
        "char": "运",
        "block": "minecraft:air"
      },
      {
        "char": "保",
        "block": "minecraft:air"
      },
      {
        "char": "陈",
        "block": "minecraft:air"
      },
      {
        "char": "水",
        "block": "minecraft:air"
      }
    ]
  },
  "slices": [
    [
      "dbcdccbakbakdcca",
      "bddcbdbbakbakrdb",
      "adcbbrdackcbkdcd",
      "cbrackaabbdcbkkb",
      "caadbbaadacbcbdI",
      "ckcckcbbakdIakkb",
      "bkakaadbcbacdcda",
      "kkdkrddkkccdkccd",
      "cackddbcbIkbakca",
      "cakcbckkkckbdbkk",
      "kdbcakrcacdacbdc",
      "cabkdcdkIkaackdb",
      "dabcadcckkkcdcdc",
      "dkckdbkdccadcbkk",
      "akddbkccbbacabck",
      "ddbcarkbkcbkbdka"
    ],
    [
      "  q  ҭq  q   q 朋",
      " ҭҭҭҭҭҭq     q朋易",
      "ҭҭq   ҭҭ     qҪL",
      "ҭҭq    哪命比ҪLҪҪL问",
      "q       朋ҪL问LL问运",
      "         L问运问LL问",
      "        ҪLL问LҪҪL",
      "    q  ҪL问LLҪq  ",
      "       L问运问L    ",
      " q     ҪL问LҪ朋   ",
      "      qL问LҪ比命   ",
      "     易L问运问L 哪ҭq ",
      "  ҭ哪命朋ҪL问LҪ  ҭҭҭ",
      " ҭҭҭ保陈比ҪLҪ      ",
      "     保陈比Ҫ水水     ",
      "     q保陈比     q "
    ],
    [
      "                ",
      "                ",
      "                ",
      "              ҪL",
      "           LҪ L问",
      "          L问L  L",
      "          ҪLҪ   ",
      "         LҪ     ",
      "        L问L     ",
      "        ҪLҪ     ",
      "       ҪLҪ      ",
      "       L问L      ",
      "     命  LҪ      ",
      "                ",
      "      保 比陈保     ",
      "        陈保      "
    ],
    [
      "                ",
      "                ",
      "                ",
      "                ",
      "                ",
      "                ",
      "                ",
      "                ",
      "                ",
      "                ",
      "                ",
      "        L       ",
      "                ",
      "                ",
      "       保陈保      ",
      "        保       "
    ],
    [
      "                ",
      "                ",
      "                ",
      "                ",
      "                ",
      "                ",
      "                ",
      "                ",
      "                ",
      "                ",
      "                ",
      "                ",
      "                ",
      "                ",
      "                ",
      "                "
    ],
    [
      "                ",
      "                ",
      "                ",
      "                ",
      "                ",
      "                ",
      "                ",
      "                ",
      "                ",
      "                ",
      "                ",
      "                ",
      "                ",
      "                ",
      "                ",
      "                "
    ]
  ]
}