{
  "xsize": 16,
  "zsize": 16,
  "palette": {
    "palette": [
      {
        "char": " ",
        "block": "minecraft:air"
      },
      {
        "char": "d",
        "block": "minecraft:air"
      },
      {
        "char": "b",
        "block": "minecraft:air"
      },
      {
        "char": "r",
        "block": "minecraft:air"
      },
      {
        "char": "a",
        "block": "minecraft:air"
      },
      {
        "char": "s",
        "block": "minecraft:air"
      },
      {
        "char": "k",
        "block": "minecraft:air"
      },
      {
        "char": "c",
        "block": "minecraft:air"
      },
      {
        "char": "J",
        "block": "minecraft:air"
      },
      {
        "char": "e",
        "block": "minecraft:air"
      },
      {
        "char": "q",
        "block": "minecraft:grass"
      },
      {
        "char": "N",
        "block": "minecraft:air"
      },
      {
        "char": "度",
        "block": "minecraft:air"
      },
      {
        "char": "版",
        "block": "minecraft:air"
      },
      {
        "char": "林",
        "block": "minecraft:air"
      },
      {
        "char": "没",
        "block": "minecraft:air"
      },
      {
        "char": "跟",
        "block": "minecraft:air"
      },
      {
        "char": "空",
        "block": "minecraft:air"
      }
    ]
  },
  "slices": [
    [
      "dbradskbkdkkbdda",
      "dcakasrcckdakbab",
      "kkadbsakddbaakdk",
      "sssssJssJsJsaakd",
      "bkdkbJaabkaddarc",
      "kcbkksbababadkkc",
      "bccdksdbckccdcka",
      "JsJssssssssscbrb",
      "kdcckJdkkacdkdbd",
      "raakasaaadkckdck",
      "ckkdcsbbkabaddaa",
      "sssssssssssJcaad",
      "dkdadsbdbaaakbcb",
      "kdbdaJkrcckdrkba",
      "cacrksckkdardbck",
      "ssssssssssssddke"
    ],
    [
      "  q             ",
      "      q         ",
      "                ",
      "                ",
      "              q ",
      "                ",
      "                ",
      "              q ",
      "                ",
      "                ",
      "                ",
      "     Nq         ",
      "                ",
      "       q    qq  ",
      "   q       q    ",
      "                "
    ],
    [
      "                ",
      "                ",
      "                ",
      "                ",
      "                ",
      "                ",
      "                ",
      "                ",
      "                ",
      "                ",
      "                ",
      "     N          ",
      "                ",
      "                ",
      "                ",
      "                "
    ],
    [
      "                ",
      "                ",
      "                ",
      "                ",
      "                ",
      "                ",
      "                ",
      "                ",
      "                ",
      "                ",
      "                ",
      "     N          ",
      "                ",
      "                ",
      "                ",
      "                "
    ],
    [
      "                ",
      "                ",
      "                ",
      "                ",
      "                ",
      "                ",
      "                ",
      "                ",
      "                ",
      "                ",
      "                ",
      "     N          ",
      "                ",
      "                ",
      "                ",
      "                "
    ],
    [
      "    度 度         ",
      "                ",
      "                ",
      "                ",
      "                ",
      "                ",
      "                ",
      "                ",
      "                ",
      "                ",
      "    版 版         ",
      "   林没跟没空        ",
      "    度 度         ",
      "                ",
      "                ",
      "                "
    ]
  ]
}