{
  "xsize": 16,
  "zsize": 16,
  "palette": {
    "palette": [
      {
        "char": " ",
        "block": "minecraft:air"
      },
      {
        "char": "o",
        "block": "minecraft:quartz_block"
      },
      {
        "char": "f",
        "block": "minecraft:polished_diorite"
      },
      {
        "char": "e",
        "block": "minecraft:smooth_quartz"
      },
      {
        "char": "p",
        "block": "minecraft:diorite"
      },
      {
        "char": "y",
        "block": "minecraft:quartz_pillar[axis=y]"
      },
      {
        "char": "a",
        "block": "minecraft:cyan_terracotta"
      },
      {
        "char": "k",
        "block": "minecraft:blackstone"
      },
      {
        "char": "b",
        "block": "minecraft:basalt[axis=x]"
      },
      {
        "char": "c",
        "block": "minecraft:cobbled_deepslate"
      },
      {
        "char": "d",
        "block": "minecraft:deepslate[axis=y]"
      },
      {
        "char": "s",
        "block": "minecraft:yellow_concrete"
      },
      {
        "char": "r",
        "block": "minecraft:grass_block[snowy=false]"
      },
      {
        "char": "J",
        "block": "minecraft:yellow_terracotta"
      },
      {
        "char": "m",
        "block": "minecraft:vine[east=false,north=false,south=true,up=false,west=false]"
      },
      {
        "char": "Ҭ",
        "block": "minecraft:smooth_stone_slab[type=bottom,waterlogged=false]"
      },
      {
        "char": "l",
        "block": "minecraft:vine[east=true,north=false,south=false,up=false,west=false]"
      },
      {
        "char": "z",
        "block": "minecraft:mossy_stone_bricks"
      },
      {
        "char": "q",
        "block": "minecraft:air"
      },
      {
        "char": "体",
        "block": "minecraft:air"
      },
      {
        "char": "西",
        "block": "minecraft:air"
      },
      {
        "char": "E",
        "block": "minecraft:stone_bricks[weathering=false]"
      },
      {
        "char": "光",
        "block": "minecraft:spruce_stairs[facing=west,half=top,shape=straight,waterlogged=false]"
      },
      {
        "char": "D",
        "block": "minecraft:cracked_stone_bricks"
      },
      {
        "char": "j",
        "block": "minecraft:vine[east=false,north=false,south=false,up=false,west=true]"
      },
      {
        "char": "i",
        "block": "minecraft:vine[east=false,north=true,south=false,up=false,west=false]"
      },
      {
        "char": "飞",
        "block": "minecraft:ladder[facing=north,waterlogged=false]"
      },
      {
        "char": "气",
        "block": "minecraft:oak_log[axis=x]"
      },
      {
        "char": "城",
        "block": "minecraft:rail[shape=north_south,waterlogged=false]"
      },
      {
        "char": "C",
        "block": "minecraft:mossy_cobblestone"
      },
      {
        "char": "u",
        "block": "minecraft:smooth_quartz_slab[type=bottom,waterlogged=false]"
      }
    ]
  },
  "slices": [
    [
      "offepefpeeepopef",
      "pfyppypeefoyefff",
      "yeefoofyeffoeyee",
      "ffyopoyfyfefefyf",
      "ffoyoffeyyfyyofe",
      "feofeffyfyepffea",
      "kbccbbbakdbdbkkb",
      "baabasdcdbbbbbaa",
      "dakcbrsbkcabkdcc",
      "absssJssdkkckbrk",
      "bkbacbsrdbkkcaac",
      "rkdkbJdcaakbbakb",
      "crcbabbkcbbdaaca",
      "fefeffyyfpeoopyp",
      "eeefyfyoyoeefypo",
      "ffeffofopeoyffoy"
    ],
    [
      "   m            ",
      "ҬҬҬҬҬҬҬҬҬҬҬҬҬҬ  ",
      "           lzҬҬ ",
      "ҬҬҬҬҬҬҬҬҬҬҬҬҬҬ  ",
      "                ",
      "                ",
      "                ",
      "                ",
      "     q        mm",
      "       体      q ",
      "      体西体       ",
      "q      体体       ",
      " q              ",
      "              E光",
      "               光",
      "mm     mmmm mmm光"
    ],
    [
      "   m            ",
      "            m   ",
      "           lDj  ",
      "            i   ",
      "                ",
      "                ",
      "                ",
      "                ",
      "              mm",
      "                ",
      "                ",
      "                ",
      "               飞",
      "              E气",
      "               气",
      "mm     mmmm mmm气"
    ],
    [
      "   m            ",
      "            m   ",
      "            Ej  ",
      "            i   ",
      "                ",
      "                ",
      "                ",
      "                ",
      "              mm",
      "                ",
      "                ",
      "                ",
      "               飞",
      "              D气",
      "               气",
      "mm     mmmm mmm气"
    ],
    [
      "   m            ",
      "            m   ",
      "            zj  ",
      "            i   ",
      "                ",
      "                ",
      "                ",
      "                ",
      "              mm",
      "                ",
      "                ",
      "                ",
      "                ",
      "              E城",
      "               城",
      "mm     mmmm mm 城"
    ],
    [
      "   m            ",
      "            m   ",
      "            Cj  ",
      "            i   ",
      "                ",
      "                ",
      "                ",
      "                ",
      "              mm",
      "                ",
      "                ",
      "                ",
      "                ",
      "              uu",
      "              uu",
      "mm     mmmm   uu"
    ]
  ]
}