{
  "xsize": 16,
  "zsize": 16,
  "palette": {
    "palette": [
      {
        "char": " ",
        "block": "minecraft:air"
      },
      {
        "char": "f",
        "block": "minecraft:polished_diorite"
      },
      {
        "char": "H",
        "block": "minecraft:cobblestone[weathering=false]"
      },
      {
        "char": "j",
        "block": "minecraft:vine[east=false,north=false,south=false,up=false,west=true]"
      },
      {
        "char": "h",
        "block": "minecraft:white_stained_glass"
      },
      {
        "char": "l",
        "block": "minecraft:vine[east=true,north=false,south=false,up=false,west=false]"
      },
      {
        "char": "请",
        "block": "minecraft:vine[east=false,north=true,south=false,up=false,west=true]"
      },
      {
        "char": "把",
        "block": "minecraft:vine[east=true,north=false,south=false,up=true,west=false]"
      },
      {
        "char": "e",
        "block": "minecraft:smooth_quartz"
      },
      {
        "char": "y",
        "block": "minecraft:quartz_pillar[axis=y]"
      },
      {
        "char": "v",
        "block": "minecraft:vine[east=false,north=false,south=false,up=true,west=false]"
      },
      {
        "char": "o",
        "block": "minecraft:quartz_block"
      },
      {
        "char": "位",
        "block": "minecraft:mossy_cobblestone_slab[type=double,waterlogged=false]"
      },
      {
        "char": "E",
        "block": "minecraft:stone_bricks[weathering=false]"
      },
      {
        "char": "D",
        "block": "minecraft:cracked_stone_bricks"
      },
      {
        "char": "公",
        "block": "minecraft:vine[east=true,north=false,south=false,up=false,west=true]"
      },
      {
        "char": "n",
        "block": "minecraft:oak_slab[type=top,waterlogged=false]"
      },
      {
        "char": "p",
        "block": "minecraft:diorite"
      },
      {
        "char": "更",
        "block": "minecraft:vine[east=false,north=false,south=false,up=true,west=true]"
      },
      {
        "char": "C",
        "block": "minecraft:mossy_cobblestone"
      },
      {
        "char": "内",
        "block": "minecraft:cobblestone_wall[east=tall,north=none,south=none,up=true,waterlogged=false,weathering=false,west=none]"
      },
      {
        "char": "欢",
        "block": "minecraft:daylight_detector[inverted=false,power=7]",
        "tag": {
          "z": 441,
          "x": 126,
          "ForgeCaps": {},
          "id": "minecraft:daylight_detector",
          "y": 133
        }
      },
      {
        "char": "需",
        "block": "minecraft:mossy_cobblestone_wall[east=low,north=none,south=none,up=false,waterlogged=false,west=low]"
      },
      {
        "char": "z",
        "block": "minecraft:mossy_stone_bricks"
      },
      {
        "char": "别",
        "block": "minecraft:mossy_stone_brick_slab[type=top,waterlogged=false]"
      },
      {
        "char": "F",
        "block": "minecraft:stone_brick_slab[type=top,waterlogged=false,weathering=false]"
      },
      {
        "char": "身",
        "block": "minecraft:stone_brick_slab[type=bottom,waterlogged=false,weathering=false]"
      }
    ]
  },
  "slices": [
    [
      "fHHjh   h h   h ",
      "lf请 h  把h h   h ",
      "le  h   h h   h ",
      "ly  h  把h h   h ",
      "lf lh   h h   h ",
      "lej hv  h hv  h ",
      "lo  h  把h h   h ",
      "loj h   hlh   h ",
      "位ED公h   h h   h ",
      "nyjlh  vh h   h ",
      "npj h   h h   h ",
      "nfjlh l hlh   hj",
      "nejlhv  h h更  h ",
      "noj h   h h   h ",
      "nfj h  vh h   hj",
      "nepeepoff e更  e "
    ],
    [
      "pECjlf e   e ej ",
      "lf请 lp o   e ej ",
      "lf   f e  lo p  ",
      "lf   f f   e fj ",
      " y   f f   p e  ",
      "lej  e f   f f  ",
      " o   f o   p f  ",
      "loj  e p  lo o  ",
      "内CDj f e  lf p  ",
      "欢ej  e e   p e  ",
      "欢ej  f e   e pj ",
      "欢pj  e把f   p ej ",
      " fj  e e   f p  ",
      "欢oj  e p   e f  ",
      "欢fj  o p   p ej ",
      "欢f   epf  leof  "
    ],
    [
      "eDHj lh    lhj  ",
      " f请   h     h   ",
      "lp    h     h   ",
      "le    h    lh   ",
      " y    h     h   ",
      " oj   h     h   ",
      " p    h     hj  ",
      " e    h     hj  ",
      "需CCj  h     h   ",
      " fj   h     hj  ",
      " ej   h    lh   ",
      " oj   h     h   ",
      " pj   h     h   ",
      " e    h    lhj  ",
      " y   lh     hj  ",
      " p    o     f   "
    ],
    [
      "fEDj            ",
      " p请             ",
      " f              ",
      "把p              ",
      "ve              ",
      " ej             ",
      " e              ",
      " o              ",
      " zzj            ",
      " y              ",
      " y              ",
      " f              ",
      " fj             ",
      " e              ",
      " e              ",
      " e              "
    ],
    [
      "zzC别            ",
      "eEFF            ",
      "fCF             ",
      "pEF             ",
      "fEF             ",
      "fz别             ",
      "eCF             ",
      "pEFF            ",
      "fzz别            ",
      "eEFF            ",
      "oHF             ",
      "fzF             ",
      "eEF             ",
      "fzF             ",
      "fzF             ",
      "oDF             "
    ],
    [
      "    身           ",
      "    身           ",
      "   身身           ",
      "                ",
      "                ",
      "                ",
      "                ",
      "                ",
      "                ",
      "                ",
      "                ",
      "                ",
      "                ",
      "                ",
      "                ",
      "                "
    ]
  ]
}