{
  "xsize": 16,
  "zsize": 16,
  "palette": {
    "palette": [
      {
        "char": " ",
        "block": "minecraft:air"
      },
      {
        "char": "a",
        "block": "minecraft:air"
      },
      {
        "char": "b",
        "block": "minecraft:air"
      },
      {
        "char": "c",
        "block": "minecraft:air"
      },
      {
        "char": "d",
        "block": "minecraft:air"
      },
      {
        "char": "k",
        "block": "minecraft:air"
      },
      {
        "char": "r",
        "block": "minecraft:air"
      },
      {
        "char": "半",
        "block": "minecraft:air"
      },
      {
        "char": "e",
        "block": "minecraft:air"
      },
      {
        "char": "y",
        "block": "minecraft:air"
      },
      {
        "char": "s",
        "block": "minecraft:air"
      },
      {
        "char": "J",
        "block": "minecraft:air"
      },
      {
        "char": "哪",
        "block": "minecraft:air"
      },
      {
        "char": "ҭ",
        "block": "minecraft:air"
      },
      {
        "char": "q",
        "block": "minecraft:grass"
      },
      {
        "char": "L",
        "block": "minecraft:air"
      },
      {
        "char": "Ҫ",
        "block": "minecraft:air"
      },
      {
        "char": "朋",
        "block": "minecraft:air"
      },
      {
        "char": "命",
        "block": "minecraft:air"
      },
      {
        "char": "N",
        "block": "minecraft:air"
      },
      {
        "char": "版",
        "block": "minecraft:air"
      },
      {
        "char": "林",
        "block": "minecraft:air"
      },
      {
        "char": "没",
        "block": "minecraft:air"
      },
      {
        "char": "跟",
        "block": "minecraft:air"
      },
      {
        "char": "空",
        "block": "minecraft:air"
      }
    ]
  },
  "slices": [
    [
      "abccdbbcdbdadbka",
      "kbdddbbrdckdrabr",
      "kcbrakdraabkbrac",
      "kdkrkcackkbkcbdb",
      "kc半bdddbdaaackdb",
      "arbckcccakdckrbc",
      "kdbdcbccckkddkkc",
      "rdkkccabccbckaca",
      "drkccdkdcdbkaddd",
      "ckccckbckcbkcbdk",
      "eybrbdcaaccbbcdk",
      "cdsJsJsssssssssa",
      "dkkkaacaJcbbbacb",
      "krkkrckbscdkdbkk",
      "ccabkdkdsacdrkaa",
      "drJsssssssssJssb"
    ],
    [
      "                ",
      "   哪ҭҭ q    q  q",
      "LҪ朋命哪ҭҭq     q  ",
      "Ҫ 命哪ҭҭҭ         ",
      "   ҭҭҭҭ         ",
      " q   ҭ       q  ",
      "            q   ",
      "         q    q ",
      " q              ",
      "                ",
      "   q            ",
      "                ",
      "                ",
      " q  q          q",
      "            q   ",
      " q      N       "
    ],
    [
      "                ",
      "                ",
      "   哪            ",
      "   ҭҭҭ          ",
      "                ",
      "                ",
      "                ",
      "                ",
      "                ",
      "                ",
      "                ",
      "                ",
      "                ",
      "                ",
      "                ",
      "        N       "
    ],
    [
      "                ",
      "                ",
      "                ",
      "                ",
      "                ",
      "                ",
      "                ",
      "                ",
      "                ",
      "                ",
      "                ",
      "                ",
      "                ",
      "                ",
      "                ",
      "        N       "
    ],
    [
      "                ",
      "                ",
      "                ",
      "                ",
      "                ",
      "                ",
      "                ",
      "                ",
      "                ",
      "                ",
      "                ",
      "                ",
      "                ",
      "                ",
      "                ",
      "        N       "
    ],
    [
      "                ",
      "                ",
      "                ",
      "                ",
      "                ",
      "                ",
      "                ",
      "                ",
      "                ",
      "                ",
      "                ",
      "                ",
      "                ",
      "                ",
      "       版 版      ",
      "      林没跟没空     "
    ]
  ]
}