{
  "xsize": 16,
  "zsize": 16,
  "palette": {
    "palette": [
      {
        "char": " ",
        "block": "minecraft:air"
      },
      {
        "char": "r",
        "block": "minecraft:air"
      },
      {
        "char": "b",
        "block": "minecraft:air"
      },
      {
        "char": "c",
        "block": "minecraft:air"
      },
      {
        "char": "k",
        "block": "minecraft:air"
      },
      {
        "char": "d",
        "block": "minecraft:air"
      },
      {
        "char": "e",
        "block": "minecraft:air"
      },
      {
        "char": "p",
        "block": "minecraft:air"
      },
      {
        "char": "f",
        "block": "minecraft:air"
      },
      {
        "char": "a",
        "block": "minecraft:air"
      },
      {
        "char": "y",
        "block": "minecraft:air"
      },
      {
        "char": "开",
        "block": "minecraft:air",
        "tag": {
          "SpawnData": {
            "entity": {}
          },
          "MaxNearbyEntities": "6s",
          "MinSpawnDelay": "200s",
          "z": 387,
          "x": 24,
          "MaxSpawnDelay": "800s",
          "RequiredPlayerRange": "16s",
          "SpawnCount": "4s",
          "ForgeCaps": {},
          "id": "minecraft:mob_spawner",
          "SpawnPotentials": [],
          "y": 132,
          "SpawnRange": "4s",
          "Delay": "584s"
        }
      },
      {
        "char": "o",
        "block": "minecraft:air"
      },
      {
        "char": "q",
        "block": "minecraft:grass"
      },
      {
        "char": "Ҭ",
        "block": "minecraft:air"
      },
      {
        "char": "C",
        "block": "minecraft:air"
      },
      {
        "char": "l",
        "block": "minecraft:air"
      },
      {
        "char": "动",
        "block": "minecraft:tall_grass[half=lower]"
      },
      {
        "char": "m",
        "block": "minecraft:air"
      },
      {
        "char": "z",
        "block": "minecraft:air"
      },
      {
        "char": "H",
        "block": "minecraft:air"
      },
      {
        "char": "龙",
        "block": "minecraft:tall_grass[half=upper]"
      },
      {
        "char": "E",
        "block": "minecraft:air"
      },
      {
        "char": "D",
        "block": "minecraft:air"
      }
    ]
  },
  "slices": [
    [
      "rrbckbcccdbepfep",
      "dkdcackcbkkpeeey",
      "cbckbbccadbfp开po",
      "ccadkkkcdkbpeeee",
      "bcakcccacccopppy",
      "ckcbkadkbkbooeef",
      "dadaacrcakdkbdbr",
      "aacakakkbabddakd",
      "akbaaadccdakbcra",
      "kcbbbacdakkkkdca",
      "kbcdakdcabdbdkcd",
      "dbrkdkkbkarbbaka",
      "crbdaddcbbrrrcdb",
      "acdkadbcckeofeoy",
      "cckkccbaaceffeeo",
      "rcababdbkd开开fpoe"
    ],
    [
      "qq              ",
      "            ҬҬҬҬ",
      "           ҬҬC  ",
      "            ҬҬҬҬ",
      "  q             ",
      "                ",
      "      q  q     q",
      "                ",
      "              q ",
      "                ",
      "           l    ",
      "  q       动     ",
      " q        q动q   ",
      "           l    ",
      "          mm    ",
      "q        lCzmmmm"
    ],
    [
      "                ",
      "                ",
      "             H  ",
      "                ",
      "                ",
      "                ",
      "                ",
      "                ",
      "                ",
      "                ",
      "           l    ",
      "          龙     ",
      "           龙    ",
      "           l    ",
      "          mm    ",
      "         lEzmmmm"
    ],
    [
      "                ",
      "                ",
      "             E  ",
      "                ",
      "                ",
      "                ",
      "                ",
      "                ",
      "                ",
      "                ",
      "           l    ",
      "                ",
      "           l    ",
      "           l    ",
      "          mm    ",
      "         lCC mmm"
    ],
    [
      "                ",
      "                ",
      "             E  ",
      "                ",
      "                ",
      "                ",
      "                ",
      "                ",
      "                ",
      "                ",
      "           l    ",
      "                ",
      "           l    ",
      "           l    ",
      "          m     ",
      "         lzE  mm"
    ],
    [
      "                ",
      "                ",
      "             D  ",
      "                ",
      "                ",
      "                ",
      "                ",
      "                ",
      "                ",
      "                ",
      "           l    ",
      "                ",
      "           l    ",
      "           l    ",
      "          m     ",
      "         lEE  mm"
    ]
  ]
}