{
  "xsize": 16,
  "zsize": 16,
  "palette": {
    "palette": [
      {
        "char": " ",
        "block": "minecraft:air"
      },
      {
        "char": "a",
        "block": "minecraft:air"
      },
      {
        "char": "c",
        "block": "minecraft:air"
      },
      {
        "char": "d",
        "block": "minecraft:air"
      },
      {
        "char": "r",
        "block": "minecraft:air"
      },
      {
        "char": "b",
        "block": "minecraft:air"
      },
      {
        "char": "k",
        "block": "minecraft:air"
      },
      {
        "char": "p",
        "block": "minecraft:air"
      },
      {
        "char": "f",
        "block": "minecraft:air"
      },
      {
        "char": "o",
        "block": "minecraft:air"
      },
      {
        "char": "y",
        "block": "minecraft:air"
      },
      {
        "char": "e",
        "block": "minecraft:air"
      },
      {
        "char": "s",
        "block": "minecraft:air"
      },
      {
        "char": "I",
        "block": "minecraft:air"
      },
      {
        "char": "J",
        "block": "minecraft:air"
      },
      {
        "char": "开",
        "block": "minecraft:air",
        "tag": {
          "SpawnData": {
            "entity": {}
          },
          "MaxNearbyEntities": "6s",
          "MinSpawnDelay": "200s",
          "z": 387,
          "x": 24,
          "MaxSpawnDelay": "800s",
          "RequiredPlayerRange": "16s",
          "SpawnCount": "4s",
          "ForgeCaps": {},
          "id": "minecraft:mob_spawner",
          "SpawnPotentials": [],
          "y": 132,
          "SpawnRange": "4s",
          "Delay": "584s"
        }
      },
      {
        "char": "q",
        "block": "minecraft:grass"
      },
      {
        "char": "水",
        "block": "minecraft:air"
      },
      {
        "char": "u",
        "block": "minecraft:air"
      },
      {
        "char": "多",
        "block": "minecraft:air"
      },
      {
        "char": "与",
        "block": "minecraft:air"
      },
      {
        "char": "园",
        "block": "minecraft:air"
      },
      {
        "char": "动",
        "block": "minecraft:tall_grass[half=lower]"
      },
      {
        "char": "千",
        "block": "minecraft:air"
      },
      {
        "char": "N",
        "block": "minecraft:air"
      },
      {
        "char": "龙",
        "block": "minecraft:tall_grass[half=upper]"
      },
      {
        "char": "杀",
        "block": "minecraft:air"
      },
      {
        "char": "Ҫ",
        "block": "minecraft:air"
      },
      {
        "char": "L",
        "block": "minecraft:air"
      },
      {
        "char": "比",
        "block": "minecraft:air"
      },
      {
        "char": "问",
        "block": "minecraft:air"
      },
      {
        "char": "版",
        "block": "minecraft:air"
      },
      {
        "char": "林",
        "block": "minecraft:air"
      },
      {
        "char": "没",
        "block": "minecraft:air"
      },
      {
        "char": "跟",
        "block": "minecraft:air"
      },
      {
        "char": "空",
        "block": "minecraft:air"
      }
    ]
  },
  "slices": [
    [
      "acdacrrdabdrrckr",
      "kckkdcdradkrcaac",
      "rcbccrkakbcbakkd",
      "kcabbkcabkbbkccb",
      "rbkkcrbccbadddbc",
      "kakcrcccrabkrdbb",
      "pforabyyycbayfeb",
      "cdbckakbakcbaada",
      "cdackcbabdckkbbc",
      "barbbkccaacbbaak",
      "eepababddddbcakk",
      "aaasssssssdrIrkd",
      "bbbbkarrdskrrrcd",
      "bkaabkcaaJcrrrbk",
      "rcbbkkakcsbrrrdc",
      "ckcssssssJ开rrrdb"
    ],
    [
      "     qqq   qq  q",
      "  q   qqq  q  q ",
      "q    q         q",
      "    q           ",
      "q    q          ",
      "    q   q   q   ",
      "   q            ",
      "                ",
      "                ",
      "  q         水 水 ",
      "          水uuu  ",
      "          多q与园多 ",
      "      qq  多q动水多 ",
      "          多水动水多 ",
      "q     q   多动q千多 ",
      "         N多q动q多 "
    ],
    [
      "                ",
      "                ",
      "                ",
      "                ",
      "                ",
      "                ",
      "                ",
      "                ",
      "                ",
      "                ",
      "                ",
      "            与   ",
      "            龙   ",
      "            龙   ",
      "           龙 杀  ",
      "         N  龙   "
    ],
    [
      "                ",
      "                ",
      "                ",
      "                ",
      "                ",
      "                ",
      "                ",
      "                ",
      "                ",
      "           ҪLҪ比 ",
      "          ҪL问LҪ ",
      "          L问与问L ",
      "          ҪL问LҪ ",
      "           ҪLҪ  ",
      "                ",
      "         N      "
    ],
    [
      "                ",
      "                ",
      "                ",
      "                ",
      "                ",
      "                ",
      "                ",
      "                ",
      "                ",
      "          比ҪLҪ  ",
      "          ҪL问LҪ ",
      "          L问与问L ",
      "          ҪL问LҪ ",
      "          比ҪLҪ比 ",
      "                ",
      "         N      "
    ],
    [
      "                ",
      "                ",
      "                ",
      "                ",
      "                ",
      "                ",
      "                ",
      "                ",
      "                ",
      "                ",
      "           L问   ",
      "           问与问  ",
      "           L问L  ",
      "                ",
      "        版 版     ",
      "       林没跟没空    "
    ]
  ]
}