{
  "xsize": 16,
  "zsize": 16,
  "palette": {
    "palette": [
      {
        "char": " ",
        "block": "minecraft:air"
      },
      {
        "char": "c",
        "block": "minecraft:cobbled_deepslate"
      },
      {
        "char": "J",
        "block": "minecraft:yellow_terracotta"
      },
      {
        "char": "a",
        "block": "minecraft:cyan_terracotta"
      },
      {
        "char": "d",
        "block": "minecraft:deepslate[axis=y]"
      },
      {
        "char": "r",
        "block": "minecraft:grass_block[snowy=false]"
      },
      {
        "char": "e",
        "block": "minecraft:smooth_quartz"
      },
      {
        "char": "k",
        "block": "minecraft:blackstone"
      },
      {
        "char": "b",
        "block": "minecraft:basalt[axis=x]"
      },
      {
        "char": "s",
        "block": "minecraft:yellow_concrete"
      },
      {
        "char": "y",
        "block": "minecraft:quartz_pillar[axis=y]"
      },
      {
        "char": "p",
        "block": "minecraft:diorite"
      },
      {
        "char": "o",
        "block": "minecraft:quartz_block"
      },
      {
        "char": "f",
        "block": "minecraft:polished_diorite"
      },
      {
        "char": "q",
        "block": "minecraft:air"
      },
      {
        "char": "提",
        "block": "minecraft:smooth_stone_slab[type=top,waterlogged=false]"
      },
      {
        "char": "之",
        "block": "minecraft:black_concrete"
      },
      {
        "char": "任",
        "block": "minecraft:azure_bluet"
      },
      {
        "char": "说",
        "block": "minecraft:air"
      },
      {
        "char": "魔",
        "block": "minecraft:barrel[facing=south,open=false]",
        "tag": {
          "z": 402,
          "x": 59,
          "ForgeData": {
            "LockFlag": "1b"
          },
          "ForgeCaps": {},
          "id": "minecraft:barrel",
          "y": 134,
          "Items": []
        }
      },
      {
        "char": "猫",
        "block": "minecraft:white_stained_glass_pane[east=false,north=true,south=true,waterlogged=false,west=false]"
      },
      {
        "char": "h",
        "block": "minecraft:white_stained_glass"
      },
      {
        "char": "形",
        "block": "minecraft:air"
      },
      {
        "char": "专",
        "block": "minecraft:air"
      },
      {
        "char": "般",
        "block": "minecraft:air"
      },
      {
        "char": "边",
        "block": "minecraft:air"
      }
    ]
  },
  "slices": [
    [
      "cJadadreeekcacbk",
      "Jscbakabkabckcbr",
      "bsrdbadkbadakkbk",
      "ssabbkbarbacckak",
      "kskbdckrkbkcdkac",
      "sJabbkaabkcbdrkk",
      "rskabddbdddkrkbk",
      "Jskckkbckbddcadk",
      "ksbbbkacdddbakda",
      "sssJsssssssJsssJ",
      "srcskdscksdbsddJ",
      "ksccsacJcrsbbsbd",
      "drsdaJbbsddsdasc",
      "sbksbdsabsdcscrs",
      "sssssssssssssssJ",
      "beaecycpepyofpee"
    ],
    [
      "      q   提 提   ",
      "          之 之  q",
      "  q   q   提提提   ",
      "    q   任       ",
      "       q        ",
      "             q  ",
      "                ",
      "        q       ",
      "                ",
      "         q      ",
      "                ",
      "         q      ",
      " q              ",
      "              q ",
      "                ",
      "                "
    ],
    [
      "          说说说   ",
      "          说说说   ",
      "          说魔说   ",
      "                ",
      "                ",
      "                ",
      "                ",
      "                ",
      "                ",
      "                ",
      "                ",
      "                ",
      "                ",
      "                ",
      "                ",
      "                "
    ],
    [
      "          猫 猫   ",
      "          说h说   ",
      "          说形说   ",
      "                ",
      "                ",
      "                ",
      "                ",
      "                ",
      "                ",
      "                ",
      "                ",
      "                ",
      "                ",
      "                ",
      "                ",
      "                "
    ],
    [
      "          专般形   ",
      "          专边形   ",
      "                ",
      "                ",
      "                ",
      "                ",
      "                ",
      "                ",
      "                ",
      "                ",
      "                ",
      "                ",
      "                ",
      "                ",
      "                ",
      "                "
    ],
    [
      "                ",
      "                ",
      "                ",
      "                ",
      "                ",
      "                ",
      "                ",
      "                ",
      "                ",
      "                ",
      "                ",
      "                ",
      "                ",
      "                ",
      "                ",
      "                "
    ]
  ]
}