{
  "xsize": 16,
  "zsize": 16,
  "palette": {
    "palette": [
      {
        "char": " ",
        "block": "minecraft:air"
      },
      {
        "char": "k",
        "block": "minecraft:blackstone"
      },
      {
        "char": "a",
        "block": "minecraft:cyan_terracotta"
      },
      {
        "char": "b",
        "block": "minecraft:basalt[axis=x]"
      },
      {
        "char": "d",
        "block": "minecraft:deepslate[axis=y]"
      },
      {
        "char": "c",
        "block": "minecraft:cobbled_deepslate"
      },
      {
        "char": "r",
        "block": "minecraft:grass_block[snowy=false]"
      },
      {
        "char": "f",
        "block": "minecraft:polished_diorite"
      },
      {
        "char": "e",
        "block": "minecraft:smooth_quartz"
      },
      {
        "char": "o",
        "block": "minecraft:quartz_block"
      },
      {
        "char": "p",
        "block": "minecraft:diorite"
      },
      {
        "char": "s",
        "block": "minecraft:yellow_concrete"
      },
      {
        "char": "J",
        "block": "minecraft:yellow_terracotta"
      },
      {
        "char": "u",
        "block": "minecraft:smooth_quartz_slab[type=bottom,waterlogged=false]"
      },
      {
        "char": "q",
        "block": "minecraft:air"
      },
      {
        "char": "水",
        "block": "minecraft:air"
      },
      {
        "char": "狂",
        "block": "minecraft:air"
      },
      {
        "char": "Ҫ",
        "block": "minecraft:oak_leaves[distance=3,persistent=false,waterlogged=false]"
      },
      {
        "char": "L",
        "block": "minecraft:oak_leaves[distance=2,persistent=false,waterlogged=false]"
      },
      {
        "char": "问",
        "block": "minecraft:oak_leaves[distance=1,persistent=false,waterlogged=false]"
      },
      {
        "char": "比",
        "block": "minecraft:oak_leaves[distance=4,persistent=false,waterlogged=false]"
      }
    ]
  },
  "slices": [
    [
      "kabkbkkdcdkadbbr",
      "bkdabakdbbckbccc",
      "bkbbbkdcaddfefdc",
      "aacdbccbkcddcdcc",
      "kddrbbcbcraopfdk",
      "caddabbackkdcakb",
      "bdbbcaaakccofpdb",
      "ccddacdkadrbaccd",
      "rcbkdbkcaabfooka",
      "ssJsssssJsssssJs",
      "dskasddscksacscb",
      "acsdksbaJbdskksb",
      "skdscbJkcJbksdas",
      "dsdksdbsdcsbcJcc",
      "JsssssssJsJJsJss",
      "efefppeeeepffeoe"
    ],
    [
      "           uuuqq",
      "          水q 水水 ",
      "                ",
      "                ",
      "   q            ",
      " q             q",
      "                ",
      "          q     ",
      "q 狂             ",
      "                ",
      "                ",
      "                ",
      "                ",
      "                ",
      "                ",
      "                "
    ],
    [
      "          ҪL问LҪ ",
      "          比ҪLҪ比 ",
      "                ",
      "                ",
      "                ",
      "                ",
      "                ",
      "                ",
      "                ",
      "                ",
      "                ",
      "                ",
      "                ",
      "                ",
      "                ",
      "                "
    ],
    [
      "          ҪL问LҪ ",
      "           ҪLҪ比 ",
      "                ",
      "                ",
      "                ",
      "                ",
      "                ",
      "                ",
      "                ",
      "                ",
      "                ",
      "                ",
      "                ",
      "                ",
      "                ",
      "                "
    ],
    [
      "           L问L  ",
      "                ",
      "                ",
      "                ",
      "                ",
      "                ",
      "                ",
      "                ",
      "                ",
      "                ",
      "                ",
      "                ",
      "                ",
      "                ",
      "                ",
      "                "
    ],
    [
      "            L   ",
      "                ",
      "                ",
      "                ",
      "                ",
      "                ",
      "                ",
      "                ",
      "                ",
      "                ",
      "                ",
      "                ",
      "                ",
      "                ",
      "                ",
      "                "
    ]
  ]
}