{
  "xsize": 16,
  "zsize": 16,
  "palette": {
    "palette": [
      {
        "char": " ",
        "block": "minecraft:air"
      },
      {
        "char": "m",
        "block": "minecraft:vine[east=false,north=false,south=true,up=false,west=false]"
      },
      {
        "char": "数",
        "block": "minecraft:vine[east=false,north=false,south=true,up=true,west=false]"
      },
      {
        "char": "z",
        "block": "minecraft:mossy_stone_bricks"
      },
      {
        "char": "C",
        "block": "minecraft:mossy_cobblestone"
      },
      {
        "char": "D",
        "block": "minecraft:cracked_stone_bricks"
      },
      {
        "char": "H",
        "block": "minecraft:cobblestone[weathering=false]"
      },
      {
        "char": "f",
        "block": "minecraft:polished_diorite"
      },
      {
        "char": "受",
        "block": "minecraft:vine[east=false,north=true,south=false,up=true,west=false]"
      },
      {
        "char": "e",
        "block": "minecraft:smooth_quartz"
      },
      {
        "char": "v",
        "block": "minecraft:vine[east=false,north=false,south=false,up=true,west=false]"
      },
      {
        "char": "h",
        "block": "minecraft:white_stained_glass"
      },
      {
        "char": "j",
        "block": "minecraft:vine[east=false,north=false,south=false,up=false,west=true]"
      },
      {
        "char": "速",
        "block": "minecraft:dark_oak_fence[east=false,north=false,south=false,waterlogged=false,west=true]"
      },
      {
        "char": "孩",
        "block": "minecraft:dark_oak_fence[east=true,north=false,south=false,waterlogged=false,west=false]"
      },
      {
        "char": "把",
        "block": "minecraft:vine[east=true,north=false,south=false,up=true,west=false]"
      },
      {
        "char": "l",
        "block": "minecraft:vine[east=true,north=false,south=false,up=false,west=false]"
      },
      {
        "char": "o",
        "block": "minecraft:quartz_block"
      },
      {
        "char": "p",
        "block": "minecraft:diorite"
      },
      {
        "char": "i",
        "block": "minecraft:vine[east=false,north=true,south=false,up=false,west=false]"
      },
      {
        "char": "u",
        "block": "minecraft:smooth_quartz_slab[type=bottom,waterlogged=false]"
      },
      {
        "char": "自",
        "block": "minecraft:smooth_quartz_slab[type=double,waterlogged=false]"
      },
      {
        "char": "g",
        "block": "minecraft:blue_concrete"
      },
      {
        "char": "风",
        "block": "minecraft:air"
      },
      {
        "char": "B",
        "block": "minecraft:smooth_quartz_slab[type=top,waterlogged=false]"
      },
      {
        "char": "E",
        "block": "minecraft:stone_bricks[weathering=false]"
      }
    ]
  },
  "slices": [
    [
      "  mmmmm数m 数数 m  ",
      "zzzCDDDDzDDzCHDD",
      "f 受受e e受vve     ",
      "h   h h   hj    ",
      "h   h h   hj    ",
      "h速 孩h h速 孩h     ",
      "h   h h   hj    ",
      "h  把h h   h     ",
      "h   h h   hj    ",
      "h速 孩h h速 孩h     ",
      "h   hlh   hj    ",
      "ffefo opffoj    ",
      "i ii    ii      ",
      "                ",
      "                ",
      "                "
    ],
    [
      "uuuuuuuuuuu自u   ",
      "ggggggggggg自uD风风",
      " eee   eef      ",
      "lf e   f e      ",
      "lf f   o o      ",
      "lf fj  o pj     ",
      "lfvfj  f o      ",
      " e f  le ej     ",
      "lf ej lo e      ",
      "le e   e e      ",
      "le pj  e p      ",
      "leefj lpoo      ",
      "   i     i      ",
      "                ",
      "                ",
      "                "
    ],
    [
      "数mmuBumm数Bu     ",
      "ggggggggg自u  E风风",
      "  p     o       ",
      "  h     hj      ",
      " lhj   lh       ",
      "  hj    hj      ",
      "  hj   lh       ",
      " lhj   lhj      ",
      " lhj    hj      ",
      " lhj    hj      ",
      "  hj    hj      ",
      "  o     f       ",
      "                ",
      "                ",
      "                ",
      "                "
    ],
    [
      "uB数m   Bu       ",
      "u自ggggg自u    E  ",
      "                ",
      "                ",
      "                ",
      "                ",
      "                ",
      "                ",
      "                ",
      "                ",
      "                ",
      "                ",
      "                ",
      "                ",
      "                ",
      "                "
    ],
    [
      "  uB Bu         ",
      "  u自g自u         ",
      "                ",
      "                ",
      "                ",
      "                ",
      "                ",
      "                ",
      "                ",
      "                ",
      "                ",
      "                ",
      "                ",
      "                ",
      "                ",
      "                "
    ],
    [
      "    u           ",
      "    u           ",
      "                ",
      "                ",
      "                ",
      "                ",
      "                ",
      "                ",
      "                ",
      "                ",
      "                ",
      "                ",
      "                ",
      "                ",
      "                ",
      "                "
    ]
  ]
}