{
  "xsize": 16,
  "zsize": 16,
  "palette": {
    "palette": [
      {
        "char": " ",
        "block": "minecraft:air"
      },
      {
        "char": "d",
        "block": "minecraft:deepslate[axis=y]"
      },
      {
        "char": "b",
        "block": "minecraft:basalt[axis=x]"
      },
      {
        "char": "r",
        "block": "minecraft:grass_block[snowy=false]"
      },
      {
        "char": "a",
        "block": "minecraft:cyan_terracotta"
      },
      {
        "char": "s",
        "block": "minecraft:yellow_concrete"
      },
      {
        "char": "k",
        "block": "minecraft:blackstone"
      },
      {
        "char": "c",
        "block": "minecraft:cobbled_deepslate"
      },
      {
        "char": "J",
        "block": "minecraft:yellow_terracotta"
      },
      {
        "char": "e",
        "block": "minecraft:smooth_quartz"
      },
      {
        "char": "q",
        "block": "minecraft:air"
      },
      {
        "char": "N",
        "block": "minecraft:cobblestone_wall[east=none,north=none,south=none,up=true,waterlogged=false,weathering=false,west=none]"
      },
      {
        "char": "度",
        "block": "minecraft:oak_trapdoor[facing=south,half=top,open=true,powered=false,waterlogged=false]"
      },
      {
        "char": "版",
        "block": "minecraft:oak_trapdoor[facing=north,half=top,open=true,powered=false,waterlogged=false]"
      },
      {
        "char": "林",
        "block": "minecraft:oak_trapdoor[facing=west,half=top,open=true,powered=false,waterlogged=false]"
      },
      {
        "char": "没",
        "block": "minecraft:redstone_lamp[lit=false]"
      },
      {
        "char": "跟",
        "block": "minecraft:cobblestone_wall[east=low,north=none,south=none,up=true,waterlogged=false,weathering=false,west=low]"
      },
      {
        "char": "空",
        "block": "minecraft:oak_trapdoor[facing=east,half=top,open=true,powered=false,waterlogged=false]"
      }
    ]
  },
  "slices": [
    [
      "dbradskbkdkkbdda",
      "dcakasrcckdakbab",
      "kkadbsakddbaakdk",
      "sssssJssJsJsaakd",
      "bkdkbJaabkaddarc",
      "kcbkksbababadkkc",
      "bccdksdbckccdcka",
      "JsJssssssssscbrb",
      "kdcckJdkkacdkdbd",
      "raakasaaadkckdck",
      "ckkdcsbbkabaddaa",
      "sssssssssssJcaad",
      "dkdadsbdbaaakbcb",
      "kdbdaJkrcckdrkba",
      "cacrksckkdardbck",
      "ssssssssssssddke"
    ],
    [
      "  q             ",
      "      q         ",
      "                ",
      "                ",
      "              q ",
      "                ",
      "                ",
      "              q ",
      "                ",
      "                ",
      "                ",
      "     Nq         ",
      "                ",
      "       q    qq  ",
      "   q       q    ",
      "                "
    ],
    [
      "                ",
      "                ",
      "                ",
      "                ",
      "                ",
      "                ",
      "                ",
      "                ",
      "                ",
      "                ",
      "                ",
      "     N          ",
      "                ",
      "                ",
      "                ",
      "                "
    ],
    [
      "                ",
      "                ",
      "                ",
      "                ",
      "                ",
      "                ",
      "                ",
      "                ",
      "                ",
      "                ",
      "                ",
      "     N          ",
      "                ",
      "                ",
      "                ",
      "                "
    ],
    [
      "                ",
      "                ",
      "                ",
      "                ",
      "                ",
      "                ",
      "                ",
      "                ",
      "                ",
      "                ",
      "                ",
      "     N          ",
      "                ",
      "                ",
      "                ",
      "                "
    ],
    [
      "    度 度         ",
      "                ",
      "                ",
      "                ",
      "                ",
      "                ",
      "                ",
      "                ",
      "                ",
      "                ",
      "    版 版         ",
      "   林没跟没空        ",
      "    度 度         ",
      "                ",
      "                ",
      "                "
    ]
  ]
}