{
  "xsize": 16,
  "zsize": 16,
  "palette": {
    "palette": [
      {
        "char": " ",
        "block": "minecraft:air"
      },
      {
        "char": "c",
        "block": "minecraft:air"
      },
      {
        "char": "k",
        "block": "minecraft:air"
      },
      {
        "char": "a",
        "block": "minecraft:air"
      },
      {
        "char": "b",
        "block": "minecraft:air"
      },
      {
        "char": "r",
        "block": "minecraft:air"
      },
      {
        "char": "d",
        "block": "minecraft:air"
      },
      {
        "char": "s",
        "block": "minecraft:air"
      },
      {
        "char": "J",
        "block": "minecraft:air"
      },
      {
        "char": "q",
        "block": "minecraft:grass"
      },
      {
        "char": "度",
        "block": "minecraft:air"
      },
      {
        "char": "版",
        "block": "minecraft:air"
      },
      {
        "char": "林",
        "block": "minecraft:air"
      },
      {
        "char": "没",
        "block": "minecraft:air"
      }
    ]
  },
  "slices": [
    [
      "cckaabrkcadacccc",
      "cbakkcadadaabccr",
      "kcabddbdbabckkad",
      "bcardbckbbssssss",
      "kdcdaabackbbrdbb",
      "radabkcbbdbbkaka",
      "abacabkbkkacbkac",
      "kakdacbkbcsJssss",
      "akbdcdddbcdddakd",
      "kbbaaadccckdrbcd",
      "adkccaakkrbbkacd",
      "dcbcaadaaksssJss",
      "bddbcbdbkbakabkk",
      "kdcakkcbkcabdrac",
      "acadkaacbabdkbcc",
      "ddcbkddckasJJsss"
    ],
    [
      "      q         ",
      "               q",
      "                ",
      "   q            ",
      "            q   ",
      "q               ",
      "                ",
      "                ",
      "                ",
      "            q   ",
      "         q      ",
      "                ",
      "                ",
      "             q  ",
      "                ",
      "  q             "
    ],
    [
      "                ",
      "                ",
      "                ",
      "                ",
      "                ",
      "                ",
      "                ",
      "                ",
      "                ",
      "                ",
      "                ",
      "                ",
      "                ",
      "                ",
      "                ",
      "                "
    ],
    [
      "                ",
      "                ",
      "                ",
      "                ",
      "                ",
      "                ",
      "                ",
      "                ",
      "                ",
      "                ",
      "                ",
      "                ",
      "                ",
      "                ",
      "                ",
      "                "
    ],
    [
      "                ",
      "                ",
      "                ",
      "                ",
      "                ",
      "                ",
      "                ",
      "                ",
      "                ",
      "                ",
      "                ",
      "                ",
      "                ",
      "                ",
      "                ",
      "                "
    ],
    [
      "               度",
      "                ",
      "                ",
      "                ",
      "                ",
      "                ",
      "                ",
      "                ",
      "                ",
      "                ",
      "               版",
      "              林没",
      "               度",
      "                ",
      "                ",
      "                "
    ]
  ]
}