{
  "xsize": 16,
  "zsize": 16,
  "palette": {
    "palette": [
      {
        "char": " ",
        "block": "minecraft:air"
      },
      {
        "char": "m",
        "block": "minecraft:vine[east=false,north=false,south=true,up=false,west=false]"
      },
      {
        "char": "g",
        "block": "minecraft:blue_concrete"
      },
      {
        "char": "j",
        "block": "minecraft:vine[east=false,north=false,south=false,up=false,west=true]"
      },
      {
        "char": "C",
        "block": "minecraft:mossy_cobblestone"
      },
      {
        "char": "z",
        "block": "minecraft:mossy_stone_bricks"
      },
      {
        "char": "H",
        "block": "minecraft:cobblestone[weathering=false]"
      },
      {
        "char": "e",
        "block": "minecraft:smooth_quartz"
      },
      {
        "char": "y",
        "block": "minecraft:quartz_pillar[axis=y]"
      },
      {
        "char": "f",
        "block": "minecraft:polished_diorite"
      },
      {
        "char": "p",
        "block": "minecraft:diorite"
      },
      {
        "char": "D",
        "block": "minecraft:cracked_stone_bricks"
      },
      {
        "char": "i",
        "block": "minecraft:vine[east=false,north=true,south=false,up=false,west=false]"
      },
      {
        "char": "Ұ",
        "block": "minecraft:vine[east=true,north=true,south=false,up=false,west=false]"
      },
      {
        "char": "请",
        "block": "minecraft:vine[east=false,north=true,south=false,up=false,west=true]"
      },
      {
        "char": "l",
        "block": "minecraft:vine[east=true,north=false,south=false,up=false,west=false]"
      },
      {
        "char": "O",
        "block": "minecraft:dark_oak_fence[east=false,north=false,south=false,waterlogged=false,west=false]"
      },
      {
        "char": "E",
        "block": "minecraft:stone_bricks[weathering=false]"
      },
      {
        "char": "o",
        "block": "minecraft:quartz_block"
      },
      {
        "char": "数",
        "block": "minecraft:vine[east=false,north=false,south=true,up=true,west=false]"
      },
      {
        "char": "F",
        "block": "minecraft:stone_brick_slab[type=top,waterlogged=false,weathering=false]"
      },
      {
        "char": "t",
        "block": "minecraft:stone_slab[type=bottom,waterlogged=false,weathering=false]"
      },
      {
        "char": "受",
        "block": "minecraft:vine[east=false,north=true,south=false,up=true,west=false]"
      },
      {
        "char": "v",
        "block": "minecraft:vine[east=false,north=false,south=false,up=true,west=false]"
      },
      {
        "char": "身",
        "block": "minecraft:stone_brick_slab[type=bottom,waterlogged=false,weathering=false]"
      },
      {
        "char": "马",
        "block": "minecraft:stone_brick_slab[type=double,waterlogged=false,weathering=false]"
      }
    ]
  },
  "slices": [
    [
      "                ",
      "                ",
      "                ",
      "                ",
      "  m m    m      ",
      "gggggggggg      ",
      "         ggj    ",
      " C       zH     ",
      "eHyfypfffDHj    ",
      "  iiii iҰf请     ",
      "        lfj     ",
      "        lfj     ",
      "        l j     ",
      "        lfj     ",
      "O       lfm     ",
      "         fCj  mm"
    ],
    [
      "                ",
      "                ",
      "                ",
      "                ",
      "                ",
      "                ",
      "gggggggggg      ",
      " E       EC     ",
      "fEfeefyeyCzj    ",
      "  iiii  lf请     ",
      "        l j     ",
      "         ej     ",
      "        lfj     ",
      "        lpj     ",
      "O       lem     ",
      "         ezj  mm"
    ],
    [
      "                ",
      "                ",
      "                ",
      "                ",
      "                ",
      "                ",
      "                ",
      "gggggggggCE     ",
      "yEypffyoeCEj    ",
      "  iiii  lf请     ",
      "        lfj     ",
      "         f      ",
      "        loj     ",
      "        lej     ",
      "O       lpm     ",
      "         ezj  mm"
    ],
    [
      "                ",
      "                ",
      "                ",
      "                ",
      "                ",
      "                ",
      "                ",
      " H       EC     ",
      "yzfepeopeEHj    ",
      "  ii i  lf请     ",
      "        lpj     ",
      "         o      ",
      "        lfj     ",
      "        lej     ",
      "O        ym     ",
      "         yzj  mm"
    ],
    [
      "                ",
      "                ",
      "                ",
      "                ",
      "                ",
      "                ",
      "                ",
      " E       DD     ",
      "fDeeffefpHEj    ",
      "  ii i   o请     ",
      "         pj     ",
      "         e      ",
      "        lfj     ",
      "         f      ",
      "O        p数     ",
      "         oC    F"
    ],
    [
      "                ",
      "                ",
      "                ",
      "                ",
      "                ",
      "                ",
      "                ",
      " C       CC     ",
      "pEoeffoeeECj    ",
      " t受v v   f请     ",
      " t       f      ",
      " t       y      ",
      " t v    vfj     ",
      " tv      fF    身",
      "Ot       e马FFFF身",
      " t    v  e马马马马马 "
    ]
  ]
}