{
  "xsize": 16,
  "zsize": 16,
  "palette": {
    "palette": [
      {
        "char": " ",
        "block": "minecraft:air"
      },
      {
        "char": "e",
        "block": "minecraft:vine[east=false,north=false,south=true,up=false,west=false]"
      },
      {
        "char": "y",
        "block": "minecraft:mossy_cobblestone"
      },
      {
        "char": "f",
        "block": "minecraft:vine[east=false,north=false,south=false,up=false,west=true]"
      },
      {
        "char": "l",
        "block": "minecraft:vine[east=true,north=false,south=false,up=false,west=false]"
      },
      {
        "char": "h",
        "block": "minecraft:vine[east=false,north=true,south=false,up=false,west=false]"
      },
      {
        "char": "k",
        "block": "minecraft:oak_fence[east=false,north=false,south=true,waterlogged=false,west=false]"
      },
      {
        "char": "j",
        "block": "minecraft:oak_fence[east=false,north=true,south=false,waterlogged=false,west=false]"
      },
      {
        "char": "G",
        "block": "minecraft:oak_fence[east=false,north=false,south=false,waterlogged=false,west=false]"
      },
      {
        "char": "W",
        "block": "minecraft:air"
      },
      {
        "char": "Z",
        "block": "minecraft:air"
      },
      {
        "char": "p",
        "block": "minecraft:mossy_stone_bricks"
      },
      {
        "char": "q",
        "block": "minecraft:stone_bricks[weathering=false]"
      },
      {
        "char": "w",
        "block": "minecraft:cobblestone[weathering=false]"
      },
      {
        "char": "Q",
        "block": "minecraft:oak_fence[east=true,north=false,south=true,waterlogged=false,west=false]"
      },
      {
        "char": "m",
        "block": "minecraft:oak_fence[east=false,north=false,south=false,waterlogged=false,west=true]"
      },
      {
        "char": "n",
        "block": "minecraft:oak_fence[east=true,north=false,south=false,waterlogged=false,west=false]"
      },
      {
        "char": "J",
        "block": "minecraft:oak_fence[east=false,north=false,south=true,waterlogged=false,west=true]"
      },
      {
        "char": "b",
        "block": "minecraft:oak_fence[east=false,north=true,south=true,waterlogged=false,west=false]"
      },
      {
        "char": "R",
        "block": "minecraft:oak_fence[east=true,north=true,south=true,waterlogged=false,west=false]"
      },
      {
        "char": "c",
        "block": "minecraft:oak_fence[east=true,north=false,south=false,waterlogged=false,west=true]"
      },
      {
        "char": "P",
        "block": "minecraft:oak_fence[east=false,north=true,south=true,waterlogged=false,west=true]"
      },
      {
        "char": "K",
        "block": "minecraft:oak_fence[east=true,north=true,south=false,waterlogged=false,west=false]"
      },
      {
        "char": "L",
        "block": "minecraft:oak_fence[east=false,north=true,south=false,waterlogged=false,west=true]"
      },
      {
        "char": "r",
        "block": "minecraft:cracked_stone_bricks"
      },
      {
        "char": "M",
        "block": "minecraft:oak_fence[east=true,north=false,south=true,waterlogged=false,west=true]"
      },
      {
        "char": "N",
        "block": "minecraft:oak_fence[east=true,north=true,south=false,waterlogged=false,west=true]"
      },
      {
        "char": "Ͱ",
        "block": "minecraft:mossy_stone_brick_slab[type=double,waterlogged=false]"
      },
      {
        "char": "a",
        "block": "minecraft:air"
      },
      {
        "char": "8",
        "block": "minecraft:air"
      },
      {
        "char": "B",
        "block": "minecraft:air"
      },
      {
        "char": "V",
        "block": "minecraft:air"
      },
      {
        "char": "z",
        "block": "minecraft:air"
      },
      {
        "char": "T",
        "block": "minecraft:air"
      },
      {
        "char": "d",
        "block": "minecraft:stone_brick_slab[type=double,waterlogged=false,weathering=false]"
      },
      {
        "char": "6",
        "block": "minecraft:air"
      },
      {
        "char": "C",
        "block": "minecraft:air"
      },
      {
        "char": "X",
        "block": "minecraft:air"
      },
      {
        "char": "U",
        "block": "minecraft:air"
      },
      {
        "char": "1",
        "block": "minecraft:air"
      },
      {
        "char": "0",
        "block": "minecraft:air"
      },
      {
        "char": "2",
        "block": "minecraft:air"
      },
      {
        "char": "7",
        "block": "minecraft:air"
      },
      {
        "char": "x",
        "block": "minecraft:stone_brick_slab[type=top,waterlogged=false,weathering=false]"
      },
      {
        "char": "s",
        "block": "minecraft:spruce_planks"
      },
      {
        "char": "E",
        "block": "minecraft:light_gray_wool"
      },
      {
        "char": "ͱ",
        "block": "minecraft:stone_brick_wall[east=none,north=none,south=none,up=true,waterlogged=false,weathering=false,west=none]"
      },
      {
        "char": "ͼ",
        "block": "minecraft:stone_brick_wall[east=low,north=none,south=none,up=true,waterlogged=false,weathering=false,west=none]"
      },
      {
        "char": "Ί",
        "block": "minecraft:mossy_stone_brick_wall[east=none,north=none,south=none,up=true,waterlogged=false,west=low]"
      },
      {
        "char": "Ά",
        "block": "minecraft:air"
      },
      {
        "char": "I",
        "block": "minecraft:quartz_block"
      },
      {
        "char": "A",
        "block": "minecraft:white_concrete"
      },
      {
        "char": "t",
        "block": "minecraft:calcite"
      },
      {
        "char": "·",
        "block": "minecraft:air"
      },
      {
        "char": "u",
        "block": "minecraft:polished_diorite"
      },
      {
        "char": "v",
        "block": "minecraft:diorite"
      },
      {
        "char": "͵",
        "block": "minecraft:air"
      },
      {
        "char": "ͷ",
        "block": "minecraft:air"
      },
      {
        "char": "Ͳ",
        "block": "minecraft:air"
      },
      {
        "char": "΅",
        "block": "minecraft:air"
      },
      {
        "char": "F",
        "block": "minecraft:smooth_quartz"
      },
      {
        "char": "Ͷ",
        "block": "minecraft:air",
        "tag": {
          "FluidTank": {
            "FluidTank": {
              "Amount": 0,
              "FluidName": "minecraft:empty"
            }
          },
          "x": -395,
          "ForgeCaps": {},
          "y": -28,
          "z": 119,
          "id": "refurbished_furniture:kitchen_sink"
        }
      },
      {
        "char": "5",
        "block": "minecraft:light_gray_carpet"
      },
      {
        "char": "ʹ",
        "block": "minecraft:air",
        "tag": {
          "Connections": [
            "L"
          ],
          "NodePos": "-108576772747292L",
          "ProcessingTime": 0,
          "TotalProcessingTime": 0,
          "x": -395,
          "Enabled": "0b",
          "y": -28,
          "Items": [],
          "z": 120,
          "id": "refurbished_furniture:stove",
          "CookingSpaces": [
            {
              "CookingTime": 0,
              "Position": 0,
              "TotalCookingTime": 0
            },
            {
              "CookingTime": 0,
              "Position": 1,
              "TotalCookingTime": 0
            },
            {
              "CookingTime": 0,
              "Position": 2,
              "TotalCookingTime": 0
            }
          ],
          "Processing": "0b"
        }
      },
      {
        "char": ";",
        "block": "minecraft:air"
      },
      {
        "char": "Ϳ",
        "block": "minecraft:air"
      },
      {
        "char": "Έ",
        "block": "minecraft:quartz_pillar[axis=y]"
      },
      {
        "char": "Ή",
        "block": "minecraft:air"
      },
      {
        "char": "ͺ",
        "block": "minecraft:chest[facing=north,type=single,waterlogged=false]",
        "loot": "bigbuildingsloot",
        "tag": {
          "x": -392,
          "y": -28,
          "Items": [],
          "z": 121,
          "id": "minecraft:chest"
        }
      },
      {
        "char": "9",
        "block": "minecraft:air"
      },
      {
        "char": "ͳ",
        "block": "minecraft:stone_brick_wall[east=low,north=none,south=low,up=true,waterlogged=false,weathering=false,west=none]"
      },
      {
        "char": "Ό",
        "block": "minecraft:stone_brick_wall[east=none,north=none,south=low,up=true,waterlogged=false,weathering=false,west=low]"
      },
      {
        "char": "D",
        "block": "minecraft:air"
      },
      {
        "char": "ͽ",
        "block": "minecraft:air"
      },
      {
        "char": "S",
        "block": "minecraft:air"
      },
      {
        "char": "Ώ",
        "block": "minecraft:potted_dead_bush"
      },
      {
        "char": "o",
        "block": "minecraft:air"
      },
      {
        "char": "3",
        "block": "minecraft:air"
      },
      {
        "char": "4",
        "block": "minecraft:cobweb"
      },
      {
        "char": "g",
        "block": "minecraft:air"
      },
      {
        "char": "i",
        "block": "minecraft:air"
      },
      {
        "char": "H",
        "block": "minecraft:air"
      },
      {
        "char": "O",
        "block": "minecraft:air"
      },
      {
        "char": "Ύ",
        "block": "minecraft:oak_wall_sign[facing=south,waterlogged=false]",
        "tag": {
          "back_text": {
            "color": "black",
            "has_glowing_text": "0b",
            "messages": [
              "{\"text\":\"\"}",
              "{\"text\":\"\"}",
              "{\"text\":\"\"}",
              "{\"text\":\"\"}"
            ]
          },
          "is_waxed": "0b",
          "x": -392,
          "y": -25,
          "z": 117,
          "id": "minecraft:sign",
          "front_text": {
            "color": "black",
            "has_glowing_text": "0b",
            "messages": [
              "{\"extra\":[{\"text\":\"Weaponry\"}],\"text\":\"\"}",
              "{\"extra\":[{\"text\":\"---------------\"}],\"text\":\"\"}",
              "{\"extra\":[{\"text\":\"ONLY USE IN CASE\"}],\"text\":\"\"}",
              "{\"extra\":[{\"text\":\"OF EMERGENCY\"}],\"text\":\"\"}"
            ]
          }
        }
      },
      {
        "char": "ͻ",
        "block": "minecraft:redstone_lamp[lit=false]"
      },
      {
        "char": "Y",
        "block": "minecraft:air"
      },
      {
        "char": "΄",
        "block": "minecraft:daylight_detector[inverted=false,power=14]",
        "tag": {
          "x": -393,
          "y": -15,
          "z": 119,
          "id": "minecraft:daylight_detector"
        }
      }
    ]
  },
  "slices": [
    [
      "e           e   ",
      "yf         lyf  ",
      "h           h   ",
      "                ",
      "   k     k      ",
      "   j     j      ",
      "                ",
      "      G         ",
      "                ",
      "   k     k      ",
      " WZj     j      ",
      "                ",
      "e           e   ",
      "pf         lqf  ",
      "                ",
      "                "
    ],
    [
      "e           e   ",
      "wf         lwf  ",
      "h           h   ",
      "                ",
      "   Qm   nJ      ",
      "   b     b      ",
      "   b     b      ",
      "   RcccccP      ",
      "   b     b      ",
      " WZb     b      ",
      "   Km   nL      ",
      "                ",
      "e           e   ",
      "rf         lwf  ",
      "                ",
      "                "
    ],
    [
      "e           e   ",
      "pf         lwf  ",
      "h           h   ",
      "                ",
      "   nccMccm      ",
      "      b         ",
      "      b         ",
      "      b         ",
      " WZ   b         ",
      "      b         ",
      "   nccNccm      ",
      "                ",
      "e           e   ",
      "wf         lpf  ",
      "                ",
      "                "
    ],
    [
      "e           e   ",
      "rf         lqf  ",
      "h           h   ",
      "                ",
      "   k     k      ",
      "   j     j      ",
      "                ",
      " WZ   G         ",
      "                ",
      "   k     k      ",
      "   j     j      ",
      "                ",
      "e           e   ",
      "yf         lwf  ",
      "                ",
      "                "
    ],
    [
      "e           e   ",
      "rf         lpf  ",
      "h           h   ",
      "                ",
      "   Qm   nJ      ",
      "   b     b      ",
      " WZb     b      ",
      "   RcccccP      ",
      "   b     b      ",
      "   b     b      ",
      "   Km   nL      ",
      "                ",
      "e           e   ",
      "qf         lwf  ",
      "                ",
      "                "
    ],
    [
      "e           e   ",
      "pf         lrf  ",
      "h           h   ",
      "                ",
      "   nccMccm      ",
      " WZ   b         ",
      "      b         ",
      "      b         ",
      "      b         ",
      "      b         ",
      "   nccNccm      ",
      "                ",
      "e           e   ",
      "pf         lpf  ",
      "                ",
      "                "
    ],
    [
      "e           e   ",
      "Ͱf         lrf  ",
      "haa         h   ",
      " aa             ",
      " WZk     k      ",
      "   j     j      ",
      "                ",
      "      G         ",
      "                ",
      "   k     k      ",
      "   j     j      ",
      "                ",
      "e           e   ",
      "rf         lwf  ",
      "                ",
      "                "
    ],
    [
      "e           e   ",
      "pf         lyf  ",
      "h8BV        h   ",
      " z T            ",
      "   Qm   nJ      ",
      "   b     b      ",
      "   b     b      ",
      "   RcccccP      ",
      "   b     b      ",
      "   b     b      ",
      "   Km   nL      ",
      "                ",
      "e           e   ",
      "qf         ldf  ",
      "                ",
      "                "
    ],
    [
      "e           e   ",
      "yf         lqf  ",
      "h   V       h   ",
      "    T           ",
      "   nccMccm      ",
      "      b         ",
      "      b         ",
      "      b         ",
      "      b         ",
      "      b         ",
      "   nccNccm      ",
      "                ",
      "e               ",
      "y          ld   ",
      "                ",
      "                "
    ],
    [
      "e           e   ",
      "rf         lpf  ",
      "h    V      h   ",
      "     T          ",
      "   k     k      ",
      "   j     j      ",
      "                ",
      "      G         ",
      "                ",
      "   k     k      ",
      "   j     j      ",
      "                ",
      "e               ",
      "p           d   ",
      "                ",
      "                "
    ],
    [
      "e           e   ",
      "qf         lqf  ",
      "h     V     h   ",
      "      T         ",
      "   Qm   nJ      ",
      "   b     b      ",
      "   b     b      ",
      "   RcccccP      ",
      "   b     b      ",
      "   b     b      ",
      "   Km   nL      ",
      "                ",
      "                ",
      "r           d   ",
      "                ",
      "                "
    ],
    [
      "e           e   ",
      "qf         lpf  ",
      "h      V    h   ",
      "       T        ",
      "   nccMccm      ",
      "      b         ",
      "      b         ",
      "      b         ",
      "      b         ",
      "      b         ",
      "   nccNccm      ",
      "                ",
      "                ",
      "p           d   ",
      "                ",
      "                "
    ],
    [
      "e           e   ",
      "qf         lwf  ",
      "h       V   h   ",
      "        T       ",
      "   k     k      ",
      "   j     j      ",
      "                ",
      "      G         ",
      "                ",
      "   k     k      ",
      "   j     j      ",
      "                ",
      "                ",
      "w           d   ",
      "                ",
      "                "
    ],
    [
      "e           e   ",
      "yf         ldf  ",
      "h        Vaah   ",
      "         Taa    ",
      "   Qm   nJ      ",
      "   b     b      ",
      "   b     b      ",
      "   RcccccP      ",
      "   b     b      ",
      "   b     b      ",
      "   Km   nL      ",
      "                ",
      "                ",
      "p           d   ",
      "                ",
      "                "
    ],
    [
      "e           e   ",
      "qf         lrf  ",
      "h         B6h   ",
      "           C    ",
      "   nccMccmXU    ",
      "      b         ",
      "      b         ",
      "      b         ",
      "      b         ",
      "      b         ",
      "   nccNccm      ",
      "                ",
      "                ",
      "y           d   ",
      "                ",
      "                "
    ],
    [
      "e           e   ",
      "wf         lwf  ",
      "h           h   ",
      "                ",
      "   k     k      ",
      "   j     jXU    ",
      "                ",
      "      G         ",
      "                ",
      "   k     k      ",
      "   j     j      ",
      "                ",
      "                ",
      "p           d   ",
      "                ",
      "                "
    ],
    [
      "e           e   ",
      "qf         lpf  ",
      "h           h   ",
      "                ",
      "   Qm   nJ      ",
      "   b     b      ",
      "   b     bXU    ",
      "   RcccccP      ",
      "   b     b      ",
      "   b     b      ",
      "   Km   nL      ",
      "                ",
      "                ",
      "y           d   ",
      "                ",
      "                "
    ],
    [
      "e           e   ",
      "pf         lwf  ",
      "h           h   ",
      "                ",
      "   nccMccm      ",
      "      b         ",
      "      b         ",
      "      b   XU    ",
      "      b         ",
      "      b         ",
      "   nccNccm      ",
      "                ",
      "                ",
      "q           d   ",
      "                ",
      "                "
    ],
    [
      "e           e   ",
      "wf         lrf  ",
      "h           h   ",
      "                ",
      "   k     k      ",
      "   j     j      ",
      "                ",
      "      G         ",
      "          XU    ",
      "   k     k      ",
      "   j     j      ",
      "                ",
      "                ",
      "r           d   ",
      "                ",
      "                "
    ],
    [
      "e           e   ",
      "pf         lrf  ",
      "h           h   ",
      "                ",
      "   Qm   nJ      ",
      "   b     b      ",
      "   b     b      ",
      "   RcccccP      ",
      "   b     b      ",
      "   b     bXU    ",
      "   Km   nL      ",
      "                ",
      "                ",
      "y           d   ",
      "                ",
      "                "
    ],
    [
      "e           e   ",
      "qf         lqf  ",
      "h           h   ",
      "                ",
      "   nccMccm      ",
      "      b         ",
      "      b         ",
      "      b         ",
      "      b         ",
      "      b         ",
      "   nccNccmXU    ",
      "          aa    ",
      "          aa    ",
      "y           d   ",
      "                ",
      "                "
    ],
    [
      "e           e   ",
      "pf         lqf  ",
      "h           h   ",
      "                ",
      "   k     k      ",
      "   j     j      ",
      "                ",
      "      G         ",
      "                ",
      "   k     k      ",
      "   j     j      ",
      "         1 C    ",
      "         027    ",
      "p           q   ",
      "                ",
      "                "
    ],
    [
      "e           e   ",
      "qf         lqf  ",
      "h           h   ",
      "                ",
      "   Qm   nJ      ",
      "   b     b      ",
      "   b     b      ",
      "   RcccccP      ",
      "   b     b      ",
      "   b     b      ",
      "   Km   nL      ",
      "        1       ",
      "        0       ",
      "p           r   ",
      "                ",
      "                "
    ],
    [
      "            e   ",
      "rf         lyf  ",
      "h           h   ",
      "                ",
      "   nccMccm      ",
      "      b         ",
      "      b         ",
      "      b         ",
      "      b         ",
      "      b         ",
      "   nccNccm      ",
      "       1        ",
      "       0        ",
      "r           q   ",
      "                ",
      "                "
    ],
    [
      "            e   ",
      "rf          pf  ",
      "h               ",
      "                ",
      "   k     k      ",
      "   j     j      ",
      "                ",
      "      G         ",
      "                ",
      "   k     k      ",
      "   j     j      ",
      "      1         ",
      "      0         ",
      "p           r   ",
      "                ",
      "                "
    ],
    [
      "e           e   ",
      "rf          rf  ",
      "   aaaaaaa      ",
      "   axxxxxa      ",
      " aadddddddaa    ",
      " axdddddddxa    ",
      " axdddddddxa    ",
      " aadddddddxa    ",
      " addddddddxa    ",
      " axdddddddxa    ",
      " aadddddddaa    ",
      "     1          ",
      "     0          ",
      "p           q   ",
      "                ",
      "                "
    ],
    [
      "            e   ",
      "daaaaaaaaaaaͰf  ",
      "aaaaaaaaaaaaa   ",
      "aaaaaaaaaaaaa   ",
      "aaadddsdddaaa   ",
      "aaadsssssdaaa   ",
      "aaadsssssdaaa   ",
      "aaadssEEEdaaa   ",
      "aaadssEEEdaaa   ",
      "aaadssEEEdaaa   ",
      "aaadddddddaaa   ",
      "aaaa1   aaaaa   ",
      "aaaa0   aaaaa   ",
      "d       aaaad   ",
      "                ",
      "                "
    ],
    [
      "                ",
      "ͱ8BBBBBBBBB6ͼΊ  ",
      "8           6   ",
      "z       Ά   C   ",
      "z  IAt·utI  C   ",
      "z  v͵   ͷt  C   ",
      "z  vͲ   ΅v  C   ",
      "z  FͶ  55u  C   ",
      "z  Fʹ 5 ;A  C   ",
      "z ͿuΈΉ ͺ u  C   ",
      "z  uIFIuFA  C   ",
      "z       z   C   ",
      "9222    z   7   ",
      "ͱ       9227ͳΌ  ",
      "                ",
      "                "
    ],
    [
      "                ",
      "                ",
      "                ",
      "                ",
      "   FDuͽtDv      ",
      "   A     u      ",
      "   S     S      ",
      "   t     t      ",
      "   S     S      ",
      "   vΏ    t      ",
      "   IDvDtDv      ",
      "                ",
      "                ",
      "                ",
      "                ",
      "                "
    ],
    [
      "                ",
      "                ",
      " oo       o3    ",
      " o o  34 o o    ",
      "   vDIvuDA3     ",
      "  ov     t      ",
      "   S     S      ",
      "  ou     to     ",
      "   S     S      ",
      "  oF     F4     ",
      "   tDvDFDuo     ",
      " o o o o o o    ",
      " oo       oo    ",
      "                ",
      "                ",
      "                "
    ],
    [
      "                ",
      "                ",
      "   ggggggg      ",
      "  giHiiiiig     ",
      " gHIAuAtFvig    ",
      " Oit   Ύ4uig    ",
      " OiA     tHg    ",
      " Oiu     vHO    ",
      " Oit     Aig    ",
      " git    4vig    ",
      " gitAIuvuAHg    ",
      "  giiiHiiig     ",
      "   ggggggg      ",
      "                ",
      "                ",
      "                "
    ],
    [
      "                ",
      "                ",
      "                ",
      "                ",
      "   ggggggg      ",
      "   giHiiiO      ",
      "   Oioooig      ",
      "   gioͻoiO      ",
      "   gHo3oig      ",
      "   giiiiig      ",
      "   ggggggg      ",
      "                ",
      "                ",
      "                ",
      "                ",
      "                "
    ],
    [
      "                ",
      "                ",
      "                ",
      "                ",
      "                ",
      "                ",
      "     ggg        ",
      "     gig        ",
      "     ggg        ",
      "                ",
      "                ",
      "                ",
      "                ",
      "                ",
      "                ",
      "                "
    ],
    [
      "                ",
      "                ",
      "                ",
      "                ",
      "                ",
      "                ",
      "                ",
      "      Y         ",
      "                ",
      "                ",
      "                ",
      "                ",
      "                ",
      "                ",
      "                ",
      "                "
    ],
    [
      "                ",
      "                ",
      "                ",
      "                ",
      "                ",
      "                ",
      "                ",
      "      Y         ",
      "                ",
      "                ",
      "                ",
      "                ",
      "                ",
      "                ",
      "                ",
      "                "
    ],
    [
      "                ",
      "                ",
      "                ",
      "                ",
      "                ",
      "                ",
      "                ",
      "      Y         ",
      "                ",
      "                ",
      "                ",
      "                ",
      "                ",
      "                ",
      "                ",
      "                "
    ],
    [
      "                ",
      "                ",
      "                ",
      "                ",
      "                ",
      "                ",
      "                ",
      "      Y         ",
      "                ",
      "                ",
      "                ",
      "                ",
      "                ",
      "                ",
      "                ",
      "                "
    ],
    [
      "                ",
      "                ",
      "                ",
      "                ",
      "                ",
      "                ",
      "                ",
      "      Y         ",
      "                ",
      "                ",
      "                ",
      "                ",
      "                ",
      "                ",
      "                ",
      "                "
    ],
    [
      "                ",
      "                ",
      "                ",
      "                ",
      "                ",
      "                ",
      "                ",
      "      Y         ",
      "                ",
      "                ",
      "                ",
      "                ",
      "                ",
      "                ",
      "                ",
      "                "
    ],
    [
      "                ",
      "                ",
      "                ",
      "                ",
      "                ",
      "                ",
      "                ",
      "      Y         ",
      "                ",
      "                ",
      "                ",
      "                ",
      "                ",
      "                ",
      "                ",
      "                "
    ],
    [
      "                ",
      "                ",
      "                ",
      "                ",
      "                ",
      "                ",
      "                ",
      "      ΄         ",
      "                ",
      "                ",
      "                ",
      "                ",
      "                ",
      "                ",
      "                ",
      "                "
    ]
  ]
}